/*
 *** MADE BY MITHION'S .SCHEMATIC TO JAVA CONVERTING TOOL v1.6 ***
 */

package wildycraft.structures;

import java.util.Random;

import wildycraft.Wildycraft;

import net.minecraft.block.Block;
import net.minecraft.init.Blocks;
import net.minecraft.item.ItemStack;
import net.minecraft.tileentity.TileEntityChest;
import net.minecraft.tileentity.TileEntityMobSpawner;
import net.minecraft.util.WeightedRandomChestContent;
import net.minecraft.world.World;
import net.minecraft.world.gen.feature.WorldGenerator;
import net.minecraftforge.common.ChestGenHooks;
import net.minecraftforge.common.DungeonHooks;

public class bkf3 extends WorldGenerator {
	public bkf3() {
	}

	public boolean generate(World world, Random rand, int i, int j, int k) {
		world.setBlock(i + 0, j + 0, k + 4, Blocks.cobblestone);
		world.setBlock(i + 0, j + 0, k + 5, Blocks.cobblestone);
		world.setBlock(i + 0, j + 0, k + 6, Blocks.cobblestone);
		world.setBlock(i + 0, j + 0, k + 7, Blocks.cobblestone);
		world.setBlock(i + 0, j + 1, k + 4, Blocks.stonebrick);
		world.setBlock(i + 0, j + 1, k + 5, Blocks.stonebrick);
		world.setBlock(i + 0, j + 1, k + 6, Blocks.stonebrick);
		world.setBlock(i + 0, j + 1, k + 7, Blocks.stonebrick);
		world.setBlock(i + 0, j + 2, k + 4, Blocks.stonebrick);
		world.setBlock(i + 0, j + 2, k + 5, Blocks.stonebrick);
		world.setBlock(i + 0, j + 2, k + 6, Blocks.stonebrick);
		world.setBlock(i + 0, j + 2, k + 7, Blocks.stonebrick);
		world.setBlock(i + 0, j + 3, k + 4, Blocks.stonebrick);
		world.setBlock(i + 0, j + 3, k + 5, Blocks.stonebrick);
		world.setBlock(i + 0, j + 3, k + 6, Blocks.stonebrick);
		world.setBlock(i + 0, j + 3, k + 7, Blocks.stonebrick);
		world.setBlock(i + 0, j + 4, k + 4, Blocks.stonebrick);
		world.setBlock(i + 0, j + 4, k + 5, Blocks.stonebrick);
		world.setBlock(i + 0, j + 4, k + 6, Blocks.stonebrick);
		world.setBlock(i + 0, j + 4, k + 7, Blocks.stonebrick);
		world.setBlock(i + 0, j + 5, k + 4, Blocks.stonebrick);
		world.setBlock(i + 0, j + 5, k + 5, Blocks.stonebrick);
		world.setBlock(i + 0, j + 5, k + 6, Blocks.stonebrick);
		world.setBlock(i + 0, j + 5, k + 7, Blocks.stonebrick);
		world.setBlock(i + 0, j + 6, k + 4, Blocks.stonebrick);
		world.setBlock(i + 0, j + 6, k + 5, Blocks.stonebrick);
		world.setBlock(i + 0, j + 6, k + 6, Blocks.stonebrick);
		world.setBlock(i + 0, j + 6, k + 7, Blocks.stonebrick);
		world.setBlock(i + 0, j + 7, k + 4, Blocks.stonebrick);
		world.setBlock(i + 0, j + 7, k + 5, Blocks.stonebrick);
		world.setBlock(i + 0, j + 7, k + 6, Blocks.stonebrick);
		world.setBlock(i + 0, j + 7, k + 7, Blocks.stonebrick);
		world.setBlock(i + 0, j + 8, k + 4, Blocks.stonebrick);
		world.setBlock(i + 0, j + 8, k + 5, Blocks.stonebrick);
		world.setBlock(i + 0, j + 8, k + 6, Blocks.stonebrick);
		world.setBlock(i + 0, j + 8, k + 7, Blocks.stonebrick);
		world.setBlock(i + 0, j + 9, k + 4, Blocks.stonebrick);
		world.setBlock(i + 0, j + 9, k + 5,
				Blocks.stone_slab, 3, 1 | (1<<1));
		world.setBlock(i + 0, j + 9, k + 6, Blocks.stonebrick);
		world.setBlock(i + 0, j + 9, k + 7,
				Blocks.stone_slab, 3, 1 | (1<<1));
		world.setBlock(i + 1, j + 0, k + 3, Blocks.cobblestone);
		world.setBlock(i + 1, j + 0, k + 4, Blocks.cobblestone);
		world.setBlock(i + 1, j + 0, k + 5, Blocks.cobblestone);
		world.setBlock(i + 1, j + 0, k + 6, Blocks.cobblestone);
		world.setBlock(i + 1, j + 0, k + 7, Blocks.cobblestone);
		world.setBlock(i + 1, j + 0, k + 8, Blocks.cobblestone);
		world.setBlock(i + 1, j + 1, k + 3, Blocks.stonebrick);
		world.setBlock(i + 1, j + 1, k + 4, Blocks.air);
		world.setBlock(i + 1, j + 1, k + 5, Blocks.air);
		world.setBlock(i + 1, j + 1, k + 6, Blocks.air);
		world.setBlock(i + 1, j + 1, k + 7, Blocks.air);
		world.setBlock(i + 1, j + 1, k + 8, Blocks.stonebrick);
		world.setBlock(i + 1, j + 2, k + 3, Blocks.stonebrick);
		world.setBlock(i + 1, j + 2, k + 4, Blocks.air);
		world.setBlock(i + 1, j + 2, k + 5, Blocks.air);
		world.setBlock(i + 1, j + 2, k + 6, Blocks.air);
		world.setBlock(i + 1, j + 2, k + 7, Blocks.air);
		world.setBlock(i + 1, j + 2, k + 8, Blocks.stonebrick);
		world.setBlock(i + 1, j + 3, k + 3, Blocks.stonebrick);
		world.setBlock(i + 1, j + 3, k + 4, Blocks.air);
		world.setBlock(i + 1, j + 3, k + 5, Blocks.air);
		world.setBlock(i + 1, j + 3, k + 6, Blocks.air);
		world.setBlock(i + 1, j + 3, k + 7, Blocks.air);
		world.setBlock(i + 1, j + 3, k + 8, Blocks.stonebrick);
		world.setBlock(i + 1, j + 4, k + 3, Blocks.stonebrick);
		world.setBlock(i + 1, j + 4, k + 4, Blocks.cobblestone);
		world.setBlock(i + 1, j + 4, k + 5, Blocks.cobblestone);
		world.setBlock(i + 1, j + 4, k + 6, Blocks.cobblestone);
		world.setBlock(i + 1, j + 4, k + 7, Blocks.cobblestone);
		world.setBlock(i + 1, j + 4, k + 8, Blocks.stonebrick);
		world.setBlock(i + 1, j + 5, k + 3, Blocks.stonebrick);
		world.setBlock(i + 1, j + 5, k + 4, Blocks.bookshelf);
		world.setBlock(i + 1, j + 5, k + 5, Blocks.bookshelf);
		world.setBlock(i + 1, j + 5, k + 6, Blocks.bookshelf);
		world.setBlock(i + 1, j + 5, k + 7, Blocks.bookshelf);
		world.setBlock(i + 1, j + 5, k + 8, Blocks.stonebrick);
		world.setBlock(i + 1, j + 6, k + 3, Blocks.stonebrick);
		world.setBlock(i + 1, j + 6, k + 4, Blocks.bookshelf);
		world.setBlock(i + 1, j + 6, k + 5, Blocks.bookshelf);
		world.setBlock(i + 1, j + 6, k + 6, Blocks.bookshelf);
		world.setBlock(i + 1, j + 6, k + 7, Blocks.bookshelf);
		world.setBlock(i + 1, j + 6, k + 8, Blocks.stonebrick);
		world.setBlock(i + 1, j + 7, k + 3, Blocks.stonebrick);
		world.setBlock(i + 1, j + 7, k + 4, Blocks.air);
		world.setBlock(i + 1, j + 7, k + 5, Blocks.air);
		world.setBlock(i + 1, j + 7, k + 6, Blocks.air);
		world.setBlock(i + 1, j + 7, k + 7, Blocks.air);
		world.setBlock(i + 1, j + 7, k + 8, Blocks.stonebrick);
		world.setBlock(i + 1, j + 8, k + 3, Blocks.stonebrick);
		world.setBlock(i + 1, j + 8, k + 4, Blocks.cobblestone);
		world.setBlock(i + 1, j + 8, k + 5, Blocks.cobblestone);
		world.setBlock(i + 1, j + 8, k + 6, Blocks.cobblestone);
		world.setBlock(i + 1, j + 8, k + 7, Blocks.cobblestone);
		world.setBlock(i + 1, j + 8, k + 8, Blocks.stonebrick);
		world.setBlock(i + 1, j + 9, k + 3,
				Blocks.stone_slab, 3, 1 | (1<<1));
		world.setBlock(i + 1, j + 9, k + 8, Blocks.stonebrick);
		world.setBlock(i + 2, j + 0, k + 2, Blocks.cobblestone);
		world.setBlock(i + 2, j + 0, k + 3, Blocks.cobblestone);
		world.setBlock(i + 2, j + 0, k + 4, Blocks.cobblestone);
		world.setBlock(i + 2, j + 0, k + 5, Blocks.cobblestone);
		world.setBlock(i + 2, j + 0, k + 6, Blocks.cobblestone);
		world.setBlock(i + 2, j + 0, k + 7, Blocks.cobblestone);
		world.setBlock(i + 2, j + 0, k + 8, Blocks.cobblestone);
		world.setBlock(i + 2, j + 0, k + 9, Blocks.cobblestone);
		world.setBlock(i + 2, j + 1, k + 2, Blocks.stonebrick);
		world.setBlock(i + 2, j + 1, k + 3, Blocks.air);
		world.setBlock(i + 2, j + 1, k + 4, Blocks.air);
		world.setBlock(i + 2, j + 1, k + 5, Blocks.air);
		world.setBlock(i + 2, j + 1, k + 6, Blocks.air);
		world.setBlock(i + 2, j + 1, k + 7, Blocks.air);
		world.setBlock(i + 2, j + 1, k + 8, Blocks.air);
		world.setBlock(i + 2, j + 1, k + 9, Blocks.stonebrick);
		world.setBlock(i + 2, j + 2, k + 2, Blocks.stonebrick);
		world.setBlock(i + 2, j + 2, k + 3, Blocks.air);
		world.setBlock(i + 2, j + 2, k + 4, Blocks.air);
		world.setBlock(i + 2, j + 2, k + 5, Blocks.air);
		world.setBlock(i + 2, j + 2, k + 6, Blocks.air);
		world.setBlock(i + 2, j + 2, k + 7, Blocks.air);
		world.setBlock(i + 2, j + 2, k + 8, Blocks.air);
		world.setBlock(i + 2, j + 2, k + 9, Blocks.stonebrick);
		world.setBlock(i + 2, j + 3, k + 2, Blocks.stonebrick);
		world.setBlock(i + 2, j + 3, k + 3, Blocks.air);
		world.setBlock(i + 2, j + 3, k + 4, Blocks.air);
		world.setBlock(i + 2, j + 3, k + 5, Blocks.air);
		world.setBlock(i + 2, j + 3, k + 6, Blocks.air);
		world.setBlock(i + 2, j + 3, k + 7, Blocks.air);
		world.setBlock(i + 2, j + 3, k + 8, Blocks.air);
		world.setBlock(i + 2, j + 3, k + 9, Blocks.stonebrick);
		world.setBlock(i + 2, j + 4, k + 2, Blocks.stonebrick);
		world.setBlock(i + 2, j + 4, k + 3, Blocks.cobblestone);
		world.setBlock(i + 2, j + 4, k + 4, Blocks.cobblestone);
		world.setBlock(i + 2, j + 4, k + 5, Blocks.cobblestone);
		world.setBlock(i + 2, j + 4, k + 6, Blocks.cobblestone);
		world.setBlock(i + 2, j + 4, k + 7, Blocks.cobblestone);
		world.setBlock(i + 2, j + 4, k + 8, Blocks.cobblestone);
		world.setBlock(i + 2, j + 4, k + 9, Blocks.stonebrick);
		world.setBlock(i + 2, j + 5, k + 2, Blocks.stonebrick);
		world.setBlock(i + 2, j + 5, k + 3, Blocks.planks);
		world.setBlock(i + 2, j + 5, k + 4, Blocks.air);
		world.setBlock(i + 2, j + 5, k + 5, Blocks.air);
		world.setBlock(i + 2, j + 5, k + 6, Blocks.air);
		world.setBlock(i + 2, j + 5, k + 7, Blocks.air);
		world.setBlock(i + 2, j + 5, k + 8, Blocks.air);
		world.setBlock(i + 2, j + 5, k + 9, Blocks.stonebrick);
		world.setBlock(i + 2, j + 6, k + 2, Blocks.stonebrick);
		world.setBlock(i + 2, j + 6, k + 3, Blocks.air);
		world.setBlock(i + 2, j + 6, k + 4, Blocks.air);
		world.setBlock(i + 2, j + 6, k + 5, Blocks.air);
		world.setBlock(i + 2, j + 6, k + 6, Blocks.air);
		world.setBlock(i + 2, j + 6, k + 7, Blocks.air);
		world.setBlock(i + 2, j + 6, k + 8, Blocks.air);
		world.setBlock(i + 2, j + 6, k + 9, Blocks.stonebrick);
		world.setBlock(i + 2, j + 7, k + 2, Blocks.stonebrick);
		world.setBlock(i + 2, j + 7, k + 3, Blocks.air);
		world.setBlock(i + 2, j + 7, k + 4, Blocks.air);
		world.setBlock(i + 2, j + 7, k + 5, Blocks.air);
		world.setBlock(i + 2, j + 7, k + 6, Blocks.air);
		world.setBlock(i + 2, j + 7, k + 7, Blocks.air);
		world.setBlock(i + 2, j + 7, k + 8, Blocks.air);
		world.setBlock(i + 2, j + 7, k + 9, Blocks.stonebrick);
		world.setBlock(i + 2, j + 8, k + 2, Blocks.stonebrick);
		world.setBlock(i + 2, j + 8, k + 3, Blocks.cobblestone);
		world.setBlock(i + 2, j + 8, k + 4, Blocks.cobblestone);
		world.setBlock(i + 2, j + 8, k + 5, Blocks.cobblestone);
		world.setBlock(i + 2, j + 8, k + 6, Blocks.cobblestone);
		world.setBlock(i + 2, j + 8, k + 7, Blocks.cobblestone);
		world.setBlock(i + 2, j + 8, k + 8, Blocks.cobblestone);
		world.setBlock(i + 2, j + 8, k + 9, Blocks.stonebrick);
		world.setBlock(i + 2, j + 9, k + 2, Blocks.stonebrick);
		world.setBlock(i + 2, j + 9, k + 4, Blocks.stonebrick);
		world.setBlock(i + 2, j + 9, k + 5, Blocks.stonebrick);
		world.setBlock(i + 2, j + 9, k + 6, Blocks.stonebrick);
		world.setBlock(i + 2, j + 9, k + 9,
				Blocks.stone_slab, 3, 1 | (1<<1));
		world.setBlock(i + 2, j + 10, k + 4, Blocks.stonebrick);
		world.setBlock(i + 2, j + 10, k + 5, Blocks.stonebrick);
		world.setBlock(i + 2, j + 10, k + 6, Blocks.stonebrick);
		world.setBlock(i + 2, j + 11, k + 4, Blocks.stonebrick);
		world.setBlock(i + 2, j + 11, k + 5, Blocks.stonebrick);
		world.setBlock(i + 2, j + 11, k + 6, Blocks.stonebrick);
		world.setBlock(i + 2, j + 12, k + 4, Blocks.stonebrick);
		world.setBlock(i + 2, j + 12, k + 5, Blocks.stonebrick);
		world.setBlock(i + 2, j + 12, k + 6, Blocks.stonebrick);
		world.setBlock(i + 2, j + 13, k + 4,
				Blocks.stone_slab, 3, 1 | (1<<1));
		world.setBlock(i + 2, j + 13, k + 5, Blocks.stonebrick);
		world.setBlock(i + 2, j + 13, k + 6,
				Blocks.stone_slab, 3, 1 | (1<<1));
		world.setBlock(i + 3, j + 0, k + 1, Blocks.cobblestone);
		world.setBlock(i + 3, j + 0, k + 2, Blocks.cobblestone);
		world.setBlock(i + 3, j + 0, k + 3, Blocks.cobblestone);
		world.setBlock(i + 3, j + 0, k + 4, Blocks.cobblestone);
		world.setBlock(i + 3, j + 0, k + 5, Blocks.cobblestone);
		world.setBlock(i + 3, j + 0, k + 6, Blocks.cobblestone);
		world.setBlock(i + 3, j + 0, k + 7, Blocks.cobblestone);
		world.setBlock(i + 3, j + 0, k + 8, Blocks.cobblestone);
		world.setBlock(i + 3, j + 0, k + 9, Blocks.cobblestone);
		world.setBlock(i + 3, j + 0, k + 10, Blocks.cobblestone);
		world.setBlock(i + 3, j + 0, k + 29, Blocks.cobblestone);
		world.setBlock(i + 3, j + 1, k + 1, Blocks.stonebrick);
		world.setBlock(i + 3, j + 1, k + 2, Blocks.air);
		world.setBlock(i + 3, j + 1, k + 3, Blocks.air);
		world.setBlock(i + 3, j + 1, k + 4, Blocks.air);
		world.setBlock(i + 3, j + 1, k + 5, Blocks.air);
		world.setBlock(i + 3, j + 1, k + 6, Blocks.air);
		world.setBlock(i + 3, j + 1, k + 7, Blocks.air);
		world.setBlock(i + 3, j + 1, k + 8, Blocks.air);
		world.setBlock(i + 3, j + 1, k + 9, Blocks.air);
		world.setBlock(i + 3, j + 1, k + 10, Blocks.stonebrick);
		world.setBlock(i + 3, j + 2, k + 1, Blocks.stonebrick);
		world.setBlock(i + 3, j + 2, k + 2, Blocks.air);
		world.setBlock(i + 3, j + 2, k + 3, Blocks.air);
		world.setBlock(i + 3, j + 2, k + 4, Blocks.air);
		world.setBlock(i + 3, j + 2, k + 5, Blocks.air);
		world.setBlock(i + 3, j + 2, k + 6, Blocks.air);
		world.setBlock(i + 3, j + 2, k + 7, Blocks.air);
		world.setBlock(i + 3, j + 2, k + 8, Blocks.air);
		world.setBlock(i + 3, j + 2, k + 9, Blocks.air);
		world.setBlock(i + 3, j + 2, k + 10, Blocks.stonebrick);
		world.setBlock(i + 3, j + 3, k + 1, Blocks.stonebrick);
		world.setBlock(i + 3, j + 3, k + 2, Blocks.air);
		world.setBlock(i + 3, j + 3, k + 3, Blocks.air);
		world.setBlock(i + 3, j + 3, k + 4, Blocks.air);
		world.setBlock(i + 3, j + 3, k + 5, Blocks.air);
		world.setBlock(i + 3, j + 3, k + 6, Blocks.air);
		world.setBlock(i + 3, j + 3, k + 7, Blocks.air);
		world.setBlock(i + 3, j + 3, k + 8, Blocks.air);
		world.setBlock(i + 3, j + 3, k + 9, Blocks.air);
		world.setBlock(i + 3, j + 3, k + 10, Blocks.stonebrick);
		world.setBlock(i + 3, j + 4, k + 1, Blocks.stonebrick);
		world.setBlock(i + 3, j + 4, k + 2, Blocks.cobblestone);
		world.setBlock(i + 3, j + 4, k + 3, Blocks.cobblestone);
		world.setBlock(i + 3, j + 4, k + 4, Blocks.cobblestone);
		world.setBlock(i + 3, j + 4, k + 5, Blocks.cobblestone);
		world.setBlock(i + 3, j + 4, k + 6, Blocks.cobblestone);
		world.setBlock(i + 3, j + 4, k + 7, Blocks.cobblestone);
		world.setBlock(i + 3, j + 4, k + 8, Blocks.cobblestone);
		world.setBlock(i + 3, j + 4, k + 9, Blocks.cobblestone);
		world.setBlock(i + 3, j + 4, k + 10, Blocks.stonebrick);
		world.setBlock(i + 3, j + 5, k + 1, Blocks.stonebrick);
		world.setBlock(i + 3, j + 5, k + 2, Blocks.planks);
		world.setBlock(i + 3, j + 5, k + 3, Blocks.air);
		world.setBlock(i + 3, j + 5, k + 4, Blocks.air);
		world.setBlock(i + 3, j + 5, k + 5, Blocks.air);
		world.setBlock(i + 3, j + 5, k + 6, Blocks.stone_slab);
		world.setBlock(i + 3, j + 5, k + 7, Blocks.stone_slab);
		world.setBlock(i + 3, j + 5, k + 8, Blocks.stone_slab);
		world.setBlock(i + 3, j + 5, k + 9, Blocks.air);
		world.setBlock(i + 3, j + 5, k + 10, Blocks.stonebrick);
		world.setBlock(i + 3, j + 6, k + 1, Blocks.stonebrick);
		world.setBlock(i + 3, j + 6, k + 2, Blocks.air);
		world.setBlock(i + 3, j + 6, k + 3, Blocks.air);
		world.setBlock(i + 3, j + 6, k + 4, Blocks.air);
		world.setBlock(i + 3, j + 6, k + 5, Blocks.air);
		world.setBlock(i + 3, j + 6, k + 6, Blocks.air);
		world.setBlock(i + 3, j + 6, k + 7, Blocks.air);
		world.setBlock(i + 3, j + 6, k + 8, Blocks.air);
		world.setBlock(i + 3, j + 6, k + 9, Blocks.air);
		world.setBlock(i + 3, j + 6, k + 10, Blocks.stonebrick);
		world.setBlock(i + 3, j + 7, k + 1, Blocks.stonebrick);
		world.setBlock(i + 3, j + 7, k + 2, Blocks.air);
		world.setBlock(i + 3, j + 7, k + 3, Blocks.air);
		world.setBlock(i + 3, j + 7, k + 4, Blocks.air);
		world.setBlock(i + 3, j + 7, k + 5, Blocks.air);
		world.setBlock(i + 3, j + 7, k + 6, Blocks.air);
		world.setBlock(i + 3, j + 7, k + 7, Blocks.air);
		world.setBlock(i + 3, j + 7, k + 8, Blocks.air);
		world.setBlock(i + 3, j + 7, k + 9, Blocks.air);
		world.setBlock(i + 3, j + 7, k + 10, Blocks.stonebrick);
		world.setBlock(i + 3, j + 8, k + 1, Blocks.stonebrick);
		world.setBlock(i + 3, j + 8, k + 2, Blocks.cobblestone);
		world.setBlock(i + 3, j + 8, k + 3, Blocks.cobblestone);
		world.setBlock(i + 3, j + 8, k + 4, Blocks.cobblestone);
		world.setBlock(i + 3, j + 8, k + 5, Blocks.cobblestone);
		world.setBlock(i + 3, j + 8, k + 6, Blocks.cobblestone);
		world.setBlock(i + 3, j + 8, k + 7, Blocks.cobblestone);
		world.setBlock(i + 3, j + 8, k + 8, Blocks.cobblestone);
		world.setBlock(i + 3, j + 8, k + 9, Blocks.cobblestone);
		world.setBlock(i + 3, j + 8, k + 10, Blocks.stonebrick);
		world.setBlock(i + 3, j + 9, k + 1,
				Blocks.stone_slab, 3, 1 | (1<<1));
		world.setBlock(i + 3, j + 9, k + 3, Blocks.stonebrick);
		world.setBlock(i + 3, j + 9, k + 4, Blocks.air);
		world.setBlock(i + 3, j + 9, k + 5, Blocks.air);
		world.setBlock(i + 3, j + 9, k + 6, Blocks.air);
		world.setBlock(i + 3, j + 9, k + 7, Blocks.stonebrick);
		world.setBlock(i + 3, j + 9, k + 10, Blocks.stonebrick);
		world.setBlock(i + 3, j + 10, k + 3, Blocks.stonebrick);
		world.setBlock(i + 3, j + 10, k + 4, Blocks.air);
		world.setBlock(i + 3, j + 10, k + 6, Blocks.air);
		world.setBlock(i + 3, j + 10, k + 7, Blocks.stonebrick);
		world.setBlock(i + 3, j + 11, k + 3, Blocks.stonebrick);
		world.setBlock(i + 3, j + 11, k + 4, Blocks.air);
		world.setBlock(i + 3, j + 11, k + 5, Blocks.air);
		world.setBlock(i + 3, j + 11, k + 6, Blocks.air);
		world.setBlock(i + 3, j + 11, k + 7, Blocks.stonebrick);
		world.setBlock(i + 3, j + 12, k + 3, Blocks.stonebrick);
		world.setBlock(i + 3, j + 12, k + 4, Blocks.cobblestone);
		world.setBlock(i + 3, j + 12, k + 5, Blocks.cobblestone);
		world.setBlock(i + 3, j + 12, k + 6, Blocks.cobblestone);
		world.setBlock(i + 3, j + 12, k + 7, Blocks.stonebrick);
		world.setBlock(i + 3, j + 13, k + 3, Blocks.stonebrick);
		world.setBlock(i + 3, j + 13, k + 7, Blocks.stonebrick);
		world.setBlock(i + 4, j + 0, k + 0, Blocks.cobblestone);
		world.setBlock(i + 4, j + 0, k + 1, Blocks.cobblestone);
		world.setBlock(i + 4, j + 0, k + 2, Blocks.cobblestone);
		world.setBlock(i + 4, j + 0, k + 3, Blocks.cobblestone);
		world.setBlock(i + 4, j + 0, k + 4, Blocks.cobblestone);
		world.setBlock(i + 4, j + 0, k + 5, Blocks.cobblestone);
		world.setBlock(i + 4, j + 0, k + 6, Blocks.cobblestone);
		world.setBlock(i + 4, j + 0, k + 7, Blocks.cobblestone);
		world.setBlock(i + 4, j + 0, k + 8, Blocks.cobblestone);
		world.setBlock(i + 4, j + 0, k + 9, Blocks.cobblestone);
		world.setBlock(i + 4, j + 0, k + 10, Blocks.cobblestone);
		world.setBlock(i + 4, j + 0, k + 11, Blocks.cobblestone);
		world.setBlock(i + 4, j + 0, k + 12, Blocks.cobblestone);
		world.setBlock(i + 4, j + 0, k + 13, Blocks.cobblestone);
		world.setBlock(i + 4, j + 0, k + 14, Blocks.cobblestone);
		world.setBlock(i + 4, j + 0, k + 15, Blocks.cobblestone);
		world.setBlock(i + 4, j + 0, k + 16, Blocks.cobblestone);
		world.setBlock(i + 4, j + 0, k + 17, Blocks.cobblestone);
		world.setBlock(i + 4, j + 0, k + 18, Blocks.cobblestone);
		world.setBlock(i + 4, j + 0, k + 19, Blocks.cobblestone);
		world.setBlock(i + 4, j + 0, k + 20, Blocks.cobblestone);
		world.setBlock(i + 4, j + 0, k + 21, Blocks.cobblestone);
		world.setBlock(i + 4, j + 0, k + 22, Blocks.cobblestone);
		world.setBlock(i + 4, j + 0, k + 29, Blocks.cobblestone);
		world.setBlock(i + 4, j + 1, k + 0, Blocks.stonebrick);
		world.setBlock(i + 4, j + 1, k + 1, Blocks.air);
		world.setBlock(i + 4, j + 1, k + 2, Blocks.air);
		world.setBlock(i + 4, j + 1, k + 3, Blocks.air);
		world.setBlock(i + 4, j + 1, k + 4, Blocks.air);
		world.setBlock(i + 4, j + 1, k + 5, Blocks.air);
		world.setBlock(i + 4, j + 1, k + 6,
				Blocks.birch_stairs, 3, 1 | (1<<1));
		world.setBlock(i + 4, j + 1, k + 7, Blocks.cauldron);
		world.setBlock(i + 4, j + 1, k + 8, Blocks.air);
		world.setBlock(i + 4, j + 1, k + 9, Blocks.air);
		world.setBlock(i + 4, j + 1, k + 10, Blocks.air);
		world.setBlock(i + 4, j + 1, k + 11, Blocks.stonebrick);
		world.setBlock(i + 4, j + 1, k + 12, Blocks.stonebrick);
		world.setBlock(i + 4, j + 1, k + 13, Blocks.stonebrick);
		world.setBlock(i + 4, j + 1, k + 14, Blocks.stonebrick);
		world.setBlock(i + 4, j + 1, k + 15, Blocks.stonebrick);
		world.setBlock(i + 4, j + 1, k + 16, Blocks.stonebrick);
		world.setBlock(i + 4, j + 1, k + 17, Blocks.stonebrick);
		world.setBlock(i + 4, j + 1, k + 18, Blocks.stonebrick);
		world.setBlock(i + 4, j + 1, k + 19, Blocks.stonebrick);
		world.setBlock(i + 4, j + 1, k + 20, Blocks.stonebrick);
		world.setBlock(i + 4, j + 1, k + 21, Blocks.stonebrick);
		world.setBlock(i + 4, j + 1, k + 22, Blocks.stonebrick);
		world.setBlock(i + 4, j + 2, k + 0, Blocks.stonebrick);
		world.setBlock(i + 4, j + 2, k + 1, Blocks.air);
		world.setBlock(i + 4, j + 2, k + 2, Blocks.air);
		world.setBlock(i + 4, j + 2, k + 3, Blocks.air);
		world.setBlock(i + 4, j + 2, k + 4, Blocks.air);
		world.setBlock(i + 4, j + 2, k + 5, Blocks.air);
		world.setBlock(i + 4, j + 2, k + 6, Blocks.air);
		world.setBlock(i + 4, j + 2, k + 7, Blocks.air);
		world.setBlock(i + 4, j + 2, k + 8, Blocks.air);
		world.setBlock(i + 4, j + 2, k + 9, Blocks.air);
		world.setBlock(i + 4, j + 2, k + 10, Blocks.air);
		world.setBlock(i + 4, j + 2, k + 11, Blocks.stonebrick);
		world.setBlock(i + 4, j + 2, k + 12, Blocks.stonebrick);
		world.setBlock(i + 4, j + 2, k + 13, Blocks.stonebrick);
		world.setBlock(i + 4, j + 2, k + 14, Blocks.stonebrick);
		world.setBlock(i + 4, j + 2, k + 15, Blocks.stonebrick);
		world.setBlock(i + 4, j + 2, k + 16, Blocks.stonebrick);
		world.setBlock(i + 4, j + 2, k + 17, Blocks.stonebrick);
		world.setBlock(i + 4, j + 2, k + 18, Blocks.stonebrick);
		world.setBlock(i + 4, j + 2, k + 19, Blocks.stonebrick);
		world.setBlock(i + 4, j + 2, k + 20, Blocks.stonebrick);
		world.setBlock(i + 4, j + 2, k + 21, Blocks.stonebrick);
		world.setBlock(i + 4, j + 2, k + 22, Blocks.stonebrick);
		world.setBlock(i + 4, j + 3, k + 0, Blocks.stonebrick);
		world.setBlock(i + 4, j + 3, k + 1, Blocks.air);
		world.setBlock(i + 4, j + 3, k + 2, Blocks.air);
		world.setBlock(i + 4, j + 3, k + 3, Blocks.air);
		world.setBlock(i + 4, j + 3, k + 4, Blocks.air);
		world.setBlock(i + 4, j + 3, k + 5, Blocks.air);
		world.setBlock(i + 4, j + 3, k + 6, Blocks.air);
		world.setBlock(i + 4, j + 3, k + 7, Blocks.air);
		world.setBlock(i + 4, j + 3, k + 8, Blocks.air);
		world.setBlock(i + 4, j + 3, k + 9, Blocks.air);
		world.setBlock(i + 4, j + 3, k + 10, Blocks.air);
		world.setBlock(i + 4, j + 3, k + 11, Blocks.stonebrick);
		world.setBlock(i + 4, j + 3, k + 12, Blocks.stonebrick);
		world.setBlock(i + 4, j + 3, k + 13, Blocks.stonebrick);
		world.setBlock(i + 4, j + 3, k + 14, Blocks.stonebrick);
		world.setBlock(i + 4, j + 3, k + 15, Blocks.stonebrick);
		world.setBlock(i + 4, j + 3, k + 16, Blocks.stonebrick);
		world.setBlock(i + 4, j + 3, k + 17, Blocks.stonebrick);
		world.setBlock(i + 4, j + 3, k + 18, Blocks.stonebrick);
		world.setBlock(i + 4, j + 3, k + 19, Blocks.stonebrick);
		world.setBlock(i + 4, j + 3, k + 20, Blocks.stonebrick);
		world.setBlock(i + 4, j + 3, k + 21, Blocks.stonebrick);
		world.setBlock(i + 4, j + 3, k + 22, Blocks.stonebrick);
		world.setBlock(i + 4, j + 4, k + 0, Blocks.stonebrick);
		world.setBlock(i + 4, j + 4, k + 1, Blocks.cobblestone);
		world.setBlock(i + 4, j + 4, k + 2, Blocks.cobblestone);
		world.setBlock(i + 4, j + 4, k + 3, Blocks.cobblestone);
		world.setBlock(i + 4, j + 4, k + 4, Blocks.cobblestone);
		world.setBlock(i + 4, j + 4, k + 5, Blocks.cobblestone);
		world.setBlock(i + 4, j + 4, k + 6, Blocks.cobblestone);
		world.setBlock(i + 4, j + 4, k + 7, Blocks.air);
		world.setBlock(i + 4, j + 4, k + 8, Blocks.cobblestone);
		world.setBlock(i + 4, j + 4, k + 9, Blocks.cobblestone);
		world.setBlock(i + 4, j + 4, k + 10, Blocks.cobblestone);
		world.setBlock(i + 4, j + 4, k + 11, Blocks.stonebrick);
		world.setBlock(i + 4, j + 4, k + 12, Blocks.stonebrick);
		world.setBlock(i + 4, j + 4, k + 13, Blocks.stonebrick);
		world.setBlock(i + 4, j + 4, k + 14, Blocks.stonebrick);
		world.setBlock(i + 4, j + 4, k + 15, Blocks.stonebrick);
		world.setBlock(i + 4, j + 4, k + 16, Blocks.stonebrick);
		world.setBlock(i + 4, j + 4, k + 17, Blocks.stonebrick);
		world.setBlock(i + 4, j + 4, k + 18, Blocks.stonebrick);
		world.setBlock(i + 4, j + 4, k + 19, Blocks.stonebrick);
		world.setBlock(i + 4, j + 4, k + 20, Blocks.stonebrick);
		world.setBlock(i + 4, j + 4, k + 21, Blocks.stonebrick);
		world.setBlock(i + 4, j + 4, k + 22, Blocks.stonebrick);
		world.setBlock(i + 4, j + 5, k + 0, Blocks.stonebrick);
		world.setBlock(i + 4, j + 5, k + 1, Blocks.bookshelf);
		world.setBlock(i + 4, j + 5, k + 2, Blocks.air);
		world.setBlock(i + 4, j + 5, k + 3, Blocks.air);
		world.setBlock(i + 4, j + 5, k + 4, Blocks.air);
		world.setBlock(i + 4, j + 5, k + 5, Blocks.air);
		world.setBlock(i + 4, j + 5, k + 6, Blocks.stone_slab);
		world.setBlock(i + 4, j + 5, k + 7, Blocks.air);
		world.setBlock(i + 4, j + 5, k + 8, Blocks.stone_slab);
		world.setBlock(i + 4, j + 5, k + 9, Blocks.air);
		world.setBlock(i + 4, j + 5, k + 10, Blocks.air);
		world.setBlock(i + 4, j + 5, k + 11, Blocks.stonebrick);
		world.setBlock(i + 4, j + 5, k + 12, Blocks.stonebrick);
		world.setBlock(i + 4, j + 5, k + 13, Blocks.stonebrick);
		world.setBlock(i + 4, j + 5, k + 14, Blocks.stonebrick);
		world.setBlock(i + 4, j + 5, k + 15, Blocks.stonebrick);
		world.setBlock(i + 4, j + 5, k + 16, Blocks.stonebrick);
		world.setBlock(i + 4, j + 5, k + 17, Blocks.stonebrick);
		world.setBlock(i + 4, j + 5, k + 18, Blocks.stonebrick);
		world.setBlock(i + 4, j + 5, k + 19, Blocks.stonebrick);
		world.setBlock(i + 4, j + 5, k + 20, Blocks.stonebrick);
		world.setBlock(i + 4, j + 5, k + 21, Blocks.stonebrick);
		world.setBlock(i + 4, j + 5, k + 22, Blocks.stonebrick);
		world.setBlock(i + 4, j + 6, k + 0, Blocks.stonebrick);
		world.setBlock(i + 4, j + 6, k + 1, Blocks.bookshelf);
		world.setBlock(i + 4, j + 6, k + 2, Blocks.air);
		world.setBlock(i + 4, j + 6, k + 3, Blocks.air);
		world.setBlock(i + 4, j + 6, k + 4, Blocks.air);
		world.setBlock(i + 4, j + 6, k + 5, Blocks.air);
		world.setBlock(i + 4, j + 6, k + 6, Blocks.air);
		world.setBlock(i + 4, j + 6, k + 7, Blocks.air);
		world.setBlock(i + 4, j + 6, k + 8, Blocks.air);
		world.setBlock(i + 4, j + 6, k + 9, Blocks.air);
		world.setBlock(i + 4, j + 6, k + 10, Blocks.air);
		world.setBlock(i + 4, j + 6, k + 11, Blocks.stonebrick);
		world.setBlock(i + 4, j + 6, k + 14,
				Blocks.stone_slab, 3, 1 | (1<<1));
		world.setBlock(i + 4, j + 6, k + 16,
				Blocks.stone_slab, 3, 1 | (1<<1));
		world.setBlock(i + 4, j + 6, k + 18,
				Blocks.stone_slab, 3, 1 | (1<<1));
		world.setBlock(i + 4, j + 6, k + 20,
				Blocks.stone_slab, 3, 1 | (1<<1));
		world.setBlock(i + 4, j + 6, k + 22,
				Blocks.stone_slab, 3, 1 | (1<<1));
		world.setBlock(i + 4, j + 7, k + 0, Blocks.stonebrick);
		world.setBlock(i + 4, j + 7, k + 1, Blocks.air);
		world.setBlock(i + 4, j + 7, k + 2, Blocks.air);
		world.setBlock(i + 4, j + 7, k + 3, Blocks.air);
		world.setBlock(i + 4, j + 7, k + 4, Blocks.air);
		world.setBlock(i + 4, j + 7, k + 5, Blocks.air);
		world.setBlock(i + 4, j + 7, k + 6, Blocks.air);
		world.setBlock(i + 4, j + 7, k + 7, Blocks.air);
		world.setBlock(i + 4, j + 7, k + 8, Blocks.air);
		world.setBlock(i + 4, j + 7, k + 9, Blocks.air);
		world.setBlock(i + 4, j + 7, k + 10, Blocks.air);
		world.setBlock(i + 4, j + 7, k + 11, Blocks.stonebrick);
		world.setBlock(i + 4, j + 8, k + 0, Blocks.stonebrick);
		world.setBlock(i + 4, j + 8, k + 1, Blocks.cobblestone);
		world.setBlock(i + 4, j + 8, k + 2, Blocks.cobblestone);
		world.setBlock(i + 4, j + 8, k + 3, Blocks.cobblestone);
		world.setBlock(i + 4, j + 8, k + 4, Blocks.cobblestone);
		world.setBlock(i + 4, j + 8, k + 5, Blocks.cobblestone);
		world.setBlock(i + 4, j + 8, k + 6, Blocks.cobblestone);
		world.setBlock(i + 4, j + 8, k + 7, Blocks.cobblestone);
		world.setBlock(i + 4, j + 8, k + 8, Blocks.cobblestone);
		world.setBlock(i + 4, j + 8, k + 9, Blocks.cobblestone);
		world.setBlock(i + 4, j + 8, k + 10, Blocks.cobblestone);
		world.setBlock(i + 4, j + 8, k + 11, Blocks.stonebrick);
		world.setBlock(i + 4, j + 9, k + 0, Blocks.stonebrick);
		world.setBlock(i + 4, j + 9, k + 2, Blocks.stonebrick);
		world.setBlock(i + 4, j + 9, k + 3, Blocks.air);
		world.setBlock(i + 4, j + 9, k + 4, Blocks.air);
		world.setBlock(i + 4, j + 9, k + 5, Blocks.air);
		world.setBlock(i + 4, j + 9, k + 6, Blocks.air);
		world.setBlock(i + 4, j + 9, k + 7, Blocks.air);
		world.setBlock(i + 4, j + 9, k + 8, Blocks.stonebrick);
		world.setBlock(i + 4, j + 9, k + 11,
				Blocks.stone_slab, 3, 1 | (1<<1));
		world.setBlock(i + 4, j + 10, k + 2, Blocks.stonebrick);
		world.setBlock(i + 4, j + 10, k + 3, Blocks.air);
		world.setBlock(i + 4, j + 10, k + 4,
				Blocks.stone_slab, 13, 1 | (1<<1));
		world.setBlock(i + 4, j + 10, k + 5, Blocks.air);
		world.setBlock(i + 4, j + 10, k + 6, Blocks.air);
		world.setBlock(i + 4, j + 10, k + 7, Blocks.air);
		world.setBlock(i + 4, j + 10, k + 8, Blocks.stonebrick);
		world.setBlock(i + 4, j + 11, k + 2, Blocks.stonebrick);
		world.setBlock(i + 4, j + 11, k + 3, Blocks.air);
		world.setBlock(i + 4, j + 11, k + 4, Blocks.air);
		world.setBlock(i + 4, j + 11, k + 5,
				Blocks.stone_brick_stairs, 2, 1 | (1<<1));
		world.setBlock(i + 4, j + 11, k + 6,
				Blocks.stone_slab, 13, 1 | (1<<1));
		world.setBlock(i + 4, j + 11, k + 7, Blocks.air);
		world.setBlock(i + 4, j + 11, k + 8, Blocks.stonebrick);
		world.setBlock(i + 4, j + 12, k + 2, Blocks.stonebrick);
		world.setBlock(i + 4, j + 12, k + 3, Blocks.cobblestone);
		world.setBlock(i + 4, j + 12, k + 4, Blocks.air);
		world.setBlock(i + 4, j + 12, k + 5, Blocks.air);
		world.setBlock(i + 4, j + 12, k + 6, Blocks.air);
		world.setBlock(i + 4, j + 12, k + 7, Blocks.cobblestone);
		world.setBlock(i + 4, j + 12, k + 8, Blocks.stonebrick);
		world.setBlock(i + 4, j + 13, k + 2,
				Blocks.stone_slab, 3, 1 | (1<<1));
		world.setBlock(i + 4, j + 13, k + 8,
				Blocks.stone_slab, 3, 1 | (1<<1));
		world.setBlock(i + 5, j + 0, k + 0, Blocks.cobblestone);
		world.setBlock(i + 5, j + 0, k + 1, Blocks.cobblestone);
		world.setBlock(i + 5, j + 0, k + 2, Blocks.cobblestone);
		world.setBlock(i + 5, j + 0, k + 3, Blocks.cobblestone);
		world.setBlock(i + 5, j + 0, k + 4, Blocks.cobblestone);
		world.setBlock(i + 5, j + 0, k + 5, Blocks.cobblestone);
		world.setBlock(i + 5, j + 0, k + 6, Blocks.cobblestone);
		world.setBlock(i + 5, j + 0, k + 7, Blocks.cobblestone);
		world.setBlock(i + 5, j + 0, k + 8, Blocks.cobblestone);
		world.setBlock(i + 5, j + 0, k + 9, Blocks.cobblestone);
		world.setBlock(i + 5, j + 0, k + 10, Blocks.cobblestone);
		world.setBlock(i + 5, j + 0, k + 11, Blocks.cobblestone);
		world.setBlock(i + 5, j + 0, k + 12, Blocks.cobblestone);
		world.setBlock(i + 5, j + 0, k + 13, Blocks.cobblestone);
		world.setBlock(i + 5, j + 0, k + 14, Blocks.cobblestone);
		world.setBlock(i + 5, j + 0, k + 15, Blocks.cobblestone);
		world.setBlock(i + 5, j + 0, k + 16, Blocks.cobblestone);
		world.setBlock(i + 5, j + 0, k + 17, Blocks.cobblestone);
		world.setBlock(i + 5, j + 0, k + 18, Blocks.cobblestone);
		world.setBlock(i + 5, j + 0, k + 19, Blocks.netherrack);
		world.setBlock(i + 5, j + 0, k + 20, Blocks.netherrack);
		world.setBlock(i + 5, j + 0, k + 21, Blocks.cobblestone);
		world.setBlock(i + 5, j + 0, k + 22, Blocks.cobblestone);
		world.setBlock(i + 5, j + 0, k + 23, Blocks.cobblestone);
		world.setBlock(i + 5, j + 0, k + 29, Blocks.cobblestone);
		world.setBlock(i + 5, j + 1, k + 0, Blocks.stonebrick);
		world.setBlock(i + 5, j + 1, k + 1, Blocks.air);
		world.setBlock(i + 5, j + 1, k + 2, Blocks.air);
		world.setBlock(i + 5, j + 1, k + 3, Blocks.air);
		world.setBlock(i + 5, j + 1, k + 4, Blocks.air);
		world.setBlock(i + 5, j + 1, k + 5, Blocks.air);
		world.setBlock(i + 5, j + 1, k + 6, Blocks.air);
		world.setBlock(i + 5, j + 1, k + 7, Blocks.air);
		world.setBlock(i + 5, j + 1, k + 8, Blocks.air);
		world.setBlock(i + 5, j + 1, k + 9, Blocks.air);
		world.setBlock(i + 5, j + 1, k + 10, Blocks.air);
		world.setBlock(i + 5, j + 1, k + 11, Blocks.air);
		world.setBlock(i + 5, j + 1, k + 12, Blocks.air);
		world.setBlock(i + 5, j + 1, k + 13, Blocks.stonebrick);
		world.setBlock(i + 5, j + 1, k + 14, Blocks.air);
		world.setBlock(i + 5, j + 1, k + 15, Blocks.air);
		world.setBlock(i + 5, j + 1, k + 16, Blocks.air);
		world.setBlock(i + 5, j + 1, k + 17, Blocks.air);
		world.setBlock(i + 5, j + 1, k + 18, Blocks.cobblestone);
		world.setBlock(i + 5, j + 1, k + 19, Blocks.fire, 15, 1 | (1<<1));
		world.setBlock(i + 5, j + 1, k + 20, Blocks.fire, 15, 1 | (1<<1));
		world.setBlock(i + 5, j + 1, k + 21, Blocks.cobblestone);
		world.setBlock(i + 5, j + 1, k + 22, Blocks.air);
		world.setBlock(i + 5, j + 1, k + 23, Blocks.stonebrick);
		world.setBlock(i + 5, j + 2, k + 0, Blocks.stonebrick);
		world.setBlock(i + 5, j + 2, k + 1, Blocks.air);
		world.setBlock(i + 5, j + 2, k + 2, Blocks.air);
		world.setBlock(i + 5, j + 2, k + 3, Blocks.air);
		world.setBlock(i + 5, j + 2, k + 4, Blocks.air);
		world.setBlock(i + 5, j + 2, k + 5, Blocks.air);
		world.setBlock(i + 5, j + 2, k + 6, Blocks.air);
		world.setBlock(i + 5, j + 2, k + 7, Blocks.air);
		world.setBlock(i + 5, j + 2, k + 8, Blocks.air);
		world.setBlock(i + 5, j + 2, k + 9, Blocks.air);
		world.setBlock(i + 5, j + 2, k + 10, Blocks.air);
		world.setBlock(i + 5, j + 2, k + 11, Blocks.air);
		world.setBlock(i + 5, j + 2, k + 12, Blocks.air);
		world.setBlock(i + 5, j + 2, k + 13, Blocks.stonebrick);
		world.setBlock(i + 5, j + 2, k + 14, Blocks.air);
		world.setBlock(i + 5, j + 2, k + 15, Blocks.air);
		world.setBlock(i + 5, j + 2, k + 17, Blocks.air);
		world.setBlock(i + 5, j + 2, k + 18, Blocks.cobblestone);
		world.setBlock(i + 5, j + 2, k + 19, Blocks.cobblestone);
		world.setBlock(i + 5, j + 2, k + 20, Blocks.cobblestone);
		world.setBlock(i + 5, j + 2, k + 21, Blocks.cobblestone);
		world.setBlock(i + 5, j + 2, k + 22, Blocks.air);
		world.setBlock(i + 5, j + 2, k + 23, Blocks.stonebrick);
		world.setBlock(i + 5, j + 3, k + 0, Blocks.stonebrick);
		world.setBlock(i + 5, j + 3, k + 1, Blocks.air);
		world.setBlock(i + 5, j + 3, k + 2, Blocks.air);
		world.setBlock(i + 5, j + 3, k + 3, Blocks.air);
		world.setBlock(i + 5, j + 3, k + 4, Blocks.air);
		world.setBlock(i + 5, j + 3, k + 5, Blocks.air);
		world.setBlock(i + 5, j + 3, k + 6, Blocks.air);
		world.setBlock(i + 5, j + 3, k + 7, Blocks.air);
		world.setBlock(i + 5, j + 3, k + 8, Blocks.air);
		world.setBlock(i + 5, j + 3, k + 9, Blocks.air);
		world.setBlock(i + 5, j + 3, k + 10, Blocks.air);
		world.setBlock(i + 5, j + 3, k + 11, Blocks.air);
		world.setBlock(i + 5, j + 3, k + 12, Blocks.air);
		world.setBlock(i + 5, j + 3, k + 13, Blocks.stonebrick);
		world.setBlock(i + 5, j + 3, k + 14, Blocks.air);
		world.setBlock(i + 5, j + 3, k + 15, Blocks.air);
		world.setBlock(i + 5, j + 3, k + 16, Blocks.air);
		world.setBlock(i + 5, j + 3, k + 17, Blocks.air);
		world.setBlock(i + 5, j + 3, k + 18, Blocks.air);
		world.setBlock(i + 5, j + 3, k + 19, Blocks.air);
		world.setBlock(i + 5, j + 3, k + 20, Blocks.air);
		world.setBlock(i + 5, j + 3, k + 21, Blocks.air);
		world.setBlock(i + 5, j + 3, k + 22, Blocks.air);
		world.setBlock(i + 5, j + 3, k + 23, Blocks.stonebrick);
		world.setBlock(i + 5, j + 4, k + 0, Blocks.stonebrick);
		world.setBlock(i + 5, j + 4, k + 1, Blocks.cobblestone);
		world.setBlock(i + 5, j + 4, k + 2, Blocks.cobblestone);
		world.setBlock(i + 5, j + 4, k + 3, Blocks.cobblestone);
		world.setBlock(i + 5, j + 4, k + 4, Blocks.cobblestone);
		world.setBlock(i + 5, j + 4, k + 5, Blocks.cobblestone);
		world.setBlock(i + 5, j + 4, k + 6, Blocks.cobblestone);
		world.setBlock(i + 5, j + 4, k + 7, Blocks.cobblestone);
		world.setBlock(i + 5, j + 4, k + 8, Blocks.cobblestone);
		world.setBlock(i + 5, j + 4, k + 9, Blocks.cobblestone);
		world.setBlock(i + 5, j + 4, k + 10, Blocks.cobblestone);
		world.setBlock(i + 5, j + 4, k + 11, Blocks.cobblestone);
		world.setBlock(i + 5, j + 4, k + 12, Blocks.cobblestone);
		world.setBlock(i + 5, j + 4, k + 13, Blocks.stonebrick);
		world.setBlock(i + 5, j + 4, k + 14, Blocks.cobblestone);
		world.setBlock(i + 5, j + 4, k + 15, Blocks.cobblestone);
		world.setBlock(i + 5, j + 4, k + 16, Blocks.cobblestone);
		world.setBlock(i + 5, j + 4, k + 17, Blocks.cobblestone);
		world.setBlock(i + 5, j + 4, k + 18, Blocks.cobblestone);
		world.setBlock(i + 5, j + 4, k + 19, Blocks.cobblestone);
		world.setBlock(i + 5, j + 4, k + 20, Blocks.cobblestone);
		world.setBlock(i + 5, j + 4, k + 21, Blocks.cobblestone);
		world.setBlock(i + 5, j + 4, k + 22, Blocks.cobblestone);
		world.setBlock(i + 5, j + 4, k + 23, Blocks.stonebrick);
		world.setBlock(i + 5, j + 5, k + 0, Blocks.stonebrick);
		world.setBlock(i + 5, j + 5, k + 1, Blocks.bookshelf);
		world.setBlock(i + 5, j + 5, k + 2, Blocks.air);
		world.setBlock(i + 5, j + 5, k + 3, Blocks.air);
		world.setBlock(i + 5, j + 5, k + 4, Blocks.air);
		world.setBlock(i + 5, j + 5, k + 5, Blocks.air);
		world.setBlock(i + 5, j + 5, k + 6, Blocks.stone_slab);
		world.setBlock(i + 5, j + 5, k + 7, Blocks.stone_slab);
		world.setBlock(i + 5, j + 5, k + 8, Blocks.stone_slab);
		world.setBlock(i + 5, j + 5, k + 9, Blocks.air);
		world.setBlock(i + 5, j + 5, k + 10, Blocks.air);
		world.setBlock(i + 5, j + 5, k + 12, Blocks.air);
		world.setBlock(i + 5, j + 5, k + 13, Blocks.air);
		world.setBlock(i + 5, j + 5, k + 14, Blocks.air);
		world.setBlock(i + 5, j + 5, k + 15, Blocks.air);
		world.setBlock(i + 5, j + 5, k + 16, Blocks.air);
		world.setBlock(i + 5, j + 5, k + 17, Blocks.air);
		world.setBlock(i + 5, j + 5, k + 18, Blocks.air);
		world.setBlock(i + 5, j + 5, k + 19, Blocks.air);
		world.setBlock(i + 5, j + 5, k + 20, Blocks.air);
		world.setBlock(i + 5, j + 5, k + 21, Blocks.air);
		world.setBlock(i + 5, j + 5, k + 22, Blocks.air);
		world.setBlock(i + 5, j + 5, k + 23, Blocks.stonebrick);
		world.setBlock(i + 5, j + 6, k + 0, Blocks.stonebrick);
		world.setBlock(i + 5, j + 6, k + 1, Blocks.bookshelf);
		world.setBlock(i + 5, j + 6, k + 2, Blocks.air);
		world.setBlock(i + 5, j + 6, k + 3, Blocks.air);
		world.setBlock(i + 5, j + 6, k + 4, Blocks.air);
		world.setBlock(i + 5, j + 6, k + 5, Blocks.air);
		world.setBlock(i + 5, j + 6, k + 6, Blocks.air);
		world.setBlock(i + 5, j + 6, k + 7, Blocks.air);
		world.setBlock(i + 5, j + 6, k + 8, Blocks.air);
		world.setBlock(i + 5, j + 6, k + 9, Blocks.air);
		world.setBlock(i + 5, j + 6, k + 10, Blocks.air);
		world.setBlock(i + 5, j + 7, k + 0, Blocks.stonebrick);
		world.setBlock(i + 5, j + 7, k + 1, Blocks.air);
		world.setBlock(i + 5, j + 7, k + 2, Blocks.air);
		world.setBlock(i + 5, j + 7, k + 3, Blocks.air);
		world.setBlock(i + 5, j + 7, k + 4, Blocks.air);
		world.setBlock(i + 5, j + 7, k + 5, Blocks.air);
		world.setBlock(i + 5, j + 7, k + 6, Blocks.air);
		world.setBlock(i + 5, j + 7, k + 7, Blocks.air);
		world.setBlock(i + 5, j + 7, k + 8, Blocks.air);
		world.setBlock(i + 5, j + 7, k + 9, Blocks.air);
		world.setBlock(i + 5, j + 7, k + 10, Blocks.air);
		world.setBlock(i + 5, j + 7, k + 11, Blocks.stonebrick);
		world.setBlock(i + 5, j + 8, k + 0, Blocks.stonebrick);
		world.setBlock(i + 5, j + 8, k + 1, Blocks.cobblestone);
		world.setBlock(i + 5, j + 8, k + 2, Blocks.cobblestone);
		world.setBlock(i + 5, j + 8, k + 3, Blocks.cobblestone);
		world.setBlock(i + 5, j + 8, k + 4, Blocks.cobblestone);
		world.setBlock(i + 5, j + 8, k + 5, Blocks.cobblestone);
		world.setBlock(i + 5, j + 8, k + 6, Blocks.cobblestone);
		world.setBlock(i + 5, j + 8, k + 7, Blocks.cobblestone);
		world.setBlock(i + 5, j + 8, k + 8, Blocks.cobblestone);
		world.setBlock(i + 5, j + 8, k + 9, Blocks.cobblestone);
		world.setBlock(i + 5, j + 8, k + 10, Blocks.cobblestone);
		world.setBlock(i + 5, j + 8, k + 11, Blocks.stonebrick);
		world.setBlock(i + 5, j + 9, k + 0,
				Blocks.stone_slab, 3, 1 | (1<<1));
		world.setBlock(i + 5, j + 9, k + 2, Blocks.stonebrick);
		world.setBlock(i + 5, j + 9, k + 3, Blocks.air);
		world.setBlock(i + 5, j + 9, k + 4, Blocks.air);
		world.setBlock(i + 5, j + 9, k + 5, Blocks.cobblestone);
		world.setBlock(i + 5, j + 9, k + 6, Blocks.air);
		world.setBlock(i + 5, j + 9, k + 7, Blocks.air);
		world.setBlock(i + 5, j + 9, k + 8, Blocks.stonebrick);
		world.setBlock(i + 5, j + 9, k + 11, Blocks.stonebrick);
		world.setBlock(i + 5, j + 10, k + 2, Blocks.stonebrick);
		world.setBlock(i + 5, j + 10, k + 3, Blocks.air);
		world.setBlock(i + 5, j + 10, k + 4,
				Blocks.stone_brick_stairs, 1, 1 | (1<<1));
		world.setBlock(i + 5, j + 10, k + 5, Blocks.cobblestone);
		world.setBlock(i + 5, j + 10, k + 6, Blocks.air);
		world.setBlock(i + 5, j + 10, k + 7, Blocks.air);
		world.setBlock(i + 5, j + 10, k + 8, Blocks.stonebrick);
		world.setBlock(i + 5, j + 11, k + 2, Blocks.stonebrick);
		world.setBlock(i + 5, j + 11, k + 3, Blocks.air);
		world.setBlock(i + 5, j + 11, k + 4, Blocks.air);
		world.setBlock(i + 5, j + 11, k + 5, Blocks.cobblestone);
		world.setBlock(i + 5, j + 11, k + 6, Blocks.air);
		world.setBlock(i + 5, j + 11, k + 7, Blocks.air);
		world.setBlock(i + 5, j + 11, k + 8, Blocks.stonebrick);
		world.setBlock(i + 5, j + 12, k + 2, Blocks.stonebrick);
		world.setBlock(i + 5, j + 12, k + 3, Blocks.cobblestone);
		world.setBlock(i + 5, j + 12, k + 4, Blocks.air);
		world.setBlock(i + 5, j + 12, k + 5, Blocks.cobblestone);
		world.setBlock(i + 5, j + 12, k + 6,
				Blocks.stone_brick_stairs);
		world.setBlock(i + 5, j + 12, k + 7, Blocks.cobblestone);
		world.setBlock(i + 5, j + 12, k + 8, Blocks.stonebrick);
		world.setBlock(i + 5, j + 13, k + 2, Blocks.stonebrick);
		world.setBlock(i + 5, j + 13, k + 8, Blocks.stonebrick);
		world.setBlock(i + 6, j + 0, k + 0, Blocks.cobblestone);
		world.setBlock(i + 6, j + 0, k + 1, Blocks.cobblestone);
		world.setBlock(i + 6, j + 0, k + 2, Blocks.cobblestone);
		world.setBlock(i + 6, j + 0, k + 3, Blocks.cobblestone);
		world.setBlock(i + 6, j + 0, k + 4, Blocks.cobblestone);
		world.setBlock(i + 6, j + 0, k + 5, Blocks.cobblestone);
		world.setBlock(i + 6, j + 0, k + 6, Blocks.cobblestone);
		world.setBlock(i + 6, j + 0, k + 7, Blocks.cobblestone);
		world.setBlock(i + 6, j + 0, k + 8, Blocks.cobblestone);
		world.setBlock(i + 6, j + 0, k + 9, Blocks.cobblestone);
		world.setBlock(i + 6, j + 0, k + 10, Blocks.cobblestone);
		world.setBlock(i + 6, j + 0, k + 11, Blocks.cobblestone);
		world.setBlock(i + 6, j + 0, k + 12, Blocks.cobblestone);
		world.setBlock(i + 6, j + 0, k + 13, Blocks.cobblestone);
		world.setBlock(i + 6, j + 0, k + 14, Blocks.cobblestone);
		world.setBlock(i + 6, j + 0, k + 15, Blocks.cobblestone);
		world.setBlock(i + 6, j + 0, k + 16, Blocks.cobblestone);
		world.setBlock(i + 6, j + 0, k + 17, Blocks.cobblestone);
		world.setBlock(i + 6, j + 0, k + 18, Blocks.cobblestone);
		world.setBlock(i + 6, j + 0, k + 19, Blocks.cobblestone);
		world.setBlock(i + 6, j + 0, k + 20, Blocks.cobblestone);
		world.setBlock(i + 6, j + 0, k + 21, Blocks.cobblestone);
		world.setBlock(i + 6, j + 0, k + 22, Blocks.cobblestone);
		world.setBlock(i + 6, j + 0, k + 23, Blocks.cobblestone);
		world.setBlock(i + 6, j + 0, k + 24, Blocks.cobblestone);
		world.setBlock(i + 6, j + 0, k + 25, Blocks.cobblestone);
		world.setBlock(i + 6, j + 1, k + 0, Blocks.stonebrick);
		world.setBlock(i + 6, j + 1, k + 1, Blocks.air);
		world.setBlock(i + 6, j + 1, k + 2, Blocks.air);
		world.setBlock(i + 6, j + 1, k + 3, Blocks.air);
		world.setBlock(i + 6, j + 1, k + 4, Blocks.air);
		world.setBlock(i + 6, j + 1, k + 5, Blocks.mob_spawner);
        TileEntityMobSpawner var19 = (TileEntityMobSpawner)world.getTileEntity(i + 6, j + 1, k + 5);

        if (var19 != null)
        {
            var19.func_145881_a().setEntityName("Black Knight");
        }
		world.setBlock(i + 6, j + 1, k + 6, Blocks.air);
		world.setBlock(i + 6, j + 1, k + 7, Blocks.air);
		world.setBlock(i + 6, j + 1, k + 8, Blocks.air);
		world.setBlock(i + 6, j + 1, k + 9, Blocks.air);
		world.setBlock(i + 6, j + 1, k + 10, Blocks.air);
		world.setBlock(i + 6, j + 1, k + 11, Blocks.air);
		world.setBlock(i + 6, j + 1, k + 12, Blocks.air);
		world.setBlock(i + 6, j + 1, k + 14, Blocks.air);
		world.setBlock(i + 6, j + 1, k + 15, Blocks.air);
		world.setBlock(i + 6, j + 1, k + 16, Blocks.air);
		world.setBlock(i + 6, j + 1, k + 17, Blocks.air);
		world.setBlock(i + 6, j + 1, k + 18, Blocks.cobblestone);
		world.setBlock(i + 6, j + 1, k + 19, Blocks.glass_pane);
		world.setBlock(i + 6, j + 1, k + 20, Blocks.glass_pane);
		world.setBlock(i + 6, j + 1, k + 21, Blocks.cobblestone);
		world.setBlock(i + 6, j + 1, k + 22, Blocks.air);
		world.setBlock(i + 6, j + 1, k + 23, Blocks.air);
		world.setBlock(i + 6, j + 1, k + 24, Blocks.stonebrick);
		world.setBlock(i + 6, j + 2, k + 0, Blocks.stonebrick);
		world.setBlock(i + 6, j + 2, k + 2, Blocks.air);
		world.setBlock(i + 6, j + 2, k + 3, Blocks.air);
		world.setBlock(i + 6, j + 2, k + 4, Blocks.air);
		world.setBlock(i + 6, j + 2, k + 5, Blocks.air);
		world.setBlock(i + 6, j + 2, k + 6, Blocks.air);
		world.setBlock(i + 6, j + 2, k + 7, Blocks.air);
		world.setBlock(i + 6, j + 2, k + 8, Blocks.air);
		world.setBlock(i + 6, j + 2, k + 9, Blocks.air);
		world.setBlock(i + 6, j + 2, k + 10, Blocks.air);
		world.setBlock(i + 6, j + 2, k + 11, Blocks.air);
		world.setBlock(i + 6, j + 2, k + 12, Blocks.air);
		world.setBlock(i + 6, j + 2, k + 14, Blocks.air);
		world.setBlock(i + 6, j + 2, k + 15, Blocks.air);
		world.setBlock(i + 6, j + 2, k + 16, Blocks.air);
		world.setBlock(i + 6, j + 2, k + 17, Blocks.air);
		world.setBlock(i + 6, j + 2, k + 18, Blocks.cobblestone);
		world.setBlock(i + 6, j + 2, k + 19, Blocks.cobblestone);
		world.setBlock(i + 6, j + 2, k + 20, Blocks.cobblestone);
		world.setBlock(i + 6, j + 2, k + 21, Blocks.cobblestone);
		world.setBlock(i + 6, j + 2, k + 22, Blocks.air);
		world.setBlock(i + 6, j + 2, k + 23, Blocks.air);
		world.setBlock(i + 6, j + 2, k + 24, Blocks.stonebrick);
		world.setBlock(i + 6, j + 3, k + 0, Blocks.stonebrick);
		world.setBlock(i + 6, j + 3, k + 1, Blocks.air);
		world.setBlock(i + 6, j + 3, k + 2, Blocks.air);
		world.setBlock(i + 6, j + 3, k + 3, Blocks.air);
		world.setBlock(i + 6, j + 3, k + 4, Blocks.air);
		world.setBlock(i + 6, j + 3, k + 5, Blocks.air);
		world.setBlock(i + 6, j + 3, k + 6, Blocks.air);
		world.setBlock(i + 6, j + 3, k + 7, Blocks.air);
		world.setBlock(i + 6, j + 3, k + 8, Blocks.air);
		world.setBlock(i + 6, j + 3, k + 9, Blocks.air);
		world.setBlock(i + 6, j + 3, k + 10, Blocks.air);
		world.setBlock(i + 6, j + 3, k + 11, Blocks.air);
		world.setBlock(i + 6, j + 3, k + 12, Blocks.air);
		world.setBlock(i + 6, j + 3, k + 13, Blocks.stonebrick);
		world.setBlock(i + 6, j + 3, k + 14, Blocks.air);
		world.setBlock(i + 6, j + 3, k + 15, Blocks.air);
		world.setBlock(i + 6, j + 3, k + 16, Blocks.air);
		world.setBlock(i + 6, j + 3, k + 17, Blocks.air);
		world.setBlock(i + 6, j + 3, k + 18, Blocks.air);
		world.setBlock(i + 6, j + 3, k + 19, Blocks.air);
		world.setBlock(i + 6, j + 3, k + 20, Blocks.air);
		world.setBlock(i + 6, j + 3, k + 21, Blocks.air);
		world.setBlock(i + 6, j + 3, k + 22, Blocks.air);
		world.setBlock(i + 6, j + 3, k + 23, Blocks.air);
		world.setBlock(i + 6, j + 3, k + 24, Blocks.stonebrick);
		world.setBlock(i + 6, j + 4, k + 0, Blocks.stonebrick);
		world.setBlock(i + 6, j + 4, k + 1, Blocks.cobblestone);
		world.setBlock(i + 6, j + 4, k + 2, Blocks.cobblestone);
		world.setBlock(i + 6, j + 4, k + 3, Blocks.cobblestone);
		world.setBlock(i + 6, j + 4, k + 4, Blocks.cobblestone);
		world.setBlock(i + 6, j + 4, k + 5, Blocks.cobblestone);
		world.setBlock(i + 6, j + 4, k + 6, Blocks.cobblestone);
		world.setBlock(i + 6, j + 4, k + 7, Blocks.cobblestone);
		world.setBlock(i + 6, j + 4, k + 8, Blocks.cobblestone);
		world.setBlock(i + 6, j + 4, k + 9, Blocks.cobblestone);
		world.setBlock(i + 6, j + 4, k + 10, Blocks.cobblestone);
		world.setBlock(i + 6, j + 4, k + 11, Blocks.cobblestone);
		world.setBlock(i + 6, j + 4, k + 12, Blocks.cobblestone);
		world.setBlock(i + 6, j + 4, k + 13, Blocks.stonebrick);
		world.setBlock(i + 6, j + 4, k + 14, Blocks.cobblestone);
		world.setBlock(i + 6, j + 4, k + 15, Blocks.cobblestone);
		world.setBlock(i + 6, j + 4, k + 16, Blocks.cobblestone);
		world.setBlock(i + 6, j + 4, k + 17, Blocks.cobblestone);
		world.setBlock(i + 6, j + 4, k + 18, Blocks.cobblestone);
		world.setBlock(i + 6, j + 4, k + 19, Blocks.cobblestone);
		world.setBlock(i + 6, j + 4, k + 20, Blocks.cobblestone);
		world.setBlock(i + 6, j + 4, k + 21, Blocks.cobblestone);
		world.setBlock(i + 6, j + 4, k + 22, Blocks.cobblestone);
		world.setBlock(i + 6, j + 4, k + 23, Blocks.cobblestone);
		world.setBlock(i + 6, j + 4, k + 24, Blocks.stonebrick);
		world.setBlock(i + 6, j + 5, k + 0, Blocks.stonebrick);
		world.setBlock(i + 6, j + 5, k + 1, Blocks.air);
		world.setBlock(i + 6, j + 5, k + 2, Blocks.air);
		world.setBlock(i + 6, j + 5, k + 3, Blocks.air);
		world.setBlock(i + 6, j + 5, k + 4, Blocks.air);
		world.setBlock(i + 6, j + 5, k + 5, Blocks.mob_spawner);
        var19 = (TileEntityMobSpawner)world.getTileEntity(i + 6, j + 5, k + 5);

        if (var19 != null)
        {
            var19.func_145881_a().setEntityName("Black Knight");
        }
		world.setBlock(i + 6, j + 5, k + 6, Blocks.air);
		world.setBlock(i + 6, j + 5, k + 7, Blocks.air);
		world.setBlock(i + 6, j + 5, k + 8, Blocks.air);
		world.setBlock(i + 6, j + 5, k + 9, Blocks.air);
		world.setBlock(i + 6, j + 5, k + 10, Blocks.air);
		world.setBlock(i + 6, j + 5, k + 11, Blocks.stonebrick);
		world.setBlock(i + 6, j + 5, k + 12, Blocks.stonebrick);
		world.setBlock(i + 6, j + 5, k + 13, Blocks.stonebrick);
		world.setBlock(i + 6, j + 5, k + 14, Blocks.stonebrick);
		world.setBlock(i + 6, j + 5, k + 15, Blocks.stonebrick);
		world.setBlock(i + 6, j + 5, k + 16, Blocks.stonebrick);
		world.setBlock(i + 6, j + 5, k + 17, Blocks.stonebrick);
		world.setBlock(i + 6, j + 5, k + 18, Blocks.stonebrick);
		world.setBlock(i + 6, j + 5, k + 19, Blocks.stonebrick);
		world.setBlock(i + 6, j + 5, k + 20, Blocks.stonebrick);
		world.setBlock(i + 6, j + 5, k + 21, Blocks.air);
		world.setBlock(i + 6, j + 5, k + 22, Blocks.air);
		world.setBlock(i + 6, j + 5, k + 23, Blocks.air);
		world.setBlock(i + 6, j + 5, k + 24, Blocks.stonebrick);
		world.setBlock(i + 6, j + 6, k + 0, Blocks.stonebrick);
		world.setBlock(i + 6, j + 6, k + 1, Blocks.air);
		world.setBlock(i + 6, j + 6, k + 2, Blocks.air);
		world.setBlock(i + 6, j + 6, k + 3, Blocks.air);
		world.setBlock(i + 6, j + 6, k + 4, Blocks.air);
		world.setBlock(i + 6, j + 6, k + 5, Blocks.air);
		world.setBlock(i + 6, j + 6, k + 6, Blocks.air);
		world.setBlock(i + 6, j + 6, k + 7, Blocks.air);
		world.setBlock(i + 6, j + 6, k + 8, Blocks.air);
		world.setBlock(i + 6, j + 6, k + 9, Blocks.air);
		world.setBlock(i + 6, j + 6, k + 11, Blocks.stonebrick);
		world.setBlock(i + 6, j + 6, k + 12, Blocks.stonebrick);
		world.setBlock(i + 6, j + 6, k + 13, Blocks.stonebrick);
		world.setBlock(i + 6, j + 6, k + 14, Blocks.stonebrick);
		world.setBlock(i + 6, j + 6, k + 15, Blocks.stonebrick);
		world.setBlock(i + 6, j + 6, k + 16, Blocks.stonebrick);
		world.setBlock(i + 6, j + 6, k + 17, Blocks.stonebrick);
		world.setBlock(i + 6, j + 6, k + 18, Blocks.stonebrick);
		world.setBlock(i + 6, j + 6, k + 19, Blocks.stonebrick);
		world.setBlock(i + 6, j + 6, k + 20, Blocks.stonebrick);
		world.setBlock(i + 6, j + 6, k + 24,
				Blocks.stone_slab, 3, 1 | (1<<1));
		world.setBlock(i + 6, j + 7, k + 0, Blocks.stonebrick);
		world.setBlock(i + 6, j + 7, k + 1, Blocks.air);
		world.setBlock(i + 6, j + 7, k + 2, Blocks.air);
		world.setBlock(i + 6, j + 7, k + 3, Blocks.air);
		world.setBlock(i + 6, j + 7, k + 4, Blocks.air);
		world.setBlock(i + 6, j + 7, k + 5, Blocks.air);
		world.setBlock(i + 6, j + 7, k + 6, Blocks.air);
		world.setBlock(i + 6, j + 7, k + 7, Blocks.air);
		world.setBlock(i + 6, j + 7, k + 8, Blocks.air);
		world.setBlock(i + 6, j + 7, k + 9, Blocks.air);
		world.setBlock(i + 6, j + 7, k + 10, Blocks.air);
		world.setBlock(i + 6, j + 7, k + 11, Blocks.stonebrick);
		world.setBlock(i + 6, j + 7, k + 12, Blocks.stonebrick);
		world.setBlock(i + 6, j + 7, k + 13, Blocks.stonebrick);
		world.setBlock(i + 6, j + 7, k + 14, Blocks.stonebrick);
		world.setBlock(i + 6, j + 7, k + 15, Blocks.stonebrick);
		world.setBlock(i + 6, j + 7, k + 16, Blocks.stonebrick);
		world.setBlock(i + 6, j + 7, k + 17, Blocks.stonebrick);
		world.setBlock(i + 6, j + 7, k + 18, Blocks.stonebrick);
		world.setBlock(i + 6, j + 7, k + 19, Blocks.stonebrick);
		world.setBlock(i + 6, j + 7, k + 20, Blocks.stonebrick);
		world.setBlock(i + 6, j + 8, k + 0, Blocks.stonebrick);
		world.setBlock(i + 6, j + 8, k + 1, Blocks.cobblestone);
		world.setBlock(i + 6, j + 8, k + 2, Blocks.cobblestone);
		world.setBlock(i + 6, j + 8, k + 3, Blocks.cobblestone);
		world.setBlock(i + 6, j + 8, k + 4, Blocks.cobblestone);
		world.setBlock(i + 6, j + 8, k + 5, Blocks.cobblestone);
		world.setBlock(i + 6, j + 8, k + 6, Blocks.cobblestone);
		world.setBlock(i + 6, j + 8, k + 7, Blocks.cobblestone);
		world.setBlock(i + 6, j + 8, k + 8, Blocks.cobblestone);
		world.setBlock(i + 6, j + 8, k + 9, Blocks.cobblestone);
		world.setBlock(i + 6, j + 8, k + 10, Blocks.cobblestone);
		world.setBlock(i + 6, j + 8, k + 11, Blocks.stonebrick);
		world.setBlock(i + 6, j + 8, k + 12, Blocks.stonebrick);
		world.setBlock(i + 6, j + 8, k + 13, Blocks.stonebrick);
		world.setBlock(i + 6, j + 8, k + 14, Blocks.stonebrick);
		world.setBlock(i + 6, j + 8, k + 15, Blocks.stonebrick);
		world.setBlock(i + 6, j + 8, k + 16, Blocks.stonebrick);
		world.setBlock(i + 6, j + 8, k + 17, Blocks.stonebrick);
		world.setBlock(i + 6, j + 8, k + 18, Blocks.stonebrick);
		world.setBlock(i + 6, j + 8, k + 19, Blocks.stonebrick);
		world.setBlock(i + 6, j + 8, k + 20, Blocks.stonebrick);
		world.setBlock(i + 6, j + 9, k + 0, Blocks.stonebrick);
		world.setBlock(i + 6, j + 9, k + 2, Blocks.stonebrick);
		world.setBlock(i + 6, j + 9, k + 3, Blocks.air);
		world.setBlock(i + 6, j + 9, k + 4,
				Blocks.stone_slab, 13, 1 | (1<<1));
		world.setBlock(i + 6, j + 9, k + 5,
				Blocks.stone_brick_stairs, 3, 1 | (1<<1));
		world.setBlock(i + 6, j + 9, k + 6, Blocks.air);
		world.setBlock(i + 6, j + 9, k + 7, Blocks.air);
		world.setBlock(i + 6, j + 9, k + 8, Blocks.stonebrick);
		world.setBlock(i + 6, j + 9, k + 11,
				Blocks.stone_slab, 3, 1 | (1<<1));
		world.setBlock(i + 6, j + 9, k + 12, Blocks.stonebrick);
		world.setBlock(i + 6, j + 9, k + 13,
				Blocks.stone_slab, 3, 1 | (1<<1));
		world.setBlock(i + 6, j + 9, k + 14, Blocks.stonebrick);
		world.setBlock(i + 6, j + 9, k + 15,
				Blocks.stone_slab, 3, 1 | (1<<1));
		world.setBlock(i + 6, j + 9, k + 16, Blocks.stonebrick);
		world.setBlock(i + 6, j + 9, k + 17,
				Blocks.stone_slab, 3, 1 | (1<<1));
		world.setBlock(i + 6, j + 9, k + 18, Blocks.stonebrick);
		world.setBlock(i + 6, j + 9, k + 19,
				Blocks.stone_slab, 3, 1 | (1<<1));
		world.setBlock(i + 6, j + 9, k + 20, Blocks.stonebrick);
		world.setBlock(i + 6, j + 10, k + 2, Blocks.stonebrick);
		world.setBlock(i + 6, j + 10, k + 3, Blocks.air);
		world.setBlock(i + 6, j + 10, k + 4, Blocks.air);
		world.setBlock(i + 6, j + 10, k + 5, Blocks.air);
		world.setBlock(i + 6, j + 10, k + 6, Blocks.air);
		world.setBlock(i + 6, j + 10, k + 7, Blocks.air);
		world.setBlock(i + 6, j + 10, k + 8, Blocks.stonebrick);
		world.setBlock(i + 6, j + 11, k + 2, Blocks.stonebrick);
		world.setBlock(i + 6, j + 11, k + 3, Blocks.air);
		world.setBlock(i + 6, j + 11, k + 4, Blocks.air);
		world.setBlock(i + 6, j + 11, k + 5, Blocks.air);
		world.setBlock(i + 6, j + 11, k + 6, Blocks.air);
		world.setBlock(i + 6, j + 11, k + 7, Blocks.air);
		world.setBlock(i + 6, j + 11, k + 8, Blocks.stonebrick);
		world.setBlock(i + 6, j + 12, k + 2, Blocks.stonebrick);
		world.setBlock(i + 6, j + 12, k + 3, Blocks.cobblestone);
		world.setBlock(i + 6, j + 12, k + 4, Blocks.air);
		world.setBlock(i + 6, j + 12, k + 5, Blocks.air);
		world.setBlock(i + 6, j + 12, k + 6, Blocks.air);
		world.setBlock(i + 6, j + 12, k + 7, Blocks.cobblestone);
		world.setBlock(i + 6, j + 12, k + 8, Blocks.stonebrick);
		world.setBlock(i + 6, j + 13, k + 2,
				Blocks.stone_slab, 3, 1 | (1<<1));
		world.setBlock(i + 6, j + 13, k + 8,
				Blocks.stone_slab, 3, 1 | (1<<1));
		world.setBlock(i + 7, j + 0, k + 0, Blocks.cobblestone);
		world.setBlock(i + 7, j + 0, k + 1, Blocks.cobblestone);
		world.setBlock(i + 7, j + 0, k + 2, Blocks.cobblestone);
		world.setBlock(i + 7, j + 0, k + 3, Blocks.cobblestone);
		world.setBlock(i + 7, j + 0, k + 4, Blocks.cobblestone);
		world.setBlock(i + 7, j + 0, k + 5, Blocks.cobblestone);
		world.setBlock(i + 7, j + 0, k + 6, Blocks.cobblestone);
		world.setBlock(i + 7, j + 0, k + 7, Blocks.cobblestone);
		world.setBlock(i + 7, j + 0, k + 8, Blocks.cobblestone);
		world.setBlock(i + 7, j + 0, k + 9, Blocks.cobblestone);
		world.setBlock(i + 7, j + 0, k + 10, Blocks.cobblestone);
		world.setBlock(i + 7, j + 0, k + 11, Blocks.cobblestone);
		world.setBlock(i + 7, j + 0, k + 12, Blocks.cobblestone);
		world.setBlock(i + 7, j + 0, k + 13, Blocks.cobblestone);
		world.setBlock(i + 7, j + 0, k + 14, Blocks.cobblestone);
		world.setBlock(i + 7, j + 0, k + 15, Blocks.cobblestone);
		world.setBlock(i + 7, j + 0, k + 16, Blocks.cobblestone);
		world.setBlock(i + 7, j + 0, k + 17, Blocks.cobblestone);
		world.setBlock(i + 7, j + 0, k + 18, Blocks.cobblestone);
		world.setBlock(i + 7, j + 0, k + 19, Blocks.cobblestone);
		world.setBlock(i + 7, j + 0, k + 20, Blocks.cobblestone);
		world.setBlock(i + 7, j + 0, k + 21, Blocks.cobblestone);
		world.setBlock(i + 7, j + 0, k + 22, Blocks.cobblestone);
		world.setBlock(i + 7, j + 0, k + 23, Blocks.cobblestone);
		world.setBlock(i + 7, j + 0, k + 24, Blocks.cobblestone);
		world.setBlock(i + 7, j + 0, k + 25, Blocks.cobblestone);
		world.setBlock(i + 7, j + 1, k + 0, Blocks.stonebrick);
		world.setBlock(i + 7, j + 1, k + 1, Blocks.chest, 3, 1 | (1<<1));
		TileEntityChest var16 = (TileEntityChest) world.getTileEntity(
				i + 7, j + 1, k + 1);

		if (var16 != null) {
			ChestGenHooks info = ChestGenHooks.getInfo(ChestGenHooks.DUNGEON_CHEST);
			WeightedRandomChestContent.generateChestContents(rand, info.getItems(rand), var16, info.getCount(rand));
			int poss = rand.nextInt(5);
			if (poss == 0) {
				ItemStack var18 = new ItemStack(Wildycraft.dragonhoe);
				var16.setInventorySlotContents(
						rand.nextInt(var16.getSizeInventory()), var18);
			}
		}
		world.setBlock(i + 7, j + 1, k + 2, Blocks.air);
		world.setBlock(i + 7, j + 1, k + 3, Blocks.air);
		world.setBlock(i + 7, j + 1, k + 4, Blocks.air);
		world.setBlock(i + 7, j + 1, k + 5, Blocks.planks, 1, 1 | (1<<1));
		world.setBlock(i + 7, j + 1, k + 6, Blocks.planks, 1, 1 | (1<<1));
		world.setBlock(i + 7, j + 1, k + 7,
				Blocks.oak_stairs, 2, 1 | (1<<1));
		world.setBlock(i + 7, j + 1, k + 8, Blocks.air);
		world.setBlock(i + 7, j + 1, k + 9, Blocks.air);
		world.setBlock(i + 7, j + 1, k + 10, Blocks.air);
		world.setBlock(i + 7, j + 1, k + 11, Blocks.air);
		world.setBlock(i + 7, j + 1, k + 12, Blocks.air);
		world.setBlock(i + 7, j + 1, k + 13, Blocks.stonebrick);
		world.setBlock(i + 7, j + 1, k + 14, Blocks.air);
		world.setBlock(i + 7, j + 1, k + 15, Blocks.air);
		world.setBlock(i + 7, j + 1, k + 16, Blocks.air);
		world.setBlock(i + 7, j + 1, k + 17, Blocks.air);
		world.setBlock(i + 7, j + 1, k + 18, Blocks.air);
		world.setBlock(i + 7, j + 1, k + 19, Blocks.air);
		world.setBlock(i + 7, j + 1, k + 20, Blocks.air);
		world.setBlock(i + 7, j + 1, k + 21, Blocks.air);
		world.setBlock(i + 7, j + 1, k + 22, Blocks.air);
		world.setBlock(i + 7, j + 1, k + 23, Blocks.air);
		world.setBlock(i + 7, j + 1, k + 24, Blocks.air);
		world.setBlock(i + 7, j + 1, k + 25, Blocks.stonebrick);
		world.setBlock(i + 7, j + 2, k + 0, Blocks.stonebrick);
		world.setBlock(i + 7, j + 2, k + 1, Blocks.air);
		world.setBlock(i + 7, j + 2, k + 2, Blocks.air);
		world.setBlock(i + 7, j + 2, k + 3, Blocks.air);
		world.setBlock(i + 7, j + 2, k + 4, Blocks.air);
		world.setBlock(i + 7, j + 2, k + 5, Blocks.air);
		world.setBlock(i + 7, j + 2, k + 6, Blocks.air);
		world.setBlock(i + 7, j + 2, k + 7, Blocks.air);
		world.setBlock(i + 7, j + 2, k + 8, Blocks.air);
		world.setBlock(i + 7, j + 2, k + 9, Blocks.air);
		world.setBlock(i + 7, j + 2, k + 10, Blocks.air);
		world.setBlock(i + 7, j + 2, k + 11, Blocks.air);
		world.setBlock(i + 7, j + 2, k + 12, Blocks.air);
		world.setBlock(i + 7, j + 2, k + 13, Blocks.stonebrick);
		world.setBlock(i + 7, j + 2, k + 14, Blocks.air);
		world.setBlock(i + 7, j + 2, k + 15, Blocks.air);
		world.setBlock(i + 7, j + 2, k + 16, Blocks.air);
		world.setBlock(i + 7, j + 2, k + 17, Blocks.air);
		world.setBlock(i + 7, j + 2, k + 18, Blocks.air);
		world.setBlock(i + 7, j + 2, k + 19, Blocks.air);
		world.setBlock(i + 7, j + 2, k + 20, Blocks.air);
		world.setBlock(i + 7, j + 2, k + 21, Blocks.air);
		world.setBlock(i + 7, j + 2, k + 22, Blocks.air);
		world.setBlock(i + 7, j + 2, k + 23, Blocks.air);
		world.setBlock(i + 7, j + 2, k + 24, Blocks.air);
		world.setBlock(i + 7, j + 2, k + 25, Blocks.stonebrick);
		world.setBlock(i + 7, j + 3, k + 0, Blocks.stonebrick);
		world.setBlock(i + 7, j + 3, k + 1, Blocks.air);
		world.setBlock(i + 7, j + 3, k + 2, Blocks.air);
		world.setBlock(i + 7, j + 3, k + 3, Blocks.air);
		world.setBlock(i + 7, j + 3, k + 4, Blocks.air);
		world.setBlock(i + 7, j + 3, k + 5, Blocks.air);
		world.setBlock(i + 7, j + 3, k + 6, Blocks.air);
		world.setBlock(i + 7, j + 3, k + 7, Blocks.air);
		world.setBlock(i + 7, j + 3, k + 8, Blocks.air);
		world.setBlock(i + 7, j + 3, k + 9, Blocks.air);
		world.setBlock(i + 7, j + 3, k + 10, Blocks.air);
		world.setBlock(i + 7, j + 3, k + 11, Blocks.air);
		world.setBlock(i + 7, j + 3, k + 12, Blocks.air);
		world.setBlock(i + 7, j + 3, k + 13, Blocks.stonebrick);
		world.setBlock(i + 7, j + 3, k + 14, Blocks.air);
		world.setBlock(i + 7, j + 3, k + 15, Blocks.air);
		world.setBlock(i + 7, j + 3, k + 16, Blocks.air);
		world.setBlock(i + 7, j + 3, k + 17, Blocks.air);
		world.setBlock(i + 7, j + 3, k + 18, Blocks.air);
		world.setBlock(i + 7, j + 3, k + 19, Blocks.air);
		world.setBlock(i + 7, j + 3, k + 20, Blocks.air);
		world.setBlock(i + 7, j + 3, k + 21, Blocks.air);
		world.setBlock(i + 7, j + 3, k + 22, Blocks.air);
		world.setBlock(i + 7, j + 3, k + 23, Blocks.air);
		world.setBlock(i + 7, j + 3, k + 24, Blocks.air);
		world.setBlock(i + 7, j + 3, k + 25, Blocks.stonebrick);
		world.setBlock(i + 7, j + 4, k + 0, Blocks.stonebrick);
		world.setBlock(i + 7, j + 4, k + 1, Blocks.cobblestone);
		world.setBlock(i + 7, j + 4, k + 2, Blocks.cobblestone);
		world.setBlock(i + 7, j + 4, k + 3, Blocks.cobblestone);
		world.setBlock(i + 7, j + 4, k + 4, Blocks.cobblestone);
		world.setBlock(i + 7, j + 4, k + 5, Blocks.cobblestone);
		world.setBlock(i + 7, j + 4, k + 6, Blocks.cobblestone);
		world.setBlock(i + 7, j + 4, k + 7, Blocks.cobblestone);
		world.setBlock(i + 7, j + 4, k + 8, Blocks.cobblestone);
		world.setBlock(i + 7, j + 4, k + 9, Blocks.cobblestone);
		world.setBlock(i + 7, j + 4, k + 10, Blocks.cobblestone);
		world.setBlock(i + 7, j + 4, k + 11, Blocks.cobblestone);
		world.setBlock(i + 7, j + 4, k + 12, Blocks.cobblestone);
		world.setBlock(i + 7, j + 4, k + 13, Blocks.stonebrick);
		world.setBlock(i + 7, j + 4, k + 14, Blocks.cobblestone);
		world.setBlock(i + 7, j + 4, k + 15, Blocks.cobblestone);
		world.setBlock(i + 7, j + 4, k + 16, Blocks.cobblestone);
		world.setBlock(i + 7, j + 4, k + 17, Blocks.cobblestone);
		world.setBlock(i + 7, j + 4, k + 18, Blocks.cobblestone);
		world.setBlock(i + 7, j + 4, k + 19, Blocks.cobblestone);
		world.setBlock(i + 7, j + 4, k + 20, Blocks.cobblestone);
		world.setBlock(i + 7, j + 4, k + 21, Blocks.cobblestone);
		world.setBlock(i + 7, j + 4, k + 22, Blocks.cobblestone);
		world.setBlock(i + 7, j + 4, k + 23, Blocks.cobblestone);
		world.setBlock(i + 7, j + 4, k + 24, Blocks.cobblestone);
		world.setBlock(i + 7, j + 4, k + 25, Blocks.stonebrick);
		world.setBlock(i + 7, j + 5, k + 0, Blocks.stonebrick);
		world.setBlock(i + 7, j + 5, k + 1, Blocks.air);
		world.setBlock(i + 7, j + 5, k + 2, Blocks.air);
		world.setBlock(i + 7, j + 5, k + 3, Blocks.air);
		world.setBlock(i + 7, j + 5, k + 4, Blocks.air);
		world.setBlock(i + 7, j + 5, k + 5, Blocks.air);
		world.setBlock(i + 7, j + 5, k + 6, Blocks.air);
		world.setBlock(i + 7, j + 5, k + 7, Blocks.air);
		world.setBlock(i + 7, j + 5, k + 8, Blocks.air);
		world.setBlock(i + 7, j + 5, k + 9, Blocks.air);
		world.setBlock(i + 7, j + 5, k + 10, Blocks.bookshelf);
		world.setBlock(i + 7, j + 5, k + 11, Blocks.stonebrick);
		world.setBlock(i + 7, j + 5, k + 12, Blocks.air);
		world.setBlock(i + 7, j + 5, k + 13, Blocks.air);
		world.setBlock(i + 7, j + 5, k + 14, Blocks.air);
		world.setBlock(i + 7, j + 5, k + 15, Blocks.air);
		world.setBlock(i + 7, j + 5, k + 16, Blocks.air);
		world.setBlock(i + 7, j + 5, k + 17, Blocks.air);
		world.setBlock(i + 7, j + 5, k + 18, Blocks.air);
		world.setBlock(i + 7, j + 5, k + 19, Blocks.air);
		world.setBlock(i + 7, j + 5, k + 20, Blocks.air);
		world.setBlock(i + 7, j + 5, k + 21, Blocks.stonebrick);
		world.setBlock(i + 7, j + 5, k + 22, Blocks.air);
		world.setBlock(i + 7, j + 5, k + 23, Blocks.air);
		world.setBlock(i + 7, j + 5, k + 24, Blocks.air);
		world.setBlock(i + 7, j + 5, k + 25, Blocks.stonebrick);
		world.setBlock(i + 7, j + 6, k + 0, Blocks.stonebrick);
		world.setBlock(i + 7, j + 6, k + 1, Blocks.air);
		world.setBlock(i + 7, j + 6, k + 2, Blocks.air);
		world.setBlock(i + 7, j + 6, k + 3, Blocks.air);
		world.setBlock(i + 7, j + 6, k + 4, Blocks.air);
		world.setBlock(i + 7, j + 6, k + 5, Blocks.air);
		world.setBlock(i + 7, j + 6, k + 6, Blocks.air);
		world.setBlock(i + 7, j + 6, k + 7, Blocks.air);
		world.setBlock(i + 7, j + 6, k + 8, Blocks.air);
		world.setBlock(i + 7, j + 6, k + 9, Blocks.air);
		world.setBlock(i + 7, j + 6, k + 10, Blocks.bookshelf);
		world.setBlock(i + 7, j + 6, k + 11, Blocks.stonebrick);
		world.setBlock(i + 7, j + 6, k + 12, Blocks.air);
		world.setBlock(i + 7, j + 6, k + 13, Blocks.air);
		world.setBlock(i + 7, j + 6, k + 14, Blocks.air);
		world.setBlock(i + 7, j + 6, k + 15, Blocks.air);
		world.setBlock(i + 7, j + 6, k + 17, Blocks.air);
		world.setBlock(i + 7, j + 6, k + 18, Blocks.air);
		world.setBlock(i + 7, j + 6, k + 19, Blocks.air);
		world.setBlock(i + 7, j + 6, k + 20, Blocks.air);
		world.setBlock(i + 7, j + 6, k + 21, Blocks.stonebrick);
		world.setBlock(i + 7, j + 7, k + 0, Blocks.stonebrick);
		world.setBlock(i + 7, j + 7, k + 1, Blocks.air);
		world.setBlock(i + 7, j + 7, k + 2, Blocks.air);
		world.setBlock(i + 7, j + 7, k + 3, Blocks.air);
		world.setBlock(i + 7, j + 7, k + 4, Blocks.air);
		world.setBlock(i + 7, j + 7, k + 5, Blocks.air);
		world.setBlock(i + 7, j + 7, k + 6, Blocks.air);
		world.setBlock(i + 7, j + 7, k + 7, Blocks.air);
		world.setBlock(i + 7, j + 7, k + 8, Blocks.air);
		world.setBlock(i + 7, j + 7, k + 9, Blocks.air);
		world.setBlock(i + 7, j + 7, k + 10, Blocks.air);
		world.setBlock(i + 7, j + 7, k + 11, Blocks.stonebrick);
		world.setBlock(i + 7, j + 7, k + 12, Blocks.air);
		world.setBlock(i + 7, j + 7, k + 13, Blocks.air);
		world.setBlock(i + 7, j + 7, k + 14, Blocks.air);
		world.setBlock(i + 7, j + 7, k + 15, Blocks.air);
		world.setBlock(i + 7, j + 7, k + 16, Blocks.air);
		world.setBlock(i + 7, j + 7, k + 17, Blocks.air);
		world.setBlock(i + 7, j + 7, k + 18, Blocks.air);
		world.setBlock(i + 7, j + 7, k + 19, Blocks.air);
		world.setBlock(i + 7, j + 7, k + 20, Blocks.air);
		world.setBlock(i + 7, j + 7, k + 21, Blocks.stonebrick);
		world.setBlock(i + 7, j + 8, k + 0, Blocks.stonebrick);
		world.setBlock(i + 7, j + 8, k + 1, Blocks.cobblestone);
		world.setBlock(i + 7, j + 8, k + 2, Blocks.cobblestone);
		world.setBlock(i + 7, j + 8, k + 3, Blocks.cobblestone);
		world.setBlock(i + 7, j + 8, k + 4, Blocks.cobblestone);
		world.setBlock(i + 7, j + 8, k + 5, Blocks.cobblestone);
		world.setBlock(i + 7, j + 8, k + 6, Blocks.cobblestone);
		world.setBlock(i + 7, j + 8, k + 7, Blocks.cobblestone);
		world.setBlock(i + 7, j + 8, k + 8, Blocks.cobblestone);
		world.setBlock(i + 7, j + 8, k + 9, Blocks.cobblestone);
		world.setBlock(i + 7, j + 8, k + 10, Blocks.cobblestone);
		world.setBlock(i + 7, j + 8, k + 11, Blocks.stonebrick);
		world.setBlock(i + 7, j + 8, k + 12, Blocks.cobblestone);
		world.setBlock(i + 7, j + 8, k + 13, Blocks.cobblestone);
		world.setBlock(i + 7, j + 8, k + 14, Blocks.cobblestone);
		world.setBlock(i + 7, j + 8, k + 15, Blocks.cobblestone);
		world.setBlock(i + 7, j + 8, k + 16, Blocks.cobblestone);
		world.setBlock(i + 7, j + 8, k + 17, Blocks.cobblestone);
		world.setBlock(i + 7, j + 8, k + 18, Blocks.cobblestone);
		world.setBlock(i + 7, j + 8, k + 19, Blocks.cobblestone);
		world.setBlock(i + 7, j + 8, k + 20, Blocks.cobblestone);
		world.setBlock(i + 7, j + 8, k + 21, Blocks.stonebrick);
		world.setBlock(i + 7, j + 9, k + 0,
				Blocks.stone_slab, 3, 1 | (1<<1));
		world.setBlock(i + 7, j + 9, k + 2, Blocks.stonebrick);
		world.setBlock(i + 7, j + 9, k + 3, Blocks.air);
		world.setBlock(i + 7, j + 9, k + 4, Blocks.air);
		world.setBlock(i + 7, j + 9, k + 5, Blocks.air);
		world.setBlock(i + 7, j + 9, k + 6, Blocks.air);
		world.setBlock(i + 7, j + 9, k + 7, Blocks.air);
		world.setBlock(i + 7, j + 9, k + 21,
				Blocks.stone_slab, 3, 1 | (1<<1));
		world.setBlock(i + 7, j + 10, k + 2, Blocks.stonebrick);
		world.setBlock(i + 7, j + 10, k + 3, Blocks.air);
		world.setBlock(i + 7, j + 10, k + 4, Blocks.air);
		world.setBlock(i + 7, j + 10, k + 5, Blocks.air);
		world.setBlock(i + 7, j + 10, k + 6, Blocks.air);
		world.setBlock(i + 7, j + 10, k + 7, Blocks.air);
		world.setBlock(i + 7, j + 11, k + 2, Blocks.stonebrick);
		world.setBlock(i + 7, j + 11, k + 3, Blocks.air);
		world.setBlock(i + 7, j + 11, k + 4, Blocks.air);
		world.setBlock(i + 7, j + 11, k + 5, Blocks.air);
		world.setBlock(i + 7, j + 11, k + 6, Blocks.air);
		world.setBlock(i + 7, j + 11, k + 7, Blocks.air);
		world.setBlock(i + 7, j + 11, k + 8, Blocks.stonebrick);
		world.setBlock(i + 7, j + 12, k + 2, Blocks.stonebrick);
		world.setBlock(i + 7, j + 12, k + 3, Blocks.cobblestone);
		world.setBlock(i + 7, j + 12, k + 4, Blocks.cobblestone);
		world.setBlock(i + 7, j + 12, k + 5, Blocks.cobblestone);
		world.setBlock(i + 7, j + 12, k + 6, Blocks.cobblestone);
		world.setBlock(i + 7, j + 12, k + 7, Blocks.cobblestone);
		world.setBlock(i + 7, j + 12, k + 8, Blocks.stonebrick);
		world.setBlock(i + 7, j + 13, k + 2, Blocks.stonebrick);
		world.setBlock(i + 7, j + 13, k + 8, Blocks.stonebrick);
		world.setBlock(i + 8, j + 0, k + 0, Blocks.cobblestone);
		world.setBlock(i + 8, j + 0, k + 1, Blocks.cobblestone);
		world.setBlock(i + 8, j + 0, k + 2, Blocks.cobblestone);
		world.setBlock(i + 8, j + 0, k + 3, Blocks.cobblestone);
		world.setBlock(i + 8, j + 0, k + 4, Blocks.cobblestone);
		world.setBlock(i + 8, j + 0, k + 5, Blocks.cobblestone);
		world.setBlock(i + 8, j + 0, k + 6, Blocks.cobblestone);
		world.setBlock(i + 8, j + 0, k + 7, Blocks.cobblestone);
		world.setBlock(i + 8, j + 0, k + 8, Blocks.cobblestone);
		world.setBlock(i + 8, j + 0, k + 9, Blocks.cobblestone);
		world.setBlock(i + 8, j + 0, k + 10, Blocks.cobblestone);
		world.setBlock(i + 8, j + 0, k + 11, Blocks.cobblestone);
		world.setBlock(i + 8, j + 0, k + 12, Blocks.cobblestone);
		world.setBlock(i + 8, j + 0, k + 13, Blocks.cobblestone);
		world.setBlock(i + 8, j + 0, k + 14, Blocks.cobblestone);
		world.setBlock(i + 8, j + 0, k + 15, Blocks.cobblestone);
		world.setBlock(i + 8, j + 0, k + 16, Blocks.cobblestone);
		world.setBlock(i + 8, j + 0, k + 17, Blocks.cobblestone);
		world.setBlock(i + 8, j + 0, k + 18, Blocks.cobblestone);
		world.setBlock(i + 8, j + 0, k + 19, Blocks.cobblestone);
		world.setBlock(i + 8, j + 0, k + 20, Blocks.cobblestone);
		world.setBlock(i + 8, j + 0, k + 21, Blocks.cobblestone);
		world.setBlock(i + 8, j + 0, k + 22, Blocks.cobblestone);
		world.setBlock(i + 8, j + 0, k + 23, Blocks.cobblestone);
		world.setBlock(i + 8, j + 0, k + 24, Blocks.cobblestone);
		world.setBlock(i + 8, j + 0, k + 25, Blocks.cobblestone);
		world.setBlock(i + 8, j + 0, k + 26, Blocks.cobblestone);
		world.setBlock(i + 8, j + 1, k + 0, Blocks.stonebrick);
		world.setBlock(i + 8, j + 1, k + 1, Blocks.air);
		world.setBlock(i + 8, j + 1, k + 2, Blocks.air);
		world.setBlock(i + 8, j + 1, k + 3, Blocks.air);
		world.setBlock(i + 8, j + 1, k + 4, Blocks.air);
		world.setBlock(i + 8, j + 1, k + 5, Blocks.planks, 1, 1 | (1<<1));
		world.setBlock(i + 8, j + 1, k + 6, Blocks.planks, 1, 1 | (1<<1));
		world.setBlock(i + 8, j + 1, k + 7, Blocks.air);
		world.setBlock(i + 8, j + 1, k + 8, Blocks.iron_bars);
		world.setBlock(i + 8, j + 1, k + 9, Blocks.iron_bars);
		world.setBlock(i + 8, j + 1, k + 10, Blocks.iron_bars);
		world.setBlock(i + 8, j + 1, k + 11, Blocks.stonebrick);
		world.setBlock(i + 8, j + 1, k + 12, Blocks.stonebrick);
		world.setBlock(i + 8, j + 1, k + 13, Blocks.stonebrick);
		world.setBlock(i + 8, j + 1, k + 14, Blocks.air);
		world.setBlock(i + 8, j + 1, k + 15, Blocks.air);
		world.setBlock(i + 8, j + 1, k + 16, Blocks.air);
		world.setBlock(i + 8, j + 1, k + 17, Blocks.air);
		world.setBlock(i + 8, j + 1, k + 18, Blocks.air);
		world.setBlock(i + 8, j + 1, k + 19, Blocks.air);
		world.setBlock(i + 8, j + 1, k + 20, Blocks.air);
		world.setBlock(i + 8, j + 1, k + 21, Blocks.air);
		world.setBlock(i + 8, j + 1, k + 22, Blocks.air);
		world.setBlock(i + 8, j + 1, k + 23, Blocks.air);
		world.setBlock(i + 8, j + 1, k + 24, Blocks.air);
		world.setBlock(i + 8, j + 1, k + 25, Blocks.air);
		world.setBlock(i + 8, j + 1, k + 26, Blocks.stonebrick);
		world.setBlock(i + 8, j + 2, k + 0, Blocks.stonebrick);
		world.setBlock(i + 8, j + 2, k + 1, Blocks.air);
		world.setBlock(i + 8, j + 2, k + 2, Blocks.air);
		world.setBlock(i + 8, j + 2, k + 3, Blocks.air);
		world.setBlock(i + 8, j + 2, k + 4, Blocks.air);
		world.setBlock(i + 8, j + 2, k + 5, Blocks.air);
		world.setBlock(i + 8, j + 2, k + 6, Blocks.air);
		world.setBlock(i + 8, j + 2, k + 7, Blocks.air);
		world.setBlock(i + 8, j + 2, k + 8, Blocks.iron_bars);
		world.setBlock(i + 8, j + 2, k + 9, Blocks.iron_bars);
		world.setBlock(i + 8, j + 2, k + 10, Blocks.iron_bars);
		world.setBlock(i + 8, j + 2, k + 11, Blocks.stonebrick);
		world.setBlock(i + 8, j + 2, k + 12, Blocks.stonebrick);
		world.setBlock(i + 8, j + 2, k + 13, Blocks.stonebrick);
		world.setBlock(i + 8, j + 2, k + 14, Blocks.air);
		world.setBlock(i + 8, j + 2, k + 15, Blocks.air);
		world.setBlock(i + 8, j + 2, k + 16, Blocks.air);
		world.setBlock(i + 8, j + 2, k + 17, Blocks.air);
		world.setBlock(i + 8, j + 2, k + 18, Blocks.air);
		world.setBlock(i + 8, j + 2, k + 19, Blocks.air);
		world.setBlock(i + 8, j + 2, k + 20, Blocks.air);
		world.setBlock(i + 8, j + 2, k + 21, Blocks.air);
		world.setBlock(i + 8, j + 2, k + 22, Blocks.air);
		world.setBlock(i + 8, j + 2, k + 23, Blocks.air);
		world.setBlock(i + 8, j + 2, k + 24, Blocks.air);
		world.setBlock(i + 8, j + 2, k + 25, Blocks.air);
		world.setBlock(i + 8, j + 2, k + 26, Blocks.stonebrick);
		world.setBlock(i + 8, j + 3, k + 0, Blocks.stonebrick);
		world.setBlock(i + 8, j + 3, k + 1, Blocks.air);
		world.setBlock(i + 8, j + 3, k + 2, Blocks.air);
		world.setBlock(i + 8, j + 3, k + 3, Blocks.air);
		world.setBlock(i + 8, j + 3, k + 4, Blocks.air);
		world.setBlock(i + 8, j + 3, k + 5, Blocks.air);
		world.setBlock(i + 8, j + 3, k + 6, Blocks.air);
		world.setBlock(i + 8, j + 3, k + 7, Blocks.air);
		world.setBlock(i + 8, j + 3, k + 8, Blocks.iron_bars);
		world.setBlock(i + 8, j + 3, k + 9, Blocks.iron_bars);
		world.setBlock(i + 8, j + 3, k + 10, Blocks.iron_bars);
		world.setBlock(i + 8, j + 3, k + 11, Blocks.stonebrick);
		world.setBlock(i + 8, j + 3, k + 12, Blocks.stonebrick);
		world.setBlock(i + 8, j + 3, k + 13, Blocks.stonebrick);
		world.setBlock(i + 8, j + 3, k + 14, Blocks.air);
		world.setBlock(i + 8, j + 3, k + 15, Blocks.air);
		world.setBlock(i + 8, j + 3, k + 16, Blocks.air);
		world.setBlock(i + 8, j + 3, k + 17, Blocks.air);
		world.setBlock(i + 8, j + 3, k + 18, Blocks.air);
		world.setBlock(i + 8, j + 3, k + 19, Blocks.air);
		world.setBlock(i + 8, j + 3, k + 20, Blocks.air);
		world.setBlock(i + 8, j + 3, k + 21, Blocks.air);
		world.setBlock(i + 8, j + 3, k + 22, Blocks.air);
		world.setBlock(i + 8, j + 3, k + 23, Blocks.air);
		world.setBlock(i + 8, j + 3, k + 24, Blocks.air);
		world.setBlock(i + 8, j + 3, k + 25, Blocks.air);
		world.setBlock(i + 8, j + 3, k + 26, Blocks.stonebrick);
		world.setBlock(i + 8, j + 4, k + 0, Blocks.stonebrick);
		world.setBlock(i + 8, j + 4, k + 1, Blocks.cobblestone);
		world.setBlock(i + 8, j + 4, k + 2, Blocks.cobblestone);
		world.setBlock(i + 8, j + 4, k + 3, Blocks.cobblestone);
		world.setBlock(i + 8, j + 4, k + 4, Blocks.cobblestone);
		world.setBlock(i + 8, j + 4, k + 5, Blocks.cobblestone);
		world.setBlock(i + 8, j + 4, k + 6, Blocks.cobblestone);
		world.setBlock(i + 8, j + 4, k + 7, Blocks.cobblestone);
		world.setBlock(i + 8, j + 4, k + 8, Blocks.cobblestone);
		world.setBlock(i + 8, j + 4, k + 9, Blocks.cobblestone);
		world.setBlock(i + 8, j + 4, k + 10, Blocks.cobblestone);
		world.setBlock(i + 8, j + 4, k + 11, Blocks.stonebrick);
		world.setBlock(i + 8, j + 4, k + 12, Blocks.stonebrick);
		world.setBlock(i + 8, j + 4, k + 13, Blocks.stonebrick);
		world.setBlock(i + 8, j + 4, k + 14, Blocks.cobblestone);
		world.setBlock(i + 8, j + 4, k + 15, Blocks.cobblestone);
		world.setBlock(i + 8, j + 4, k + 16, Blocks.cobblestone);
		world.setBlock(i + 8, j + 4, k + 17, Blocks.cobblestone);
		world.setBlock(i + 8, j + 4, k + 18, Blocks.cobblestone);
		world.setBlock(i + 8, j + 4, k + 19, Blocks.cobblestone);
		world.setBlock(i + 8, j + 4, k + 20, Blocks.cobblestone);
		world.setBlock(i + 8, j + 4, k + 21, Blocks.cobblestone);
		world.setBlock(i + 8, j + 4, k + 22, Blocks.cobblestone);
		world.setBlock(i + 8, j + 4, k + 23, Blocks.cobblestone);
		world.setBlock(i + 8, j + 4, k + 24, Blocks.cobblestone);
		world.setBlock(i + 8, j + 4, k + 25, Blocks.cobblestone);
		world.setBlock(i + 8, j + 4, k + 26, Blocks.stonebrick);
		world.setBlock(i + 8, j + 5, k + 0, Blocks.stonebrick);
		world.setBlock(i + 8, j + 5, k + 1, Blocks.bookshelf);
		world.setBlock(i + 8, j + 5, k + 2, Blocks.air);
		world.setBlock(i + 8, j + 5, k + 3, Blocks.planks);
		world.setBlock(i + 8, j + 5, k + 4, Blocks.air);
		world.setBlock(i + 8, j + 5, k + 5, Blocks.planks);
		world.setBlock(i + 8, j + 5, k + 6, Blocks.air);
		world.setBlock(i + 8, j + 5, k + 7, Blocks.air);
		world.setBlock(i + 8, j + 5, k + 8, Blocks.air);
		world.setBlock(i + 8, j + 5, k + 9, Blocks.air);
		world.setBlock(i + 8, j + 5, k + 10, Blocks.bookshelf);
		world.setBlock(i + 8, j + 5, k + 11, Blocks.stonebrick);
		world.setBlock(i + 8, j + 5, k + 12, Blocks.wool);
		world.setBlock(i + 8, j + 5, k + 13, Blocks.wool);
		world.setBlock(i + 8, j + 5, k + 14, Blocks.air);
		world.setBlock(i + 8, j + 5, k + 15, Blocks.air);
		world.setBlock(i + 8, j + 5, k + 16, Blocks.planks);
		world.setBlock(i + 8, j + 5, k + 17, Blocks.planks);
		world.setBlock(i + 8, j + 5, k + 18, Blocks.planks);
		world.setBlock(i + 8, j + 5, k + 19, Blocks.air);
		world.setBlock(i + 8, j + 5, k + 20, Blocks.air);
		world.setBlock(i + 8, j + 5, k + 21, Blocks.air);
		world.setBlock(i + 8, j + 5, k + 22, Blocks.stonebrick);
		world.setBlock(i + 8, j + 5, k + 23, Blocks.air);
		world.setBlock(i + 8, j + 5, k + 24, Blocks.air);
		world.setBlock(i + 8, j + 5, k + 25, Blocks.air);
		world.setBlock(i + 8, j + 5, k + 26, Blocks.stonebrick);
		world.setBlock(i + 8, j + 6, k + 0, Blocks.stonebrick);
		world.setBlock(i + 8, j + 6, k + 1, Blocks.bookshelf);
		world.setBlock(i + 8, j + 6, k + 2, Blocks.air);
		world.setBlock(i + 8, j + 6, k + 3, Blocks.air);
		world.setBlock(i + 8, j + 6, k + 4, Blocks.air);
		world.setBlock(i + 8, j + 6, k + 5, Blocks.air);
		world.setBlock(i + 8, j + 6, k + 6, Blocks.air);
		world.setBlock(i + 8, j + 6, k + 7, Blocks.air);
		world.setBlock(i + 8, j + 6, k + 8, Blocks.air);
		world.setBlock(i + 8, j + 6, k + 9, Blocks.air);
		world.setBlock(i + 8, j + 6, k + 10, Blocks.bookshelf);
		world.setBlock(i + 8, j + 6, k + 11, Blocks.stonebrick);
		world.setBlock(i + 8, j + 6, k + 12, Blocks.air);
		world.setBlock(i + 8, j + 6, k + 13, Blocks.air);
		world.setBlock(i + 8, j + 6, k + 14, Blocks.air);
		world.setBlock(i + 8, j + 6, k + 15, Blocks.air);
		world.setBlock(i + 8, j + 6, k + 16, Blocks.air);
		world.setBlock(i + 8, j + 6, k + 17, Blocks.air);
		world.setBlock(i + 8, j + 6, k + 18, Blocks.air);
		world.setBlock(i + 8, j + 6, k + 19, Blocks.air);
		world.setBlock(i + 8, j + 6, k + 20, Blocks.air);
		world.setBlock(i + 8, j + 6, k + 21, Blocks.air);
		world.setBlock(i + 8, j + 6, k + 22, Blocks.stonebrick);
		world.setBlock(i + 8, j + 6, k + 26,
				Blocks.stone_slab, 3, 1 | (1<<1));
		world.setBlock(i + 8, j + 7, k + 0, Blocks.stonebrick);
		world.setBlock(i + 8, j + 7, k + 1, Blocks.air);
		world.setBlock(i + 8, j + 7, k + 2, Blocks.air);
		world.setBlock(i + 8, j + 7, k + 3, Blocks.air);
		world.setBlock(i + 8, j + 7, k + 4, Blocks.air);
		world.setBlock(i + 8, j + 7, k + 5, Blocks.air);
		world.setBlock(i + 8, j + 7, k + 6, Blocks.air);
		world.setBlock(i + 8, j + 7, k + 7, Blocks.air);
		world.setBlock(i + 8, j + 7, k + 8, Blocks.air);
		world.setBlock(i + 8, j + 7, k + 9, Blocks.air);
		world.setBlock(i + 8, j + 7, k + 10, Blocks.air);
		world.setBlock(i + 8, j + 7, k + 11, Blocks.stonebrick);
		world.setBlock(i + 8, j + 7, k + 12, Blocks.air);
		world.setBlock(i + 8, j + 7, k + 13, Blocks.air);
		world.setBlock(i + 8, j + 7, k + 14, Blocks.air);
		world.setBlock(i + 8, j + 7, k + 15, Blocks.air);
		world.setBlock(i + 8, j + 7, k + 16, Blocks.air);
		world.setBlock(i + 8, j + 7, k + 17, Blocks.air);
		world.setBlock(i + 8, j + 7, k + 18, Blocks.air);
		world.setBlock(i + 8, j + 7, k + 19, Blocks.air);
		world.setBlock(i + 8, j + 7, k + 20, Blocks.air);
		world.setBlock(i + 8, j + 7, k + 21, Blocks.air);

		generate2(world, rand, i, j, k);
		return true;
	}

	public boolean generate2(World world, Random rand, int i, int j, int k) {
		world.setBlock(i + 8, j + 7, k + 22, Blocks.stonebrick);
		world.setBlock(i + 8, j + 8, k + 0, Blocks.stonebrick);
		world.setBlock(i + 8, j + 8, k + 1, Blocks.cobblestone);
		world.setBlock(i + 8, j + 8, k + 2, Blocks.cobblestone);
		world.setBlock(i + 8, j + 8, k + 3, Blocks.cobblestone);
		world.setBlock(i + 8, j + 8, k + 4, Blocks.cobblestone);
		world.setBlock(i + 8, j + 8, k + 5, Blocks.cobblestone);
		world.setBlock(i + 8, j + 8, k + 6, Blocks.cobblestone);
		world.setBlock(i + 8, j + 8, k + 7, Blocks.cobblestone);
		world.setBlock(i + 8, j + 8, k + 8, Blocks.cobblestone);
		world.setBlock(i + 8, j + 8, k + 9, Blocks.cobblestone);
		world.setBlock(i + 8, j + 8, k + 10, Blocks.cobblestone);
		world.setBlock(i + 8, j + 8, k + 11, Blocks.stonebrick);
		world.setBlock(i + 8, j + 8, k + 12, Blocks.cobblestone);
		world.setBlock(i + 8, j + 8, k + 13, Blocks.cobblestone);
		world.setBlock(i + 8, j + 8, k + 14, Blocks.cobblestone);
		world.setBlock(i + 8, j + 8, k + 15, Blocks.cobblestone);
		world.setBlock(i + 8, j + 8, k + 16, Blocks.cobblestone);
		world.setBlock(i + 8, j + 8, k + 17, Blocks.cobblestone);
		world.setBlock(i + 8, j + 8, k + 18, Blocks.cobblestone);
		world.setBlock(i + 8, j + 8, k + 19, Blocks.cobblestone);
		world.setBlock(i + 8, j + 8, k + 20, Blocks.cobblestone);
		world.setBlock(i + 8, j + 8, k + 21, Blocks.cobblestone);
		world.setBlock(i + 8, j + 8, k + 22, Blocks.stonebrick);
		world.setBlock(i + 8, j + 9, k + 0, Blocks.stonebrick);
		world.setBlock(i + 8, j + 9, k + 2, Blocks.stonebrick);
		world.setBlock(i + 8, j + 9, k + 3, Blocks.air);
		world.setBlock(i + 8, j + 9, k + 4, Blocks.air);
		world.setBlock(i + 8, j + 9, k + 5, Blocks.air);
		world.setBlock(i + 8, j + 9, k + 6, Blocks.air);
		world.setBlock(i + 8, j + 9, k + 7, Blocks.air);
		world.setBlock(i + 8, j + 9, k + 8, Blocks.stonebrick);
		world.setBlock(i + 8, j + 9, k + 22, Blocks.stonebrick);
		world.setBlock(i + 8, j + 10, k + 2, Blocks.stonebrick);
		world.setBlock(i + 8, j + 10, k + 3, Blocks.air);
		world.setBlock(i + 8, j + 10, k + 4, Blocks.air);
		world.setBlock(i + 8, j + 10, k + 5, Blocks.air);
		world.setBlock(i + 8, j + 10, k + 6, Blocks.air);
		world.setBlock(i + 8, j + 10, k + 7, Blocks.air);
		world.setBlock(i + 8, j + 10, k + 8, Blocks.stonebrick);
		world.setBlock(i + 8, j + 11, k + 2, Blocks.stonebrick);
		world.setBlock(i + 8, j + 11, k + 3, Blocks.air);
		world.setBlock(i + 8, j + 11, k + 4, Blocks.air);
		world.setBlock(i + 8, j + 11, k + 5, Blocks.air);
		world.setBlock(i + 8, j + 11, k + 6, Blocks.air);
		world.setBlock(i + 8, j + 11, k + 7, Blocks.air);
		world.setBlock(i + 8, j + 11, k + 8, Blocks.stonebrick);
		world.setBlock(i + 8, j + 12, k + 2, Blocks.stonebrick);
		world.setBlock(i + 8, j + 12, k + 3, Blocks.cobblestone);
		world.setBlock(i + 8, j + 12, k + 4, Blocks.cobblestone);
		world.setBlock(i + 8, j + 12, k + 5, Blocks.cobblestone);
		world.setBlock(i + 8, j + 12, k + 6, Blocks.cobblestone);
		world.setBlock(i + 8, j + 12, k + 7, Blocks.cobblestone);
		world.setBlock(i + 8, j + 12, k + 8, Blocks.stonebrick);
		world.setBlock(i + 8, j + 13, k + 2,
				Blocks.stone_slab, 3, 1 | (1<<1));
		world.setBlock(i + 8, j + 13, k + 8,
				Blocks.stone_slab, 3, 1 | (1<<1));
		world.setBlock(i + 9, j + 0, k + 0, Blocks.cobblestone);
		world.setBlock(i + 9, j + 0, k + 1, Blocks.cobblestone);
		world.setBlock(i + 9, j + 0, k + 2, Blocks.cobblestone);
		world.setBlock(i + 9, j + 0, k + 3, Blocks.cobblestone);
		world.setBlock(i + 9, j + 0, k + 4, Blocks.cobblestone);
		world.setBlock(i + 9, j + 0, k + 5, Blocks.cobblestone);
		world.setBlock(i + 9, j + 0, k + 6, Blocks.cobblestone);
		world.setBlock(i + 9, j + 0, k + 7, Blocks.cobblestone);
		world.setBlock(i + 9, j + 0, k + 8, Blocks.cobblestone);
		world.setBlock(i + 9, j + 0, k + 9, Blocks.cobblestone);
		world.setBlock(i + 9, j + 0, k + 10, Blocks.cobblestone);
		world.setBlock(i + 9, j + 0, k + 11, Blocks.cobblestone);
		world.setBlock(i + 9, j + 0, k + 12, Blocks.cobblestone);
		world.setBlock(i + 9, j + 0, k + 13, Blocks.cobblestone);
		world.setBlock(i + 9, j + 0, k + 14, Blocks.cobblestone);
		world.setBlock(i + 9, j + 0, k + 15, Blocks.cobblestone);
		world.setBlock(i + 9, j + 0, k + 16, Blocks.cobblestone);
		world.setBlock(i + 9, j + 0, k + 17, Blocks.cobblestone);
		world.setBlock(i + 9, j + 0, k + 18, Blocks.cobblestone);
		world.setBlock(i + 9, j + 0, k + 19, Blocks.cobblestone);
		world.setBlock(i + 9, j + 0, k + 20, Blocks.cobblestone);
		world.setBlock(i + 9, j + 0, k + 21, Blocks.cobblestone);
		world.setBlock(i + 9, j + 0, k + 22, Blocks.cobblestone);
		world.setBlock(i + 9, j + 0, k + 23, Blocks.cobblestone);
		world.setBlock(i + 9, j + 0, k + 24, Blocks.cobblestone);
		world.setBlock(i + 9, j + 0, k + 25, Blocks.cobblestone);
		world.setBlock(i + 9, j + 0, k + 26, Blocks.cobblestone);
		world.setBlock(i + 9, j + 1, k + 0, Blocks.stonebrick);
		world.setBlock(i + 9, j + 1, k + 1, Blocks.air);
		world.setBlock(i + 9, j + 1, k + 2, Blocks.air);
		world.setBlock(i + 9, j + 1, k + 3, Blocks.air);
		world.setBlock(i + 9, j + 1, k + 4, Blocks.air);
		world.setBlock(i + 9, j + 1, k + 5, Blocks.air);
		world.setBlock(i + 9, j + 1, k + 6, Blocks.air);
		world.setBlock(i + 9, j + 1, k + 7, Blocks.air);
		world.setBlock(i + 9, j + 1, k + 8, Blocks.iron_bars);
		world.setBlock(i + 9, j + 1, k + 9, Blocks.air);
		world.setBlock(i + 9, j + 1, k + 10, Blocks.air);
		world.setBlock(i + 9, j + 1, k + 11, Blocks.air);
		world.setBlock(i + 9, j + 1, k + 12, Blocks.air);
		world.setBlock(i + 9, j + 1, k + 13, Blocks.stonebrick);
		world.setBlock(i + 9, j + 1, k + 14, Blocks.air);
		world.setBlock(i + 9, j + 1, k + 15, Blocks.air);
		world.setBlock(i + 9, j + 1, k + 16, Blocks.mob_spawner);
        TileEntityMobSpawner var19 = (TileEntityMobSpawner)world.getTileEntity(i + 9, j + 1, k + 16);

        if (var19 != null)
        {
            var19.func_145881_a().setEntityName("Black Knight");
        }
		world.setBlock(i + 9, j + 1, k + 17, Blocks.air);
		world.setBlock(i + 9, j + 1, k + 18, Blocks.air);
		world.setBlock(i + 9, j + 1, k + 19, Blocks.air);
		world.setBlock(i + 9, j + 1, k + 20, Blocks.air);
		world.setBlock(i + 9, j + 1, k + 21, Blocks.air);
		world.setBlock(i + 9, j + 1, k + 22, Blocks.air);
		world.setBlock(i + 9, j + 1, k + 23, Blocks.mob_spawner);
        var19 = (TileEntityMobSpawner)world.getTileEntity(i + 9, j + 1, k + 23);

        if (var19 != null)
        {
            var19.func_145881_a().setEntityName("Black Knight");
        }
		world.setBlock(i + 9, j + 1, k + 24, Blocks.air);
		world.setBlock(i + 9, j + 1, k + 25, Blocks.air);
		world.setBlock(i + 9, j + 1, k + 26, Blocks.stonebrick);
		world.setBlock(i + 9, j + 2, k + 0, Blocks.stonebrick);
		world.setBlock(i + 9, j + 2, k + 1, Blocks.air);
		world.setBlock(i + 9, j + 2, k + 2, Blocks.air);
		world.setBlock(i + 9, j + 2, k + 3, Blocks.air);
		world.setBlock(i + 9, j + 2, k + 4, Blocks.air);
		world.setBlock(i + 9, j + 2, k + 5, Blocks.air);
		world.setBlock(i + 9, j + 2, k + 6, Blocks.air);
		world.setBlock(i + 9, j + 2, k + 7, Blocks.air);
		world.setBlock(i + 9, j + 2, k + 8, Blocks.iron_bars);
		world.setBlock(i + 9, j + 2, k + 9, Blocks.air);
		world.setBlock(i + 9, j + 2, k + 10, Blocks.air);
		world.setBlock(i + 9, j + 2, k + 11, Blocks.air);
		world.setBlock(i + 9, j + 2, k + 12, Blocks.air);
		world.setBlock(i + 9, j + 2, k + 13, Blocks.stonebrick);
		world.setBlock(i + 9, j + 2, k + 14, Blocks.air);
		world.setBlock(i + 9, j + 2, k + 15, Blocks.air);
		world.setBlock(i + 9, j + 2, k + 16, Blocks.air);
		world.setBlock(i + 9, j + 2, k + 17, Blocks.air);
		world.setBlock(i + 9, j + 2, k + 18, Blocks.air);
		world.setBlock(i + 9, j + 2, k + 19, Blocks.air);
		world.setBlock(i + 9, j + 2, k + 20, Blocks.air);
		world.setBlock(i + 9, j + 2, k + 21, Blocks.air);
		world.setBlock(i + 9, j + 2, k + 22, Blocks.air);
		world.setBlock(i + 9, j + 2, k + 23, Blocks.air);
		world.setBlock(i + 9, j + 2, k + 24, Blocks.air);
		world.setBlock(i + 9, j + 2, k + 25, Blocks.air);
		world.setBlock(i + 9, j + 2, k + 26, Blocks.stonebrick);
		world.setBlock(i + 9, j + 3, k + 0, Blocks.stonebrick);
		world.setBlock(i + 9, j + 3, k + 1, Blocks.air);
		world.setBlock(i + 9, j + 3, k + 2, Blocks.air);
		world.setBlock(i + 9, j + 3, k + 3, Blocks.air);
		world.setBlock(i + 9, j + 3, k + 4, Blocks.air);
		world.setBlock(i + 9, j + 3, k + 5, Blocks.air);
		world.setBlock(i + 9, j + 3, k + 6, Blocks.air);
		world.setBlock(i + 9, j + 3, k + 7, Blocks.air);
		world.setBlock(i + 9, j + 3, k + 8, Blocks.iron_bars);
		world.setBlock(i + 9, j + 3, k + 9, Blocks.air);
		world.setBlock(i + 9, j + 3, k + 10, Blocks.air);
		world.setBlock(i + 9, j + 3, k + 11, Blocks.air);
		world.setBlock(i + 9, j + 3, k + 12, Blocks.air);
		world.setBlock(i + 9, j + 3, k + 13, Blocks.stonebrick);
		world.setBlock(i + 9, j + 3, k + 14, Blocks.air);
		world.setBlock(i + 9, j + 3, k + 15, Blocks.air);
		world.setBlock(i + 9, j + 3, k + 16, Blocks.air);
		world.setBlock(i + 9, j + 3, k + 17, Blocks.air);
		world.setBlock(i + 9, j + 3, k + 18, Blocks.air);
		world.setBlock(i + 9, j + 3, k + 19, Blocks.air);
		world.setBlock(i + 9, j + 3, k + 20, Blocks.air);
		world.setBlock(i + 9, j + 3, k + 21, Blocks.air);
		world.setBlock(i + 9, j + 3, k + 22, Blocks.air);
		world.setBlock(i + 9, j + 3, k + 23, Blocks.air);
		world.setBlock(i + 9, j + 3, k + 24, Blocks.air);
		world.setBlock(i + 9, j + 3, k + 25, Blocks.air);
		world.setBlock(i + 9, j + 3, k + 26, Blocks.stonebrick);
		world.setBlock(i + 9, j + 4, k + 0, Blocks.stonebrick);
		world.setBlock(i + 9, j + 4, k + 1, Blocks.cobblestone);
		world.setBlock(i + 9, j + 4, k + 2, Blocks.cobblestone);
		world.setBlock(i + 9, j + 4, k + 3, Blocks.cobblestone);
		world.setBlock(i + 9, j + 4, k + 4, Blocks.cobblestone);
		world.setBlock(i + 9, j + 4, k + 5, Blocks.cobblestone);
		world.setBlock(i + 9, j + 4, k + 6, Blocks.cobblestone);
		world.setBlock(i + 9, j + 4, k + 7, Blocks.cobblestone);
		world.setBlock(i + 9, j + 4, k + 8, Blocks.cobblestone);
		world.setBlock(i + 9, j + 4, k + 9, Blocks.cobblestone);
		world.setBlock(i + 9, j + 4, k + 10, Blocks.cobblestone);
		world.setBlock(i + 9, j + 4, k + 11, Blocks.cobblestone);
		world.setBlock(i + 9, j + 4, k + 12, Blocks.cobblestone);
		world.setBlock(i + 9, j + 4, k + 13, Blocks.stonebrick);
		world.setBlock(i + 9, j + 4, k + 14, Blocks.cobblestone);
		world.setBlock(i + 9, j + 4, k + 15, Blocks.cobblestone);
		world.setBlock(i + 9, j + 4, k + 16, Blocks.cobblestone);
		world.setBlock(i + 9, j + 4, k + 17, Blocks.cobblestone);
		world.setBlock(i + 9, j + 4, k + 18, Blocks.cobblestone);
		world.setBlock(i + 9, j + 4, k + 19, Blocks.cobblestone);
		world.setBlock(i + 9, j + 4, k + 20, Blocks.cobblestone);
		world.setBlock(i + 9, j + 4, k + 21, Blocks.cobblestone);
		world.setBlock(i + 9, j + 4, k + 22, Blocks.cobblestone);
		world.setBlock(i + 9, j + 4, k + 23, Blocks.cobblestone);
		world.setBlock(i + 9, j + 4, k + 24, Blocks.cobblestone);
		world.setBlock(i + 9, j + 4, k + 25, Blocks.cobblestone);
		world.setBlock(i + 9, j + 4, k + 26, Blocks.stonebrick);
		world.setBlock(i + 9, j + 5, k + 0, Blocks.stonebrick);
		world.setBlock(i + 9, j + 5, k + 1, Blocks.bookshelf);
		world.setBlock(i + 9, j + 5, k + 2, Blocks.planks);
		world.setBlock(i + 9, j + 5, k + 3, Blocks.air);
		world.setBlock(i + 9, j + 5, k + 4, Blocks.air);
		world.setBlock(i + 9, j + 5, k + 5, Blocks.air);
		world.setBlock(i + 9, j + 5, k + 6, Blocks.planks);
		world.setBlock(i + 9, j + 5, k + 7, Blocks.air);
		world.setBlock(i + 9, j + 5, k + 8, Blocks.air);
		world.setBlock(i + 9, j + 5, k + 9, Blocks.air);
		world.setBlock(i + 9, j + 5, k + 10, Blocks.bookshelf);
		world.setBlock(i + 9, j + 5, k + 11, Blocks.stonebrick);
		world.setBlock(i + 9, j + 5, k + 12, Blocks.wool, 14, 1 | (1<<1));
		world.setBlock(i + 9, j + 5, k + 13, Blocks.wool, 14, 1 | (1<<1));
		world.setBlock(i + 9, j + 5, k + 14, Blocks.air);
		world.setBlock(i + 9, j + 5, k + 15, Blocks.air);
		world.setBlock(i + 9, j + 5, k + 16, Blocks.planks);
		world.setBlock(i + 9, j + 5, k + 17, Blocks.planks);
		world.setBlock(i + 9, j + 5, k + 18, Blocks.air);
		world.setBlock(i + 9, j + 5, k + 19, Blocks.air);
		world.setBlock(i + 9, j + 5, k + 20, Blocks.air);
		world.setBlock(i + 9, j + 5, k + 21, Blocks.air);
		world.setBlock(i + 9, j + 5, k + 22, Blocks.air);
		world.setBlock(i + 9, j + 5, k + 23, Blocks.stonebrick);
		world.setBlock(i + 9, j + 5, k + 24, Blocks.air);
		world.setBlock(i + 9, j + 5, k + 25, Blocks.air);
		world.setBlock(i + 9, j + 5, k + 26, Blocks.stonebrick);
		world.setBlock(i + 9, j + 6, k + 0, Blocks.stonebrick);
		world.setBlock(i + 9, j + 6, k + 1, Blocks.bookshelf);
		world.setBlock(i + 9, j + 6, k + 2, Blocks.air);
		world.setBlock(i + 9, j + 6, k + 3, Blocks.air);
		world.setBlock(i + 9, j + 6, k + 4, Blocks.air);
		world.setBlock(i + 9, j + 6, k + 5, Blocks.air);
		world.setBlock(i + 9, j + 6, k + 6, Blocks.air);
		world.setBlock(i + 9, j + 6, k + 7, Blocks.air);
		world.setBlock(i + 9, j + 6, k + 8, Blocks.air);
		world.setBlock(i + 9, j + 6, k + 9, Blocks.air);
		world.setBlock(i + 9, j + 6, k + 10, Blocks.bookshelf);
		world.setBlock(i + 9, j + 6, k + 11, Blocks.stonebrick);
		world.setBlock(i + 9, j + 6, k + 12, Blocks.air);
		world.setBlock(i + 9, j + 6, k + 13, Blocks.air);
		world.setBlock(i + 9, j + 6, k + 14, Blocks.air);
		world.setBlock(i + 9, j + 6, k + 15, Blocks.air);
		world.setBlock(i + 9, j + 6, k + 16, Blocks.air);
		world.setBlock(i + 9, j + 6, k + 17, Blocks.air);
		world.setBlock(i + 9, j + 6, k + 18, Blocks.air);
		world.setBlock(i + 9, j + 6, k + 19, Blocks.air);
		world.setBlock(i + 9, j + 6, k + 20, Blocks.air);
		world.setBlock(i + 9, j + 6, k + 21, Blocks.air);
		world.setBlock(i + 9, j + 6, k + 22, Blocks.air);
		world.setBlock(i + 9, j + 6, k + 23, Blocks.stonebrick);
		world.setBlock(i + 9, j + 7, k + 0, Blocks.stonebrick);
		world.setBlock(i + 9, j + 7, k + 1, Blocks.air);
		world.setBlock(i + 9, j + 7, k + 2, Blocks.air);
		world.setBlock(i + 9, j + 7, k + 3, Blocks.air);
		world.setBlock(i + 9, j + 7, k + 4, Blocks.air);
		world.setBlock(i + 9, j + 7, k + 5, Blocks.air);
		world.setBlock(i + 9, j + 7, k + 6, Blocks.air);
		world.setBlock(i + 9, j + 7, k + 7, Blocks.air);
		world.setBlock(i + 9, j + 7, k + 8, Blocks.air);
		world.setBlock(i + 9, j + 7, k + 9, Blocks.air);
		world.setBlock(i + 9, j + 7, k + 10, Blocks.air);
		world.setBlock(i + 9, j + 7, k + 11, Blocks.stonebrick);
		world.setBlock(i + 9, j + 7, k + 12, Blocks.air);
		world.setBlock(i + 9, j + 7, k + 13, Blocks.air);
		world.setBlock(i + 9, j + 7, k + 14, Blocks.air);
		world.setBlock(i + 9, j + 7, k + 15, Blocks.air);
		world.setBlock(i + 9, j + 7, k + 16, Blocks.air);
		world.setBlock(i + 9, j + 7, k + 17, Blocks.air);
		world.setBlock(i + 9, j + 7, k + 18, Blocks.air);
		world.setBlock(i + 9, j + 7, k + 19, Blocks.air);
		world.setBlock(i + 9, j + 7, k + 20, Blocks.air);
		world.setBlock(i + 9, j + 7, k + 21, Blocks.air);
		world.setBlock(i + 9, j + 7, k + 22, Blocks.air);
		world.setBlock(i + 9, j + 7, k + 23, Blocks.stonebrick);
		world.setBlock(i + 9, j + 8, k + 0, Blocks.stonebrick);
		world.setBlock(i + 9, j + 8, k + 1, Blocks.cobblestone);
		world.setBlock(i + 9, j + 8, k + 2, Blocks.cobblestone);
		world.setBlock(i + 9, j + 8, k + 3, Blocks.cobblestone);
		world.setBlock(i + 9, j + 8, k + 4, Blocks.cobblestone);
		world.setBlock(i + 9, j + 8, k + 5, Blocks.cobblestone);
		world.setBlock(i + 9, j + 8, k + 6, Blocks.cobblestone);
		world.setBlock(i + 9, j + 8, k + 7, Blocks.cobblestone);
		world.setBlock(i + 9, j + 8, k + 8, Blocks.cobblestone);
		world.setBlock(i + 9, j + 8, k + 9, Blocks.cobblestone);
		world.setBlock(i + 9, j + 8, k + 10, Blocks.cobblestone);
		world.setBlock(i + 9, j + 8, k + 11, Blocks.stonebrick);
		world.setBlock(i + 9, j + 8, k + 12, Blocks.cobblestone);
		world.setBlock(i + 9, j + 8, k + 13, Blocks.cobblestone);
		world.setBlock(i + 9, j + 8, k + 14, Blocks.cobblestone);
		world.setBlock(i + 9, j + 8, k + 15, Blocks.cobblestone);
		world.setBlock(i + 9, j + 8, k + 16, Blocks.cobblestone);
		world.setBlock(i + 9, j + 8, k + 17, Blocks.cobblestone);
		world.setBlock(i + 9, j + 8, k + 18, Blocks.cobblestone);
		world.setBlock(i + 9, j + 8, k + 19, Blocks.cobblestone);
		world.setBlock(i + 9, j + 8, k + 20, Blocks.cobblestone);
		world.setBlock(i + 9, j + 8, k + 21, Blocks.cobblestone);
		world.setBlock(i + 9, j + 8, k + 22, Blocks.cobblestone);
		world.setBlock(i + 9, j + 8, k + 23, Blocks.stonebrick);
		world.setBlock(i + 9, j + 9, k + 0,
				Blocks.stone_slab, 3, 1 | (1<<1));
		world.setBlock(i + 9, j + 9, k + 3, Blocks.stonebrick);
		world.setBlock(i + 9, j + 9, k + 4, Blocks.air);
		world.setBlock(i + 9, j + 9, k + 5, Blocks.air);
		world.setBlock(i + 9, j + 9, k + 6, Blocks.air);
		world.setBlock(i + 9, j + 9, k + 7, Blocks.stonebrick);
		world.setBlock(i + 9, j + 9, k + 12, Blocks.mob_spawner);
        var19 = (TileEntityMobSpawner)world.getTileEntity(i + 9, j + 9, k + 12);

        if (var19 != null)
        {
            var19.func_145881_a().setEntityName("Black Knight");
        }
		world.setBlock(i + 9, j + 9, k + 23,
				Blocks.stone_slab, 3, 1 | (1<<1));
		world.setBlock(i + 9, j + 10, k + 3, Blocks.stonebrick);
		world.setBlock(i + 9, j + 10, k + 4, Blocks.air);
		world.setBlock(i + 9, j + 10, k + 6, Blocks.air);
		world.setBlock(i + 9, j + 10, k + 7, Blocks.stonebrick);
		world.setBlock(i + 9, j + 11, k + 3, Blocks.stonebrick);
		world.setBlock(i + 9, j + 11, k + 4, Blocks.air);
		world.setBlock(i + 9, j + 11, k + 5, Blocks.air);
		world.setBlock(i + 9, j + 11, k + 6, Blocks.air);
