/*
*** MADE BY MITHION'S .SCHEMATIC TO JAVA CONVERTING TOOL v1.6 ***
*/

package wildycraft.structures;
import java.util.Random;

import wildycraft.Wildycraft;
import wildycraft.entity.EntityDarkWizard;

import net.minecraft.entity.EntityLiving;
import net.minecraft.entity.IEntityLivingData;
import net.minecraft.init.Blocks;
import net.minecraft.init.Items;
import net.minecraft.item.Item;
import net.minecraft.item.ItemStack;
import net.minecraft.tileentity.TileEntityChest;
import net.minecraft.tileentity.TileEntityMobSpawner;
import net.minecraft.util.MathHelper;
import net.minecraft.util.WeightedRandomChestContent;
import net.minecraft.world.World;
import net.minecraft.world.gen.feature.WorldGenerator;
import net.minecraftforge.common.ChestGenHooks;

public class DarkWizardsTower extends WorldGenerator
{
	public DarkWizardsTower() { }

	public boolean generate(World world, Random rand, int x, int y, int z) {
		
		for (int i = 0; i < 11; i++){
			for (int j = 0; j < 11; j++){
				for (int k = 1; k < 20; k++){
					world.setBlock(x + i, y + k, z + j, Blocks.air);
				}
			}
		}
		generateS(world,rand,x,y,z);
		return true;
	}
	
	public boolean generateS(World world, Random rand, int i, int j, int k) {
		world.setBlock(i + 0, j + 1, k + 0, Blocks.cobblestone_wall, 1, 4);
		world.setBlock(i + 0, j + 1, k + 1, Blocks.cobblestone_wall, 1, 4);
		world.setBlock(i + 0, j + 1, k + 2, Blocks.cobblestone_wall, 1, 4);
		world.setBlock(i + 0, j + 1, k + 3, Blocks.cobblestone_wall, 1, 4);
		world.setBlock(i + 0, j + 1, k + 4, Blocks.cobblestone_wall, 1, 4);
		world.setBlock(i + 0, j + 1, k + 5, Blocks.cobblestone_wall, 1, 4);
		world.setBlock(i + 0, j + 1, k + 6, Blocks.cobblestone_wall, 1, 4);
		world.setBlock(i + 0, j + 1, k + 7, Blocks.cobblestone_wall, 1, 4);
		world.setBlock(i + 0, j + 1, k + 8, Blocks.cobblestone_wall, 1, 4);
		world.setBlock(i + 0, j + 1, k + 9, Blocks.cobblestone_wall, 1, 4);
		world.setBlock(i + 0, j + 1, k + 10, Blocks.cobblestone_wall, 1, 4);
		world.setBlock(i + 0, j + 1, k + 11, Blocks.cobblestone_wall, 1, 4);
		world.setBlock(i + 0, j + 2, k + 0, Blocks.cobblestone_wall, 1, 4);
		world.setBlock(i + 0, j + 2, k + 1, Blocks.cobblestone_wall, 1, 4);
		world.setBlock(i + 0, j + 2, k + 2, Blocks.cobblestone_wall, 1, 4);
		world.setBlock(i + 0, j + 2, k + 3, Blocks.cobblestone_wall, 1, 4);
		world.setBlock(i + 0, j + 2, k + 5, Blocks.cobblestone_wall, 1, 4);
		world.setBlock(i + 0, j + 2, k + 6, Blocks.cobblestone_wall, 1, 4);
		world.setBlock(i + 0, j + 2, k + 7, Blocks.cobblestone_wall, 1, 4);
		world.setBlock(i + 0, j + 2, k + 8, Blocks.cobblestone_wall, 1, 4);
		world.setBlock(i + 0, j + 2, k + 9, Blocks.cobblestone_wall, 1, 4);
		world.setBlock(i + 0, j + 2, k + 10, Blocks.cobblestone_wall, 1, 4);
		world.setBlock(i + 0, j + 2, k + 11, Blocks.cobblestone_wall, 1, 4);
		world.setBlock(i + 0, j + 8, k + 4, Blocks.stone_slab, 6, 4);
		world.setBlock(i + 0, j + 8, k + 5, Blocks.nether_brick_stairs);
		world.setBlock(i + 0, j + 8, k + 6, Blocks.nether_brick_stairs);
		world.setBlock(i + 0, j + 8, k + 7, Blocks.stone_slab, 6, 4);
		world.setBlock(i + 1, j + 1, k + 0, Blocks.cobblestone_wall, 1, 4);
		world.setBlock(i + 1, j + 1, k + 1, Blocks.stonebrick, 1, 4);
		world.setBlock(i + 1, j + 1, k + 2, Blocks.stonebrick, 1, 4);
		world.setBlock(i + 1, j + 1, k + 3, Blocks.stonebrick, 1, 4);
		world.setBlock(i + 1, j + 1, k + 5, Blocks.stonebrick);
		world.setBlock(i + 1, j + 1, k + 6, Blocks.stonebrick);
		world.setBlock(i + 1, j + 1, k + 7, Blocks.stonebrick);
		world.setBlock(i + 1, j + 1, k + 8, Blocks.stonebrick, 1, 4);
		world.setBlock(i + 1, j + 1, k + 9, Blocks.stonebrick, 1, 4);
		world.setBlock(i + 1, j + 1, k + 10, Blocks.stonebrick, 1, 4);
		world.setBlock(i + 1, j + 1, k + 11, Blocks.cobblestone_wall, 1, 4);
		world.setBlock(i + 1, j + 2, k + 0, Blocks.cobblestone_wall, 1, 4);
		world.setBlock(i + 1, j + 2, k + 1, Blocks.stonebrick, 1, 4);
		world.setBlock(i + 1, j + 2, k + 2, Blocks.stonebrick, 1, 4);
		world.setBlock(i + 1, j + 2, k + 3, Blocks.stonebrick, 1, 4);
		world.setBlock(i + 1, j + 2, k + 5, Blocks.stonebrick);
		world.setBlock(i + 1, j + 2, k + 6, Blocks.stonebrick);
		world.setBlock(i + 1, j + 2, k + 7, Blocks.stonebrick);
		world.setBlock(i + 1, j + 2, k + 8, Blocks.stonebrick, 1, 4);
		world.setBlock(i + 1, j + 2, k + 9, Blocks.stonebrick, 1, 4);
		world.setBlock(i + 1, j + 2, k + 10, Blocks.stonebrick, 1, 4);
		world.setBlock(i + 1, j + 2, k + 11, Blocks.cobblestone_wall, 1, 4);
		world.setBlock(i + 1, j + 3, k + 3, Blocks.iron_bars);
		world.setBlock(i + 1, j + 3, k + 4, Blocks.stonebrick);
		world.setBlock(i + 1, j + 3, k + 5, Blocks.stonebrick);
		world.setBlock(i + 1, j + 3, k + 6, Blocks.stonebrick);
		world.setBlock(i + 1, j + 3, k + 7, Blocks.stonebrick);
		world.setBlock(i + 1, j + 3, k + 8, Blocks.iron_bars);
		world.setBlock(i + 1, j + 4, k + 1, Blocks.stonebrick, 1, 4);
		world.setBlock(i + 1, j + 4, k + 2, Blocks.stonebrick, 1, 4);
		world.setBlock(i + 1, j + 4, k + 3, Blocks.stonebrick, 1, 4);
		world.setBlock(i + 1, j + 4, k + 4, Blocks.stonebrick, 1, 4);
		world.setBlock(i + 1, j + 4, k + 5, Blocks.stonebrick, 1, 4);
		world.setBlock(i + 1, j + 4, k + 6, Blocks.stonebrick, 1, 4);
		world.setBlock(i + 1, j + 4, k + 7, Blocks.stonebrick, 1, 4);
		world.setBlock(i + 1, j + 4, k + 8, Blocks.stonebrick, 1, 4);
		world.setBlock(i + 1, j + 4, k + 9, Blocks.stonebrick, 1, 4);
		world.setBlock(i + 1, j + 4, k + 10, Blocks.stonebrick, 1, 4);
		world.setBlock(i + 1, j + 5, k + 1, Blocks.stonebrick, 1, 4);
		world.setBlock(i + 1, j + 5, k + 2, Blocks.stonebrick, 1, 4);
		world.setBlock(i + 1, j + 5, k + 3, Blocks.stonebrick, 1, 4);
		world.setBlock(i + 1, j + 5, k + 4, Blocks.stonebrick, 1, 4);
		world.setBlock(i + 1, j + 5, k + 5, Blocks.nether_brick);
		world.setBlock(i + 1, j + 5, k + 6, Blocks.nether_brick);
		world.setBlock(i + 1, j + 5, k + 7, Blocks.stonebrick, 1, 4);
		world.setBlock(i + 1, j + 5, k + 8, Blocks.stonebrick, 1, 4);
		world.setBlock(i + 1, j + 5, k + 9, Blocks.stonebrick, 1, 4);
		world.setBlock(i + 1, j + 5, k + 10, Blocks.stonebrick, 1, 4);
		world.setBlock(i + 1, j + 6, k + 4, Blocks.nether_brick);
		world.setBlock(i + 1, j + 6, k + 5, Blocks.nether_brick);
		world.setBlock(i + 1, j + 6, k + 6, Blocks.nether_brick);
		world.setBlock(i + 1, j + 6, k + 7, Blocks.nether_brick);
		world.setBlock(i + 1, j + 7, k + 1, Blocks.stone_slab, 6, 4);
		world.setBlock(i + 1, j + 7, k + 2, Blocks.nether_brick_stairs);
		world.setBlock(i + 1, j + 7, k + 3, Blocks.nether_brick_stairs);
		world.setBlock(i + 1, j + 7, k + 4, Blocks.nether_brick);
		world.setBlock(i + 1, j + 7, k + 5, Blocks.nether_brick);
		world.setBlock(i + 1, j + 7, k + 6, Blocks.nether_brick);
		world.setBlock(i + 1, j + 7, k + 7, Blocks.nether_brick);
		world.setBlock(i + 1, j + 7, k + 8, Blocks.nether_brick_stairs);
		world.setBlock(i + 1, j + 7, k + 9, Blocks.nether_brick_stairs);
		world.setBlock(i + 1, j + 7, k + 10, Blocks.stone_slab, 6, 4);
		world.setBlock(i + 1, j + 8, k + 4, Blocks.nether_brick_stairs, 2, 4);
		world.setBlock(i + 1, j + 8, k + 5, Blocks.netherrack);
		world.setBlock(i + 1, j + 8, k + 6, Blocks.netherrack);
		world.setBlock(i + 1, j + 8, k + 7, Blocks.nether_brick_stairs, 3, 4);
		world.setBlock(i + 1, j + 9, k + 5, Blocks.fire, 15, 4);
		world.setBlock(i + 1, j + 9, k + 6, Blocks.fire, 15, 4);
		world.setBlock(i + 2, j + 0, k + 5, Blocks.stonebrick);
		world.setBlock(i + 2, j + 0, k + 6, Blocks.stonebrick);
		world.setBlock(i + 2, j + 0, k + 7, Blocks.stonebrick);
		world.setBlock(i + 2, j + 0, k + 12, Blocks.grass);
		world.setBlock(i + 2, j + 1, k + 0, Blocks.cobblestone_wall, 1, 4);
		world.setBlock(i + 2, j + 1, k + 1, Blocks.stonebrick, 1, 4);
		world.setBlock(i + 2, j + 1, k + 2, Blocks.stonebrick, 1, 4);
		world.setBlock(i + 2, j + 1, k + 3, Blocks.stonebrick, 1, 4);
		world.setBlock(i + 2, j + 1, k + 4, Blocks.stonebrick);
		world.setBlock(i + 2, j + 1, k + 8, Blocks.stonebrick);
		world.setBlock(i + 2, j + 1, k + 9, Blocks.stonebrick, 1, 4);
		world.setBlock(i + 2, j + 1, k + 10, Blocks.stonebrick, 1, 4);
		world.setBlock(i + 2, j + 1, k + 11, Blocks.cobblestone_wall, 1, 4);
		world.setBlock(i + 2, j + 2, k + 0, Blocks.cobblestone_wall, 1, 4);
		world.setBlock(i + 2, j + 2, k + 1, Blocks.stonebrick, 1, 4);
		world.setBlock(i + 2, j + 2, k + 3, Blocks.stonebrick, 1, 4);
		world.setBlock(i + 2, j + 2, k + 4, Blocks.stonebrick);
		world.setBlock(i + 2, j + 2, k + 8, Blocks.stonebrick);
		world.setBlock(i + 2, j + 2, k + 10, Blocks.stonebrick, 1, 4);
		world.setBlock(i + 2, j + 2, k + 11, Blocks.cobblestone_wall, 1, 4);
		world.setBlock(i + 2, j + 3, k + 3, Blocks.stonebrick, 1, 4);
		world.setBlock(i + 2, j + 3, k + 4, Blocks.stonebrick);
		world.setBlock(i + 2, j + 3, k + 8, Blocks.stonebrick);
		world.setBlock(i + 2, j + 4, k + 1, Blocks.stonebrick, 1, 4);
		world.setBlock(i + 2, j + 4, k + 2, Blocks.stonebrick, 1, 4);
		world.setBlock(i + 2, j + 4, k + 3, Blocks.stonebrick, 1, 4);
		world.setBlock(i + 2, j + 4, k + 4, Blocks.stonebrick, 1, 4);
		world.setBlock(i + 2, j + 4, k + 5, Blocks.stonebrick, 1, 4);
		world.setBlock(i + 2, j + 4, k + 6, Blocks.stonebrick, 1, 4);
		world.setBlock(i + 2, j + 4, k + 7, Blocks.stonebrick, 1, 4);
		world.setBlock(i + 2, j + 4, k + 8, Blocks.stonebrick, 1, 4);
		world.setBlock(i + 2, j + 4, k + 9, Blocks.stonebrick, 1, 4);
		world.setBlock(i + 2, j + 4, k + 10, Blocks.stonebrick, 1, 4);
		world.setBlock(i + 2, j + 5, k + 1, Blocks.stonebrick, 1, 4);
		world.setBlock(i + 2, j + 5, k + 3, Blocks.stonebrick, 1, 4);
		world.setBlock(i + 2, j + 5, k + 8, Blocks.stonebrick, 1, 4);
		world.setBlock(i + 2, j + 5, k + 10, Blocks.stonebrick, 1, 4);
		world.setBlock(i + 2, j + 7, k + 1, Blocks.nether_brick_stairs, 2, 4);
		world.setBlock(i + 2, j + 7, k + 2, Blocks.stonebrick, 1, 4);
		world.setBlock(i + 2, j + 7, k + 3, Blocks.stonebrick, 1, 4);
		world.setBlock(i + 2, j + 7, k + 4, Blocks.stonebrick, 1, 4);
		world.setBlock(i + 2, j + 7, k + 5, Blocks.stonebrick, 1, 4);
		world.setBlock(i + 2, j + 7, k + 6, Blocks.stonebrick, 1, 4);
		world.setBlock(i + 2, j + 7, k + 7, Blocks.stonebrick, 1, 4);
		world.setBlock(i + 2, j + 7, k + 8, Blocks.stonebrick, 1, 4);
		world.setBlock(i + 2, j + 7, k + 9, Blocks.stonebrick, 1, 4);
		world.setBlock(i + 2, j + 7, k + 10, Blocks.nether_brick_stairs, 3, 4);
		world.setBlock(i + 2, j + 8, k + 2, Blocks.stonebrick, 1, 4);
		world.setBlock(i + 2, j + 8, k + 3, Blocks.stonebrick, 1, 4);
		world.setBlock(i + 2, j + 8, k + 4, Blocks.stonebrick, 1, 4);
		world.setBlock(i + 2, j + 8, k + 5, Blocks.stonebrick, 1, 4);
		world.setBlock(i + 2, j + 8, k + 6, Blocks.stonebrick, 1, 4);
		world.setBlock(i + 2, j + 8, k + 7, Blocks.stonebrick, 1, 4);
		world.setBlock(i + 2, j + 8, k + 8, Blocks.stonebrick, 1, 4);
		world.setBlock(i + 2, j + 8, k + 9, Blocks.stonebrick, 1, 4);
		world.setBlock(i + 2, j + 9, k + 4, Blocks.stonebrick, 1, 4);
		world.setBlock(i + 2, j + 9, k + 5, Blocks.nether_brick);
		world.setBlock(i + 2, j + 9, k + 6, Blocks.nether_brick);
		world.setBlock(i + 2, j + 9, k + 7, Blocks.stonebrick, 1, 4);
		world.setBlock(i + 2, j + 10, k + 2, Blocks.stonebrick, 1, 4);
		world.setBlock(i + 2, j + 10, k + 3, Blocks.stonebrick, 1, 4);
		world.setBlock(i + 2, j + 10, k + 4, Blocks.stonebrick, 1, 4);
		world.setBlock(i + 2, j + 10, k + 5, Blocks.nether_brick);
		world.setBlock(i + 2, j + 10, k + 6, Blocks.nether_brick);
		world.setBlock(i + 2, j + 10, k + 7, Blocks.stonebrick, 1, 4);
		world.setBlock(i + 2, j + 10, k + 8, Blocks.stonebrick, 1, 4);
		world.setBlock(i + 2, j + 10, k + 9, Blocks.stonebrick, 1, 4);
		world.setBlock(i + 2, j + 11, k + 2, Blocks.stonebrick, 1, 4);
		world.setBlock(i + 2, j + 11, k + 3, Blocks.stonebrick, 1, 4);
		world.setBlock(i + 2, j + 11, k + 4, Blocks.stonebrick, 1, 4);
		world.setBlock(i + 2, j + 11, k + 5, Blocks.stone_slab, 6, 4);
		world.setBlock(i + 2, j + 11, k + 6, Blocks.stone_slab, 6, 4);
		world.setBlock(i + 2, j + 11, k + 7, Blocks.stonebrick, 1, 4);
		world.setBlock(i + 2, j + 11, k + 8, Blocks.stonebrick, 1, 4);
		world.setBlock(i + 2, j + 11, k + 9, Blocks.stonebrick, 1, 4);
		world.setBlock(i + 3, j + 0, k + 4, Blocks.stonebrick);
		world.setBlock(i + 3, j + 0, k + 5, Blocks.stonebrick);
		world.setBlock(i + 3, j + 0, k + 6, Blocks.stonebrick);
		world.setBlock(i + 3, j + 0, k + 7, Blocks.stonebrick);
		world.setBlock(i + 3, j + 0, k + 8, Blocks.stonebrick);
		world.setBlock(i + 3, j + 1, k + 0, Blocks.cobblestone_wall, 1, 4);
		world.setBlock(i + 3, j + 1, k + 1, Blocks.stonebrick, 1, 4);
		world.setBlock(i + 3, j + 1, k + 2, Blocks.stonebrick, 1, 4);
		world.setBlock(i + 3, j + 1, k + 3, Blocks.stonebrick);
		world.setBlock(i + 3, j + 1, k + 9, Blocks.stonebrick);
		world.setBlock(i + 3, j + 1, k + 10, Blocks.stonebrick, 1, 4);
		world.setBlock(i + 3, j + 1, k + 11, Blocks.cobblestone_wall, 1, 4);
		world.setBlock(i + 3, j + 2, k + 0, Blocks.cobblestone_wall, 1, 4);
		world.setBlock(i + 3, j + 2, k + 1, Blocks.stonebrick, 1, 4);
		world.setBlock(i + 3, j + 2, k + 2, Blocks.stonebrick, 1, 4);
		world.setBlock(i + 3, j + 2, k + 3, Blocks.stonebrick);
		world.setBlock(i + 3, j + 2, k + 9, Blocks.stonebrick);
		world.setBlock(i + 3, j + 2, k + 10, Blocks.stonebrick, 1, 4);
		world.setBlock(i + 3, j + 2, k + 11, Blocks.cobblestone_wall, 1, 4);
		world.setBlock(i + 3, j + 3, k + 1, Blocks.iron_bars);
		world.setBlock(i + 3, j + 3, k + 2, Blocks.stonebrick, 1, 4);
		world.setBlock(i + 3, j + 3, k + 3, Blocks.stonebrick);
		world.setBlock(i + 3, j + 3, k + 9, Blocks.stonebrick);
		world.setBlock(i + 3, j + 3, k + 10, Blocks.iron_bars);
		world.setBlock(i + 3, j + 4, k + 1, Blocks.stonebrick, 1, 4);
		world.setBlock(i + 3, j + 4, k + 2, Blocks.stonebrick, 1, 4);
		world.setBlock(i + 3, j + 4, k + 3, Blocks.stonebrick, 1, 4);
		world.setBlock(i + 3, j + 4, k + 4, Blocks.stonebrick, 1, 4);
		world.setBlock(i + 3, j + 4, k + 5, Blocks.stonebrick, 1, 4);
		world.setBlock(i + 3, j + 4, k + 6, Blocks.stonebrick, 1, 4);
		world.setBlock(i + 3, j + 4, k + 7, Blocks.stonebrick, 1, 4);
		world.setBlock(i + 3, j + 4, k + 8, Blocks.stonebrick, 1, 4);
		world.setBlock(i + 3, j + 4, k + 9, Blocks.stonebrick, 1, 4);
		world.setBlock(i + 3, j + 4, k + 10, Blocks.stonebrick, 1, 4);
		world.setBlock(i + 3, j + 5, k + 1, Blocks.stonebrick, 1, 4);
		world.setBlock(i + 3, j + 5, k + 2, Blocks.stonebrick, 1, 4);
		world.setBlock(i + 3, j + 5, k + 9, Blocks.stonebrick, 1, 4);
		world.setBlock(i + 3, j + 5, k + 10, Blocks.stonebrick, 1, 4);
		world.setBlock(i + 3, j + 7, k + 1, Blocks.nether_brick_stairs, 2, 4);
		world.setBlock(i + 3, j + 7, k + 2, Blocks.stonebrick, 1, 4);
		world.setBlock(i + 3, j + 7, k + 3, Blocks.stonebrick, 1, 4);
		world.setBlock(i + 3, j + 7, k + 4, Blocks.stonebrick, 1, 4);
		world.setBlock(i + 3, j + 7, k + 5, Blocks.stonebrick, 1, 4);
		world.setBlock(i + 3, j + 7, k + 6, Blocks.stonebrick, 1, 4);
		world.setBlock(i + 3, j + 7, k + 7, Blocks.stonebrick, 1, 4);
		world.setBlock(i + 3, j + 7, k + 8, Blocks.stonebrick, 1, 4);
		world.setBlock(i + 3, j + 7, k + 9, Blocks.stonebrick, 1, 4);
		world.setBlock(i + 3, j + 7, k + 10, Blocks.nether_brick_stairs, 3, 4);
		world.setBlock(i + 3, j + 8, k + 2, Blocks.stonebrick, 1, 4);
		world.setBlock(i + 3, j + 8, k + 4, Blocks.stonebrick, 1, 4);
		world.setBlock(i + 3, j + 8, k + 7, Blocks.stonebrick, 1, 4);
		world.setBlock(i + 3, j + 8, k + 9, Blocks.stonebrick, 1, 4);
		world.setBlock(i + 3, j + 10, k + 2, Blocks.stonebrick, 1, 4);
		world.setBlock(i + 3, j + 10, k + 3, Blocks.stonebrick, 1, 4);
		world.setBlock(i + 3, j + 10, k + 4, Blocks.stonebrick, 1, 4);
		world.setBlock(i + 3, j + 10, k + 5, Blocks.stonebrick, 1, 4);
		world.setBlock(i + 3, j + 10, k + 6, Blocks.stonebrick, 1, 4);
		world.setBlock(i + 3, j + 10, k + 7, Blocks.stonebrick, 1, 4);
		world.setBlock(i + 3, j + 10, k + 8, Blocks.stonebrick, 1, 4);
		world.setBlock(i + 3, j + 10, k + 9, Blocks.stonebrick, 1, 4);
		world.setBlock(i + 3, j + 11, k + 2, Blocks.stonebrick, 1, 4);
		world.setBlock(i + 3, j + 11, k + 4, Blocks.stonebrick, 1, 4);
		world.setBlock(i + 3, j + 11, k + 5, Blocks.stonebrick, 1, 4);
		world.setBlock(i + 3, j + 11, k + 6, Blocks.stonebrick, 1, 4);
		world.setBlock(i + 3, j + 11, k + 7, Blocks.stonebrick, 1, 4);
		world.setBlock(i + 3, j + 11, k + 9, Blocks.stonebrick, 1, 4);
		world.setBlock(i + 3, j + 12, k + 5, Blocks.stonebrick, 1, 4);
		world.setBlock(i + 3, j + 12, k + 6, Blocks.stonebrick, 1, 4);
		world.setBlock(i + 3, j + 13, k + 3, Blocks.stonebrick, 1, 4);
		world.setBlock(i + 3, j + 13, k + 4, Blocks.stonebrick, 1, 4);
		world.setBlock(i + 3, j + 13, k + 5, Blocks.obsidian);
		world.setBlock(i + 3, j + 13, k + 6, Blocks.obsidian);
		world.setBlock(i + 3, j + 13, k + 7, Blocks.stonebrick, 1, 4);
		world.setBlock(i + 3, j + 13, k + 8, Blocks.stonebrick, 1, 4);
		world.setBlock(i + 3, j + 14, k + 5, Blocks.obsidian);
		world.setBlock(i + 3, j + 14, k + 6, Blocks.obsidian);
		world.setBlock(i + 3, j + 15, k + 5, Blocks.obsidian);
		world.setBlock(i + 3, j + 15, k + 6, Blocks.obsidian);
		world.setBlock(i + 3, j + 16, k + 5, Blocks.glass);
		world.setBlock(i + 3, j + 16, k + 6, Blocks.glass);
		world.setBlock(i + 3, j + 17, k + 5, Blocks.obsidian);
		world.setBlock(i + 3, j + 17, k + 6, Blocks.obsidian);
		world.setBlock(i + 4, j + 0, k + 3, Blocks.stonebrick);
		world.setBlock(i + 4, j + 0, k + 4, Blocks.stonebrick);
		world.setBlock(i + 4, j + 0, k + 5, Blocks.stonebrick);
		world.setBlock(i + 4, j + 0, k + 6, Blocks.stonebrick);
		world.setBlock(i + 4, j + 0, k + 7, Blocks.stonebrick);
		world.setBlock(i + 4, j + 0, k + 8, Blocks.stonebrick);
		world.setBlock(i + 4, j + 0, k + 9, Blocks.stonebrick);
		world.setBlock(i + 4, j + 1, k + 0, Blocks.cobblestone_wall, 1, 4);
		world.setBlock(i + 4, j + 1, k + 2, Blocks.stonebrick);
		world.setBlock(i + 4, j + 1, k + 10, Blocks.stonebrick);
		world.setBlock(i + 4, j + 1, k + 11, Blocks.cobblestone_wall, 1, 4);
		world.setBlock(i + 4, j + 2, k + 2, Blocks.stonebrick);
		world.setBlock(i + 4, j + 2, k + 10, Blocks.stonebrick);
		world.setBlock(i + 4, j + 2, k + 11, Blocks.cobblestone_wall, 1, 4);
		world.setBlock(i + 4, j + 3, k + 1, Blocks.stonebrick);
		world.setBlock(i + 4, j + 3, k + 2, Blocks.stonebrick);
		world.setBlock(i + 4, j + 3, k + 10, Blocks.stonebrick);
		world.setBlock(i + 4, j + 4, k + 1, Blocks.stonebrick, 1, 4);
		world.setBlock(i + 4, j + 4, k + 2, Blocks.stonebrick, 1, 4);
		world.setBlock(i + 4, j + 4, k + 3, Blocks.stonebrick, 1, 4);
		world.setBlock(i + 4, j + 4, k + 4, Blocks.stonebrick, 1, 4);
		world.setBlock(i + 4, j + 4, k + 5, Blocks.stonebrick, 1, 4);
		world.setBlock(i + 4, j + 4, k + 6, Blocks.stonebrick, 1, 4);
		world.setBlock(i + 4, j + 4, k + 7, Blocks.stonebrick, 1, 4);
		world.setBlock(i + 4, j + 4, k + 8, Blocks.stonebrick, 1, 4);
		world.setBlock(i + 4, j + 4, k + 9, Blocks.stonebrick, 1, 4);
		world.setBlock(i + 4, j + 4, k + 10, Blocks.stonebrick, 1, 4);
		world.setBlock(i + 4, j + 5, k + 1, Blocks.stonebrick, 1, 4);
		world.setBlock(i + 4, j + 5, k + 10, Blocks.stonebrick, 1, 4);
		world.setBlock(i + 4, j + 6, k + 1, Blocks.nether_brick);
		world.setBlock(i + 4, j + 6, k + 10, Blocks.nether_brick);
		world.setBlock(i + 4, j + 7, k + 1, Blocks.nether_brick);
		world.setBlock(i + 4, j + 7, k + 2, Blocks.stonebrick, 1, 4);
		world.setBlock(i + 4, j + 7, k + 3, Blocks.stonebrick, 1, 4);
		world.setBlock(i + 4, j + 7, k + 4, Blocks.stonebrick, 1, 4);
		world.setBlock(i + 4, j + 7, k + 5, Blocks.stonebrick, 1, 4);
		world.setBlock(i + 4, j + 7, k + 6, Blocks.stonebrick, 1, 4);
		world.setBlock(i + 4, j + 7, k + 7, Blocks.stonebrick, 1, 4);
		world.setBlock(i + 4, j + 7, k + 8, Blocks.stonebrick, 1, 4);
		world.setBlock(i + 4, j + 7, k + 9, Blocks.stonebrick, 1, 4);
		world.setBlock(i + 4, j + 7, k + 10, Blocks.nether_brick);
		world.setBlock(i + 4, j + 8, k + 1, Blocks.nether_brick);
		world.setBlock(i + 4, j + 8, k + 2, Blocks.stonebrick, 1, 4);
		world.setBlock(i + 4, j + 8, k + 3, Blocks.stonebrick, 1, 4);
		world.setBlock(i + 4, j + 8, k + 8, Blocks.stonebrick, 1, 4);
		world.setBlock(i + 4, j + 8, k + 9, Blocks.stonebrick, 1, 4);
		world.setBlock(i + 4, j + 8, k + 10, Blocks.nether_brick);
		world.setBlock(i + 4, j + 9, k + 0, Blocks.stone_slab, 6, 4);
		world.setBlock(i + 4, j + 9, k + 1, Blocks.nether_brick_stairs);
		world.setBlock(i + 4, j + 9, k + 2, Blocks.stonebrick, 1, 4);
		world.setBlock(i + 4, j + 9, k + 9, Blocks.stonebrick, 1, 4);
		world.setBlock(i + 4, j + 9, k + 10, Blocks.nether_brick_stairs);
		world.setBlock(i + 4, j + 9, k + 11, Blocks.stone_slab, 6, 4);
		world.setBlock(i + 4, j + 10, k + 2, Blocks.stonebrick, 1, 4);
		world.setBlock(i + 4, j + 10, k + 3, Blocks.stonebrick, 1, 4);
		world.setBlock(i + 4, j + 10, k + 4, Blocks.stonebrick, 1, 4);
		world.setBlock(i + 4, j + 10, k + 5, Blocks.stonebrick, 1, 4);
		world.setBlock(i + 4, j + 10, k + 6, Blocks.stonebrick, 1, 4);
		world.setBlock(i + 4, j + 10, k + 7, Blocks.stonebrick, 1, 4);
		world.setBlock(i + 4, j + 10, k + 8, Blocks.stonebrick, 1, 4);
		world.setBlock(i + 4, j + 10, k + 9, Blocks.stonebrick, 1, 4);
		world.setBlock(i + 4, j + 11, k + 2, Blocks.stonebrick, 1, 4);
		world.setBlock(i + 4, j + 11, k + 3, Blocks.stonebrick, 1, 4);
		world.setBlock(i + 4, j + 11, k + 4, Blocks.stonebrick, 1, 4);
		world.setBlock(i + 4, j + 11, k + 7, Blocks.stonebrick, 1, 4);
		world.setBlock(i + 4, j + 11, k + 8, Blocks.stonebrick, 1, 4);
		world.setBlock(i + 4, j + 11, k + 9, Blocks.stonebrick, 1, 4);
		world.setBlock(i + 4, j + 13, k + 3, Blocks.stonebrick, 1, 4);
		world.setBlock(i + 4, j + 13, k + 4, Blocks.obsidian);
		world.setBlock(i + 4, j + 13, k + 5, Blocks.obsidian);
		world.setBlock(i + 4, j + 13, k + 6, Blocks.obsidian);
		world.setBlock(i + 4, j + 13, k + 7, Blocks.obsidian);
		world.setBlock(i + 4, j + 13, k + 8, Blocks.stonebrick, 1, 4);
		world.setBlock(i + 4, j + 14, k + 4, Blocks.obsidian);
		world.setBlock(i + 4, j + 14, k + 5, Blocks.chest, 5, 4);
		world.setBlock(i + 4, j + 14, k + 6, Blocks.chest, 5, 4);
		world.setBlock(i + 4, j + 14, k + 7, Blocks.obsidian);
		world.setBlock(i + 4, j + 15, k + 4, Blocks.obsidian);
		world.setBlock(i + 4, j + 15, k + 7, Blocks.obsidian);
		world.setBlock(i + 4, j + 16, k + 4, Blocks.glass);
		world.setBlock(i + 4, j + 16, k + 7, Blocks.glass);
		world.setBlock(i + 4, j + 17, k + 4, Blocks.obsidian);
		world.setBlock(i + 4, j + 17, k + 5, Blocks.obsidian);
		world.setBlock(i + 4, j + 17, k + 6, Blocks.obsidian);
		world.setBlock(i + 4, j + 17, k + 7, Blocks.obsidian);
		world.setBlock(i + 4, j + 18, k + 5, Blocks.obsidian);
		world.setBlock(i + 4, j + 18, k + 6, Blocks.obsidian);
		world.setBlock(i + 5, j + 0, k + 2, Blocks.stonebrick);
		world.setBlock(i + 5, j + 0, k + 3, Blocks.stonebrick);
		world.setBlock(i + 5, j + 0, k + 4, Blocks.stonebrick);
		world.setBlock(i + 5, j + 0, k + 5, Blocks.stonebrick);
		world.setBlock(i + 5, j + 0, k + 6, Blocks.stonebrick);
		world.setBlock(i + 5, j + 0, k + 7, Blocks.stonebrick);
		world.setBlock(i + 5, j + 0, k + 8, Blocks.stonebrick);
		world.setBlock(i + 5, j + 0, k + 9, Blocks.stonebrick);
		world.setBlock(i + 5, j + 1, k + 0, Blocks.cobblestone_wall, 1, 4);
		world.setBlock(i + 5, j + 1, k + 1, Blocks.stonebrick);
		world.setBlock(i + 5, j + 1, k + 10, Blocks.stonebrick);
		world.setBlock(i + 5, j + 1, k + 11, Blocks.cobblestone_wall, 1, 4);
		world.setBlock(i + 5, j + 2, k + 0, Blocks.cobblestone_wall, 1, 4);
		world.setBlock(i + 5, j + 2, k + 1, Blocks.stonebrick);
		world.setBlock(i + 5, j + 2, k + 10, Blocks.stonebrick);
		world.setBlock(i + 5, j + 2, k + 11, Blocks.cobblestone_wall, 1, 4);
		world.setBlock(i + 5, j + 3, k + 1, Blocks.stonebrick);
		world.setBlock(i + 5, j + 3, k + 10, Blocks.stonebrick);
		world.setBlock(i + 5, j + 4, k + 1, Blocks.stonebrick, 1, 4);
		world.setBlock(i + 5, j + 4, k + 2, Blocks.stonebrick, 1, 4);
		world.setBlock(i + 5, j + 4, k + 3, Blocks.stonebrick, 1, 4);
		world.setBlock(i + 5, j + 4, k + 4, Blocks.stonebrick, 1, 4);
		world.setBlock(i + 5, j + 4, k + 5, Blocks.stonebrick, 1, 4);
		world.setBlock(i + 5, j + 4, k + 6, Blocks.stonebrick, 1, 4);
		world.setBlock(i + 5, j + 4, k + 7, Blocks.stonebrick, 1, 4);
		world.setBlock(i + 5, j + 4, k + 8, Blocks.stonebrick, 1, 4);
		world.setBlock(i + 5, j + 4, k + 10, Blocks.stonebrick, 1, 4);
		world.setBlock(i + 5, j + 5, k + 1, Blocks.nether_brick);
		world.setBlock(i + 5, j + 5, k + 10, Blocks.nether_brick);
		world.setBlock(i + 5, j + 6, k + 1, Blocks.nether_brick);
		world.setBlock(i + 5, j + 6, k + 10, Blocks.nether_brick);
		world.setBlock(i + 5, j + 7, k + 1, Blocks.nether_brick);
		world.setBlock(i + 5, j + 7, k + 2, Blocks.stonebrick, 1, 4);
		world.setBlock(i + 5, j + 7, k + 3, Blocks.stonebrick, 1, 4);
		world.setBlock(i + 5, j + 7, k + 4, Blocks.stonebrick, 1, 4);
		world.setBlock(i + 5, j + 7, k + 5, Blocks.stonebrick, 1, 4);
		world.setBlock(i + 5, j + 7, k + 6, Blocks.stonebrick, 1, 4);
		world.setBlock(i + 5, j + 7, k + 7, Blocks.stonebrick, 1, 4);
		world.setBlock(i + 5, j + 7, k + 8, Blocks.stonebrick, 1, 4);
		world.setBlock(i + 5, j + 7, k + 9, Blocks.stonebrick, 1, 4);
		world.setBlock(i + 5, j + 7, k + 10, Blocks.nether_brick);
		world.setBlock(i + 5, j + 8, k + 1, Blocks.nether_brick);
		world.setBlock(i + 5, j + 8, k + 9, Blocks.stonebrick, 1, 4);
		world.setBlock(i + 5, j + 8, k + 10, Blocks.nether_brick);
		world.setBlock(i + 5, j + 9, k + 0, Blocks.nether_brick_stairs, 2, 4);
		world.setBlock(i + 5, j + 9, k + 1, Blocks.netherrack);
		world.setBlock(i + 5, j + 9, k + 9, Blocks.stonebrick, 1, 4);
		world.setBlock(i + 5, j + 9, k + 10, Blocks.netherrack);
		world.setBlock(i + 5, j + 9, k + 11, Blocks.nether_brick_stairs, 3, 4);
		world.setBlock(i + 5, j + 10, k + 2, Blocks.nether_brick);
		world.setBlock(i + 5, j + 10, k + 3, Blocks.stonebrick, 1, 4);
		world.setBlock(i + 5, j + 10, k + 4, Blocks.stonebrick, 1, 4);
		world.setBlock(i + 5, j + 10, k + 5, Blocks.stonebrick, 1, 4);
		world.setBlock(i + 5, j + 10, k + 6, Blocks.stonebrick, 1, 4);
		world.setBlock(i + 5, j + 10, k + 7, Blocks.stonebrick, 1, 4);
		world.setBlock(i + 5, j + 10, k + 9, Blocks.nether_brick);
		world.setBlock(i + 5, j + 10, k + 10, Blocks.fire, 15, 4);
		world.setBlock(i + 5, j + 11, k + 2, Blocks.nether_brick_stairs, 2, 4);
		world.setBlock(i + 5, j + 11, k + 3, Blocks.stonebrick, 1, 4);
		world.setBlock(i + 5, j + 11, k + 9, Blocks.nether_brick_stairs, 3, 4);
		world.setBlock(i + 5, j + 12, k + 3, Blocks.stonebrick, 1, 4);
		world.setBlock(i + 5, j + 13, k + 3, Blocks.obsidian);
		world.setBlock(i + 5, j + 13, k + 4, Blocks.obsidian);
		world.setBlock(i + 5, j + 13, k + 5, Blocks.obsidian);
		world.setBlock(i + 5, j + 13, k + 6, Blocks.obsidian);
		world.setBlock(i + 5, j + 13, k + 7, Blocks.obsidian);
		world.setBlock(i + 5, j + 13, k + 8, Blocks.obsidian);
		world.setBlock(i + 5, j + 14, k + 3, Blocks.obsidian);
		world.setBlock(i + 5, j + 14, k + 7, Blocks.chest, 2, 4);
		
		TileEntityChest te3 = (TileEntityChest) world.getTileEntity(
				i + 5, j + 14, k + 7);

		if (te3 != null) {
			ChestGenHooks info = ChestGenHooks.getInfo(ChestGenHooks.DUNGEON_CHEST);
			WeightedRandomChestContent.generateChestContents(rand, info.getItems(rand), te3, info.getCount(rand));
			int poss = rand.nextInt(3);
			if (poss == 2) {
				ItemStack var18 = new ItemStack(Wildycraft.IceStaff);
				te3.setInventorySlotContents(
						rand.nextInt(te3.getSizeInventory()), var18);
			}
			if (poss > 0){
				ItemStack var20 = new ItemStack(Wildycraft.waterRune,10 * poss);
				te3.setInventorySlotContents(
						rand.nextInt(te3.getSizeInventory()), var20);
			}
		}
		
		world.setBlock(i + 5, j + 14, k + 8, Blocks.obsidian);
		world.setBlock(i + 5, j + 15, k + 3, Blocks.obsidian);
		world.setBlock(i + 5, j + 15, k + 8, Blocks.obsidian);
		world.setBlock(i + 5, j + 16, k + 3, Blocks.glass);
		world.setBlock(i + 5, j + 16, k + 8, Blocks.glass);
		world.setBlock(i + 5, j + 17, k + 3, Blocks.obsidian);
		world.setBlock(i + 5, j + 17, k + 4, Blocks.obsidian);
		world.setBlock(i + 5, j + 17, k + 5, Blocks.obsidian);
		world.setBlock(i + 5, j + 17, k + 6, Blocks.obsidian);
		world.setBlock(i + 5, j + 17, k + 7, Blocks.obsidian);
		world.setBlock(i + 5, j + 17, k + 8, Blocks.obsidian);
		world.setBlock(i + 5, j + 18, k + 4, Blocks.obsidian);
		world.setBlock(i + 5, j + 18, k + 5, Blocks.obsidian);
		world.setBlock(i + 5, j + 18, k + 6, Blocks.obsidian);
		world.setBlock(i + 5, j + 18, k + 7, Blocks.obsidian);
		world.setBlock(i + 5, j + 19, k + 5, Blocks.obsidian);
		world.setBlock(i + 5, j + 19, k + 6, Blocks.obsidian);
		world.setBlock(i + 6, j + 0, k + 1, Blocks.stonebrick);
		world.setBlock(i + 6, j + 0, k + 2, Blocks.stonebrick);
		world.setBlock(i + 6, j + 0, k + 3, Blocks.stonebrick);
		world.setBlock(i + 6, j + 0, k + 4, Blocks.stonebrick);
		world.setBlock(i + 6, j + 0, k + 5, Blocks.stonebrick);
		world.setBlock(i + 6, j + 0, k + 6, Blocks.stonebrick);
		world.setBlock(i + 6, j + 0, k + 7, Blocks.stonebrick);
		world.setBlock(i + 6, j + 0, k + 8, Blocks.stonebrick);
		world.setBlock(i + 6, j + 0, k + 9, Blocks.stonebrick);
		world.setBlock(i + 6, j + 1, k + 10, Blocks.stonebrick);
		world.setBlock(i + 6, j + 1, k + 11, Blocks.cobblestone_wall, 1, 4);
		world.setBlock(i + 6, j + 2, k + 10, Blocks.stonebrick);
		world.setBlock(i + 6, j + 2, k + 11, Blocks.cobblestone_wall, 1, 4);
		world.setBlock(i + 6, j + 3, k + 1, Blocks.stonebrick);
		world.setBlock(i + 6, j + 3, k + 10, Blocks.stonebrick);
		world.setBlock(i + 6, j + 4, k + 1, Blocks.stonebrick, 1, 4);
		world.setBlock(i + 6, j + 4, k + 2, Blocks.stonebrick, 1, 4);
		world.setBlock(i + 6, j + 4, k + 3, Blocks.stonebrick, 1, 4);
		world.setBlock(i + 6, j + 4, k + 4, Blocks.stonebrick, 1, 4);
		world.setBlock(i + 6, j + 4, k + 5, Blocks.stonebrick, 1, 4);
		world.setBlock(i + 6, j + 4, k + 6, Blocks.stonebrick, 1, 4);
		world.setBlock(i + 6, j + 4, k + 7, Blocks.stonebrick, 1, 4);
		world.setBlock(i + 6, j + 4, k + 8, Blocks.stonebrick, 1, 4);
		world.setBlock(i + 6, j + 4, k + 9, Blocks.stonebrick, 1, 4);
		world.setBlock(i + 6, j + 4, k + 10, Blocks.stonebrick, 1, 4);
		world.setBlock(i + 6, j + 5, k + 1, Blocks.nether_brick);
		world.setBlock(i + 6, j + 5, k + 10, Blocks.nether_brick);
		world.setBlock(i + 6, j + 6, k + 1, Blocks.nether_brick);
		world.setBlock(i + 6, j + 6, k + 10, Blocks.nether_brick);
		world.setBlock(i + 6, j + 7, k + 1, Blocks.nether_brick);
		world.setBlock(i + 6, j + 7, k + 3, Blocks.stonebrick, 1, 4);
		world.setBlock(i + 6, j + 7, k + 4, Blocks.stonebrick, 1, 4);
		world.setBlock(i + 6, j + 7, k + 5, Blocks.stonebrick, 1, 4);
		world.setBlock(i + 6, j + 7, k + 6, Blocks.stonebrick, 1, 4);
		world.setBlock(i + 6, j + 7, k + 7, Blocks.stonebrick, 1, 4);
		world.setBlock(i + 6, j + 7, k + 8, Blocks.stonebrick, 1, 4);
		world.setBlock(i + 6, j + 7, k + 9, Blocks.stonebrick, 1, 4);
		world.setBlock(i + 6, j + 7, k + 10, Blocks.nether_brick);
		world.setBlock(i + 6, j + 8, k + 1, Blocks.nether_brick);
		world.setBlock(i + 6, j + 8, k + 9, Blocks.stonebrick, 1, 4);
		world.setBlock(i + 6, j + 8, k + 10, Blocks.nether_brick);
		world.setBlock(i + 6, j + 9, k + 0, Blocks.nether_brick_stairs, 2, 4);
		world.setBlock(i + 6, j + 9, k + 1, Blocks.netherrack);
		world.setBlock(i + 6, j + 9, k + 9, Blocks.stonebrick, 1, 4);
		world.setBlock(i + 6, j + 9, k + 10, Blocks.netherrack);
		world.setBlock(i + 6, j + 9, k + 11, Blocks.nether_brick_stairs, 3, 4);
		world.setBlock(i + 6, j + 10, k + 2, Blocks.nether_brick);
		world.setBlock(i + 6, j + 10, k + 3, Blocks.stonebrick, 1, 4);
		world.setBlock(i + 6, j + 10, k + 4, Blocks.stonebrick, 1, 4);
		world.setBlock(i + 6, j + 10, k + 5, Blocks.stonebrick, 1, 4);
		world.setBlock(i + 6, j + 10, k + 6, Blocks.stonebrick, 1, 4);
		world.setBlock(i + 6, j + 10, k + 7, Blocks.stonebrick, 1, 4);
		world.setBlock(i + 6, j + 10, k + 8, Blocks.stonebrick, 1, 4);
		world.setBlock(i + 6, j + 10, k + 9, Blocks.nether_brick);
		world.setBlock(i + 6, j + 10, k + 10, Blocks.fire, 15, 4);
		world.setBlock(i + 6, j + 11, k + 2, Blocks.nether_brick_stairs, 2, 4);
		world.setBlock(i + 6, j + 11, k + 3, Blocks.stonebrick, 1, 4);
		world.setBlock(i + 6, j + 11, k + 9, Blocks.nether_brick_stairs, 3, 4);
		world.setBlock(i + 6, j + 12, k + 3, Blocks.stonebrick, 1, 4);
		world.setBlock(i + 6, j + 13, k + 3, Blocks.obsidian);
		world.setBlock(i + 6, j + 13, k + 5, Blocks.obsidian);
		world.setBlock(i + 6, j + 13, k + 6, Blocks.obsidian);
		world.setBlock(i + 6, j + 13, k + 7, Blocks.obsidian);
		world.setBlock(i + 6, j + 13, k + 8, Blocks.obsidian);
		world.setBlock(i + 6, j + 14, k + 3, Blocks.obsidian);
		world.setBlock(i + 6, j + 14, k + 7, Blocks.chest, 2, 4);
		TileEntityChest te4 = (TileEntityChest) world.getTileEntity(
				i + 6, j + 14, k + 7);

		if (te4 != null) {
			ChestGenHooks info = ChestGenHooks.getInfo(ChestGenHooks.DUNGEON_CHEST);
			WeightedRandomChestContent.generateChestContents(rand, info.getItems(rand), te4, info.getCount(rand));
			int poss = rand.nextInt(3);
			if (poss > 0){
				ItemStack var20 = new ItemStack(Items.ender_pearl,1 * poss);
				te4.setInventorySlotContents(
						rand.nextInt(te4.getSizeInventory()), var20);
			}
		}
		
		world.setBlock(i + 6, j + 14, k + 8, Blocks.obsidian);
		world.setBlock(i + 6, j + 15, k + 3, Blocks.obsidian);
		world.setBlock(i + 6, j + 15, k + 8, Blocks.obsidian);
		world.setBlock(i + 6, j + 16, k + 3, Blocks.glass);
		world.setBlock(i + 6, j + 16, k + 8, Blocks.glass);
		world.setBlock(i + 6, j + 17, k + 3, Blocks.obsidian);
		world.setBlock(i + 6, j + 17, k + 4, Blocks.obsidian);
		world.setBlock(i + 6, j + 17, k + 5, Blocks.obsidian);
		world.setBlock(i + 6, j + 17, k + 6, Blocks.obsidian);
		world.setBlock(i + 6, j + 17, k + 7, Blocks.obsidian);
		world.setBlock(i + 6, j + 17, k + 8, Blocks.obsidian);
		world.setBlock(i + 6, j + 18, k + 4, Blocks.obsidian);
		world.setBlock(i + 6, j + 18, k + 5, Blocks.obsidian);
		world.setBlock(i + 6, j + 18, k + 6, Blocks.obsidian);
		world.setBlock(i + 6, j + 18, k + 7, Blocks.obsidian);
		world.setBlock(i + 6, j + 19, k + 5, Blocks.obsidian);
		world.setBlock(i + 6, j + 19, k + 6, Blocks.obsidian);
		world.setBlock(i + 7, j + 0, k + 2, Blocks.stonebrick);
		world.setBlock(i + 7, j + 0, k + 3, Blocks.stonebrick);
		world.setBlock(i + 7, j + 0, k + 4, Blocks.stonebrick);
		world.setBlock(i + 7, j + 0, k + 5, Blocks.stonebrick);
		world.setBlock(i + 7, j + 0, k + 6, Blocks.stonebrick);
		world.setBlock(i + 7, j + 0, k + 7, Blocks.stonebrick);
		world.setBlock(i + 7, j + 0, k + 8, Blocks.stonebrick);
		world.setBlock(i + 7, j + 1, k + 0, Blocks.cobblestone_wall, 1, 4);
		world.setBlock(i + 7, j + 1, k + 1, Blocks.stonebrick);
		world.setBlock(i + 7, j + 1, k + 9, Blocks.stonebrick);
		world.setBlock(i + 7, j + 1, k + 11, Blocks.cobblestone_wall, 1, 4);
		world.setBlock(i + 7, j + 2, k + 0, Blocks.cobblestone_wall, 1, 4);
		world.setBlock(i + 7, j + 2, k + 1, Blocks.stonebrick);
		world.setBlock(i + 7, j + 2, k + 9, Blocks.stonebrick);
		world.setBlock(i + 7, j + 3, k + 1, Blocks.stonebrick);
		world.setBlock(i + 7, j + 3, k + 9, Blocks.stonebrick);
		world.setBlock(i + 7, j + 3, k + 10, Blocks.stonebrick);
		world.setBlock(i + 7, j + 4, k + 1, Blocks.stonebrick, 1, 4);
		world.setBlock(i + 7, j + 4, k + 2, Blocks.stonebrick, 1, 4);
		world.setBlock(i + 7, j + 4, k + 3, Blocks.stonebrick, 1, 4);
		world.setBlock(i + 7, j + 4, k + 4, Blocks.stonebrick, 1, 4);
		world.setBlock(i + 7, j + 4, k + 5, Blocks.stonebrick, 1, 4);
		world.setBlock(i + 7, j + 4, k + 6, Blocks.stonebrick, 1, 4);
		world.setBlock(i + 7, j + 4, k + 7, Blocks.stonebrick, 1, 4);
		world.setBlock(i + 7, j + 4, k + 8, Blocks.stonebrick, 1, 4);
		world.setBlock(i + 7, j + 4, k + 9, Blocks.stonebrick, 1, 4);
		world.setBlock(i + 7, j + 4, k + 10, Blocks.stonebrick, 1, 4);
		world.setBlock(i + 7, j + 5, k + 1, Blocks.stonebrick, 1, 4);
		world.setBlock(i + 7, j + 5, k + 10, Blocks.stonebrick, 1, 4);
		world.setBlock(i + 7, j + 6, k + 1, Blocks.nether_brick);
		world.setBlock(i + 7, j + 6, k + 10, Blocks.nether_brick);
		world.setBlock(i + 7, j + 7, k + 1, Blocks.nether_brick);
		world.setBlock(i + 7, j + 7, k + 2, Blocks.stonebrick, 1, 4);
		world.setBlock(i + 7, j + 7, k + 3, Blocks.stonebrick, 1, 4);
		world.setBlock(i + 7, j + 7, k + 4, Blocks.stonebrick, 1, 4);
		world.setBlock(i + 7, j + 7, k + 5, Blocks.stonebrick, 1, 4);
		world.setBlock(i + 7, j + 7, k + 6, Blocks.stonebrick, 1, 4);
		world.setBlock(i + 7, j + 7, k + 7, Blocks.stonebrick, 1, 4);
		world.setBlock(i + 7, j + 7, k + 8, Blocks.stonebrick, 1, 4);
		world.setBlock(i + 7, j + 7, k + 9, Blocks.stonebrick, 1, 4);
		world.setBlock(i + 7, j + 7, k + 10, Blocks.nether_brick);
		world.setBlock(i + 7, j + 8, k + 1, Blocks.nether_brick);
		world.setBlock(i + 7, j + 8, k + 2, Blocks.stonebrick, 1, 4);
		world.setBlock(i + 7, j + 8, k + 3, Blocks.stonebrick, 1, 4);
		world.setBlock(i + 7, j + 8, k + 8, Blocks.stonebrick, 1, 4);
		world.setBlock(i + 7, j + 8, k + 9, Blocks.stonebrick, 1, 4);
		world.setBlock(i + 7, j + 8, k + 10, Blocks.nether_brick);
		world.setBlock(i + 7, j + 9, k + 0, Blocks.stone_slab, 6, 4);
		world.setBlock(i + 7, j + 9, k + 1, Blocks.nether_brick_stairs, 1, 4);
		world.setBlock(i + 7, j + 9, k + 2, Blocks.stonebrick, 1, 4);
		world.setBlock(i + 7, j + 9, k + 9, Blocks.stonebrick, 1, 4);
		world.setBlock(i + 7, j + 9, k + 10, Blocks.nether_brick_stairs, 1, 4);
		world.setBlock(i + 7, j + 9, k + 11, Blocks.stone_slab, 6, 4);
		world.setBlock(i + 7, j + 10, k + 2, Blocks.stonebrick, 1, 4);
		world.setBlock(i + 7, j + 10, k + 3, Blocks.stonebrick, 1, 4);
		world.setBlock(i + 7, j + 10, k + 4, Blocks.stonebrick, 1, 4);
		world.setBlock(i + 7, j + 10, k + 5, Blocks.stonebrick, 1, 4);
		world.setBlock(i + 7, j + 10, k + 6, Blocks.stonebrick, 1, 4);
		world.setBlock(i + 7, j + 10, k + 7, Blocks.stonebrick, 1, 4);
		world.setBlock(i + 7, j + 10, k + 8, Blocks.stonebrick, 1, 4);
		world.setBlock(i + 7, j + 10, k + 9, Blocks.stonebrick, 1, 4);
		world.setBlock(i + 7, j + 11, k + 2, Blocks.stonebrick, 1, 4);
		world.setBlock(i + 7, j + 11, k + 3, Blocks.stonebrick, 1, 4);
		world.setBlock(i + 7, j + 11, k + 4, Blocks.stonebrick, 1, 4);
		world.setBlock(i + 7, j + 11, k + 7, Blocks.stonebrick, 1, 4);
		world.setBlock(i + 7, j + 11, k + 8, Blocks.stonebrick, 1, 4);
		world.setBlock(i + 7, j + 11, k + 9, Blocks.stonebrick, 1, 4);
		world.setBlock(i + 7, j + 13, k + 3, Blocks.stonebrick, 1, 4);
		world.setBlock(i + 7, j + 13, k + 4, Blocks.obsidian);
		world.setBlock(i + 7, j + 13, k + 5, Blocks.obsidian);
		world.setBlock(i + 7, j + 13, k + 6, Blocks.obsidian);
		world.setBlock(i + 7, j + 13, k + 7, Blocks.obsidian);
		world.setBlock(i + 7, j + 13, k + 8, Blocks.stonebrick, 1, 4);
		world.setBlock(i + 7, j + 14, k + 4, Blocks.obsidian);
		world.setBlock(i + 7, j + 14, k + 5, Blocks.chest, 4, 4);
		world.setBlock(i + 7, j + 14, k + 6, Blocks.chest, 4, 4);
		world.setBlock(i + 7, j + 14, k + 7, Blocks.obsidian);
		world.setBlock(i + 7, j + 15, k + 4, Blocks.obsidian);
		world.setBlock(i + 7, j + 15, k + 7, Blocks.obsidian);
		world.setBlock(i + 7, j + 16, k + 4, Blocks.glass);
		world.setBlock(i + 7, j + 16, k + 7, Blocks.glass);
		world.setBlock(i + 7, j + 17, k + 4, Blocks.obsidian);
		world.setBlock(i + 7, j + 17, k + 5, Blocks.obsidian);
		world.setBlock(i + 7, j + 17, k + 6, Blocks.obsidian);
		world.setBlock(i + 7, j + 17, k + 7, Blocks.obsidian);
		world.setBlock(i + 7, j + 18, k + 5, Blocks.obsidian);
		world.setBlock(i + 7, j + 18, k + 6, Blocks.obsidian);
		world.setBlock(i + 8, j + 0, k + 3, Blocks.stonebrick);
		world.setBlock(i + 8, j + 0, k + 4, Blocks.stonebrick);
		world.setBlock(i + 8, j + 0, k + 5, Blocks.stonebrick);
		world.setBlock(i + 8, j + 0, k + 6, Blocks.stonebrick);
		world.setBlock(i + 8, j + 0, k + 7, Blocks.stonebrick);
		world.setBlock(i + 8, j + 1, k + 0, Blocks.cobblestone_wall, 1, 4);
		world.setBlock(i + 8, j + 1, k + 1, Blocks.stonebrick, 1, 4);
		world.setBlock(i + 8, j + 1, k + 2, Blocks.stonebrick);
		world.setBlock(i + 8, j + 1, k + 8, Blocks.stonebrick);
		world.setBlock(i + 8, j + 1, k + 9, Blocks.stonebrick, 1, 4);
		world.setBlock(i + 8, j + 1, k + 10, Blocks.stonebrick, 1, 4);
		world.setBlock(i + 8, j + 1, k + 11, Blocks.cobblestone_wall, 1, 4);
		world.setBlock(i + 8, j + 2, k + 0, Blocks.cobblestone_wall, 1, 4);
		world.setBlock(i + 8, j + 2, k + 1, Blocks.stonebrick, 1, 4);
		world.setBlock(i + 8, j + 2, k + 2, Blocks.stonebrick);
		world.setBlock(i + 8, j + 2, k + 8, Blocks.stonebrick);
		world.setBlock(i + 8, j + 2, k + 9, Blocks.stonebrick, 1, 4);
		world.setBlock(i + 8, j + 2, k + 10, Blocks.stonebrick, 1, 4);
		world.setBlock(i + 8, j + 2, k + 11, Blocks.cobblestone_wall, 1, 4);
		world.setBlock(i + 8, j + 3, k + 1, Blocks.iron_bars);
		world.setBlock(i + 8, j + 3, k + 2, Blocks.stonebrick);
		world.setBlock(i + 8, j + 3, k + 8, Blocks.stonebrick);
		world.setBlock(i + 8, j + 3, k + 9, Blocks.stonebrick, 1, 4);
		world.setBlock(i + 8, j + 3, k + 10, Blocks.iron_bars);
		world.setBlock(i + 8, j + 4, k + 1, Blocks.stonebrick, 1, 4);
		world.setBlock(i + 8, j + 4, k + 2, Blocks.stonebrick, 1, 4);
		world.setBlock(i + 8, j + 4, k + 3, Blocks.stonebrick, 1, 4);
		world.setBlock(i + 8, j + 4, k + 4, Blocks.stonebrick, 1, 4);
		world.setBlock(i + 8, j + 4, k + 5, Blocks.stonebrick, 1, 4);
		world.setBlock(i + 8, j + 4, k + 6, Blocks.stonebrick, 1, 4);
		world.setBlock(i + 8, j + 4, k + 7, Blocks.stonebrick, 1, 4);
		world.setBlock(i + 8, j + 4, k + 8, Blocks.stonebrick, 1, 4);
		world.setBlock(i + 8, j + 4, k + 9, Blocks.stonebrick, 1, 4);
		world.setBlock(i + 8, j + 4, k + 10, Blocks.stonebrick, 1, 4);
		world.setBlock(i + 8, j + 5, k + 1, Blocks.stonebrick, 1, 4);
		world.setBlock(i + 8, j + 5, k + 2, Blocks.stonebrick, 1, 4);
		world.setBlock(i + 8, j + 5, k + 9, Blocks.stonebrick, 1, 4);
		world.setBlock(i + 8, j + 5, k + 10, Blocks.stonebrick, 1, 4);
		world.setBlock(i + 8, j + 7, k + 1, Blocks.nether_brick_stairs, 2, 4);
		world.setBlock(i + 8, j + 7, k + 2, Blocks.stonebrick, 1, 4);
		world.setBlock(i + 8, j + 7, k + 3, Blocks.stonebrick, 1, 4);
		world.setBlock(i + 8, j + 7, k + 4, Blocks.stonebrick, 1, 4);
		world.setBlock(i + 8, j + 7, k + 5, Blocks.stonebrick, 1, 4);
		world.setBlock(i + 8, j + 7, k + 6, Blocks.stonebrick, 1, 4);
		world.setBlock(i + 8, j + 7, k + 7, Blocks.stonebrick, 1, 4);
		world.setBlock(i + 8, j + 7, k + 8, Blocks.stonebrick, 1, 4);
		world.setBlock(i + 8, j + 7, k + 9, Blocks.stonebrick, 1, 4);
		world.setBlock(i + 8, j + 7, k + 10, Blocks.nether_brick_stairs, 3, 4);
		world.setBlock(i + 8, j + 8, k + 2, Blocks.stonebrick, 1, 4);
		world.setBlock(i + 8, j + 8, k + 4, Blocks.stonebrick, 1, 4);
		world.setBlock(i + 8, j + 8, k + 7, Blocks.stonebrick, 1, 4);
		world.setBlock(i + 8, j + 8, k + 9, Blocks.stonebrick, 1, 4);
		world.setBlock(i + 8, j + 10, k + 2, Blocks.stonebrick, 1, 4);
		world.setBlock(i + 8, j + 10, k + 3, Blocks.stonebrick, 1, 4);
		world.setBlock(i + 8, j + 10, k + 4, Blocks.stonebrick, 1, 4);
		world.setBlock(i + 8, j + 10, k + 5, Blocks.stonebrick, 1, 4);
		world.setBlock(i + 8, j + 10, k + 6, Blocks.stonebrick, 1, 4);
		world.setBlock(i + 8, j + 10, k + 7, Blocks.stonebrick, 1, 4);
		world.setBlock(i + 8, j + 10, k + 8, Blocks.stonebrick, 1, 4);
		world.setBlock(i + 8, j + 10, k + 9, Blocks.stonebrick, 1, 4);
		world.setBlock(i + 8, j + 11, k + 2, Blocks.stonebrick, 1, 4);
		world.setBlock(i + 8, j + 11, k + 4, Blocks.stonebrick, 1, 4);
		world.setBlock(i + 8, j + 11, k + 5, Blocks.stonebrick, 1, 4);
		world.setBlock(i + 8, j + 11, k + 6, Blocks.stonebrick, 1, 4);
		world.setBlock(i + 8, j + 11, k + 7, Blocks.stonebrick, 1, 4);
		world.setBlock(i + 8, j + 11, k + 9, Blocks.stonebrick, 1, 4);
		world.setBlock(i + 8, j + 12, k + 5, Blocks.stonebrick, 1, 4);
		world.setBlock(i + 8, j + 12, k + 6, Blocks.stonebrick, 1, 4);
		world.setBlock(i + 8, j + 13, k + 3, Blocks.stonebrick, 1, 4);
		world.setBlock(i + 8, j + 13, k + 4, Blocks.stonebrick, 1, 4);
		world.setBlock(i + 8, j + 13, k + 5, Blocks.obsidian);
		world.setBlock(i + 8, j + 13, k + 6, Blocks.obsidian);
		world.setBlock(i + 8, j + 13, k + 7, Blocks.stonebrick, 1, 4);
		world.setBlock(i + 8, j + 13, k + 8, Blocks.stonebrick, 1, 4);
		world.setBlock(i + 8, j + 14, k + 5, Blocks.obsidian);
		world.setBlock(i + 8, j + 14, k + 6, Blocks.obsidian);
		world.setBlock(i + 8, j + 15, k + 5, Blocks.obsidian);
		world.setBlock(i + 8, j + 15, k + 6, Blocks.obsidian);
		world.setBlock(i + 8, j + 16, k + 5, Blocks.glass);
		world.setBlock(i + 8, j + 16, k + 6, Blocks.glass);
		world.setBlock(i + 8, j + 17, k + 5, Blocks.obsidian);
		world.setBlock(i + 8, j + 17, k + 6, Blocks.obsidian);
		world.setBlock(i + 9, j + 0, k + 4, Blocks.stonebrick);
		world.setBlock(i + 9, j + 0, k + 5, Blocks.stonebrick);
		world.setBlock(i + 9, j + 0, k + 6, Blocks.stonebrick);
		world.setBlock(i + 9, j + 1, k + 0, Blocks.cobblestone_wall, 1, 4);
		world.setBlock(i + 9, j + 1, k + 1, Blocks.stonebrick, 1, 4);
		world.setBlock(i + 9, j + 1, k + 2, Blocks.stonebrick, 1, 4);
		world.setBlock(i + 9, j + 1, k + 3, Blocks.stonebrick);
		world.setBlock(i + 9, j + 1, k + 7, Blocks.stonebrick);
		world.setBlock(i + 9, j + 1, k + 8, Blocks.stonebrick, 1, 4);
		world.setBlock(i + 9, j + 1, k + 9, Blocks.stonebrick);
		world.setBlock(i + 9, j + 1, k + 10, Blocks.stonebrick, 1, 4);
		world.setBlock(i + 9, j + 1, k + 11, Blocks.cobblestone_wall, 1, 4);
		world.setBlock(i + 9, j + 2, k + 0, Blocks.cobblestone_wall, 1, 4);
		world.setBlock(i + 9, j + 2, k + 1, Blocks.stonebrick, 1, 4);
		world.setBlock(i + 9, j + 2, k + 3, Blocks.stonebrick);
		world.setBlock(i + 9, j + 2, k + 7, Blocks.stonebrick);
		world.setBlock(i + 9, j + 2, k + 8, Blocks.stonebrick, 1, 4);
		world.setBlock(i + 9, j + 2, k + 10, Blocks.stonebrick, 1, 4);
		world.setBlock(i + 9, j + 2, k + 11, Blocks.cobblestone_wall, 1, 4);
		world.setBlock(i + 9, j + 3, k + 3, Blocks.stonebrick);
		world.setBlock(i + 9, j + 3, k + 7, Blocks.stonebrick);
		world.setBlock(i + 9, j + 3, k + 8, Blocks.stonebrick, 1, 4);
		world.setBlock(i + 9, j + 4, k + 1, Blocks.stonebrick, 1, 4);
		world.setBlock(i + 9, j + 4, k + 2, Blocks.stonebrick, 1, 4);
		world.setBlock(i + 9, j + 4, k + 3, Blocks.stonebrick, 1, 4);
		world.setBlock(i + 9, j + 4, k + 4, Blocks.stonebrick, 1, 4);
		world.setBlock(i + 9, j + 4, k + 5, Blocks.stonebrick, 1, 4);
		world.setBlock(i + 9, j + 4, k + 6, Blocks.stonebrick, 1, 4);
		world.setBlock(i + 9, j + 4, k + 7, Blocks.stonebrick, 1, 4);
		world.setBlock(i + 9, j + 4, k + 8, Blocks.stonebrick, 1, 4);
		world.setBlock(i + 9, j + 4, k + 9, Blocks.stonebrick, 1, 4);
		world.setBlock(i + 9, j + 4, k + 10, Blocks.stonebrick, 1, 4);
		world.setBlock(i + 9, j + 5, k + 1, Blocks.stonebrick, 1, 4);
		world.setBlock(i + 9, j + 5, k + 3, Blocks.stonebrick, 1, 4);
		world.setBlock(i + 9, j + 5, k + 8, Blocks.stonebrick, 1, 4);
		world.setBlock(i + 9, j + 5, k + 10, Blocks.stonebrick, 1, 4);
		world.setBlock(i + 9, j + 7, k + 1, Blocks.nether_brick_stairs, 2, 4);
		world.setBlock(i + 9, j + 7, k + 2, Blocks.stonebrick, 1, 4);
		world.setBlock(i + 9, j + 7, k + 3, Blocks.stonebrick, 1, 4);
		world.setBlock(i + 9, j + 7, k + 4, Blocks.stonebrick, 1, 4);
		world.setBlock(i + 9, j + 7, k + 5, Blocks.stonebrick, 1, 4);
		world.setBlock(i + 9, j + 7, k + 6, Blocks.stonebrick, 1, 4);
		world.setBlock(i + 9, j + 7, k + 7, Blocks.stonebrick, 1, 4);
		world.setBlock(i + 9, j + 7, k + 8, Blocks.stonebrick, 1, 4);
		world.setBlock(i + 9, j + 7, k + 9, Blocks.stonebrick, 1, 4);
		world.setBlock(i + 9, j + 7, k + 10, Blocks.nether_brick_stairs, 3, 4);
		world.setBlock(i + 9, j + 8, k + 2, Blocks.stonebrick, 1, 4);
		world.setBlock(i + 9, j + 8, k + 3, Blocks.stonebrick, 1, 4);
		world.setBlock(i + 9, j + 8, k + 4, Blocks.stonebrick, 1, 4);
		world.setBlock(i + 9, j + 8, k + 5, Blocks.stonebrick, 1, 4);
		world.setBlock(i + 9, j + 8, k + 6, Blocks.stonebrick, 1, 4);
		world.setBlock(i + 9, j + 8, k + 7, Blocks.stonebrick, 1, 4);
		world.setBlock(i + 9, j + 8, k + 8, Blocks.stonebrick, 1, 4);
		world.setBlock(i + 9, j + 8, k + 9, Blocks.stonebrick, 1, 4);
		world.setBlock(i + 9, j + 9, k + 4, Blocks.stonebrick, 1, 4);
		world.setBlock(i + 9, j + 9, k + 5, Blocks.nether_brick);
		world.setBlock(i + 9, j + 9, k + 6, Blocks.nether_brick);
		world.setBlock(i + 9, j + 9, k + 7, Blocks.stonebrick, 1, 4);
		world.setBlock(i + 9, j + 10, k + 2, Blocks.stonebrick, 1, 4);
		world.setBlock(i + 9, j + 10, k + 3, Blocks.stonebrick, 1, 4);
		world.setBlock(i + 9, j + 10, k + 4, Blocks.stonebrick, 1, 4);
		world.setBlock(i + 9, j + 10, k + 5, Blocks.nether_brick);
		world.setBlock(i + 9, j + 10, k + 6, Blocks.nether_brick);
		world.setBlock(i + 9, j + 10, k + 7, Blocks.stonebrick, 1, 4);
		world.setBlock(i + 9, j + 10, k + 8, Blocks.stonebrick, 1, 4);
		world.setBlock(i + 9, j + 10, k + 9, Blocks.stonebrick, 1, 4);
		world.setBlock(i + 9, j + 11, k + 2, Blocks.stonebrick, 1, 4);
		world.setBlock(i + 9, j + 11, k + 3, Blocks.stonebrick, 1, 4);
		world.setBlock(i + 9, j + 11, k + 4, Blocks.stonebrick, 1, 4);
		world.setBlock(i + 9, j + 11, k + 5, Blocks.stone_slab, 6, 4);
		world.setBlock(i + 9, j + 11, k + 6, Blocks.stone_slab, 6, 4);
		world.setBlock(i + 9, j + 11, k + 7, Blocks.stonebrick, 1, 4);
		world.setBlock(i + 9, j + 11, k + 8, Blocks.stonebrick, 1, 4);
		world.setBlock(i + 9, j + 11, k + 9, Blocks.stonebrick, 1, 4);
		world.setBlock(i + 10, j + 1, k + 0, Blocks.cobblestone_wall, 1, 4);
		world.setBlock(i + 10, j + 1, k + 1, Blocks.stonebrick, 1, 4);
		world.setBlock(i + 10, j + 1, k + 2, Blocks.stonebrick, 1, 4);
		world.setBlock(i + 10, j + 1, k + 3, Blocks.stonebrick, 1, 4);
		world.setBlock(i + 10, j + 1, k + 4, Blocks.stonebrick);
		world.setBlock(i + 10, j + 1, k + 5, Blocks.stonebrick);
		world.setBlock(i + 10, j + 1, k + 6, Blocks.stonebrick);
		world.setBlock(i + 10, j + 1, k + 8, Blocks.stonebrick, 1, 4);
		world.setBlock(i + 10, j + 1, k + 9, Blocks.stonebrick, 1, 4);
		world.setBlock(i + 10, j + 1, k + 10, Blocks.stonebrick, 1, 4);
		world.setBlock(i + 10, j + 1, k + 11, Blocks.cobblestone_wall, 1, 4);
		world.setBlock(i + 10, j + 2, k + 0, Blocks.cobblestone_wall, 1, 4);
		world.setBlock(i + 10, j + 2, k + 1, Blocks.stonebrick, 1, 4);
		world.setBlock(i + 10, j + 2, k + 2, Blocks.stonebrick, 1, 4);
		world.setBlock(i + 10, j + 2, k + 3, Blocks.stonebrick, 1, 4);
		world.setBlock(i + 10, j + 2, k + 4, Blocks.stonebrick);
		world.setBlock(i + 10, j + 2, k + 5, Blocks.stonebrick);
		world.setBlock(i + 10, j + 2, k + 6, Blocks.stonebrick);
		world.setBlock(i + 10, j + 2, k + 8, Blocks.stonebrick, 1, 4);
		world.setBlock(i + 10, j + 2, k + 9, Blocks.stonebrick, 1, 4);
		world.setBlock(i + 10, j + 2, k + 10, Blocks.stonebrick, 1, 4);
		world.setBlock(i + 10, j + 2, k + 11, Blocks.cobblestone_wall, 1, 4);
		world.setBlock(i + 10, j + 3, k + 3, Blocks.iron_bars);
		world.setBlock(i + 10, j + 3, k + 4, Blocks.stonebrick);
		world.setBlock(i + 10, j + 3, k + 5, Blocks.stonebrick);
		world.setBlock(i + 10, j + 3, k + 6, Blocks.stonebrick);
		world.setBlock(i + 10, j + 3, k + 7, Blocks.stonebrick);
		world.setBlock(i + 10, j + 3, k + 8, Blocks.iron_bars);
		world.setBlock(i + 10, j + 4, k + 1, Blocks.stonebrick, 1, 4);
		world.setBlock(i + 10, j + 4, k + 2, Blocks.stonebrick, 1, 4);
		world.setBlock(i + 10, j + 4, k + 3, Blocks.stonebrick, 1, 4);
		world.setBlock(i + 10, j + 4, k + 4, Blocks.stonebrick, 1, 4);
		world.setBlock(i + 10, j + 4, k + 5, Blocks.stonebrick, 1, 4);
		world.setBlock(i + 10, j + 4, k + 6, Blocks.stonebrick, 1, 4);
		world.setBlock(i + 10, j + 4, k + 7, Blocks.stonebrick, 1, 4);
		world.setBlock(i + 10, j + 4, k + 8, Blocks.stonebrick, 1, 4);
		world.setBlock(i + 10, j + 4, k + 9, Blocks.stonebrick, 1, 4);
		world.setBlock(i + 10, j + 4, k + 10, Blocks.stonebrick, 1, 4);
		world.setBlock(i + 10, j + 5, k + 1, Blocks.stonebrick, 1, 4);
		world.setBlock(i + 10, j + 5, k + 2, Blocks.stonebrick, 1, 4);
		world.setBlock(i + 10, j + 5, k + 3, Blocks.stonebrick, 1, 4);
		world.setBlock(i + 10, j + 5, k + 4, Blocks.stonebrick, 1, 4);
		world.setBlock(i + 10, j + 5, k + 5, Blocks.nether_brick);
		world.setBlock(i + 10, j + 5, k + 6, Blocks.nether_brick);
		world.setBlock(i + 10, j + 5, k + 7, Blocks.stonebrick, 1, 4);
		world.setBlock(i + 10, j + 5, k + 8, Blocks.stonebrick, 1, 4);
		world.setBlock(i + 10, j + 5, k + 9, Blocks.stonebrick, 1, 4);
		world.setBlock(i + 10, j + 5, k + 10, Blocks.stonebrick, 1, 4);
		world.setBlock(i + 10, j + 6, k + 4, Blocks.nether_brick);
		world.setBlock(i + 10, j + 6, k + 5, Blocks.nether_brick);
		world.setBlock(i + 10, j + 6, k + 6, Blocks.nether_brick);
		world.setBlock(i + 10, j + 6, k + 7, Blocks.nether_brick);
		world.setBlock(i + 10, j + 7, k + 1, Blocks.stone_slab, 6, 4);
		world.setBlock(i + 10, j + 7, k + 2, Blocks.nether_brick_stairs, 1, 4);
		world.setBlock(i + 10, j + 7, k + 3, Blocks.nether_brick_stairs, 1, 4);
		world.setBlock(i + 10, j + 7, k + 4, Blocks.nether_brick);
		world.setBlock(i + 10, j + 7, k + 5, Blocks.nether_brick);
		world.setBlock(i + 10, j + 7, k + 6, Blocks.nether_brick);
		world.setBlock(i + 10, j + 7, k + 7, Blocks.nether_brick);
		world.setBlock(i + 10, j + 7, k + 8, Blocks.nether_brick_stairs, 1, 4);
		world.setBlock(i + 10, j + 7, k + 9, Blocks.nether_brick_stairs, 1, 4);
		world.setBlock(i + 10, j + 7, k + 10, Blocks.stone_slab, 6, 4);
		world.setBlock(i + 10, j + 8, k + 4, Blocks.nether_brick_stairs, 2, 4);
		world.setBlock(i + 10, j + 8, k + 5, Blocks.netherrack);
		world.setBlock(i + 10, j + 8, k + 6, Blocks.netherrack);
		world.setBlock(i + 10, j + 8, k + 7, Blocks.nether_brick_stairs, 3, 4);
		world.setBlock(i + 10, j + 9, k + 5, Blocks.fire, 15, 4);
		world.setBlock(i + 10, j + 9, k + 6, Blocks.fire, 15, 4);
		world.setBlock(i + 11, j + 1, k + 0, Blocks.cobblestone_wall, 1, 4);
		world.setBlock(i + 11, j + 1, k + 1, Blocks.cobblestone_wall, 1, 4);
		world.setBlock(i + 11, j + 1, k + 2, Blocks.cobblestone_wall, 1, 4);
		world.setBlock(i + 11, j + 1, k + 3, Blocks.cobblestone_wall, 1, 4);
		world.setBlock(i + 11, j + 1, k + 4, Blocks.cobblestone_wall, 1, 4);
		world.setBlock(i + 11, j + 1, k + 5, Blocks.cobblestone_wall, 1, 4);
		world.setBlock(i + 11, j + 1, k + 6, Blocks.cobblestone_wall, 1, 4);
		world.setBlock(i + 11, j + 1, k + 7, Blocks.cobblestone_wall, 1, 4);
		world.setBlock(i + 11, j + 1, k + 8, Blocks.cobblestone_wall, 1, 4);
		world.setBlock(i + 11, j + 1, k + 9, Blocks.cobblestone_wall, 1, 4);
		world.setBlock(i + 11, j + 1, k + 10, Blocks.cobblestone_wall, 1, 4);
		world.setBlock(i + 11, j + 1, k + 11, Blocks.cobblestone_wall, 1, 4);
		world.setBlock(i + 11, j + 2, k + 0, Blocks.cobblestone_wall, 1, 4);
		world.setBlock(i + 11, j + 2, k + 1, Blocks.cobblestone_wall, 1, 4);
		world.setBlock(i + 11, j + 2, k + 2, Blocks.cobblestone_wall, 1, 4);
		world.setBlock(i + 11, j + 2, k + 3, Blocks.cobblestone_wall, 1, 4);
		world.setBlock(i + 11, j + 2, k + 4, Blocks.cobblestone_wall, 1, 4);
		world.setBlock(i + 11, j + 2, k + 5, Blocks.cobblestone_wall, 1, 4);
		world.setBlock(i + 11, j + 2, k + 6, Blocks.cobblestone_wall, 1, 4);
		world.setBlock(i + 11, j + 2, k + 8, Blocks.cobblestone_wall, 1, 4);
		world.setBlock(i + 11, j + 2, k + 9, Blocks.cobblestone_wall, 1, 4);
		world.setBlock(i + 11, j + 2, k + 10, Blocks.cobblestone_wall, 1, 4);
		world.setBlock(i + 11, j + 2, k + 11, Blocks.cobblestone_wall, 1, 4);
		world.setBlock(i + 11, j + 8, k + 4, Blocks.stone_slab, 6, 4);
		world.setBlock(i + 11, j + 8, k + 5, Blocks.nether_brick_stairs, 1, 4);
		world.setBlock(i + 11, j + 8, k + 6, Blocks.nether_brick_stairs, 1, 4);
		world.setBlock(i + 11, j + 8, k + 7, Blocks.stone_slab, 6, 4);
		world.setBlock(i + 1, j + 3, k + 1, Blocks.torch, 5, 4);
		world.setBlock(i + 1, j + 3, k + 10, Blocks.torch, 5, 4);
		world.setBlock(i + 2, j + 2, k + 6, Blocks.torch, 1, 4);
		world.setBlock(i + 2, j + 6, k + 3, Blocks.torch, 5, 4);
		world.setBlock(i + 2, j + 6, k + 8, Blocks.torch, 5, 4);
		world.setBlock(i + 3, j + 6, k + 2, Blocks.torch, 5, 4);
		world.setBlock(i + 3, j + 6, k + 9, Blocks.torch, 5, 4);
		world.setBlock(i + 3, j + 9, k + 4, Blocks.torch, 5, 4);
		world.setBlock(i + 3, j + 9, k + 7, Blocks.torch, 5, 4);
		world.setBlock(i + 3, j + 14, k + 4, Blocks.torch, 5, 4);
		world.setBlock(i + 3, j + 14, k + 7, Blocks.torch, 5, 4);
		world.setBlock(i + 4, j + 2, k + 9, Blocks.torch, 4, 4);
		world.setBlock(i + 4, j + 9, k + 3, Blocks.torch, 5, 4);
		world.setBlock(i + 4, j + 9, k + 8, Blocks.torch, 5, 4);
		world.setBlock(i + 4, j + 12, k + 4, Blocks.torch, 5, 4);
		world.setBlock(i + 4, j + 12, k + 7, Blocks.torch, 5, 4);
		world.setBlock(i + 4, j + 14, k + 3, Blocks.torch, 5, 4);
		world.setBlock(i + 4, j + 14, k + 8, Blocks.torch, 5, 4);
		world.setBlock(i + 5, j + 1, k + 9, Blocks.ladder, 2, 4);
		world.setBlock(i + 5, j + 2, k + 9, Blocks.ladder, 2, 4);
		world.setBlock(i + 5, j + 3, k + 0, Blocks.torch, 4, 4);
		world.setBlock(i + 5, j + 3, k + 9, Blocks.ladder, 2, 4);
		world.setBlock(i + 5, j + 4, k + 9, Blocks.ladder, 2, 4);
		world.setBlock(i + 5, j + 5, k + 9, Blocks.ladder, 2, 4);
		world.setBlock(i + 5, j + 6, k + 9, Blocks.ladder, 2, 4);
		world.setBlock(i + 5, j + 8, k + 8, Blocks.ladder, 2, 4);
		world.setBlock(i + 5, j + 9, k + 8, Blocks.ladder, 2, 4);
		world.setBlock(i + 5, j + 10, k + 8, Blocks.ladder, 2, 4);
		world.setBlock(i + 5, j + 11, k + 8, Blocks.ladder, 2, 4);
		world.setBlock(i + 5, j + 15, k + 7, Blocks.torch, 4, 4);
		world.setBlock(i + 5, j + 20, k + 5, Blocks.torch, 5, 4);
		world.setBlock(i + 5, j + 20, k + 6, Blocks.torch, 5, 4);
		world.setBlock(i + 6, j + 2, k + 9, Blocks.torch, 4, 4);
		world.setBlock(i + 6, j + 5, k + 2, Blocks.ladder, 3, 4);
		world.setBlock(i + 6, j + 6, k + 2, Blocks.ladder, 3, 4);
		world.setBlock(i + 6, j + 7, k + 2, Blocks.ladder, 3, 4);
		world.setBlock(i + 6, j + 8, k + 2, Blocks.ladder, 3, 4);
		world.setBlock(i + 6, j + 9, k + 2, Blocks.ladder, 3, 4);
		world.setBlock(i + 6, j + 11, k + 4, Blocks.ladder, 3, 4);
		world.setBlock(i + 6, j + 12, k + 4, Blocks.ladder, 3, 4);
		world.setBlock(i + 6, j + 13, k + 4, Blocks.ladder, 3, 4);
		world.setBlock(i + 6, j + 14, k + 4, Blocks.ladder, 3, 4);
		world.setBlock(i + 6, j + 15, k + 7, Blocks.torch, 4, 4);
		world.setBlock(i + 6, j + 20, k + 5, Blocks.torch, 5, 4);
		world.setBlock(i + 6, j + 20, k + 6, Blocks.torch, 5, 4);
		world.setBlock(i + 7, j + 3, k + 0, Blocks.torch, 4, 4);
		world.setBlock(i + 7, j + 9, k + 3, Blocks.torch, 5, 4);
		world.setBlock(i + 7, j + 9, k + 8, Blocks.torch, 5, 4);
		world.setBlock(i + 7, j + 12, k + 4, Blocks.torch, 5, 4);
		world.setBlock(i + 7, j + 12, k + 7, Blocks.torch, 5, 4);
		world.setBlock(i + 7, j + 14, k + 3, Blocks.torch, 5, 4);
		world.setBlock(i + 7, j + 14, k + 8, Blocks.torch, 5, 4);
		world.setBlock(i + 8, j + 6, k + 2, Blocks.torch, 5, 4);
		world.setBlock(i + 8, j + 6, k + 9, Blocks.torch, 5, 4);
		world.setBlock(i + 8, j + 9, k + 4, Blocks.torch, 5, 4);
		world.setBlock(i + 8, j + 9, k + 7, Blocks.torch, 5, 4);
		world.setBlock(i + 8, j + 14, k + 4, Blocks.torch, 5, 4);
		world.setBlock(i + 8, j + 14, k + 7, Blocks.torch, 5, 4);
		world.setBlock(i + 9, j + 2, k + 5, Blocks.torch, 2, 4);
		world.setBlock(i + 9, j + 6, k + 3, Blocks.torch, 5, 4);
		world.setBlock(i + 9, j + 6, k + 8, Blocks.torch, 5, 4);
		world.setBlock(i + 10, j + 3, k + 1, Blocks.torch, 5, 4);
		world.setBlock(i + 10, j + 3, k + 10, Blocks.torch, 5, 4);
		
		for (int c = 0; c < 20; c++){
			EntityDarkWizard dw = new EntityDarkWizard(world);
            dw.setLocationAndAngles(i + xLocs[c] + 0.5, j + yLocs[c] + 0.5, k + zLocs[c] + 0.5, MathHelper.wrapAngleTo180_float(world.rand.nextFloat() * 360.0F), 0.0F);
            dw.rotationYawHead = dw.rotationYaw;
            dw.renderYawOffset = dw.rotationYaw;
            dw.onSpawnWithEgg((IEntityLivingData)null);
			world.spawnEntityInWorld(dw);
		}
		
		world.setBlock(i + 5, j + 1, k + 6, Blocks.mob_spawner);
        TileEntityMobSpawner var19 = (TileEntityMobSpawner)world.getTileEntity(i + 5, j + 1, k + 6);

        if (var19 != null)
        {
            var19.func_145881_a().setEntityName("Dark Wizard");
        }
        
        world.setBlock(i + 6, j + 1, k + 1, Blocks.wooden_door, 1, 4);
		world.setBlock(i + 6, j + 2, k + 1, Blocks.wooden_door, 8, 4);
		
		return true;
	}
	final int[] xLocs = {4,10,7,1,2,2,9,9,2,2,9,9,3,3,8,8,3,3,8,8};
	final int[] yLocs = {1,1,1,1,2,2,2,2,5,5,5,5,8,8,8,8,11,11,11,11};
	final int[] zLocs = {1,7,10,4,2,9,2,9,2,9,2,9,3,8,3,8,3,8,3,8};
	
}