/*
*** MADE BY MITHION'S .SCHEMATIC TO JAVA CONVERTING TOOL v1.6 ***
*/

package wildycraft.structures;
import java.util.Random;

import wildycraft.Wildycraft;
import wildycraft.entity.EntityFremVillager;

import net.minecraft.block.Block;
import net.minecraft.init.Blocks;
import net.minecraft.item.ItemStack;
import net.minecraft.world.World;
import net.minecraft.world.gen.feature.WorldGenerator;

public class Lighthouse extends WorldGenerator
{
	public Lighthouse() { }

	public boolean generate(World world, Random rand, int i, int j, int k) {
		world.setBlock(i + 0, j + 0, k + 6, Wildycraft.rsAsh);
		world.setBlock(i + 0, j + 0, k + 7, Wildycraft.rsAsh);
		world.setBlock(i + 0, j + 0, k + 8, Wildycraft.rsAsh);
		world.setBlock(i + 0, j + 0, k + 9, Wildycraft.rsAsh);
		world.setBlock(i + 1, j + 0, k + 4, Wildycraft.rsAsh);
		world.setBlock(i + 1, j + 0, k + 5, Wildycraft.rsAsh);
		world.setBlock(i + 1, j + 0, k + 6, Wildycraft.rsAsh);
		world.setBlock(i + 1, j + 0, k + 7, Wildycraft.rsAsh);
		world.setBlock(i + 1, j + 0, k + 8, Wildycraft.rsAsh);
		world.setBlock(i + 1, j + 0, k + 9, Wildycraft.rsAsh);
		world.setBlock(i + 1, j + 0, k + 10, Wildycraft.rsAsh);
		world.setBlock(i + 1, j + 0, k + 11, Wildycraft.rsAsh);
		world.setBlock(i + 1, j + 14, k + 6, Blocks.fence);
		world.setBlock(i + 1, j + 14, k + 7, Blocks.fence);
		world.setBlock(i + 1, j + 14, k + 8, Blocks.fence);
		world.setBlock(i + 1, j + 14, k + 9, Blocks.fence);
		world.setBlock(i + 1, j + 15, k + 5, Blocks.planks, 1, 4);
		world.setBlock(i + 1, j + 15, k + 6, Blocks.planks, 1, 4);
		world.setBlock(i + 1, j + 15, k + 7, Blocks.planks, 1, 4);
		world.setBlock(i + 1, j + 15, k + 8, Blocks.planks, 1, 4);
		world.setBlock(i + 1, j + 15, k + 9, Blocks.planks, 1, 4);
		world.setBlock(i + 1, j + 15, k + 10, Blocks.planks, 1, 4);
		world.setBlock(i + 1, j + 16, k + 5, Blocks.iron_bars);
		world.setBlock(i + 1, j + 16, k + 6, Blocks.iron_bars);
		world.setBlock(i + 1, j + 16, k + 7, Blocks.iron_bars);
		world.setBlock(i + 1, j + 16, k + 8, Blocks.iron_bars);
		world.setBlock(i + 1, j + 16, k + 9, Blocks.iron_bars);
		world.setBlock(i + 1, j + 16, k + 10, Blocks.iron_bars);
		world.setBlock(i + 2, j + 0, k + 3, Wildycraft.rsAsh);
		world.setBlock(i + 2, j + 0, k + 4, Wildycraft.rsAsh);
		world.setBlock(i + 2, j + 0, k + 5, Wildycraft.rsAsh);
		world.setBlock(i + 2, j + 0, k + 6, Blocks.quartz_block);
		world.setBlock(i + 2, j + 0, k + 7, Blocks.quartz_block);
		world.setBlock(i + 2, j + 0, k + 8, Blocks.quartz_block);
		world.setBlock(i + 2, j + 0, k + 9, Blocks.quartz_block);
		world.setBlock(i + 2, j + 0, k + 10, Wildycraft.rsAsh);
		world.setBlock(i + 2, j + 0, k + 11, Wildycraft.rsAsh);
		world.setBlock(i + 2, j + 0, k + 12, Wildycraft.rsAsh);
		world.setBlock(i + 2, j + 1, k + 6, Blocks.quartz_block);
		world.setBlock(i + 2, j + 1, k + 7, Blocks.quartz_block);
		world.setBlock(i + 2, j + 1, k + 8, Blocks.quartz_block);
		world.setBlock(i + 2, j + 1, k + 9, Blocks.quartz_block);
		world.setBlock(i + 2, j + 2, k + 6, Blocks.quartz_block);
		world.setBlock(i + 2, j + 2, k + 7, Blocks.quartz_block);
		world.setBlock(i + 2, j + 2, k + 8, Blocks.quartz_block);
		world.setBlock(i + 2, j + 2, k + 9, Blocks.quartz_block);
		world.setBlock(i + 2, j + 3, k + 6, Blocks.quartz_block);
		world.setBlock(i + 2, j + 3, k + 7, Blocks.quartz_block);
		world.setBlock(i + 2, j + 3, k + 8, Blocks.quartz_block);
		world.setBlock(i + 2, j + 3, k + 9, Blocks.quartz_block);
		world.setBlock(i + 2, j + 4, k + 6, Blocks.quartz_block);
		world.setBlock(i + 2, j + 4, k + 7, Blocks.quartz_block);
		world.setBlock(i + 2, j + 4, k + 8, Blocks.quartz_block);
		world.setBlock(i + 2, j + 4, k + 9, Blocks.quartz_block);
		world.setBlock(i + 2, j + 5, k + 6, Blocks.quartz_block);
		world.setBlock(i + 2, j + 5, k + 7, Blocks.quartz_block);
		world.setBlock(i + 2, j + 5, k + 8, Blocks.quartz_block);
		world.setBlock(i + 2, j + 5, k + 9, Blocks.quartz_block);
		world.setBlock(i + 2, j + 6, k + 6, Blocks.quartz_block);
		world.setBlock(i + 2, j + 6, k + 7, Blocks.quartz_block);
		world.setBlock(i + 2, j + 6, k + 8, Blocks.quartz_block);
		world.setBlock(i + 2, j + 6, k + 9, Blocks.quartz_block);
		world.setBlock(i + 2, j + 7, k + 6, Blocks.quartz_block);
		world.setBlock(i + 2, j + 7, k + 7, Blocks.quartz_block);
		world.setBlock(i + 2, j + 7, k + 8, Blocks.quartz_block);
		world.setBlock(i + 2, j + 7, k + 9, Blocks.quartz_block);
		world.setBlock(i + 2, j + 8, k + 6, Blocks.quartz_block);
		world.setBlock(i + 2, j + 8, k + 7, Blocks.quartz_block);
		world.setBlock(i + 2, j + 8, k + 8, Blocks.quartz_block);
		world.setBlock(i + 2, j + 8, k + 9, Blocks.quartz_block);
		world.setBlock(i + 2, j + 9, k + 6, Blocks.quartz_block);
		world.setBlock(i + 2, j + 9, k + 7, Blocks.quartz_block);
		world.setBlock(i + 2, j + 9, k + 8, Blocks.quartz_block);
		world.setBlock(i + 2, j + 9, k + 9, Blocks.quartz_block);
		world.setBlock(i + 2, j + 10, k + 6, Blocks.quartz_block);
		world.setBlock(i + 2, j + 10, k + 7, Blocks.quartz_block);
		world.setBlock(i + 2, j + 10, k + 8, Blocks.quartz_block);
		world.setBlock(i + 2, j + 10, k + 9, Blocks.quartz_block);
		world.setBlock(i + 2, j + 11, k + 6, Blocks.quartz_block);
		world.setBlock(i + 2, j + 11, k + 7, Blocks.quartz_block);
		world.setBlock(i + 2, j + 11, k + 8, Blocks.quartz_block);
		world.setBlock(i + 2, j + 11, k + 9, Blocks.quartz_block);
		world.setBlock(i + 2, j + 12, k + 6, Blocks.quartz_block);
		world.setBlock(i + 2, j + 12, k + 7, Blocks.quartz_block);
		world.setBlock(i + 2, j + 12, k + 8, Blocks.quartz_block);
		world.setBlock(i + 2, j + 12, k + 9, Blocks.quartz_block);
		world.setBlock(i + 2, j + 13, k + 6, Blocks.quartz_block);
		world.setBlock(i + 2, j + 13, k + 7, Blocks.quartz_block);
		world.setBlock(i + 2, j + 13, k + 8, Blocks.quartz_block);
		world.setBlock(i + 2, j + 13, k + 9, Blocks.quartz_block);
		world.setBlock(i + 2, j + 14, k + 6, Blocks.quartz_block);
		world.setBlock(i + 2, j + 14, k + 7, Blocks.quartz_block);
		world.setBlock(i + 2, j + 14, k + 8, Blocks.quartz_block);
		world.setBlock(i + 2, j + 14, k + 9, Blocks.quartz_block);
		world.setBlock(i + 2, j + 15, k + 4, Blocks.planks, 1, 4);
		world.setBlock(i + 2, j + 15, k + 5, Blocks.planks, 1, 4);
		world.setBlock(i + 2, j + 15, k + 6, Blocks.planks, 1, 4);
		world.setBlock(i + 2, j + 15, k + 7, Blocks.planks, 1, 4);
		world.setBlock(i + 2, j + 15, k + 8, Blocks.planks, 1, 4);
		world.setBlock(i + 2, j + 15, k + 9, Blocks.planks, 1, 4);
		world.setBlock(i + 2, j + 15, k + 10, Blocks.planks, 1, 4);
		world.setBlock(i + 2, j + 15, k + 11, Blocks.planks, 1, 4);
		world.setBlock(i + 2, j + 16, k + 4, Blocks.iron_bars);
		world.setBlock(i + 2, j + 16, k + 5, Blocks.iron_bars);
		world.setBlock(i + 2, j + 16, k + 10, Blocks.iron_bars);
		world.setBlock(i + 2, j + 16, k + 11, Blocks.iron_bars);
		world.setBlock(i + 2, j + 21, k + 6, Blocks.hardened_clay, 14, 4);
		world.setBlock(i + 2, j + 21, k + 7, Blocks.hardened_clay, 14, 4);
		world.setBlock(i + 2, j + 21, k + 8, Blocks.hardened_clay, 14, 4);
		world.setBlock(i + 2, j + 21, k + 9, Blocks.hardened_clay, 14, 4);
		world.setBlock(i + 3, j + 0, k + 2, Wildycraft.rsAsh);
		world.setBlock(i + 3, j + 0, k + 3, Wildycraft.rsAsh);
		world.setBlock(i + 3, j + 0, k + 4, Wildycraft.rsAsh);
		world.setBlock(i + 3, j + 0, k + 5, Blocks.quartz_block);
		world.setBlock(i + 3, j + 0, k + 6, Blocks.planks, 1, 4);
		world.setBlock(i + 3, j + 0, k + 7, Blocks.planks, 1, 4);
		world.setBlock(i + 3, j + 0, k + 8, Blocks.planks, 1, 4);
		world.setBlock(i + 3, j + 0, k + 9, Blocks.planks, 1, 4);
		world.setBlock(i + 3, j + 0, k + 10, Blocks.quartz_block);
		world.setBlock(i + 3, j + 0, k + 11, Wildycraft.rsAsh);
		world.setBlock(i + 3, j + 0, k + 12, Wildycraft.rsAsh);
		world.setBlock(i + 3, j + 0, k + 13, Wildycraft.rsAsh);
		world.setBlock(i + 3, j + 1, k + 5, Blocks.quartz_block);
		world.setBlock(i + 3, j + 1, k + 10, Blocks.quartz_block);
		world.setBlock(i + 3, j + 2, k + 5, Blocks.quartz_block);
		world.setBlock(i + 3, j + 2, k + 10, Blocks.quartz_block);
		world.setBlock(i + 3, j + 3, k + 5, Blocks.quartz_block);
		world.setBlock(i + 3, j + 3, k + 10, Blocks.quartz_block);
		world.setBlock(i + 3, j + 4, k + 5, Blocks.quartz_block);
		world.setBlock(i + 3, j + 4, k + 10, Blocks.quartz_block);
		world.setBlock(i + 3, j + 5, k + 5, Blocks.quartz_block);
		world.setBlock(i + 3, j + 5, k + 10, Blocks.quartz_block);
		world.setBlock(i + 3, j + 6, k + 5, Blocks.quartz_block);
		world.setBlock(i + 3, j + 6, k + 10, Blocks.quartz_block);
		world.setBlock(i + 3, j + 7, k + 5, Blocks.quartz_block);
		world.setBlock(i + 3, j + 7, k + 6, Blocks.planks, 1, 4);
		world.setBlock(i + 3, j + 7, k + 7, Blocks.planks, 1, 4);
		world.setBlock(i + 3, j + 7, k + 8, Blocks.planks, 1, 4);
		world.setBlock(i + 3, j + 7, k + 9, Blocks.planks, 1, 4);
		world.setBlock(i + 3, j + 7, k + 10, Blocks.quartz_block);
		world.setBlock(i + 3, j + 8, k + 5, Blocks.quartz_block);
		world.setBlock(i + 3, j + 8, k + 6, Blocks.web);
		world.setBlock(i + 3, j + 8, k + 7, Blocks.bookshelf);
		world.setBlock(i + 3, j + 8, k + 8, Blocks.bookshelf);
		world.setBlock(i + 3, j + 8, k + 10, Blocks.quartz_block);
		world.setBlock(i + 3, j + 9, k + 5, Blocks.quartz_block);
		world.setBlock(i + 3, j + 9, k + 7, Blocks.bookshelf);
		world.setBlock(i + 3, j + 9, k + 8, Blocks.bookshelf);
		world.setBlock(i + 3, j + 9, k + 10, Blocks.quartz_block);
		world.setBlock(i + 3, j + 10, k + 5, Blocks.quartz_block);
		world.setBlock(i + 3, j + 10, k + 10, Blocks.quartz_block);
		world.setBlock(i + 3, j + 11, k + 5, Blocks.quartz_block);
		world.setBlock(i + 3, j + 11, k + 10, Blocks.quartz_block);
		world.setBlock(i + 3, j + 12, k + 5, Blocks.quartz_block);
		world.setBlock(i + 3, j + 12, k + 10, Blocks.quartz_block);
		world.setBlock(i + 3, j + 13, k + 5, Blocks.quartz_block);
		world.setBlock(i + 3, j + 13, k + 10, Blocks.quartz_block);
		world.setBlock(i + 3, j + 14, k + 3, Blocks.fence);
		world.setBlock(i + 3, j + 14, k + 4, Blocks.fence);
		world.setBlock(i + 3, j + 14, k + 5, Blocks.quartz_block);
		world.setBlock(i + 3, j + 14, k + 10, Blocks.quartz_block);
		world.setBlock(i + 3, j + 14, k + 11, Blocks.fence);
		world.setBlock(i + 3, j + 14, k + 12, Blocks.fence);
		world.setBlock(i + 3, j + 15, k + 3, Blocks.planks, 1, 4);
		world.setBlock(i + 3, j + 15, k + 4, Blocks.planks, 1, 4);
		world.setBlock(i + 3, j + 15, k + 5, Blocks.planks, 1, 4);
		world.setBlock(i + 3, j + 15, k + 6, Blocks.planks, 1, 4);
		world.setBlock(i + 3, j + 15, k + 7, Blocks.planks, 1, 4);
		world.setBlock(i + 3, j + 15, k + 8, Blocks.planks, 1, 4);
		world.setBlock(i + 3, j + 15, k + 9, Blocks.planks, 1, 4);
		world.setBlock(i + 3, j + 15, k + 10, Blocks.planks, 1, 4);
		world.setBlock(i + 3, j + 15, k + 11, Blocks.planks, 1, 4);
		world.setBlock(i + 3, j + 15, k + 12, Blocks.planks, 1, 4);
		world.setBlock(i + 3, j + 16, k + 3, Blocks.iron_bars);
		world.setBlock(i + 3, j + 16, k + 4, Blocks.iron_bars);
		world.setBlock(i + 3, j + 16, k + 5, Blocks.glass_pane);
		world.setBlock(i + 3, j + 16, k + 6, Blocks.stone);
		world.setBlock(i + 3, j + 16, k + 9, Blocks.stone);
		world.setBlock(i + 3, j + 16, k + 10, Blocks.glass_pane);
		world.setBlock(i + 3, j + 16, k + 11, Blocks.iron_bars);
		world.setBlock(i + 3, j + 16, k + 12, Blocks.iron_bars);
		world.setBlock(i + 3, j + 17, k + 5, Blocks.glass_pane);
		world.setBlock(i + 3, j + 17, k + 6, Blocks.stone);
		world.setBlock(i + 3, j + 17, k + 9, Blocks.stone);
		world.setBlock(i + 3, j + 17, k + 10, Blocks.glass_pane);
		world.setBlock(i + 3, j + 18, k + 5, Blocks.glass_pane);
		world.setBlock(i + 3, j + 18, k + 6, Blocks.stone);
		world.setBlock(i + 3, j + 18, k + 9, Blocks.stone);
		world.setBlock(i + 3, j + 18, k + 10, Blocks.glass_pane);
		world.setBlock(i + 3, j + 19, k + 5, Blocks.glass_pane);
		world.setBlock(i + 3, j + 19, k + 6, Blocks.stone);
		world.setBlock(i + 3, j + 19, k + 9, Blocks.stone);
		world.setBlock(i + 3, j + 19, k + 10, Blocks.glass_pane);
		world.setBlock(i + 3, j + 20, k + 5, Blocks.glass_pane);
		world.setBlock(i + 3, j + 20, k + 6, Blocks.stone);
		world.setBlock(i + 3, j + 20, k + 7, Blocks.stone_slab, 8, 4);
		world.setBlock(i + 3, j + 20, k + 8, Blocks.stone_slab, 8, 4);
		world.setBlock(i + 3, j + 20, k + 9, Blocks.stone);
		world.setBlock(i + 3, j + 20, k + 10, Blocks.glass_pane);
		world.setBlock(i + 3, j + 21, k + 5, Blocks.hardened_clay, 14, 4);
		world.setBlock(i + 3, j + 21, k + 6, Blocks.hardened_clay, 14, 4);
		world.setBlock(i + 3, j + 21, k + 7, Blocks.hardened_clay, 14, 4);
		world.setBlock(i + 3, j + 21, k + 8, Blocks.hardened_clay, 14, 4);
		world.setBlock(i + 3, j + 21, k + 9, Blocks.hardened_clay, 14, 4);
		world.setBlock(i + 3, j + 21, k + 10, Blocks.hardened_clay, 14, 4);
		world.setBlock(i + 3, j + 22, k + 6, Blocks.hardened_clay, 14, 4);
		world.setBlock(i + 3, j + 22, k + 7, Blocks.hardened_clay, 14, 4);
		world.setBlock(i + 3, j + 22, k + 8, Blocks.hardened_clay, 14, 4);
		world.setBlock(i + 3, j + 22, k + 9, Blocks.hardened_clay, 14, 4);
		world.setBlock(i + 4, j + 0, k + 1, Wildycraft.rsAsh);
		world.setBlock(i + 4, j + 0, k + 2, Wildycraft.rsAsh);
		world.setBlock(i + 4, j + 0, k + 3, Wildycraft.rsAsh);
		world.setBlock(i + 4, j + 0, k + 4, Blocks.quartz_block);
		world.setBlock(i + 4, j + 0, k + 5, Blocks.planks, 1, 4);
		world.setBlock(i + 4, j + 0, k + 6, Blocks.planks, 1, 4);
		world.setBlock(i + 4, j + 0, k + 7, Blocks.planks, 1, 4);
		world.setBlock(i + 4, j + 0, k + 9, Blocks.planks, 1, 4);
		world.setBlock(i + 4, j + 0, k + 10, Blocks.planks, 1, 4);
		world.setBlock(i + 4, j + 0, k + 11, Blocks.quartz_block);
		world.setBlock(i + 4, j + 0, k + 12, Wildycraft.rsAsh);
		world.setBlock(i + 4, j + 0, k + 13, Wildycraft.rsAsh);
		world.setBlock(i + 4, j + 0, k + 14, Wildycraft.rsAsh);
		world.setBlock(i + 4, j + 1, k + 4, Blocks.quartz_block);
		world.setBlock(i + 4, j + 1, k + 9, Blocks.planks, 1, 4);
		world.setBlock(i + 4, j + 1, k + 11, Blocks.quartz_block);
		world.setBlock(i + 4, j + 2, k + 4, Blocks.quartz_block);
		world.setBlock(i + 4, j + 2, k + 11, Blocks.quartz_block);
		world.setBlock(i + 4, j + 3, k + 4, Blocks.quartz_block);
		world.setBlock(i + 4, j + 3, k + 11, Blocks.quartz_block);
		world.setBlock(i + 4, j + 4, k + 4, Blocks.quartz_block);
		world.setBlock(i + 4, j + 4, k + 11, Blocks.quartz_block);
		world.setBlock(i + 4, j + 5, k + 4, Blocks.quartz_block);
		world.setBlock(i + 4, j + 5, k + 11, Blocks.quartz_block);
		world.setBlock(i + 4, j + 6, k + 4, Blocks.quartz_block);
		world.setBlock(i + 4, j + 6, k + 11, Blocks.quartz_block);
		world.setBlock(i + 4, j + 7, k + 4, Blocks.quartz_block);
		world.setBlock(i + 4, j + 7, k + 5, Blocks.planks, 1, 4);
		world.setBlock(i + 4, j + 7, k + 6, Blocks.planks, 1, 4);
		world.setBlock(i + 4, j + 7, k + 7, Blocks.planks, 1, 4);
		world.setBlock(i + 4, j + 7, k + 8, Blocks.planks, 1, 4);
		world.setBlock(i + 4, j + 7, k + 9, Blocks.planks, 1, 4);
		world.setBlock(i + 4, j + 7, k + 10, Blocks.planks, 1, 4);
		world.setBlock(i + 4, j + 7, k + 11, Blocks.quartz_block);
		world.setBlock(i + 4, j + 8, k + 4, Blocks.quartz_block);
		world.setBlock(i + 4, j + 8, k + 11, Blocks.quartz_block);
		world.setBlock(i + 4, j + 9, k + 4, Blocks.quartz_block);
		world.setBlock(i + 4, j + 9, k + 11, Blocks.quartz_block);
		world.setBlock(i + 4, j + 10, k + 4, Blocks.quartz_block);
		world.setBlock(i + 4, j + 10, k + 11, Blocks.quartz_block);
		world.setBlock(i + 4, j + 11, k + 4, Blocks.quartz_block);
		world.setBlock(i + 4, j + 11, k + 11, Blocks.quartz_block);
		world.setBlock(i + 4, j + 12, k + 4, Blocks.quartz_block);
		world.setBlock(i + 4, j + 12, k + 11, Blocks.quartz_block);
		world.setBlock(i + 4, j + 13, k + 4, Blocks.quartz_block);
		world.setBlock(i + 4, j + 13, k + 11, Blocks.quartz_block);
		world.setBlock(i + 4, j + 14, k + 3, Blocks.fence);
		world.setBlock(i + 4, j + 14, k + 4, Blocks.quartz_block);
		world.setBlock(i + 4, j + 14, k + 11, Blocks.quartz_block);
		world.setBlock(i + 4, j + 14, k + 12, Blocks.fence);
		world.setBlock(i + 4, j + 15, k + 2, Blocks.planks, 1, 4);
		world.setBlock(i + 4, j + 15, k + 3, Blocks.planks, 1, 4);
		world.setBlock(i + 4, j + 15, k + 4, Blocks.planks, 1, 4);
		world.setBlock(i + 4, j + 15, k + 5, Blocks.planks, 1, 4);
		world.setBlock(i + 4, j + 15, k + 6, Blocks.planks, 1, 4);
		world.setBlock(i + 4, j + 15, k + 7, Blocks.planks, 1, 4);
		world.setBlock(i + 4, j + 15, k + 8, Blocks.planks, 1, 4);
		world.setBlock(i + 4, j + 15, k + 9, Blocks.planks, 1, 4);
		world.setBlock(i + 4, j + 15, k + 10, Blocks.planks, 1, 4);
		world.setBlock(i + 4, j + 15, k + 11, Blocks.planks, 1, 4);
		world.setBlock(i + 4, j + 15, k + 12, Blocks.planks, 1, 4);
		world.setBlock(i + 4, j + 15, k + 13, Blocks.planks, 1, 4);
		world.setBlock(i + 4, j + 16, k + 2, Blocks.iron_bars);
		world.setBlock(i + 4, j + 16, k + 3, Blocks.iron_bars);
		world.setBlock(i + 4, j + 16, k + 4, Blocks.glass_pane);
		world.setBlock(i + 4, j + 16, k + 5, Blocks.glass_pane);
		world.setBlock(i + 4, j + 16, k + 10, Blocks.glass_pane);
		world.setBlock(i + 4, j + 16, k + 11, Blocks.glass_pane);
		world.setBlock(i + 4, j + 16, k + 12, Blocks.iron_bars);
		world.setBlock(i + 4, j + 16, k + 13, Blocks.iron_bars);
		world.setBlock(i + 4, j + 17, k + 4, Blocks.glass_pane);
		world.setBlock(i + 4, j + 17, k + 5, Blocks.glass_pane);
		world.setBlock(i + 4, j + 17, k + 10, Blocks.glass_pane);
		world.setBlock(i + 4, j + 17, k + 11, Blocks.glass_pane);
		world.setBlock(i + 4, j + 18, k + 4, Blocks.glass_pane);
		world.setBlock(i + 4, j + 18, k + 5, Blocks.glass_pane);
		world.setBlock(i + 4, j + 18, k + 10, Blocks.glass_pane);
		world.setBlock(i + 4, j + 18, k + 11, Blocks.glass_pane);
		world.setBlock(i + 4, j + 19, k + 4, Blocks.glass_pane);
		world.setBlock(i + 4, j + 19, k + 5, Blocks.glass_pane);
		world.setBlock(i + 4, j + 19, k + 10, Blocks.glass_pane);
		world.setBlock(i + 4, j + 19, k + 11, Blocks.glass_pane);
		world.setBlock(i + 4, j + 20, k + 4, Blocks.glass_pane);
		world.setBlock(i + 4, j + 20, k + 5, Blocks.glass_pane);
		world.setBlock(i + 4, j + 20, k + 7, Blocks.stone_slab, 8, 4);
		world.setBlock(i + 4, j + 20, k + 8, Blocks.stone_slab, 8, 4);
		world.setBlock(i + 4, j + 20, k + 10, Blocks.glass_pane);
		world.setBlock(i + 4, j + 20, k + 11, Blocks.glass_pane);
		world.setBlock(i + 4, j + 21, k + 4, Blocks.hardened_clay, 14, 4);
		world.setBlock(i + 4, j + 21, k + 5, Blocks.hardened_clay, 14, 4);
		world.setBlock(i + 4, j + 21, k + 10, Blocks.hardened_clay, 14, 4);
		world.setBlock(i + 4, j + 21, k + 11, Blocks.hardened_clay, 14, 4);
		world.setBlock(i + 4, j + 22, k + 5, Blocks.hardened_clay, 14, 4);
		world.setBlock(i + 4, j + 22, k + 6, Blocks.hardened_clay, 14, 4);
		world.setBlock(i + 4, j + 22, k + 7, Blocks.hardened_clay, 14, 4);
		world.setBlock(i + 4, j + 22, k + 8, Blocks.hardened_clay, 14, 4);
		world.setBlock(i + 4, j + 22, k + 9, Blocks.hardened_clay, 14, 4);
		world.setBlock(i + 4, j + 22, k + 10, Blocks.hardened_clay, 14, 4);
		world.setBlock(i + 5, j + 0, k + 1, Wildycraft.rsAsh);
		world.setBlock(i + 5, j + 0, k + 2, Wildycraft.rsAsh);
		world.setBlock(i + 5, j + 0, k + 3, Blocks.quartz_block);
		world.setBlock(i + 5, j + 0, k + 4, Blocks.planks, 1, 4);
		world.setBlock(i + 5, j + 0, k + 5, Blocks.planks, 1, 4);
		world.setBlock(i + 5, j + 0, k + 6, Blocks.planks, 1, 4);
		world.setBlock(i + 5, j + 0, k + 7, Blocks.planks, 1, 4);
		world.setBlock(i + 5, j + 0, k + 8, Blocks.planks, 1, 4);
		world.setBlock(i + 5, j + 0, k + 9, Blocks.planks, 1, 4);
		world.setBlock(i + 5, j + 0, k + 10, Blocks.planks, 1, 4);
		world.setBlock(i + 5, j + 0, k + 11, Blocks.planks, 1, 4);
		world.setBlock(i + 5, j + 0, k + 12, Blocks.quartz_block);
		world.setBlock(i + 5, j + 0, k + 13, Wildycraft.rsAsh);
		world.setBlock(i + 5, j + 0, k + 14, Wildycraft.rsAsh);
		world.setBlock(i + 5, j + 1, k + 3, Blocks.quartz_block);
		world.setBlock(i + 5, j + 1, k + 12, Blocks.quartz_block);
		world.setBlock(i + 5, j + 2, k + 3, Blocks.quartz_block);
		world.setBlock(i + 5, j + 2, k + 12, Blocks.quartz_block);
		world.setBlock(i + 5, j + 3, k + 3, Blocks.quartz_block);
		world.setBlock(i + 5, j + 3, k + 12, Blocks.quartz_block);
		world.setBlock(i + 5, j + 4, k + 3, Blocks.quartz_block);
		world.setBlock(i + 5, j + 4, k + 12, Blocks.quartz_block);
		world.setBlock(i + 5, j + 5, k + 3, Blocks.quartz_block);
		world.setBlock(i + 5, j + 5, k + 12, Blocks.quartz_block);
		world.setBlock(i + 5, j + 6, k + 3, Blocks.quartz_block);
		world.setBlock(i + 5, j + 6, k + 12, Blocks.quartz_block);
		world.setBlock(i + 5, j + 7, k + 3, Blocks.quartz_block);
		world.setBlock(i + 5, j + 7, k + 4, Blocks.planks, 1, 4);
		world.setBlock(i + 5, j + 7, k + 5, Blocks.planks, 1, 4);
		world.setBlock(i + 5, j + 7, k + 6, Blocks.planks, 1, 4);
		world.setBlock(i + 5, j + 7, k + 7, Blocks.planks, 1, 4);
		world.setBlock(i + 5, j + 7, k + 8, Blocks.planks, 1, 4);
		world.setBlock(i + 5, j + 7, k + 9, Blocks.planks, 1, 4);
		world.setBlock(i + 5, j + 7, k + 10, Blocks.planks, 1, 4);
		world.setBlock(i + 5, j + 7, k + 11, Blocks.planks, 1, 4);
		world.setBlock(i + 5, j + 7, k + 12, Blocks.quartz_block);
		world.setBlock(i + 5, j + 8, k + 3, Blocks.quartz_block);
		world.setBlock(i + 5, j + 8, k + 4, Blocks.web);
		world.setBlock(i + 5, j + 8, k + 12, Blocks.quartz_block);
		world.setBlock(i + 5, j + 9, k + 3, Blocks.quartz_block);
		world.setBlock(i + 5, j + 9, k + 12, Blocks.quartz_block);
		world.setBlock(i + 5, j + 10, k + 3, Blocks.quartz_block);
		world.setBlock(i + 5, j + 10, k + 12, Blocks.quartz_block);
		world.setBlock(i + 5, j + 11, k + 3, Blocks.quartz_block);
		world.setBlock(i + 5, j + 11, k + 12, Blocks.quartz_block);
		world.setBlock(i + 5, j + 12, k + 3, Blocks.quartz_block);
		world.setBlock(i + 5, j + 12, k + 12, Blocks.quartz_block);
		world.setBlock(i + 5, j + 13, k + 3, Blocks.quartz_block);
		world.setBlock(i + 5, j + 13, k + 12, Blocks.quartz_block);
		world.setBlock(i + 5, j + 14, k + 3, Blocks.quartz_block);
		world.setBlock(i + 5, j + 14, k + 12, Blocks.quartz_block);
		world.setBlock(i + 5, j + 15, k + 1, Blocks.planks, 1, 4);
		world.setBlock(i + 5, j + 15, k + 2, Blocks.planks, 1, 4);
		world.setBlock(i + 5, j + 15, k + 3, Blocks.planks, 1, 4);
		world.setBlock(i + 5, j + 15, k + 4, Blocks.planks, 1, 4);
		world.setBlock(i + 5, j + 15, k + 5, Blocks.planks, 1, 4);
		world.setBlock(i + 5, j + 15, k + 6, Blocks.planks, 1, 4);
		world.setBlock(i + 5, j + 15, k + 7, Blocks.planks, 1, 4);
		world.setBlock(i + 5, j + 15, k + 8, Blocks.planks, 1, 4);
		world.setBlock(i + 5, j + 15, k + 9, Blocks.planks, 1, 4);
		world.setBlock(i + 5, j + 15, k + 10, Blocks.planks, 1, 4);
		world.setBlock(i + 5, j + 15, k + 11, Blocks.planks, 1, 4);
		world.setBlock(i + 5, j + 15, k + 12, Blocks.planks, 1, 4);
		world.setBlock(i + 5, j + 15, k + 13, Blocks.planks, 1, 4);
		world.setBlock(i + 5, j + 15, k + 14, Blocks.planks, 1, 4);
		world.setBlock(i + 5, j + 16, k + 1, Blocks.iron_bars);
		world.setBlock(i + 5, j + 16, k + 2, Blocks.iron_bars);
		world.setBlock(i + 5, j + 16, k + 3, Blocks.glass_pane);
		world.setBlock(i + 5, j + 16, k + 4, Blocks.glass_pane);
		world.setBlock(i + 5, j + 16, k + 11, Blocks.glass_pane);
		world.setBlock(i + 5, j + 16, k + 12, Blocks.glass_pane);
		world.setBlock(i + 5, j + 16, k + 13, Blocks.iron_bars);
		world.setBlock(i + 5, j + 16, k + 14, Blocks.iron_bars);
		world.setBlock(i + 5, j + 17, k + 3, Blocks.glass_pane);
		world.setBlock(i + 5, j + 17, k + 4, Blocks.glass_pane);
		world.setBlock(i + 5, j + 17, k + 11, Blocks.glass_pane);
		world.setBlock(i + 5, j + 17, k + 12, Blocks.glass_pane);
		world.setBlock(i + 5, j + 18, k + 3, Blocks.glass_pane);
		world.setBlock(i + 5, j + 18, k + 4, Blocks.glass_pane);
		world.setBlock(i + 5, j + 18, k + 11, Blocks.glass_pane);
		world.setBlock(i + 5, j + 18, k + 12, Blocks.glass_pane);
		world.setBlock(i + 5, j + 19, k + 3, Blocks.glass_pane);
		world.setBlock(i + 5, j + 19, k + 4, Blocks.glass_pane);
		world.setBlock(i + 5, j + 19, k + 11, Blocks.glass_pane);
		world.setBlock(i + 5, j + 19, k + 12, Blocks.glass_pane);
		world.setBlock(i + 5, j + 20, k + 3, Blocks.glass_pane);
		world.setBlock(i + 5, j + 20, k + 4, Blocks.glass_pane);
		world.setBlock(i + 5, j + 20, k + 7, Blocks.stone_slab, 8, 4);
		world.setBlock(i + 5, j + 20, k + 8, Blocks.stone_slab, 8, 4);
		world.setBlock(i + 5, j + 20, k + 11, Blocks.glass_pane);
		world.setBlock(i + 5, j + 20, k + 12, Blocks.glass_pane);
		world.setBlock(i + 5, j + 21, k + 3, Blocks.hardened_clay, 14, 4);
		world.setBlock(i + 5, j + 21, k + 4, Blocks.hardened_clay, 14, 4);
		world.setBlock(i + 5, j + 21, k + 11, Blocks.hardened_clay, 14, 4);
		world.setBlock(i + 5, j + 21, k + 12, Blocks.hardened_clay, 14, 4);
		world.setBlock(i + 5, j + 22, k + 4, Blocks.hardened_clay, 14, 4);
		world.setBlock(i + 5, j + 22, k + 5, Blocks.hardened_clay, 14, 4);
		world.setBlock(i + 5, j + 22, k + 6, Blocks.hardened_clay, 14, 4);
		world.setBlock(i + 5, j + 22, k + 7, Blocks.hardened_clay, 14, 4);
		world.setBlock(i + 5, j + 22, k + 8, Blocks.hardened_clay, 14, 4);
		world.setBlock(i + 5, j + 22, k + 9, Blocks.hardened_clay, 14, 4);
		world.setBlock(i + 5, j + 22, k + 10, Blocks.hardened_clay, 14, 4);
		world.setBlock(i + 5, j + 22, k + 11, Blocks.hardened_clay, 14, 4);
		world.setBlock(i + 5, j + 23, k + 6, Blocks.hardened_clay, 14, 4);
		world.setBlock(i + 5, j + 23, k + 7, Blocks.hardened_clay, 14, 4);
		world.setBlock(i + 5, j + 23, k + 8, Blocks.hardened_clay, 14, 4);
		world.setBlock(i + 5, j + 23, k + 9, Blocks.hardened_clay, 14, 4);
		world.setBlock(i + 6, j + 0, k + 0, Wildycraft.rsAsh);
		world.setBlock(i + 6, j + 0, k + 1, Wildycraft.rsAsh);
		world.setBlock(i + 6, j + 0, k + 2, Blocks.quartz_block);
		world.setBlock(i + 6, j + 0, k + 3, Blocks.planks, 1, 4);
		world.setBlock(i + 6, j + 0, k + 4, Blocks.planks, 1, 4);
		world.setBlock(i + 6, j + 0, k + 5, Blocks.planks, 1, 4);
		world.setBlock(i + 6, j + 0, k + 6, Blocks.planks, 1, 4);
		world.setBlock(i + 6, j + 0, k + 7, Blocks.planks, 1, 4);
		world.setBlock(i + 6, j + 0, k + 8, Blocks.planks, 1, 4);
		world.setBlock(i + 6, j + 0, k + 9, Blocks.planks, 1, 4);
		world.setBlock(i + 6, j + 0, k + 10, Blocks.planks, 1, 4);
		world.setBlock(i + 6, j + 0, k + 11, Blocks.planks, 1, 4);
		world.setBlock(i + 6, j + 0, k + 12, Blocks.planks, 1, 4);
		world.setBlock(i + 6, j + 0, k + 13, Blocks.quartz_block);
		world.setBlock(i + 6, j + 0, k + 14, Wildycraft.rsAsh);
		world.setBlock(i + 6, j + 0, k + 15, Wildycraft.rsAsh);
		world.setBlock(i + 6, j + 1, k + 2, Blocks.quartz_block);
		world.setBlock(i + 6, j + 1, k + 5, Blocks.chest, 5, 4);
		world.setBlock(i + 6, j + 1, k + 13, Blocks.quartz_block);
		world.setBlock(i + 6, j + 2, k + 2, Blocks.quartz_block);
		world.setBlock(i + 6, j + 2, k + 13, Blocks.quartz_block);
		world.setBlock(i + 6, j + 3, k + 2, Blocks.quartz_block);
		world.setBlock(i + 6, j + 3, k + 13, Blocks.quartz_block);
		world.setBlock(i + 6, j + 4, k + 2, Blocks.quartz_block);
		world.setBlock(i + 6, j + 4, k + 13, Blocks.quartz_block);
		world.setBlock(i + 6, j + 5, k + 2, Blocks.quartz_block);
		world.setBlock(i + 6, j + 5, k + 13, Blocks.quartz_block);
		world.setBlock(i + 6, j + 6, k + 2, Blocks.quartz_block);
		world.setBlock(i + 6, j + 6, k + 13, Blocks.quartz_block);
		world.setBlock(i + 6, j + 7, k + 2, Blocks.quartz_block);
		world.setBlock(i + 6, j + 7, k + 3, Blocks.planks, 1, 4);
		world.setBlock(i + 6, j + 7, k + 4, Blocks.planks, 1, 4);
		world.setBlock(i + 6, j + 7, k + 5, Blocks.planks, 1, 4);
		world.setBlock(i + 6, j + 7, k + 6, Blocks.planks, 1, 4);
		world.setBlock(i + 6, j + 7, k + 7, Blocks.planks, 1, 4);
		world.setBlock(i + 6, j + 7, k + 8, Blocks.planks, 1, 4);
		world.setBlock(i + 6, j + 7, k + 9, Blocks.planks, 1, 4);
		world.setBlock(i + 6, j + 7, k + 10, Blocks.planks, 1, 4);
		world.setBlock(i + 6, j + 7, k + 11, Blocks.planks, 1, 4);
		world.setBlock(i + 6, j + 7, k + 12, Blocks.planks, 1, 4);
		world.setBlock(i + 6, j + 7, k + 13, Blocks.quartz_block);
		world.setBlock(i + 6, j + 8, k + 2, Blocks.quartz_block);
		world.setBlock(i + 6, j + 8, k + 13, Blocks.quartz_block);
		world.setBlock(i + 6, j + 9, k + 2, Blocks.quartz_block);
		world.setBlock(i + 6, j + 9, k + 13, Blocks.quartz_block);
		world.setBlock(i + 6, j + 10, k + 2, Blocks.quartz_block);
		world.setBlock(i + 6, j + 10, k + 13, Blocks.quartz_block);
		world.setBlock(i + 6, j + 11, k + 2, Blocks.quartz_block);
		world.setBlock(i + 6, j + 11, k + 13, Blocks.quartz_block);
		world.setBlock(i + 6, j + 12, k + 2, Blocks.quartz_block);
		world.setBlock(i + 6, j + 12, k + 13, Blocks.quartz_block);
		world.setBlock(i + 6, j + 13, k + 2, Blocks.quartz_block);
		world.setBlock(i + 6, j + 13, k + 13, Blocks.quartz_block);
		world.setBlock(i + 6, j + 14, k + 1, Blocks.fence);
		world.setBlock(i + 6, j + 14, k + 2, Blocks.quartz_block);
		world.setBlock(i + 6, j + 14, k + 13, Blocks.quartz_block);
		world.setBlock(i + 6, j + 14, k + 14, Blocks.fence);
		world.setBlock(i + 6, j + 15, k + 1, Blocks.planks, 1, 4);
		world.setBlock(i + 6, j + 15, k + 2, Blocks.planks, 1, 4);
		world.setBlock(i + 6, j + 15, k + 3, Blocks.planks, 1, 4);
		world.setBlock(i + 6, j + 15, k + 4, Blocks.planks, 1, 4);
		world.setBlock(i + 6, j + 15, k + 5, Blocks.planks, 1, 4);
		world.setBlock(i + 6, j + 15, k + 6, Blocks.planks, 1, 4);
		world.setBlock(i + 6, j + 15, k + 7, Blocks.planks, 1, 4);
		world.setBlock(i + 6, j + 15, k + 8, Blocks.planks, 1, 4);
		world.setBlock(i + 6, j + 15, k + 9, Blocks.planks, 1, 4);
		world.setBlock(i + 6, j + 15, k + 10, Blocks.planks, 1, 4);
		world.setBlock(i + 6, j + 15, k + 11, Blocks.planks, 1, 4);
		world.setBlock(i + 6, j + 15, k + 12, Blocks.planks, 1, 4);
		world.setBlock(i + 6, j + 15, k + 13, Blocks.planks, 1, 4);
		world.setBlock(i + 6, j + 15, k + 14, Blocks.planks, 1, 4);
		world.setBlock(i + 6, j + 16, k + 1, Blocks.iron_bars);
		world.setBlock(i + 6, j + 16, k + 3, Blocks.stone);
		world.setBlock(i + 6, j + 16, k + 12, Blocks.stone);
		world.setBlock(i + 6, j + 16, k + 14, Blocks.iron_bars);
		world.setBlock(i + 6, j + 17, k + 3, Blocks.stone);
		world.setBlock(i + 6, j + 17, k + 12, Blocks.stone);
		world.setBlock(i + 6, j + 18, k + 3, Blocks.stone);
		world.setBlock(i + 6, j + 18, k + 12, Blocks.stone);
		world.setBlock(i + 6, j + 19, k + 3, Blocks.stone);
		world.setBlock(i + 6, j + 19, k + 6, Blocks.glass_pane);
		world.setBlock(i + 6, j + 19, k + 7, Blocks.glass_pane);
		world.setBlock(i + 6, j + 19, k + 8, Blocks.glass_pane);
		world.setBlock(i + 6, j + 19, k + 9, Blocks.glass_pane);
		world.setBlock(i + 6, j + 19, k + 12, Blocks.stone);
		world.setBlock(i + 6, j + 20, k + 3, Blocks.stone);
		world.setBlock(i + 6, j + 20, k + 7, Blocks.stone_slab, 8, 4);
		world.setBlock(i + 6, j + 20, k + 8, Blocks.stone_slab, 8, 4);
		world.setBlock(i + 6, j + 20, k + 12, Blocks.stone);
		world.setBlock(i + 6, j + 21, k + 2, Blocks.hardened_clay, 14, 4);
		world.setBlock(i + 6, j + 21, k + 3, Blocks.hardened_clay, 14, 4);
		world.setBlock(i + 6, j + 21, k + 12, Blocks.hardened_clay, 14, 4);
		world.setBlock(i + 6, j + 21, k + 13, Blocks.hardened_clay, 14, 4);
		world.setBlock(i + 6, j + 22, k + 3, Blocks.hardened_clay, 14, 4);
		world.setBlock(i + 6, j + 22, k + 4, Blocks.hardened_clay, 14, 4);
		world.setBlock(i + 6, j + 22, k + 5, Blocks.hardened_clay, 14, 4);
		world.setBlock(i + 6, j + 22, k + 10, Blocks.hardened_clay, 14, 4);
		world.setBlock(i + 6, j + 22, k + 11, Blocks.hardened_clay, 14, 4);
		world.setBlock(i + 6, j + 22, k + 12, Blocks.hardened_clay, 14, 4);
		world.setBlock(i + 6, j + 23, k + 5, Blocks.hardened_clay, 14, 4);
		world.setBlock(i + 6, j + 23, k + 6, Blocks.hardened_clay, 14, 4);
		world.setBlock(i + 6, j + 23, k + 7, Blocks.hardened_clay, 14, 4);
		world.setBlock(i + 6, j + 23, k + 8, Blocks.hardened_clay, 14, 4);
		world.setBlock(i + 6, j + 23, k + 9, Blocks.hardened_clay, 14, 4);
		world.setBlock(i + 6, j + 23, k + 10, Blocks.hardened_clay, 14, 4);
		world.setBlock(i + 7, j + 0, k + 0, Wildycraft.rsAsh);
		world.setBlock(i + 7, j + 0, k + 1, Wildycraft.rsAsh);
		world.setBlock(i + 7, j + 0, k + 2, Blocks.quartz_block);
		world.setBlock(i + 7, j + 0, k + 3, Blocks.planks, 1, 4);
		world.setBlock(i + 7, j + 0, k + 4, Blocks.planks, 1, 4);
		world.setBlock(i + 7, j + 0, k + 5, Blocks.planks, 1, 4);
		world.setBlock(i + 7, j + 0, k + 6, Blocks.planks, 1, 4);
		world.setBlock(i + 7, j + 0, k + 7, Blocks.planks, 1, 4);
		world.setBlock(i + 7, j + 0, k + 8, Blocks.planks, 1, 4);
		world.setBlock(i + 7, j + 0, k + 9, Blocks.planks, 1, 4);
		world.setBlock(i + 7, j + 0, k + 10, Blocks.planks, 1, 4);
		world.setBlock(i + 7, j + 0, k + 11, Blocks.planks, 1, 4);
		world.setBlock(i + 7, j + 0, k + 12, Blocks.planks, 1, 4);
		world.setBlock(i + 7, j + 0, k + 13, Blocks.quartz_block);
		world.setBlock(i + 7, j + 0, k + 14, Wildycraft.rsAsh);
		world.setBlock(i + 7, j + 0, k + 15, Wildycraft.rsAsh);
		world.setBlock(i + 7, j + 1, k + 2, Blocks.quartz_block);
		world.setBlock(i + 7, j + 1, k + 13, Blocks.quartz_block);
		world.setBlock(i + 7, j + 2, k + 2, Blocks.quartz_block);
		world.setBlock(i + 7, j + 2, k + 8, Blocks.oak_stairs, 6, 4);
		world.setBlock(i + 7, j + 2, k + 9, Blocks.oak_stairs, 4, 4);
		world.setBlock(i + 7, j + 2, k + 13, Blocks.quartz_block);
		world.setBlock(i + 7, j + 3, k + 2, Blocks.quartz_block);
		world.setBlock(i + 7, j + 3, k + 9, Blocks.oak_stairs, 2, 4);
		world.setBlock(i + 7, j + 3, k + 10, Blocks.oak_stairs, 4, 4);
		world.setBlock(i + 7, j + 3, k + 13, Blocks.quartz_block);
		world.setBlock(i + 7, j + 4, k + 2, Blocks.quartz_block);
		world.setBlock(i + 7, j + 4, k + 13, Blocks.quartz_block);
		world.setBlock(i + 7, j + 5, k + 2, Blocks.quartz_block);
		world.setBlock(i + 7, j + 5, k + 13, Blocks.quartz_block);
		world.setBlock(i + 7, j + 6, k + 2, Blocks.quartz_block);
		world.setBlock(i + 7, j + 6, k + 8, Blocks.oak_stairs, 6, 4);
		world.setBlock(i + 7, j + 6, k + 9, Blocks.oak_stairs, 4, 4);
		world.setBlock(i + 7, j + 6, k + 13, Blocks.quartz_block);
		world.setBlock(i + 7, j + 7, k + 2, Blocks.quartz_block);
		world.setBlock(i + 7, j + 7, k + 3, Blocks.planks, 1, 4);
		world.setBlock(i + 7, j + 7, k + 4, Blocks.planks, 1, 4);
		world.setBlock(i + 7, j + 7, k + 5, Blocks.planks, 1, 4);
		world.setBlock(i + 7, j + 7, k + 6, Blocks.planks, 1, 4);
		world.setBlock(i + 7, j + 7, k + 7, Blocks.planks, 1, 4);
		world.setBlock(i + 7, j + 7, k + 9, Blocks.oak_stairs, 2, 4);
		world.setBlock(i + 7, j + 7, k + 10, Blocks.oak_stairs, 4, 4);
		world.setBlock(i + 7, j + 7, k + 11, Blocks.planks, 1, 4);
		world.setBlock(i + 7, j + 7, k + 12, Blocks.planks, 1, 4);
		world.setBlock(i + 7, j + 7, k + 13, Blocks.quartz_block);
		world.setBlock(i + 7, j + 8, k + 2, Blocks.quartz_block);
		world.setBlock(i + 7, j + 8, k + 3, Blocks.chest, 3, 4);
		world.setBlock(i + 7, j + 8, k + 13, Blocks.quartz_block);
		world.setBlock(i + 7, j + 9, k + 2, Blocks.quartz_block);
		world.setBlock(i + 7, j + 9, k + 13, Blocks.quartz_block);
		world.setBlock(i + 7, j + 10, k + 2, Blocks.quartz_block);
		world.setBlock(i + 7, j + 10, k + 8, Blocks.oak_stairs, 6, 4);
		world.setBlock(i + 7, j + 10, k + 9, Blocks.oak_stairs, 4, 4);
		world.setBlock(i + 7, j + 10, k + 13, Blocks.quartz_block);
		world.setBlock(i + 7, j + 11, k + 2, Blocks.quartz_block);
		world.setBlock(i + 7, j + 11, k + 9, Blocks.oak_stairs, 2, 4);
		world.setBlock(i + 7, j + 11, k + 10, Blocks.oak_stairs, 4, 4);
		world.setBlock(i + 7, j + 11, k + 13, Blocks.quartz_block);
		world.setBlock(i + 7, j + 12, k + 2, Blocks.quartz_block);
		world.setBlock(i + 7, j + 12, k + 13, Blocks.quartz_block);
		world.setBlock(i + 7, j + 13, k + 2, Blocks.quartz_block);
		world.setBlock(i + 7, j + 13, k + 13, Blocks.quartz_block);
		world.setBlock(i + 7, j + 14, k + 1, Blocks.fence);
		world.setBlock(i + 7, j + 14, k + 2, Blocks.quartz_block);
		world.setBlock(i + 7, j + 14, k + 8, Blocks.oak_stairs, 6, 4);
		world.setBlock(i + 7, j + 14, k + 9, Blocks.oak_stairs, 4, 4);
		world.setBlock(i + 7, j + 14, k + 13, Blocks.quartz_block);
		world.setBlock(i + 7, j + 14, k + 14, Blocks.fence);
		world.setBlock(i + 7, j + 15, k + 1, Blocks.planks, 1, 4);
		world.setBlock(i + 7, j + 15, k + 2, Blocks.planks, 1, 4);
		world.setBlock(i + 7, j + 15, k + 3, Blocks.planks, 1, 4);
		world.setBlock(i + 7, j + 15, k + 4, Blocks.planks, 1, 4);
		world.setBlock(i + 7, j + 15, k + 5, Blocks.planks, 1, 4);
		world.setBlock(i + 7, j + 15, k + 6, Blocks.planks, 1, 4);
		world.setBlock(i + 7, j + 15, k + 7, Blocks.planks, 1, 4);
		world.setBlock(i + 7, j + 15, k + 9, Blocks.oak_stairs, 2, 4);
		world.setBlock(i + 7, j + 15, k + 10, Blocks.wooden_slab, 8, 4);
		world.setBlock(i + 7, j + 15, k + 11, Blocks.planks, 1, 4);
		world.setBlock(i + 7, j + 15, k + 12, Blocks.planks, 1, 4);
		world.setBlock(i + 7, j + 15, k + 13, Blocks.planks, 1, 4);
		world.setBlock(i + 7, j + 15, k + 14, Blocks.planks, 1, 4);
		world.setBlock(i + 7, j + 16, k + 1, Blocks.iron_bars);
		world.setBlock(i + 7, j + 16, k + 14, Blocks.iron_bars);
		world.setBlock(i + 7, j + 18, k + 7, Blocks.stone_brick_stairs, 4, 4);
		world.setBlock(i + 7, j + 18, k + 8, Blocks.stone_brick_stairs, 7, 4);
		world.setBlock(i + 7, j + 19, k + 6, Blocks.glass_pane);
		world.setBlock(i + 7, j + 19, k + 7, Blocks.glowstone, 0, 4);
		world.setBlock(i + 7, j + 19, k + 8, Blocks.glowstone, 0, 4);
		world.setBlock(i + 7, j + 19, k + 9, Blocks.glass_pane);
		world.setBlock(i + 7, j + 20, k + 3, Blocks.stone_slab, 8, 4);
		world.setBlock(i + 7, j + 20, k + 4, Blocks.stone_slab, 8, 4);
		world.setBlock(i + 7, j + 20, k + 5, Blocks.stone_slab, 8, 4);
		world.setBlock(i + 7, j + 20, k + 6, Blocks.stone_slab, 8, 4);
		world.setBlock(i + 7, j + 20, k + 7, Blocks.stonebrick);
		world.setBlock(i + 7, j + 20, k + 8, Blocks.stonebrick);
		world.setBlock(i + 7, j + 20, k + 9, Blocks.stone_slab, 8, 4);
		world.setBlock(i + 7, j + 20, k + 10, Blocks.stone_slab, 8, 4);
		world.setBlock(i + 7, j + 20, k + 11, Blocks.stone_slab, 8, 4);
		world.setBlock(i + 7, j + 20, k + 12, Blocks.stone_slab, 8, 4);
		world.setBlock(i + 7, j + 21, k + 2, Blocks.hardened_clay, 14, 4);
		world.setBlock(i + 7, j + 21, k + 3, Blocks.hardened_clay, 14, 4);
		world.setBlock(i + 7, j + 21, k + 12, Blocks.hardened_clay, 14, 4);
		world.setBlock(i + 7, j + 21, k + 13, Blocks.hardened_clay, 14, 4);
		world.setBlock(i + 7, j + 22, k + 3, Blocks.hardened_clay, 14, 4);
		world.setBlock(i + 7, j + 22, k + 4, Blocks.hardened_clay, 14, 4);
		world.setBlock(i + 7, j + 22, k + 5, Blocks.hardened_clay, 14, 4);
		world.setBlock(i + 7, j + 22, k + 10, Blocks.hardened_clay, 14, 4);
		world.setBlock(i + 7, j + 22, k + 11, Blocks.hardened_clay, 14, 4);
		world.setBlock(i + 7, j + 22, k + 12, Blocks.hardened_clay, 14, 4);
		world.setBlock(i + 7, j + 23, k + 5, Blocks.hardened_clay, 14, 4);
		world.setBlock(i + 7, j + 23, k + 6, Blocks.hardened_clay, 14, 4);
		world.setBlock(i + 7, j + 23, k + 7, Blocks.hardened_clay, 14, 4);
		world.setBlock(i + 7, j + 23, k + 8, Blocks.hardened_clay, 14, 4);
		world.setBlock(i + 7, j + 23, k + 9, Blocks.hardened_clay, 14, 4);
		world.setBlock(i + 7, j + 23, k + 10, Blocks.hardened_clay, 14, 4);
		world.setBlock(i + 8, j + 0, k + 0, Wildycraft.rsAsh);
		world.setBlock(i + 8, j + 0, k + 1, Wildycraft.rsAsh);
		world.setBlock(i + 8, j + 0, k + 2, Blocks.quartz_block);
		world.setBlock(i + 8, j + 0, k + 3, Blocks.planks, 1, 4);
		world.setBlock(i + 8, j + 0, k + 4, Blocks.planks, 1, 4);
		world.setBlock(i + 8, j + 0, k + 5, Blocks.planks, 1, 4);
		world.setBlock(i + 8, j + 0, k + 6, Blocks.planks, 1, 4);
		world.setBlock(i + 8, j + 0, k + 7, Blocks.planks, 1, 4);
		world.setBlock(i + 8, j + 0, k + 8, Blocks.planks, 1, 4);
		world.setBlock(i + 8, j + 0, k + 9, Blocks.planks, 1, 4);
		world.setBlock(i + 8, j + 0, k + 10, Blocks.planks, 1, 4);
		world.setBlock(i + 8, j + 0, k + 11, Blocks.planks, 1, 4);
		world.setBlock(i + 8, j + 0, k + 12, Blocks.planks, 1, 4);
		world.setBlock(i + 8, j + 0, k + 13, Blocks.quartz_block);
		world.setBlock(i + 8, j + 0, k + 14, Wildycraft.rsAsh);
		world.setBlock(i + 8, j + 0, k + 15, Wildycraft.rsAsh);
		world.setBlock(i + 8, j + 1, k + 2, Blocks.quartz_block);
		world.setBlock(i + 8, j + 1, k + 4, Blocks.spruce_stairs, 3, 4);
		world.setBlock(i + 8, j + 1, k + 5, Blocks.fence);
		world.setBlock(i + 8, j + 1, k + 6, Blocks.spruce_stairs, 2, 4);
		world.setBlock(i + 8, j + 1, k + 8, Blocks.oak_stairs, 6, 4);
		world.setBlock(i + 8, j + 1, k + 9, Blocks.fence);
		world.setBlock(i + 8, j + 1, k + 13, Blocks.quartz_block);
		world.setBlock(i + 8, j + 2, k + 2, Blocks.quartz_block);
		world.setBlock(i + 8, j + 2, k + 5, Blocks.carpet, 12, 4);
		world.setBlock(i + 8, j + 2, k + 8, Blocks.oak_stairs, 1, 4);
		world.setBlock(i + 8, j + 2, k + 9, Blocks.fence);
		world.setBlock(i + 8, j + 2, k + 13, Blocks.quartz_block);
		world.setBlock(i + 8, j + 3, k + 2, Blocks.quartz_block);
		world.setBlock(i + 8, j + 3, k + 9, Blocks.fence);
		world.setBlock(i + 8, j + 3, k + 10, Blocks.oak_stairs, 7, 4);
		world.setBlock(i + 8, j + 3, k + 13, Blocks.quartz_block);
		world.setBlock(i + 8, j + 4, k + 2, Blocks.quartz_block);
		world.setBlock(i + 8, j + 4, k + 9, Blocks.fence);
		world.setBlock(i + 8, j + 4, k + 10, Blocks.oak_stairs);
		world.setBlock(i + 8, j + 4, k + 13, Blocks.quartz_block);
		world.setBlock(i + 8, j + 5, k + 2, Blocks.quartz_block);
		world.setBlock(i + 8, j + 5, k + 8, Blocks.oak_stairs, 6, 4);
		world.setBlock(i + 8, j + 5, k + 9, Blocks.fence);
		world.setBlock(i + 8, j + 5, k + 13, Blocks.quartz_block);
		world.setBlock(i + 8, j + 6, k + 2, Blocks.quartz_block);
		world.setBlock(i + 8, j + 6, k + 8, Blocks.oak_stairs, 1, 4);
		world.setBlock(i + 8, j + 6, k + 9, Blocks.fence);
		world.setBlock(i + 8, j + 6, k + 13, Blocks.quartz_block);
		world.setBlock(i + 8, j + 7, k + 2, Blocks.quartz_block);
		world.setBlock(i + 8, j + 7, k + 3, Blocks.planks, 1, 4);
		world.setBlock(i + 8, j + 7, k + 4, Blocks.planks, 1, 4);
		world.setBlock(i + 8, j + 7, k + 5, Blocks.planks, 1, 4);
		world.setBlock(i + 8, j + 7, k + 6, Blocks.planks, 1, 4);
		world.setBlock(i + 8, j + 7, k + 7, Blocks.planks, 1, 4);
		world.setBlock(i + 8, j + 7, k + 9, Blocks.fence);
		world.setBlock(i + 8, j + 7, k + 10, Blocks.oak_stairs, 7, 4);
		world.setBlock(i + 8, j + 7, k + 11, Blocks.planks, 1, 4);
		world.setBlock(i + 8, j + 7, k + 12, Blocks.planks, 1, 4);
		world.setBlock(i + 8, j + 7, k + 13, Blocks.quartz_block);
		world.setBlock(i + 8, j + 8, k + 2, Blocks.quartz_block);
		world.setBlock(i + 8, j + 8, k + 3, Blocks.bed, 10, 4);
		world.setBlock(i + 8, j + 8, k + 4, Blocks.bed, 2, 4);
		world.setBlock(i + 8, j + 8, k + 9, Blocks.fence);
		world.setBlock(i + 8, j + 8, k + 10, Blocks.oak_stairs);
		world.setBlock(i + 8, j + 8, k + 13, Blocks.quartz_block);
		world.setBlock(i + 8, j + 9, k + 2, Blocks.quartz_block);
		world.setBlock(i + 8, j + 9, k + 8, Blocks.oak_stairs, 6, 4);
		world.setBlock(i + 8, j + 9, k + 9, Blocks.fence);
		world.setBlock(i + 8, j + 9, k + 13, Blocks.quartz_block);
		world.setBlock(i + 8, j + 10, k + 2, Blocks.quartz_block);
		world.setBlock(i + 8, j + 10, k + 8, Blocks.oak_stairs, 1, 4);
		world.setBlock(i + 8, j + 10, k + 9, Blocks.fence);
		world.setBlock(i + 8, j + 10, k + 13, Blocks.quartz_block);
		world.setBlock(i + 8, j + 11, k + 2, Blocks.quartz_block);
		world.setBlock(i + 8, j + 11, k + 9, Blocks.fence);
		world.setBlock(i + 8, j + 11, k + 10, Blocks.oak_stairs, 7, 4);
		world.setBlock(i + 8, j + 11, k + 13, Blocks.quartz_block);
		world.setBlock(i + 8, j + 12, k + 2, Blocks.quartz_block);
		world.setBlock(i + 8, j + 12, k + 9, Blocks.fence);
		world.setBlock(i + 8, j + 12, k + 10, Blocks.oak_stairs);
		world.setBlock(i + 8, j + 12, k + 13, Blocks.quartz_block);
		world.setBlock(i + 8, j + 13, k + 2, Blocks.quartz_block);
		world.setBlock(i + 8, j + 13, k + 8, Blocks.oak_stairs, 6, 4);
		world.setBlock(i + 8, j + 13, k + 9, Blocks.fence);
		world.setBlock(i + 8, j + 13, k + 13, Blocks.quartz_block);
		world.setBlock(i + 8, j + 14, k + 1, Blocks.fence);
		world.setBlock(i + 8, j + 14, k + 2, Blocks.quartz_block);
		world.setBlock(i + 8, j + 14, k + 8, Blocks.oak_stairs, 1, 4);
		world.setBlock(i + 8, j + 14, k + 9, Blocks.fence);
		world.setBlock(i + 8, j + 14, k + 13, Blocks.quartz_block);
		world.setBlock(i + 8, j + 14, k + 14, Blocks.fence);
		world.setBlock(i + 8, j + 15, k + 1, Blocks.planks, 1, 4);
		world.setBlock(i + 8, j + 15, k + 2, Blocks.planks, 1, 4);
		world.setBlock(i + 8, j + 15, k + 3, Blocks.planks, 1, 4);
		world.setBlock(i + 8, j + 15, k + 4, Blocks.planks, 1, 4);
		world.setBlock(i + 8, j + 15, k + 5, Blocks.planks, 1, 4);
		world.setBlock(i + 8, j + 15, k + 6, Blocks.planks, 1, 4);
		world.setBlock(i + 8, j + 15, k + 7, Blocks.planks, 1, 4);
		world.setBlock(i + 8, j + 15, k + 9, Blocks.fence);
		world.setBlock(i + 8, j + 15, k + 11, Blocks.planks, 1, 4);
		world.setBlock(i + 8, j + 15, k + 12, Blocks.planks, 1, 4);
		world.setBlock(i + 8, j + 15, k + 13, Blocks.planks, 1, 4);
		world.setBlock(i + 8, j + 15, k + 14, Blocks.planks, 1, 4);
		world.setBlock(i + 8, j + 16, k + 1, Blocks.iron_bars);
		world.setBlock(i + 8, j + 16, k + 14, Blocks.iron_bars);
		world.setBlock(i + 8, j + 18, k + 7, Blocks.stone_brick_stairs, 6, 4);
		world.setBlock(i + 8, j + 18, k + 8, Blocks.stone_brick_stairs, 5, 4);
		world.setBlock(i + 8, j + 19, k + 6, Blocks.glass_pane);
		world.setBlock(i + 8, j + 19, k + 7, Blocks.glowstone, 0, 4);
		world.setBlock(i + 8, j + 19, k + 8, Blocks.glowstone, 0, 4);
		world.setBlock(i + 8, j + 19, k + 9, Blocks.glass_pane);
		world.setBlock(i + 8, j + 20, k + 3, Blocks.stone_slab, 8, 4);
		world.setBlock(i + 8, j + 20, k + 4, Blocks.stone_slab, 8, 4);
		world.setBlock(i + 8, j + 20, k + 5, Blocks.stone_slab, 8, 4);
		world.setBlock(i + 8, j + 20, k + 6, Blocks.stone_slab, 8, 4);
		world.setBlock(i + 8, j + 20, k + 7, Blocks.stonebrick);
		world.setBlock(i + 8, j + 20, k + 8, Blocks.stonebrick);
		world.setBlock(i + 8, j + 20, k + 9, Blocks.stone_slab, 8, 4);
		world.setBlock(i + 8, j + 20, k + 10, Blocks.stone_slab, 8, 4);
		world.setBlock(i + 8, j + 20, k + 11, Blocks.stone_slab, 8, 4);
		world.setBlock(i + 8, j + 20, k + 12, Blocks.stone_slab, 8, 4);
		world.setBlock(i + 8, j + 21, k + 2, Blocks.hardened_clay, 14, 4);
		world.setBlock(i + 8, j + 21, k + 3, Blocks.hardened_clay, 14, 4);
		world.setBlock(i + 8, j + 21, k + 12, Blocks.hardened_clay, 14, 4);
		world.setBlock(i + 8, j + 21, k + 13, Blocks.hardened_clay, 14, 4);
		world.setBlock(i + 8, j + 22, k + 3, Blocks.hardened_clay, 14, 4);
		world.setBlock(i + 8, j + 22, k + 4, Blocks.hardened_clay, 14, 4);
		world.setBlock(i + 8, j + 22, k + 5, Blocks.hardened_clay, 14, 4);
		world.setBlock(i + 8, j + 22, k + 10, Blocks.hardened_clay, 14, 4);
		world.setBlock(i + 8, j + 22, k + 11, Blocks.hardened_clay, 14, 4);
		world.setBlock(i + 8, j + 22, k + 12, Blocks.hardened_clay, 14, 4);
		world.setBlock(i + 8, j + 23, k + 5, Blocks.hardened_clay, 14, 4);
		world.setBlock(i + 8, j + 23, k + 6, Blocks.hardened_clay, 14, 4);
		world.setBlock(i + 8, j + 23, k + 7, Blocks.hardened_clay, 14, 4);
		world.setBlock(i + 8, j + 23, k + 8, Blocks.hardened_clay, 14, 4);
		world.setBlock(i + 8, j + 23, k + 9, Blocks.hardened_clay, 14, 4);
		world.setBlock(i + 8, j + 23, k + 10, Blocks.hardened_clay, 14, 4);
		world.setBlock(i + 9, j + 0, k + 0, Wildycraft.rsAsh);
		world.setBlock(i + 9, j + 0, k + 1, Wildycraft.rsAsh);
		world.setBlock(i + 9, j + 0, k + 2, Blocks.quartz_block);
		world.setBlock(i + 9, j + 0, k + 3, Blocks.planks, 1, 4);
		world.setBlock(i + 9, j + 0, k + 4, Blocks.planks, 1, 4);
		world.setBlock(i + 9, j + 0, k + 5, Blocks.planks, 1, 4);
		world.setBlock(i + 9, j + 0, k + 6, Blocks.planks, 1, 4);
		world.setBlock(i + 9, j + 0, k + 7, Blocks.planks, 1, 4);
		world.setBlock(i + 9, j + 0, k + 8, Blocks.planks, 1, 4);
		world.setBlock(i + 9, j + 0, k + 9, Blocks.planks, 1, 4);
		world.setBlock(i + 9, j + 0, k + 10, Blocks.planks, 1, 4);
		world.setBlock(i + 9, j + 0, k + 11, Blocks.planks, 1, 4);
		world.setBlock(i + 9, j + 0, k + 12, Blocks.planks, 1, 4);
		world.setBlock(i + 9, j + 0, k + 13, Blocks.quartz_block);
		world.setBlock(i + 9, j + 0, k + 14, Wildycraft.rsAsh);
		world.setBlock(i + 9, j + 0, k + 15, Wildycraft.rsAsh);
		world.setBlock(i + 9, j + 1, k + 2, Blocks.quartz_block);
		world.setBlock(i + 9, j + 1, k + 5, Blocks.spruce_stairs);
		world.setBlock(i + 9, j + 1, k + 8, Blocks.oak_stairs, 5, 4);
		world.setBlock(i + 9, j + 1, k + 9, Blocks.oak_stairs, 3, 4);
		world.setBlock(i + 9, j + 1, k + 13, Blocks.quartz_block);
		world.setBlock(i + 9, j + 2, k + 2, Blocks.quartz_block);
		world.setBlock(i + 9, j + 2, k + 13, Blocks.quartz_block);
		world.setBlock(i + 9, j + 3, k + 2, Blocks.quartz_block);
		world.setBlock(i + 9, j + 3, k + 13, Blocks.quartz_block);
		world.setBlock(i + 9, j + 4, k + 2, Blocks.quartz_block);
		world.setBlock(i + 9, j + 4, k + 9, Blocks.oak_stairs, 5, 4);
		world.setBlock(i + 9, j + 4, k + 10, Blocks.oak_stairs, 7, 4);
		world.setBlock(i + 9, j + 4, k + 13, Blocks.quartz_block);
		world.setBlock(i + 9, j + 5, k + 2, Blocks.quartz_block);
		world.setBlock(i + 9, j + 5, k + 8, Blocks.oak_stairs, 5, 4);
		world.setBlock(i + 9, j + 5, k + 9, Blocks.oak_stairs, 3, 4);
		world.setBlock(i + 9, j + 5, k + 13, Blocks.quartz_block);
		world.setBlock(i + 9, j + 6, k + 2, Blocks.quartz_block);
		world.setBlock(i + 9, j + 6, k + 13, Blocks.quartz_block);
		world.setBlock(i + 9, j + 7, k + 2, Blocks.quartz_block);
		world.setBlock(i + 9, j + 7, k + 3, Blocks.planks, 1, 4);
		world.setBlock(i + 9, j + 7, k + 4, Blocks.planks, 1, 4);
		world.setBlock(i + 9, j + 7, k + 5, Blocks.planks, 1, 4);
		world.setBlock(i + 9, j + 7, k + 6, Blocks.planks, 1, 4);
		world.setBlock(i + 9, j + 7, k + 7, Blocks.planks, 1, 4);
		world.setBlock(i + 9, j + 7, k + 11, Blocks.planks, 1, 4);
		world.setBlock(i + 9, j + 7, k + 12, Blocks.planks, 1, 4);
		world.setBlock(i + 9, j + 7, k + 13, Blocks.quartz_block);
		world.setBlock(i + 9, j + 8, k + 2, Blocks.quartz_block);
		world.setBlock(i + 9, j + 8, k + 9, Blocks.oak_stairs, 5, 4);
		world.setBlock(i + 9, j + 8, k + 10, Blocks.oak_stairs, 7, 4);
		world.setBlock(i + 9, j + 8, k + 13, Blocks.quartz_block);
		world.setBlock(i + 9, j + 9, k + 2, Blocks.quartz_block);
		world.setBlock(i + 9, j + 9, k + 8, Blocks.oak_stairs, 5, 4);
		world.setBlock(i + 9, j + 9, k + 9, Blocks.oak_stairs, 3, 4);
		world.setBlock(i + 9, j + 9, k + 13, Blocks.quartz_block);
		world.setBlock(i + 9, j + 10, k + 2, Blocks.quartz_block);
		world.setBlock(i + 9, j + 10, k + 13, Blocks.quartz_block);
		world.setBlock(i + 9, j + 11, k + 2, Blocks.quartz_block);
		world.setBlock(i + 9, j + 11, k + 13, Blocks.quartz_block);
		world.setBlock(i + 9, j + 12, k + 2, Blocks.quartz_block);
		world.setBlock(i + 9, j + 12, k + 9, Blocks.oak_stairs, 5, 4);
		world.setBlock(i + 9, j + 12, k + 10, Blocks.oak_stairs, 7, 4);
		world.setBlock(i + 9, j + 12, k + 13, Blocks.quartz_block);
		world.setBlock(i + 9, j + 13, k + 2, Blocks.quartz_block);
		world.setBlock(i + 9, j + 13, k + 8, Blocks.oak_stairs, 5, 4);
		world.setBlock(i + 9, j + 13, k + 9, Blocks.oak_stairs, 3, 4);
		world.setBlock(i + 9, j + 13, k + 13, Blocks.quartz_block);
		world.setBlock(i + 9, j + 14, k + 1, Blocks.fence);
		world.setBlock(i + 9, j + 14, k + 2, Blocks.quartz_block);
		world.setBlock(i + 9, j + 14, k + 13, Blocks.quartz_block);
		world.setBlock(i + 9, j + 14, k + 14, Blocks.fence);
		world.setBlock(i + 9, j + 15, k + 1, Blocks.planks, 1, 4);
		world.setBlock(i + 9, j + 15, k + 2, Blocks.planks, 1, 4);
		world.setBlock(i + 9, j + 15, k + 3, Blocks.planks, 1, 4);
		world.setBlock(i + 9, j + 15, k + 4, Blocks.planks, 1, 4);
		world.setBlock(i + 9, j + 15, k + 5, Blocks.planks, 1, 4);
		world.setBlock(i + 9, j + 15, k + 6, Blocks.planks, 1, 4);
		world.setBlock(i + 9, j + 15, k + 7, Blocks.planks, 1, 4);
		world.setBlock(i + 9, j + 15, k + 11, Blocks.planks, 1, 4);
		world.setBlock(i + 9, j + 15, k + 12, Blocks.planks, 1, 4);
		world.setBlock(i + 9, j + 15, k + 13, Blocks.planks, 1, 4);
		world.setBlock(i + 9, j + 15, k + 14, Blocks.planks, 1, 4);
		world.setBlock(i + 9, j + 16, k + 1, Blocks.iron_bars);
		world.setBlock(i + 9, j + 16, k + 3, Blocks.stone);
		world.setBlock(i + 9, j + 16, k + 12, Blocks.stone);
		world.setBlock(i + 9, j + 16, k + 14, Blocks.iron_bars);
		world.setBlock(i + 9, j + 17, k + 3, Blocks.stone);
		world.setBlock(i + 9, j + 17, k + 12, Blocks.stone);
		world.setBlock(i + 9, j + 18, k + 3, Blocks.stone);
		world.setBlock(i + 9, j + 18, k + 12, Blocks.stone);
		world.setBlock(i + 9, j + 19, k + 3, Blocks.stone);
		world.setBlock(i + 9, j + 19, k + 6, Blocks.glass_pane);
		world.setBlock(i + 9, j + 19, k + 7, Blocks.glass_pane);
		world.setBlock(i + 9, j + 19, k + 8, Blocks.glass_pane);
		world.setBlock(i + 9, j + 19, k + 9, Blocks.glass_pane);
		world.setBlock(i + 9, j + 19, k + 12, Blocks.stone);
		world.setBlock(i + 9, j + 20, k + 3, Blocks.stone);
		world.setBlock(i + 9, j + 20, k + 7, Blocks.stone_slab, 8, 4);
		world.setBlock(i + 9, j + 20, k + 8, Blocks.stone_slab, 8, 4);
		world.setBlock(i + 9, j + 20, k + 12, Blocks.stone);
		world.setBlock(i + 9, j + 21, k + 2, Blocks.hardened_clay, 14, 4);
		world.setBlock(i + 9, j + 21, k + 3, Blocks.hardened_clay, 14, 4);
		world.setBlock(i + 9, j + 21, k + 12, Blocks.hardened_clay, 14, 4);
		world.setBlock(i + 9, j + 21, k + 13, Blocks.hardened_clay, 14, 4);
		world.setBlock(i + 9, j + 22, k + 3, Blocks.hardened_clay, 14, 4);
		world.setBlock(i + 9, j + 22, k + 4, Blocks.hardened_clay, 14, 4);
		world.setBlock(i + 9, j + 22, k + 5, Blocks.hardened_clay, 14, 4);
		world.setBlock(i + 9, j + 22, k + 10, Blocks.hardened_clay, 14, 4);
		world.setBlock(i + 9, j + 22, k + 11, Blocks.hardened_clay, 14, 4);
		world.setBlock(i + 9, j + 22, k + 12, Blocks.hardened_clay, 14, 4);
		world.setBlock(i + 9, j + 23, k + 5, Blocks.hardened_clay, 14, 4);
		world.setBlock(i + 9, j + 23, k + 6, Blocks.hardened_clay, 14, 4);
		world.setBlock(i + 9, j + 23, k + 7, Blocks.hardened_clay, 14, 4);
		world.setBlock(i + 9, j + 23, k + 8, Blocks.hardened_clay, 14, 4);
		world.setBlock(i + 9, j + 23, k + 9, Blocks.hardened_clay, 14, 4);
		world.setBlock(i + 9, j + 23, k + 10, Blocks.hardened_clay, 14, 4);
		world.setBlock(i + 10, j + 0, k + 1, Wildycraft.rsAsh);
		world.setBlock(i + 10, j + 0, k + 2, Wildycraft.rsAsh);
		world.setBlock(i + 10, j + 0, k + 3, Blocks.quartz_block);
		world.setBlock(i + 10, j + 0, k + 4, Blocks.planks, 1, 4);
		world.setBlock(i + 10, j + 0, k + 5, Blocks.planks, 1, 4);
		world.setBlock(i + 10, j + 0, k + 6, Blocks.planks, 1, 4);
		world.setBlock(i + 10, j + 0, k + 7, Blocks.planks, 1, 4);
		world.setBlock(i + 10, j + 0, k + 8, Blocks.planks, 1, 4);
		world.setBlock(i + 10, j + 0, k + 9, Blocks.planks, 1, 4);
		world.setBlock(i + 10, j + 0, k + 10, Blocks.planks, 1, 4);
		world.setBlock(i + 10, j + 0, k + 11, Blocks.planks, 1, 4);
		world.setBlock(i + 10, j + 0, k + 12, Blocks.quartz_block);
		world.setBlock(i + 10, j + 0, k + 13, Wildycraft.rsAsh);
		world.setBlock(i + 10, j + 0, k + 14, Wildycraft.rsAsh);
		world.setBlock(i + 10, j + 1, k + 3, Blocks.quartz_block);
		world.setBlock(i + 10, j + 1, k + 12, Blocks.quartz_block);
		world.setBlock(i + 10, j + 2, k + 3, Blocks.quartz_block);
		world.setBlock(i + 10, j + 2, k + 12, Blocks.quartz_block);
		world.setBlock(i + 10, j + 3, k + 3, Blocks.quartz_block);
		world.setBlock(i + 10, j + 3, k + 12, Blocks.quartz_block);
		world.setBlock(i + 10, j + 4, k + 3, Blocks.quartz_block);
		world.setBlock(i + 10, j + 4, k + 12, Blocks.quartz_block);
		world.setBlock(i + 10, j + 5, k + 3, Blocks.quartz_block);
		world.setBlock(i + 10, j + 5, k + 12, Blocks.quartz_block);
		world.setBlock(i + 10, j + 6, k + 3, Blocks.quartz_block);
		world.setBlock(i + 10, j + 6, k + 12, Blocks.quartz_block);
		world.setBlock(i + 10, j + 7, k + 3, Blocks.quartz_block);
		world.setBlock(i + 10, j + 7, k + 4, Blocks.planks, 1, 4);
		world.setBlock(i + 10, j + 7, k + 5, Blocks.planks, 1, 4);
		world.setBlock(i + 10, j + 7, k + 6, Blocks.planks, 1, 4);
		world.setBlock(i + 10, j + 7, k + 7, Blocks.planks, 1, 4);
		world.setBlock(i + 10, j + 7, k + 8, Blocks.planks, 1, 4);
		world.setBlock(i + 10, j + 7, k + 9, Blocks.planks, 1, 4);
		world.setBlock(i + 10, j + 7, k + 10, Blocks.planks, 1, 4);
		world.setBlock(i + 10, j + 7, k + 11, Blocks.planks, 1, 4);
		world.setBlock(i + 10, j + 7, k + 12, Blocks.quartz_block);
		world.setBlock(i + 10, j + 8, k + 3, Blocks.quartz_block);
		world.setBlock(i + 10, j + 8, k + 12, Blocks.quartz_block);
		world.setBlock(i + 10, j + 9, k + 3, Blocks.quartz_block);
		world.setBlock(i + 10, j + 9, k + 12, Blocks.quartz_block);
		world.setBlock(i + 10, j + 10, k + 3, Blocks.quartz_block);
		world.setBlock(i + 10, j + 10, k + 12, Blocks.quartz_block);
		world.setBlock(i + 10, j + 11, k + 3, Blocks.quartz_block);
		world.setBlock(i + 10, j + 11, k + 12, Blocks.quartz_block);
		world.setBlock(i + 10, j + 12, k + 3, Blocks.quartz_block);
		world.setBlock(i + 10, j + 12, k + 12, Blocks.quartz_block);
		world.setBlock(i + 10, j + 13, k + 3, Blocks.quartz_block);
		world.setBlock(i + 10, j + 13, k + 12, Blocks.quartz_block);
		world.setBlock(i + 10, j + 14, k + 3, Blocks.quartz_block);
		world.setBlock(i + 10, j + 14, k + 12, Blocks.quartz_block);
		world.setBlock(i + 10, j + 15, k + 1, Blocks.planks, 1, 4);
		world.setBlock(i + 10, j + 15, k + 2, Blocks.planks, 1, 4);
		world.setBlock(i + 10, j + 15, k + 3, Blocks.planks, 1, 4);
		world.setBlock(i + 10, j + 15, k + 4, Blocks.planks, 1, 4);
		world.setBlock(i + 10, j + 15, k + 5, Blocks.planks, 1, 4);
		world.setBlock(i + 10, j + 15, k + 6, Blocks.planks, 1, 4);
		world.setBlock(i + 10, j + 15, k + 7, Blocks.planks, 1, 4);
		world.setBlock(i + 10, j + 15, k + 8, Blocks.planks, 1, 4);
		world.setBlock(i + 10, j + 15, k + 9, Blocks.planks, 1, 4);
		world.setBlock(i + 10, j + 15, k + 10, Blocks.planks, 1, 4);
		world.setBlock(i + 10, j + 15, k + 11, Blocks.planks, 1, 4);
		world.setBlock(i + 10, j + 15, k + 12, Blocks.planks, 1, 4);
		world.setBlock(i + 10, j + 15, k + 13, Blocks.planks, 1, 4);
		world.setBlock(i + 10, j + 15, k + 14, Blocks.planks, 1, 4);
		world.setBlock(i + 10, j + 16, k + 1, Blocks.iron_bars);
		world.setBlock(i + 10, j + 16, k + 2, Blocks.iron_bars);
		world.setBlock(i + 10, j + 16, k + 3, Blocks.glass_pane);
		world.setBlock(i + 10, j + 16, k + 4, Blocks.glass_pane);
		world.setBlock(i + 10, j + 16, k + 11, Blocks.glass_pane);
		world.setBlock(i + 10, j + 16, k + 12, Blocks.glass_pane);
		world.setBlock(i + 10, j + 16, k + 13, Blocks.iron_bars);
		world.setBlock(i + 10, j + 16, k + 14, Blocks.iron_bars);
		world.setBlock(i + 10, j + 17, k + 3, Blocks.glass_pane);
		world.setBlock(i + 10, j + 17, k + 4, Blocks.glass_pane);
		world.setBlock(i + 10, j + 17, k + 11, Blocks.glass_pane);
		world.setBlock(i + 10, j + 17, k + 12, Blocks.glass_pane);
		world.setBlock(i + 10, j + 18, k + 3, Blocks.glass_pane);
		world.setBlock(i + 10, j + 18, k + 4, Blocks.glass_pane);
		world.setBlock(i + 10, j + 18, k + 11, Blocks.glass_pane);
		world.setBlock(i + 10, j + 18, k + 12, Blocks.glass_pane);
		world.setBlock(i + 10, j + 19, k + 3, Blocks.glass_pane);
		world.setBlock(i + 10, j + 19, k + 4, Blocks.glass_pane);
		world.setBlock(i + 10, j + 19, k + 11, Blocks.glass_pane);
		world.setBlock(i + 10, j + 19, k + 12, Blocks.glass_pane);
		world.setBlock(i + 10, j + 20, k + 3, Blocks.glass_pane);
		world.setBlock(i + 10, j + 20, k + 4, Blocks.glass_pane);
		world.setBlock(i + 10, j + 20, k + 7, Blocks.stone_slab, 8, 4);
		world.setBlock(i + 10, j + 20, k + 8, Blocks.stone_slab, 8, 4);
		world.setBlock(i + 10, j + 20, k + 11, Blocks.glass_pane);
		world.setBlock(i + 10, j + 20, k + 12, Blocks.glass_pane);
		world.setBlock(i + 10, j + 21, k + 3, Blocks.hardened_clay, 14, 4);
		world.setBlock(i + 10, j + 21, k + 4, Blocks.hardened_clay, 14, 4);
		world.setBlock(i + 10, j + 21, k + 11, Blocks.hardened_clay, 14, 4);
		world.setBlock(i + 10, j + 21, k + 12, Blocks.hardened_clay, 14, 4);
		world.setBlock(i + 10, j + 22, k + 4, Blocks.hardened_clay, 14, 4);
		world.setBlock(i + 10, j + 22, k + 5, Blocks.hardened_clay, 14, 4);
		world.setBlock(i + 10, j + 22, k + 6, Blocks.hardened_clay, 14, 4);
		world.setBlock(i + 10, j + 22, k + 7, Blocks.hardened_clay, 14, 4);
		world.setBlock(i + 10, j + 22, k + 8, Blocks.hardened_clay, 14, 4);
		world.setBlock(i + 10, j + 22, k + 9, Blocks.hardened_clay, 14, 4);
		world.setBlock(i + 10, j + 22, k + 10, Blocks.hardened_clay, 14, 4);
		world.setBlock(i + 10, j + 22, k + 11, Blocks.hardened_clay, 14, 4);
		world.setBlock(i + 10, j + 23, k + 6, Blocks.hardened_clay, 14, 4);
		world.setBlock(i + 10, j + 23, k + 7, Blocks.hardened_clay, 14, 4);
		world.setBlock(i + 10, j + 23, k + 8, Blocks.hardened_clay, 14, 4);
		world.setBlock(i + 10, j + 23, k + 9, Blocks.hardened_clay, 14, 4);
		world.setBlock(i + 11, j + 0, k + 1, Wildycraft.rsAsh);
		world.setBlock(i + 11, j + 0, k + 2, Wildycraft.rsAsh);
		world.setBlock(i + 11, j + 0, k + 3, Wildycraft.rsAsh);
		world.setBlock(i + 11, j + 0, k + 4, Blocks.quartz_block);
		world.setBlock(i + 11, j + 0, k + 5, Blocks.planks, 1, 4);
		world.setBlock(i + 11, j + 0, k + 6, Blocks.planks, 1, 4);
		world.setBlock(i + 11, j + 0, k + 7, Blocks.planks, 1, 4);
		world.setBlock(i + 11, j + 0, k + 8, Blocks.planks, 1, 4);
		world.setBlock(i + 11, j + 0, k + 9, Blocks.planks, 1, 4);
		world.setBlock(i + 11, j + 0, k + 10, Blocks.planks, 1, 4);
		world.setBlock(i + 11, j + 0, k + 11, Blocks.quartz_block);
		world.setBlock(i + 11, j + 0, k + 12, Wildycraft.rsAsh);
		world.setBlock(i + 11, j + 0, k + 13, Wildycraft.rsAsh);
		world.setBlock(i + 11, j + 0, k + 14, Wildycraft.rsAsh);
		world.setBlock(i + 11, j + 1, k + 4, Blocks.quartz_block);
		world.setBlock(i + 11, j + 1, k + 11, Blocks.quartz_block);
		world.setBlock(i + 11, j + 2, k + 4, Blocks.quartz_block);
		world.setBlock(i + 11, j + 2, k + 11, Blocks.quartz_block);
		world.setBlock(i + 11, j + 3, k + 4, Blocks.quartz_block);
		world.setBlock(i + 11, j + 3, k + 11, Blocks.quartz_block);
		world.setBlock(i + 11, j + 4, k + 4, Blocks.quartz_block);
		world.setBlock(i + 11, j + 4, k + 11, Blocks.quartz_block);
		world.setBlock(i + 11, j + 5, k + 4, Blocks.quartz_block);
		world.setBlock(i + 11, j + 5, k + 11, Blocks.quartz_block);
		world.setBlock(i + 11, j + 6, k + 4, Blocks.quartz_block);
		world.setBlock(i + 11, j + 6, k + 11, Blocks.quartz_block);
		world.setBlock(i + 11, j + 7, k + 4, Blocks.quartz_block);
		world.setBlock(i + 11, j + 7, k + 5, Blocks.planks, 1, 4);
		world.setBlock(i + 11, j + 7, k + 6, Blocks.planks, 1, 4);
		world.setBlock(i + 11, j + 7, k + 7, Blocks.planks, 1, 4);
		world.setBlock(i + 11, j + 7, k + 8, Blocks.planks, 1, 4);
		world.setBlock(i + 11, j + 7, k + 9, Blocks.planks, 1, 4);
		world.setBlock(i + 11, j + 7, k + 10, Blocks.planks, 1, 4);
		world.setBlock(i + 11, j + 7, k + 11, Blocks.quartz_block);
		world.setBlock(i + 11, j + 8, k + 4, Blocks.quartz_block);
		world.setBlock(i + 11, j + 8, k + 11, Blocks.quartz_block);
		world.setBlock(i + 11, j + 9, k + 4, Blocks.quartz_block);
		world.setBlock(i + 11, j + 9, k + 11, Blocks.quartz_block);
		world.setBlock(i + 11, j + 10, k + 4, Blocks.quartz_block);
		world.setBlock(i + 11, j + 10, k + 11, Blocks.quartz_block);
		world.setBlock(i + 11, j + 11, k + 4, Blocks.quartz_block);
		world.setBlock(i + 11, j + 11, k + 11, Blocks.quartz_block);
		world.setBlock(i + 11, j + 12, k + 4, Blocks.quartz_block);
		world.setBlock(i + 11, j + 12, k + 11, Blocks.quartz_block);
		world.setBlock(i + 11, j + 13, k + 4, Blocks.quartz_block);
		world.setBlock(i + 11, j + 13, k + 11, Blocks.quartz_block);
		world.setBlock(i + 11, j + 14, k + 3, Blocks.fence);
		world.setBlock(i + 11, j + 14, k + 4, Blocks.quartz_block);
		world.setBlock(i + 11, j + 14, k + 11, Blocks.quartz_block);
		world.setBlock(i + 11, j + 14, k + 12, Blocks.fence);
		world.setBlock(i + 11, j + 15, k + 2, Blocks.planks, 1, 4);
		world.setBlock(i + 11, j + 15, k + 3, Blocks.planks, 1, 4);
		world.setBlock(i + 11, j + 15, k + 4, Blocks.planks, 1, 4);
		world.setBlock(i + 11, j + 15, k + 5, Blocks.planks, 1, 4);
		world.setBlock(i + 11, j + 15, k + 6, Blocks.planks, 1, 4);
		world.setBlock(i + 11, j + 15, k + 7, Blocks.planks, 1, 4);
		world.setBlock(i + 11, j + 15, k + 8, Blocks.planks, 1, 4);
		world.setBlock(i + 11, j + 15, k + 9, Blocks.planks, 1, 4);
		world.setBlock(i + 11, j + 15, k + 10, Blocks.planks, 1, 4);
		world.setBlock(i + 11, j + 15, k + 11, Blocks.planks, 1, 4);
		world.setBlock(i + 11, j + 15, k + 12, Blocks.planks, 1, 4);
		world.setBlock(i + 11, j + 15, k + 13, Blocks.planks, 1, 4);
		world.setBlock(i + 11, j + 16, k + 2, Blocks.iron_bars);
		world.setBlock(i + 11, j + 16, k + 3, Blocks.iron_bars);
		world.setBlock(i + 11, j + 16, k + 4, Blocks.glass_pane);
		world.setBlock(i + 11, j + 16, k + 5, Blocks.glass_pane);
		world.setBlock(i + 11, j + 16, k + 10, Blocks.glass_pane);
		world.setBlock(i + 11, j + 16, k + 11, Blocks.glass_pane);
		world.setBlock(i + 11, j + 16, k + 12, Blocks.iron_bars);
		world.setBlock(i + 11, j + 16, k + 13, Blocks.iron_bars);
		world.setBlock(i + 11, j + 17, k + 4, Blocks.glass_pane);
		world.setBlock(i + 11, j + 17, k + 5, Blocks.glass_pane);
		world.setBlock(i + 11, j + 17, k + 10, Blocks.glass_pane);
		world.setBlock(i + 11, j + 17, k + 11, Blocks.glass_pane);
		world.setBlock(i + 11, j + 18, k + 4, Blocks.glass_pane);
		world.setBlock(i + 11, j + 18, k + 5, Blocks.glass_pane);
		world.setBlock(i + 11, j + 18, k + 10, Blocks.glass_pane);
		world.setBlock(i + 11, j + 18, k + 11, Blocks.glass_pane);
		world.setBlock(i + 11, j + 19, k + 4, Blocks.glass_pane);
		world.setBlock(i + 11, j + 19, k + 5, Blocks.glass_pane);
		world.setBlock(i + 11, j + 19, k + 10, Blocks.glass_pane);
		world.setBlock(i + 11, j + 19, k + 11, Blocks.glass_pane);
		world.setBlock(i + 11, j + 20, k + 4, Blocks.glass_pane);
		world.setBlock(i + 11, j + 20, k + 5, Blocks.glass_pane);
		world.setBlock(i + 11, j + 20, k + 7, Blocks.stone_slab, 8, 4);
		world.setBlock(i + 11, j + 20, k + 8, Blocks.stone_slab, 8, 4);
		world.setBlock(i + 11, j + 20, k + 10, Blocks.glass_pane);
		world.setBlock(i + 11, j + 20, k + 11, Blocks.glass_pane);
		world.setBlock(i + 11, j + 21, k + 4, Blocks.hardened_clay, 14, 4);
		world.setBlock(i + 11, j + 21, k + 5, Blocks.hardened_clay, 14, 4);
		world.setBlock(i + 11, j + 21, k + 10, Blocks.hardened_clay, 14, 4);
		world.setBlock(i + 11, j + 21, k + 11, Blocks.hardened_clay, 14, 4);
		world.setBlock(i + 11, j + 22, k + 5, Blocks.hardened_clay, 14, 4);
		world.setBlock(i + 11, j + 22, k + 6, Blocks.hardened_clay, 14, 4);
		world.setBlock(i + 11, j + 22, k + 7, Blocks.hardened_clay, 14, 4);
		world.setBlock(i + 11, j + 22, k + 8, Blocks.hardened_clay, 14, 4);
		world.setBlock(i + 11, j + 22, k + 9, Blocks.hardened_clay, 14, 4);
		world.setBlock(i + 11, j + 22, k + 10, Blocks.hardened_clay, 14, 4);
		world.setBlock(i + 12, j + 0, k + 2, Wildycraft.rsAsh);
		world.setBlock(i + 12, j + 0, k + 3, Wildycraft.rsAsh);
		world.setBlock(i + 12, j + 0, k + 4, Wildycraft.rsAsh);
		world.setBlock(i + 12, j + 0, k + 5, Blocks.quartz_block);
		world.setBlock(i + 12, j + 0, k + 6, Blocks.planks, 1, 4);
		world.setBlock(i + 12, j + 0, k + 7, Blocks.planks, 1, 4);
		world.setBlock(i + 12, j + 0, k + 8, Blocks.planks, 1, 4);
		world.setBlock(i + 12, j + 0, k + 9, Blocks.planks, 1, 4);
		world.setBlock(i + 12, j + 0, k + 10, Blocks.quartz_block);
		world.setBlock(i + 12, j + 0, k + 11, Wildycraft.rsAsh);
		world.setBlock(i + 12, j + 0, k + 12, Wildycraft.rsAsh);
		world.setBlock(i + 12, j + 0, k + 13, Wildycraft.rsAsh);
		world.setBlock(i + 12, j + 1, k + 5, Blocks.quartz_block);
		world.setBlock(i + 12, j + 1, k + 10, Blocks.quartz_block);
		world.setBlock(i + 12, j + 2, k + 5, Blocks.quartz_block);
		world.setBlock(i + 12, j + 2, k + 10, Blocks.quartz_block);
		world.setBlock(i + 12, j + 3, k + 5, Blocks.quartz_block);
		world.setBlock(i + 12, j + 3, k + 10, Blocks.quartz_block);
		world.setBlock(i + 12, j + 4, k + 5, Blocks.quartz_block);
		world.setBlock(i + 12, j + 4, k + 10, Blocks.quartz_block);
		world.setBlock(i + 12, j + 5, k + 5, Blocks.quartz_block);
		world.setBlock(i + 12, j + 5, k + 10, Blocks.quartz_block);
		world.setBlock(i + 12, j + 6, k + 5, Blocks.quartz_block);
		world.setBlock(i + 12, j + 6, k + 10, Blocks.quartz_block);
		world.setBlock(i + 12, j + 7, k + 5, Blocks.quartz_block);
		world.setBlock(i + 12, j + 7, k + 6, Blocks.planks, 1, 4);
		world.setBlock(i + 12, j + 7, k + 7, Blocks.planks, 1, 4);
		world.setBlock(i + 12, j + 7, k + 8, Blocks.planks, 1, 4);
		world.setBlock(i + 12, j + 7, k + 9, Blocks.planks, 1, 4);
		world.setBlock(i + 12, j + 7, k + 10, Blocks.quartz_block);
		world.setBlock(i + 12, j + 8, k + 5, Blocks.quartz_block);
		world.setBlock(i + 12, j + 8, k + 6, Blocks.crafting_table);
		world.setBlock(i + 12, j + 8, k + 10, Blocks.quartz_block);
		world.setBlock(i + 12, j + 9, k + 5, Blocks.quartz_block);
		world.setBlock(i + 12, j + 9, k + 6, Blocks.chest, 4, 4);
		world.setBlock(i + 12, j + 9, k + 10, Blocks.quartz_block);
		world.setBlock(i + 12, j + 10, k + 5, Blocks.quartz_block);
		world.setBlock(i + 12, j + 10, k + 10, Blocks.quartz_block);
		world.setBlock(i + 12, j + 11, k + 5, Blocks.quartz_block);
		world.setBlock(i + 12, j + 11, k + 10, Blocks.quartz_block);
		world.setBlock(i + 12, j + 12, k + 5, Blocks.quartz_block);
		world.setBlock(i + 12, j + 12, k + 10, Blocks.quartz_block);
		world.setBlock(i + 12, j + 13, k + 5, Blocks.quartz_block);
		world.setBlock(i + 12, j + 13, k + 10, Blocks.quartz_block);
		world.setBlock(i + 12, j + 14, k + 3, Blocks.fence);
		world.setBlock(i + 12, j + 14, k + 4, Blocks.fence);
		world.setBlock(i + 12, j + 14, k + 5, Blocks.quartz_block);
		world.setBlock(i + 12, j + 14, k + 10, Blocks.quartz_block);
		world.setBlock(i + 12, j + 14, k + 11, Blocks.fence);
		world.setBlock(i + 12, j + 14, k + 12, Blocks.fence);
		world.setBlock(i + 12, j + 15, k + 3, Blocks.planks, 1, 4);
		world.setBlock(i + 12, j + 15, k + 4, Blocks.planks, 1, 4);
		world.setBlock(i + 12, j + 15, k + 5, Blocks.planks, 1, 4);
		world.setBlock(i + 12, j + 15, k + 6, Blocks.planks, 1, 4);
		world.setBlock(i + 12, j + 15, k + 7, Blocks.planks, 1, 4);
		world.setBlock(i + 12, j + 15, k + 8, Blocks.planks, 1, 4);
		world.setBlock(i + 12, j + 15, k + 9, Blocks.planks, 1, 4);
		world.setBlock(i + 12, j + 15, k + 10, Blocks.planks, 1, 4);
		world.setBlock(i + 12, j + 15, k + 11, Blocks.planks, 1, 4);
		world.setBlock(i + 12, j + 15, k + 12, Blocks.planks, 1, 4);
		world.setBlock(i + 12, j + 16, k + 3, Blocks.iron_bars);
		world.setBlock(i + 12, j + 16, k + 4, Blocks.iron_bars);
		world.setBlock(i + 12, j + 16, k + 5, Blocks.glass_pane);
		world.setBlock(i + 12, j + 16, k + 6, Blocks.stone);
		world.setBlock(i + 12, j + 16, k + 9, Blocks.stone);
		world.setBlock(i + 12, j + 16, k + 10, Blocks.glass_pane);
		world.setBlock(i + 12, j + 16, k + 11, Blocks.iron_bars);
		world.setBlock(i + 12, j + 16, k + 12, Blocks.iron_bars);
		world.setBlock(i + 12, j + 17, k + 5, Blocks.glass_pane);
		world.setBlock(i + 12, j + 17, k + 6, Blocks.stone);
		world.setBlock(i + 12, j + 17, k + 9, Blocks.stone);
		world.setBlock(i + 12, j + 17, k + 10, Blocks.glass_pane);
		world.setBlock(i + 12, j + 18, k + 5, Blocks.glass_pane);
		world.setBlock(i + 12, j + 18, k + 6, Blocks.stone);
		world.setBlock(i + 12, j + 18, k + 9, Blocks.stone);
		world.setBlock(i + 12, j + 18, k + 10, Blocks.glass_pane);
		world.setBlock(i + 12, j + 19, k + 5, Blocks.glass_pane);
		world.setBlock(i + 12, j + 19, k + 6, Blocks.stone);
		world.setBlock(i + 12, j + 19, k + 9, Blocks.stone);
		world.setBlock(i + 12, j + 19, k + 10, Blocks.glass_pane);
		world.setBlock(i + 12, j + 20, k + 5, Blocks.glass_pane);
		world.setBlock(i + 12, j + 20, k + 6, Blocks.stone);
		world.setBlock(i + 12, j + 20, k + 7, Blocks.stone_slab, 8, 4);
		world.setBlock(i + 12, j + 20, k + 8, Blocks.stone_slab, 8, 4);
		world.setBlock(i + 12, j + 20, k + 9, Blocks.stone);
		world.setBlock(i + 12, j + 20, k + 10, Blocks.glass_pane);
		world.setBlock(i + 12, j + 21, k + 5, Blocks.hardened_clay, 14, 4);
		world.setBlock(i + 12, j + 21, k + 6, Blocks.hardened_clay, 14, 4);
		world.setBlock(i + 12, j + 21, k + 7, Blocks.hardened_clay, 14, 4);
		world.setBlock(i + 12, j + 21, k + 8, Blocks.hardened_clay, 14, 4);
		world.setBlock(i + 12, j + 21, k + 9, Blocks.hardened_clay, 14, 4);
		world.setBlock(i + 12, j + 21, k + 10, Blocks.hardened_clay, 14, 4);
		world.setBlock(i + 12, j + 22, k + 6, Blocks.hardened_clay, 14, 4);
		world.setBlock(i + 12, j + 22, k + 7, Blocks.hardened_clay, 14, 4);
		world.setBlock(i + 12, j + 22, k + 8, Blocks.hardened_clay, 14, 4);
		world.setBlock(i + 12, j + 22, k + 9, Blocks.hardened_clay, 14, 4);
		world.setBlock(i + 13, j + 0, k + 3, Wildycraft.rsAsh);
		world.setBlock(i + 13, j + 0, k + 4, Wildycraft.rsAsh);
		world.setBlock(i + 13, j + 0, k + 5, Wildycraft.rsAsh);
		world.setBlock(i + 13, j + 0, k + 6, Blocks.quartz_block);
		world.setBlock(i + 13, j + 0, k + 7, Blocks.planks, 1, 4);
		world.setBlock(i + 13, j + 0, k + 8, Blocks.quartz_block);
		world.setBlock(i + 13, j + 0, k + 9, Blocks.quartz_block);
		world.setBlock(i + 13, j + 0, k + 10, Wildycraft.rsAsh);
		world.setBlock(i + 13, j + 0, k + 11, Wildycraft.rsAsh);
		world.setBlock(i + 13, j + 0, k + 12, Wildycraft.rsAsh);
		world.setBlock(i + 13, j + 1, k + 6, Blocks.quartz_block);
		world.setBlock(i + 13, j + 1, k + 8, Blocks.quartz_block);
		world.setBlock(i + 13, j + 1, k + 9, Blocks.quartz_block);
		world.setBlock(i + 13, j + 2, k + 6, Blocks.quartz_block);
		world.setBlock(i + 13, j + 2, k + 8, Blocks.quartz_block);
		world.setBlock(i + 13, j + 2, k + 9, Blocks.quartz_block);
		world.setBlock(i + 13, j + 3, k + 6, Blocks.quartz_block);
		world.setBlock(i + 13, j + 3, k + 7, Blocks.quartz_block);
		world.setBlock(i + 13, j + 3, k + 8, Blocks.quartz_block);
		world.setBlock(i + 13, j + 3, k + 9, Blocks.quartz_block);
		world.setBlock(i + 13, j + 4, k + 6, Blocks.quartz_block);
		world.setBlock(i + 13, j + 4, k + 7, Blocks.quartz_block);
		world.setBlock(i + 13, j + 4, k + 8, Blocks.quartz_block);
		world.setBlock(i + 13, j + 4, k + 9, Blocks.quartz_block);
		world.setBlock(i + 13, j + 5, k + 6, Blocks.quartz_block);
		world.setBlock(i + 13, j + 5, k + 7, Blocks.quartz_block);
		world.setBlock(i + 13, j + 5, k + 8, Blocks.quartz_block);
		world.setBlock(i + 13, j + 5, k + 9, Blocks.quartz_block);
		world.setBlock(i + 13, j + 6, k + 6, Blocks.quartz_block);
		world.setBlock(i + 13, j + 6, k + 7, Blocks.quartz_block);
		world.setBlock(i + 13, j + 6, k + 8, Blocks.quartz_block);
		world.setBlock(i + 13, j + 6, k + 9, Blocks.quartz_block);
		world.setBlock(i + 13, j + 7, k + 6, Blocks.quartz_block);
		world.setBlock(i + 13, j + 7, k + 7, Blocks.quartz_block);
		world.setBlock(i + 13, j + 7, k + 8, Blocks.quartz_block);
		world.setBlock(i + 13, j + 7, k + 9, Blocks.quartz_block);
		world.setBlock(i + 13, j + 8, k + 6, Blocks.quartz_block);
		world.setBlock(i + 13, j + 8, k + 7, Blocks.quartz_block);
		world.setBlock(i + 13, j + 8, k + 8, Blocks.quartz_block);
		world.setBlock(i + 13, j + 8, k + 9, Blocks.quartz_block);
		world.setBlock(i + 13, j + 9, k + 6, Blocks.quartz_block);
		world.setBlock(i + 13, j + 9, k + 7, Blocks.quartz_block);
		world.setBlock(i + 13, j + 9, k + 8, Blocks.quartz_block);
		world.setBlock(i + 13, j + 9, k + 9, Blocks.quartz_block);
		world.setBlock(i + 13, j + 10, k + 6, Blocks.quartz_block);
		world.setBlock(i + 13, j + 10, k + 7, Blocks.quartz_block);
		world.setBlock(i + 13, j + 10, k + 8, Blocks.quartz_block);
		world.setBlock(i + 13, j + 10, k + 9, Blocks.quartz_block);
		world.setBlock(i + 13, j + 11, k + 6, Blocks.quartz_block);
		world.setBlock(i + 13, j + 11, k + 7, Blocks.quartz_block);
		world.setBlock(i + 13, j + 11, k + 8, Blocks.quartz_block);
		world.setBlock(i + 13, j + 11, k + 9, Blocks.quartz_block);
		world.setBlock(i + 13, j + 12, k + 6, Blocks.quartz_block);
		world.setBlock(i + 13, j + 12, k + 7, Blocks.quartz_block);
		world.setBlock(i + 13, j + 12, k + 8, Blocks.quartz_block);
		world.setBlock(i + 13, j + 12, k + 9, Blocks.quartz_block);
		world.setBlock(i + 13, j + 13, k + 6, Blocks.quartz_block);
		world.setBlock(i + 13, j + 13, k + 7, Blocks.quartz_block);
		world.setBlock(i + 13, j + 13, k + 8, Blocks.quartz_block);
		world.setBlock(i + 13, j + 13, k + 9, Blocks.quartz_block);
		world.setBlock(i + 13, j + 14, k + 6, Blocks.quartz_block);
		world.setBlock(i + 13, j + 14, k + 7, Blocks.quartz_block);
		world.setBlock(i + 13, j + 14, k + 8, Blocks.quartz_block);
		world.setBlock(i + 13, j + 14, k + 9, Blocks.quartz_block);
		world.setBlock(i + 13, j + 15, k + 4, Blocks.planks, 1, 4);
		world.setBlock(i + 13, j + 15, k + 5, Blocks.planks, 1, 4);
		world.setBlock(i + 13, j + 15, k + 6, Blocks.planks, 1, 4);
		world.setBlock(i + 13, j + 15, k + 7, Blocks.planks, 1, 4);
		world.setBlock(i + 13, j + 15, k + 8, Blocks.planks, 1, 4);
		world.setBlock(i + 13, j + 15, k + 9, Blocks.planks, 1, 4);
		world.setBlock(i + 13, j + 15, k + 10, Blocks.planks, 1, 4);
		world.setBlock(i + 13, j + 15, k + 11, Blocks.planks, 1, 4);
		world.setBlock(i + 13, j + 16, k + 4, Blocks.iron_bars);
		world.setBlock(i + 13, j + 16, k + 5, Blocks.iron_bars);
		world.setBlock(i + 13, j + 16, k + 10, Blocks.iron_bars);
		world.setBlock(i + 13, j + 16, k + 11, Blocks.iron_bars);
		world.setBlock(i + 13, j + 21, k + 6, Blocks.hardened_clay, 14, 4);
		world.setBlock(i + 13, j + 21, k + 7, Blocks.hardened_clay, 14, 4);
		world.setBlock(i + 13, j + 21, k + 8, Blocks.hardened_clay, 14, 4);
		world.setBlock(i + 13, j + 21, k + 9, Blocks.hardened_clay, 14, 4);
		world.setBlock(i + 14, j + 0, k + 4, Wildycraft.rsAsh);
		world.setBlock(i + 14, j + 0, k + 5, Wildycraft.rsAsh);
		world.setBlock(i + 14, j + 0, k + 6, Wildycraft.rsAsh);
		world.setBlock(i + 14, j + 0, k + 7, Wildycraft.rsAsh);
		world.setBlock(i + 14, j + 0, k + 8, Wildycraft.rsAsh);
		world.setBlock(i + 14, j + 0, k + 9, Wildycraft.rsAsh);
		world.setBlock(i + 14, j + 0, k + 10, Wildycraft.rsAsh);
		world.setBlock(i + 14, j + 0, k + 11, Wildycraft.rsAsh);
		world.setBlock(i + 14, j + 14, k + 6, Blocks.fence);
		world.setBlock(i + 14, j + 14, k + 7, Blocks.fence);
		world.setBlock(i + 14, j + 14, k + 8, Blocks.fence);
		world.setBlock(i + 14, j + 14, k + 9, Blocks.fence);
		world.setBlock(i + 14, j + 15, k + 5, Blocks.planks, 1, 4);
		world.setBlock(i + 14, j + 15, k + 6, Blocks.planks, 1, 4);
		world.setBlock(i + 14, j + 15, k + 7, Blocks.planks, 1, 4);
		world.setBlock(i + 14, j + 15, k + 8, Blocks.planks, 1, 4);
		world.setBlock(i + 14, j + 15, k + 9, Blocks.planks, 1, 4);
		world.setBlock(i + 14, j + 15, k + 10, Blocks.planks, 1, 4);
		world.setBlock(i + 14, j + 16, k + 5, Blocks.iron_bars);
		world.setBlock(i + 14, j + 16, k + 6, Blocks.iron_bars);
		world.setBlock(i + 14, j + 16, k + 7, Blocks.iron_bars);
		world.setBlock(i + 14, j + 16, k + 8, Blocks.iron_bars);
		world.setBlock(i + 14, j + 16, k + 9, Blocks.iron_bars);
		world.setBlock(i + 14, j + 16, k + 10, Blocks.iron_bars);
		world.setBlock(i + 15, j + 0, k + 6, Wildycraft.rsAsh);
		world.setBlock(i + 15, j + 0, k + 7, Wildycraft.rsAsh);
		world.setBlock(i + 15, j + 0, k + 8, Wildycraft.rsAsh);
		world.setBlock(i + 15, j + 0, k + 9, Wildycraft.rsAsh);
		world.setBlock(i + 3, j + 10, k + 9, Blocks.torch, 1, 4);
		world.setBlock(i + 4, j + 0, k + 8, Blocks.ladder, 2, 4);
		world.setBlock(i + 4, j + 1, k + 8, Blocks.ladder, 2, 4);
		world.setBlock(i + 6, j + 10, k + 3, Blocks.torch, 3, 4);
		world.setBlock(i + 13, j + 1, k + 7, Blocks.wooden_door, 6, 4);
		world.setBlock(i + 13, j + 2, k + 7, Blocks.wooden_door, 8, 4);

		EntityFremVillager c = new EntityFremVillager(world);
		c.setCurrentItemOrArmor(0, new ItemStack(Wildycraft.runesword));
        c.setProfession(0);
		c.setPosition(i + 8 + 0.5, j + 8 + 0.5, k + 5 + 0.5);
		world.spawnEntityInWorld(c);
		
		return true;
	}
}