/*
*** MADE BY MITHION'S .SCHEMATIC TO JAVA CONVERTING TOOL v1.6 ***
*/

package wildycraft.structures;
import java.util.Random;

import wildycraft.Wildycraft;

import net.minecraft.init.Blocks;
import net.minecraft.nbt.NBTTagCompound;
import net.minecraft.tileentity.TileEntityMobSpawner;
import net.minecraft.world.World;
import net.minecraft.world.gen.feature.WorldGenerator;

public class LighthouseUnderground2 extends WorldGenerator
{
	public LighthouseUnderground2() { }

	public boolean generate(World world, Random rand, int i, int j, int k) {
		world.setBlock(i + 0, j + 4, k + 17, Blocks.stone);
		world.setBlock(i + 0, j + 4, k + 18, Blocks.stone);
		world.setBlock(i + 0, j + 4, k + 19, Blocks.stone);
		world.setBlock(i + 0, j + 4, k + 20, Blocks.stone);
		world.setBlock(i + 0, j + 4, k + 21, Blocks.stone);
		world.setBlock(i + 0, j + 5, k + 17, Blocks.stone);
		world.setBlock(i + 0, j + 5, k + 18, Blocks.stone);
		world.setBlock(i + 0, j + 5, k + 19, Blocks.stone);
		world.setBlock(i + 0, j + 5, k + 20, Blocks.stone);
		world.setBlock(i + 0, j + 5, k + 21, Blocks.stone);
		world.setBlock(i + 0, j + 6, k + 17, Blocks.stone);
		world.setBlock(i + 0, j + 6, k + 18, Blocks.stone);
		world.setBlock(i + 0, j + 6, k + 19, Blocks.stone);
		world.setBlock(i + 0, j + 6, k + 20, Blocks.stone);
		world.setBlock(i + 0, j + 6, k + 21, Blocks.stone);
		world.setBlock(i + 0, j + 7, k + 17, Blocks.stone);
		world.setBlock(i + 0, j + 7, k + 18, Blocks.stone);
		world.setBlock(i + 0, j + 7, k + 19, Blocks.stone);
		world.setBlock(i + 0, j + 7, k + 20, Blocks.stone);
		world.setBlock(i + 0, j + 7, k + 21, Blocks.stone);
		world.setBlock(i + 0, j + 8, k + 17, Blocks.stone);
		world.setBlock(i + 0, j + 8, k + 18, Blocks.stone);
		world.setBlock(i + 0, j + 8, k + 19, Blocks.stone);
		world.setBlock(i + 0, j + 8, k + 20, Blocks.stone);
		world.setBlock(i + 0, j + 8, k + 21, Blocks.stone);
		world.setBlock(i + 0, j + 9, k + 17, Blocks.stone);
		world.setBlock(i + 0, j + 9, k + 18, Blocks.stone);
		world.setBlock(i + 0, j + 9, k + 19, Blocks.stone);
		world.setBlock(i + 0, j + 9, k + 20, Blocks.stone);
		world.setBlock(i + 0, j + 9, k + 21, Blocks.stone);
		world.setBlock(i + 1, j + 4, k + 16, Blocks.stone);
		world.setBlock(i + 1, j + 4, k + 17, Blocks.stone);
		world.setBlock(i + 1, j + 4, k + 18, Blocks.stone);
		world.setBlock(i + 1, j + 4, k + 19, Blocks.stone);
		world.setBlock(i + 1, j + 4, k + 20, Blocks.stone);
		world.setBlock(i + 1, j + 4, k + 21, Blocks.stone);
		world.setBlock(i + 1, j + 4, k + 22, Blocks.stone);
		world.setBlock(i + 1, j + 4, k + 23, Blocks.stone);
		world.setBlock(i + 1, j + 5, k + 16, Blocks.stone);
		world.setBlock(i + 1, j + 5, k + 17, Blocks.stone);
		world.setBlock(i + 1, j + 5, k + 18, Blocks.stone);
		world.setBlock(i + 1, j + 5, k + 19, Blocks.stone);
		world.setBlock(i + 1, j + 5, k + 20, Blocks.stone);
		world.setBlock(i + 1, j + 5, k + 21, Blocks.stone);
		world.setBlock(i + 1, j + 5, k + 22, Blocks.stone);
		world.setBlock(i + 1, j + 5, k + 23, Blocks.stone);
		world.setBlock(i + 1, j + 6, k + 16, Blocks.stone);
		world.setBlock(i + 1, j + 6, k + 17, Blocks.air);
		world.setBlock(i + 1, j + 6, k + 18, Blocks.air);
		world.setBlock(i + 1, j + 6, k + 19, Blocks.air);
		world.setBlock(i + 1, j + 6, k + 20, Blocks.air);
		world.setBlock(i + 1, j + 6, k + 21, Blocks.air);
		world.setBlock(i + 1, j + 6, k + 22, Blocks.stone);
		world.setBlock(i + 1, j + 6, k + 23, Blocks.stone);
		world.setBlock(i + 1, j + 7, k + 16, Blocks.stone);
		world.setBlock(i + 1, j + 7, k + 17, Blocks.air);
		world.setBlock(i + 1, j + 7, k + 18, Blocks.air);
		world.setBlock(i + 1, j + 7, k + 19, Blocks.air);
		world.setBlock(i + 1, j + 7, k + 20, Blocks.air);
		world.setBlock(i + 1, j + 7, k + 21, Blocks.air);
		world.setBlock(i + 1, j + 7, k + 22, Blocks.stone);
		world.setBlock(i + 1, j + 7, k + 23, Blocks.stone);
		world.setBlock(i + 1, j + 8, k + 16, Blocks.stone);
		world.setBlock(i + 1, j + 8, k + 17, Blocks.air);
		world.setBlock(i + 1, j + 8, k + 18, Blocks.air);
		world.setBlock(i + 1, j + 8, k + 19, Blocks.air);
		world.setBlock(i + 1, j + 8, k + 20, Blocks.air);
		world.setBlock(i + 1, j + 8, k + 21, Blocks.air);
		world.setBlock(i + 1, j + 8, k + 22, Blocks.stone);
		world.setBlock(i + 1, j + 8, k + 23, Blocks.stone);
		world.setBlock(i + 1, j + 9, k + 16, Blocks.stone);
		world.setBlock(i + 1, j + 9, k + 17, Blocks.stone);
		world.setBlock(i + 1, j + 9, k + 18, Blocks.stone);
		world.setBlock(i + 1, j + 9, k + 19, Blocks.stone);
		world.setBlock(i + 1, j + 9, k + 20, Blocks.stone);
		world.setBlock(i + 1, j + 9, k + 21, Blocks.stone);
		world.setBlock(i + 1, j + 9, k + 22, Blocks.stone);
		world.setBlock(i + 1, j + 9, k + 23, Blocks.stone);
		world.setBlock(i + 1, j + 10, k + 17, Blocks.stone);
		world.setBlock(i + 1, j + 10, k + 18, Blocks.stone);
		world.setBlock(i + 1, j + 10, k + 19, Blocks.stone);
		world.setBlock(i + 1, j + 10, k + 20, Blocks.stone);
		world.setBlock(i + 1, j + 10, k + 21, Blocks.stone);
		world.setBlock(i + 2, j + 4, k + 14, Blocks.stone);
		world.setBlock(i + 2, j + 4, k + 15, Blocks.stone);
		world.setBlock(i + 2, j + 4, k + 16, Blocks.stone);
		world.setBlock(i + 2, j + 4, k + 17, Blocks.stone);
		world.setBlock(i + 2, j + 4, k + 18, Blocks.stone);
		world.setBlock(i + 2, j + 4, k + 19, Blocks.stone);
		world.setBlock(i + 2, j + 4, k + 20, Blocks.stone);
		world.setBlock(i + 2, j + 4, k + 21, Blocks.stone);
		world.setBlock(i + 2, j + 4, k + 22, Blocks.stone);
		world.setBlock(i + 2, j + 4, k + 23, Blocks.stone);
		world.setBlock(i + 2, j + 4, k + 24, Blocks.stone);
		world.setBlock(i + 2, j + 5, k + 14, Blocks.stone);
		world.setBlock(i + 2, j + 5, k + 15, Blocks.stone);
		world.setBlock(i + 2, j + 5, k + 16, Blocks.stone);
		world.setBlock(i + 2, j + 5, k + 17, Blocks.stone);
		world.setBlock(i + 2, j + 5, k + 18, Blocks.stone);
		world.setBlock(i + 2, j + 5, k + 19, Blocks.stone);
		world.setBlock(i + 2, j + 5, k + 20, Blocks.stone);
		world.setBlock(i + 2, j + 5, k + 21, Blocks.stone);
		world.setBlock(i + 2, j + 5, k + 22, Blocks.stone);
		world.setBlock(i + 2, j + 5, k + 23, Blocks.stone);
		world.setBlock(i + 2, j + 5, k + 24, Blocks.stone);
		world.setBlock(i + 2, j + 6, k + 14, Blocks.stone);
		world.setBlock(i + 2, j + 6, k + 15, Blocks.stone);
		world.setBlock(i + 2, j + 6, k + 16, Blocks.air);
		world.setBlock(i + 2, j + 6, k + 17, Blocks.air);
		world.setBlock(i + 2, j + 6, k + 18, Blocks.air);
		world.setBlock(i + 2, j + 6, k + 19, Blocks.air);
		world.setBlock(i + 2, j + 6, k + 20, Blocks.air);
		world.setBlock(i + 2, j + 6, k + 21, Blocks.air);
		world.setBlock(i + 2, j + 6, k + 22, Blocks.air);
		world.setBlock(i + 2, j + 6, k + 23, Blocks.air);
		world.setBlock(i + 2, j + 6, k + 24, Blocks.stone);
		world.setBlock(i + 2, j + 7, k + 14, Blocks.stone);
		world.setBlock(i + 2, j + 7, k + 15, Blocks.stone);
		world.setBlock(i + 2, j + 7, k + 16, Blocks.air);
		world.setBlock(i + 2, j + 7, k + 17, Blocks.air);
		world.setBlock(i + 2, j + 7, k + 18, Blocks.air);
		world.setBlock(i + 2, j + 7, k + 19, Blocks.air);
		world.setBlock(i + 2, j + 7, k + 20, Blocks.air);
		world.setBlock(i + 2, j + 7, k + 21, Blocks.air);
		world.setBlock(i + 2, j + 7, k + 22, Blocks.air);
		world.setBlock(i + 2, j + 7, k + 23, Blocks.air);
		world.setBlock(i + 2, j + 7, k + 24, Blocks.stone);
		world.setBlock(i + 2, j + 8, k + 14, Blocks.stone);
		world.setBlock(i + 2, j + 8, k + 15, Blocks.stone);
		world.setBlock(i + 2, j + 8, k + 16, Blocks.air);
		world.setBlock(i + 2, j + 8, k + 17, Blocks.air);
		world.setBlock(i + 2, j + 8, k + 18, Blocks.air);
		world.setBlock(i + 2, j + 8, k + 19, Blocks.air);
		world.setBlock(i + 2, j + 8, k + 20, Blocks.air);
		world.setBlock(i + 2, j + 8, k + 21, Blocks.air);
		world.setBlock(i + 2, j + 8, k + 22, Blocks.air);
		world.setBlock(i + 2, j + 8, k + 23, Blocks.air);
		world.setBlock(i + 2, j + 8, k + 24, Blocks.stone);
		world.setBlock(i + 2, j + 9, k + 14, Blocks.stone);
		world.setBlock(i + 2, j + 9, k + 15, Blocks.stone);
		world.setBlock(i + 2, j + 9, k + 16, Blocks.stone);
		world.setBlock(i + 2, j + 9, k + 17, Blocks.air);
		world.setBlock(i + 2, j + 9, k + 18, Blocks.air);
		world.setBlock(i + 2, j + 9, k + 19, Blocks.air);
		world.setBlock(i + 2, j + 9, k + 20, Blocks.air);
		world.setBlock(i + 2, j + 9, k + 21, Blocks.air);
		world.setBlock(i + 2, j + 9, k + 22, Blocks.stone);
		world.setBlock(i + 2, j + 9, k + 23, Blocks.stone);
		world.setBlock(i + 2, j + 9, k + 24, Blocks.stone);
		world.setBlock(i + 2, j + 10, k + 16, Blocks.stone);
		world.setBlock(i + 2, j + 10, k + 17, Blocks.stone);
		world.setBlock(i + 2, j + 10, k + 18, Blocks.stone);
		world.setBlock(i + 2, j + 10, k + 19, Blocks.stone);
		world.setBlock(i + 2, j + 10, k + 20, Blocks.stone);
		world.setBlock(i + 2, j + 10, k + 21, Blocks.stone);
		world.setBlock(i + 2, j + 10, k + 22, Blocks.stone);
		world.setBlock(i + 2, j + 10, k + 23, Blocks.stone);
		world.setBlock(i + 3, j + 4, k + 13, Blocks.stone);
		world.setBlock(i + 3, j + 4, k + 14, Blocks.stone);
		world.setBlock(i + 3, j + 4, k + 15, Blocks.stone);
		world.setBlock(i + 3, j + 4, k + 16, Blocks.stone);
		world.setBlock(i + 3, j + 4, k + 17, Blocks.stone);
		world.setBlock(i + 3, j + 4, k + 18, Blocks.stone);
		world.setBlock(i + 3, j + 4, k + 19, Blocks.stone);
		world.setBlock(i + 3, j + 4, k + 20, Blocks.stone);
		world.setBlock(i + 3, j + 4, k + 21, Blocks.stone);
		world.setBlock(i + 3, j + 4, k + 22, Blocks.stone);
		world.setBlock(i + 3, j + 4, k + 23, Blocks.stone);
		world.setBlock(i + 3, j + 4, k + 24, Blocks.stone);
		world.setBlock(i + 3, j + 4, k + 25, Blocks.stone);
		world.setBlock(i + 3, j + 5, k + 13, Blocks.stone);
		world.setBlock(i + 3, j + 5, k + 14, Blocks.stone);
		world.setBlock(i + 3, j + 5, k + 15, Blocks.stone);
		world.setBlock(i + 3, j + 5, k + 16, Blocks.stone);
		world.setBlock(i + 3, j + 5, k + 17, Blocks.stone);
		world.setBlock(i + 3, j + 5, k + 18, Blocks.stone);
		world.setBlock(i + 3, j + 5, k + 19, Blocks.stone);
		world.setBlock(i + 3, j + 5, k + 20, Blocks.stone);
		world.setBlock(i + 3, j + 5, k + 21, Blocks.stone);
		world.setBlock(i + 3, j + 5, k + 22, Blocks.stone);
		world.setBlock(i + 3, j + 5, k + 23, Blocks.stone);
		world.setBlock(i + 3, j + 5, k + 24, Blocks.stone);
		world.setBlock(i + 3, j + 5, k + 25, Blocks.stone);
		world.setBlock(i + 3, j + 6, k + 13, Blocks.stone);
		world.setBlock(i + 3, j + 6, k + 14, Blocks.air);
		world.setBlock(i + 3, j + 6, k + 15, Blocks.air);
		world.setBlock(i + 3, j + 6, k + 16, Blocks.air);
		world.setBlock(i + 3, j + 6, k + 17, Blocks.air);
		world.setBlock(i + 3, j + 6, k + 18, Blocks.air);
		world.setBlock(i + 3, j + 6, k + 19, Blocks.air);
		world.setBlock(i + 3, j + 6, k + 20, Blocks.air);
		world.setBlock(i + 3, j + 6, k + 21, Blocks.air);
		world.setBlock(i + 3, j + 6, k + 22, Blocks.air);
		world.setBlock(i + 3, j + 6, k + 23, Blocks.air);
		world.setBlock(i + 3, j + 6, k + 24, Blocks.air);
		world.setBlock(i + 3, j + 6, k + 25, Blocks.stone);
		world.setBlock(i + 3, j + 7, k + 13, Blocks.stone);
		world.setBlock(i + 3, j + 7, k + 14, Blocks.air);
		world.setBlock(i + 3, j + 7, k + 15, Blocks.air);
		world.setBlock(i + 3, j + 7, k + 16, Blocks.air);
		world.setBlock(i + 3, j + 7, k + 17, Blocks.air);
		world.setBlock(i + 3, j + 7, k + 18, Blocks.air);
		world.setBlock(i + 3, j + 7, k + 19, Blocks.air);
		world.setBlock(i + 3, j + 7, k + 20, Blocks.air);
		world.setBlock(i + 3, j + 7, k + 21, Blocks.air);
		world.setBlock(i + 3, j + 7, k + 22, Blocks.air);
		world.setBlock(i + 3, j + 7, k + 23, Blocks.air);
		world.setBlock(i + 3, j + 7, k + 24, Blocks.air);
		world.setBlock(i + 3, j + 7, k + 25, Blocks.stone);
		world.setBlock(i + 3, j + 8, k + 13, Blocks.stone);
		world.setBlock(i + 3, j + 8, k + 14, Blocks.air);
		world.setBlock(i + 3, j + 8, k + 15, Blocks.air);
		world.setBlock(i + 3, j + 8, k + 16, Blocks.air);
		world.setBlock(i + 3, j + 8, k + 17, Blocks.air);
		world.setBlock(i + 3, j + 8, k + 18, Blocks.air);
		world.setBlock(i + 3, j + 8, k + 19, Blocks.air);
		world.setBlock(i + 3, j + 8, k + 20, Blocks.air);
		world.setBlock(i + 3, j + 8, k + 21, Blocks.air);
		world.setBlock(i + 3, j + 8, k + 22, Blocks.air);
		world.setBlock(i + 3, j + 8, k + 23, Blocks.air);
		world.setBlock(i + 3, j + 8, k + 24, Blocks.air);
		world.setBlock(i + 3, j + 8, k + 25, Blocks.stone);
		world.setBlock(i + 3, j + 9, k + 13, Blocks.stone);
		world.setBlock(i + 3, j + 9, k + 14, Blocks.stone);
		world.setBlock(i + 3, j + 9, k + 15, Blocks.stone);
		world.setBlock(i + 3, j + 9, k + 16, Blocks.air);
		world.setBlock(i + 3, j + 9, k + 17, Blocks.air);
		world.setBlock(i + 3, j + 9, k + 18, Blocks.air);
		world.setBlock(i + 3, j + 9, k + 19, Blocks.air);
		world.setBlock(i + 3, j + 9, k + 20, Blocks.air);
		world.setBlock(i + 3, j + 9, k + 21, Blocks.air);
		world.setBlock(i + 3, j + 9, k + 22, Blocks.air);
		world.setBlock(i + 3, j + 9, k + 23, Blocks.air);
		world.setBlock(i + 3, j + 9, k + 24, Blocks.stone);
		world.setBlock(i + 3, j + 9, k + 25, Blocks.stone);
		world.setBlock(i + 3, j + 10, k + 14, Blocks.stone);
		world.setBlock(i + 3, j + 10, k + 15, Blocks.stone);
		world.setBlock(i + 3, j + 10, k + 16, Blocks.stone);
		world.setBlock(i + 3, j + 10, k + 17, Blocks.stone);
		world.setBlock(i + 3, j + 10, k + 18, Blocks.stone);
		world.setBlock(i + 3, j + 10, k + 19, Blocks.stone);
		world.setBlock(i + 3, j + 10, k + 20, Blocks.stone);
		world.setBlock(i + 3, j + 10, k + 21, Blocks.stone);
		world.setBlock(i + 3, j + 10, k + 22, Blocks.stone);
		world.setBlock(i + 3, j + 10, k + 23, Blocks.stone);
		world.setBlock(i + 3, j + 10, k + 24, Blocks.stone);
		world.setBlock(i + 3, j + 11, k + 17, Blocks.stone);
		world.setBlock(i + 3, j + 11, k + 18, Blocks.stone);
		world.setBlock(i + 3, j + 11, k + 19, Blocks.stone);
		world.setBlock(i + 3, j + 11, k + 20, Blocks.stone);
		world.setBlock(i + 4, j + 4, k + 12, Blocks.stone);
		world.setBlock(i + 4, j + 4, k + 13, Blocks.stone);
		world.setBlock(i + 4, j + 4, k + 14, Blocks.stone);
		world.setBlock(i + 4, j + 4, k + 15, Blocks.stone);
		world.setBlock(i + 4, j + 4, k + 16, Blocks.stone);
		world.setBlock(i + 4, j + 4, k + 17, Blocks.stone);
		world.setBlock(i + 4, j + 4, k + 18, Blocks.stone);
		world.setBlock(i + 4, j + 4, k + 19, Blocks.stone);
		world.setBlock(i + 4, j + 4, k + 20, Blocks.stone);
		world.setBlock(i + 4, j + 4, k + 21, Blocks.stone);
		world.setBlock(i + 4, j + 4, k + 22, Blocks.stone);
		world.setBlock(i + 4, j + 4, k + 23, Blocks.stone);
		world.setBlock(i + 4, j + 4, k + 24, Blocks.stone);
		world.setBlock(i + 4, j + 4, k + 25, Blocks.stone);
		world.setBlock(i + 4, j + 4, k + 26, Blocks.stone);
		world.setBlock(i + 4, j + 5, k + 12, Blocks.stone);
		world.setBlock(i + 4, j + 5, k + 13, Blocks.stone);
		world.setBlock(i + 4, j + 5, k + 14, Blocks.stone);
		world.setBlock(i + 4, j + 5, k + 15, Blocks.stone);
		world.setBlock(i + 4, j + 5, k + 16, Blocks.stone);
		world.setBlock(i + 4, j + 5, k + 17, Blocks.stone);
		world.setBlock(i + 4, j + 5, k + 18, Blocks.stone);
		world.setBlock(i + 4, j + 5, k + 19, Blocks.stone);
		world.setBlock(i + 4, j + 5, k + 20, Blocks.stone);
		world.setBlock(i + 4, j + 5, k + 21, Blocks.stone);
		world.setBlock(i + 4, j + 5, k + 22, Blocks.stone);
		world.setBlock(i + 4, j + 5, k + 23, Blocks.stone);
		world.setBlock(i + 4, j + 5, k + 24, Blocks.stone);
		world.setBlock(i + 4, j + 5, k + 25, Blocks.stone);
		world.setBlock(i + 4, j + 5, k + 26, Blocks.stone);
		world.setBlock(i + 4, j + 6, k + 12, Blocks.stone);
		world.setBlock(i + 4, j + 6, k + 13, Blocks.air);
		world.setBlock(i + 4, j + 6, k + 14, Blocks.air);
		world.setBlock(i + 4, j + 6, k + 15, Blocks.air);
		world.setBlock(i + 4, j + 6, k + 16, Blocks.air);
		world.setBlock(i + 4, j + 6, k + 17, Blocks.air);
		world.setBlock(i + 4, j + 6, k + 18, Blocks.air);
		world.setBlock(i + 4, j + 6, k + 19, Blocks.air);
		world.setBlock(i + 4, j + 6, k + 20, Blocks.air);
		world.setBlock(i + 4, j + 6, k + 21, Blocks.air);
		world.setBlock(i + 4, j + 6, k + 22, Blocks.air);
		world.setBlock(i + 4, j + 6, k + 23, Blocks.air);
		world.setBlock(i + 4, j + 6, k + 24, Blocks.air);
		world.setBlock(i + 4, j + 6, k + 25, Blocks.air);
		world.setBlock(i + 4, j + 6, k + 26, Blocks.stone);
		world.setBlock(i + 4, j + 7, k + 12, Blocks.stone);
		world.setBlock(i + 4, j + 7, k + 13, Blocks.air);
		world.setBlock(i + 4, j + 7, k + 14, Blocks.air);
		world.setBlock(i + 4, j + 7, k + 15, Blocks.air);
		world.setBlock(i + 4, j + 7, k + 16, Blocks.air);
		world.setBlock(i + 4, j + 7, k + 17, Blocks.air);
		world.setBlock(i + 4, j + 7, k + 18, Blocks.air);
		world.setBlock(i + 4, j + 7, k + 19, Blocks.air);
		world.setBlock(i + 4, j + 7, k + 20, Blocks.air);
		world.setBlock(i + 4, j + 7, k + 21, Blocks.air);
		world.setBlock(i + 4, j + 7, k + 22, Blocks.air);
		world.setBlock(i + 4, j + 7, k + 23, Blocks.air);
		world.setBlock(i + 4, j + 7, k + 24, Blocks.air);
		world.setBlock(i + 4, j + 7, k + 25, Blocks.air);
		world.setBlock(i + 4, j + 7, k + 26, Blocks.stone);
		world.setBlock(i + 4, j + 8, k + 12, Blocks.stone);
		world.setBlock(i + 4, j + 8, k + 13, Blocks.air);
		world.setBlock(i + 4, j + 8, k + 14, Blocks.air);
		world.setBlock(i + 4, j + 8, k + 15, Blocks.air);
		world.setBlock(i + 4, j + 8, k + 16, Blocks.air);
		world.setBlock(i + 4, j + 8, k + 17, Blocks.air);
		world.setBlock(i + 4, j + 8, k + 18, Blocks.air);
		world.setBlock(i + 4, j + 8, k + 19, Blocks.air);
		world.setBlock(i + 4, j + 8, k + 20, Blocks.air);
		world.setBlock(i + 4, j + 8, k + 21, Blocks.air);
		world.setBlock(i + 4, j + 8, k + 22, Blocks.air);
		world.setBlock(i + 4, j + 8, k + 23, Blocks.air);
		world.setBlock(i + 4, j + 8, k + 24, Blocks.air);
		world.setBlock(i + 4, j + 8, k + 25, Blocks.air);
		world.setBlock(i + 4, j + 8, k + 26, Blocks.stone);
		world.setBlock(i + 4, j + 9, k + 12, Blocks.stone);
		world.setBlock(i + 4, j + 9, k + 13, Blocks.stone);
		world.setBlock(i + 4, j + 9, k + 14, Blocks.air);
		world.setBlock(i + 4, j + 9, k + 15, Blocks.air);
		world.setBlock(i + 4, j + 9, k + 16, Blocks.air);
		world.setBlock(i + 4, j + 9, k + 17, Blocks.air);
		world.setBlock(i + 4, j + 9, k + 18, Blocks.air);
		world.setBlock(i + 4, j + 9, k + 19, Blocks.air);
		world.setBlock(i + 4, j + 9, k + 20, Blocks.air);
		world.setBlock(i + 4, j + 9, k + 21, Blocks.air);
		world.setBlock(i + 4, j + 9, k + 22, Blocks.air);
		world.setBlock(i + 4, j + 9, k + 23, Blocks.air);
		world.setBlock(i + 4, j + 9, k + 24, Blocks.air);
		world.setBlock(i + 4, j + 9, k + 25, Blocks.stone);
		world.setBlock(i + 4, j + 9, k + 26, Blocks.stone);
		world.setBlock(i + 4, j + 10, k + 13, Blocks.stone);
		world.setBlock(i + 4, j + 10, k + 14, Blocks.stone);
		world.setBlock(i + 4, j + 10, k + 15, Blocks.stone);
		world.setBlock(i + 4, j + 10, k + 16, Blocks.stone);
		world.setBlock(i + 4, j + 10, k + 17, Blocks.stone);
		world.setBlock(i + 4, j + 10, k + 18, Blocks.air);
		world.setBlock(i + 4, j + 10, k + 19, Blocks.air);
		world.setBlock(i + 4, j + 10, k + 20, Blocks.air);
		world.setBlock(i + 4, j + 10, k + 21, Blocks.stone);
		world.setBlock(i + 4, j + 10, k + 22, Blocks.stone);
		world.setBlock(i + 4, j + 10, k + 23, Blocks.stone);
		world.setBlock(i + 4, j + 10, k + 24, Blocks.stone);
		world.setBlock(i + 4, j + 10, k + 25, Blocks.stone);
		world.setBlock(i + 4, j + 11, k + 16, Blocks.stone);
		world.setBlock(i + 4, j + 11, k + 17, Blocks.stone);
		world.setBlock(i + 4, j + 11, k + 18, Blocks.stone);
		world.setBlock(i + 4, j + 11, k + 19, Blocks.stone);
		world.setBlock(i + 4, j + 11, k + 20, Blocks.stone);
		world.setBlock(i + 4, j + 11, k + 21, Blocks.stone);
		world.setBlock(i + 4, j + 11, k + 22, Blocks.stone);
		world.setBlock(i + 5, j + 4, k + 11, Blocks.stone);
		world.setBlock(i + 5, j + 4, k + 12, Blocks.stone);
		world.setBlock(i + 5, j + 4, k + 13, Blocks.stone);
		world.setBlock(i + 5, j + 4, k + 14, Blocks.stone);
		world.setBlock(i + 5, j + 4, k + 15, Blocks.stone);
		world.setBlock(i + 5, j + 4, k + 16, Blocks.stone);
		world.setBlock(i + 5, j + 4, k + 17, Blocks.stone);
		world.setBlock(i + 5, j + 4, k + 18, Blocks.stone);
		world.setBlock(i + 5, j + 4, k + 19, Blocks.stone);
		world.setBlock(i + 5, j + 4, k + 20, Blocks.stone);
		world.setBlock(i + 5, j + 4, k + 21, Blocks.stone);
		world.setBlock(i + 5, j + 4, k + 22, Blocks.stone);
		world.setBlock(i + 5, j + 4, k + 23, Blocks.stone);
		world.setBlock(i + 5, j + 4, k + 24, Blocks.stone);
		world.setBlock(i + 5, j + 4, k + 25, Blocks.stone);
		world.setBlock(i + 5, j + 4, k + 26, Blocks.stone);
		world.setBlock(i + 5, j + 4, k + 27, Blocks.stone);
		world.setBlock(i + 5, j + 5, k + 11, Blocks.stone);
		world.setBlock(i + 5, j + 5, k + 12, Blocks.stone);
		world.setBlock(i + 5, j + 5, k + 13, Blocks.stone);
		world.setBlock(i + 5, j + 5, k + 14, Blocks.stone);
		world.setBlock(i + 5, j + 5, k + 15, Blocks.stone);
		world.setBlock(i + 5, j + 5, k + 16, Blocks.stone);
		world.setBlock(i + 5, j + 5, k + 17, Blocks.stone);
		world.setBlock(i + 5, j + 5, k + 18, Blocks.stone);
		world.setBlock(i + 5, j + 5, k + 19, Blocks.stone);
		world.setBlock(i + 5, j + 5, k + 20, Blocks.stone);
		world.setBlock(i + 5, j + 5, k + 21, Blocks.stone);
		world.setBlock(i + 5, j + 5, k + 22, Blocks.stone);
		world.setBlock(i + 5, j + 5, k + 23, Blocks.stone);
		world.setBlock(i + 5, j + 5, k + 24, Blocks.stone);
		world.setBlock(i + 5, j + 5, k + 25, Blocks.stone);
		world.setBlock(i + 5, j + 5, k + 26, Blocks.stone);
		world.setBlock(i + 5, j + 5, k + 27, Blocks.stone);
		world.setBlock(i + 5, j + 6, k + 11, Blocks.stone);
		world.setBlock(i + 5, j + 6, k + 12, Blocks.air);
		world.setBlock(i + 5, j + 6, k + 13, Blocks.air);
		world.setBlock(i + 5, j + 6, k + 14, Blocks.air);
		world.setBlock(i + 5, j + 6, k + 15, Blocks.air);
		world.setBlock(i + 5, j + 6, k + 16, Blocks.air);
		world.setBlock(i + 5, j + 6, k + 17, Blocks.air);
		world.setBlock(i + 5, j + 6, k + 18, Blocks.air);
		world.setBlock(i + 5, j + 6, k + 19, Blocks.air);
		world.setBlock(i + 5, j + 6, k + 20, Blocks.air);
		world.setBlock(i + 5, j + 6, k + 21, Blocks.air);
		world.setBlock(i + 5, j + 6, k + 22, Blocks.air);
		world.setBlock(i + 5, j + 6, k + 23, Blocks.air);
		world.setBlock(i + 5, j + 6, k + 24, Blocks.air);
		world.setBlock(i + 5, j + 6, k + 25, Blocks.air);
		world.setBlock(i + 5, j + 6, k + 26, Blocks.air);
		world.setBlock(i + 5, j + 6, k + 27, Blocks.stone);
		world.setBlock(i + 5, j + 7, k + 11, Blocks.stone);
		world.setBlock(i + 5, j + 7, k + 12, Blocks.air);
		world.setBlock(i + 5, j + 7, k + 13, Blocks.air);
		world.setBlock(i + 5, j + 7, k + 14, Blocks.air);
		world.setBlock(i + 5, j + 7, k + 15, Blocks.air);
		world.setBlock(i + 5, j + 7, k + 16, Blocks.air);
		world.setBlock(i + 5, j + 7, k + 17, Blocks.air);
		world.setBlock(i + 5, j + 7, k + 18, Blocks.air);
		world.setBlock(i + 5, j + 7, k + 19, Blocks.air);
		world.setBlock(i + 5, j + 7, k + 20, Blocks.air);
		world.setBlock(i + 5, j + 7, k + 21, Blocks.air);
		world.setBlock(i + 5, j + 7, k + 22, Blocks.air);
		world.setBlock(i + 5, j + 7, k + 23, Blocks.air);
		world.setBlock(i + 5, j + 7, k + 24, Blocks.air);
		world.setBlock(i + 5, j + 7, k + 25, Blocks.air);
		world.setBlock(i + 5, j + 7, k + 26, Blocks.air);
		world.setBlock(i + 5, j + 7, k + 27, Blocks.stone);
		world.setBlock(i + 5, j + 8, k + 11, Blocks.stone);
		world.setBlock(i + 5, j + 8, k + 12, Blocks.air);
		world.setBlock(i + 5, j + 8, k + 13, Blocks.air);
		world.setBlock(i + 5, j + 8, k + 14, Blocks.air);
		world.setBlock(i + 5, j + 8, k + 15, Blocks.air);
		world.setBlock(i + 5, j + 8, k + 16, Blocks.air);
		world.setBlock(i + 5, j + 8, k + 17, Blocks.air);
		world.setBlock(i + 5, j + 8, k + 18, Blocks.air);
		world.setBlock(i + 5, j + 8, k + 19, Blocks.air);
		world.setBlock(i + 5, j + 8, k + 20, Blocks.air);
		world.setBlock(i + 5, j + 8, k + 21, Blocks.air);
		world.setBlock(i + 5, j + 8, k + 22, Blocks.air);
		world.setBlock(i + 5, j + 8, k + 23, Blocks.air);
		world.setBlock(i + 5, j + 8, k + 24, Blocks.air);
		world.setBlock(i + 5, j + 8, k + 25, Blocks.air);
		world.setBlock(i + 5, j + 8, k + 26, Blocks.air);
		world.setBlock(i + 5, j + 8, k + 27, Blocks.stone);
		world.setBlock(i + 5, j + 9, k + 11, Blocks.stone);
		world.setBlock(i + 5, j + 9, k + 12, Blocks.stone);
		world.setBlock(i + 5, j + 9, k + 13, Blocks.air);
		world.setBlock(i + 5, j + 9, k + 14, Blocks.air);
		world.setBlock(i + 5, j + 9, k + 15, Blocks.air);
		world.setBlock(i + 5, j + 9, k + 16, Blocks.air);
		world.setBlock(i + 5, j + 9, k + 17, Blocks.air);
		world.setBlock(i + 5, j + 9, k + 18, Blocks.air);
		world.setBlock(i + 5, j + 9, k + 19, Blocks.air);
		world.setBlock(i + 5, j + 9, k + 20, Blocks.air);
		world.setBlock(i + 5, j + 9, k + 21, Blocks.air);
		world.setBlock(i + 5, j + 9, k + 22, Blocks.air);
		world.setBlock(i + 5, j + 9, k + 23, Blocks.air);
		world.setBlock(i + 5, j + 9, k + 24, Blocks.air);
		world.setBlock(i + 5, j + 9, k + 25, Blocks.air);
		world.setBlock(i + 5, j + 9, k + 26, Blocks.stone);
		world.setBlock(i + 5, j + 9, k + 27, Blocks.stone);
		world.setBlock(i + 5, j + 10, k + 12, Blocks.stone);
		world.setBlock(i + 5, j + 10, k + 13, Blocks.stone);
		world.setBlock(i + 5, j + 10, k + 14, Blocks.stone);
		world.setBlock(i + 5, j + 10, k + 15, Blocks.stone);
		world.setBlock(i + 5, j + 10, k + 16, Blocks.air);
		world.setBlock(i + 5, j + 10, k + 17, Blocks.air);
		world.setBlock(i + 5, j + 10, k + 18, Blocks.air);
		world.setBlock(i + 5, j + 10, k + 19, Blocks.air);
		world.setBlock(i + 5, j + 10, k + 20, Blocks.air);
		world.setBlock(i + 5, j + 10, k + 21, Blocks.air);
		world.setBlock(i + 5, j + 10, k + 22, Blocks.air);
		world.setBlock(i + 5, j + 10, k + 23, Blocks.stone);
		world.setBlock(i + 5, j + 10, k + 24, Blocks.stone);
		world.setBlock(i + 5, j + 10, k + 25, Blocks.stone);
		world.setBlock(i + 5, j + 10, k + 26, Blocks.stone);
		world.setBlock(i + 5, j + 11, k + 15, Blocks.stone);
		world.setBlock(i + 5, j + 11, k + 16, Blocks.stone);
		world.setBlock(i + 5, j + 11, k + 17, Blocks.stone);
		world.setBlock(i + 5, j + 11, k + 18, Blocks.stone);
		world.setBlock(i + 5, j + 11, k + 19, Blocks.stone);
		world.setBlock(i + 5, j + 11, k + 20, Blocks.stone);
		world.setBlock(i + 5, j + 11, k + 21, Blocks.stone);
		world.setBlock(i + 5, j + 11, k + 22, Blocks.stone);
		world.setBlock(i + 5, j + 11, k + 23, Blocks.stone);
		world.setBlock(i + 5, j + 12, k + 18, Blocks.stone);
		world.setBlock(i + 5, j + 12, k + 19, Blocks.stone);
		world.setBlock(i + 6, j + 4, k + 11, Blocks.stone);
		world.setBlock(i + 6, j + 4, k + 12, Blocks.stone);
		world.setBlock(i + 6, j + 4, k + 13, Blocks.stone);
		world.setBlock(i + 6, j + 4, k + 14, Blocks.stone);
		world.setBlock(i + 6, j + 4, k + 15, Blocks.stone);
		world.setBlock(i + 6, j + 4, k + 16, Blocks.stone);
		world.setBlock(i + 6, j + 4, k + 17, Blocks.stone);
		world.setBlock(i + 6, j + 4, k + 18, Blocks.stone);
		world.setBlock(i + 6, j + 4, k + 19, Blocks.stone);
		world.setBlock(i + 6, j + 4, k + 20, Blocks.stone);
		world.setBlock(i + 6, j + 4, k + 21, Blocks.stone);
		world.setBlock(i + 6, j + 4, k + 22, Blocks.stone);
		world.setBlock(i + 6, j + 4, k + 23, Blocks.stone);
		world.setBlock(i + 6, j + 4, k + 24, Blocks.stone);
		world.setBlock(i + 6, j + 4, k + 25, Blocks.stone);
		world.setBlock(i + 6, j + 4, k + 26, Blocks.stone);
		world.setBlock(i + 6, j + 4, k + 27, Blocks.stone);
		world.setBlock(i + 6, j + 5, k + 11, Blocks.stone);
		world.setBlock(i + 6, j + 5, k + 12, Blocks.stone);
		world.setBlock(i + 6, j + 5, k + 13, Blocks.stone);
		world.setBlock(i + 6, j + 5, k + 14, Blocks.stone);
		world.setBlock(i + 6, j + 5, k + 15, Blocks.stone);
		world.setBlock(i + 6, j + 5, k + 16, Blocks.stone);
		world.setBlock(i + 6, j + 5, k + 17, Blocks.stone);
		world.setBlock(i + 6, j + 5, k + 20, Blocks.stone);
		world.setBlock(i + 6, j + 5, k + 21, Blocks.stone);
		world.setBlock(i + 6, j + 5, k + 22, Blocks.stone);
		world.setBlock(i + 6, j + 5, k + 23, Blocks.stone);
		world.setBlock(i + 6, j + 5, k + 24, Blocks.stone);
		world.setBlock(i + 6, j + 5, k + 25, Blocks.stone);
		world.setBlock(i + 6, j + 5, k + 26, Blocks.stone);
		world.setBlock(i + 6, j + 5, k + 27, Blocks.stone);
		world.setBlock(i + 6, j + 6, k + 11, Blocks.stone);
		world.setBlock(i + 6, j + 6, k + 12, Blocks.air);
		world.setBlock(i + 6, j + 6, k + 13, Blocks.air);
		world.setBlock(i + 6, j + 6, k + 14, Blocks.air);
		world.setBlock(i + 6, j + 6, k + 15, Blocks.air);
		world.setBlock(i + 6, j + 6, k + 16, Blocks.air);
		world.setBlock(i + 6, j + 6, k + 17, Blocks.air);
		world.setBlock(i + 6, j + 6, k + 18, Blocks.air);
		world.setBlock(i + 6, j + 6, k + 19, Blocks.air);
		world.setBlock(i + 6, j + 6, k + 20, Blocks.air);
		world.setBlock(i + 6, j + 6, k + 21, Blocks.air);
		world.setBlock(i + 6, j + 6, k + 22, Blocks.air);
		world.setBlock(i + 6, j + 6, k + 23, Blocks.air);
		world.setBlock(i + 6, j + 6, k + 24, Blocks.air);
		world.setBlock(i + 6, j + 6, k + 25, Blocks.air);
		world.setBlock(i + 6, j + 6, k + 26, Blocks.air);
		world.setBlock(i + 6, j + 6, k + 27, Blocks.stone);
		world.setBlock(i + 6, j + 7, k + 11, Blocks.stone);
		world.setBlock(i + 6, j + 7, k + 12, Blocks.air);
		world.setBlock(i + 6, j + 7, k + 13, Blocks.air);
		world.setBlock(i + 6, j + 7, k + 14, Blocks.air);
		world.setBlock(i + 6, j + 7, k + 15, Blocks.air);
		world.setBlock(i + 6, j + 7, k + 16, Blocks.air);
		world.setBlock(i + 6, j + 7, k + 17, Blocks.air);
		world.setBlock(i + 6, j + 7, k + 18, Blocks.air);
		world.setBlock(i + 6, j + 7, k + 19, Blocks.air);
		world.setBlock(i + 6, j + 7, k + 20, Blocks.air);
		world.setBlock(i + 6, j + 7, k + 21, Blocks.air);
		world.setBlock(i + 6, j + 7, k + 22, Blocks.air);
		world.setBlock(i + 6, j + 7, k + 23, Blocks.air);
		world.setBlock(i + 6, j + 7, k + 24, Blocks.air);
		world.setBlock(i + 6, j + 7, k + 25, Blocks.air);
		world.setBlock(i + 6, j + 7, k + 26, Blocks.air);
		world.setBlock(i + 6, j + 7, k + 27, Blocks.stone);
		world.setBlock(i + 6, j + 8, k + 11, Blocks.stone);
		world.setBlock(i + 6, j + 8, k + 12, Blocks.air);
		world.setBlock(i + 6, j + 8, k + 13, Blocks.air);
		world.setBlock(i + 6, j + 8, k + 14, Blocks.air);
		world.setBlock(i + 6, j + 8, k + 15, Blocks.air);
		world.setBlock(i + 6, j + 8, k + 16, Blocks.air);
		world.setBlock(i + 6, j + 8, k + 17, Blocks.air);
		world.setBlock(i + 6, j + 8, k + 18, Blocks.air);
		world.setBlock(i + 6, j + 8, k + 19, Blocks.air);
		world.setBlock(i + 6, j + 8, k + 20, Blocks.air);
		world.setBlock(i + 6, j + 8, k + 21, Blocks.air);
		world.setBlock(i + 6, j + 8, k + 22, Blocks.air);
		world.setBlock(i + 6, j + 8, k + 23, Blocks.air);
		world.setBlock(i + 6, j + 8, k + 24, Blocks.air);
		world.setBlock(i + 6, j + 8, k + 25, Blocks.air);
		world.setBlock(i + 6, j + 8, k + 26, Blocks.air);
		world.setBlock(i + 6, j + 8, k + 27, Blocks.stone);
		world.setBlock(i + 6, j + 9, k + 11, Blocks.stone);
		world.setBlock(i + 6, j + 9, k + 12, Blocks.stone);
		world.setBlock(i + 6, j + 9, k + 13, Blocks.air);
		world.setBlock(i + 6, j + 9, k + 14, Blocks.air);
		world.setBlock(i + 6, j + 9, k + 15, Blocks.air);
		world.setBlock(i + 6, j + 9, k + 16, Blocks.air);
		world.setBlock(i + 6, j + 9, k + 17, Blocks.air);
		world.setBlock(i + 6, j + 9, k + 18, Blocks.air);
		world.setBlock(i + 6, j + 9, k + 19, Blocks.air);
		world.setBlock(i + 6, j + 9, k + 20, Blocks.air);
		world.setBlock(i + 6, j + 9, k + 21, Blocks.air);
		world.setBlock(i + 6, j + 9, k + 22, Blocks.air);
		world.setBlock(i + 6, j + 9, k + 23, Blocks.air);
		world.setBlock(i + 6, j + 9, k + 24, Blocks.air);
		world.setBlock(i + 6, j + 9, k + 25, Blocks.air);
		world.setBlock(i + 6, j + 9, k + 26, Blocks.stone);
		world.setBlock(i + 6, j + 9, k + 27, Blocks.stone);
		world.setBlock(i + 6, j + 10, k + 12, Blocks.stone);
		world.setBlock(i + 6, j + 10, k + 13, Blocks.stone);
		world.setBlock(i + 6, j + 10, k + 14, Blocks.stone);
		world.setBlock(i + 6, j + 10, k + 15, Blocks.air);
		world.setBlock(i + 6, j + 10, k + 16, Blocks.air);
		world.setBlock(i + 6, j + 10, k + 17, Blocks.air);
		world.setBlock(i + 6, j + 10, k + 18, Blocks.air);
		world.setBlock(i + 6, j + 10, k + 19, Blocks.air);
		world.setBlock(i + 6, j + 10, k + 20, Blocks.air);
		world.setBlock(i + 6, j + 10, k + 21, Blocks.air);
		world.setBlock(i + 6, j + 10, k + 22, Blocks.air);
		world.setBlock(i + 6, j + 10, k + 23, Blocks.air);
		world.setBlock(i + 6, j + 10, k + 24, Blocks.stone);
		world.setBlock(i + 6, j + 10, k + 25, Blocks.stone);
		world.setBlock(i + 6, j + 10, k + 26, Blocks.stone);
		world.setBlock(i + 6, j + 11, k + 14, Blocks.stone);
		world.setBlock(i + 6, j + 11, k + 15, Blocks.stone);
		world.setBlock(i + 6, j + 11, k + 16, Blocks.stone);
		world.setBlock(i + 6, j + 11, k + 17, Blocks.stone);
		world.setBlock(i + 6, j + 11, k + 18, Blocks.air);
		world.setBlock(i + 6, j + 11, k + 19, Blocks.air);
		world.setBlock(i + 6, j + 11, k + 20, Blocks.stone);
		world.setBlock(i + 6, j + 11, k + 21, Blocks.stone);
		world.setBlock(i + 6, j + 11, k + 22, Blocks.stone);
		world.setBlock(i + 6, j + 11, k + 23, Blocks.stone);
		world.setBlock(i + 6, j + 11, k + 24, Blocks.stone);
		world.setBlock(i + 6, j + 12, k + 17, Blocks.stone);
		world.setBlock(i + 6, j + 12, k + 18, Blocks.stone);
		world.setBlock(i + 6, j + 12, k + 19, Blocks.stone);
		world.setBlock(i + 6, j + 12, k + 20, Blocks.stone);
		world.setBlock(i + 7, j + 4, k + 10, Blocks.stone);
		world.setBlock(i + 7, j + 4, k + 11, Blocks.stone);
		world.setBlock(i + 7, j + 4, k + 12, Blocks.stone);
		world.setBlock(i + 7, j + 4, k + 13, Blocks.stone);
		world.setBlock(i + 7, j + 4, k + 14, Blocks.stone);
		world.setBlock(i + 7, j + 4, k + 15, Blocks.stone);
		world.setBlock(i + 7, j + 4, k + 16, Blocks.stone);
		world.setBlock(i + 7, j + 4, k + 17, Blocks.stone);
		world.setBlock(i + 7, j + 4, k + 18, Blocks.stone);
		world.setBlock(i + 7, j + 4, k + 19, Blocks.stone);
		world.setBlock(i + 7, j + 4, k + 20, Blocks.stone);
		world.setBlock(i + 7, j + 4, k + 21, Blocks.stone);
		world.setBlock(i + 7, j + 4, k + 22, Blocks.stone);
		world.setBlock(i + 7, j + 4, k + 23, Blocks.stone);
		world.setBlock(i + 7, j + 4, k + 24, Blocks.stone);
		world.setBlock(i + 7, j + 4, k + 25, Blocks.stone);
		world.setBlock(i + 7, j + 4, k + 26, Blocks.stone);
		world.setBlock(i + 7, j + 4, k + 27, Blocks.stone);
		world.setBlock(i + 7, j + 5, k + 10, Blocks.stone);
		world.setBlock(i + 7, j + 5, k + 11, Blocks.stone);
		world.setBlock(i + 7, j + 5, k + 12, Blocks.stone);
		world.setBlock(i + 7, j + 5, k + 13, Blocks.stone);
		world.setBlock(i + 7, j + 5, k + 14, Blocks.stone);
		world.setBlock(i + 7, j + 5, k + 15, Blocks.stone);
		world.setBlock(i + 7, j + 5, k + 16, Blocks.stone);
		world.setBlock(i + 7, j + 5, k + 17, Blocks.stone);
		world.setBlock(i + 7, j + 5, k + 20, Blocks.stone);
		world.setBlock(i + 7, j + 5, k + 21, Blocks.stone);
		world.setBlock(i + 7, j + 5, k + 22, Blocks.stone);
		world.setBlock(i + 7, j + 5, k + 23, Blocks.stone);
		world.setBlock(i + 7, j + 5, k + 24, Blocks.stone);
		world.setBlock(i + 7, j + 5, k + 25, Blocks.stone);
		world.setBlock(i + 7, j + 5, k + 26, Blocks.stone);
		world.setBlock(i + 7, j + 5, k + 27, Blocks.stone);
		world.setBlock(i + 7, j + 6, k + 10, Blocks.stone);
		world.setBlock(i + 7, j + 6, k + 11, Blocks.air);
		world.setBlock(i + 7, j + 6, k + 12, Blocks.air);
		world.setBlock(i + 7, j + 6, k + 13, Blocks.air);
		world.setBlock(i + 7, j + 6, k + 14, Blocks.air);
		world.setBlock(i + 7, j + 6, k + 15, Blocks.air);
		world.setBlock(i + 7, j + 6, k + 16, Blocks.air);
		world.setBlock(i + 7, j + 6, k + 17, Blocks.air);
		world.setBlock(i + 7, j + 6, k + 18, Blocks.air);
		world.setBlock(i + 7, j + 6, k + 19, Blocks.air);
		world.setBlock(i + 7, j + 6, k + 20, Blocks.air);
		world.setBlock(i + 7, j + 6, k + 21, Blocks.air);
		world.setBlock(i + 7, j + 6, k + 23, Blocks.stone);
		world.setBlock(i + 7, j + 6, k + 24, Blocks.air);
		world.setBlock(i + 7, j + 6, k + 25, Blocks.air);
		world.setBlock(i + 7, j + 6, k + 26, Blocks.air);
		world.setBlock(i + 7, j + 6, k + 27, Blocks.stone);
		world.setBlock(i + 7, j + 7, k + 10, Blocks.stone);
		world.setBlock(i + 7, j + 7, k + 11, Blocks.air);
		world.setBlock(i + 7, j + 7, k + 12, Blocks.air);
		world.setBlock(i + 7, j + 7, k + 13, Blocks.air);
		world.setBlock(i + 7, j + 7, k + 14, Blocks.air);
		world.setBlock(i + 7, j + 7, k + 15, Blocks.air);
		world.setBlock(i + 7, j + 7, k + 16, Blocks.air);
		world.setBlock(i + 7, j + 7, k + 17, Blocks.air);
		world.setBlock(i + 7, j + 7, k + 18, Blocks.air);
		world.setBlock(i + 7, j + 7, k + 19, Blocks.air);
		world.setBlock(i + 7, j + 7, k + 20, Blocks.air);
		world.setBlock(i + 7, j + 7, k + 21, Blocks.air);
		world.setBlock(i + 7, j + 7, k + 23, Blocks.stone);
		world.setBlock(i + 7, j + 7, k + 24, Blocks.air);
		world.setBlock(i + 7, j + 7, k + 25, Blocks.air);
		world.setBlock(i + 7, j + 7, k + 26, Blocks.air);
		world.setBlock(i + 7, j + 7, k + 27, Blocks.stone);
		world.setBlock(i + 7, j + 8, k + 10, Blocks.stone);
		world.setBlock(i + 7, j + 8, k + 11, Blocks.air);
		world.setBlock(i + 7, j + 8, k + 12, Blocks.air);
		world.setBlock(i + 7, j + 8, k + 13, Blocks.air);
		world.setBlock(i + 7, j + 8, k + 14, Blocks.air);
		world.setBlock(i + 7, j + 8, k + 15, Blocks.air);
		world.setBlock(i + 7, j + 8, k + 16, Blocks.air);
		world.setBlock(i + 7, j + 8, k + 17, Blocks.air);
		world.setBlock(i + 7, j + 8, k + 18, Blocks.air);
		world.setBlock(i + 7, j + 8, k + 19, Blocks.air);
		world.setBlock(i + 7, j + 8, k + 20, Blocks.air);
		world.setBlock(i + 7, j + 8, k + 21, Blocks.air);
		world.setBlock(i + 7, j + 8, k + 23, Blocks.stone);
		world.setBlock(i + 7, j + 8, k + 24, Blocks.air);
		world.setBlock(i + 7, j + 8, k + 25, Blocks.air);
		world.setBlock(i + 7, j + 8, k + 26, Blocks.air);
		world.setBlock(i + 7, j + 8, k + 27, Blocks.stone);
		world.setBlock(i + 7, j + 9, k + 10, Blocks.stone);
		world.setBlock(i + 7, j + 9, k + 11, Blocks.stone);
		world.setBlock(i + 7, j + 9, k + 12, Blocks.air);
		world.setBlock(i + 7, j + 9, k + 13, Blocks.air);
		world.setBlock(i + 7, j + 9, k + 14, Blocks.air);
		world.setBlock(i + 7, j + 9, k + 15, Blocks.air);
		world.setBlock(i + 7, j + 9, k + 16, Blocks.air);
		world.setBlock(i + 7, j + 9, k + 17, Blocks.air);
		world.setBlock(i + 7, j + 9, k + 18, Blocks.air);
		world.setBlock(i + 7, j + 9, k + 19, Blocks.air);
		world.setBlock(i + 7, j + 9, k + 20, Blocks.air);
		world.setBlock(i + 7, j + 9, k + 21, Blocks.air);
		world.setBlock(i + 7, j + 9, k + 23, Blocks.stone);
		world.setBlock(i + 7, j + 9, k + 24, Blocks.air);
		world.setBlock(i + 7, j + 9, k + 25, Blocks.air);
		world.setBlock(i + 7, j + 9, k + 26, Blocks.stone);
		world.setBlock(i + 7, j + 9, k + 27, Blocks.stone);
		world.setBlock(i + 7, j + 10, k + 11, Blocks.stone);
		world.setBlock(i + 7, j + 10, k + 12, Blocks.stone);
		world.setBlock(i + 7, j + 10, k + 13, Blocks.stone);
		world.setBlock(i + 7, j + 10, k + 14, Blocks.stone);
		world.setBlock(i + 7, j + 10, k + 15, Blocks.air);
		world.setBlock(i + 7, j + 10, k + 16, Blocks.air);
		world.setBlock(i + 7, j + 10, k + 17, Blocks.air);
		world.setBlock(i + 7, j + 10, k + 18, Blocks.air);
		world.setBlock(i + 7, j + 10, k + 19, Blocks.air);
		world.setBlock(i + 7, j + 10, k + 20, Blocks.air);
		world.setBlock(i + 7, j + 10, k + 21, Blocks.air);
		world.setBlock(i + 7, j + 10, k + 23, Blocks.stone);
		world.setBlock(i + 7, j + 10, k + 24, Blocks.stone);
		world.setBlock(i + 7, j + 10, k + 25, Blocks.stone);
		world.setBlock(i + 7, j + 10, k + 26, Blocks.stone);
		world.setBlock(i + 7, j + 11, k + 14, Blocks.stone);
		world.setBlock(i + 7, j + 11, k + 15, Blocks.stone);
		world.setBlock(i + 7, j + 11, k + 16, Blocks.stone);
		world.setBlock(i + 7, j + 11, k + 17, Blocks.air);
		world.setBlock(i + 7, j + 11, k + 18, Blocks.air);
		world.setBlock(i + 7, j + 11, k + 19, Blocks.air);
		world.setBlock(i + 7, j + 11, k + 20, Blocks.air);
		world.setBlock(i + 7, j + 11, k + 21, Blocks.stone);
		world.setBlock(i + 7, j + 11, k + 23, Blocks.stone);
		world.setBlock(i + 7, j + 11, k + 24, Blocks.stone);
		world.setBlock(i + 7, j + 12, k + 16, Blocks.stone);
		world.setBlock(i + 7, j + 12, k + 17, Blocks.stone);
		world.setBlock(i + 7, j + 12, k + 18, Blocks.stone);
		world.setBlock(i + 7, j + 12, k + 19, Blocks.stone);
		world.setBlock(i + 7, j + 12, k + 20, Blocks.stone);
		world.setBlock(i + 7, j + 12, k + 21, Blocks.stone);
		world.setBlock(i + 7, j + 12, k + 23, Blocks.stone);
		world.setBlock(i + 8, j + 4, k + 10, Blocks.stone);
		world.setBlock(i + 8, j + 4, k + 11, Blocks.stone);
		world.setBlock(i + 8, j + 4, k + 12, Blocks.stone);
		world.setBlock(i + 8, j + 4, k + 13, Blocks.stone);
		world.setBlock(i + 8, j + 4, k + 14, Blocks.stone);
		world.setBlock(i + 8, j + 4, k + 15, Blocks.stone);
		world.setBlock(i + 8, j + 4, k + 16, Blocks.stone);
		world.setBlock(i + 8, j + 4, k + 17, Blocks.stone);
		world.setBlock(i + 8, j + 4, k + 18, Blocks.stone);
		world.setBlock(i + 8, j + 4, k + 19, Blocks.stone);
		world.setBlock(i + 8, j + 4, k + 20, Blocks.stone);
		world.setBlock(i + 8, j + 4, k + 21, Blocks.stone);
		world.setBlock(i + 8, j + 4, k + 22, Blocks.stone);
		world.setBlock(i + 8, j + 4, k + 23, Blocks.stone);
		world.setBlock(i + 8, j + 4, k + 24, Blocks.stone);
		world.setBlock(i + 8, j + 4, k + 25, Blocks.stone);
		world.setBlock(i + 8, j + 4, k + 26, Blocks.stone);
		world.setBlock(i + 8, j + 4, k + 27, Blocks.stone);
		world.setBlock(i + 8, j + 5, k + 10, Blocks.stone);
		world.setBlock(i + 8, j + 5, k + 11, Blocks.stone);
		world.setBlock(i + 8, j + 5, k + 12, Blocks.stone);
		world.setBlock(i + 8, j + 5, k + 13, Blocks.stone);
		world.setBlock(i + 8, j + 5, k + 14, Blocks.stone);
		world.setBlock(i + 8, j + 5, k + 15, Blocks.stone);
		world.setBlock(i + 8, j + 5, k + 16, Blocks.stone);
		world.setBlock(i + 8, j + 5, k + 20, Blocks.stone);
		world.setBlock(i + 8, j + 5, k + 21, Blocks.stone);
		world.setBlock(i + 8, j + 5, k + 22, Blocks.stone);
		world.setBlock(i + 8, j + 5, k + 23, Blocks.stone);
		world.setBlock(i + 8, j + 5, k + 24, Blocks.stone);
		world.setBlock(i + 8, j + 5, k + 25, Blocks.stone);
		world.setBlock(i + 8, j + 5, k + 26, Blocks.stone);
		world.setBlock(i + 8, j + 5, k + 27, Blocks.stone);
		world.setBlock(i + 8, j + 6, k + 10, Blocks.stone);
		world.setBlock(i + 8, j + 6, k + 11, Blocks.air);
		world.setBlock(i + 8, j + 6, k + 12, Blocks.air);
		world.setBlock(i + 8, j + 6, k + 13, Blocks.air);
		world.setBlock(i + 8, j + 6, k + 14, Blocks.air);
		world.setBlock(i + 8, j + 6, k + 15, Blocks.air);
		world.setBlock(i + 8, j + 6, k + 16, Blocks.air);
		world.setBlock(i + 8, j + 6, k + 17, Blocks.air);
		world.setBlock(i + 8, j + 6, k + 18, Blocks.air);
		world.setBlock(i + 8, j + 6, k + 19, Blocks.air);
		world.setBlock(i + 8, j + 6, k + 20, Blocks.air);
		world.setBlock(i + 8, j + 6, k + 21, Blocks.air);
		world.setBlock(i + 8, j + 6, k + 22, Blocks.air);
		world.setBlock(i + 8, j + 6, k + 23, Blocks.air);
		world.setBlock(i + 8, j + 6, k + 24, Blocks.air);
		world.setBlock(i + 8, j + 6, k + 25, Blocks.air);
		world.setBlock(i + 8, j + 6, k + 26, Blocks.air);
		world.setBlock(i + 8, j + 6, k + 27, Blocks.stone);
		world.setBlock(i + 8, j + 7, k + 10, Blocks.stone);
		world.setBlock(i + 8, j + 7, k + 11, Blocks.air);
		world.setBlock(i + 8, j + 7, k + 12, Blocks.air);
		world.setBlock(i + 8, j + 7, k + 13, Blocks.air);
		world.setBlock(i + 8, j + 7, k + 14, Blocks.air);
		world.setBlock(i + 8, j + 7, k + 15, Blocks.air);
		world.setBlock(i + 8, j + 7, k + 16, Blocks.air);
		world.setBlock(i + 8, j + 7, k + 17, Blocks.air);
		world.setBlock(i + 8, j + 7, k + 18, Blocks.air);
		world.setBlock(i + 8, j + 7, k + 19, Blocks.air);
		world.setBlock(i + 8, j + 7, k + 20, Blocks.air);
		world.setBlock(i + 8, j + 7, k + 21, Blocks.air);
		world.setBlock(i + 8, j + 7, k + 22, Blocks.air);
		world.setBlock(i + 8, j + 7, k + 23, Blocks.air);
		world.setBlock(i + 8, j + 7, k + 24, Blocks.air);
		world.setBlock(i + 8, j + 7, k + 25, Blocks.air);
		world.setBlock(i + 8, j + 7, k + 26, Blocks.air);
		world.setBlock(i + 8, j + 7, k + 27, Blocks.stone);
		world.setBlock(i + 8, j + 8, k + 10, Blocks.stone);
		world.setBlock(i + 8, j + 8, k + 11, Blocks.air);
		world.setBlock(i + 8, j + 8, k + 12, Blocks.air);
		world.setBlock(i + 8, j + 8, k + 13, Blocks.air);
		world.setBlock(i + 8, j + 8, k + 14, Blocks.air);
		world.setBlock(i + 8, j + 8, k + 15, Blocks.air);
		world.setBlock(i + 8, j + 8, k + 16, Blocks.air);
		world.setBlock(i + 8, j + 8, k + 17, Blocks.air);
		world.setBlock(i + 8, j + 8, k + 18, Blocks.air);
		world.setBlock(i + 8, j + 8, k + 19, Blocks.air);
		world.setBlock(i + 8, j + 8, k + 20, Blocks.air);
		world.setBlock(i + 8, j + 8, k + 21, Blocks.air);
		world.setBlock(i + 8, j + 8, k + 22, Blocks.air);
		world.setBlock(i + 8, j + 8, k + 23, Blocks.air);
		world.setBlock(i + 8, j + 8, k + 24, Blocks.air);
		world.setBlock(i + 8, j + 8, k + 25, Blocks.air);
		world.setBlock(i + 8, j + 8, k + 26, Blocks.air);
		world.setBlock(i + 8, j + 8, k + 27, Blocks.stone);
		world.setBlock(i + 8, j + 9, k + 10, Blocks.stone);
		world.setBlock(i + 8, j + 9, k + 11, Blocks.stone);
		world.setBlock(i + 8, j + 9, k + 12, Blocks.air);
		world.setBlock(i + 8, j + 9, k + 13, Blocks.air);
		world.setBlock(i + 8, j + 9, k + 14, Blocks.air);
		world.setBlock(i + 8, j + 9, k + 15, Blocks.air);
		world.setBlock(i + 8, j + 9, k + 16, Blocks.air);
		world.setBlock(i + 8, j + 9, k + 17, Blocks.air);
		world.setBlock(i + 8, j + 9, k + 18, Blocks.air);
		world.setBlock(i + 8, j + 9, k + 19, Blocks.air);
		world.setBlock(i + 8, j + 9, k + 20, Blocks.air);
		world.setBlock(i + 8, j + 9, k + 21, Blocks.air);
		world.setBlock(i + 8, j + 9, k + 22, Blocks.air);
		world.setBlock(i + 8, j + 9, k + 23, Blocks.air);
		world.setBlock(i + 8, j + 9, k + 24, Blocks.air);
		world.setBlock(i + 8, j + 9, k + 25, Blocks.air);
		world.setBlock(i + 8, j + 9, k + 26, Blocks.stone);
		world.setBlock(i + 8, j + 9, k + 27, Blocks.stone);
		world.setBlock(i + 8, j + 10, k + 11, Blocks.stone);
		world.setBlock(i + 8, j + 10, k + 12, Blocks.stone);
		world.setBlock(i + 8, j + 10, k + 13, Blocks.stone);
		world.setBlock(i + 8, j + 10, k + 14, Blocks.air);
		world.setBlock(i + 8, j + 10, k + 15, Blocks.air);
		world.setBlock(i + 8, j + 10, k + 16, Blocks.air);
		world.setBlock(i + 8, j + 10, k + 17, Blocks.air);
		world.setBlock(i + 8, j + 10, k + 18, Blocks.air);
		world.setBlock(i + 8, j + 10, k + 19, Blocks.air);
		world.setBlock(i + 8, j + 10, k + 20, Blocks.air);
		world.setBlock(i + 8, j + 10, k + 21, Blocks.air);
		world.setBlock(i + 8, j + 10, k + 22, Blocks.air);
		world.setBlock(i + 8, j + 10, k + 23, Blocks.air);
		world.setBlock(i + 8, j + 10, k + 24, Blocks.stone);
		world.setBlock(i + 8, j + 10, k + 25, Blocks.stone);
		world.setBlock(i + 8, j + 10, k + 26, Blocks.stone);
		world.setBlock(i + 8, j + 11, k + 13, Blocks.stone);
		world.setBlock(i + 8, j + 11, k + 14, Blocks.stone);
		world.setBlock(i + 8, j + 11, k + 15, Blocks.stone);
		world.setBlock(i + 8, j + 11, k + 16, Blocks.stone);
		world.setBlock(i + 8, j + 11, k + 17, Blocks.air);
		world.setBlock(i + 8, j + 11, k + 18, Blocks.air);
		world.setBlock(i + 8, j + 11, k + 19, Blocks.air);
		world.setBlock(i + 8, j + 11, k + 20, Blocks.air);
		world.setBlock(i + 8, j + 11, k + 21, Blocks.stone);
		world.setBlock(i + 8, j + 11, k + 22, Blocks.stone);
		world.setBlock(i + 8, j + 11, k + 23, Blocks.stone);
		world.setBlock(i + 8, j + 11, k + 24, Blocks.stone);
		world.setBlock(i + 8, j + 12, k + 16, Blocks.stone);
		world.setBlock(i + 8, j + 12, k + 17, Blocks.stone);
		world.setBlock(i + 8, j + 12, k + 18, Blocks.stone);
		world.setBlock(i + 8, j + 12, k + 19, Blocks.stone);
		world.setBlock(i + 8, j + 12, k + 20, Blocks.stone);
		world.setBlock(i + 8, j + 12, k + 21, Blocks.stone);
		world.setBlock(i + 9, j + 4, k + 10, Blocks.stone);
		world.setBlock(i + 9, j + 4, k + 11, Blocks.stone);
		world.setBlock(i + 9, j + 4, k + 12, Blocks.stone);
		world.setBlock(i + 9, j + 4, k + 13, Blocks.stone);
		world.setBlock(i + 9, j + 4, k + 14, Blocks.stone);
		world.setBlock(i + 9, j + 4, k + 15, Blocks.stone);
		world.setBlock(i + 9, j + 4, k + 16, Blocks.stone);
		world.setBlock(i + 9, j + 4, k + 17, Blocks.stone);
		world.setBlock(i + 9, j + 4, k + 18, Blocks.stone);
		world.setBlock(i + 9, j + 4, k + 19, Blocks.stone);
		world.setBlock(i + 9, j + 4, k + 20, Blocks.stone);
		world.setBlock(i + 9, j + 4, k + 21, Blocks.stone);
		world.setBlock(i + 9, j + 4, k + 22, Blocks.stone);
		world.setBlock(i + 9, j + 4, k + 23, Blocks.stone);
		world.setBlock(i + 9, j + 4, k + 24, Blocks.stone);
		world.setBlock(i + 9, j + 4, k + 25, Blocks.stone);
		world.setBlock(i + 9, j + 4, k + 26, Blocks.stone);
		world.setBlock(i + 9, j + 4, k + 27, Blocks.stone);
		world.setBlock(i + 9, j + 5, k + 10, Blocks.stone);
		world.setBlock(i + 9, j + 5, k + 11, Blocks.stone);
		world.setBlock(i + 9, j + 5, k + 12, Blocks.stone);
		world.setBlock(i + 9, j + 5, k + 13, Blocks.stone);
		world.setBlock(i + 9, j + 5, k + 14, Blocks.stone);
		world.setBlock(i + 9, j + 5, k + 15, Blocks.stone);
		world.setBlock(i + 9, j + 5, k + 16, Blocks.stone);
		world.setBlock(i + 9, j + 5, k + 19, Blocks.stone);
		world.setBlock(i + 9, j + 5, k + 20, Blocks.stone);
		world.setBlock(i + 9, j + 5, k + 21, Blocks.stone);
		world.setBlock(i + 9, j + 5, k + 22, Blocks.stone);
		world.setBlock(i + 9, j + 5, k + 23, Blocks.stone);
		world.setBlock(i + 9, j + 5, k + 24, Blocks.stone);
		world.setBlock(i + 9, j + 5, k + 25, Blocks.stone);
		world.setBlock(i + 9, j + 5, k + 26, Blocks.stone);
		world.setBlock(i + 9, j + 5, k + 27, Blocks.stone);
		world.setBlock(i + 9, j + 6, k + 10, Blocks.stone);
		world.setBlock(i + 9, j + 6, k + 11, Blocks.air);
		world.setBlock(i + 9, j + 6, k + 12, Blocks.air);
		world.setBlock(i + 9, j + 6, k + 13, Blocks.air);
		world.setBlock(i + 9, j + 6, k + 14, Blocks.air);
		world.setBlock(i + 9, j + 6, k + 15, Blocks.air);
		world.setBlock(i + 9, j + 6, k + 16, Blocks.air);
		world.setBlock(i + 9, j + 6, k + 17, Blocks.air);
		world.setBlock(i + 9, j + 6, k + 18, Blocks.air);
		world.setBlock(i + 9, j + 6, k + 19, Blocks.air);
		world.setBlock(i + 9, j + 6, k + 20, Blocks.air);
		world.setBlock(i + 9, j + 6, k + 21, Blocks.air);
		world.setBlock(i + 9, j + 6, k + 22, Blocks.air);
		world.setBlock(i + 9, j + 6, k + 23, Blocks.air);
		world.setBlock(i + 9, j + 6, k + 24, Blocks.air);
		world.setBlock(i + 9, j + 6, k + 25, Blocks.air);
		world.setBlock(i + 9, j + 6, k + 26, Blocks.air);
		world.setBlock(i + 9, j + 6, k + 27, Blocks.stone);
		world.setBlock(i + 9, j + 7, k + 10, Blocks.stone);
		world.setBlock(i + 9, j + 7, k + 11, Blocks.air);
		world.setBlock(i + 9, j + 7, k + 12, Blocks.air);
		world.setBlock(i + 9, j + 7, k + 13, Blocks.air);
		world.setBlock(i + 9, j + 7, k + 14, Blocks.air);
		world.setBlock(i + 9, j + 7, k + 15, Blocks.air);
		world.setBlock(i + 9, j + 7, k + 16, Blocks.air);
		world.setBlock(i + 9, j + 7, k + 17, Blocks.air);
		world.setBlock(i + 9, j + 7, k + 18, Blocks.air);
		world.setBlock(i + 9, j + 7, k + 19, Blocks.air);
		world.setBlock(i + 9, j + 7, k + 20, Blocks.air);
		world.setBlock(i + 9, j + 7, k + 21, Blocks.air);
		world.setBlock(i + 9, j + 7, k + 22, Blocks.air);
		world.setBlock(i + 9, j + 7, k + 23, Blocks.air);
		world.setBlock(i + 9, j + 7, k + 24, Blocks.air);
		world.setBlock(i + 9, j + 7, k + 25, Blocks.air);
		world.setBlock(i + 9, j + 7, k + 26, Blocks.air);
		world.setBlock(i + 9, j + 7, k + 27, Blocks.stone);
		world.setBlock(i + 9, j + 8, k + 10, Blocks.stone);
		world.setBlock(i + 9, j + 8, k + 11, Blocks.air);
		world.setBlock(i + 9, j + 8, k + 12, Blocks.air);
		world.setBlock(i + 9, j + 8, k + 13, Blocks.air);
		world.setBlock(i + 9, j + 8, k + 14, Blocks.air);
		world.setBlock(i + 9, j + 8, k + 15, Blocks.air);
		world.setBlock(i + 9, j + 8, k + 16, Blocks.air);
		world.setBlock(i + 9, j + 8, k + 17, Blocks.air);
		world.setBlock(i + 9, j + 8, k + 18, Blocks.air);
		world.setBlock(i + 9, j + 8, k + 19, Blocks.air);
		world.setBlock(i + 9, j + 8, k + 20, Blocks.air);
		world.setBlock(i + 9, j + 8, k + 21, Blocks.air);
		world.setBlock(i + 9, j + 8, k + 22, Blocks.air);
		world.setBlock(i + 9, j + 8, k + 23, Blocks.air);
		world.setBlock(i + 9, j + 8, k + 24, Blocks.air);
		world.setBlock(i + 9, j + 8, k + 25, Blocks.air);
		world.setBlock(i + 9, j + 8, k + 26, Blocks.air);
		world.setBlock(i + 9, j + 8, k + 27, Blocks.stone);
		world.setBlock(i + 9, j + 9, k + 10, Blocks.stone);
		world.setBlock(i + 9, j + 9, k + 11, Blocks.stone);
		world.setBlock(i + 9, j + 9, k + 12, Blocks.air);
		world.setBlock(i + 9, j + 9, k + 13, Blocks.air);
		world.setBlock(i + 9, j + 9, k + 14, Blocks.air);
		world.setBlock(i + 9, j + 9, k + 15, Blocks.air);
		world.setBlock(i + 9, j + 9, k + 16, Blocks.air);
		world.setBlock(i + 9, j + 9, k + 17, Blocks.air);
		world.setBlock(i + 9, j + 9, k + 18, Blocks.air);
		world.setBlock(i + 9, j + 9, k + 19, Blocks.air);
		world.setBlock(i + 9, j + 9, k + 20, Blocks.air);
		world.setBlock(i + 9, j + 9, k + 21, Blocks.air);
		world.setBlock(i + 9, j + 9, k + 22, Blocks.air);
		world.setBlock(i + 9, j + 9, k + 23, Blocks.air);
		world.setBlock(i + 9, j + 9, k + 24, Blocks.air);
		world.setBlock(i + 9, j + 9, k + 25, Blocks.air);
		world.setBlock(i + 9, j + 9, k + 26, Blocks.stone);
		world.setBlock(i + 9, j + 9, k + 27, Blocks.stone);
		world.setBlock(i + 9, j + 10, k + 11, Blocks.stone);
		world.setBlock(i + 9, j + 10, k + 12, Blocks.stone);
		world.setBlock(i + 9, j + 10, k + 13, Blocks.stone);
		world.setBlock(i + 9, j + 10, k + 14, Blocks.stone);
		world.setBlock(i + 9, j + 10, k + 15, Blocks.air);
		world.setBlock(i + 9, j + 10, k + 16, Blocks.air);
		world.setBlock(i + 9, j + 10, k + 17, Blocks.air);
		world.setBlock(i + 9, j + 10, k + 18, Blocks.air);
		world.setBlock(i + 9, j + 10, k + 19, Blocks.air);
		world.setBlock(i + 9, j + 10, k + 20, Blocks.air);
		world.setBlock(i + 9, j + 10, k + 21, Blocks.air);
		world.setBlock(i + 9, j + 10, k + 22, Blocks.air);
		world.setBlock(i + 9, j + 10, k + 23, Blocks.stone);
		world.setBlock(i + 9, j + 10, k + 24, Blocks.stone);
		world.setBlock(i + 9, j + 10, k + 25, Blocks.stone);
		world.setBlock(i + 9, j + 10, k + 26, Blocks.stone);
		world.setBlock(i + 9, j + 11, k + 14, Blocks.stone);
		world.setBlock(i + 9, j + 11, k + 15, Blocks.stone);
		world.setBlock(i + 9, j + 11, k + 16, Blocks.stone);
		world.setBlock(i + 9, j + 11, k + 17, Blocks.air);
		world.setBlock(i + 9, j + 11, k + 18, Blocks.air);
		world.setBlock(i + 9, j + 11, k + 19, Blocks.air);
		world.setBlock(i + 9, j + 11, k + 20, Blocks.air);
		world.setBlock(i + 9, j + 11, k + 21, Blocks.stone);
		world.setBlock(i + 9, j + 11, k + 22, Blocks.stone);
		world.setBlock(i + 9, j + 11, k + 23, Blocks.stone);
		world.setBlock(i + 9, j + 12, k + 16, Blocks.stone);
		world.setBlock(i + 9, j + 12, k + 17, Blocks.stone);
		world.setBlock(i + 9, j + 12, k + 18, Blocks.stone);
		world.setBlock(i + 9, j + 12, k + 19, Blocks.stone);
		world.setBlock(i + 9, j + 12, k + 20, Blocks.stone);
		world.setBlock(i + 9, j + 12, k + 21, Blocks.stone);
		world.setBlock(i + 10, j + 4, k + 11, Blocks.stone);
		world.setBlock(i + 10, j + 4, k + 12, Blocks.stone);
		world.setBlock(i + 10, j + 4, k + 13, Blocks.stone);
		world.setBlock(i + 10, j + 4, k + 14, Blocks.stone);
		world.setBlock(i + 10, j + 4, k + 15, Blocks.stone);
		world.setBlock(i + 10, j + 4, k + 16, Blocks.stone);
		world.setBlock(i + 10, j + 4, k + 17, Blocks.stone);
		world.setBlock(i + 10, j + 4, k + 18, Blocks.stone);
		world.setBlock(i + 10, j + 4, k + 19, Blocks.stone);
		world.setBlock(i + 10, j + 4, k + 20, Blocks.stone);
		world.setBlock(i + 10, j + 4, k + 21, Blocks.stone);
		world.setBlock(i + 10, j + 4, k + 22, Blocks.stone);
		world.setBlock(i + 10, j + 4, k + 23, Blocks.stone);
		world.setBlock(i + 10, j + 4, k + 24, Blocks.stone);
		world.setBlock(i + 10, j + 4, k + 25, Blocks.stone);
		world.setBlock(i + 10, j + 4, k + 26, Blocks.stone);
		world.setBlock(i + 10, j + 5, k + 11, Blocks.stone);
		world.setBlock(i + 10, j + 5, k + 12, Blocks.stone);
		world.setBlock(i + 10, j + 5, k + 13, Blocks.stone);
		world.setBlock(i + 10, j + 5, k + 14, Blocks.stone);
		world.setBlock(i + 10, j + 5, k + 15, Blocks.stone);
		world.setBlock(i + 10, j + 5, k + 16, Blocks.stone);
		world.setBlock(i + 10, j + 5, k + 17, Blocks.stone);
		world.setBlock(i + 10, j + 5, k + 18, Blocks.stone);
		world.setBlock(i + 10, j + 5, k + 19, Blocks.stone);
		world.setBlock(i + 10, j + 5, k + 20, Blocks.stone);
		world.setBlock(i + 10, j + 5, k + 21, Blocks.stone);
		world.setBlock(i + 10, j + 5, k + 22, Blocks.stone);
		world.setBlock(i + 10, j + 5, k + 23, Blocks.stone);
		world.setBlock(i + 10, j + 5, k + 24, Blocks.stone);
		world.setBlock(i + 10, j + 5, k + 25, Blocks.stone);
		world.setBlock(i + 10, j + 5, k + 26, Blocks.stone);
		world.setBlock(i + 10, j + 6, k + 11, Blocks.stone);
		world.setBlock(i + 10, j + 6, k + 12, Blocks.air);
		world.setBlock(i + 10, j + 6, k + 13, Blocks.air);
		world.setBlock(i + 10, j + 6, k + 14, Blocks.air);
		world.setBlock(i + 10, j + 6, k + 15, Blocks.air);
		world.setBlock(i + 10, j + 6, k + 16, Blocks.air);
		world.setBlock(i + 10, j + 6, k + 17, Blocks.air);
		world.setBlock(i + 10, j + 6, k + 18, Blocks.air);
		world.setBlock(i + 10, j + 6, k + 19, Blocks.air);
		world.setBlock(i + 10, j + 6, k + 20, Blocks.air);
		world.setBlock(i + 10, j + 6, k + 21, Blocks.air);
		world.setBlock(i + 10, j + 6, k + 22, Blocks.air);
		world.setBlock(i + 10, j + 6, k + 23, Blocks.air);
		world.setBlock(i + 10, j + 6, k + 24, Blocks.air);
		world.setBlock(i + 10, j + 6, k + 25, Blocks.air);
		world.setBlock(i + 10, j + 6, k + 26, Blocks.stone);
		world.setBlock(i + 10, j + 7, k + 11, Blocks.stone);
		world.setBlock(i + 10, j + 7, k + 12, Blocks.air);
		world.setBlock(i + 10, j + 7, k + 13, Blocks.air);
		world.setBlock(i + 10, j + 7, k + 14, Blocks.air);
		world.setBlock(i + 10, j + 7, k + 15, Blocks.air);
		world.setBlock(i + 10, j + 7, k + 16, Blocks.air);
		world.setBlock(i + 10, j + 7, k + 17, Blocks.air);
		world.setBlock(i + 10, j + 7, k + 18, Blocks.air);
		world.setBlock(i + 10, j + 7, k + 19, Blocks.air);
		world.setBlock(i + 10, j + 7, k + 20, Blocks.air);
		world.setBlock(i + 10, j + 7, k + 21, Blocks.air);
		world.setBlock(i + 10, j + 7, k + 22, Blocks.air);
		world.setBlock(i + 10, j + 7, k + 23, Blocks.air);
		world.setBlock(i + 10, j + 7, k + 24, Blocks.air);
		world.setBlock(i + 10, j + 7, k + 25, Blocks.air);
		world.setBlock(i + 10, j + 7, k + 26, Blocks.stone);
		world.setBlock(i + 10, j + 8, k + 11, Blocks.stone);
		world.setBlock(i + 10, j + 8, k + 12, Blocks.air);
		world.setBlock(i + 10, j + 8, k + 13, Blocks.air);
		world.setBlock(i + 10, j + 8, k + 14, Blocks.air);
		world.setBlock(i + 10, j + 8, k + 15, Blocks.air);
		world.setBlock(i + 10, j + 8, k + 16, Blocks.air);
		world.setBlock(i + 10, j + 8, k + 17, Blocks.air);
		world.setBlock(i + 10, j + 8, k + 18, Blocks.air);
		world.setBlock(i + 10, j + 8, k + 19, Blocks.air);
		world.setBlock(i + 10, j + 8, k + 20, Blocks.air);
		world.setBlock(i + 10, j + 8, k + 21, Blocks.air);
		world.setBlock(i + 10, j + 8, k + 22, Blocks.air);
		world.setBlock(i + 10, j + 8, k + 23, Blocks.air);
		world.setBlock(i + 10, j + 8, k + 24, Blocks.air);
		world.setBlock(i + 10, j + 8, k + 25, Blocks.air);
		world.setBlock(i + 10, j + 8, k + 26, Blocks.stone);
		world.setBlock(i + 10, j + 9, k + 11, Blocks.stone);
		world.setBlock(i + 10, j + 9, k + 12, Blocks.stone);
		world.setBlock(i + 10, j + 9, k + 13, Blocks.air);
		world.setBlock(i + 10, j + 9, k + 14, Blocks.air);
		world.setBlock(i + 10, j + 9, k + 15, Blocks.air);
		world.setBlock(i + 10, j + 9, k + 16, Blocks.air);
		world.setBlock(i + 10, j + 9, k + 17, Blocks.air);
		world.setBlock(i + 10, j + 9, k + 18, Blocks.air);
		world.setBlock(i + 10, j + 9, k + 19, Blocks.air);
		world.setBlock(i + 10, j + 9, k + 20, Blocks.air);
		world.setBlock(i + 10, j + 9, k + 21, Blocks.air);
		world.setBlock(i + 10, j + 9, k + 22, Blocks.air);
		world.setBlock(i + 10, j + 9, k + 23, Blocks.air);
		world.setBlock(i + 10, j + 9, k + 24, Blocks.air);
		world.setBlock(i + 10, j + 9, k + 25, Blocks.stone);
		world.setBlock(i + 10, j + 9, k + 26, Blocks.stone);
		world.setBlock(i + 10, j + 10, k + 12, Blocks.stone);
		world.setBlock(i + 10, j + 10, k + 13, Blocks.stone);
		world.setBlock(i + 10, j + 10, k + 14, Blocks.stone);
		world.setBlock(i + 10, j + 10, k + 15, Blocks.air);
		world.setBlock(i + 10, j + 10, k + 16, Blocks.air);
		world.setBlock(i + 10, j + 10, k + 17, Blocks.air);
		world.setBlock(i + 10, j + 10, k + 18, Blocks.air);
		world.setBlock(i + 10, j + 10, k + 19, Blocks.air);
		world.setBlock(i + 10, j + 10, k + 20, Blocks.air);
		world.setBlock(i + 10, j + 10, k + 21, Blocks.air);
		world.setBlock(i + 10, j + 10, k + 22, Blocks.air);
		world.setBlock(i + 10, j + 10, k + 23, Blocks.stone);
		world.setBlock(i + 10, j + 10, k + 24, Blocks.stone);
		world.setBlock(i + 10, j + 10, k + 25, Blocks.stone);
		world.setBlock(i + 10, j + 11, k + 14, Blocks.stone);
		world.setBlock(i + 10, j + 11, k + 15, Blocks.stone);
		world.setBlock(i + 10, j + 11, k + 16, Blocks.stone);
		world.setBlock(i + 10, j + 11, k + 17, Blocks.stone);
		world.setBlock(i + 10, j + 11, k + 18, Blocks.air);
		world.setBlock(i + 10, j + 11, k + 19, Blocks.air);
		world.setBlock(i + 10, j + 11, k + 20, Blocks.stone);
		world.setBlock(i + 10, j + 11, k + 21, Blocks.stone);
		world.setBlock(i + 10, j + 11, k + 22, Blocks.stone);
		world.setBlock(i + 10, j + 11, k + 23, Blocks.stone);
		world.setBlock(i + 10, j + 12, k + 17, Blocks.stone);
		world.setBlock(i + 10, j + 12, k + 18, Blocks.stone);
		world.setBlock(i + 10, j + 12, k + 19, Blocks.stone);
		world.setBlock(i + 10, j + 12, k + 20, Blocks.stone);
		world.setBlock(i + 11, j + 4, k + 11, Blocks.stone);
		world.setBlock(i + 11, j + 4, k + 12, Blocks.stone);
		world.setBlock(i + 11, j + 4, k + 13, Blocks.stone);
		world.setBlock(i + 11, j + 4, k + 14, Blocks.stone);
		world.setBlock(i + 11, j + 4, k + 15, Blocks.stone);
		world.setBlock(i + 11, j + 4, k + 16, Blocks.stone);
		world.setBlock(i + 11, j + 4, k + 17, Blocks.stone);
		world.setBlock(i + 11, j + 4, k + 18, Blocks.stone);
		world.setBlock(i + 11, j + 4, k + 19, Blocks.stone);
		world.setBlock(i + 11, j + 4, k + 20, Blocks.stone);
		world.setBlock(i + 11, j + 4, k + 21, Blocks.stone);
		world.setBlock(i + 11, j + 4, k + 22, Blocks.stone);
		world.setBlock(i + 11, j + 4, k + 23, Blocks.stone);
		world.setBlock(i + 11, j + 4, k + 24, Blocks.stone);
		world.setBlock(i + 11, j + 4, k + 25, Blocks.stone);
		world.setBlock(i + 11, j + 4, k + 26, Blocks.stone);
		world.setBlock(i + 11, j + 5, k + 11, Blocks.stone);
		world.setBlock(i + 11, j + 5, k + 12, Blocks.stone);
		world.setBlock(i + 11, j + 5, k + 13, Blocks.stone);
		world.setBlock(i + 11, j + 5, k + 14, Blocks.stone);
		world.setBlock(i + 11, j + 5, k + 15, Blocks.stone);
		world.setBlock(i + 11, j + 5, k + 16, Blocks.stone);
		world.setBlock(i + 11, j + 5, k + 17, Blocks.stone);
		world.setBlock(i + 11, j + 5, k + 18, Blocks.stone);
		world.setBlock(i + 11, j + 5, k + 19, Blocks.stone);
		world.setBlock(i + 11, j + 5, k + 20, Blocks.stone);
		world.setBlock(i + 11, j + 5, k + 21, Blocks.stone);
		world.setBlock(i + 11, j + 5, k + 22, Blocks.stone);
		world.setBlock(i + 11, j + 5, k + 23, Blocks.stone);
		world.setBlock(i + 11, j + 5, k + 24, Blocks.stone);
		world.setBlock(i + 11, j + 5, k + 25, Blocks.stone);
		world.setBlock(i + 11, j + 5, k + 26, Blocks.stone);
		world.setBlock(i + 11, j + 6, k + 11, Blocks.stone);
		world.setBlock(i + 11, j + 6, k + 12, Blocks.air);
		world.setBlock(i + 11, j + 6, k + 13, Blocks.air);
		world.setBlock(i + 11, j + 6, k + 14, Blocks.air);
		world.setBlock(i + 11, j + 6, k + 15, Blocks.air);
		world.setBlock(i + 11, j + 6, k + 16, Blocks.air);
		world.setBlock(i + 11, j + 6, k + 17, Blocks.air);
		world.setBlock(i + 11, j + 6, k + 18, Blocks.air);
		world.setBlock(i + 11, j + 6, k + 19, Blocks.air);
		world.setBlock(i + 11, j + 6, k + 20, Blocks.air);
		world.setBlock(i + 11, j + 6, k + 21, Blocks.air);
		world.setBlock(i + 11, j + 6, k + 22, Blocks.air);
		world.setBlock(i + 11, j + 6, k + 23, Blocks.air);
		world.setBlock(i + 11, j + 6, k + 24, Blocks.air);
		world.setBlock(i + 11, j + 6, k + 25, Blocks.air);
		world.setBlock(i + 11, j + 6, k + 26, Blocks.stone);
		world.setBlock(i + 11, j + 7, k + 11, Blocks.stone);
		world.setBlock(i + 11, j + 7, k + 12, Blocks.air);
		world.setBlock(i + 11, j + 7, k + 13, Blocks.air);
		world.setBlock(i + 11, j + 7, k + 14, Blocks.air);
		world.setBlock(i + 11, j + 7, k + 15, Blocks.air);
		world.setBlock(i + 11, j + 7, k + 16, Blocks.air);
		world.setBlock(i + 11, j + 7, k + 17, Blocks.air);
		world.setBlock(i + 11, j + 7, k + 18, Blocks.air);
		world.setBlock(i + 11, j + 7, k + 19, Blocks.air);
		world.setBlock(i + 11, j + 7, k + 20, Blocks.air);
		world.setBlock(i + 11, j + 7, k + 21, Blocks.air);
		world.setBlock(i + 11, j + 7, k + 22, Blocks.air);
		world.setBlock(i + 11, j + 7, k + 23, Blocks.air);
		world.setBlock(i + 11, j + 7, k + 24, Blocks.air);
		world.setBlock(i + 11, j + 7, k + 25, Blocks.air);
		world.setBlock(i + 11, j + 7, k + 26, Blocks.stone);
		world.setBlock(i + 11, j + 8, k + 11, Blocks.stone);
		world.setBlock(i + 11, j + 8, k + 12, Blocks.air);
		world.setBlock(i + 11, j + 8, k + 13, Blocks.air);
		world.setBlock(i + 11, j + 8, k + 14, Blocks.air);
		world.setBlock(i + 11, j + 8, k + 15, Blocks.air);
		world.setBlock(i + 11, j + 8, k + 16, Blocks.air);
		world.setBlock(i + 11, j + 8, k + 17, Blocks.air);
		world.setBlock(i + 11, j + 8, k + 18, Blocks.air);
		world.setBlock(i + 11, j + 8, k + 19, Blocks.air);
		world.setBlock(i + 11, j + 8, k + 20, Blocks.air);
		world.setBlock(i + 11, j + 8, k + 21, Blocks.air);
		world.setBlock(i + 11, j + 8, k + 22, Blocks.air);
		world.setBlock(i + 11, j + 8, k + 23, Blocks.air);
		world.setBlock(i + 11, j + 8, k + 24, Blocks.air);
		world.setBlock(i + 11, j + 8, k + 25, Blocks.air);
		world.setBlock(i + 11, j + 8, k + 26, Blocks.stone);
		world.setBlock(i + 11, j + 9, k + 11, Blocks.stone);
		world.setBlock(i + 11, j + 9, k + 12, Blocks.stone);
		world.setBlock(i + 11, j + 9, k + 13, Blocks.stone);
		world.setBlock(i + 11, j + 9, k + 14, Blocks.air);
		world.setBlock(i + 11, j + 9, k + 15, Blocks.air);
		world.setBlock(i + 11, j + 9, k + 16, Blocks.air);
		world.setBlock(i + 11, j + 9, k + 17, Blocks.air);
		world.setBlock(i + 11, j + 9, k + 18, Blocks.air);
		world.setBlock(i + 11, j + 9, k + 19, Blocks.air);
		world.setBlock(i + 11, j + 9, k + 20, Blocks.air);
		world.setBlock(i + 11, j + 9, k + 21, Blocks.air);
		world.setBlock(i + 11, j + 9, k + 22, Blocks.air);
		world.setBlock(i + 11, j + 9, k + 23, Blocks.air);
		world.setBlock(i + 11, j + 9, k + 24, Blocks.air);
		world.setBlock(i + 11, j + 9, k + 25, Blocks.stone);
		world.setBlock(i + 11, j + 9, k + 26, Blocks.stone);
		world.setBlock(i + 11, j + 10, k + 13, Blocks.stone);
		world.setBlock(i + 11, j + 10, k + 14, Blocks.stone);
		world.setBlock(i + 11, j + 10, k + 15, Blocks.stone);
		world.setBlock(i + 11, j + 10, k + 16, Blocks.air);
		world.setBlock(i + 11, j + 10, k + 17, Blocks.air);
		world.setBlock(i + 11, j + 10, k + 18, Blocks.air);
		world.setBlock(i + 11, j + 10, k + 19, Blocks.air);
		world.setBlock(i + 11, j + 10, k + 20, Blocks.air);
		world.setBlock(i + 11, j + 10, k + 21, Blocks.air);
		world.setBlock(i + 11, j + 10, k + 22, Blocks.stone);
		world.setBlock(i + 11, j + 10, k + 23, Blocks.stone);
		world.setBlock(i + 11, j + 10, k + 24, Blocks.stone);
		world.setBlock(i + 11, j + 10, k + 25, Blocks.stone);
		world.setBlock(i + 11, j + 11, k + 15, Blocks.stone);
		world.setBlock(i + 11, j + 11, k + 16, Blocks.stone);
		world.setBlock(i + 11, j + 11, k + 17, Blocks.stone);
		world.setBlock(i + 11, j + 11, k + 18, Blocks.stone);
		world.setBlock(i + 11, j + 11, k + 19, Blocks.stone);
		world.setBlock(i + 11, j + 11, k + 20, Blocks.stone);
		world.setBlock(i + 11, j + 11, k + 21, Blocks.stone);
		world.setBlock(i + 11, j + 11, k + 22, Blocks.stone);
		world.setBlock(i + 11, j + 12, k + 18, Blocks.stone);
		world.setBlock(i + 11, j + 12, k + 19, Blocks.stone);
		world.setBlock(i + 12, j + 4, k + 12, Blocks.stone);
		world.setBlock(i + 12, j + 4, k + 13, Blocks.stone);
		world.setBlock(i + 12, j + 4, k + 14, Blocks.stone);
		world.setBlock(i + 12, j + 4, k + 15, Blocks.stone);
		world.setBlock(i + 12, j + 4, k + 16, Blocks.stone);
		world.setBlock(i + 12, j + 4, k + 17, Blocks.stone);
		world.setBlock(i + 12, j + 4, k + 18, Blocks.stone);
		world.setBlock(i + 12, j + 4, k + 19, Blocks.stone);
		world.setBlock(i + 12, j + 4, k + 20, Blocks.stone);
		world.setBlock(i + 12, j + 4, k + 21, Blocks.stone);
		world.setBlock(i + 12, j + 4, k + 22, Blocks.stone);
		world.setBlock(i + 12, j + 4, k + 23, Blocks.stone);
		world.setBlock(i + 12, j + 4, k + 24, Blocks.stone);
		world.setBlock(i + 12, j + 4, k + 25, Blocks.stone);
		world.setBlock(i + 12, j + 5, k + 12, Blocks.stone);
		world.setBlock(i + 12, j + 5, k + 13, Blocks.stone);
		world.setBlock(i + 12, j + 5, k + 14, Blocks.stone);
		world.setBlock(i + 12, j + 5, k + 15, Blocks.stone);
		world.setBlock(i + 12, j + 5, k + 16, Blocks.stone);
		world.setBlock(i + 12, j + 5, k + 17, Blocks.stone);
		world.setBlock(i + 12, j + 5, k + 18, Blocks.stone);
		world.setBlock(i + 12, j + 5, k + 19, Blocks.stone);
		world.setBlock(i + 12, j + 5, k + 20, Blocks.stone);
		world.setBlock(i + 12, j + 5, k + 21, Blocks.stone);
		world.setBlock(i + 12, j + 5, k + 22, Blocks.stone);
		world.setBlock(i + 12, j + 5, k + 23, Blocks.stone);
		world.setBlock(i + 12, j + 5, k + 24, Blocks.stone);
		world.setBlock(i + 12, j + 5, k + 25, Blocks.stone);
		world.setBlock(i + 12, j + 6, k + 12, Blocks.stone);
		world.setBlock(i + 12, j + 6, k + 13, Blocks.stone);
		world.setBlock(i + 12, j + 6, k + 14, Blocks.air);
		world.setBlock(i + 12, j + 6, k + 15, Blocks.air);
		world.setBlock(i + 12, j + 6, k + 16, Blocks.air);
		world.setBlock(i + 12, j + 6, k + 17, Blocks.air);
		world.setBlock(i + 12, j + 6, k + 18, Blocks.air);
		world.setBlock(i + 12, j + 6, k + 19, Blocks.air);
		world.setBlock(i + 12, j + 6, k + 20, Blocks.air);
		world.setBlock(i + 12, j + 6, k + 21, Blocks.air);
		world.setBlock(i + 12, j + 6, k + 22, Blocks.air);
		world.setBlock(i + 12, j + 6, k + 23, Blocks.air);
		world.setBlock(i + 12, j + 6, k + 24, Blocks.air);
		world.setBlock(i + 12, j + 6, k + 25, Blocks.stone);
		world.setBlock(i + 12, j + 7, k + 12, Blocks.stone);
		world.setBlock(i + 12, j + 7, k + 13, Blocks.stone);
		world.setBlock(i + 12, j + 7, k + 14, Blocks.air);
		world.setBlock(i + 12, j + 7, k + 15, Blocks.air);
		world.setBlock(i + 12, j + 7, k + 16, Blocks.air);
		world.setBlock(i + 12, j + 7, k + 17, Blocks.air);
		world.setBlock(i + 12, j + 7, k + 18, Blocks.air);
		world.setBlock(i + 12, j + 7, k + 19, Blocks.air);
		world.setBlock(i + 12, j + 7, k + 20, Blocks.air);
		world.setBlock(i + 12, j + 7, k + 21, Blocks.air);
		world.setBlock(i + 12, j + 7, k + 22, Blocks.air);
		world.setBlock(i + 12, j + 7, k + 23, Blocks.air);
		world.setBlock(i + 12, j + 7, k + 24, Blocks.air);
		world.setBlock(i + 12, j + 7, k + 25, Blocks.stone);
		world.setBlock(i + 12, j + 8, k + 12, Blocks.stone);
		world.setBlock(i + 12, j + 8, k + 13, Blocks.stone);
		world.setBlock(i + 12, j + 8, k + 14, Blocks.air);
		world.setBlock(i + 12, j + 8, k + 15, Blocks.air);
		world.setBlock(i + 12, j + 8, k + 16, Blocks.air);
		world.setBlock(i + 12, j + 8, k + 17, Blocks.air);
		world.setBlock(i + 12, j + 8, k + 18, Blocks.air);
		world.setBlock(i + 12, j + 8, k + 19, Blocks.air);
		world.setBlock(i + 12, j + 8, k + 20, Blocks.air);
		world.setBlock(i + 12, j + 8, k + 21, Blocks.air);
		world.setBlock(i + 12, j + 8, k + 22, Blocks.air);
		world.setBlock(i + 12, j + 8, k + 23, Blocks.air);
		world.setBlock(i + 12, j + 8, k + 24, Blocks.air);
		world.setBlock(i + 12, j + 8, k + 25, Blocks.stone);
		world.setBlock(i + 12, j + 9, k + 12, Blocks.stone);
		world.setBlock(i + 12, j + 9, k + 13, Blocks.stone);
		world.setBlock(i + 12, j + 9, k + 14, Blocks.stone);
		world.setBlock(i + 12, j + 9, k + 15, Blocks.air);
		world.setBlock(i + 12, j + 9, k + 16, Blocks.air);
		world.setBlock(i + 12, j + 9, k + 17, Blocks.air);
		world.setBlock(i + 12, j + 9, k + 18, Blocks.air);
		world.setBlock(i + 12, j + 9, k + 19, Blocks.air);
		world.setBlock(i + 12, j + 9, k + 20, Blocks.air);
		world.setBlock(i + 12, j + 9, k + 21, Blocks.air);
		world.setBlock(i + 12, j + 9, k + 22, Blocks.air);
		world.setBlock(i + 12, j + 9, k + 23, Blocks.stone);
		world.setBlock(i + 12, j + 9, k + 24, Blocks.stone);
		world.setBlock(i + 12, j + 9, k + 25, Blocks.stone);
		world.setBlock(i + 12, j + 10, k + 14, Blocks.stone);
		world.setBlock(i + 12, j + 10, k + 15, Blocks.stone);
		world.setBlock(i + 12, j + 10, k + 16, Blocks.stone);
		world.setBlock(i + 12, j + 10, k + 17, Blocks.air);
		world.setBlock(i + 12, j + 10, k + 18, Blocks.air);
		world.setBlock(i + 12, j + 10, k + 19, Blocks.air);
		world.setBlock(i + 12, j + 10, k + 20, Blocks.air);
		world.setBlock(i + 12, j + 10, k + 21, Blocks.stone);
		world.setBlock(i + 12, j + 10, k + 22, Blocks.stone);
		world.setBlock(i + 12, j + 10, k + 23, Blocks.stone);
		world.setBlock(i + 12, j + 10, k + 24, Blocks.stone);
		world.setBlock(i + 12, j + 11, k + 16, Blocks.stone);
		world.setBlock(i + 12, j + 11, k + 17, Blocks.stone);
		world.setBlock(i + 12, j + 11, k + 18, Blocks.stone);
		world.setBlock(i + 12, j + 11, k + 19, Blocks.stone);
		world.setBlock(i + 12, j + 11, k + 20, Blocks.stone);
		world.setBlock(i + 12, j + 11, k + 21, Blocks.stone);
		world.setBlock(i + 13, j + 4, k + 14, Blocks.stone);
		world.setBlock(i + 13, j + 4, k + 15, Blocks.stone);
		world.setBlock(i + 13, j + 4, k + 16, Blocks.stone);
		world.setBlock(i + 13, j + 4, k + 17, Blocks.stone);
		world.setBlock(i + 13, j + 4, k + 18, Blocks.stone);
		world.setBlock(i + 13, j + 4, k + 19, Blocks.stone);
		world.setBlock(i + 13, j + 4, k + 20, Blocks.stone);
		world.setBlock(i + 13, j + 4, k + 21, Blocks.stone);
		world.setBlock(i + 13, j + 4, k + 22, Blocks.stone);
		world.setBlock(i + 13, j + 4, k + 23, Blocks.stone);
		world.setBlock(i + 13, j + 4, k + 24, Blocks.stone);
		world.setBlock(i + 13, j + 5, k + 14, Blocks.stone);
		world.setBlock(i + 13, j + 5, k + 15, Blocks.stone);
		world.setBlock(i + 13, j + 5, k + 16, Blocks.stone);
		world.setBlock(i + 13, j + 5, k + 17, Blocks.stone);
		world.setBlock(i + 13, j + 5, k + 18, Blocks.stone);
		world.setBlock(i + 13, j + 5, k + 19, Blocks.stone);
		world.setBlock(i + 13, j + 5, k + 20, Blocks.stone);
		world.setBlock(i + 13, j + 5, k + 21, Blocks.stone);
		world.setBlock(i + 13, j + 5, k + 22, Blocks.stone);
		world.setBlock(i + 13, j + 5, k + 23, Blocks.stone);
		world.setBlock(i + 13, j + 5, k + 24, Blocks.stone);
		world.setBlock(i + 13, j + 6, k + 14, Blocks.stone);
		world.setBlock(i + 13, j + 6, k + 15, Blocks.air);
		world.setBlock(i + 13, j + 6, k + 16, Blocks.air);
		world.setBlock(i + 13, j + 6, k + 17, Blocks.air);
		world.setBlock(i + 13, j + 6, k + 18, Blocks.air);
		world.setBlock(i + 13, j + 6, k + 19, Blocks.air);
		world.setBlock(i + 13, j + 6, k + 20, Blocks.air);
		world.setBlock(i + 13, j + 6, k + 21, Blocks.air);
		world.setBlock(i + 13, j + 6, k + 22, Blocks.air);
		world.setBlock(i + 13, j + 6, k + 23, Blocks.stone);
		world.setBlock(i + 13, j + 6, k + 24, Blocks.stone);
		world.setBlock(i + 13, j + 7, k + 14, Blocks.stone);
		world.setBlock(i + 13, j + 7, k + 15, Blocks.air);
		world.setBlock(i + 13, j + 7, k + 16, Blocks.air);
		world.setBlock(i + 13, j + 7, k + 17, Blocks.air);
		world.setBlock(i + 13, j + 7, k + 18, Blocks.air);
		world.setBlock(i + 13, j + 7, k + 19, Blocks.air);
		world.setBlock(i + 13, j + 7, k + 20, Blocks.air);
		world.setBlock(i + 13, j + 7, k + 21, Blocks.air);
		world.setBlock(i + 13, j + 7, k + 22, Blocks.air);
		world.setBlock(i + 13, j + 7, k + 23, Blocks.stone);
		world.setBlock(i + 13, j + 7, k + 24, Blocks.stone);
		world.setBlock(i + 13, j + 8, k + 14, Blocks.stone);
		world.setBlock(i + 13, j + 8, k + 15, Blocks.air);
		world.setBlock(i + 13, j + 8, k + 16, Blocks.air);
		world.setBlock(i + 13, j + 8, k + 17, Blocks.air);
		world.setBlock(i + 13, j + 8, k + 18, Blocks.air);
		world.setBlock(i + 13, j + 8, k + 19, Blocks.air);
		world.setBlock(i + 13, j + 8, k + 20, Blocks.air);
		world.setBlock(i + 13, j + 8, k + 21, Blocks.air);
		world.setBlock(i + 13, j + 8, k + 22, Blocks.air);
		world.setBlock(i + 13, j + 8, k + 23, Blocks.stone);
		world.setBlock(i + 13, j + 8, k + 24, Blocks.stone);
		world.setBlock(i + 13, j + 9, k + 14, Blocks.stone);
		world.setBlock(i + 13, j + 9, k + 15, Blocks.stone);
		world.setBlock(i + 13, j + 9, k + 16, Blocks.air);
		world.setBlock(i + 13, j + 9, k + 17, Blocks.air);
		world.setBlock(i + 13, j + 9, k + 18, Blocks.air);
		world.setBlock(i + 13, j + 9, k + 19, Blocks.air);
		world.setBlock(i + 13, j + 9, k + 20, Blocks.air);
		world.setBlock(i + 13, j + 9, k + 21, Blocks.air);
		world.setBlock(i + 13, j + 9, k + 22, Blocks.stone);
		world.setBlock(i + 13, j + 9, k + 23, Blocks.stone);
		world.setBlock(i + 13, j + 9, k + 24, Blocks.stone);
		world.setBlock(i + 13, j + 10, k + 15, Blocks.stone);
		world.setBlock(i + 13, j + 10, k + 16, Blocks.stone);
		world.setBlock(i + 13, j + 10, k + 17, Blocks.stone);
		world.setBlock(i + 13, j + 10, k + 18, Blocks.air);
		world.setBlock(i + 13, j + 10, k + 19, Blocks.air);
		world.setBlock(i + 13, j + 10, k + 20, Blocks.stone);
		world.setBlock(i + 13, j + 10, k + 21, Blocks.stone);
		world.setBlock(i + 13, j + 10, k + 22, Blocks.stone);
		world.setBlock(i + 13, j + 11, k + 17, Blocks.stone);
		world.setBlock(i + 13, j + 11, k + 18, Blocks.stone);
		world.setBlock(i + 13, j + 11, k + 19, Blocks.stone);
		world.setBlock(i + 13, j + 11, k + 20, Blocks.stone);
		world.setBlock(i + 14, j + 4, k + 15, Blocks.stone);
		world.setBlock(i + 14, j + 4, k + 16, Blocks.stone);
		world.setBlock(i + 14, j + 4, k + 17, Blocks.stone);
		world.setBlock(i + 14, j + 4, k + 18, Blocks.stone);
		world.setBlock(i + 14, j + 4, k + 19, Blocks.stone);
		world.setBlock(i + 14, j + 4, k + 20, Blocks.stone);
		world.setBlock(i + 14, j + 4, k + 21, Blocks.stone);
		world.setBlock(i + 14, j + 4, k + 22, Blocks.stone);
		world.setBlock(i + 14, j + 5, k + 15, Blocks.stone);
		world.setBlock(i + 14, j + 5, k + 16, Blocks.stone);
		world.setBlock(i + 14, j + 5, k + 17, Blocks.stone);
		world.setBlock(i + 14, j + 5, k + 18, Blocks.stone);
		world.setBlock(i + 14, j + 5, k + 19, Blocks.stone);
		world.setBlock(i + 14, j + 5, k + 20, Blocks.stone);
		world.setBlock(i + 14, j + 5, k + 21, Blocks.stone);
		world.setBlock(i + 14, j + 5, k + 22, Blocks.stone);
		world.setBlock(i + 14, j + 6, k + 15, Blocks.stone);
		world.setBlock(i + 14, j + 6, k + 16, Blocks.air);
		world.setBlock(i + 14, j + 6, k + 17, Blocks.air);
		world.setBlock(i + 14, j + 6, k + 18, Blocks.air);
		world.setBlock(i + 14, j + 6, k + 19, Blocks.air);
		world.setBlock(i + 14, j + 6, k + 20, Blocks.air);
		world.setBlock(i + 14, j + 6, k + 21, Blocks.air);
		world.setBlock(i + 14, j + 6, k + 22, Blocks.stone);
		world.setBlock(i + 14, j + 7, k + 15, Blocks.stone);
		world.setBlock(i + 14, j + 7, k + 16, Blocks.air);
		world.setBlock(i + 14, j + 7, k + 17, Blocks.air);
		world.setBlock(i + 14, j + 7, k + 18, Blocks.air);
		world.setBlock(i + 14, j + 7, k + 19, Blocks.air);
		world.setBlock(i + 14, j + 7, k + 20, Blocks.air);
		world.setBlock(i + 14, j + 7, k + 21, Blocks.air);
		world.setBlock(i + 14, j + 7, k + 22, Blocks.stone);
		world.setBlock(i + 14, j + 8, k + 15, Blocks.stone);
		world.setBlock(i + 14, j + 8, k + 16, Blocks.air);
		world.setBlock(i + 14, j + 8, k + 17, Blocks.air);
		world.setBlock(i + 14, j + 8, k + 18, Blocks.air);
		world.setBlock(i + 14, j + 8, k + 19, Blocks.air);
		world.setBlock(i + 14, j + 8, k + 20, Blocks.air);
		world.setBlock(i + 14, j + 8, k + 21, Blocks.air);
		world.setBlock(i + 14, j + 8, k + 22, Blocks.stone);
		world.setBlock(i + 14, j + 9, k + 15, Blocks.stone);
		world.setBlock(i + 14, j + 9, k + 16, Blocks.stone);
		world.setBlock(i + 14, j + 9, k + 17, Blocks.air);
		world.setBlock(i + 14, j + 9, k + 18, Blocks.air);
		world.setBlock(i + 14, j + 9, k + 19, Blocks.air);
		world.setBlock(i + 14, j + 9, k + 20, Blocks.air);
		world.setBlock(i + 14, j + 9, k + 21, Blocks.stone);
		world.setBlock(i + 14, j + 9, k + 22, Blocks.stone);
		world.setBlock(i + 14, j + 10, k + 16, Blocks.stone);

		generate2(world, rand, i, j, k);
		return true;
	}

	public boolean generate2(World world, Random rand, int i, int j, int k) {
		world.setBlock(i + 14, j + 10, k + 17, Blocks.stone);
		world.setBlock(i + 14, j + 10, k + 18, Blocks.air);
		world.setBlock(i + 14, j + 10, k + 19, Blocks.air);
		world.setBlock(i + 14, j + 10, k + 20, Blocks.stone);
		world.setBlock(i + 14, j + 10, k + 21, Blocks.stone);
		world.setBlock(i + 14, j + 11, k + 17, Blocks.stone);
		world.setBlock(i + 14, j + 11, k + 18, Blocks.stone);
		world.setBlock(i + 14, j + 11, k + 19, Blocks.stone);
		world.setBlock(i + 14, j + 11, k + 20, Blocks.stone);
		world.setBlock(i + 15, j + 4, k + 16, Blocks.stone);
		world.setBlock(i + 15, j + 4, k + 17, Blocks.stone);
		world.setBlock(i + 15, j + 4, k + 18, Blocks.stone);
		world.setBlock(i + 15, j + 4, k + 19, Blocks.stone);
		world.setBlock(i + 15, j + 4, k + 20, Blocks.stone);
		world.setBlock(i + 15, j + 4, k + 21, Blocks.stone);
		world.setBlock(i + 15, j + 5, k + 16, Blocks.stone);
		world.setBlock(i + 15, j + 5, k + 17, Blocks.stone);
		world.setBlock(i + 15, j + 5, k + 18, Blocks.stone);
		world.setBlock(i + 15, j + 5, k + 19, Blocks.stone);
		world.setBlock(i + 15, j + 5, k + 20, Blocks.stone);
		world.setBlock(i + 15, j + 5, k + 21, Blocks.stone);
		world.setBlock(i + 15, j + 6, k + 16, Blocks.stone);
		world.setBlock(i + 15, j + 6, k + 17, Blocks.air);
		world.setBlock(i + 15, j + 6, k + 18, Blocks.air);
		world.setBlock(i + 15, j + 6, k + 19, Blocks.air);
		world.setBlock(i + 15, j + 6, k + 20, Blocks.air);
		world.setBlock(i + 15, j + 6, k + 21, Blocks.stone);
		world.setBlock(i + 15, j + 7, k + 16, Blocks.stone);
		world.setBlock(i + 15, j + 7, k + 17, Blocks.air);
		world.setBlock(i + 15, j + 7, k + 18, Blocks.air);
		world.setBlock(i + 15, j + 7, k + 19, Blocks.air);
		world.setBlock(i + 15, j + 7, k + 20, Blocks.air);
		world.setBlock(i + 15, j + 7, k + 21, Blocks.stone);
		world.setBlock(i + 15, j + 8, k + 16, Blocks.stone);
		world.setBlock(i + 15, j + 8, k + 21, Blocks.stone);
		world.setBlock(i + 15, j + 9, k + 16, Blocks.stone);
		world.setBlock(i + 15, j + 9, k + 17, Blocks.air);
		world.setBlock(i + 15, j + 9, k + 18, Blocks.air);
		world.setBlock(i + 15, j + 9, k + 19, Blocks.air);
		world.setBlock(i + 15, j + 9, k + 20, Blocks.air);
		world.setBlock(i + 15, j + 9, k + 21, Blocks.stone);
		world.setBlock(i + 15, j + 10, k + 16, Blocks.stone);
		world.setBlock(i + 15, j + 10, k + 17, Blocks.stone);
		world.setBlock(i + 15, j + 10, k + 18, Blocks.stone);
		world.setBlock(i + 15, j + 10, k + 19, Blocks.stone);
		world.setBlock(i + 15, j + 10, k + 20, Blocks.stone);
		world.setBlock(i + 15, j + 10, k + 21, Blocks.stone);
		world.setBlock(i + 15, j + 11, k + 17, Blocks.stone);
		world.setBlock(i + 15, j + 11, k + 18, Blocks.stone);
		world.setBlock(i + 15, j + 11, k + 19, Blocks.stone);
		world.setBlock(i + 15, j + 11, k + 20, Blocks.stone);
		world.setBlock(i + 16, j + 4, k + 16, Blocks.stone);
		world.setBlock(i + 16, j + 4, k + 17, Blocks.stone);
		world.setBlock(i + 16, j + 4, k + 18, Blocks.stone);
		world.setBlock(i + 16, j + 4, k + 19, Blocks.stone);
		world.setBlock(i + 16, j + 4, k + 20, Blocks.stone);
		world.setBlock(i + 16, j + 4, k + 21, Blocks.stone);
		world.setBlock(i + 16, j + 5, k + 16, Blocks.stone);
		world.setBlock(i + 16, j + 5, k + 17, Blocks.stone);
		world.setBlock(i + 16, j + 5, k + 18, Blocks.stone);
		world.setBlock(i + 16, j + 5, k + 19, Blocks.stone);
		world.setBlock(i + 16, j + 5, k + 20, Blocks.stone);
		world.setBlock(i + 16, j + 5, k + 21, Blocks.stone);
		world.setBlock(i + 16, j + 6, k + 16, Blocks.stone);
		world.setBlock(i + 16, j + 6, k + 21, Blocks.stone);
		world.setBlock(i + 16, j + 7, k + 16, Blocks.stone);
		world.setBlock(i + 16, j + 7, k + 21, Blocks.stone);
		world.setBlock(i + 16, j + 8, k + 16, Blocks.stone);
		world.setBlock(i + 16, j + 8, k + 17, Blocks.stone);
		world.setBlock(i + 16, j + 8, k + 18, Blocks.stone);
		world.setBlock(i + 16, j + 8, k + 19, Blocks.stone);
		world.setBlock(i + 16, j + 8, k + 20, Blocks.stone);
		world.setBlock(i + 16, j + 8, k + 21, Blocks.stone);
		world.setBlock(i + 16, j + 9, k + 16, Blocks.stone);
		world.setBlock(i + 16, j + 9, k + 17, Blocks.stone);
		world.setBlock(i + 16, j + 9, k + 18, Blocks.stone);
		world.setBlock(i + 16, j + 9, k + 19, Blocks.stone);
		world.setBlock(i + 16, j + 9, k + 20, Blocks.stone);
		world.setBlock(i + 16, j + 9, k + 21, Blocks.stone);
		world.setBlock(i + 16, j + 10, k + 16, Blocks.stone);
		world.setBlock(i + 16, j + 10, k + 17, Blocks.stone);
		world.setBlock(i + 16, j + 10, k + 18, Blocks.stone);
		world.setBlock(i + 16, j + 10, k + 19, Blocks.stone);
		world.setBlock(i + 16, j + 10, k + 20, Blocks.stone);
		world.setBlock(i + 16, j + 10, k + 21, Blocks.stone);
		world.setBlock(i + 17, j + 4, k + 16, Blocks.stone);
		world.setBlock(i + 17, j + 4, k + 17, Blocks.stone);
		world.setBlock(i + 17, j + 4, k + 18, Blocks.stone);
		world.setBlock(i + 17, j + 4, k + 19, Blocks.stone);
		world.setBlock(i + 17, j + 4, k + 20, Blocks.stone);
		world.setBlock(i + 17, j + 4, k + 21, Blocks.stone);
		world.setBlock(i + 17, j + 5, k + 16, Blocks.stone);
		world.setBlock(i + 17, j + 5, k + 17, Blocks.stone);
		world.setBlock(i + 17, j + 5, k + 18, Blocks.stone);
		world.setBlock(i + 17, j + 5, k + 19, Blocks.stone);
		world.setBlock(i + 17, j + 5, k + 20, Blocks.stone);
		world.setBlock(i + 17, j + 5, k + 21, Blocks.stone);
		world.setBlock(i + 17, j + 6, k + 16, Blocks.stone);
		world.setBlock(i + 17, j + 6, k + 17, Blocks.air);
		world.setBlock(i + 17, j + 6, k + 18, Blocks.air);
		world.setBlock(i + 17, j + 6, k + 19, Blocks.air);
		world.setBlock(i + 17, j + 6, k + 20, Blocks.air);
		world.setBlock(i + 17, j + 6, k + 21, Blocks.stone);
		world.setBlock(i + 17, j + 7, k + 16, Blocks.stone);
		world.setBlock(i + 17, j + 7, k + 17, Blocks.air);
		world.setBlock(i + 17, j + 7, k + 18, Blocks.air);
		world.setBlock(i + 17, j + 7, k + 19, Blocks.air);
		world.setBlock(i + 17, j + 7, k + 20, Blocks.air);
		world.setBlock(i + 17, j + 7, k + 21, Blocks.stone);
		world.setBlock(i + 17, j + 8, k + 16, Blocks.stone);
		world.setBlock(i + 17, j + 8, k + 21, Blocks.stone);
		world.setBlock(i + 17, j + 9, k + 16, Blocks.stone);
		world.setBlock(i + 17, j + 9, k + 17, Blocks.stone);
		world.setBlock(i + 17, j + 9, k + 18, Blocks.air);
		world.setBlock(i + 17, j + 9, k + 19, Blocks.air);
		world.setBlock(i + 17, j + 9, k + 20, Blocks.stone);
		world.setBlock(i + 17, j + 9, k + 21, Blocks.stone);
		world.setBlock(i + 17, j + 10, k + 17, Blocks.stone);
		world.setBlock(i + 17, j + 10, k + 18, Blocks.stone);
		world.setBlock(i + 17, j + 10, k + 19, Blocks.stone);
		world.setBlock(i + 17, j + 10, k + 20, Blocks.stone);
		world.setBlock(i + 18, j + 4, k + 16, Blocks.stone);
		world.setBlock(i + 18, j + 4, k + 17, Blocks.stone);
		world.setBlock(i + 18, j + 4, k + 18, Blocks.stone);
		world.setBlock(i + 18, j + 4, k + 19, Blocks.stone);
		world.setBlock(i + 18, j + 4, k + 20, Blocks.stone);
		world.setBlock(i + 18, j + 4, k + 21, Blocks.stone);
		world.setBlock(i + 18, j + 5, k + 16, Blocks.stone);
		world.setBlock(i + 18, j + 5, k + 17, Blocks.stone);
		world.setBlock(i + 18, j + 5, k + 18, Blocks.stone);
		world.setBlock(i + 18, j + 5, k + 19, Blocks.stone);
		world.setBlock(i + 18, j + 5, k + 20, Blocks.stone);
		world.setBlock(i + 18, j + 5, k + 21, Blocks.stone);
		world.setBlock(i + 18, j + 6, k + 16, Blocks.stone);
		world.setBlock(i + 18, j + 6, k + 17, Blocks.air);
		world.setBlock(i + 18, j + 6, k + 18, Blocks.air);
		world.setBlock(i + 18, j + 6, k + 19, Blocks.air);
		world.setBlock(i + 18, j + 6, k + 20, Blocks.air);
		world.setBlock(i + 18, j + 6, k + 21, Blocks.stone);
		world.setBlock(i + 18, j + 7, k + 16, Blocks.stone);
		world.setBlock(i + 18, j + 7, k + 17, Blocks.air);
		world.setBlock(i + 18, j + 7, k + 18, Blocks.air);
		world.setBlock(i + 18, j + 7, k + 19, Blocks.air);
		world.setBlock(i + 18, j + 7, k + 20, Blocks.air);
		world.setBlock(i + 18, j + 7, k + 21, Blocks.stone);
		world.setBlock(i + 18, j + 8, k + 16, Blocks.stone);
		world.setBlock(i + 18, j + 8, k + 17, Blocks.air);
		world.setBlock(i + 18, j + 8, k + 18, Blocks.air);
		world.setBlock(i + 18, j + 8, k + 19, Blocks.air);
		world.setBlock(i + 18, j + 8, k + 20, Blocks.air);
		world.setBlock(i + 18, j + 8, k + 21, Blocks.stone);
		world.setBlock(i + 18, j + 9, k + 16, Blocks.stone);
		world.setBlock(i + 18, j + 9, k + 17, Blocks.stone);
		world.setBlock(i + 18, j + 9, k + 18, Blocks.air);
		world.setBlock(i + 18, j + 9, k + 19, Blocks.air);
		world.setBlock(i + 18, j + 9, k + 20, Blocks.stone);
		world.setBlock(i + 18, j + 9, k + 21, Blocks.stone);
		world.setBlock(i + 18, j + 10, k + 17, Blocks.stone);
		world.setBlock(i + 18, j + 10, k + 18, Blocks.stone);
		world.setBlock(i + 18, j + 10, k + 19, Blocks.stone);
		world.setBlock(i + 18, j + 10, k + 20, Blocks.stone);
		world.setBlock(i + 19, j + 0, k + 16, Blocks.stone);
		world.setBlock(i + 19, j + 0, k + 17, Blocks.stone);
		world.setBlock(i + 19, j + 0, k + 18, Blocks.stone);
		world.setBlock(i + 19, j + 0, k + 19, Blocks.stone);
		world.setBlock(i + 19, j + 0, k + 20, Blocks.stone);
		world.setBlock(i + 19, j + 1, k + 16, Blocks.stone);
		world.setBlock(i + 19, j + 1, k + 17, Blocks.stone);
		world.setBlock(i + 19, j + 1, k + 18, Blocks.stone);
		world.setBlock(i + 19, j + 1, k + 19, Blocks.stone);
		world.setBlock(i + 19, j + 1, k + 20, Blocks.stone);
		world.setBlock(i + 19, j + 2, k + 16, Blocks.stone);
		world.setBlock(i + 19, j + 2, k + 17, Blocks.stone);
		world.setBlock(i + 19, j + 2, k + 18, Blocks.stone);
		world.setBlock(i + 19, j + 2, k + 19, Blocks.stone);
		world.setBlock(i + 19, j + 2, k + 20, Blocks.stone);
		world.setBlock(i + 19, j + 3, k + 16, Blocks.stone);
		world.setBlock(i + 19, j + 3, k + 17, Blocks.stone);
		world.setBlock(i + 19, j + 3, k + 18, Blocks.stone);
		world.setBlock(i + 19, j + 3, k + 19, Blocks.stone);
		world.setBlock(i + 19, j + 3, k + 20, Blocks.stone);
		world.setBlock(i + 19, j + 4, k + 16, Blocks.stone);
		world.setBlock(i + 19, j + 4, k + 17, Blocks.stone);
		world.setBlock(i + 19, j + 4, k + 18, Blocks.stone);
		world.setBlock(i + 19, j + 4, k + 19, Blocks.stone);
		world.setBlock(i + 19, j + 4, k + 20, Blocks.stone);
		world.setBlock(i + 19, j + 4, k + 21, Blocks.stone);
		world.setBlock(i + 19, j + 5, k + 15, Blocks.stone);
		world.setBlock(i + 19, j + 5, k + 16, Blocks.stone);
		world.setBlock(i + 19, j + 5, k + 17, Blocks.stone);
		world.setBlock(i + 19, j + 5, k + 18, Blocks.stone);
		world.setBlock(i + 19, j + 5, k + 19, Blocks.stone);
		world.setBlock(i + 19, j + 5, k + 20, Blocks.stone);
		world.setBlock(i + 19, j + 5, k + 21, Blocks.stone);
		world.setBlock(i + 19, j + 6, k + 15, Blocks.stone);
		world.setBlock(i + 19, j + 6, k + 16, Blocks.air);
		world.setBlock(i + 19, j + 6, k + 17, Blocks.air);
		world.setBlock(i + 19, j + 6, k + 18, Blocks.air);
		world.setBlock(i + 19, j + 6, k + 19, Blocks.air);
		world.setBlock(i + 19, j + 6, k + 20, Blocks.air);
		world.setBlock(i + 19, j + 6, k + 21, Blocks.stone);
		world.setBlock(i + 19, j + 7, k + 15, Blocks.stone);
		world.setBlock(i + 19, j + 7, k + 16, Blocks.air);
		world.setBlock(i + 19, j + 7, k + 17, Blocks.air);
		world.setBlock(i + 19, j + 7, k + 18, Blocks.air);
		world.setBlock(i + 19, j + 7, k + 19, Blocks.air);
		world.setBlock(i + 19, j + 7, k + 20, Blocks.air);
		world.setBlock(i + 19, j + 7, k + 21, Blocks.stone);
		world.setBlock(i + 19, j + 8, k + 15, Blocks.stone);
		world.setBlock(i + 19, j + 8, k + 16, Blocks.stone);
		world.setBlock(i + 19, j + 8, k + 17, Blocks.air);
		world.setBlock(i + 19, j + 8, k + 18, Blocks.air);
		world.setBlock(i + 19, j + 8, k + 19, Blocks.air);
		world.setBlock(i + 19, j + 8, k + 20, Blocks.air);
		world.setBlock(i + 19, j + 8, k + 21, Blocks.stone);
		world.setBlock(i + 19, j + 9, k + 16, Blocks.stone);
		world.setBlock(i + 19, j + 9, k + 17, Blocks.stone);
		world.setBlock(i + 19, j + 9, k + 18, Blocks.air);
		world.setBlock(i + 19, j + 9, k + 19, Blocks.air);
		world.setBlock(i + 19, j + 9, k + 20, Blocks.stone);
		world.setBlock(i + 19, j + 9, k + 21, Blocks.stone);
		world.setBlock(i + 19, j + 10, k + 17, Blocks.stone);
		world.setBlock(i + 19, j + 10, k + 18, Blocks.stone);
		world.setBlock(i + 19, j + 10, k + 19, Blocks.stone);
		world.setBlock(i + 19, j + 10, k + 20, Blocks.stone);
		world.setBlock(i + 20, j + 0, k + 15, Blocks.stone);
		world.setBlock(i + 20, j + 0, k + 16, Blocks.stone);
		world.setBlock(i + 20, j + 0, k + 17, Blocks.stone);
		world.setBlock(i + 20, j + 0, k + 18, Blocks.stone);
		world.setBlock(i + 20, j + 0, k + 19, Blocks.stone);
		world.setBlock(i + 20, j + 0, k + 20, Blocks.stone);
		world.setBlock(i + 20, j + 0, k + 21, Blocks.stone);
		world.setBlock(i + 20, j + 1, k + 15, Blocks.stone);
		world.setBlock(i + 20, j + 1, k + 16, Blocks.stone);
		world.setBlock(i + 20, j + 1, k + 17, Blocks.stone);
		world.setBlock(i + 20, j + 1, k + 18, Blocks.stone);
		world.setBlock(i + 20, j + 1, k + 19, Blocks.stone);
		world.setBlock(i + 20, j + 1, k + 20, Blocks.stone);
		world.setBlock(i + 20, j + 1, k + 21, Blocks.stone);
		world.setBlock(i + 20, j + 2, k + 15, Blocks.stone);
		world.setBlock(i + 20, j + 2, k + 16, Blocks.stone);
		world.setBlock(i + 20, j + 2, k + 17, Blocks.stone);
		world.setBlock(i + 20, j + 2, k + 19, Blocks.air);
		world.setBlock(i + 20, j + 2, k + 20, Blocks.air);
		world.setBlock(i + 20, j + 2, k + 21, Blocks.stone);
		world.setBlock(i + 20, j + 3, k + 15, Blocks.stone);
		world.setBlock(i + 20, j + 3, k + 16, Blocks.air);
		world.setBlock(i + 20, j + 3, k + 17, Blocks.air);
		world.setBlock(i + 20, j + 3, k + 19, Blocks.air);
		world.setBlock(i + 20, j + 3, k + 20, Blocks.air);
		world.setBlock(i + 20, j + 3, k + 21, Blocks.stone);
		world.setBlock(i + 20, j + 4, k + 15, Blocks.stone);
		world.setBlock(i + 20, j + 4, k + 16, Blocks.air);
		world.setBlock(i + 20, j + 4, k + 17, Blocks.air);
		world.setBlock(i + 20, j + 4, k + 20, Blocks.air);
		world.setBlock(i + 20, j + 4, k + 21, Blocks.stone);
		world.setBlock(i + 20, j + 5, k + 15, Blocks.stone);
		world.setBlock(i + 20, j + 5, k + 16, Blocks.air);
		world.setBlock(i + 20, j + 5, k + 17, Blocks.air);
		world.setBlock(i + 20, j + 5, k + 19, Blocks.air);
		world.setBlock(i + 20, j + 5, k + 20, Blocks.air);
		world.setBlock(i + 20, j + 5, k + 21, Blocks.stone);
		world.setBlock(i + 20, j + 6, k + 15, Blocks.stone);
		world.setBlock(i + 20, j + 6, k + 16, Blocks.air);
		world.setBlock(i + 20, j + 6, k + 17, Blocks.air);
		world.setBlock(i + 20, j + 6, k + 18, Blocks.air);
		world.setBlock(i + 20, j + 6, k + 19, Blocks.air);
		world.setBlock(i + 20, j + 6, k + 20, Blocks.air);
		world.setBlock(i + 20, j + 6, k + 21, Blocks.stone);
		world.setBlock(i + 20, j + 7, k + 15, Blocks.stone);
		world.setBlock(i + 20, j + 7, k + 16, Blocks.air);
		world.setBlock(i + 20, j + 7, k + 17, Blocks.air);
		world.setBlock(i + 20, j + 7, k + 18, Blocks.air);
		world.setBlock(i + 20, j + 7, k + 19, Blocks.air);
		world.setBlock(i + 20, j + 7, k + 20, Blocks.air);
		world.setBlock(i + 20, j + 7, k + 21, Blocks.stone);
		world.setBlock(i + 20, j + 8, k + 15, Blocks.stone);
		world.setBlock(i + 20, j + 8, k + 16, Blocks.stone);
		world.setBlock(i + 20, j + 8, k + 17, Blocks.air);
		world.setBlock(i + 20, j + 8, k + 18, Blocks.air);
		world.setBlock(i + 20, j + 8, k + 19, Blocks.air);
		world.setBlock(i + 20, j + 8, k + 20, Blocks.air);
		world.setBlock(i + 20, j + 8, k + 21, Blocks.stone);
		world.setBlock(i + 20, j + 9, k + 16, Blocks.stone);
		world.setBlock(i + 20, j + 9, k + 17, Blocks.stone);
		world.setBlock(i + 20, j + 9, k + 18, Blocks.air);
		world.setBlock(i + 20, j + 9, k + 19, Blocks.air);
		world.setBlock(i + 20, j + 9, k + 20, Blocks.stone);
		world.setBlock(i + 20, j + 9, k + 21, Blocks.stone);
		world.setBlock(i + 20, j + 10, k + 17, Blocks.stone);
		world.setBlock(i + 20, j + 10, k + 18, Blocks.stone);
		world.setBlock(i + 20, j + 10, k + 19, Blocks.stone);
		world.setBlock(i + 20, j + 10, k + 20, Blocks.stone);
		world.setBlock(i + 21, j + 0, k + 12, Blocks.stone);
		world.setBlock(i + 21, j + 0, k + 14, Blocks.stone);
		world.setBlock(i + 21, j + 0, k + 15, Blocks.stone);
		world.setBlock(i + 21, j + 0, k + 16, Blocks.stone);
		world.setBlock(i + 21, j + 0, k + 17, Blocks.stone);
		world.setBlock(i + 21, j + 0, k + 18, Blocks.stone);
		world.setBlock(i + 21, j + 0, k + 19, Blocks.stone);
		world.setBlock(i + 21, j + 0, k + 20, Blocks.stone);
		world.setBlock(i + 21, j + 0, k + 21, Blocks.stone);
		world.setBlock(i + 21, j + 0, k + 22, Blocks.stone);
		world.setBlock(i + 21, j + 0, k + 23, Blocks.stone);
		world.setBlock(i + 21, j + 1, k + 12, Blocks.stone);
		world.setBlock(i + 21, j + 1, k + 14, Blocks.stone);
		world.setBlock(i + 21, j + 1, k + 15, Blocks.stone);
		world.setBlock(i + 21, j + 1, k + 16, Blocks.stone);
		world.setBlock(i + 21, j + 1, k + 17, Blocks.stone);
		world.setBlock(i + 21, j + 1, k + 18, Blocks.stone);
		world.setBlock(i + 21, j + 1, k + 19, Blocks.stone);
		world.setBlock(i + 21, j + 1, k + 20, Blocks.stone);
		world.setBlock(i + 21, j + 1, k + 21, Blocks.stone);
		world.setBlock(i + 21, j + 1, k + 22, Blocks.stone);
		world.setBlock(i + 21, j + 1, k + 23, Blocks.stone);
		world.setBlock(i + 21, j + 2, k + 12, Blocks.stone);
		world.setBlock(i + 21, j + 2, k + 14, Blocks.stone);
		world.setBlock(i + 21, j + 2, k + 15, Blocks.air);
		world.setBlock(i + 21, j + 2, k + 16, Blocks.stone);
		world.setBlock(i + 21, j + 2, k + 17, Blocks.stone);
		world.setBlock(i + 21, j + 2, k + 18, Blocks.air);
		world.setBlock(i + 21, j + 2, k + 19, Blocks.air);
		world.setBlock(i + 21, j + 2, k + 20, Blocks.stone);
		world.setBlock(i + 21, j + 2, k + 21, Blocks.air);
		world.setBlock(i + 21, j + 2, k + 22, Blocks.stone);
		world.setBlock(i + 21, j + 2, k + 23, Blocks.stone);
		world.setBlock(i + 21, j + 3, k + 12, Blocks.stone);
		world.setBlock(i + 21, j + 3, k + 14, Blocks.stone);
		world.setBlock(i + 21, j + 3, k + 15, Blocks.air);
		world.setBlock(i + 21, j + 3, k + 16, Blocks.air);
		world.setBlock(i + 21, j + 3, k + 17, Blocks.air);
		world.setBlock(i + 21, j + 3, k + 18, Blocks.air);
		world.setBlock(i + 21, j + 3, k + 19, Blocks.air);
		world.setBlock(i + 21, j + 3, k + 20, Blocks.stone);
		world.setBlock(i + 21, j + 3, k + 21, Blocks.air);
		world.setBlock(i + 21, j + 3, k + 22, Blocks.stone);
		world.setBlock(i + 21, j + 3, k + 23, Blocks.stone);
		world.setBlock(i + 21, j + 4, k + 12, Blocks.stone);
		world.setBlock(i + 21, j + 4, k + 14, Blocks.stone);
		world.setBlock(i + 21, j + 4, k + 15, Blocks.air);
		world.setBlock(i + 21, j + 4, k + 16, Blocks.air);
		world.setBlock(i + 21, j + 4, k + 17, Blocks.air);
		world.setBlock(i + 21, j + 4, k + 18, Blocks.air);
		world.setBlock(i + 21, j + 4, k + 19, Blocks.air);
		world.setBlock(i + 21, j + 4, k + 20, Blocks.air);
		world.setBlock(i + 21, j + 4, k + 21, Blocks.air);
		world.setBlock(i + 21, j + 4, k + 22, Blocks.stone);
		world.setBlock(i + 21, j + 4, k + 23, Blocks.stone);
