package wildycraft.structures;

import java.util.Random;

import wildycraft.Wildycraft;
import net.minecraft.init.Blocks;
import net.minecraft.world.World;

public class LunarIsle2 {

	public boolean generate14(World world, Random rand, int i, int j, int k) {
		world.setBlock(i + 34, j + 8, k + 92, Wildycraft.denseStone);
		world.setBlock(i + 34, j + 9, k + 2, Wildycraft.denseStone);
		world.setBlock(i + 34, j + 9, k + 55, Wildycraft.denseStone);
		world.setBlock(i + 34, j + 9, k + 56, Wildycraft.denseStone);
		world.setBlock(i + 34, j + 9, k + 57, Wildycraft.denseStone);
		world.setBlock(i + 34, j + 9, k + 58, Wildycraft.denseStone);
		world.setBlock(i + 34, j + 9, k + 59, Wildycraft.denseStone);
		world.setBlock(i + 34, j + 9, k + 60, Wildycraft.denseStone);
		world.setBlock(i + 34, j + 9, k + 61, Wildycraft.denseStone);
		world.setBlock(i + 34, j + 9, k + 62, Wildycraft.denseStone);
		world.setBlock(i + 34, j + 9, k + 63, Wildycraft.denseStone);
		world.setBlock(i + 34, j + 9, k + 64, Wildycraft.denseStone);
		world.setBlock(i + 34, j + 9, k + 65, Wildycraft.denseStone);
		world.setBlock(i + 34, j + 9, k + 66, Wildycraft.denseStone);
		world.setBlock(i + 34, j + 9, k + 67, Wildycraft.denseStone);
		world.setBlock(i + 34, j + 9, k + 68, Wildycraft.denseStone);
		world.setBlock(i + 34, j + 9, k + 69, Wildycraft.denseStone);
		world.setBlock(i + 34, j + 9, k + 70, Wildycraft.denseStone);
		world.setBlock(i + 34, j + 9, k + 71, Wildycraft.denseStone);
		world.setBlock(i + 34, j + 9, k + 72, Wildycraft.denseStone);
		world.setBlock(i + 34, j + 9, k + 73, Wildycraft.denseStone);
		world.setBlock(i + 34, j + 9, k + 74, Wildycraft.denseStone);
		world.setBlock(i + 34, j + 9, k + 75, Wildycraft.denseStone);
		world.setBlock(i + 34, j + 9, k + 76, Wildycraft.denseStone);
		world.setBlock(i + 34, j + 9, k + 77, Wildycraft.denseStone);
		world.setBlock(i + 34, j + 9, k + 78, Wildycraft.denseStone);
		world.setBlock(i + 34, j + 9, k + 79, Wildycraft.denseStone);
		world.setBlock(i + 34, j + 9, k + 80, Wildycraft.denseStone);
		world.setBlock(i + 34, j + 9, k + 81, Wildycraft.denseStone);
		world.setBlock(i + 34, j + 9, k + 82, Wildycraft.denseStone);
		world.setBlock(i + 34, j + 9, k + 83, Wildycraft.denseStone);
		world.setBlock(i + 34, j + 9, k + 84, Wildycraft.denseStone);
		world.setBlock(i + 34, j + 9, k + 85, Wildycraft.denseStone);
		world.setBlock(i + 34, j + 9, k + 86, Wildycraft.denseStone);
		world.setBlock(i + 34, j + 9, k + 87, Wildycraft.denseStone);
		world.setBlock(i + 34, j + 9, k + 88, Wildycraft.denseStone);
		world.setBlock(i + 34, j + 9, k + 89, Wildycraft.denseStone);
		world.setBlock(i + 34, j + 9, k + 90, Wildycraft.denseStone);
		world.setBlock(i + 34, j + 9, k + 91, Wildycraft.denseStone);
		world.setBlock(i + 34, j + 9, k + 92, Wildycraft.denseStone);
		world.setBlock(i + 34, j + 9, k + 93, Wildycraft.denseStone);
		world.setBlock(i + 34, j + 10, k + 1, Wildycraft.denseStone);
		world.setBlock(i + 34, j + 10, k + 2, Wildycraft.denseStone);
		world.setBlock(i + 34, j + 10, k + 3, Wildycraft.denseStone);
		world.setBlock(i + 34, j + 10, k + 54, Wildycraft.denseStone);
		world.setBlock(i + 34, j + 10, k + 55, Wildycraft.denseStone);
		world.setBlock(i + 34, j + 10, k + 56, Wildycraft.denseStone);
		world.setBlock(i + 34, j + 10, k + 57, Wildycraft.denseStone);
		world.setBlock(i + 34, j + 10, k + 58, Wildycraft.denseStone);
		world.setBlock(i + 34, j + 10, k + 59, Wildycraft.denseStone);
		world.setBlock(i + 34, j + 10, k + 60, Wildycraft.denseStone);
		world.setBlock(i + 34, j + 10, k + 61, Wildycraft.denseStone);
		world.setBlock(i + 34, j + 10, k + 62, Wildycraft.denseStone);
		world.setBlock(i + 34, j + 10, k + 63, Wildycraft.denseStone);
		world.setBlock(i + 34, j + 10, k + 64, Wildycraft.denseStone);
		world.setBlock(i + 34, j + 10, k + 65, Wildycraft.denseStone);
		world.setBlock(i + 34, j + 10, k + 66, Wildycraft.denseStone);
		world.setBlock(i + 34, j + 10, k + 67, Wildycraft.denseStone);
		world.setBlock(i + 34, j + 10, k + 68, Wildycraft.denseStone);
		world.setBlock(i + 34, j + 10, k + 69, Wildycraft.denseStone);
		world.setBlock(i + 34, j + 10, k + 70, Wildycraft.denseStone);
		world.setBlock(i + 34, j + 10, k + 71, Wildycraft.denseStone);
		world.setBlock(i + 34, j + 10, k + 72, Wildycraft.denseStone);
		world.setBlock(i + 34, j + 10, k + 73, Wildycraft.denseStone);
		world.setBlock(i + 34, j + 10, k + 74, Wildycraft.denseStone);
		world.setBlock(i + 34, j + 10, k + 75, Wildycraft.denseStone);
		world.setBlock(i + 34, j + 10, k + 76, Wildycraft.denseStone);
		world.setBlock(i + 34, j + 10, k + 77, Wildycraft.denseStone);
		world.setBlock(i + 34, j + 10, k + 78, Wildycraft.denseStone);
		world.setBlock(i + 34, j + 10, k + 79, Wildycraft.denseStone);
		world.setBlock(i + 34, j + 10, k + 80, Wildycraft.denseStone);
		world.setBlock(i + 34, j + 10, k + 81, Wildycraft.denseStone);
		world.setBlock(i + 34, j + 10, k + 82, Wildycraft.denseStone);
		world.setBlock(i + 34, j + 10, k + 83, Wildycraft.denseStone);
		world.setBlock(i + 34, j + 10, k + 84, Wildycraft.denseStone);
		world.setBlock(i + 34, j + 10, k + 85, Wildycraft.denseStone);
		world.setBlock(i + 34, j + 10, k + 86, Wildycraft.denseStone);
		world.setBlock(i + 34, j + 10, k + 87, Wildycraft.denseStone);
		world.setBlock(i + 34, j + 10, k + 88, Wildycraft.denseStone);
		world.setBlock(i + 34, j + 10, k + 89, Wildycraft.denseStone);
		world.setBlock(i + 34, j + 10, k + 90, Wildycraft.denseStone);
		world.setBlock(i + 34, j + 10, k + 91, Wildycraft.denseStone);
		world.setBlock(i + 34, j + 10, k + 92, Wildycraft.denseStone);
		world.setBlock(i + 34, j + 10, k + 93, Wildycraft.denseStone);
		world.setBlock(i + 34, j + 11, k + 0, Blocks.dirt);
		world.setBlock(i + 34, j + 11, k + 1, Blocks.dirt);
		world.setBlock(i + 34, j + 11, k + 2, Blocks.dirt);
		world.setBlock(i + 34, j + 11, k + 3, Blocks.dirt);
		world.setBlock(i + 34, j + 11, k + 4, Blocks.dirt);
		world.setBlock(i + 34, j + 11, k + 53, Blocks.dirt);
		world.setBlock(i + 34, j + 11, k + 54, Blocks.dirt);
		world.setBlock(i + 34, j + 11, k + 55, Blocks.dirt);
		world.setBlock(i + 34, j + 11, k + 56, Blocks.dirt);
		world.setBlock(i + 34, j + 11, k + 57, Blocks.dirt);
		world.setBlock(i + 34, j + 11, k + 58, Blocks.dirt);
		world.setBlock(i + 34, j + 11, k + 59, Blocks.dirt);
		world.setBlock(i + 34, j + 11, k + 60, Blocks.dirt);
		world.setBlock(i + 34, j + 11, k + 61, Blocks.dirt);
		world.setBlock(i + 34, j + 11, k + 62, Blocks.dirt);
		world.setBlock(i + 34, j + 11, k + 63, Blocks.dirt);
		world.setBlock(i + 34, j + 11, k + 64, Blocks.dirt);
		world.setBlock(i + 34, j + 11, k + 65, Blocks.dirt);
		world.setBlock(i + 34, j + 11, k + 66, Blocks.dirt);
		world.setBlock(i + 34, j + 11, k + 67, Blocks.dirt);
		world.setBlock(i + 34, j + 11, k + 68, Blocks.dirt);
		world.setBlock(i + 34, j + 11, k + 69, Blocks.dirt);
		world.setBlock(i + 34, j + 11, k + 70, Blocks.dirt);
		world.setBlock(i + 34, j + 11, k + 71, Blocks.dirt);
		world.setBlock(i + 34, j + 11, k + 72, Blocks.dirt);
		world.setBlock(i + 34, j + 11, k + 73, Blocks.dirt);
		world.setBlock(i + 34, j + 11, k + 74, Blocks.dirt);
		world.setBlock(i + 34, j + 11, k + 75, Blocks.dirt);
		world.setBlock(i + 34, j + 11, k + 76, Blocks.dirt);
		world.setBlock(i + 34, j + 11, k + 77, Blocks.dirt);
		world.setBlock(i + 34, j + 11, k + 78, Blocks.dirt);
		world.setBlock(i + 34, j + 11, k + 79, Blocks.dirt);
		world.setBlock(i + 34, j + 11, k + 80, Blocks.dirt);
		world.setBlock(i + 34, j + 11, k + 81, Blocks.dirt);
		world.setBlock(i + 34, j + 11, k + 82, Blocks.dirt);
		world.setBlock(i + 34, j + 11, k + 83, Blocks.dirt);
		world.setBlock(i + 34, j + 11, k + 84, Blocks.dirt);
		world.setBlock(i + 34, j + 11, k + 85, Blocks.dirt);
		world.setBlock(i + 34, j + 11, k + 86, Blocks.dirt);
		world.setBlock(i + 34, j + 11, k + 87, Blocks.dirt);
		world.setBlock(i + 34, j + 11, k + 88, Blocks.dirt);
		world.setBlock(i + 34, j + 11, k + 89, Blocks.dirt);
		world.setBlock(i + 34, j + 11, k + 90, Blocks.dirt);
		world.setBlock(i + 34, j + 11, k + 91, Blocks.dirt);
		world.setBlock(i + 34, j + 11, k + 92, Blocks.dirt);
		world.setBlock(i + 34, j + 11, k + 93, Blocks.dirt);
		world.setBlock(i + 34, j + 11, k + 94, Blocks.dirt);
		world.setBlock(i + 34, j + 12, k + 0, Blocks.grass);
		world.setBlock(i + 34, j + 12, k + 1, Blocks.grass);
		world.setBlock(i + 34, j + 12, k + 2, Blocks.grass);
		world.setBlock(i + 34, j + 12, k + 3, Blocks.grass);
		world.setBlock(i + 34, j + 12, k + 4, Blocks.grass);
		world.setBlock(i + 34, j + 12, k + 53, Blocks.grass);
		world.setBlock(i + 34, j + 12, k + 54, Blocks.grass);
		world.setBlock(i + 34, j + 12, k + 55, Blocks.grass);
		world.setBlock(i + 34, j + 12, k + 56, Blocks.grass);
		world.setBlock(i + 34, j + 12, k + 57, Blocks.dirt);
		world.setBlock(i + 34, j + 12, k + 58, Blocks.dirt);
		world.setBlock(i + 34, j + 12, k + 59, Blocks.dirt);
		world.setBlock(i + 34, j + 12, k + 60, Blocks.dirt);
		world.setBlock(i + 34, j + 12, k + 61, Blocks.dirt);
		world.setBlock(i + 34, j + 12, k + 62, Blocks.dirt);
		world.setBlock(i + 34, j + 12, k + 63, Blocks.dirt);
		world.setBlock(i + 34, j + 12, k + 64, Blocks.dirt);
		world.setBlock(i + 34, j + 12, k + 65, Blocks.dirt);
		world.setBlock(i + 34, j + 12, k + 66, Blocks.dirt);
		world.setBlock(i + 34, j + 12, k + 67, Blocks.dirt);
		world.setBlock(i + 34, j + 12, k + 68, Blocks.dirt);
		world.setBlock(i + 34, j + 12, k + 69, Blocks.dirt);
		world.setBlock(i + 34, j + 12, k + 70, Blocks.dirt);
		world.setBlock(i + 34, j + 12, k + 71, Blocks.dirt);
		world.setBlock(i + 34, j + 12, k + 72, Blocks.dirt);
		world.setBlock(i + 34, j + 12, k + 73, Blocks.dirt);
		world.setBlock(i + 34, j + 12, k + 74, Blocks.dirt);
		world.setBlock(i + 34, j + 12, k + 75, Blocks.dirt);
		world.setBlock(i + 34, j + 12, k + 76, Blocks.dirt);
		world.setBlock(i + 34, j + 12, k + 77, Blocks.dirt);
		world.setBlock(i + 34, j + 12, k + 78, Blocks.dirt);
		world.setBlock(i + 34, j + 12, k + 79, Blocks.dirt);
		world.setBlock(i + 34, j + 12, k + 80, Blocks.dirt);
		world.setBlock(i + 34, j + 12, k + 81, Blocks.dirt);
		world.setBlock(i + 34, j + 12, k + 82, Blocks.dirt);
		world.setBlock(i + 34, j + 12, k + 83, Blocks.dirt);
		world.setBlock(i + 34, j + 12, k + 84, Blocks.dirt);
		world.setBlock(i + 34, j + 12, k + 85, Blocks.dirt);
		world.setBlock(i + 34, j + 12, k + 86, Blocks.dirt);
		world.setBlock(i + 34, j + 12, k + 87, Blocks.dirt);
		world.setBlock(i + 34, j + 12, k + 88, Blocks.dirt);
		world.setBlock(i + 34, j + 12, k + 89, Blocks.dirt);
		world.setBlock(i + 34, j + 12, k + 90, Blocks.dirt);
		world.setBlock(i + 34, j + 12, k + 91, Blocks.dirt);
		world.setBlock(i + 34, j + 12, k + 92, Blocks.dirt);
		world.setBlock(i + 34, j + 12, k + 93, Blocks.grass);
		world.setBlock(i + 34, j + 12, k + 94, Blocks.grass);
		world.setBlock(i + 34, j + 13, k + 57, Blocks.grass);
		world.setBlock(i + 34, j + 13, k + 58, Blocks.dirt);
		world.setBlock(i + 34, j + 13, k + 59, Blocks.grass);
		world.setBlock(i + 34, j + 13, k + 60, Blocks.grass);
		world.setBlock(i + 34, j + 13, k + 61, Blocks.grass);
		world.setBlock(i + 34, j + 13, k + 62, Blocks.grass);
		world.setBlock(i + 34, j + 13, k + 63, Blocks.grass);
		world.setBlock(i + 34, j + 13, k + 64, Blocks.quartz_block);
		world.setBlock(i + 34, j + 13, k + 65, Blocks.grass);
		world.setBlock(i + 34, j + 13, k + 66, Blocks.grass);
		world.setBlock(i + 34, j + 13, k + 67, Blocks.grass);
		world.setBlock(i + 34, j + 13, k + 68, Blocks.grass);
		world.setBlock(i + 34, j + 13, k + 69, Blocks.grass);
		world.setBlock(i + 34, j + 13, k + 70, Blocks.planks, 1, 4);
		world.setBlock(i + 34, j + 13, k + 71, Blocks.planks, 1, 4);
		world.setBlock(i + 34, j + 13, k + 72, Blocks.planks, 1, 4);
		world.setBlock(i + 34, j + 13, k + 73, Blocks.planks, 1, 4);
		world.setBlock(i + 34, j + 13, k + 74, Blocks.planks, 1, 4);
		world.setBlock(i + 34, j + 13, k + 75, Blocks.planks, 1, 4);
		world.setBlock(i + 34, j + 13, k + 76, Blocks.planks, 1, 4);
		world.setBlock(i + 34, j + 13, k + 77, Blocks.planks, 1, 4);
		world.setBlock(i + 34, j + 13, k + 78, Blocks.planks, 1, 4);
		world.setBlock(i + 34, j + 13, k + 79, Blocks.planks, 1, 4);
		world.setBlock(i + 34, j + 13, k + 80, Blocks.planks, 1, 4);
		world.setBlock(i + 34, j + 13, k + 81, Blocks.grass);
		world.setBlock(i + 34, j + 13, k + 82, Blocks.grass);
		world.setBlock(i + 34, j + 13, k + 83, Blocks.grass);
		world.setBlock(i + 34, j + 13, k + 84, Blocks.grass);
		world.setBlock(i + 34, j + 13, k + 85, Blocks.grass);
		world.setBlock(i + 34, j + 13, k + 86, Blocks.grass);
		world.setBlock(i + 34, j + 13, k + 87, Blocks.grass);
		world.setBlock(i + 34, j + 13, k + 88, Blocks.grass);
		world.setBlock(i + 34, j + 13, k + 89, Blocks.grass);
		world.setBlock(i + 34, j + 13, k + 90, Blocks.dirt);
		world.setBlock(i + 34, j + 13, k + 91, Blocks.grass);
		world.setBlock(i + 34, j + 13, k + 92, Blocks.grass);
		world.setBlock(i + 34, j + 14, k + 58, Blocks.planks, 1, 4);
		world.setBlock(i + 34, j + 14, k + 70, Blocks.log2, 5, 4);
		world.setBlock(i + 34, j + 14, k + 80, Blocks.log2, 5, 4);
		world.setBlock(i + 34, j + 14, k + 90, Blocks.planks, 1, 4);
		world.setBlock(i + 34, j + 15, k + 58, Blocks.planks, 1, 4);
		world.setBlock(i + 34, j + 15, k + 70, Blocks.planks, 1, 4);
		world.setBlock(i + 34, j + 15, k + 80, Blocks.planks, 1, 4);
		world.setBlock(i + 34, j + 15, k + 90, Blocks.planks, 1, 4);
		world.setBlock(i + 34, j + 16, k + 58, Blocks.planks, 1, 4);
		world.setBlock(i + 34, j + 16, k + 70, Blocks.planks, 1, 4);
		world.setBlock(i + 34, j + 16, k + 80, Blocks.planks, 1, 4);
		world.setBlock(i + 34, j + 16, k + 90, Blocks.planks, 1, 4);
		world.setBlock(i + 34, j + 17, k + 58, Blocks.planks, 1, 4);
		world.setBlock(i + 34, j + 17, k + 69, Blocks.wooden_slab, 13, 4);
		world.setBlock(i + 34, j + 17, k + 70, Blocks.planks, 1, 4);
		world.setBlock(i + 34, j + 17, k + 71, Blocks.dark_oak_stairs, 7, 4);
		world.setBlock(i + 34, j + 17, k + 72, Blocks.dark_oak_stairs, 4, 4);
		world.setBlock(i + 34, j + 17, k + 73, Blocks.wooden_slab, 13, 4);
		world.setBlock(i + 34, j + 17, k + 74, Blocks.wooden_slab, 13, 4);
		world.setBlock(i + 34, j + 17, k + 75, Blocks.wooden_slab, 13, 4);
		world.setBlock(i + 34, j + 17, k + 76, Blocks.wooden_slab, 13, 4);
		world.setBlock(i + 34, j + 17, k + 77, Blocks.wooden_slab, 13, 4);
		world.setBlock(i + 34, j + 17, k + 78, Blocks.dark_oak_stairs, 4, 4);
		world.setBlock(i + 34, j + 17, k + 79, Blocks.dark_oak_stairs, 4, 4);
		world.setBlock(i + 34, j + 17, k + 80, Blocks.planks, 1, 4);
		world.setBlock(i + 34, j + 17, k + 81, Blocks.wooden_slab, 13, 4);
		world.setBlock(i + 34, j + 17, k + 90, Blocks.planks, 1, 4);
		world.setBlock(i + 34, j + 18, k + 58, Blocks.fence);
		world.setBlock(i + 34, j + 18, k + 70, Blocks.planks, 1, 4);
		world.setBlock(i + 34, j + 18, k + 80, Blocks.planks, 1, 4);
		world.setBlock(i + 34, j + 18, k + 90, Blocks.fence);
		world.setBlock(i + 34, j + 19, k + 70, Blocks.planks, 1, 4);
		world.setBlock(i + 34, j + 19, k + 80, Blocks.planks, 1, 4);
		world.setBlock(i + 34, j + 20, k + 70, Blocks.planks, 1, 4);
		world.setBlock(i + 34, j + 20, k + 80, Blocks.planks, 1, 4);
		world.setBlock(i + 34, j + 21, k + 69, Blocks.dark_oak_stairs, 2, 4);
		world.setBlock(i + 34, j + 21, k + 70, Blocks.planks, 1, 4);
		world.setBlock(i + 34, j + 21, k + 80, Blocks.planks, 1, 4);
		world.setBlock(i + 34, j + 21, k + 81, Blocks.dark_oak_stairs, 3, 4);
		world.setBlock(i + 34, j + 22, k + 70, Blocks.dark_oak_stairs, 2, 4);
		world.setBlock(i + 34, j + 22, k + 71, Blocks.wooden_slab, 9, 4);
		world.setBlock(i + 34, j + 22, k + 72, Blocks.wooden_slab, 9, 4);
		world.setBlock(i + 34, j + 22, k + 73, Blocks.wooden_slab, 9, 4);
		world.setBlock(i + 34, j + 22, k + 74, Blocks.wooden_slab, 9, 4);
		world.setBlock(i + 34, j + 22, k + 75, Blocks.log2, 5, 4);
		world.setBlock(i + 34, j + 22, k + 76, Blocks.wooden_slab, 9, 4);
		world.setBlock(i + 34, j + 22, k + 77, Blocks.wooden_slab, 9, 4);
		world.setBlock(i + 34, j + 22, k + 78, Blocks.wooden_slab, 9, 4);
		world.setBlock(i + 34, j + 22, k + 79, Blocks.wooden_slab, 9, 4);
		world.setBlock(i + 34, j + 22, k + 80, Blocks.dark_oak_stairs, 3, 4);
		world.setBlock(i + 34, j + 23, k + 71, Blocks.dark_oak_stairs, 2, 4);
		world.setBlock(i + 34, j + 23, k + 72, Blocks.planks, 1, 4);
		world.setBlock(i + 34, j + 23, k + 73, Blocks.planks, 1, 4);
		world.setBlock(i + 34, j + 23, k + 74, Blocks.glowstone);
		world.setBlock(i + 34, j + 23, k + 75, Blocks.glowstone);
		world.setBlock(i + 34, j + 23, k + 76, Blocks.glowstone);
		world.setBlock(i + 34, j + 23, k + 77, Blocks.planks, 1, 4);
		world.setBlock(i + 34, j + 23, k + 78, Blocks.planks, 1, 4);
		world.setBlock(i + 34, j + 23, k + 79, Blocks.dark_oak_stairs, 3, 4);
		world.setBlock(i + 34, j + 24, k + 72, Blocks.dark_oak_stairs, 2, 4);
		world.setBlock(i + 34, j + 24, k + 73, Blocks.planks, 1, 4);
		world.setBlock(i + 34, j + 24, k + 74, Blocks.planks, 1, 4);
		world.setBlock(i + 34, j + 24, k + 75, Blocks.glowstone);
		world.setBlock(i + 34, j + 24, k + 76, Blocks.planks, 1, 4);
		world.setBlock(i + 34, j + 24, k + 77, Blocks.planks, 1, 4);
		world.setBlock(i + 34, j + 24, k + 78, Blocks.dark_oak_stairs, 3, 4);
		world.setBlock(i + 34, j + 25, k + 73, Blocks.dark_oak_stairs, 2, 4);
		world.setBlock(i + 34, j + 25, k + 74, Blocks.planks, 1, 4);
		world.setBlock(i + 34, j + 25, k + 75, Blocks.planks, 1, 4);
		world.setBlock(i + 34, j + 25, k + 76, Blocks.planks, 1, 4);
		world.setBlock(i + 34, j + 25, k + 77, Blocks.dark_oak_stairs, 3, 4);
		world.setBlock(i + 34, j + 26, k + 74, Blocks.dark_oak_stairs, 2, 4);
		world.setBlock(i + 34, j + 26, k + 75, Blocks.planks, 5, 4);
		world.setBlock(i + 34, j + 26, k + 76, Blocks.dark_oak_stairs, 3, 4);
		world.setBlock(i + 35, j + 0, k + 70, Blocks.stone);
		world.setBlock(i + 35, j + 0, k + 71, Blocks.stone);
		world.setBlock(i + 35, j + 0, k + 72, Blocks.stone);
		world.setBlock(i + 35, j + 0, k + 73, Blocks.stone);
		world.setBlock(i + 35, j + 0, k + 74, Blocks.stone);
		world.setBlock(i + 35, j + 0, k + 75, Blocks.stone);
		world.setBlock(i + 35, j + 0, k + 76, Blocks.stone);
		world.setBlock(i + 35, j + 0, k + 77, Blocks.stone);
		world.setBlock(i + 35, j + 0, k + 78, Blocks.stone);
		world.setBlock(i + 35, j + 1, k + 67, Blocks.stone);
		world.setBlock(i + 35, j + 1, k + 68, Blocks.stone);
		world.setBlock(i + 35, j + 1, k + 69, Blocks.stone);
		world.setBlock(i + 35, j + 1, k + 70, Blocks.stone);
		world.setBlock(i + 35, j + 1, k + 71, Blocks.stone);
		world.setBlock(i + 35, j + 1, k + 72, Blocks.stone);
		world.setBlock(i + 35, j + 1, k + 73, Blocks.stone);
		world.setBlock(i + 35, j + 1, k + 74, Blocks.stone);
		world.setBlock(i + 35, j + 1, k + 75, Blocks.stone);
		world.setBlock(i + 35, j + 1, k + 76, Blocks.stone);
		world.setBlock(i + 35, j + 1, k + 77, Blocks.stone);
		world.setBlock(i + 35, j + 1, k + 78, Blocks.stone);
		world.setBlock(i + 35, j + 1, k + 79, Blocks.stone);
		world.setBlock(i + 35, j + 1, k + 80, Blocks.stone);
		world.setBlock(i + 35, j + 1, k + 81, Blocks.stone);
		world.setBlock(i + 35, j + 2, k + 64, Blocks.stone);
		world.setBlock(i + 35, j + 2, k + 65, Blocks.stone);
		world.setBlock(i + 35, j + 2, k + 66, Blocks.stone);
		world.setBlock(i + 35, j + 2, k + 67, Blocks.stone);
		world.setBlock(i + 35, j + 2, k + 68, Blocks.stone);
		world.setBlock(i + 35, j + 2, k + 69, Blocks.stone);
		world.setBlock(i + 35, j + 2, k + 70, Blocks.stone);
		world.setBlock(i + 35, j + 2, k + 71, Blocks.stone);
		world.setBlock(i + 35, j + 2, k + 72, Blocks.stone);
		world.setBlock(i + 35, j + 2, k + 73, Blocks.stone);
		world.setBlock(i + 35, j + 2, k + 74, Blocks.stone);
		world.setBlock(i + 35, j + 2, k + 75, Blocks.stone);
		world.setBlock(i + 35, j + 2, k + 76, Blocks.stone);
		world.setBlock(i + 35, j + 2, k + 77, Blocks.stone);
		world.setBlock(i + 35, j + 2, k + 78, Blocks.stone);
		world.setBlock(i + 35, j + 2, k + 79, Blocks.stone);
		world.setBlock(i + 35, j + 2, k + 80, Blocks.stone);
		world.setBlock(i + 35, j + 2, k + 81, Blocks.stone);
		world.setBlock(i + 35, j + 2, k + 82, Blocks.stone);
		world.setBlock(i + 35, j + 2, k + 83, Blocks.stone);
		world.setBlock(i + 35, j + 3, k + 62, Blocks.stone);
		world.setBlock(i + 35, j + 3, k + 63, Blocks.stone);
		world.setBlock(i + 35, j + 3, k + 64, Blocks.stone);
		world.setBlock(i + 35, j + 3, k + 65, Blocks.stone);
		world.setBlock(i + 35, j + 3, k + 66, Blocks.stone);
		world.setBlock(i + 35, j + 3, k + 67, Blocks.stone);
		world.setBlock(i + 35, j + 3, k + 68, Blocks.stone);
		world.setBlock(i + 35, j + 3, k + 69, Blocks.stone);
		world.setBlock(i + 35, j + 3, k + 70, Blocks.stone);
		world.setBlock(i + 35, j + 3, k + 71, Blocks.stone);
		world.setBlock(i + 35, j + 3, k + 72, Blocks.stone);
		world.setBlock(i + 35, j + 3, k + 73, Blocks.stone);
		world.setBlock(i + 35, j + 3, k + 74, Blocks.stone);
		world.setBlock(i + 35, j + 3, k + 75, Blocks.stone);
		world.setBlock(i + 35, j + 3, k + 76, Blocks.stone);
		world.setBlock(i + 35, j + 3, k + 77, Blocks.stone);
		world.setBlock(i + 35, j + 3, k + 78, Blocks.stone);
		world.setBlock(i + 35, j + 3, k + 79, Blocks.stone);
		world.setBlock(i + 35, j + 3, k + 80, Blocks.stone);
		world.setBlock(i + 35, j + 3, k + 81, Blocks.stone);
		world.setBlock(i + 35, j + 3, k + 82, Blocks.stone);
		world.setBlock(i + 35, j + 3, k + 83, Blocks.stone);
		world.setBlock(i + 35, j + 3, k + 84, Blocks.stone);
		world.setBlock(i + 35, j + 3, k + 85, Blocks.stone);
		world.setBlock(i + 35, j + 3, k + 86, Blocks.stone);
		world.setBlock(i + 35, j + 4, k + 60, Blocks.stone);
		world.setBlock(i + 35, j + 4, k + 61, Blocks.stone);
		world.setBlock(i + 35, j + 4, k + 62, Blocks.stone);
		world.setBlock(i + 35, j + 4, k + 63, Blocks.stone);
		world.setBlock(i + 35, j + 4, k + 64, Blocks.stone);
		world.setBlock(i + 35, j + 4, k + 65, Blocks.stone);
		world.setBlock(i + 35, j + 4, k + 66, Blocks.stone);
		world.setBlock(i + 35, j + 4, k + 67, Blocks.stone);
		world.setBlock(i + 35, j + 4, k + 68, Blocks.stone);
		world.setBlock(i + 35, j + 4, k + 69, Blocks.stone);
		world.setBlock(i + 35, j + 4, k + 70, Blocks.stone);
		world.setBlock(i + 35, j + 4, k + 71, Blocks.stone);
		world.setBlock(i + 35, j + 4, k + 72, Blocks.stone);
		world.setBlock(i + 35, j + 4, k + 73, Blocks.stone);
		world.setBlock(i + 35, j + 4, k + 74, Blocks.stone);
		world.setBlock(i + 35, j + 4, k + 75, Blocks.stone);
		world.setBlock(i + 35, j + 4, k + 76, Blocks.stone);
		world.setBlock(i + 35, j + 4, k + 77, Blocks.stone);
		world.setBlock(i + 35, j + 4, k + 78, Blocks.stone);
		world.setBlock(i + 35, j + 4, k + 79, Blocks.stone);
		world.setBlock(i + 35, j + 4, k + 80, Blocks.stone);
		world.setBlock(i + 35, j + 4, k + 81, Blocks.stone);
		world.setBlock(i + 35, j + 4, k + 82, Blocks.stone);
		world.setBlock(i + 35, j + 4, k + 83, Blocks.stone);
		world.setBlock(i + 35, j + 4, k + 84, Blocks.stone);
		world.setBlock(i + 35, j + 4, k + 85, Blocks.stone);
		world.setBlock(i + 35, j + 4, k + 86, Blocks.stone);
		world.setBlock(i + 35, j + 4, k + 87, Blocks.stone);
		world.setBlock(i + 35, j + 4, k + 88, Blocks.stone);
		world.setBlock(i + 35, j + 5, k + 59, Blocks.stone);
		world.setBlock(i + 35, j + 5, k + 60, Blocks.stone);
		world.setBlock(i + 35, j + 5, k + 61, Blocks.stone);
		world.setBlock(i + 35, j + 5, k + 62, Blocks.stone);
		world.setBlock(i + 35, j + 5, k + 63, Blocks.stone);
		world.setBlock(i + 35, j + 5, k + 64, Blocks.stone);
		world.setBlock(i + 35, j + 5, k + 65, Blocks.stone);
		world.setBlock(i + 35, j + 5, k + 66, Blocks.stone);
		world.setBlock(i + 35, j + 5, k + 67, Blocks.stone);
		world.setBlock(i + 35, j + 5, k + 68, Blocks.stone);
		world.setBlock(i + 35, j + 5, k + 69, Blocks.stone);
		world.setBlock(i + 35, j + 5, k + 70, Blocks.stone);
		world.setBlock(i + 35, j + 5, k + 71, Blocks.stone);
		world.setBlock(i + 35, j + 5, k + 72, Blocks.stone);
		world.setBlock(i + 35, j + 5, k + 73, Blocks.stone);
		world.setBlock(i + 35, j + 5, k + 74, Blocks.stone);
		world.setBlock(i + 35, j + 5, k + 75, Blocks.stone);
		world.setBlock(i + 35, j + 5, k + 76, Blocks.stone);
		world.setBlock(i + 35, j + 5, k + 77, Blocks.stone);
		world.setBlock(i + 35, j + 5, k + 78, Blocks.stone);
		world.setBlock(i + 35, j + 5, k + 79, Blocks.stone);
		world.setBlock(i + 35, j + 5, k + 80, Blocks.stone);
		world.setBlock(i + 35, j + 5, k + 81, Blocks.stone);
		world.setBlock(i + 35, j + 5, k + 82, Blocks.stone);
		world.setBlock(i + 35, j + 5, k + 83, Blocks.stone);
		world.setBlock(i + 35, j + 5, k + 84, Blocks.stone);
		world.setBlock(i + 35, j + 5, k + 85, Blocks.stone);
		world.setBlock(i + 35, j + 5, k + 86, Blocks.stone);
		world.setBlock(i + 35, j + 5, k + 87, Blocks.stone);
		world.setBlock(i + 35, j + 5, k + 88, Blocks.stone);
		world.setBlock(i + 35, j + 5, k + 89, Blocks.stone);
		world.setBlock(i + 35, j + 6, k + 58, Blocks.stone);
		world.setBlock(i + 35, j + 6, k + 59, Blocks.stone);
		world.setBlock(i + 35, j + 6, k + 60, Blocks.stone);
		world.setBlock(i + 35, j + 6, k + 61, Blocks.stone);
		world.setBlock(i + 35, j + 6, k + 62, Blocks.stone);
		world.setBlock(i + 35, j + 6, k + 63, Blocks.stone);
		world.setBlock(i + 35, j + 6, k + 64, Blocks.stone);
		world.setBlock(i + 35, j + 6, k + 65, Blocks.stone);
		world.setBlock(i + 35, j + 6, k + 66, Blocks.stone);
		world.setBlock(i + 35, j + 6, k + 67, Blocks.stone);
		world.setBlock(i + 35, j + 6, k + 68, Blocks.stone);
		world.setBlock(i + 35, j + 6, k + 69, Blocks.stone);
		world.setBlock(i + 35, j + 6, k + 70, Blocks.stone);
		world.setBlock(i + 35, j + 6, k + 71, Blocks.stone);
		world.setBlock(i + 35, j + 6, k + 72, Blocks.stone);
		world.setBlock(i + 35, j + 6, k + 73, Blocks.stone);
		world.setBlock(i + 35, j + 6, k + 74, Blocks.stone);
		world.setBlock(i + 35, j + 6, k + 75, Blocks.stone);
		world.setBlock(i + 35, j + 6, k + 76, Blocks.stone);
		world.setBlock(i + 35, j + 6, k + 77, Blocks.stone);
		world.setBlock(i + 35, j + 6, k + 78, Blocks.stone);
		world.setBlock(i + 35, j + 6, k + 79, Blocks.stone);
		world.setBlock(i + 35, j + 6, k + 80, Blocks.stone);
		world.setBlock(i + 35, j + 6, k + 81, Blocks.stone);
		world.setBlock(i + 35, j + 6, k + 82, Blocks.stone);
		world.setBlock(i + 35, j + 6, k + 83, Blocks.stone);
		world.setBlock(i + 35, j + 6, k + 84, Blocks.stone);
		world.setBlock(i + 35, j + 6, k + 85, Blocks.stone);
		world.setBlock(i + 35, j + 6, k + 86, Blocks.stone);
		world.setBlock(i + 35, j + 6, k + 87, Blocks.stone);
		world.setBlock(i + 35, j + 6, k + 88, Blocks.stone);
		world.setBlock(i + 35, j + 6, k + 89, Blocks.stone);
		world.setBlock(i + 35, j + 6, k + 90, Blocks.stone);
		world.setBlock(i + 35, j + 7, k + 57, Blocks.stone);
		world.setBlock(i + 35, j + 7, k + 58, Blocks.stone);
		world.setBlock(i + 35, j + 7, k + 59, Blocks.stone);
		world.setBlock(i + 35, j + 7, k + 60, Blocks.stone);
		world.setBlock(i + 35, j + 7, k + 61, Blocks.stone);
		world.setBlock(i + 35, j + 7, k + 62, Blocks.stone);
		world.setBlock(i + 35, j + 7, k + 63, Blocks.stone);
		world.setBlock(i + 35, j + 7, k + 64, Blocks.stone);
		world.setBlock(i + 35, j + 7, k + 65, Blocks.stone);
		world.setBlock(i + 35, j + 7, k + 66, Blocks.stone);
		world.setBlock(i + 35, j + 7, k + 67, Blocks.stone);
		world.setBlock(i + 35, j + 7, k + 68, Blocks.stone);
		world.setBlock(i + 35, j + 7, k + 69, Blocks.stone);
		world.setBlock(i + 35, j + 7, k + 70, Blocks.stone);
		world.setBlock(i + 35, j + 7, k + 71, Blocks.stone);
		world.setBlock(i + 35, j + 7, k + 72, Blocks.stone);
		world.setBlock(i + 35, j + 7, k + 73, Blocks.stone);
		world.setBlock(i + 35, j + 7, k + 74, Blocks.stone);
		world.setBlock(i + 35, j + 7, k + 75, Blocks.stone);
		world.setBlock(i + 35, j + 7, k + 76, Blocks.stone);
		world.setBlock(i + 35, j + 7, k + 77, Blocks.stone);
		world.setBlock(i + 35, j + 7, k + 78, Blocks.stone);
		world.setBlock(i + 35, j + 7, k + 79, Blocks.stone);
		world.setBlock(i + 35, j + 7, k + 80, Blocks.stone);
		world.setBlock(i + 35, j + 7, k + 81, Blocks.stone);
		world.setBlock(i + 35, j + 7, k + 82, Blocks.stone);
		world.setBlock(i + 35, j + 7, k + 83, Blocks.stone);
		world.setBlock(i + 35, j + 7, k + 84, Blocks.stone);
		world.setBlock(i + 35, j + 7, k + 85, Blocks.stone);
		world.setBlock(i + 35, j + 7, k + 86, Blocks.stone);
		world.setBlock(i + 35, j + 7, k + 87, Blocks.stone);
		world.setBlock(i + 35, j + 7, k + 88, Blocks.stone);
		world.setBlock(i + 35, j + 7, k + 89, Blocks.stone);
		world.setBlock(i + 35, j + 7, k + 90, Blocks.stone);
		world.setBlock(i + 35, j + 7, k + 91, Blocks.stone);
		world.setBlock(i + 35, j + 8, k + 56, Wildycraft.denseStone);
		world.setBlock(i + 35, j + 8, k + 57, Wildycraft.denseStone);
		world.setBlock(i + 35, j + 8, k + 58, Wildycraft.denseStone);
		world.setBlock(i + 35, j + 8, k + 59, Wildycraft.denseStone);
		world.setBlock(i + 35, j + 8, k + 60, Wildycraft.denseStone);
		world.setBlock(i + 35, j + 8, k + 61, Wildycraft.denseStone);
		world.setBlock(i + 35, j + 8, k + 62, Wildycraft.denseStone);
		world.setBlock(i + 35, j + 8, k + 63, Wildycraft.denseStone);
		world.setBlock(i + 35, j + 8, k + 64, Wildycraft.denseStone);
		world.setBlock(i + 35, j + 8, k + 65, Wildycraft.denseStone);
		world.setBlock(i + 35, j + 8, k + 66, Wildycraft.denseStone);
		world.setBlock(i + 35, j + 8, k + 67, Wildycraft.denseStone);
		world.setBlock(i + 35, j + 8, k + 68, Wildycraft.denseStone);
		world.setBlock(i + 35, j + 8, k + 69, Wildycraft.denseStone);
		world.setBlock(i + 35, j + 8, k + 70, Wildycraft.denseStone);
		world.setBlock(i + 35, j + 8, k + 71, Wildycraft.denseStone);
		world.setBlock(i + 35, j + 8, k + 72, Wildycraft.denseStone);
		world.setBlock(i + 35, j + 8, k + 73, Wildycraft.denseStone);
		world.setBlock(i + 35, j + 8, k + 74, Wildycraft.denseStone);
		world.setBlock(i + 35, j + 8, k + 75, Wildycraft.denseStone);
		world.setBlock(i + 35, j + 8, k + 76, Wildycraft.denseStone);
		world.setBlock(i + 35, j + 8, k + 77, Wildycraft.denseStone);
		world.setBlock(i + 35, j + 8, k + 78, Wildycraft.denseStone);
		world.setBlock(i + 35, j + 8, k + 79, Wildycraft.denseStone);
		world.setBlock(i + 35, j + 8, k + 80, Wildycraft.denseStone);
		world.setBlock(i + 35, j + 8, k + 81, Wildycraft.denseStone);
		world.setBlock(i + 35, j + 8, k + 82, Wildycraft.denseStone);
		world.setBlock(i + 35, j + 8, k + 83, Wildycraft.denseStone);
		world.setBlock(i + 35, j + 8, k + 84, Wildycraft.denseStone);
		world.setBlock(i + 35, j + 8, k + 85, Wildycraft.denseStone);
		world.setBlock(i + 35, j + 8, k + 86, Wildycraft.denseStone);
		world.setBlock(i + 35, j + 8, k + 87, Wildycraft.denseStone);
		world.setBlock(i + 35, j + 8, k + 88, Wildycraft.denseStone);
		world.setBlock(i + 35, j + 8, k + 89, Wildycraft.denseStone);
		world.setBlock(i + 35, j + 8, k + 90, Wildycraft.denseStone);
		world.setBlock(i + 35, j + 8, k + 91, Wildycraft.denseStone);
		world.setBlock(i + 35, j + 8, k + 92, Wildycraft.denseStone);
		world.setBlock(i + 35, j + 9, k + 2, Wildycraft.denseStone);
		world.setBlock(i + 35, j + 9, k + 55, Wildycraft.denseStone);
		world.setBlock(i + 35, j + 9, k + 56, Wildycraft.denseStone);
		world.setBlock(i + 35, j + 9, k + 57, Wildycraft.denseStone);
		world.setBlock(i + 35, j + 9, k + 58, Wildycraft.denseStone);
		world.setBlock(i + 35, j + 9, k + 59, Wildycraft.denseStone);
		world.setBlock(i + 35, j + 9, k + 60, Wildycraft.denseStone);
		world.setBlock(i + 35, j + 9, k + 61, Wildycraft.denseStone);
		world.setBlock(i + 35, j + 9, k + 62, Wildycraft.denseStone);
		world.setBlock(i + 35, j + 9, k + 63, Wildycraft.denseStone);
		world.setBlock(i + 35, j + 9, k + 64, Wildycraft.denseStone);
		world.setBlock(i + 35, j + 9, k + 65, Wildycraft.denseStone);
		world.setBlock(i + 35, j + 9, k + 66, Wildycraft.denseStone);
		world.setBlock(i + 35, j + 9, k + 67, Wildycraft.denseStone);
		world.setBlock(i + 35, j + 9, k + 68, Wildycraft.denseStone);
		world.setBlock(i + 35, j + 9, k + 69, Wildycraft.denseStone);
		world.setBlock(i + 35, j + 9, k + 70, Wildycraft.denseStone);
		world.setBlock(i + 35, j + 9, k + 71, Wildycraft.denseStone);
		world.setBlock(i + 35, j + 9, k + 72, Wildycraft.denseStone);
		world.setBlock(i + 35, j + 9, k + 73, Wildycraft.denseStone);
		world.setBlock(i + 35, j + 9, k + 74, Wildycraft.denseStone);
		world.setBlock(i + 35, j + 9, k + 75, Wildycraft.denseStone);
		world.setBlock(i + 35, j + 9, k + 76, Wildycraft.denseStone);
		world.setBlock(i + 35, j + 9, k + 77, Wildycraft.denseStone);
		world.setBlock(i + 35, j + 9, k + 78, Wildycraft.denseStone);
		world.setBlock(i + 35, j + 9, k + 79, Wildycraft.denseStone);
		world.setBlock(i + 35, j + 9, k + 80, Wildycraft.denseStone);
		world.setBlock(i + 35, j + 9, k + 81, Wildycraft.denseStone);
		world.setBlock(i + 35, j + 9, k + 82, Wildycraft.denseStone);
		world.setBlock(i + 35, j + 9, k + 83, Wildycraft.denseStone);
		world.setBlock(i + 35, j + 9, k + 84, Wildycraft.denseStone);
		world.setBlock(i + 35, j + 9, k + 85, Wildycraft.denseStone);
		world.setBlock(i + 35, j + 9, k + 86, Wildycraft.denseStone);
		world.setBlock(i + 35, j + 9, k + 87, Wildycraft.denseStone);
		world.setBlock(i + 35, j + 9, k + 88, Wildycraft.denseStone);
		world.setBlock(i + 35, j + 9, k + 89, Wildycraft.denseStone);
		world.setBlock(i + 35, j + 9, k + 90, Wildycraft.denseStone);
		world.setBlock(i + 35, j + 9, k + 91, Wildycraft.denseStone);
		world.setBlock(i + 35, j + 9, k + 92, Wildycraft.denseStone);
		world.setBlock(i + 35, j + 9, k + 93, Wildycraft.denseStone);
		world.setBlock(i + 35, j + 10, k + 1, Wildycraft.denseStone);
		world.setBlock(i + 35, j + 10, k + 2, Wildycraft.denseStone);
		world.setBlock(i + 35, j + 10, k + 3, Wildycraft.denseStone);
		world.setBlock(i + 35, j + 10, k + 54, Wildycraft.denseStone);
		world.setBlock(i + 35, j + 10, k + 55, Wildycraft.denseStone);
		world.setBlock(i + 35, j + 10, k + 56, Wildycraft.denseStone);
		world.setBlock(i + 35, j + 10, k + 57, Wildycraft.denseStone);
		world.setBlock(i + 35, j + 10, k + 58, Wildycraft.denseStone);
		world.setBlock(i + 35, j + 10, k + 59, Wildycraft.denseStone);
		world.setBlock(i + 35, j + 10, k + 60, Wildycraft.denseStone);
		world.setBlock(i + 35, j + 10, k + 61, Wildycraft.denseStone);
		world.setBlock(i + 35, j + 10, k + 62, Wildycraft.denseStone);
		world.setBlock(i + 35, j + 10, k + 63, Wildycraft.denseStone);
		world.setBlock(i + 35, j + 10, k + 64, Wildycraft.denseStone);
		world.setBlock(i + 35, j + 10, k + 65, Wildycraft.denseStone);
		world.setBlock(i + 35, j + 10, k + 66, Wildycraft.denseStone);
		world.setBlock(i + 35, j + 10, k + 67, Wildycraft.denseStone);
		world.setBlock(i + 35, j + 10, k + 68, Wildycraft.denseStone);
		world.setBlock(i + 35, j + 10, k + 69, Wildycraft.denseStone);
		world.setBlock(i + 35, j + 10, k + 70, Wildycraft.denseStone);
		world.setBlock(i + 35, j + 10, k + 71, Wildycraft.denseStone);
		world.setBlock(i + 35, j + 10, k + 72, Wildycraft.denseStone);
		world.setBlock(i + 35, j + 10, k + 73, Wildycraft.denseStone);
		world.setBlock(i + 35, j + 10, k + 74, Wildycraft.denseStone);
		world.setBlock(i + 35, j + 10, k + 75, Wildycraft.denseStone);
		world.setBlock(i + 35, j + 10, k + 76, Wildycraft.denseStone);
		world.setBlock(i + 35, j + 10, k + 77, Wildycraft.denseStone);
		world.setBlock(i + 35, j + 10, k + 78, Wildycraft.denseStone);
		world.setBlock(i + 35, j + 10, k + 79, Wildycraft.denseStone);
		world.setBlock(i + 35, j + 10, k + 80, Wildycraft.denseStone);
		world.setBlock(i + 35, j + 10, k + 81, Wildycraft.denseStone);
		world.setBlock(i + 35, j + 10, k + 82, Wildycraft.denseStone);
		world.setBlock(i + 35, j + 10, k + 83, Wildycraft.denseStone);
		world.setBlock(i + 35, j + 10, k + 84, Wildycraft.denseStone);
		world.setBlock(i + 35, j + 10, k + 85, Wildycraft.denseStone);
		world.setBlock(i + 35, j + 10, k + 86, Wildycraft.denseStone);
		world.setBlock(i + 35, j + 10, k + 87, Wildycraft.denseStone);
		world.setBlock(i + 35, j + 10, k + 88, Wildycraft.denseStone);
		world.setBlock(i + 35, j + 10, k + 89, Wildycraft.denseStone);
		world.setBlock(i + 35, j + 10, k + 90, Wildycraft.denseStone);
		world.setBlock(i + 35, j + 10, k + 91, Wildycraft.denseStone);
		world.setBlock(i + 35, j + 10, k + 92, Wildycraft.denseStone);
		world.setBlock(i + 35, j + 10, k + 93, Wildycraft.denseStone);
		world.setBlock(i + 35, j + 10, k + 94, Wildycraft.denseStone);
		world.setBlock(i + 35, j + 11, k + 0, Blocks.dirt);
		world.setBlock(i + 35, j + 11, k + 1, Blocks.dirt);
		world.setBlock(i + 35, j + 11, k + 2, Blocks.dirt);
		world.setBlock(i + 35, j + 11, k + 3, Blocks.dirt);
		world.setBlock(i + 35, j + 11, k + 4, Blocks.dirt);
		world.setBlock(i + 35, j + 11, k + 53, Blocks.dirt);
		world.setBlock(i + 35, j + 11, k + 54, Blocks.dirt);
		world.setBlock(i + 35, j + 11, k + 55, Blocks.dirt);
		world.setBlock(i + 35, j + 11, k + 56, Blocks.dirt);
		world.setBlock(i + 35, j + 11, k + 57, Blocks.dirt);
		world.setBlock(i + 35, j + 11, k + 58, Blocks.dirt);
		world.setBlock(i + 35, j + 11, k + 59, Blocks.dirt);
		world.setBlock(i + 35, j + 11, k + 60, Blocks.dirt);
		world.setBlock(i + 35, j + 11, k + 61, Blocks.dirt);
		world.setBlock(i + 35, j + 11, k + 62, Blocks.dirt);
		world.setBlock(i + 35, j + 11, k + 63, Blocks.dirt);
		world.setBlock(i + 35, j + 11, k + 64, Blocks.dirt);
		world.setBlock(i + 35, j + 11, k + 65, Blocks.dirt);
		world.setBlock(i + 35, j + 11, k + 66, Blocks.dirt);
		world.setBlock(i + 35, j + 11, k + 67, Blocks.dirt);
		world.setBlock(i + 35, j + 11, k + 68, Blocks.dirt);
		world.setBlock(i + 35, j + 11, k + 69, Blocks.dirt);
		world.setBlock(i + 35, j + 11, k + 70, Blocks.dirt);
		world.setBlock(i + 35, j + 11, k + 71, Blocks.dirt);
		world.setBlock(i + 35, j + 11, k + 72, Blocks.dirt);
		world.setBlock(i + 35, j + 11, k + 73, Blocks.dirt);
		world.setBlock(i + 35, j + 11, k + 74, Blocks.dirt);
		world.setBlock(i + 35, j + 11, k + 75, Blocks.dirt);
		world.setBlock(i + 35, j + 11, k + 76, Blocks.dirt);
		world.setBlock(i + 35, j + 11, k + 77, Blocks.dirt);
		world.setBlock(i + 35, j + 11, k + 78, Blocks.dirt);
		world.setBlock(i + 35, j + 11, k + 79, Blocks.dirt);
		world.setBlock(i + 35, j + 11, k + 80, Blocks.dirt);
		world.setBlock(i + 35, j + 11, k + 81, Blocks.dirt);
		world.setBlock(i + 35, j + 11, k + 82, Blocks.dirt);
		world.setBlock(i + 35, j + 11, k + 83, Blocks.dirt);
		world.setBlock(i + 35, j + 11, k + 84, Blocks.dirt);
		world.setBlock(i + 35, j + 11, k + 85, Blocks.dirt);
		world.setBlock(i + 35, j + 11, k + 86, Blocks.dirt);
		world.setBlock(i + 35, j + 11, k + 87, Blocks.dirt);
		world.setBlock(i + 35, j + 11, k + 88, Blocks.dirt);
		world.setBlock(i + 35, j + 11, k + 89, Blocks.dirt);
		world.setBlock(i + 35, j + 11, k + 90, Blocks.dirt);
		world.setBlock(i + 35, j + 11, k + 91, Blocks.dirt);
		world.setBlock(i + 35, j + 11, k + 92, Blocks.dirt);
		world.setBlock(i + 35, j + 11, k + 93, Blocks.dirt);
		world.setBlock(i + 35, j + 11, k + 94, Blocks.dirt);
		world.setBlock(i + 35, j + 12, k + 0, Blocks.grass);
		world.setBlock(i + 35, j + 12, k + 1, Blocks.grass);
		world.setBlock(i + 35, j + 12, k + 2, Blocks.grass);
		world.setBlock(i + 35, j + 12, k + 3, Blocks.grass);
		world.setBlock(i + 35, j + 12, k + 4, Blocks.grass);
		world.setBlock(i + 35, j + 12, k + 53, Blocks.grass);
		world.setBlock(i + 35, j + 12, k + 54, Blocks.grass);
		world.setBlock(i + 35, j + 12, k + 55, Blocks.grass);
		world.setBlock(i + 35, j + 12, k + 56, Blocks.grass);
		world.setBlock(i + 35, j + 12, k + 57, Blocks.grass);
		world.setBlock(i + 35, j + 12, k + 58, Blocks.dirt);
		world.setBlock(i + 35, j + 12, k + 59, Blocks.dirt);
		world.setBlock(i + 35, j + 12, k + 60, Blocks.dirt);
		world.setBlock(i + 35, j + 12, k + 61, Blocks.dirt);
		world.setBlock(i + 35, j + 12, k + 62, Blocks.dirt);
		world.setBlock(i + 35, j + 12, k + 63, Blocks.dirt);
		world.setBlock(i + 35, j + 12, k + 64, Blocks.dirt);
		world.setBlock(i + 35, j + 12, k + 65, Blocks.dirt);
		world.setBlock(i + 35, j + 12, k + 66, Blocks.dirt);
		world.setBlock(i + 35, j + 12, k + 67, Blocks.dirt);
		world.setBlock(i + 35, j + 12, k + 68, Blocks.dirt);
		world.setBlock(i + 35, j + 12, k + 69, Blocks.dirt);
		world.setBlock(i + 35, j + 12, k + 70, Blocks.dirt);
		world.setBlock(i + 35, j + 12, k + 71, Blocks.dirt);
		world.setBlock(i + 35, j + 12, k + 72, Blocks.dirt);
		world.setBlock(i + 35, j + 12, k + 73, Blocks.dirt);
		world.setBlock(i + 35, j + 12, k + 74, Blocks.dirt);
		world.setBlock(i + 35, j + 12, k + 75, Blocks.dirt);
		world.setBlock(i + 35, j + 12, k + 76, Blocks.dirt);
		world.setBlock(i + 35, j + 12, k + 77, Blocks.dirt);
		world.setBlock(i + 35, j + 12, k + 78, Blocks.dirt);
		world.setBlock(i + 35, j + 12, k + 79, Blocks.dirt);
		world.setBlock(i + 35, j + 12, k + 80, Blocks.dirt);
		world.setBlock(i + 35, j + 12, k + 81, Blocks.dirt);
		world.setBlock(i + 35, j + 12, k + 82, Blocks.dirt);
		world.setBlock(i + 35, j + 12, k + 83, Blocks.dirt);
		world.setBlock(i + 35, j + 12, k + 84, Blocks.dirt);
		world.setBlock(i + 35, j + 12, k + 85, Blocks.dirt);
		world.setBlock(i + 35, j + 12, k + 86, Blocks.dirt);
		world.setBlock(i + 35, j + 12, k + 87, Blocks.dirt);
		world.setBlock(i + 35, j + 12, k + 88, Blocks.dirt);
		world.setBlock(i + 35, j + 12, k + 89, Blocks.dirt);
		world.setBlock(i + 35, j + 12, k + 90, Blocks.dirt);
		world.setBlock(i + 35, j + 12, k + 91, Blocks.dirt);
		world.setBlock(i + 35, j + 12, k + 92, Blocks.dirt);
		world.setBlock(i + 35, j + 12, k + 93, Blocks.grass);
		world.setBlock(i + 35, j + 12, k + 94, Blocks.grass);
		world.setBlock(i + 35, j + 13, k + 58, Blocks.planks, 1, 4);
		world.setBlock(i + 35, j + 13, k + 59, Blocks.grass);
		world.setBlock(i + 35, j + 13, k + 60, Blocks.grass);
		world.setBlock(i + 35, j + 13, k + 61, Blocks.grass);
		world.setBlock(i + 35, j + 13, k + 62, Blocks.grass);
		world.setBlock(i + 35, j + 13, k + 63, Blocks.grass);
		world.setBlock(i + 35, j + 13, k + 64, Blocks.quartz_block);
		world.setBlock(i + 35, j + 13, k + 65, Blocks.quartz_block);
		world.setBlock(i + 35, j + 13, k + 66, Blocks.grass);
		world.setBlock(i + 35, j + 13, k + 67, Blocks.grass);
		world.setBlock(i + 35, j + 13, k + 68, Blocks.grass);
		world.setBlock(i + 35, j + 13, k + 69, Blocks.grass);
		world.setBlock(i + 35, j + 13, k + 70, Blocks.planks, 1, 4);
		world.setBlock(i + 35, j + 13, k + 71, Blocks.planks, 1, 4);
		world.setBlock(i + 35, j + 13, k + 72, Blocks.planks, 1, 4);
		world.setBlock(i + 35, j + 13, k + 73, Blocks.planks, 1, 4);
		world.setBlock(i + 35, j + 13, k + 74, Blocks.planks, 1, 4);
		world.setBlock(i + 35, j + 13, k + 75, Blocks.planks, 1, 4);
		world.setBlock(i + 35, j + 13, k + 76, Blocks.planks, 1, 4);
		world.setBlock(i + 35, j + 13, k + 77, Blocks.planks, 1, 4);
		world.setBlock(i + 35, j + 13, k + 78, Blocks.planks, 1, 4);
		world.setBlock(i + 35, j + 13, k + 79, Blocks.planks, 1, 4);
		world.setBlock(i + 35, j + 13, k + 80, Blocks.planks, 1, 4);
		world.setBlock(i + 35, j + 13, k + 81, Blocks.grass);
		world.setBlock(i + 35, j + 13, k + 82, Blocks.grass);
		world.setBlock(i + 35, j + 13, k + 83, Blocks.grass);
		world.setBlock(i + 35, j + 13, k + 84, Blocks.grass);
		world.setBlock(i + 35, j + 13, k + 85, Blocks.grass);
		world.setBlock(i + 35, j + 13, k + 86, Blocks.grass);
		world.setBlock(i + 35, j + 13, k + 87, Blocks.grass);
		world.setBlock(i + 35, j + 13, k + 88, Blocks.grass);
		world.setBlock(i + 35, j + 13, k + 89, Blocks.grass);
		world.setBlock(i + 35, j + 13, k + 90, Blocks.dirt);
		world.setBlock(i + 35, j + 13, k + 91, Blocks.grass);
		world.setBlock(i + 35, j + 13, k + 92, Blocks.grass);
		world.setBlock(i + 35, j + 14, k + 58, Blocks.planks, 1, 4);
		world.setBlock(i + 35, j + 14, k + 70, Blocks.log2, 1, 4);
		world.setBlock(i + 35, j + 14, k + 71, Blocks.log2, 1, 4);
		world.setBlock(i + 35, j + 14, k + 72, Blocks.log2, 1, 4);
		world.setBlock(i + 35, j + 14, k + 73, Blocks.log2, 1, 4);
		world.setBlock(i + 35, j + 14, k + 77, Blocks.log2, 1, 4);
		world.setBlock(i + 35, j + 14, k + 78, Blocks.log2, 1, 4);
		world.setBlock(i + 35, j + 14, k + 79, Blocks.log2, 1, 4);
		world.setBlock(i + 35, j + 14, k + 80, Blocks.log2, 1, 4);
		world.setBlock(i + 35, j + 14, k + 90, Blocks.planks, 1, 4);
		world.setBlock(i + 35, j + 15, k + 58, Blocks.planks, 1, 4);
		world.setBlock(i + 35, j + 15, k + 70, Blocks.log2, 1, 4);
		world.setBlock(i + 35, j + 15, k + 71, Blocks.planks, 1, 4);
		world.setBlock(i + 35, j + 15, k + 72, Blocks.wooden_slab, 1, 4);
		world.setBlock(i + 35, j + 15, k + 73, Blocks.log2, 1, 4);
		world.setBlock(i + 35, j + 15, k + 77, Blocks.log2, 1, 4);
		world.setBlock(i + 35, j + 15, k + 78, Blocks.wooden_slab, 1, 4);
		world.setBlock(i + 35, j + 15, k + 79, Blocks.planks, 1, 4);
		world.setBlock(i + 35, j + 15, k + 80, Blocks.log2, 1, 4);
		world.setBlock(i + 35, j + 15, k + 90, Blocks.planks, 1, 4);
		world.setBlock(i + 35, j + 16, k + 58, Blocks.planks, 1, 4);
		world.setBlock(i + 35, j + 16, k + 70, Blocks.log2, 1, 4);
		world.setBlock(i + 35, j + 16, k + 71, Blocks.planks, 1, 4);
		world.setBlock(i + 35, j + 16, k + 73, Blocks.log2, 1, 4);
		world.setBlock(i + 35, j + 16, k + 77, Blocks.log2, 1, 4);
		world.setBlock(i + 35, j + 16, k + 79, Blocks.planks, 1, 4);
		world.setBlock(i + 35, j + 16, k + 80, Blocks.log2, 1, 4);
		world.setBlock(i + 35, j + 16, k + 90, Blocks.planks, 1, 4);
		world.setBlock(i + 35, j + 17, k + 58, Blocks.planks, 1, 4);
		world.setBlock(i + 35, j + 17, k + 69, Blocks.dark_oak_stairs, 6, 4);
		world.setBlock(i + 35, j + 17, k + 70, Blocks.log2, 1, 4);
		world.setBlock(i + 35, j + 17, k + 71, Blocks.planks, 1, 4);
		world.setBlock(i + 35, j + 17, k + 72, Blocks.planks, 1, 4);
		world.setBlock(i + 35, j + 17, k + 73, Blocks.log2, 1, 4);
		world.setBlock(i + 35, j + 17, k + 74, Blocks.wooden_slab, 13, 4);
		world.setBlock(i + 35, j + 17, k + 75, Blocks.wooden_slab, 13, 4);
		world.setBlock(i + 35, j + 17, k + 76, Blocks.wooden_slab, 13, 4);
		world.setBlock(i + 35, j + 17, k + 77, Blocks.log2, 1, 4);
		world.setBlock(i + 35, j + 17, k + 78, Blocks.planks, 1, 4);
		world.setBlock(i + 35, j + 17, k + 79, Blocks.planks, 1, 4);
		world.setBlock(i + 35, j + 17, k + 80, Blocks.log2, 1, 4);
		world.setBlock(i + 35, j + 17, k + 81, Blocks.dark_oak_stairs, 7, 4);
		world.setBlock(i + 35, j + 17, k + 90, Blocks.planks, 1, 4);
		world.setBlock(i + 35, j + 18, k + 58, Blocks.fence);
		world.setBlock(i + 35, j + 18, k + 70, Blocks.log2, 1, 4);
		world.setBlock(i + 35, j + 18, k + 71, Blocks.planks, 1, 4);
		world.setBlock(i + 35, j + 18, k + 72, Blocks.planks, 1, 4);
		world.setBlock(i + 35, j + 18, k + 73, Blocks.log2, 1, 4);
		world.setBlock(i + 35, j + 18, k + 77, Blocks.log2, 1, 4);
		world.setBlock(i + 35, j + 18, k + 78, Blocks.planks, 1, 4);
		world.setBlock(i + 35, j + 18, k + 79, Blocks.planks, 1, 4);
		world.setBlock(i + 35, j + 18, k + 80, Blocks.log2, 1, 4);
		world.setBlock(i + 35, j + 18, k + 90, Blocks.fence);
		world.setBlock(i + 35, j + 19, k + 70, Blocks.log2, 1, 4);
		world.setBlock(i + 35, j + 19, k + 71, Blocks.planks, 1, 4);
		world.setBlock(i + 35, j + 19, k + 72, Blocks.planks, 1, 4);
		world.setBlock(i + 35, j + 19, k + 73, Blocks.log2, 1, 4);
		world.setBlock(i + 35, j + 19, k + 77, Blocks.log2, 1, 4);
		world.setBlock(i + 35, j + 19, k + 78, Blocks.planks, 1, 4);
		world.setBlock(i + 35, j + 19, k + 79, Blocks.planks, 1, 4);
		world.setBlock(i + 35, j + 19, k + 80, Blocks.log2, 1, 4);
		world.setBlock(i + 35, j + 20, k + 70, Blocks.log2, 1, 4);
		world.setBlock(i + 35, j + 20, k + 71, Blocks.planks, 1, 4);
		world.setBlock(i + 35, j + 20, k + 72, Blocks.planks, 1, 4);
		world.setBlock(i + 35, j + 20, k + 73, Blocks.log2, 1, 4);
		world.setBlock(i + 35, j + 20, k + 77, Blocks.log2, 1, 4);
		world.setBlock(i + 35, j + 20, k + 78, Blocks.planks, 1, 4);
		world.setBlock(i + 35, j + 20, k + 79, Blocks.planks, 1, 4);
		world.setBlock(i + 35, j + 20, k + 80, Blocks.log2, 1, 4);
		world.setBlock(i + 35, j + 21, k + 69, Blocks.dark_oak_stairs, 2, 4);
		world.setBlock(i + 35, j + 21, k + 70, Blocks.log2, 1, 4);
		world.setBlock(i + 35, j + 21, k + 71, Blocks.planks, 1, 4);
		world.setBlock(i + 35, j + 21, k + 72, Blocks.planks, 1, 4);
		world.setBlock(i + 35, j + 21, k + 73, Blocks.planks, 1, 4);
		world.setBlock(i + 35, j + 21, k + 74, Blocks.dark_oak_stairs, 7, 4);
		world.setBlock(i + 35, j + 21, k + 75, Blocks.dark_oak_stairs, 5, 4);
		world.setBlock(i + 35, j + 21, k + 76, Blocks.dark_oak_stairs, 6, 4);
		world.setBlock(i + 35, j + 21, k + 77, Blocks.planks, 1, 4);
		world.setBlock(i + 35, j + 21, k + 78, Blocks.planks, 1, 4);
		world.setBlock(i + 35, j + 21, k + 79, Blocks.planks, 1, 4);
		world.setBlock(i + 35, j + 21, k + 80, Blocks.log2, 1, 4);
		world.setBlock(i + 35, j + 21, k + 81, Blocks.dark_oak_stairs, 3, 4);
		world.setBlock(i + 35, j + 22, k + 70, Blocks.dark_oak_stairs, 2, 4);
		world.setBlock(i + 35, j + 22, k + 71, Blocks.planks, 1, 4);
		world.setBlock(i + 35, j + 22, k + 72, Blocks.planks, 1, 4);
		world.setBlock(i + 35, j + 22, k + 73, Blocks.planks, 1, 4);
		world.setBlock(i + 35, j + 22, k + 74, Blocks.planks, 1, 4);
		world.setBlock(i + 35, j + 22, k + 75, Blocks.planks, 1, 4);
		world.setBlock(i + 35, j + 22, k + 76, Blocks.planks, 1, 4);
		world.setBlock(i + 35, j + 22, k + 77, Blocks.planks, 1, 4);
		world.setBlock(i + 35, j + 22, k + 78, Blocks.planks, 1, 4);
		world.setBlock(i + 35, j + 22, k + 79, Blocks.planks, 1, 4);
		world.setBlock(i + 35, j + 22, k + 80, Blocks.dark_oak_stairs, 3, 4);
		world.setBlock(i + 35, j + 23, k + 71, Blocks.dark_oak_stairs, 2, 4);
		world.setBlock(i + 35, j + 23, k + 72, Blocks.planks, 1, 4);
		world.setBlock(i + 35, j + 23, k + 73, Blocks.planks, 1, 4);
		world.setBlock(i + 35, j + 23, k + 74, Blocks.stained_glass_pane);
		world.setBlock(i + 35, j + 23, k + 75, Blocks.stained_glass_pane);
		world.setBlock(i + 35, j + 23, k + 76, Blocks.stained_glass_pane);
		world.setBlock(i + 35, j + 23, k + 77, Blocks.planks, 1, 4);
		world.setBlock(i + 35, j + 23, k + 78, Blocks.planks, 1, 4);
		world.setBlock(i + 35, j + 23, k + 79, Blocks.dark_oak_stairs, 3, 4);
		world.setBlock(i + 35, j + 24, k + 72, Blocks.dark_oak_stairs, 2, 4);
		world.setBlock(i + 35, j + 24, k + 73, Blocks.planks, 1, 4);
		world.setBlock(i + 35, j + 24, k + 74, Blocks.planks, 1, 4);
		world.setBlock(i + 35, j + 24, k + 75, Blocks.stained_glass_pane);
		world.setBlock(i + 35, j + 24, k + 76, Blocks.planks, 1, 4);
		world.setBlock(i + 35, j + 24, k + 77, Blocks.planks, 1, 4);
		world.setBlock(i + 35, j + 24, k + 78, Blocks.dark_oak_stairs, 3, 4);
		world.setBlock(i + 35, j + 25, k + 73, Blocks.dark_oak_stairs, 2, 4);
		world.setBlock(i + 35, j + 25, k + 74, Blocks.planks, 1, 4);
		world.setBlock(i + 35, j + 25, k + 75, Blocks.planks, 1, 4);
		world.setBlock(i + 35, j + 25, k + 76, Blocks.planks, 1, 4);
		world.setBlock(i + 35, j + 25, k + 77, Blocks.dark_oak_stairs, 3, 4);
		world.setBlock(i + 35, j + 26, k + 74, Blocks.dark_oak_stairs, 2, 4);
		world.setBlock(i + 35, j + 26, k + 75, Blocks.planks, 5, 4);
		world.setBlock(i + 35, j + 26, k + 76, Blocks.dark_oak_stairs, 3, 4);
		world.setBlock(i + 36, j + 0, k + 70, Blocks.stone);
		world.setBlock(i + 36, j + 0, k + 71, Blocks.stone);
		world.setBlock(i + 36, j + 0, k + 72, Blocks.stone);
		world.setBlock(i + 36, j + 0, k + 73, Blocks.stone);
		world.setBlock(i + 36, j + 0, k + 74, Blocks.stone);
		world.setBlock(i + 36, j + 0, k + 75, Blocks.stone);
		world.setBlock(i + 36, j + 0, k + 76, Blocks.stone);
		world.setBlock(i + 36, j + 0, k + 77, Blocks.stone);
		world.setBlock(i + 36, j + 0, k + 78, Blocks.stone);
		world.setBlock(i + 36, j + 1, k + 67, Blocks.stone);
		world.setBlock(i + 36, j + 1, k + 68, Blocks.stone);
		world.setBlock(i + 36, j + 1, k + 69, Blocks.stone);
		world.setBlock(i + 36, j + 1, k + 70, Blocks.stone);
		world.setBlock(i + 36, j + 1, k + 71, Blocks.stone);
		world.setBlock(i + 36, j + 1, k + 72, Blocks.stone);
		world.setBlock(i + 36, j + 1, k + 73, Blocks.stone);
		world.setBlock(i + 36, j + 1, k + 74, Blocks.stone);
		world.setBlock(i + 36, j + 1, k + 75, Blocks.stone);
		world.setBlock(i + 36, j + 1, k + 76, Blocks.stone);
		world.setBlock(i + 36, j + 1, k + 77, Blocks.stone);
		world.setBlock(i + 36, j + 1, k + 78, Blocks.stone);
		world.setBlock(i + 36, j + 1, k + 79, Blocks.stone);
		world.setBlock(i + 36, j + 1, k + 80, Blocks.stone);
		world.setBlock(i + 36, j + 1, k + 81, Blocks.stone);
		world.setBlock(i + 36, j + 2, k + 65, Blocks.stone);
		world.setBlock(i + 36, j + 2, k + 66, Blocks.stone);
		world.setBlock(i + 36, j + 2, k + 67, Blocks.stone);
		world.setBlock(i + 36, j + 2, k + 68, Blocks.stone);
		world.setBlock(i + 36, j + 2, k + 69, Blocks.stone);
		world.setBlock(i + 36, j + 2, k + 70, Blocks.stone);
		world.setBlock(i + 36, j + 2, k + 71, Blocks.stone);
		world.setBlock(i + 36, j + 2, k + 72, Blocks.stone);
		world.setBlock(i + 36, j + 2, k + 73, Blocks.stone);
		world.setBlock(i + 36, j + 2, k + 74, Blocks.stone);
		world.setBlock(i + 36, j + 2, k + 75, Blocks.stone);
		world.setBlock(i + 36, j + 2, k + 76, Blocks.stone);
		world.setBlock(i + 36, j + 2, k + 77, Blocks.stone);
		world.setBlock(i + 36, j + 2, k + 78, Blocks.stone);
		world.setBlock(i + 36, j + 2, k + 79, Blocks.stone);
		world.setBlock(i + 36, j + 2, k + 80, Blocks.stone);
		world.setBlock(i + 36, j + 2, k + 81, Blocks.stone);
		world.setBlock(i + 36, j + 2, k + 82, Blocks.stone);
		world.setBlock(i + 36, j + 2, k + 83, Blocks.stone);
		world.setBlock(i + 36, j + 2, k + 84, Blocks.stone);
		world.setBlock(i + 36, j + 3, k + 62, Blocks.stone);
		world.setBlock(i + 36, j + 3, k + 63, Blocks.stone);
		world.setBlock(i + 36, j + 3, k + 64, Blocks.stone);
		world.setBlock(i + 36, j + 3, k + 65, Blocks.stone);
		world.setBlock(i + 36, j + 3, k + 66, Blocks.stone);
		world.setBlock(i + 36, j + 3, k + 67, Blocks.stone);
		world.setBlock(i + 36, j + 3, k + 68, Blocks.stone);
		world.setBlock(i + 36, j + 3, k + 69, Blocks.stone);
		world.setBlock(i + 36, j + 3, k + 70, Blocks.stone);
		world.setBlock(i + 36, j + 3, k + 71, Blocks.stone);
		world.setBlock(i + 36, j + 3, k + 72, Blocks.stone);
		world.setBlock(i + 36, j + 3, k + 73, Blocks.stone);
		world.setBlock(i + 36, j + 3, k + 74, Blocks.stone);
		world.setBlock(i + 36, j + 3, k + 75, Blocks.stone);
		world.setBlock(i + 36, j + 3, k + 76, Blocks.stone);
		world.setBlock(i + 36, j + 3, k + 77, Blocks.stone);
		world.setBlock(i + 36, j + 3, k + 78, Blocks.stone);
		world.setBlock(i + 36, j + 3, k + 79, Blocks.stone);
		world.setBlock(i + 36, j + 3, k + 80, Blocks.stone);
		world.setBlock(i + 36, j + 3, k + 81, Blocks.stone);
		world.setBlock(i + 36, j + 3, k + 82, Blocks.stone);
		world.setBlock(i + 36, j + 3, k + 83, Blocks.stone);
		world.setBlock(i + 36, j + 3, k + 84, Blocks.stone);
		world.setBlock(i + 36, j + 3, k + 85, Blocks.stone);
		world.setBlock(i + 36, j + 3, k + 86, Blocks.stone);
		world.setBlock(i + 36, j + 3, k + 87, Blocks.stone);
		world.setBlock(i + 36, j + 4, k + 61, Blocks.stone);
		world.setBlock(i + 36, j + 4, k + 62, Blocks.stone);
		world.setBlock(i + 36, j + 4, k + 63, Blocks.stone);
		world.setBlock(i + 36, j + 4, k + 64, Blocks.stone);
		world.setBlock(i + 36, j + 4, k + 65, Blocks.stone);
		world.setBlock(i + 36, j + 4, k + 66, Blocks.stone);
		world.setBlock(i + 36, j + 4, k + 67, Blocks.stone);
		world.setBlock(i + 36, j + 4, k + 68, Blocks.stone);
		world.setBlock(i + 36, j + 4, k + 69, Blocks.stone);
		world.setBlock(i + 36, j + 4, k + 70, Blocks.stone);
		world.setBlock(i + 36, j + 4, k + 71, Blocks.stone);
		world.setBlock(i + 36, j + 4, k + 72, Blocks.stone);
		world.setBlock(i + 36, j + 4, k + 73, Blocks.stone);
		world.setBlock(i + 36, j + 4, k + 74, Blocks.stone);
		world.setBlock(i + 36, j + 4, k + 75, Blocks.stone);
		world.setBlock(i + 36, j + 4, k + 76, Blocks.stone);
		world.setBlock(i + 36, j + 4, k + 77, Blocks.stone);
		world.setBlock(i + 36, j + 4, k + 78, Blocks.stone);
		world.setBlock(i + 36, j + 4, k + 79, Blocks.stone);
		world.setBlock(i + 36, j + 4, k + 80, Blocks.stone);
		world.setBlock(i + 36, j + 4, k + 81, Blocks.stone);
		world.setBlock(i + 36, j + 4, k + 82, Blocks.stone);
		world.setBlock(i + 36, j + 4, k + 83, Blocks.stone);
		world.setBlock(i + 36, j + 4, k + 84, Blocks.stone);
		world.setBlock(i + 36, j + 4, k + 85, Blocks.stone);
		world.setBlock(i + 36, j + 4, k + 86, Blocks.stone);
		world.setBlock(i + 36, j + 4, k + 87, Blocks.stone);
		world.setBlock(i + 36, j + 4, k + 88, Blocks.stone);
		world.setBlock(i + 36, j + 5, k + 59, Blocks.stone);
		world.setBlock(i + 36, j + 5, k + 60, Blocks.stone);
		world.setBlock(i + 36, j + 5, k + 61, Blocks.stone);
		world.setBlock(i + 36, j + 5, k + 62, Blocks.stone);
		world.setBlock(i + 36, j + 5, k + 63, Blocks.stone);
		world.setBlock(i + 36, j + 5, k + 64, Blocks.stone);
		world.setBlock(i + 36, j + 5, k + 65, Blocks.stone);
		world.setBlock(i + 36, j + 5, k + 66, Blocks.stone);
		world.setBlock(i + 36, j + 5, k + 67, Blocks.stone);
		world.setBlock(i + 36, j + 5, k + 68, Blocks.stone);
		world.setBlock(i + 36, j + 5, k + 69, Blocks.stone);
		world.setBlock(i + 36, j + 5, k + 70, Blocks.stone);
		world.setBlock(i + 36, j + 5, k + 71, Blocks.stone);
		world.setBlock(i + 36, j + 5, k + 72, Blocks.stone);
		world.setBlock(i + 36, j + 5, k + 73, Blocks.stone);
		world.setBlock(i + 36, j + 5, k + 74, Blocks.stone);
		world.setBlock(i + 36, j + 5, k + 75, Blocks.stone);
		world.setBlock(i + 36, j + 5, k + 76, Blocks.stone);
		world.setBlock(i + 36, j + 5, k + 77, Blocks.stone);
		world.setBlock(i + 36, j + 5, k + 78, Blocks.stone);
		world.setBlock(i + 36, j + 5, k + 79, Blocks.stone);
		world.setBlock(i + 36, j + 5, k + 80, Blocks.stone);
		world.setBlock(i + 36, j + 5, k + 81, Blocks.stone);
		world.setBlock(i + 36, j + 5, k + 82, Blocks.stone);
		world.setBlock(i + 36, j + 5, k + 83, Blocks.stone);
		world.setBlock(i + 36, j + 5, k + 84, Blocks.stone);
		world.setBlock(i + 36, j + 5, k + 85, Blocks.stone);
		world.setBlock(i + 36, j + 5, k + 86, Blocks.stone);
		world.setBlock(i + 36, j + 5, k + 87, Blocks.stone);
		world.setBlock(i + 36, j + 5, k + 88, Blocks.stone);
		world.setBlock(i + 36, j + 5, k + 89, Blocks.stone);
		world.setBlock(i + 36, j + 6, k + 58, Blocks.stone);
		world.setBlock(i + 36, j + 6, k + 59, Blocks.stone);
		world.setBlock(i + 36, j + 6, k + 60, Blocks.stone);
		world.setBlock(i + 36, j + 6, k + 61, Blocks.stone);
		world.setBlock(i + 36, j + 6, k + 62, Blocks.stone);
		world.setBlock(i + 36, j + 6, k + 63, Blocks.stone);
		world.setBlock(i + 36, j + 6, k + 64, Blocks.stone);
		world.setBlock(i + 36, j + 6, k + 65, Blocks.stone);
		world.setBlock(i + 36, j + 6, k + 66, Blocks.stone);
		world.setBlock(i + 36, j + 6, k + 67, Blocks.stone);
		world.setBlock(i + 36, j + 6, k + 68, Blocks.stone);
		world.setBlock(i + 36, j + 6, k + 69, Blocks.stone);
		world.setBlock(i + 36, j + 6, k + 70, Blocks.stone);
		world.setBlock(i + 36, j + 6, k + 71, Blocks.stone);
		world.setBlock(i + 36, j + 6, k + 72, Blocks.stone);
		world.setBlock(i + 36, j + 6, k + 73, Blocks.stone);
		world.setBlock(i + 36, j + 6, k + 74, Blocks.stone);
		world.setBlock(i + 36, j + 6, k + 75, Blocks.stone);
		world.setBlock(i + 36, j + 6, k + 76, Blocks.stone);
		world.setBlock(i + 36, j + 6, k + 77, Blocks.stone);
		world.setBlock(i + 36, j + 6, k + 78, Blocks.stone);
		world.setBlock(i + 36, j + 6, k + 79, Blocks.stone);
		world.setBlock(i + 36, j + 6, k + 80, Blocks.stone);
		world.setBlock(i + 36, j + 6, k + 81, Blocks.stone);
		world.setBlock(i + 36, j + 6, k + 82, Blocks.stone);
		world.setBlock(i + 36, j + 6, k + 83, Blocks.stone);
		world.setBlock(i + 36, j + 6, k + 84, Blocks.stone);
		world.setBlock(i + 36, j + 6, k + 85, Blocks.stone);
		world.setBlock(i + 36, j + 6, k + 86, Blocks.stone);
		world.setBlock(i + 36, j + 6, k + 87, Blocks.stone);
		world.setBlock(i + 36, j + 6, k + 88, Blocks.stone);
		world.setBlock(i + 36, j + 6, k + 89, Blocks.stone);
		world.setBlock(i + 36, j + 6, k + 90, Blocks.stone);
		world.setBlock(i + 36, j + 7, k + 57, Blocks.stone);
		world.setBlock(i + 36, j + 7, k + 58, Blocks.stone);
		world.setBlock(i + 36, j + 7, k + 59, Blocks.stone);
		world.setBlock(i + 36, j + 7, k + 60, Blocks.stone);
		world.setBlock(i + 36, j + 7, k + 61, Blocks.stone);
		world.setBlock(i + 36, j + 7, k + 62, Blocks.stone);
		world.setBlock(i + 36, j + 7, k + 63, Blocks.stone);
		world.setBlock(i + 36, j + 7, k + 64, Blocks.stone);
		world.setBlock(i + 36, j + 7, k + 65, Blocks.stone);
		world.setBlock(i + 36, j + 7, k + 66, Blocks.stone);
		world.setBlock(i + 36, j + 7, k + 67, Blocks.stone);
		world.setBlock(i + 36, j + 7, k + 68, Blocks.stone);
		world.setBlock(i + 36, j + 7, k + 69, Blocks.stone);
		world.setBlock(i + 36, j + 7, k + 70, Blocks.stone);
		world.setBlock(i + 36, j + 7, k + 71, Blocks.stone);
		world.setBlock(i + 36, j + 7, k + 72, Blocks.stone);
		world.setBlock(i + 36, j + 7, k + 73, Blocks.stone);
		world.setBlock(i + 36, j + 7, k + 74, Blocks.stone);
		world.setBlock(i + 36, j + 7, k + 75, Blocks.stone);
		world.setBlock(i + 36, j + 7, k + 76, Blocks.stone);
		world.setBlock(i + 36, j + 7, k + 77, Blocks.stone);
		world.setBlock(i + 36, j + 7, k + 78, Blocks.stone);
		world.setBlock(i + 36, j + 7, k + 79, Blocks.stone);
		world.setBlock(i + 36, j + 7, k + 80, Blocks.stone);
		world.setBlock(i + 36, j + 7, k + 81, Blocks.stone);
		world.setBlock(i + 36, j + 7, k + 82, Blocks.stone);
		world.setBlock(i + 36, j + 7, k + 83, Blocks.stone);
		world.setBlock(i + 36, j + 7, k + 84, Blocks.stone);
		world.setBlock(i + 36, j + 7, k + 85, Blocks.stone);
		world.setBlock(i + 36, j + 7, k + 86, Blocks.stone);
		world.setBlock(i + 36, j + 7, k + 87, Blocks.stone);
		world.setBlock(i + 36, j + 7, k + 88, Blocks.stone);
		world.setBlock(i + 36, j + 7, k + 89, Blocks.stone);
		world.setBlock(i + 36, j + 7, k + 90, Blocks.stone);
		world.setBlock(i + 36, j + 7, k + 91, Blocks.stone);
		world.setBlock(i + 36, j + 8, k + 56, Wildycraft.denseStone);
		world.setBlock(i + 36, j + 8, k + 57, Wildycraft.denseStone);
		world.setBlock(i + 36, j + 8, k + 58, Wildycraft.denseStone);
		world.setBlock(i + 36, j + 8, k + 59, Wildycraft.denseStone);
		world.setBlock(i + 36, j + 8, k + 60, Wildycraft.denseStone);
		world.setBlock(i + 36, j + 8, k + 61, Wildycraft.denseStone);
		world.setBlock(i + 36, j + 8, k + 62, Wildycraft.denseStone);
		world.setBlock(i + 36, j + 8, k + 63, Wildycraft.denseStone);
		world.setBlock(i + 36, j + 8, k + 64, Wildycraft.denseStone);
		world.setBlock(i + 36, j + 8, k + 65, Wildycraft.denseStone);
		world.setBlock(i + 36, j + 8, k + 66, Wildycraft.denseStone);
		world.setBlock(i + 36, j + 8, k + 67, Wildycraft.denseStone);
		world.setBlock(i + 36, j + 8, k + 68, Wildycraft.denseStone);
		world.setBlock(i + 36, j + 8, k + 69, Wildycraft.denseStone);
		world.setBlock(i + 36, j + 8, k + 70, Wildycraft.denseStone);
		world.setBlock(i + 36, j + 8, k + 71, Wildycraft.denseStone);
		world.setBlock(i + 36, j + 8, k + 72, Wildycraft.denseStone);
		world.setBlock(i + 36, j + 8, k + 73, Wildycraft.denseStone);
		world.setBlock(i + 36, j + 8, k + 74, Wildycraft.denseStone);
		world.setBlock(i + 36, j + 8, k + 75, Wildycraft.denseStone);
		world.setBlock(i + 36, j + 8, k + 76, Wildycraft.denseStone);
		world.setBlock(i + 36, j + 8, k + 77, Wildycraft.denseStone);
		world.setBlock(i + 36, j + 8, k + 78, Wildycraft.denseStone);
		world.setBlock(i + 36, j + 8, k + 79, Wildycraft.denseStone);
		world.setBlock(i + 36, j + 8, k + 80, Wildycraft.denseStone);
		world.setBlock(i + 36, j + 8, k + 81, Wildycraft.denseStone);
		world.setBlock(i + 36, j + 8, k + 82, Wildycraft.denseStone);
		world.setBlock(i + 36, j + 8, k + 83, Wildycraft.denseStone);
		world.setBlock(i + 36, j + 8, k + 84, Wildycraft.denseStone);
		world.setBlock(i + 36, j + 8, k + 85, Wildycraft.denseStone);
		world.setBlock(i + 36, j + 8, k + 86, Wildycraft.denseStone);
		world.setBlock(i + 36, j + 8, k + 87, Wildycraft.denseStone);
		world.setBlock(i + 36, j + 8, k + 88, Wildycraft.denseStone);
		world.setBlock(i + 36, j + 8, k + 89, Wildycraft.denseStone);
		world.setBlock(i + 36, j + 8, k + 90, Wildycraft.denseStone);
		world.setBlock(i + 36, j + 8, k + 91, Wildycraft.denseStone);
		world.setBlock(i + 36, j + 8, k + 92, Wildycraft.denseStone);
		world.setBlock(i + 36, j + 8, k + 93, Wildycraft.denseStone);
		world.setBlock(i + 36, j + 9, k + 55, Wildycraft.denseStone);
		world.setBlock(i + 36, j + 9, k + 56, Wildycraft.denseStone);
		world.setBlock(i + 36, j + 9, k + 57, Wildycraft.denseStone);
		world.setBlock(i + 36, j + 9, k + 58, Wildycraft.denseStone);
		world.setBlock(i + 36, j + 9, k + 59, Wildycraft.denseStone);
		world.setBlock(i + 36, j + 9, k + 60, Wildycraft.denseStone);
		world.setBlock(i + 36, j + 9, k + 61, Wildycraft.denseStone);
		world.setBlock(i + 36, j + 9, k + 62, Wildycraft.denseStone);
		world.setBlock(i + 36, j + 9, k + 63, Wildycraft.denseStone);
		world.setBlock(i + 36, j + 9, k + 64, Wildycraft.denseStone);
		world.setBlock(i + 36, j + 9, k + 65, Wildycraft.denseStone);
		world.setBlock(i + 36, j + 9, k + 66, Wildycraft.denseStone);
		world.setBlock(i + 36, j + 9, k + 67, Wildycraft.denseStone);
		world.setBlock(i + 36, j + 9, k + 68, Wildycraft.denseStone);
		world.setBlock(i + 36, j + 9, k + 69, Wildycraft.denseStone);
		world.setBlock(i + 36, j + 9, k + 70, Wildycraft.denseStone);
		world.setBlock(i + 36, j + 9, k + 71, Wildycraft.denseStone);
		world.setBlock(i + 36, j + 9, k + 72, Wildycraft.denseStone);
		world.setBlock(i + 36, j + 9, k + 73, Wildycraft.denseStone);
		world.setBlock(i + 36, j + 9, k + 74, Wildycraft.denseStone);
		world.setBlock(i + 36, j + 9, k + 75, Wildycraft.denseStone);
		world.setBlock(i + 36, j + 9, k + 76, Wildycraft.denseStone);
		world.setBlock(i + 36, j + 9, k + 77, Wildycraft.denseStone);
		world.setBlock(i + 36, j + 9, k + 78, Wildycraft.denseStone);
		world.setBlock(i + 36, j + 9, k + 79, Wildycraft.denseStone);
		world.setBlock(i + 36, j + 9, k + 80, Wildycraft.denseStone);
		world.setBlock(i + 36, j + 9, k + 81, Wildycraft.denseStone);
		world.setBlock(i + 36, j + 9, k + 82, Wildycraft.denseStone);
		world.setBlock(i + 36, j + 9, k + 83, Wildycraft.denseStone);
		world.setBlock(i + 36, j + 9, k + 84, Wildycraft.denseStone);
		world.setBlock(i + 36, j + 9, k + 85, Wildycraft.denseStone);
		world.setBlock(i + 36, j + 9, k + 86, Wildycraft.denseStone);
		world.setBlock(i + 36, j + 9, k + 87, Wildycraft.denseStone);
		world.setBlock(i + 36, j + 9, k + 88, Wildycraft.denseStone);
		world.setBlock(i + 36, j + 9, k + 89, Wildycraft.denseStone);
		world.setBlock(i + 36, j + 9, k + 90, Wildycraft.denseStone);
		world.setBlock(i + 36, j + 9, k + 91, Wildycraft.denseStone);
		world.setBlock(i + 36, j + 9, k + 92, Wildycraft.denseStone);
		world.setBlock(i + 36, j + 9, k + 93, Wildycraft.denseStone);
		world.setBlock(i + 36, j + 10, k + 2, Wildycraft.denseStone);
		world.setBlock(i + 36, j + 10, k + 55, Wildycraft.denseStone);
		world.setBlock(i + 36, j + 10, k + 56, Wildycraft.denseStone);
		world.setBlock(i + 36, j + 10, k + 57, Wildycraft.denseStone);
		world.setBlock(i + 36, j + 10, k + 58, Wildycraft.denseStone);
		world.setBlock(i + 36, j + 10, k + 59, Wildycraft.denseStone);
		world.setBlock(i + 36, j + 10, k + 60, Wildycraft.denseStone);
		world.setBlock(i + 36, j + 10, k + 61, Wildycraft.denseStone);
		world.setBlock(i + 36, j + 10, k + 62, Wildycraft.denseStone);
		world.setBlock(i + 36, j + 10, k + 63, Wildycraft.denseStone);
		world.setBlock(i + 36, j + 10, k + 64, Wildycraft.denseStone);
		world.setBlock(i + 36, j + 10, k + 65, Wildycraft.denseStone);
		world.setBlock(i + 36, j + 10, k + 66, Wildycraft.denseStone);
		world.setBlock(i + 36, j + 10, k + 67, Wildycraft.denseStone);
		world.setBlock(i + 36, j + 10, k + 68, Wildycraft.denseStone);
		world.setBlock(i + 36, j + 10, k + 69, Wildycraft.denseStone);
		world.setBlock(i + 36, j + 10, k + 70, Wildycraft.denseStone);
		world.setBlock(i + 36, j + 10, k + 71, Wildycraft.denseStone);
		world.setBlock(i + 36, j + 10, k + 72, Wildycraft.denseStone);
		world.setBlock(i + 36, j + 10, k + 73, Wildycraft.denseStone);
		world.setBlock(i + 36, j + 10, k + 74, Wildycraft.denseStone);
		world.setBlock(i + 36, j + 10, k + 75, Wildycraft.denseStone);
		world.setBlock(i + 36, j + 10, k + 76, Wildycraft.denseStone);
		world.setBlock(i + 36, j + 10, k + 77, Wildycraft.denseStone);
		world.setBlock(i + 36, j + 10, k + 78, Wildycraft.denseStone);
		world.setBlock(i + 36, j + 10, k + 79, Wildycraft.denseStone);
		world.setBlock(i + 36, j + 10, k + 80, Wildycraft.denseStone);
		world.setBlock(i + 36, j + 10, k + 81, Wildycraft.denseStone);
		world.setBlock(i + 36, j + 10, k + 82, Wildycraft.denseStone);
		world.setBlock(i + 36, j + 10, k + 83, Wildycraft.denseStone);
		world.setBlock(i + 36, j + 10, k + 84, Wildycraft.denseStone);
		world.setBlock(i + 36, j + 10, k + 85, Wildycraft.denseStone);
		world.setBlock(i + 36, j + 10, k + 86, Wildycraft.denseStone);
		world.setBlock(i + 36, j + 10, k + 87, Wildycraft.denseStone);
		world.setBlock(i + 36, j + 10, k + 88, Wildycraft.denseStone);
		world.setBlock(i + 36, j + 10, k + 89, Wildycraft.denseStone);
		world.setBlock(i + 36, j + 10, k + 90, Wildycraft.denseStone);
		world.setBlock(i + 36, j + 10, k + 91, Wildycraft.denseStone);
		world.setBlock(i + 36, j + 10, k + 92, Wildycraft.denseStone);
		world.setBlock(i + 36, j + 10, k + 93, Wildycraft.denseStone);
		world.setBlock(i + 36, j + 10, k + 94, Wildycraft.denseStone);
		world.setBlock(i + 36, j + 11, k + 1, Blocks.dirt);
		world.setBlock(i + 36, j + 11, k + 2, Blocks.dirt);
		world.setBlock(i + 36, j + 11, k + 3, Blocks.grass);
		world.setBlock(i + 36, j + 11, k + 54, Blocks.dirt);
		world.setBlock(i + 36, j + 11, k + 55, Blocks.dirt);
		world.setBlock(i + 36, j + 11, k + 56, Blocks.dirt);
		world.setBlock(i + 36, j + 11, k + 57, Blocks.dirt);
		world.setBlock(i + 36, j + 11, k + 58, Blocks.dirt);
		world.setBlock(i + 36, j + 11, k + 59, Blocks.dirt);
		world.setBlock(i + 36, j + 11, k + 60, Blocks.dirt);
		world.setBlock(i + 36, j + 11, k + 61, Blocks.dirt);
		world.setBlock(i + 36, j + 11, k + 62, Blocks.dirt);
		world.setBlock(i + 36, j + 11, k + 63, Blocks.dirt);
		world.setBlock(i + 36, j + 11, k + 64, Blocks.dirt);
		world.setBlock(i + 36, j + 11, k + 65, Blocks.dirt);
		world.setBlock(i + 36, j + 11, k + 66, Blocks.dirt);
		world.setBlock(i + 36, j + 11, k + 67, Blocks.dirt);
		world.setBlock(i + 36, j + 11, k + 68, Blocks.dirt);
		world.setBlock(i + 36, j + 11, k + 69, Blocks.dirt);
		world.setBlock(i + 36, j + 11, k + 70, Blocks.dirt);
		world.setBlock(i + 36, j + 11, k + 71, Blocks.dirt);
		world.setBlock(i + 36, j + 11, k + 72, Blocks.dirt);
		world.setBlock(i + 36, j + 11, k + 73, Blocks.dirt);
		world.setBlock(i + 36, j + 11, k + 74, Blocks.dirt);
		world.setBlock(i + 36, j + 11, k + 75, Blocks.dirt);
		world.setBlock(i + 36, j + 11, k + 76, Blocks.dirt);
		world.setBlock(i + 36, j + 11, k + 77, Blocks.dirt);
		world.setBlock(i + 36, j + 11, k + 78, Blocks.dirt);
		world.setBlock(i + 36, j + 11, k + 79, Blocks.dirt);
		world.setBlock(i + 36, j + 11, k + 80, Blocks.dirt);
		world.setBlock(i + 36, j + 11, k + 81, Blocks.dirt);
		world.setBlock(i + 36, j + 11, k + 82, Blocks.dirt);
		world.setBlock(i + 36, j + 11, k + 83, Blocks.dirt);
		world.setBlock(i + 36, j + 11, k + 84, Blocks.dirt);
		world.setBlock(i + 36, j + 11, k + 85, Blocks.dirt);
		world.setBlock(i + 36, j + 11, k + 86, Blocks.dirt);
		world.setBlock(i + 36, j + 11, k + 87, Blocks.dirt);
		world.setBlock(i + 36, j + 11, k + 88, Blocks.dirt);
		world.setBlock(i + 36, j + 11, k + 89, Blocks.dirt);
		world.setBlock(i + 36, j + 11, k + 90, Blocks.dirt);
		world.setBlock(i + 36, j + 11, k + 91, Blocks.dirt);
		world.setBlock(i + 36, j + 11, k + 92, Blocks.dirt);
		world.setBlock(i + 36, j + 11, k + 93, Blocks.dirt);
		world.setBlock(i + 36, j + 11, k + 94, Blocks.dirt);
		world.setBlock(i + 36, j + 11, k + 95, Blocks.dirt);
		world.setBlock(i + 36, j + 12, k + 1, Blocks.grass);
		world.setBlock(i + 36, j + 12, k + 2, Blocks.grass);
		world.setBlock(i + 36, j + 12, k + 54, Blocks.grass);
		world.setBlock(i + 36, j + 12, k + 55, Blocks.grass);
		world.setBlock(i + 36, j + 12, k + 56, Blocks.grass);
		world.setBlock(i + 36, j + 12, k + 57, Blocks.grass);
		world.setBlock(i + 36, j + 12, k + 58, Blocks.dirt);
		world.setBlock(i + 36, j + 12, k + 59, Blocks.dirt);
		world.setBlock(i + 36, j + 12, k + 60, Blocks.dirt);
		world.setBlock(i + 36, j + 12, k + 61, Blocks.dirt);
		world.setBlock(i + 36, j + 12, k + 62, Blocks.dirt);
		world.setBlock(i + 36, j + 12, k + 63, Blocks.dirt);
		world.setBlock(i + 36, j + 12, k + 64, Blocks.dirt);
		world.setBlock(i + 36, j + 12, k + 65, Blocks.dirt);
		world.setBlock(i + 36, j + 12, k + 66, Blocks.dirt);
		world.setBlock(i + 36, j + 12, k + 67, Blocks.dirt);
		world.setBlock(i + 36, j + 12, k + 68, Blocks.dirt);
		world.setBlock(i + 36, j + 12, k + 69, Blocks.dirt);
		world.setBlock(i + 36, j + 12, k + 70, Blocks.dirt);
		world.setBlock(i + 36, j + 12, k + 71, Blocks.dirt);
		world.setBlock(i + 36, j + 12, k + 72, Blocks.dirt);
		world.setBlock(i + 36, j + 12, k + 73, Blocks.dirt);
		world.setBlock(i + 36, j + 12, k + 74, Blocks.dirt);
		world.setBlock(i + 36, j + 12, k + 75, Blocks.dirt);
		world.setBlock(i + 36, j + 12, k + 76, Blocks.dirt);
		world.setBlock(i + 36, j + 12, k + 77, Blocks.dirt);
		world.setBlock(i + 36, j + 12, k + 78, Blocks.dirt);
		world.setBlock(i + 36, j + 12, k + 79, Blocks.dirt);
		world.setBlock(i + 36, j + 12, k + 80, Blocks.dirt);
		world.setBlock(i + 36, j + 12, k + 81, Blocks.dirt);
		world.setBlock(i + 36, j + 12, k + 82, Blocks.dirt);
		world.setBlock(i + 36, j + 12, k + 83, Blocks.dirt);
		world.setBlock(i + 36, j + 12, k + 84, Blocks.dirt);
		world.setBlock(i + 36, j + 12, k + 85, Blocks.dirt);
		world.setBlock(i + 36, j + 12, k + 86, Blocks.dirt);
		world.setBlock(i + 36, j + 12, k + 87, Blocks.dirt);
		world.setBlock(i + 36, j + 12, k + 88, Blocks.dirt);
		world.setBlock(i + 36, j + 12, k + 89, Blocks.dirt);
		world.setBlock(i + 36, j + 12, k + 90, Blocks.dirt);
		world.setBlock(i + 36, j + 12, k + 91, Blocks.dirt);
		world.setBlock(i + 36, j + 12, k + 92, Blocks.dirt);
		world.setBlock(i + 36, j + 12, k + 93, Blocks.grass);
		world.setBlock(i + 36, j + 12, k + 94, Blocks.grass);
		world.setBlock(i + 36, j + 12, k + 95, Blocks.grass);
		world.setBlock(i + 36, j + 13, k + 58, Blocks.planks, 1, 4);
		world.setBlock(i + 36, j + 13, k + 59, Blocks.dirt);
		world.setBlock(i + 36, j + 13, k + 60, Blocks.grass);
		world.setBlock(i + 36, j + 13, k + 61, Blocks.grass);
		world.setBlock(i + 36, j + 13, k + 62, Blocks.grass);
		world.setBlock(i + 36, j + 13, k + 63, Blocks.grass);
		world.setBlock(i + 36, j + 13, k + 64, Blocks.grass);
		world.setBlock(i + 36, j + 13, k + 65, Blocks.quartz_block);
		world.setBlock(i + 36, j + 13, k + 66, Blocks.quartz_block);
		world.setBlock(i + 36, j + 13, k + 67, Blocks.quartz_block);
		world.setBlock(i + 36, j + 13, k + 68, Blocks.grass);
		world.setBlock(i + 36, j + 13, k + 69, Blocks.grass);
		world.setBlock(i + 36, j + 13, k + 70, Blocks.grass);
		world.setBlock(i + 36, j + 13, k + 71, Blocks.grass);
		world.setBlock(i + 36, j + 13, k + 72, Blocks.grass);
		world.setBlock(i + 36, j + 13, k + 73, Blocks.grass);
		world.setBlock(i + 36, j + 13, k + 74, Blocks.grass);
		world.setBlock(i + 36, j + 13, k + 75, Blocks.grass);
		world.setBlock(i + 36, j + 13, k + 76, Blocks.grass);
		world.setBlock(i + 36, j + 13, k + 77, Blocks.grass);
		world.setBlock(i + 36, j + 13, k + 78, Blocks.grass);
		world.setBlock(i + 36, j + 13, k + 79, Blocks.grass);
		world.setBlock(i + 36, j + 13, k + 80, Blocks.grass);
		world.setBlock(i + 36, j + 13, k + 81, Blocks.grass);
		world.setBlock(i + 36, j + 13, k + 82, Blocks.grass);
		world.setBlock(i + 36, j + 13, k + 83, Blocks.grass);
		world.setBlock(i + 36, j + 13, k + 84, Blocks.grass);
		world.setBlock(i + 36, j + 13, k + 85, Blocks.grass);
		world.setBlock(i + 36, j + 13, k + 86, Blocks.grass);
		world.setBlock(i + 36, j + 13, k + 87, Blocks.grass);
		world.setBlock(i + 36, j + 13, k + 88, Blocks.grass);
		world.setBlock(i + 36, j + 13, k + 89, Blocks.grass);
		world.setBlock(i + 36, j + 13, k + 90, Blocks.dirt);
		world.setBlock(i + 36, j + 13, k + 91, Blocks.grass);
		world.setBlock(i + 36, j + 13, k + 92, Blocks.grass);
		world.setBlock(i + 36, j + 14, k + 58, Blocks.planks, 1, 4);
		world.setBlock(i + 36, j + 14, k + 59, Blocks.planks, 1, 4);
		world.setBlock(i + 36, j + 14, k + 90, Blocks.planks, 1, 4);
		world.setBlock(i + 36, j + 15, k + 58, Blocks.planks, 1, 4);
		world.setBlock(i + 36, j + 15, k + 59, Blocks.planks, 1, 4);
		world.setBlock(i + 36, j + 15, k + 90, Blocks.planks, 1, 4);
		world.setBlock(i + 36, j + 16, k + 58, Blocks.planks, 1, 4);
		world.setBlock(i + 36, j + 16, k + 59, Blocks.planks, 1, 4);
		world.setBlock(i + 36, j + 16, k + 90, Blocks.planks, 1, 4);
		world.setBlock(i + 36, j + 17, k + 58, Blocks.planks, 1, 4);
		world.setBlock(i + 36, j + 17, k + 59, Blocks.planks, 1, 4);
		world.setBlock(i + 36, j + 17, k + 69, Blocks.dark_oak_stairs, 5, 4);
		world.setBlock(i + 36, j + 17, k + 70, Blocks.dark_oak_stairs, 5, 4);
		world.setBlock(i + 36, j + 17, k + 71, Blocks.wooden_slab, 13, 4);
		world.setBlock(i + 36, j + 17, k + 72, Blocks.wooden_slab, 13, 4);
		world.setBlock(i + 36, j + 17, k + 73, Blocks.wooden_slab, 13, 4);
		world.setBlock(i + 36, j + 17, k + 74, Blocks.wooden_slab, 13, 4);
		world.setBlock(i + 36, j + 17, k + 75, Blocks.wooden_slab, 13, 4);
		world.setBlock(i + 36, j + 17, k + 76, Blocks.wooden_slab, 13, 4);
		world.setBlock(i + 36, j + 17, k + 77, Blocks.wooden_slab, 13, 4);
		world.setBlock(i + 36, j + 17, k + 78, Blocks.wooden_slab, 13, 4);
		world.setBlock(i + 36, j + 17, k + 79, Blocks.wooden_slab, 13, 4);
		world.setBlock(i + 36, j + 17, k + 80, Blocks.dark_oak_stairs, 6, 4);
		world.setBlock(i + 36, j + 17, k + 81, Blocks.dark_oak_stairs, 5, 4);
		world.setBlock(i + 36, j + 17, k + 90, Blocks.planks, 1, 4);
		world.setBlock(i + 36, j + 18, k + 58, Blocks.fence);
		world.setBlock(i + 36, j + 18, k + 59, Blocks.fence);
		world.setBlock(i + 36, j + 18, k + 73, Blocks.fence);
		world.setBlock(i + 36, j + 18, k + 74, Blocks.fence);
		world.setBlock(i + 36, j + 18, k + 75, Blocks.fence);
		world.setBlock(i + 36, j + 18, k + 76, Blocks.fence);
		world.setBlock(i + 36, j + 18, k + 77, Blocks.fence);
		world.setBlock(i + 36, j + 18, k + 90, Blocks.fence);
		world.setBlock(i + 36, j + 21, k + 69, Blocks.dark_oak_stairs, 2, 4);
		world.setBlock(i + 36, j + 21, k + 81, Blocks.dark_oak_stairs, 3, 4);
		world.setBlock(i + 36, j + 22, k + 70, Blocks.dark_oak_stairs, 2, 4);
		world.setBlock(i + 36, j + 22, k + 80, Blocks.dark_oak_stairs, 3, 4);
		world.setBlock(i + 36, j + 23, k + 71, Blocks.dark_oak_stairs, 2, 4);
		world.setBlock(i + 36, j + 23, k + 79, Blocks.dark_oak_stairs, 3, 4);
		world.setBlock(i + 36, j + 24, k + 72, Blocks.dark_oak_stairs, 2, 4);
		world.setBlock(i + 36, j + 24, k + 78, Blocks.dark_oak_stairs, 3, 4);
		world.setBlock(i + 36, j + 25, k + 73, Blocks.dark_oak_stairs, 2, 4);
		world.setBlock(i + 36, j + 25, k + 77, Blocks.dark_oak_stairs, 3, 4);
		world.setBlock(i + 36, j + 26, k + 74, Blocks.dark_oak_stairs, 2, 4);
		world.setBlock(i + 36, j + 26, k + 75, Blocks.planks, 5, 4);
		world.setBlock(i + 36, j + 26, k + 76, Blocks.dark_oak_stairs, 3, 4);
		world.setBlock(i + 37, j + 0, k + 70, Blocks.stone);
		world.setBlock(i + 37, j + 0, k + 71, Blocks.stone);
		world.setBlock(i + 37, j + 0, k + 72, Blocks.stone);
		world.setBlock(i + 37, j + 0, k + 73, Blocks.stone);
		world.setBlock(i + 37, j + 0, k + 74, Blocks.stone);
		world.setBlock(i + 37, j + 0, k + 75, Blocks.stone);
		world.setBlock(i + 37, j + 0, k + 76, Blocks.stone);
		world.setBlock(i + 37, j + 0, k + 77, Blocks.stone);
		world.setBlock(i + 37, j + 0, k + 78, Blocks.stone);
		world.setBlock(i + 37, j + 1, k + 67, Blocks.stone);
		world.setBlock(i + 37, j + 1, k + 68, Blocks.stone);
		world.setBlock(i + 37, j + 1, k + 69, Blocks.stone);
		world.setBlock(i + 37, j + 1, k + 70, Blocks.stone);
		world.setBlock(i + 37, j + 1, k + 71, Blocks.stone);
		world.setBlock(i + 37, j + 1, k + 72, Blocks.stone);
		world.setBlock(i + 37, j + 1, k + 73, Blocks.stone);
		world.setBlock(i + 37, j + 1, k + 74, Blocks.stone);
		world.setBlock(i + 37, j + 1, k + 75, Blocks.stone);
		world.setBlock(i + 37, j + 1, k + 76, Blocks.stone);
		world.setBlock(i + 37, j + 1, k + 77, Blocks.stone);
		world.setBlock(i + 37, j + 1, k + 78, Blocks.stone);
		world.setBlock(i + 37, j + 1, k + 79, Blocks.stone);
		world.setBlock(i + 37, j + 1, k + 80, Blocks.stone);
		world.setBlock(i + 37, j + 1, k + 81, Blocks.stone);
		world.setBlock(i + 37, j + 2, k + 65, Blocks.stone);
		world.setBlock(i + 37, j + 2, k + 66, Blocks.stone);
		world.setBlock(i + 37, j + 2, k + 67, Blocks.stone);
		world.setBlock(i + 37, j + 2, k + 68, Blocks.stone);
		world.setBlock(i + 37, j + 2, k + 69, Blocks.stone);
		world.setBlock(i + 37, j + 2, k + 70, Blocks.stone);
		world.setBlock(i + 37, j + 2, k + 71, Blocks.stone);
		world.setBlock(i + 37, j + 2, k + 72, Blocks.stone);
		world.setBlock(i + 37, j + 2, k + 73, Blocks.stone);
		world.setBlock(i + 37, j + 2, k + 74, Blocks.stone);
		world.setBlock(i + 37, j + 2, k + 75, Blocks.stone);
		world.setBlock(i + 37, j + 2, k + 76, Blocks.stone);
		world.setBlock(i + 37, j + 2, k + 77, Blocks.stone);
		world.setBlock(i + 37, j + 2, k + 78, Blocks.stone);
		world.setBlock(i + 37, j + 2, k + 79, Blocks.stone);
		world.setBlock(i + 37, j + 2, k + 80, Blocks.stone);
		world.setBlock(i + 37, j + 2, k + 81, Blocks.stone);
		world.setBlock(i + 37, j + 2, k + 82, Blocks.stone);
		world.setBlock(i + 37, j + 2, k + 83, Blocks.stone);
		world.setBlock(i + 37, j + 2, k + 84, Blocks.stone);
		world.setBlock(i + 37, j + 3, k + 63, Blocks.stone);
		world.setBlock(i + 37, j + 3, k + 64, Blocks.stone);
		world.setBlock(i + 37, j + 3, k + 65, Blocks.stone);
		world.setBlock(i + 37, j + 3, k + 66, Blocks.stone);
		world.setBlock(i + 37, j + 3, k + 67, Blocks.stone);
		world.setBlock(i + 37, j + 3, k + 68, Blocks.stone);
		world.setBlock(i + 37, j + 3, k + 69, Blocks.stone);
		world.setBlock(i + 37, j + 3, k + 70, Blocks.stone);
		world.setBlock(i + 37, j + 3, k + 71, Blocks.stone);
		world.setBlock(i + 37, j + 3, k + 72, Blocks.stone);
		world.setBlock(i + 37, j + 3, k + 73, Blocks.stone);
		world.setBlock(i + 37, j + 3, k + 74, Blocks.stone);
		world.setBlock(i + 37, j + 3, k + 75, Blocks.stone);
		world.setBlock(i + 37, j + 3, k + 76, Blocks.stone);
		world.setBlock(i + 37, j + 3, k + 77, Blocks.stone);
		world.setBlock(i + 37, j + 3, k + 78, Blocks.stone);
		world.setBlock(i + 37, j + 3, k + 79, Blocks.stone);
		world.setBlock(i + 37, j + 3, k + 80, Blocks.stone);
		world.setBlock(i + 37, j + 3, k + 81, Blocks.stone);
		world.setBlock(i + 37, j + 3, k + 82, Blocks.stone);
		world.setBlock(i + 37, j + 3, k + 83, Blocks.stone);
		world.setBlock(i + 37, j + 3, k + 84, Blocks.stone);
		world.setBlock(i + 37, j + 3, k + 85, Blocks.stone);
		world.setBlock(i + 37, j + 3, k + 86, Blocks.stone);
		world.setBlock(i + 37, j + 3, k + 87, Blocks.stone);
		world.setBlock(i + 37, j + 4, k + 61, Blocks.stone);
		world.setBlock(i + 37, j + 4, k + 62, Blocks.stone);
		world.setBlock(i + 37, j + 4, k + 63, Blocks.stone);
		world.setBlock(i + 37, j + 4, k + 64, Blocks.stone);
		world.setBlock(i + 37, j + 4, k + 65, Blocks.stone);
		world.setBlock(i + 37, j + 4, k + 66, Blocks.stone);
		world.setBlock(i + 37, j + 4, k + 67, Blocks.stone);
		world.setBlock(i + 37, j + 4, k + 68, Blocks.stone);
		world.setBlock(i + 37, j + 4, k + 69, Blocks.stone);
		world.setBlock(i + 37, j + 4, k + 70, Blocks.stone);
		world.setBlock(i + 37, j + 4, k + 71, Blocks.stone);
		world.setBlock(i + 37, j + 4, k + 72, Blocks.stone);
		world.setBlock(i + 37, j + 4, k + 73, Blocks.stone);
		world.setBlock(i + 37, j + 4, k + 74, Blocks.stone);
		world.setBlock(i + 37, j + 4, k + 75, Blocks.stone);
		world.setBlock(i + 37, j + 4, k + 76, Blocks.stone);
		world.setBlock(i + 37, j + 4, k + 77, Blocks.stone);
		world.setBlock(i + 37, j + 4, k + 78, Blocks.stone);
		world.setBlock(i + 37, j + 4, k + 79, Blocks.stone);
		world.setBlock(i + 37, j + 4, k + 80, Blocks.stone);
		world.setBlock(i + 37, j + 4, k + 81, Blocks.stone);
		world.setBlock(i + 37, j + 4, k + 82, Blocks.stone);
		world.setBlock(i + 37, j + 4, k + 83, Blocks.stone);
		world.setBlock(i + 37, j + 4, k + 84, Blocks.stone);
		world.setBlock(i + 37, j + 4, k + 85, Blocks.stone);
		world.setBlock(i + 37, j + 4, k + 86, Blocks.stone);
		world.setBlock(i + 37, j + 4, k + 87, Blocks.stone);
		world.setBlock(i + 37, j + 4, k + 88, Blocks.stone);
		world.setBlock(i + 37, j + 5, k + 60, Blocks.stone);
		world.setBlock(i + 37, j + 5, k + 61, Blocks.stone);
		world.setBlock(i + 37, j + 5, k + 62, Blocks.stone);
		world.setBlock(i + 37, j + 5, k + 63, Blocks.stone);
		world.setBlock(i + 37, j + 5, k + 64, Blocks.stone);
		world.setBlock(i + 37, j + 5, k + 65, Blocks.stone);
		world.setBlock(i + 37, j + 5, k + 66, Blocks.stone);
		world.setBlock(i + 37, j + 5, k + 67, Blocks.stone);
		world.setBlock(i + 37, j + 5, k + 68, Blocks.stone);
		world.setBlock(i + 37, j + 5, k + 69, Blocks.stone);
		world.setBlock(i + 37, j + 5, k + 70, Blocks.stone);
		world.setBlock(i + 37, j + 5, k + 71, Blocks.stone);
		world.setBlock(i + 37, j + 5, k + 72, Blocks.stone);
		world.setBlock(i + 37, j + 5, k + 73, Blocks.stone);
		world.setBlock(i + 37, j + 5, k + 74, Blocks.stone);
		world.setBlock(i + 37, j + 5, k + 75, Blocks.stone);
		world.setBlock(i + 37, j + 5, k + 76, Blocks.stone);
		world.setBlock(i + 37, j + 5, k + 77, Blocks.stone);
		world.setBlock(i + 37, j + 5, k + 78, Blocks.stone);
		world.setBlock(i + 37, j + 5, k + 79, Blocks.stone);
		world.setBlock(i + 37, j + 5, k + 80, Blocks.stone);
		world.setBlock(i + 37, j + 5, k + 81, Blocks.stone);
		world.setBlock(i + 37, j + 5, k + 82, Blocks.stone);
		world.setBlock(i + 37, j + 5, k + 83, Blocks.stone);
		world.setBlock(i + 37, j + 5, k + 84, Blocks.stone);
		world.setBlock(i + 37, j + 5, k + 85, Blocks.stone);
		world.setBlock(i + 37, j + 5, k + 86, Blocks.stone);
		world.setBlock(i + 37, j + 5, k + 87, Blocks.stone);
		world.setBlock(i + 37, j + 5, k + 88, Blocks.stone);
		world.setBlock(i + 37, j + 5, k + 89, Blocks.stone);
		world.setBlock(i + 37, j + 6, k + 59, Blocks.stone);
		world.setBlock(i + 37, j + 6, k + 60, Blocks.stone);
		world.setBlock(i + 37, j + 6, k + 61, Blocks.stone);
		world.setBlock(i + 37, j + 6, k + 62, Blocks.stone);
		world.setBlock(i + 37, j + 6, k + 63, Blocks.stone);
		world.setBlock(i + 37, j + 6, k + 64, Blocks.stone);
		world.setBlock(i + 37, j + 6, k + 65, Blocks.stone);
		world.setBlock(i + 37, j + 6, k + 66, Blocks.stone);
		world.setBlock(i + 37, j + 6, k + 67, Blocks.stone);
		world.setBlock(i + 37, j + 6, k + 68, Blocks.stone);
		world.setBlock(i + 37, j + 6, k + 69, Blocks.stone);
		world.setBlock(i + 37, j + 6, k + 70, Blocks.stone);
		world.setBlock(i + 37, j + 6, k + 71, Blocks.stone);
		world.setBlock(i + 37, j + 6, k + 72, Blocks.stone);
		world.setBlock(i + 37, j + 6, k + 73, Blocks.stone);
		world.setBlock(i + 37, j + 6, k + 74, Blocks.stone);
		world.setBlock(i + 37, j + 6, k + 75, Blocks.stone);
		world.setBlock(i + 37, j + 6, k + 76, Blocks.stone);
		world.setBlock(i + 37, j + 6, k + 77, Blocks.stone);
		world.setBlock(i + 37, j + 6, k + 78, Blocks.stone);
		world.setBlock(i + 37, j + 6, k + 79, Blocks.stone);
		world.setBlock(i + 37, j + 6, k + 80, Blocks.stone);
		world.setBlock(i + 37, j + 6, k + 81, Blocks.stone);
		world.setBlock(i + 37, j + 6, k + 82, Blocks.stone);
		world.setBlock(i + 37, j + 6, k + 83, Blocks.stone);
		world.setBlock(i + 37, j + 6, k + 84, Blocks.stone);
		world.setBlock(i + 37, j + 6, k + 85, Blocks.stone);
		world.setBlock(i + 37, j + 6, k + 86, Blocks.stone);
		world.setBlock(i + 37, j + 6, k + 87, Blocks.stone);
		world.setBlock(i + 37, j + 6, k + 88, Blocks.stone);
		world.setBlock(i + 37, j + 6, k + 89, Blocks.stone);
		world.setBlock(i + 37, j + 6, k + 90, Blocks.stone);
		world.setBlock(i + 37, j + 6, k + 91, Blocks.stone);
		world.setBlock(i + 37, j + 7, k + 57, Blocks.stone);
		world.setBlock(i + 37, j + 7, k + 58, Blocks.stone);
		world.setBlock(i + 37, j + 7, k + 59, Blocks.stone);

		generate15(world, rand, i, j, k);
		return true;
	}

	public boolean generate15(World world, Random rand, int i, int j, int k) {
		world.setBlock(i + 37, j + 7, k + 60, Blocks.stone);
		world.setBlock(i + 37, j + 7, k + 61, Blocks.stone);
		world.setBlock(i + 37, j + 7, k + 62, Blocks.stone);
		world.setBlock(i + 37, j + 7, k + 63, Blocks.stone);
		world.setBlock(i + 37, j + 7, k + 64, Blocks.stone);
		world.setBlock(i + 37, j + 7, k + 65, Blocks.stone);
		world.setBlock(i + 37, j + 7, k + 66, Blocks.stone);
		world.setBlock(i + 37, j + 7, k + 67, Blocks.stone);
		world.setBlock(i + 37, j + 7, k + 68, Blocks.stone);
		world.setBlock(i + 37, j + 7, k + 69, Blocks.stone);
		world.setBlock(i + 37, j + 7, k + 70, Blocks.stone);
		world.setBlock(i + 37, j + 7, k + 71, Blocks.stone);
		world.setBlock(i + 37, j + 7, k + 72, Blocks.stone);
		world.setBlock(i + 37, j + 7, k + 73, Blocks.stone);
		world.setBlock(i + 37, j + 7, k + 74, Blocks.stone);
		world.setBlock(i + 37, j + 7, k + 75, Blocks.stone);
		world.setBlock(i + 37, j + 7, k + 76, Blocks.stone);
		world.setBlock(i + 37, j + 7, k + 77, Blocks.stone);
		world.setBlock(i + 37, j + 7, k + 78, Blocks.stone);
		world.setBlock(i + 37, j + 7, k + 79, Blocks.stone);
		world.setBlock(i + 37, j + 7, k + 80, Blocks.stone);
		world.setBlock(i + 37, j + 7, k + 81, Blocks.stone);
		world.setBlock(i + 37, j + 7, k + 82, Blocks.stone);
		world.setBlock(i + 37, j + 7, k + 83, Blocks.stone);
		world.setBlock(i + 37, j + 7, k + 84, Blocks.stone);
		world.setBlock(i + 37, j + 7, k + 85, Blocks.stone);
		world.setBlock(i + 37, j + 7, k + 86, Blocks.stone);
		world.setBlock(i + 37, j + 7, k + 87, Blocks.stone);
		world.setBlock(i + 37, j + 7, k + 88, Blocks.stone);
		world.setBlock(i + 37, j + 7, k + 89, Blocks.stone);
		world.setBlock(i + 37, j + 7, k + 90, Blocks.stone);
		world.setBlock(i + 37, j + 7, k + 91, Blocks.stone);
		world.setBlock(i + 37, j + 7, k + 92, Blocks.stone);
		world.setBlock(i + 37, j + 8, k + 56, Wildycraft.denseStone);
		world.setBlock(i + 37, j + 8, k + 57, Wildycraft.denseStone);
		world.setBlock(i + 37, j + 8, k + 58, Wildycraft.denseStone);
		world.setBlock(i + 37, j + 8, k + 59, Wildycraft.denseStone);
		world.setBlock(i + 37, j + 8, k + 60, Wildycraft.denseStone);
		world.setBlock(i + 37, j + 8, k + 61, Wildycraft.denseStone);
		world.setBlock(i + 37, j + 8, k + 62, Wildycraft.denseStone);
		world.setBlock(i + 37, j + 8, k + 63, Wildycraft.denseStone);
		world.setBlock(i + 37, j + 8, k + 64, Wildycraft.denseStone);
		world.setBlock(i + 37, j + 8, k + 65, Wildycraft.denseStone);
		world.setBlock(i + 37, j + 8, k + 66, Wildycraft.denseStone);
		world.setBlock(i + 37, j + 8, k + 67, Wildycraft.denseStone);
		world.setBlock(i + 37, j + 8, k + 68, Wildycraft.denseStone);
		world.setBlock(i + 37, j + 8, k + 69, Wildycraft.denseStone);
		world.setBlock(i + 37, j + 8, k + 70, Wildycraft.denseStone);
		world.setBlock(i + 37, j + 8, k + 71, Wildycraft.denseStone);
		world.setBlock(i + 37, j + 8, k + 72, Wildycraft.denseStone);
		world.setBlock(i + 37, j + 8, k + 73, Wildycraft.denseStone);
		world.setBlock(i + 37, j + 8, k + 74, Wildycraft.denseStone);
		world.setBlock(i + 37, j + 8, k + 75, Wildycraft.denseStone);
		world.setBlock(i + 37, j + 8, k + 76, Wildycraft.denseStone);
		world.setBlock(i + 37, j + 8, k + 77, Wildycraft.denseStone);
		world.setBlock(i + 37, j + 8, k + 78, Wildycraft.denseStone);
		world.setBlock(i + 37, j + 8, k + 79, Wildycraft.denseStone);
		world.setBlock(i + 37, j + 8, k + 80, Wildycraft.denseStone);
		world.setBlock(i + 37, j + 8, k + 81, Wildycraft.denseStone);
		world.setBlock(i + 37, j + 8, k + 82, Wildycraft.denseStone);
		world.setBlock(i + 37, j + 8, k + 83, Wildycraft.denseStone);
		world.setBlock(i + 37, j + 8, k + 84, Wildycraft.denseStone);
		world.setBlock(i + 37, j + 8, k + 85, Wildycraft.denseStone);
		world.setBlock(i + 37, j + 8, k + 86, Wildycraft.denseStone);
		world.setBlock(i + 37, j + 8, k + 87, Wildycraft.denseStone);
		world.setBlock(i + 37, j + 8, k + 88, Wildycraft.denseStone);
		world.setBlock(i + 37, j + 8, k + 89, Wildycraft.denseStone);
		world.setBlock(i + 37, j + 8, k + 90, Wildycraft.denseStone);
		world.setBlock(i + 37, j + 8, k + 91, Wildycraft.denseStone);
		world.setBlock(i + 37, j + 8, k + 92, Wildycraft.denseStone);
		world.setBlock(i + 37, j + 8, k + 93, Wildycraft.denseStone);
		world.setBlock(i + 37, j + 9, k + 55, Wildycraft.denseStone);
		world.setBlock(i + 37, j + 9, k + 56, Wildycraft.denseStone);
		world.setBlock(i + 37, j + 9, k + 57, Wildycraft.denseStone);
		world.setBlock(i + 37, j + 9, k + 58, Wildycraft.denseStone);
		world.setBlock(i + 37, j + 9, k + 59, Wildycraft.denseStone);
		world.setBlock(i + 37, j + 9, k + 60, Wildycraft.denseStone);
		world.setBlock(i + 37, j + 9, k + 61, Wildycraft.denseStone);
		world.setBlock(i + 37, j + 9, k + 62, Wildycraft.denseStone);
		world.setBlock(i + 37, j + 9, k + 63, Wildycraft.denseStone);
		world.setBlock(i + 37, j + 9, k + 64, Wildycraft.denseStone);
		world.setBlock(i + 37, j + 9, k + 65, Wildycraft.denseStone);
		world.setBlock(i + 37, j + 9, k + 66, Wildycraft.denseStone);
		world.setBlock(i + 37, j + 9, k + 67, Wildycraft.denseStone);
		world.setBlock(i + 37, j + 9, k + 68, Wildycraft.denseStone);
		world.setBlock(i + 37, j + 9, k + 69, Wildycraft.denseStone);
		world.setBlock(i + 37, j + 9, k + 70, Wildycraft.denseStone);
		world.setBlock(i + 37, j + 9, k + 71, Wildycraft.denseStone);
		world.setBlock(i + 37, j + 9, k + 72, Wildycraft.denseStone);
		world.setBlock(i + 37, j + 9, k + 73, Wildycraft.denseStone);
		world.setBlock(i + 37, j + 9, k + 74, Wildycraft.denseStone);
		world.setBlock(i + 37, j + 9, k + 75, Wildycraft.denseStone);
		world.setBlock(i + 37, j + 9, k + 76, Wildycraft.denseStone);
		world.setBlock(i + 37, j + 9, k + 77, Wildycraft.denseStone);
		world.setBlock(i + 37, j + 9, k + 78, Wildycraft.denseStone);
		world.setBlock(i + 37, j + 9, k + 79, Wildycraft.denseStone);
		world.setBlock(i + 37, j + 9, k + 80, Wildycraft.denseStone);
		world.setBlock(i + 37, j + 9, k + 81, Wildycraft.denseStone);
		world.setBlock(i + 37, j + 9, k + 82, Wildycraft.denseStone);
		world.setBlock(i + 37, j + 9, k + 83, Wildycraft.denseStone);
		world.setBlock(i + 37, j + 9, k + 84, Wildycraft.denseStone);
		world.setBlock(i + 37, j + 9, k + 85, Wildycraft.denseStone);
		world.setBlock(i + 37, j + 9, k + 86, Wildycraft.denseStone);
		world.setBlock(i + 37, j + 9, k + 87, Wildycraft.denseStone);
		world.setBlock(i + 37, j + 9, k + 88, Wildycraft.denseStone);
		world.setBlock(i + 37, j + 9, k + 89, Wildycraft.denseStone);
		world.setBlock(i + 37, j + 9, k + 90, Wildycraft.denseStone);
		world.setBlock(i + 37, j + 9, k + 91, Wildycraft.denseStone);
		world.setBlock(i + 37, j + 9, k + 92, Wildycraft.denseStone);
		world.setBlock(i + 37, j + 9, k + 93, Wildycraft.denseStone);
		world.setBlock(i + 37, j + 10, k + 2, Wildycraft.denseStone);
		world.setBlock(i + 37, j + 10, k + 55, Wildycraft.denseStone);
		world.setBlock(i + 37, j + 10, k + 56, Wildycraft.denseStone);
		world.setBlock(i + 37, j + 10, k + 57, Wildycraft.denseStone);
		world.setBlock(i + 37, j + 10, k + 58, Wildycraft.denseStone);
		world.setBlock(i + 37, j + 10, k + 59, Wildycraft.denseStone);
		world.setBlock(i + 37, j + 10, k + 60, Wildycraft.denseStone);
		world.setBlock(i + 37, j + 10, k + 61, Wildycraft.denseStone);
		world.setBlock(i + 37, j + 10, k + 62, Wildycraft.denseStone);
		world.setBlock(i + 37, j + 10, k + 63, Wildycraft.denseStone);
		world.setBlock(i + 37, j + 10, k + 64, Wildycraft.denseStone);
		world.setBlock(i + 37, j + 10, k + 65, Wildycraft.denseStone);
		world.setBlock(i + 37, j + 10, k + 66, Wildycraft.denseStone);
		world.setBlock(i + 37, j + 10, k + 67, Wildycraft.denseStone);
		world.setBlock(i + 37, j + 10, k + 68, Wildycraft.denseStone);
		world.setBlock(i + 37, j + 10, k + 69, Wildycraft.denseStone);
		world.setBlock(i + 37, j + 10, k + 70, Wildycraft.denseStone);
		world.setBlock(i + 37, j + 10, k + 71, Wildycraft.denseStone);
		world.setBlock(i + 37, j + 10, k + 72, Wildycraft.denseStone);
		world.setBlock(i + 37, j + 10, k + 73, Wildycraft.denseStone);
		world.setBlock(i + 37, j + 10, k + 74, Wildycraft.denseStone);
		world.setBlock(i + 37, j + 10, k + 75, Wildycraft.denseStone);
		world.setBlock(i + 37, j + 10, k + 76, Wildycraft.denseStone);
		world.setBlock(i + 37, j + 10, k + 77, Wildycraft.denseStone);
		world.setBlock(i + 37, j + 10, k + 78, Wildycraft.denseStone);
		world.setBlock(i + 37, j + 10, k + 79, Wildycraft.denseStone);
		world.setBlock(i + 37, j + 10, k + 80, Wildycraft.denseStone);
		world.setBlock(i + 37, j + 10, k + 81, Wildycraft.denseStone);
		world.setBlock(i + 37, j + 10, k + 82, Wildycraft.denseStone);
		world.setBlock(i + 37, j + 10, k + 83, Wildycraft.denseStone);
		world.setBlock(i + 37, j + 10, k + 84, Wildycraft.denseStone);
		world.setBlock(i + 37, j + 10, k + 85, Wildycraft.denseStone);
		world.setBlock(i + 37, j + 10, k + 86, Wildycraft.denseStone);
		world.setBlock(i + 37, j + 10, k + 87, Wildycraft.denseStone);
		world.setBlock(i + 37, j + 10, k + 88, Wildycraft.denseStone);
		world.setBlock(i + 37, j + 10, k + 89, Wildycraft.denseStone);
		world.setBlock(i + 37, j + 10, k + 90, Wildycraft.denseStone);
		world.setBlock(i + 37, j + 10, k + 91, Wildycraft.denseStone);
		world.setBlock(i + 37, j + 10, k + 92, Wildycraft.denseStone);
		world.setBlock(i + 37, j + 10, k + 93, Wildycraft.denseStone);
		world.setBlock(i + 37, j + 10, k + 94, Wildycraft.denseStone);
		world.setBlock(i + 37, j + 11, k + 1, Blocks.grass);
		world.setBlock(i + 37, j + 11, k + 2, Blocks.grass);
		world.setBlock(i + 37, j + 11, k + 3, Blocks.grass);
		world.setBlock(i + 37, j + 11, k + 54, Blocks.dirt);
		world.setBlock(i + 37, j + 11, k + 55, Blocks.dirt);
		world.setBlock(i + 37, j + 11, k + 56, Blocks.dirt);
		world.setBlock(i + 37, j + 11, k + 57, Blocks.dirt);
		world.setBlock(i + 37, j + 11, k + 58, Blocks.dirt);
		world.setBlock(i + 37, j + 11, k + 59, Blocks.dirt);
		world.setBlock(i + 37, j + 11, k + 60, Blocks.dirt);
		world.setBlock(i + 37, j + 11, k + 61, Blocks.dirt);
		world.setBlock(i + 37, j + 11, k + 62, Blocks.dirt);
		world.setBlock(i + 37, j + 11, k + 63, Blocks.dirt);
		world.setBlock(i + 37, j + 11, k + 64, Blocks.dirt);
		world.setBlock(i + 37, j + 11, k + 65, Blocks.dirt);
		world.setBlock(i + 37, j + 11, k + 66, Blocks.dirt);
		world.setBlock(i + 37, j + 11, k + 67, Blocks.dirt);
		world.setBlock(i + 37, j + 11, k + 68, Blocks.dirt);
		world.setBlock(i + 37, j + 11, k + 69, Blocks.dirt);
		world.setBlock(i + 37, j + 11, k + 70, Blocks.dirt);
		world.setBlock(i + 37, j + 11, k + 71, Blocks.dirt);
		world.setBlock(i + 37, j + 11, k + 72, Blocks.dirt);
		world.setBlock(i + 37, j + 11, k + 73, Blocks.dirt);
		world.setBlock(i + 37, j + 11, k + 74, Blocks.dirt);
		world.setBlock(i + 37, j + 11, k + 75, Blocks.dirt);
		world.setBlock(i + 37, j + 11, k + 76, Blocks.dirt);
		world.setBlock(i + 37, j + 11, k + 77, Blocks.dirt);
		world.setBlock(i + 37, j + 11, k + 78, Blocks.dirt);
		world.setBlock(i + 37, j + 11, k + 79, Blocks.dirt);
		world.setBlock(i + 37, j + 11, k + 80, Blocks.dirt);
		world.setBlock(i + 37, j + 11, k + 81, Blocks.dirt);
		world.setBlock(i + 37, j + 11, k + 82, Blocks.dirt);
		world.setBlock(i + 37, j + 11, k + 83, Blocks.dirt);
		world.setBlock(i + 37, j + 11, k + 84, Blocks.dirt);
		world.setBlock(i + 37, j + 11, k + 85, Blocks.dirt);
		world.setBlock(i + 37, j + 11, k + 86, Blocks.dirt);
