package wildycraft.structures;
import java.util.Random;

import wildycraft.Wildycraft;
import net.minecraft.world.World;
import net.minecraft.init.Blocks;
import net.minecraft.world.gen.feature.WorldGenerator;

public class LunarIsle extends WorldGenerator
{
	public LunarIsle() { }

	public boolean generate(World world, Random rand, int i, int j, int k) {
		world.setBlock(i + 0, j + 31, k + 26, Blocks.wool);
		world.setBlock(i + 0, j + 31, k + 27, Blocks.wool);
		world.setBlock(i + 0, j + 31, k + 28, Blocks.wool);
		world.setBlock(i + 0, j + 32, k + 26, Blocks.wool);
		world.setBlock(i + 0, j + 32, k + 27, Blocks.wool);
		world.setBlock(i + 0, j + 32, k + 28, Blocks.wool);
		world.setBlock(i + 0, j + 33, k + 26, Blocks.wool);
		world.setBlock(i + 0, j + 33, k + 27, Blocks.wool);
		world.setBlock(i + 0, j + 33, k + 28, Blocks.wool);
		world.setBlock(i + 1, j + 11, k + 40, Blocks.dirt);
		world.setBlock(i + 1, j + 11, k + 41, Blocks.dirt);
		world.setBlock(i + 1, j + 11, k + 42, Blocks.dirt);
		world.setBlock(i + 1, j + 11, k + 43, Blocks.dirt);
		world.setBlock(i + 1, j + 11, k + 44, Blocks.dirt);
		world.setBlock(i + 1, j + 11, k + 45, Blocks.dirt);
		world.setBlock(i + 1, j + 11, k + 46, Blocks.dirt);
		world.setBlock(i + 1, j + 11, k + 47, Blocks.dirt);
		world.setBlock(i + 1, j + 11, k + 48, Blocks.dirt);
		world.setBlock(i + 1, j + 11, k + 49, Blocks.dirt);
		world.setBlock(i + 1, j + 11, k + 50, Blocks.dirt);
		world.setBlock(i + 1, j + 11, k + 51, Blocks.dirt);
		world.setBlock(i + 1, j + 11, k + 52, Blocks.dirt);
		world.setBlock(i + 1, j + 11, k + 53, Blocks.dirt);
		world.setBlock(i + 1, j + 11, k + 54, Blocks.dirt);
		world.setBlock(i + 1, j + 12, k + 40, Blocks.grass);
		world.setBlock(i + 1, j + 12, k + 41, Blocks.grass);
		world.setBlock(i + 1, j + 12, k + 42, Blocks.grass);
		world.setBlock(i + 1, j + 12, k + 43, Blocks.grass);
		world.setBlock(i + 1, j + 12, k + 44, Blocks.grass);
		world.setBlock(i + 1, j + 12, k + 45, Blocks.grass);
		world.setBlock(i + 1, j + 12, k + 46, Blocks.grass);
		world.setBlock(i + 1, j + 12, k + 47, Blocks.grass);
		world.setBlock(i + 1, j + 12, k + 48, Blocks.grass);
		world.setBlock(i + 1, j + 12, k + 49, Blocks.grass);
		world.setBlock(i + 1, j + 12, k + 50, Blocks.grass);
		world.setBlock(i + 1, j + 12, k + 51, Blocks.grass);
		world.setBlock(i + 1, j + 12, k + 52, Blocks.grass);
		world.setBlock(i + 1, j + 12, k + 53, Blocks.grass);
		world.setBlock(i + 1, j + 12, k + 54, Blocks.grass);
		world.setBlock(i + 1, j + 23, k + 26, Blocks.spruce_stairs, 6, 4);
		world.setBlock(i + 1, j + 23, k + 27, Blocks.spruce_stairs, 4, 4);
		world.setBlock(i + 1, j + 23, k + 28, Blocks.spruce_stairs, 7, 4);
		world.setBlock(i + 1, j + 24, k + 26, Blocks.planks, 1, 4);
		world.setBlock(i + 1, j + 24, k + 27, Blocks.planks, 1, 4);
		world.setBlock(i + 1, j + 24, k + 28, Blocks.planks, 1, 4);
		world.setBlock(i + 1, j + 25, k + 26, Blocks.planks, 1, 4);
		world.setBlock(i + 1, j + 25, k + 27, Blocks.planks, 1, 4);
		world.setBlock(i + 1, j + 25, k + 28, Blocks.planks, 1, 4);
		world.setBlock(i + 1, j + 26, k + 26, Blocks.planks, 1, 4);
		world.setBlock(i + 1, j + 26, k + 27, Blocks.planks, 1, 4);
		world.setBlock(i + 1, j + 26, k + 28, Blocks.planks, 1, 4);
		world.setBlock(i + 1, j + 27, k + 26, Blocks.planks, 1, 4);
		world.setBlock(i + 1, j + 27, k + 27, Blocks.planks, 1, 4);
		world.setBlock(i + 1, j + 27, k + 28, Blocks.planks, 1, 4);
		world.setBlock(i + 1, j + 28, k + 26, Blocks.fence);
		world.setBlock(i + 1, j + 28, k + 27, Blocks.fence);
		world.setBlock(i + 1, j + 28, k + 28, Blocks.fence);
		world.setBlock(i + 1, j + 30, k + 26, Blocks.wool);
		world.setBlock(i + 1, j + 30, k + 27, Blocks.wool);
		world.setBlock(i + 1, j + 30, k + 28, Blocks.wool);
		world.setBlock(i + 1, j + 31, k + 25, Blocks.wool);
		world.setBlock(i + 1, j + 31, k + 26, Blocks.wool);
		world.setBlock(i + 1, j + 31, k + 27, Blocks.wool);
		world.setBlock(i + 1, j + 31, k + 28, Blocks.wool);
		world.setBlock(i + 1, j + 31, k + 29, Blocks.wool);
		world.setBlock(i + 1, j + 32, k + 25, Blocks.wool);
		world.setBlock(i + 1, j + 32, k + 26, Blocks.wool);
		world.setBlock(i + 1, j + 32, k + 27, Blocks.wool);
		world.setBlock(i + 1, j + 32, k + 28, Blocks.wool);
		world.setBlock(i + 1, j + 32, k + 29, Blocks.wool);
		world.setBlock(i + 1, j + 33, k + 25, Blocks.wool);
		world.setBlock(i + 1, j + 33, k + 26, Blocks.wool);
		world.setBlock(i + 1, j + 33, k + 27, Blocks.wool);
		world.setBlock(i + 1, j + 33, k + 28, Blocks.wool);
		world.setBlock(i + 1, j + 33, k + 29, Blocks.wool);
		world.setBlock(i + 1, j + 34, k + 26, Blocks.wool);
		world.setBlock(i + 1, j + 34, k + 27, Blocks.wool);
		world.setBlock(i + 1, j + 34, k + 28, Blocks.wool);
		world.setBlock(i + 2, j + 10, k + 40, Wildycraft.denseStone);
		world.setBlock(i + 2, j + 10, k + 41, Wildycraft.denseStone);
		world.setBlock(i + 2, j + 10, k + 42, Wildycraft.denseStone);
		world.setBlock(i + 2, j + 10, k + 43, Wildycraft.denseStone);
		world.setBlock(i + 2, j + 10, k + 44, Wildycraft.denseStone);
		world.setBlock(i + 2, j + 10, k + 45, Wildycraft.denseStone);
		world.setBlock(i + 2, j + 10, k + 46, Wildycraft.denseStone);
		world.setBlock(i + 2, j + 10, k + 47, Wildycraft.denseStone);
		world.setBlock(i + 2, j + 10, k + 48, Wildycraft.denseStone);
		world.setBlock(i + 2, j + 10, k + 49, Wildycraft.denseStone);
		world.setBlock(i + 2, j + 10, k + 50, Wildycraft.denseStone);
		world.setBlock(i + 2, j + 10, k + 51, Wildycraft.denseStone);
		world.setBlock(i + 2, j + 10, k + 52, Wildycraft.denseStone);
		world.setBlock(i + 2, j + 10, k + 53, Wildycraft.denseStone);
		world.setBlock(i + 2, j + 10, k + 54, Wildycraft.denseStone);
		world.setBlock(i + 2, j + 11, k + 34, Blocks.dirt);
		world.setBlock(i + 2, j + 11, k + 35, Blocks.dirt);
		world.setBlock(i + 2, j + 11, k + 36, Blocks.dirt);
		world.setBlock(i + 2, j + 11, k + 37, Blocks.dirt);
		world.setBlock(i + 2, j + 11, k + 38, Blocks.dirt);
		world.setBlock(i + 2, j + 11, k + 39, Blocks.dirt);
		world.setBlock(i + 2, j + 11, k + 40, Blocks.dirt);
		world.setBlock(i + 2, j + 11, k + 41, Blocks.dirt);
		world.setBlock(i + 2, j + 11, k + 42, Blocks.dirt);
		world.setBlock(i + 2, j + 11, k + 43, Blocks.dirt);
		world.setBlock(i + 2, j + 11, k + 44, Blocks.dirt);
		world.setBlock(i + 2, j + 11, k + 45, Blocks.dirt);
		world.setBlock(i + 2, j + 11, k + 46, Blocks.dirt);
		world.setBlock(i + 2, j + 11, k + 47, Blocks.dirt);
		world.setBlock(i + 2, j + 11, k + 48, Blocks.dirt);
		world.setBlock(i + 2, j + 11, k + 49, Blocks.dirt);
		world.setBlock(i + 2, j + 11, k + 50, Blocks.dirt);
		world.setBlock(i + 2, j + 11, k + 51, Blocks.dirt);
		world.setBlock(i + 2, j + 11, k + 52, Blocks.dirt);
		world.setBlock(i + 2, j + 11, k + 53, Blocks.dirt);
		world.setBlock(i + 2, j + 11, k + 54, Blocks.dirt);
		world.setBlock(i + 2, j + 11, k + 55, Blocks.dirt);
		world.setBlock(i + 2, j + 11, k + 56, Blocks.dirt);
		world.setBlock(i + 2, j + 11, k + 57, Blocks.dirt);
		world.setBlock(i + 2, j + 11, k + 58, Blocks.dirt);
		world.setBlock(i + 2, j + 11, k + 59, Blocks.dirt);
		world.setBlock(i + 2, j + 12, k + 34, Blocks.grass);
		world.setBlock(i + 2, j + 12, k + 35, Blocks.grass);
		world.setBlock(i + 2, j + 12, k + 36, Blocks.grass);
		world.setBlock(i + 2, j + 12, k + 37, Blocks.grass);
		world.setBlock(i + 2, j + 12, k + 38, Blocks.grass);
		world.setBlock(i + 2, j + 12, k + 39, Blocks.grass);
		world.setBlock(i + 2, j + 12, k + 40, Blocks.grass);
		world.setBlock(i + 2, j + 12, k + 41, Blocks.grass);
		world.setBlock(i + 2, j + 12, k + 42, Blocks.grass);
		world.setBlock(i + 2, j + 12, k + 43, Blocks.grass);
		world.setBlock(i + 2, j + 12, k + 44, Blocks.grass);
		world.setBlock(i + 2, j + 12, k + 45, Blocks.grass);
		world.setBlock(i + 2, j + 12, k + 46, Blocks.grass);
		world.setBlock(i + 2, j + 12, k + 47, Blocks.grass);
		world.setBlock(i + 2, j + 12, k + 48, Blocks.grass);
		world.setBlock(i + 2, j + 12, k + 49, Blocks.grass);
		world.setBlock(i + 2, j + 12, k + 50, Blocks.grass);
		world.setBlock(i + 2, j + 12, k + 51, Blocks.grass);
		world.setBlock(i + 2, j + 12, k + 52, Blocks.grass);
		world.setBlock(i + 2, j + 12, k + 53, Blocks.grass);
		world.setBlock(i + 2, j + 12, k + 54, Blocks.grass);
		world.setBlock(i + 2, j + 12, k + 55, Blocks.grass);
		world.setBlock(i + 2, j + 12, k + 56, Blocks.grass);
		world.setBlock(i + 2, j + 12, k + 57, Blocks.grass);
		world.setBlock(i + 2, j + 12, k + 58, Blocks.grass);
		world.setBlock(i + 2, j + 12, k + 59, Blocks.grass);
		world.setBlock(i + 2, j + 22, k + 27, Blocks.spruce_stairs, 4, 4);
		world.setBlock(i + 2, j + 23, k + 25, Blocks.spruce_stairs, 4, 4);
		world.setBlock(i + 2, j + 23, k + 26, Blocks.planks, 1, 4);
		world.setBlock(i + 2, j + 23, k + 27, Blocks.planks, 1, 4);
		world.setBlock(i + 2, j + 23, k + 28, Blocks.planks, 1, 4);
		world.setBlock(i + 2, j + 23, k + 29, Blocks.spruce_stairs, 4, 4);
		world.setBlock(i + 2, j + 24, k + 25, Blocks.planks, 1, 4);
		world.setBlock(i + 2, j + 24, k + 26, Blocks.bed, 9, 4);
		world.setBlock(i + 3, j + 24, k + 26, Blocks.bed, 1, 4);
		world.setBlock(i + 2, j + 24, k + 29, Blocks.planks, 1, 4);
		world.setBlock(i + 2, j + 25, k + 25, Blocks.planks, 1, 4);
		world.setBlock(i + 2, j + 25, k + 29, Blocks.planks, 1, 4);
		world.setBlock(i + 2, j + 26, k + 25, Blocks.planks, 1, 4);
		world.setBlock(i + 2, j + 26, k + 26, Blocks.wooden_slab, 9, 4);
		world.setBlock(i + 2, j + 26, k + 27, Blocks.wooden_slab, 9, 4);
		world.setBlock(i + 2, j + 26, k + 28, Blocks.wooden_slab, 9, 4);
		world.setBlock(i + 2, j + 26, k + 29, Blocks.planks, 1, 4);
		world.setBlock(i + 2, j + 27, k + 25, Blocks.planks, 1, 4);
		world.setBlock(i + 2, j + 27, k + 27, Blocks.oak_stairs, 1, 4);
		world.setBlock(i + 2, j + 27, k + 29, Blocks.planks, 1, 4);
		world.setBlock(i + 2, j + 28, k + 25, Blocks.fence);
		world.setBlock(i + 2, j + 28, k + 29, Blocks.fence);
		world.setBlock(i + 2, j + 29, k + 25, Blocks.fence);
		world.setBlock(i + 2, j + 29, k + 29, Blocks.fence);
		world.setBlock(i + 2, j + 30, k + 25, Blocks.fence);
		world.setBlock(i + 2, j + 30, k + 26, Blocks.wool);
		world.setBlock(i + 2, j + 30, k + 27, Blocks.wool);
		world.setBlock(i + 2, j + 30, k + 28, Blocks.wool);
		world.setBlock(i + 2, j + 30, k + 29, Blocks.fence);
		world.setBlock(i + 2, j + 31, k + 25, Blocks.wool);
		world.setBlock(i + 2, j + 31, k + 26, Blocks.wool);
		world.setBlock(i + 2, j + 31, k + 27, Blocks.wool);
		world.setBlock(i + 2, j + 31, k + 28, Blocks.wool);
		world.setBlock(i + 2, j + 31, k + 29, Blocks.wool);
		world.setBlock(i + 2, j + 32, k + 25, Blocks.wool);
		world.setBlock(i + 2, j + 32, k + 26, Blocks.wool);
		world.setBlock(i + 2, j + 32, k + 27, Blocks.wool);
		world.setBlock(i + 2, j + 32, k + 28, Blocks.wool);
		world.setBlock(i + 2, j + 32, k + 29, Blocks.wool);
		world.setBlock(i + 2, j + 33, k + 25, Blocks.wool);
		world.setBlock(i + 2, j + 33, k + 26, Blocks.wool);
		world.setBlock(i + 2, j + 33, k + 27, Blocks.wool);
		world.setBlock(i + 2, j + 33, k + 28, Blocks.wool);
		world.setBlock(i + 2, j + 33, k + 29, Blocks.wool);
		world.setBlock(i + 2, j + 34, k + 26, Blocks.wool);
		world.setBlock(i + 2, j + 34, k + 27, Blocks.wool);
		world.setBlock(i + 2, j + 34, k + 28, Blocks.wool);
		world.setBlock(i + 3, j + 9, k + 41, Wildycraft.denseStone);
		world.setBlock(i + 3, j + 9, k + 42, Wildycraft.denseStone);
		world.setBlock(i + 3, j + 9, k + 43, Wildycraft.denseStone);
		world.setBlock(i + 3, j + 9, k + 44, Wildycraft.denseStone);
		world.setBlock(i + 3, j + 9, k + 45, Wildycraft.denseStone);
		world.setBlock(i + 3, j + 9, k + 46, Wildycraft.denseStone);
		world.setBlock(i + 3, j + 9, k + 47, Wildycraft.denseStone);
		world.setBlock(i + 3, j + 9, k + 48, Wildycraft.denseStone);
		world.setBlock(i + 3, j + 10, k + 34, Wildycraft.denseStone);
		world.setBlock(i + 3, j + 10, k + 35, Wildycraft.denseStone);
		world.setBlock(i + 3, j + 10, k + 36, Wildycraft.denseStone);
		world.setBlock(i + 3, j + 10, k + 37, Wildycraft.denseStone);
		world.setBlock(i + 3, j + 10, k + 38, Wildycraft.denseStone);
		world.setBlock(i + 3, j + 10, k + 39, Wildycraft.denseStone);
		world.setBlock(i + 3, j + 10, k + 40, Wildycraft.denseStone);
		world.setBlock(i + 3, j + 10, k + 41, Wildycraft.denseStone);
		world.setBlock(i + 3, j + 10, k + 42, Wildycraft.denseStone);
		world.setBlock(i + 3, j + 10, k + 43, Wildycraft.denseStone);
		world.setBlock(i + 3, j + 10, k + 44, Wildycraft.denseStone);
		world.setBlock(i + 3, j + 10, k + 45, Wildycraft.denseStone);
		world.setBlock(i + 3, j + 10, k + 46, Wildycraft.denseStone);
		world.setBlock(i + 3, j + 10, k + 47, Wildycraft.denseStone);
		world.setBlock(i + 3, j + 10, k + 48, Wildycraft.denseStone);
		world.setBlock(i + 3, j + 10, k + 49, Wildycraft.denseStone);
		world.setBlock(i + 3, j + 10, k + 50, Wildycraft.denseStone);
		world.setBlock(i + 3, j + 10, k + 51, Wildycraft.denseStone);
		world.setBlock(i + 3, j + 10, k + 52, Wildycraft.denseStone);
		world.setBlock(i + 3, j + 10, k + 53, Wildycraft.denseStone);
		world.setBlock(i + 3, j + 10, k + 54, Wildycraft.denseStone);
		world.setBlock(i + 3, j + 10, k + 55, Wildycraft.denseStone);
		world.setBlock(i + 3, j + 10, k + 56, Wildycraft.denseStone);
		world.setBlock(i + 3, j + 10, k + 57, Wildycraft.denseStone);
		world.setBlock(i + 3, j + 10, k + 58, Wildycraft.denseStone);
		world.setBlock(i + 3, j + 10, k + 59, Wildycraft.denseStone);
		world.setBlock(i + 3, j + 11, k + 29, Blocks.dirt);
		world.setBlock(i + 3, j + 11, k + 30, Blocks.dirt);
		world.setBlock(i + 3, j + 11, k + 31, Blocks.dirt);
		world.setBlock(i + 3, j + 11, k + 32, Blocks.dirt);
		world.setBlock(i + 3, j + 11, k + 33, Blocks.dirt);
		world.setBlock(i + 3, j + 11, k + 34, Blocks.dirt);
		world.setBlock(i + 3, j + 11, k + 35, Blocks.dirt);
		world.setBlock(i + 3, j + 11, k + 36, Blocks.dirt);
		world.setBlock(i + 3, j + 11, k + 37, Blocks.dirt);
		world.setBlock(i + 3, j + 11, k + 38, Blocks.dirt);
		world.setBlock(i + 3, j + 11, k + 39, Blocks.dirt);
		world.setBlock(i + 3, j + 11, k + 40, Blocks.dirt);
		world.setBlock(i + 3, j + 11, k + 41, Blocks.dirt);
		world.setBlock(i + 3, j + 11, k + 42, Blocks.dirt);
		world.setBlock(i + 3, j + 11, k + 43, Blocks.dirt);
		world.setBlock(i + 3, j + 11, k + 44, Blocks.dirt);
		world.setBlock(i + 3, j + 11, k + 45, Blocks.dirt);
		world.setBlock(i + 3, j + 11, k + 46, Blocks.dirt);
		world.setBlock(i + 3, j + 11, k + 47, Blocks.dirt);
		world.setBlock(i + 3, j + 11, k + 48, Blocks.dirt);
		world.setBlock(i + 3, j + 11, k + 49, Blocks.dirt);
		world.setBlock(i + 3, j + 11, k + 50, Blocks.dirt);
		world.setBlock(i + 3, j + 11, k + 51, Blocks.dirt);
		world.setBlock(i + 3, j + 11, k + 52, Blocks.dirt);
		world.setBlock(i + 3, j + 11, k + 53, Blocks.dirt);
		world.setBlock(i + 3, j + 11, k + 54, Blocks.dirt);
		world.setBlock(i + 3, j + 11, k + 55, Blocks.dirt);
		world.setBlock(i + 3, j + 11, k + 56, Blocks.dirt);
		world.setBlock(i + 3, j + 11, k + 57, Blocks.dirt);
		world.setBlock(i + 3, j + 11, k + 58, Blocks.dirt);
		world.setBlock(i + 3, j + 11, k + 59, Blocks.dirt);
		world.setBlock(i + 3, j + 11, k + 60, Blocks.dirt);
		world.setBlock(i + 3, j + 11, k + 61, Blocks.dirt);
		world.setBlock(i + 3, j + 11, k + 62, Blocks.dirt);
		world.setBlock(i + 3, j + 11, k + 63, Blocks.dirt);
		world.setBlock(i + 3, j + 12, k + 29, Blocks.grass);
		world.setBlock(i + 3, j + 12, k + 30, Blocks.grass);
		world.setBlock(i + 3, j + 12, k + 31, Blocks.grass);
		world.setBlock(i + 3, j + 12, k + 32, Blocks.grass);
		world.setBlock(i + 3, j + 12, k + 33, Blocks.grass);
		world.setBlock(i + 3, j + 12, k + 34, Blocks.grass);
		world.setBlock(i + 3, j + 12, k + 35, Blocks.grass);
		world.setBlock(i + 3, j + 12, k + 36, Blocks.grass);
		world.setBlock(i + 3, j + 12, k + 37, Blocks.grass);
		world.setBlock(i + 3, j + 12, k + 38, Blocks.grass);
		world.setBlock(i + 3, j + 12, k + 39, Blocks.grass);
		world.setBlock(i + 3, j + 12, k + 40, Blocks.grass);
		world.setBlock(i + 3, j + 12, k + 41, Blocks.grass);
		world.setBlock(i + 3, j + 12, k + 42, Blocks.grass);
		world.setBlock(i + 3, j + 12, k + 43, Blocks.grass);
		world.setBlock(i + 3, j + 12, k + 44, Blocks.grass);
		world.setBlock(i + 3, j + 12, k + 45, Blocks.grass);
		world.setBlock(i + 3, j + 12, k + 46, Blocks.grass);
		world.setBlock(i + 3, j + 12, k + 47, Blocks.grass);
		world.setBlock(i + 3, j + 12, k + 48, Blocks.grass);
		world.setBlock(i + 3, j + 12, k + 49, Blocks.grass);
		world.setBlock(i + 3, j + 12, k + 50, Blocks.grass);
		world.setBlock(i + 3, j + 12, k + 51, Blocks.grass);
		world.setBlock(i + 3, j + 12, k + 52, Blocks.grass);
		world.setBlock(i + 3, j + 12, k + 53, Blocks.grass);
		world.setBlock(i + 3, j + 12, k + 54, Blocks.grass);
		world.setBlock(i + 3, j + 12, k + 55, Blocks.grass);
		world.setBlock(i + 3, j + 12, k + 56, Blocks.grass);
		world.setBlock(i + 3, j + 12, k + 57, Blocks.grass);
		world.setBlock(i + 3, j + 12, k + 58, Blocks.grass);
		world.setBlock(i + 3, j + 12, k + 59, Blocks.grass);
		world.setBlock(i + 3, j + 12, k + 60, Blocks.grass);
		world.setBlock(i + 3, j + 12, k + 61, Blocks.grass);
		world.setBlock(i + 3, j + 12, k + 62, Blocks.grass);
		world.setBlock(i + 3, j + 12, k + 63, Blocks.grass);
		world.setBlock(i + 3, j + 21, k + 27, Blocks.wooden_slab, 9, 4);
		world.setBlock(i + 3, j + 22, k + 26, Blocks.spruce_stairs, 4, 4);
		world.setBlock(i + 3, j + 22, k + 27, Blocks.planks, 1, 4);
		world.setBlock(i + 3, j + 22, k + 28, Blocks.spruce_stairs, 4, 4);
		world.setBlock(i + 3, j + 23, k + 25, Blocks.planks, 1, 4);
		world.setBlock(i + 3, j + 23, k + 26, Blocks.planks, 1, 4);
		world.setBlock(i + 3, j + 23, k + 27, Blocks.planks, 1, 4);
		world.setBlock(i + 3, j + 23, k + 28, Blocks.furnace, 2, 4);
		world.setBlock(i + 3, j + 23, k + 29, Blocks.spruce_stairs, 7, 4);
		world.setBlock(i + 3, j + 24, k + 25, Blocks.planks, 1, 4);
		world.setBlock(i + 3, j + 24, k + 29, Blocks.planks, 1, 4);
		world.setBlock(i + 3, j + 25, k + 25, Blocks.glass_pane);
		world.setBlock(i + 3, j + 25, k + 29, Blocks.glass_pane);
		world.setBlock(i + 3, j + 26, k + 25, Blocks.planks, 1, 4);
		world.setBlock(i + 3, j + 26, k + 26, Blocks.wooden_slab, 9, 4);
		world.setBlock(i + 3, j + 26, k + 27, Blocks.wooden_slab, 9, 4);
		world.setBlock(i + 3, j + 26, k + 28, Blocks.wooden_slab, 9, 4);
		world.setBlock(i + 3, j + 26, k + 29, Blocks.planks, 1, 4);
		world.setBlock(i + 3, j + 27, k + 25, Blocks.planks, 1, 4);
		world.setBlock(i + 3, j + 27, k + 29, Blocks.planks, 1, 4);
		world.setBlock(i + 3, j + 28, k + 25, Blocks.fence);
		world.setBlock(i + 3, j + 28, k + 29, Blocks.fence);
		world.setBlock(i + 3, j + 30, k + 26, Blocks.wool);
		world.setBlock(i + 3, j + 30, k + 27, Blocks.wool);
		world.setBlock(i + 3, j + 30, k + 28, Blocks.wool);
		world.setBlock(i + 3, j + 31, k + 25, Blocks.wool);
		world.setBlock(i + 3, j + 31, k + 26, Blocks.wool);
		world.setBlock(i + 3, j + 31, k + 27, Blocks.wool);
		world.setBlock(i + 3, j + 31, k + 28, Blocks.wool);
		world.setBlock(i + 3, j + 31, k + 29, Blocks.wool);
		world.setBlock(i + 3, j + 32, k + 25, Blocks.wool);
		world.setBlock(i + 3, j + 32, k + 26, Blocks.wool);
		world.setBlock(i + 3, j + 32, k + 27, Blocks.wool);
		world.setBlock(i + 3, j + 32, k + 28, Blocks.wool);
		world.setBlock(i + 3, j + 32, k + 29, Blocks.wool);
		world.setBlock(i + 3, j + 33, k + 25, Blocks.wool);
		world.setBlock(i + 3, j + 33, k + 26, Blocks.wool);
		world.setBlock(i + 3, j + 33, k + 27, Blocks.wool);
		world.setBlock(i + 3, j + 33, k + 28, Blocks.wool);
		world.setBlock(i + 3, j + 33, k + 29, Blocks.wool);
		world.setBlock(i + 3, j + 34, k + 26, Blocks.wool);
		world.setBlock(i + 3, j + 34, k + 27, Blocks.wool);
		world.setBlock(i + 3, j + 34, k + 28, Blocks.wool);
		world.setBlock(i + 4, j + 8, k + 42, Wildycraft.denseStone);
		world.setBlock(i + 4, j + 8, k + 43, Wildycraft.denseStone);
		world.setBlock(i + 4, j + 8, k + 44, Wildycraft.denseStone);
		world.setBlock(i + 4, j + 8, k + 45, Wildycraft.denseStone);
		world.setBlock(i + 4, j + 8, k + 46, Wildycraft.denseStone);
		world.setBlock(i + 4, j + 8, k + 47, Wildycraft.denseStone);
		world.setBlock(i + 4, j + 9, k + 34, Wildycraft.denseStone);
		world.setBlock(i + 4, j + 9, k + 35, Wildycraft.denseStone);
		world.setBlock(i + 4, j + 9, k + 36, Wildycraft.denseStone);
		world.setBlock(i + 4, j + 9, k + 37, Wildycraft.denseStone);
		world.setBlock(i + 4, j + 9, k + 38, Wildycraft.denseStone);
		world.setBlock(i + 4, j + 9, k + 39, Wildycraft.denseStone);
		world.setBlock(i + 4, j + 9, k + 40, Wildycraft.denseStone);
		world.setBlock(i + 4, j + 9, k + 41, Wildycraft.denseStone);
		world.setBlock(i + 4, j + 9, k + 42, Wildycraft.denseStone);
		world.setBlock(i + 4, j + 9, k + 43, Wildycraft.denseStone);
		world.setBlock(i + 4, j + 9, k + 44, Wildycraft.denseStone);
		world.setBlock(i + 4, j + 9, k + 45, Wildycraft.denseStone);
		world.setBlock(i + 4, j + 9, k + 46, Wildycraft.denseStone);
		world.setBlock(i + 4, j + 9, k + 47, Wildycraft.denseStone);
		world.setBlock(i + 4, j + 9, k + 48, Wildycraft.denseStone);
		world.setBlock(i + 4, j + 9, k + 49, Wildycraft.denseStone);
		world.setBlock(i + 4, j + 9, k + 50, Wildycraft.denseStone);
		world.setBlock(i + 4, j + 9, k + 51, Wildycraft.denseStone);
		world.setBlock(i + 4, j + 9, k + 52, Wildycraft.denseStone);
		world.setBlock(i + 4, j + 9, k + 53, Wildycraft.denseStone);
		world.setBlock(i + 4, j + 9, k + 54, Wildycraft.denseStone);
		world.setBlock(i + 4, j + 9, k + 55, Wildycraft.denseStone);
		world.setBlock(i + 4, j + 9, k + 56, Wildycraft.denseStone);
		world.setBlock(i + 4, j + 9, k + 57, Wildycraft.denseStone);
		world.setBlock(i + 4, j + 10, k + 29, Wildycraft.denseStone);
		world.setBlock(i + 4, j + 10, k + 30, Wildycraft.denseStone);
		world.setBlock(i + 4, j + 10, k + 31, Wildycraft.denseStone);
		world.setBlock(i + 4, j + 10, k + 32, Wildycraft.denseStone);
		world.setBlock(i + 4, j + 10, k + 33, Wildycraft.denseStone);
		world.setBlock(i + 4, j + 10, k + 34, Wildycraft.denseStone);
		world.setBlock(i + 4, j + 10, k + 35, Wildycraft.denseStone);
		world.setBlock(i + 4, j + 10, k + 36, Wildycraft.denseStone);
		world.setBlock(i + 4, j + 10, k + 37, Wildycraft.denseStone);
		world.setBlock(i + 4, j + 10, k + 38, Wildycraft.denseStone);
		world.setBlock(i + 4, j + 10, k + 39, Wildycraft.denseStone);
		world.setBlock(i + 4, j + 10, k + 40, Wildycraft.denseStone);
		world.setBlock(i + 4, j + 10, k + 41, Wildycraft.denseStone);
		world.setBlock(i + 4, j + 10, k + 42, Wildycraft.denseStone);
		world.setBlock(i + 4, j + 10, k + 43, Wildycraft.denseStone);
		world.setBlock(i + 4, j + 10, k + 44, Wildycraft.denseStone);
		world.setBlock(i + 4, j + 10, k + 45, Wildycraft.denseStone);
		world.setBlock(i + 4, j + 10, k + 46, Wildycraft.denseStone);
		world.setBlock(i + 4, j + 10, k + 47, Wildycraft.denseStone);
		world.setBlock(i + 4, j + 10, k + 48, Wildycraft.denseStone);
		world.setBlock(i + 4, j + 10, k + 49, Wildycraft.denseStone);
		world.setBlock(i + 4, j + 10, k + 50, Wildycraft.denseStone);
		world.setBlock(i + 4, j + 10, k + 51, Wildycraft.denseStone);
		world.setBlock(i + 4, j + 10, k + 52, Wildycraft.denseStone);
		world.setBlock(i + 4, j + 10, k + 53, Wildycraft.denseStone);
		world.setBlock(i + 4, j + 10, k + 54, Wildycraft.denseStone);
		world.setBlock(i + 4, j + 10, k + 55, Wildycraft.denseStone);
		world.setBlock(i + 4, j + 10, k + 56, Wildycraft.denseStone);
		world.setBlock(i + 4, j + 10, k + 57, Wildycraft.denseStone);
		world.setBlock(i + 4, j + 10, k + 58, Wildycraft.denseStone);
		world.setBlock(i + 4, j + 10, k + 59, Wildycraft.denseStone);
		world.setBlock(i + 4, j + 10, k + 60, Wildycraft.denseStone);
		world.setBlock(i + 4, j + 10, k + 61, Wildycraft.denseStone);
		world.setBlock(i + 4, j + 10, k + 62, Wildycraft.denseStone);
		world.setBlock(i + 4, j + 10, k + 63, Wildycraft.denseStone);
		world.setBlock(i + 4, j + 11, k + 25, Blocks.dirt);
		world.setBlock(i + 4, j + 11, k + 26, Blocks.dirt);
		world.setBlock(i + 4, j + 11, k + 27, Blocks.dirt);
		world.setBlock(i + 4, j + 11, k + 28, Blocks.dirt);
		world.setBlock(i + 4, j + 11, k + 29, Blocks.dirt);
		world.setBlock(i + 4, j + 11, k + 30, Blocks.dirt);
		world.setBlock(i + 4, j + 11, k + 31, Blocks.dirt);
		world.setBlock(i + 4, j + 11, k + 32, Blocks.dirt);
		world.setBlock(i + 4, j + 11, k + 33, Blocks.dirt);
		world.setBlock(i + 4, j + 11, k + 34, Blocks.dirt);
		world.setBlock(i + 4, j + 11, k + 35, Blocks.dirt);
		world.setBlock(i + 4, j + 11, k + 36, Blocks.dirt);
		world.setBlock(i + 4, j + 11, k + 37, Blocks.dirt);
		world.setBlock(i + 4, j + 11, k + 38, Blocks.dirt);
		world.setBlock(i + 4, j + 11, k + 39, Blocks.dirt);
		world.setBlock(i + 4, j + 11, k + 40, Blocks.dirt);
		world.setBlock(i + 4, j + 11, k + 41, Blocks.dirt);
		world.setBlock(i + 4, j + 11, k + 42, Blocks.dirt);
		world.setBlock(i + 4, j + 11, k + 43, Blocks.dirt);
		world.setBlock(i + 4, j + 11, k + 44, Blocks.dirt);
		world.setBlock(i + 4, j + 11, k + 45, Blocks.dirt);
		world.setBlock(i + 4, j + 11, k + 46, Blocks.dirt);
		world.setBlock(i + 4, j + 11, k + 47, Blocks.dirt);
		world.setBlock(i + 4, j + 11, k + 48, Blocks.dirt);
		world.setBlock(i + 4, j + 11, k + 49, Blocks.dirt);
		world.setBlock(i + 4, j + 11, k + 50, Blocks.dirt);
		world.setBlock(i + 4, j + 11, k + 51, Blocks.dirt);
		world.setBlock(i + 4, j + 11, k + 52, Blocks.dirt);
		world.setBlock(i + 4, j + 11, k + 53, Blocks.dirt);
		world.setBlock(i + 4, j + 11, k + 54, Blocks.dirt);
		world.setBlock(i + 4, j + 11, k + 55, Blocks.dirt);
		world.setBlock(i + 4, j + 11, k + 56, Blocks.dirt);
		world.setBlock(i + 4, j + 11, k + 57, Blocks.dirt);
		world.setBlock(i + 4, j + 11, k + 58, Blocks.dirt);
		world.setBlock(i + 4, j + 11, k + 59, Blocks.dirt);
		world.setBlock(i + 4, j + 11, k + 60, Blocks.dirt);
		world.setBlock(i + 4, j + 11, k + 61, Blocks.dirt);
		world.setBlock(i + 4, j + 11, k + 62, Blocks.dirt);
		world.setBlock(i + 4, j + 11, k + 63, Blocks.dirt);
		world.setBlock(i + 4, j + 11, k + 64, Blocks.dirt);
		world.setBlock(i + 4, j + 11, k + 65, Blocks.dirt);
		world.setBlock(i + 4, j + 11, k + 66, Blocks.dirt);
		world.setBlock(i + 4, j + 11, k + 67, Blocks.dirt);
		world.setBlock(i + 4, j + 12, k + 25, Blocks.grass);
		world.setBlock(i + 4, j + 12, k + 26, Blocks.grass);
		world.setBlock(i + 4, j + 12, k + 27, Blocks.grass);
		world.setBlock(i + 4, j + 12, k + 28, Blocks.grass);
		world.setBlock(i + 4, j + 12, k + 29, Blocks.grass);
		world.setBlock(i + 4, j + 12, k + 30, Blocks.grass);
		world.setBlock(i + 4, j + 12, k + 31, Blocks.grass);
		world.setBlock(i + 4, j + 12, k + 32, Blocks.grass);
		world.setBlock(i + 4, j + 12, k + 33, Blocks.grass);
		world.setBlock(i + 4, j + 12, k + 34, Blocks.grass);
		world.setBlock(i + 4, j + 12, k + 35, Blocks.grass);
		world.setBlock(i + 4, j + 12, k + 36, Blocks.grass);
		world.setBlock(i + 4, j + 12, k + 37, Blocks.grass);
		world.setBlock(i + 4, j + 12, k + 38, Blocks.grass);
		world.setBlock(i + 4, j + 12, k + 39, Blocks.grass);
		world.setBlock(i + 4, j + 12, k + 40, Blocks.grass);
		world.setBlock(i + 4, j + 12, k + 41, Blocks.grass);
		world.setBlock(i + 4, j + 12, k + 42, Blocks.grass);
		world.setBlock(i + 4, j + 12, k + 43, Blocks.grass);
		world.setBlock(i + 4, j + 12, k + 44, Blocks.grass);
		world.setBlock(i + 4, j + 12, k + 45, Blocks.grass);
		world.setBlock(i + 4, j + 12, k + 46, Blocks.grass);
		world.setBlock(i + 4, j + 12, k + 47, Blocks.grass);
		world.setBlock(i + 4, j + 12, k + 48, Blocks.grass);
		world.setBlock(i + 4, j + 12, k + 49, Blocks.grass);
		world.setBlock(i + 4, j + 12, k + 50, Blocks.grass);
		world.setBlock(i + 4, j + 12, k + 51, Blocks.grass);
		world.setBlock(i + 4, j + 12, k + 52, Blocks.grass);
		world.setBlock(i + 4, j + 12, k + 53, Blocks.grass);
		world.setBlock(i + 4, j + 12, k + 54, Blocks.grass);
		world.setBlock(i + 4, j + 12, k + 55, Blocks.grass);
		world.setBlock(i + 4, j + 12, k + 56, Blocks.grass);
		world.setBlock(i + 4, j + 12, k + 57, Blocks.grass);
		world.setBlock(i + 4, j + 12, k + 58, Blocks.grass);
		world.setBlock(i + 4, j + 12, k + 59, Blocks.grass);
		world.setBlock(i + 4, j + 12, k + 60, Blocks.grass);
		world.setBlock(i + 4, j + 12, k + 61, Blocks.grass);
		world.setBlock(i + 4, j + 12, k + 62, Blocks.grass);
		world.setBlock(i + 4, j + 12, k + 63, Blocks.grass);
		world.setBlock(i + 4, j + 12, k + 64, Blocks.grass);
		world.setBlock(i + 4, j + 12, k + 65, Blocks.grass);
		world.setBlock(i + 4, j + 12, k + 66, Blocks.grass);
		world.setBlock(i + 4, j + 12, k + 67, Blocks.grass);
		world.setBlock(i + 4, j + 21, k + 27, Blocks.wooden_slab, 9, 4);
		world.setBlock(i + 4, j + 22, k + 26, Blocks.spruce_stairs, 6, 4);
		world.setBlock(i + 4, j + 22, k + 27, Blocks.planks, 1, 4);
		world.setBlock(i + 4, j + 22, k + 28, Blocks.spruce_stairs, 7, 4);
		world.setBlock(i + 4, j + 23, k + 25, Blocks.planks, 1, 4);
		world.setBlock(i + 4, j + 23, k + 26, Blocks.planks, 1, 4);
		world.setBlock(i + 4, j + 23, k + 27, Blocks.planks, 1, 4);
		world.setBlock(i + 4, j + 23, k + 28, Blocks.planks, 1, 4);
		world.setBlock(i + 4, j + 23, k + 29, Blocks.spruce_stairs, 7, 4);
		world.setBlock(i + 4, j + 24, k + 25, Blocks.planks, 1, 4);
		world.setBlock(i + 4, j + 24, k + 26, Blocks.planks, 1, 4);
		world.setBlock(i + 4, j + 24, k + 28, Blocks.planks, 1, 4);
		world.setBlock(i + 4, j + 24, k + 29, Blocks.planks, 1, 4);
		world.setBlock(i + 4, j + 25, k + 25, Blocks.planks, 1, 4);
		world.setBlock(i + 4, j + 25, k + 26, Blocks.planks, 1, 4);
		world.setBlock(i + 4, j + 25, k + 28, Blocks.planks, 1, 4);
		world.setBlock(i + 4, j + 25, k + 29, Blocks.planks, 1, 4);
		world.setBlock(i + 4, j + 26, k + 25, Blocks.planks, 1, 4);
		world.setBlock(i + 4, j + 26, k + 26, Blocks.planks, 1, 4);
		world.setBlock(i + 4, j + 26, k + 27, Blocks.glowstone);
		world.setBlock(i + 4, j + 26, k + 28, Blocks.planks, 1, 4);
		world.setBlock(i + 4, j + 26, k + 29, Blocks.planks, 1, 4);
		world.setBlock(i + 4, j + 27, k + 25, Blocks.spruce_stairs, 1, 4);
		world.setBlock(i + 4, j + 27, k + 27, Blocks.planks, 5, 4);
		world.setBlock(i + 4, j + 27, k + 29, Blocks.spruce_stairs, 1, 4);
		world.setBlock(i + 4, j + 30, k + 26, Blocks.wool);
		world.setBlock(i + 4, j + 30, k + 27, Blocks.wool);
		world.setBlock(i + 4, j + 30, k + 28, Blocks.wool);
		world.setBlock(i + 4, j + 31, k + 25, Blocks.wool);
		world.setBlock(i + 4, j + 31, k + 26, Blocks.wool);
		world.setBlock(i + 4, j + 31, k + 27, Blocks.wool);
		world.setBlock(i + 4, j + 31, k + 28, Blocks.wool);
		world.setBlock(i + 4, j + 31, k + 29, Blocks.wool);
		world.setBlock(i + 4, j + 32, k + 25, Blocks.wool);
		world.setBlock(i + 4, j + 32, k + 26, Blocks.wool);
		world.setBlock(i + 4, j + 32, k + 27, Blocks.wool);
		world.setBlock(i + 4, j + 32, k + 28, Blocks.wool);
		world.setBlock(i + 4, j + 32, k + 29, Blocks.wool);
		world.setBlock(i + 4, j + 33, k + 25, Blocks.wool);
		world.setBlock(i + 4, j + 33, k + 26, Blocks.wool);
		world.setBlock(i + 4, j + 33, k + 27, Blocks.wool);
		world.setBlock(i + 4, j + 33, k + 28, Blocks.wool);
		world.setBlock(i + 4, j + 33, k + 29, Blocks.wool);
		world.setBlock(i + 4, j + 34, k + 26, Blocks.wool);
		world.setBlock(i + 4, j + 34, k + 27, Blocks.wool);
		world.setBlock(i + 4, j + 34, k + 28, Blocks.wool);
		world.setBlock(i + 5, j + 7, k + 43, Blocks.stone);
		world.setBlock(i + 5, j + 7, k + 44, Blocks.stone);
		world.setBlock(i + 5, j + 7, k + 45, Blocks.stone);
		world.setBlock(i + 5, j + 7, k + 46, Blocks.stone);
		world.setBlock(i + 5, j + 8, k + 37, Wildycraft.denseStone);
		world.setBlock(i + 5, j + 8, k + 38, Wildycraft.denseStone);
		world.setBlock(i + 5, j + 8, k + 39, Wildycraft.denseStone);
		world.setBlock(i + 5, j + 8, k + 40, Wildycraft.denseStone);
		world.setBlock(i + 5, j + 8, k + 41, Wildycraft.denseStone);
		world.setBlock(i + 5, j + 8, k + 42, Wildycraft.denseStone);
		world.setBlock(i + 5, j + 8, k + 43, Wildycraft.denseStone);
		world.setBlock(i + 5, j + 8, k + 44, Wildycraft.denseStone);
		world.setBlock(i + 5, j + 8, k + 45, Wildycraft.denseStone);
		world.setBlock(i + 5, j + 8, k + 46, Wildycraft.denseStone);
		world.setBlock(i + 5, j + 8, k + 47, Wildycraft.denseStone);
		world.setBlock(i + 5, j + 8, k + 48, Wildycraft.denseStone);
		world.setBlock(i + 5, j + 8, k + 49, Wildycraft.denseStone);
		world.setBlock(i + 5, j + 8, k + 50, Wildycraft.denseStone);
		world.setBlock(i + 5, j + 8, k + 51, Wildycraft.denseStone);
		world.setBlock(i + 5, j + 8, k + 52, Wildycraft.denseStone);
		world.setBlock(i + 5, j + 8, k + 53, Wildycraft.denseStone);
		world.setBlock(i + 5, j + 8, k + 54, Wildycraft.denseStone);
		world.setBlock(i + 5, j + 8, k + 55, Wildycraft.denseStone);
		world.setBlock(i + 5, j + 8, k + 56, Wildycraft.denseStone);
		world.setBlock(i + 5, j + 8, k + 57, Wildycraft.denseStone);
		world.setBlock(i + 5, j + 9, k + 29, Wildycraft.denseStone);
		world.setBlock(i + 5, j + 9, k + 30, Wildycraft.denseStone);
		world.setBlock(i + 5, j + 9, k + 31, Wildycraft.denseStone);
		world.setBlock(i + 5, j + 9, k + 32, Wildycraft.denseStone);
		world.setBlock(i + 5, j + 9, k + 33, Wildycraft.denseStone);
		world.setBlock(i + 5, j + 9, k + 34, Wildycraft.denseStone);
		world.setBlock(i + 5, j + 9, k + 35, Wildycraft.denseStone);
		world.setBlock(i + 5, j + 9, k + 36, Wildycraft.denseStone);
		world.setBlock(i + 5, j + 9, k + 37, Wildycraft.denseStone);
		world.setBlock(i + 5, j + 9, k + 38, Wildycraft.denseStone);
		world.setBlock(i + 5, j + 9, k + 39, Wildycraft.denseStone);
		world.setBlock(i + 5, j + 9, k + 40, Wildycraft.denseStone);
		world.setBlock(i + 5, j + 9, k + 41, Wildycraft.denseStone);
		world.setBlock(i + 5, j + 9, k + 42, Wildycraft.denseStone);
		world.setBlock(i + 5, j + 9, k + 43, Wildycraft.denseStone);
		world.setBlock(i + 5, j + 9, k + 44, Wildycraft.denseStone);
		world.setBlock(i + 5, j + 9, k + 45, Wildycraft.denseStone);
		world.setBlock(i + 5, j + 9, k + 46, Wildycraft.denseStone);
		world.setBlock(i + 5, j + 9, k + 47, Wildycraft.denseStone);
		world.setBlock(i + 5, j + 9, k + 48, Wildycraft.denseStone);
		world.setBlock(i + 5, j + 9, k + 49, Wildycraft.denseStone);
		world.setBlock(i + 5, j + 9, k + 50, Wildycraft.denseStone);
		world.setBlock(i + 5, j + 9, k + 51, Wildycraft.denseStone);
		world.setBlock(i + 5, j + 9, k + 52, Wildycraft.denseStone);
		world.setBlock(i + 5, j + 9, k + 53, Wildycraft.denseStone);
		world.setBlock(i + 5, j + 9, k + 54, Wildycraft.denseStone);
		world.setBlock(i + 5, j + 9, k + 55, Wildycraft.denseStone);
		world.setBlock(i + 5, j + 9, k + 56, Wildycraft.denseStone);
		world.setBlock(i + 5, j + 9, k + 57, Wildycraft.denseStone);
		world.setBlock(i + 5, j + 9, k + 58, Wildycraft.denseStone);
		world.setBlock(i + 5, j + 9, k + 59, Wildycraft.denseStone);
		world.setBlock(i + 5, j + 9, k + 60, Wildycraft.denseStone);
		world.setBlock(i + 5, j + 9, k + 61, Wildycraft.denseStone);
		world.setBlock(i + 5, j + 10, k + 25, Wildycraft.denseStone);
		world.setBlock(i + 5, j + 10, k + 26, Wildycraft.denseStone);
		world.setBlock(i + 5, j + 10, k + 27, Wildycraft.denseStone);
		world.setBlock(i + 5, j + 10, k + 28, Wildycraft.denseStone);
		world.setBlock(i + 5, j + 10, k + 29, Wildycraft.denseStone);
		world.setBlock(i + 5, j + 10, k + 30, Wildycraft.denseStone);
		world.setBlock(i + 5, j + 10, k + 31, Wildycraft.denseStone);
		world.setBlock(i + 5, j + 10, k + 32, Wildycraft.denseStone);
		world.setBlock(i + 5, j + 10, k + 33, Wildycraft.denseStone);
		world.setBlock(i + 5, j + 10, k + 34, Wildycraft.denseStone);
		world.setBlock(i + 5, j + 10, k + 35, Wildycraft.denseStone);
		world.setBlock(i + 5, j + 10, k + 36, Wildycraft.denseStone);
		world.setBlock(i + 5, j + 10, k + 37, Wildycraft.denseStone);
		world.setBlock(i + 5, j + 10, k + 38, Wildycraft.denseStone);
		world.setBlock(i + 5, j + 10, k + 39, Wildycraft.denseStone);
		world.setBlock(i + 5, j + 10, k + 40, Wildycraft.denseStone);
		world.setBlock(i + 5, j + 10, k + 41, Wildycraft.denseStone);
		world.setBlock(i + 5, j + 10, k + 42, Wildycraft.denseStone);
		world.setBlock(i + 5, j + 10, k + 43, Wildycraft.denseStone);
		world.setBlock(i + 5, j + 10, k + 44, Wildycraft.denseStone);
		world.setBlock(i + 5, j + 10, k + 45, Wildycraft.denseStone);
		world.setBlock(i + 5, j + 10, k + 46, Wildycraft.denseStone);
		world.setBlock(i + 5, j + 10, k + 47, Wildycraft.denseStone);
		world.setBlock(i + 5, j + 10, k + 48, Wildycraft.denseStone);
		world.setBlock(i + 5, j + 10, k + 49, Wildycraft.denseStone);
		world.setBlock(i + 5, j + 10, k + 50, Wildycraft.denseStone);
		world.setBlock(i + 5, j + 10, k + 51, Wildycraft.denseStone);
		world.setBlock(i + 5, j + 10, k + 52, Wildycraft.denseStone);
		world.setBlock(i + 5, j + 10, k + 53, Wildycraft.denseStone);
		world.setBlock(i + 5, j + 10, k + 54, Wildycraft.denseStone);
		world.setBlock(i + 5, j + 10, k + 55, Wildycraft.denseStone);
		world.setBlock(i + 5, j + 10, k + 56, Wildycraft.denseStone);
		world.setBlock(i + 5, j + 10, k + 57, Wildycraft.denseStone);
		world.setBlock(i + 5, j + 10, k + 58, Wildycraft.denseStone);
		world.setBlock(i + 5, j + 10, k + 59, Wildycraft.denseStone);
		world.setBlock(i + 5, j + 10, k + 60, Wildycraft.denseStone);
		world.setBlock(i + 5, j + 10, k + 61, Wildycraft.denseStone);
		world.setBlock(i + 5, j + 10, k + 62, Wildycraft.denseStone);
		world.setBlock(i + 5, j + 10, k + 63, Wildycraft.denseStone);
		world.setBlock(i + 5, j + 10, k + 64, Wildycraft.denseStone);
		world.setBlock(i + 5, j + 10, k + 65, Wildycraft.denseStone);
		world.setBlock(i + 5, j + 10, k + 66, Wildycraft.denseStone);
		world.setBlock(i + 5, j + 10, k + 67, Wildycraft.denseStone);
		world.setBlock(i + 5, j + 11, k + 22, Blocks.dirt);
		world.setBlock(i + 5, j + 11, k + 23, Blocks.dirt);
		world.setBlock(i + 5, j + 11, k + 24, Blocks.dirt);
		world.setBlock(i + 5, j + 11, k + 25, Blocks.dirt);
		world.setBlock(i + 5, j + 11, k + 26, Blocks.dirt);
		world.setBlock(i + 5, j + 11, k + 27, Blocks.dirt);
		world.setBlock(i + 5, j + 11, k + 28, Blocks.dirt);
		world.setBlock(i + 5, j + 11, k + 29, Blocks.dirt);
		world.setBlock(i + 5, j + 11, k + 30, Blocks.dirt);
		world.setBlock(i + 5, j + 11, k + 31, Blocks.dirt);
		world.setBlock(i + 5, j + 11, k + 32, Blocks.dirt);
		world.setBlock(i + 5, j + 11, k + 33, Blocks.dirt);
		world.setBlock(i + 5, j + 11, k + 34, Blocks.dirt);
		world.setBlock(i + 5, j + 11, k + 35, Blocks.dirt);
		world.setBlock(i + 5, j + 11, k + 36, Blocks.dirt);
		world.setBlock(i + 5, j + 11, k + 37, Blocks.dirt);
		world.setBlock(i + 5, j + 11, k + 38, Blocks.dirt);
		world.setBlock(i + 5, j + 11, k + 39, Blocks.dirt);
		world.setBlock(i + 5, j + 11, k + 40, Blocks.dirt);
		world.setBlock(i + 5, j + 11, k + 41, Blocks.dirt);
		world.setBlock(i + 5, j + 11, k + 42, Blocks.dirt);
		world.setBlock(i + 5, j + 11, k + 43, Blocks.dirt);
		world.setBlock(i + 5, j + 11, k + 44, Blocks.dirt);
		world.setBlock(i + 5, j + 11, k + 45, Blocks.dirt);
		world.setBlock(i + 5, j + 11, k + 46, Blocks.dirt);
		world.setBlock(i + 5, j + 11, k + 47, Blocks.dirt);
		world.setBlock(i + 5, j + 11, k + 48, Blocks.dirt);
		world.setBlock(i + 5, j + 11, k + 49, Blocks.dirt);
		world.setBlock(i + 5, j + 11, k + 50, Blocks.dirt);
		world.setBlock(i + 5, j + 11, k + 51, Blocks.dirt);
		world.setBlock(i + 5, j + 11, k + 52, Blocks.dirt);
		world.setBlock(i + 5, j + 11, k + 53, Blocks.dirt);
		world.setBlock(i + 5, j + 11, k + 54, Blocks.dirt);
		world.setBlock(i + 5, j + 11, k + 55, Blocks.dirt);
		world.setBlock(i + 5, j + 11, k + 56, Blocks.dirt);
		world.setBlock(i + 5, j + 11, k + 57, Blocks.dirt);
		world.setBlock(i + 5, j + 11, k + 58, Blocks.dirt);
		world.setBlock(i + 5, j + 11, k + 59, Blocks.dirt);
		world.setBlock(i + 5, j + 11, k + 60, Blocks.dirt);
		world.setBlock(i + 5, j + 11, k + 61, Blocks.dirt);
		world.setBlock(i + 5, j + 11, k + 62, Blocks.dirt);
		world.setBlock(i + 5, j + 11, k + 63, Blocks.dirt);
		world.setBlock(i + 5, j + 11, k + 64, Blocks.dirt);
		world.setBlock(i + 5, j + 11, k + 65, Blocks.dirt);
		world.setBlock(i + 5, j + 11, k + 66, Blocks.dirt);
		world.setBlock(i + 5, j + 11, k + 67, Blocks.dirt);
		world.setBlock(i + 5, j + 11, k + 68, Blocks.dirt);
		world.setBlock(i + 5, j + 11, k + 69, Blocks.dirt);
		world.setBlock(i + 5, j + 11, k + 70, Blocks.dirt);
		world.setBlock(i + 5, j + 11, k + 71, Blocks.dirt);
		world.setBlock(i + 5, j + 12, k + 22, Blocks.grass);
		world.setBlock(i + 5, j + 12, k + 23, Blocks.grass);
		world.setBlock(i + 5, j + 12, k + 24, Blocks.grass);
		world.setBlock(i + 5, j + 12, k + 25, Blocks.grass);
		world.setBlock(i + 5, j + 12, k + 26, Blocks.grass);
		world.setBlock(i + 5, j + 12, k + 27, Blocks.grass);
		world.setBlock(i + 5, j + 12, k + 28, Blocks.grass);
		world.setBlock(i + 5, j + 12, k + 29, Blocks.grass);
		world.setBlock(i + 5, j + 12, k + 30, Blocks.grass);
		world.setBlock(i + 5, j + 12, k + 31, Blocks.grass);
		world.setBlock(i + 5, j + 12, k + 32, Blocks.grass);
		world.setBlock(i + 5, j + 12, k + 33, Blocks.grass);
		world.setBlock(i + 5, j + 12, k + 34, Blocks.grass);
		world.setBlock(i + 5, j + 12, k + 35, Blocks.grass);
		world.setBlock(i + 5, j + 12, k + 36, Blocks.grass);
		world.setBlock(i + 5, j + 12, k + 37, Blocks.grass);
		world.setBlock(i + 5, j + 12, k + 38, Blocks.grass);
		world.setBlock(i + 5, j + 12, k + 39, Blocks.grass);
		world.setBlock(i + 5, j + 12, k + 40, Blocks.grass);
		world.setBlock(i + 5, j + 12, k + 41, Blocks.grass);
		world.setBlock(i + 5, j + 12, k + 42, Blocks.grass);
		world.setBlock(i + 5, j + 12, k + 43, Blocks.grass);
		world.setBlock(i + 5, j + 12, k + 44, Blocks.grass);
		world.setBlock(i + 5, j + 12, k + 45, Blocks.grass);
		world.setBlock(i + 5, j + 12, k + 46, Blocks.grass);
		world.setBlock(i + 5, j + 12, k + 47, Blocks.grass);
		world.setBlock(i + 5, j + 12, k + 48, Blocks.grass);
		world.setBlock(i + 5, j + 12, k + 49, Blocks.grass);
		world.setBlock(i + 5, j + 12, k + 50, Blocks.grass);
		world.setBlock(i + 5, j + 12, k + 51, Blocks.grass);
		world.setBlock(i + 5, j + 12, k + 52, Blocks.grass);
		world.setBlock(i + 5, j + 12, k + 53, Blocks.grass);
		world.setBlock(i + 5, j + 12, k + 54, Blocks.grass);
		world.setBlock(i + 5, j + 12, k + 55, Blocks.grass);
		world.setBlock(i + 5, j + 12, k + 56, Blocks.grass);
		world.setBlock(i + 5, j + 12, k + 57, Blocks.grass);
		world.setBlock(i + 5, j + 12, k + 58, Blocks.grass);
		world.setBlock(i + 5, j + 12, k + 59, Blocks.grass);
		world.setBlock(i + 5, j + 12, k + 60, Blocks.grass);
		world.setBlock(i + 5, j + 12, k + 61, Blocks.grass);
		world.setBlock(i + 5, j + 12, k + 62, Blocks.grass);
		world.setBlock(i + 5, j + 12, k + 63, Blocks.grass);
		world.setBlock(i + 5, j + 12, k + 64, Blocks.grass);
		world.setBlock(i + 5, j + 12, k + 65, Blocks.grass);
		world.setBlock(i + 5, j + 12, k + 66, Blocks.grass);
		world.setBlock(i + 5, j + 12, k + 67, Blocks.grass);
		world.setBlock(i + 5, j + 12, k + 68, Blocks.grass);
		world.setBlock(i + 5, j + 12, k + 69, Blocks.grass);
		world.setBlock(i + 5, j + 12, k + 70, Blocks.grass);
		world.setBlock(i + 5, j + 12, k + 71, Blocks.grass);
		world.setBlock(i + 5, j + 21, k + 27, Blocks.wooden_slab, 9, 4);
		world.setBlock(i + 5, j + 22, k + 26, Blocks.spruce_stairs, 6, 4);
		world.setBlock(i + 5, j + 22, k + 27, Blocks.planks, 1, 4);
		world.setBlock(i + 5, j + 22, k + 28, Blocks.spruce_stairs, 7, 4);
		world.setBlock(i + 5, j + 23, k + 25, Blocks.planks, 1, 4);
		world.setBlock(i + 5, j + 23, k + 26, Blocks.planks, 1, 4);
		world.setBlock(i + 5, j + 23, k + 27, Blocks.crafting_table);
		world.setBlock(i + 5, j + 23, k + 28, Blocks.planks, 1, 4);
		world.setBlock(i + 5, j + 23, k + 29, Blocks.spruce_stairs, 7, 4);
		world.setBlock(i + 5, j + 23, k + 31, Blocks.spruce_stairs);
		world.setBlock(i + 5, j + 23, k + 32, Blocks.spruce_stairs);
		world.setBlock(i + 5, j + 23, k + 33, Blocks.spruce_stairs);
		world.setBlock(i + 5, j + 24, k + 25, Blocks.planks, 1, 4);
		world.setBlock(i + 5, j + 24, k + 29, Blocks.planks, 1, 4);
		world.setBlock(i + 5, j + 25, k + 25, Blocks.spruce_stairs, 1, 4);
		world.setBlock(i + 5, j + 25, k + 29, Blocks.spruce_stairs, 1, 4);
		world.setBlock(i + 5, j + 30, k + 26, Blocks.wool);
		world.setBlock(i + 5, j + 30, k + 27, Blocks.wool);
		world.setBlock(i + 5, j + 30, k + 28, Blocks.wool);
		world.setBlock(i + 5, j + 31, k + 25, Blocks.wool);
		world.setBlock(i + 5, j + 31, k + 26, Blocks.wool);
		world.setBlock(i + 5, j + 31, k + 27, Blocks.wool);
		world.setBlock(i + 5, j + 31, k + 28, Blocks.wool);
		world.setBlock(i + 5, j + 31, k + 29, Blocks.wool);
		world.setBlock(i + 5, j + 32, k + 25, Blocks.wool);
		world.setBlock(i + 5, j + 32, k + 26, Blocks.wool);
		world.setBlock(i + 5, j + 32, k + 27, Blocks.wool);
		world.setBlock(i + 5, j + 32, k + 28, Blocks.wool);
		world.setBlock(i + 5, j + 32, k + 29, Blocks.wool);
		world.setBlock(i + 5, j + 33, k + 25, Blocks.wool);
		world.setBlock(i + 5, j + 33, k + 26, Blocks.wool);
		world.setBlock(i + 5, j + 33, k + 27, Blocks.wool);
		world.setBlock(i + 5, j + 33, k + 28, Blocks.wool);
		world.setBlock(i + 5, j + 33, k + 29, Blocks.wool);
		world.setBlock(i + 5, j + 34, k + 26, Blocks.wool);
		world.setBlock(i + 5, j + 34, k + 27, Blocks.wool);
		world.setBlock(i + 5, j + 34, k + 28, Blocks.wool);
		world.setBlock(i + 6, j + 6, k + 44, Blocks.stone);
		world.setBlock(i + 6, j + 6, k + 45, Blocks.stone);
		world.setBlock(i + 6, j + 7, k + 35, Blocks.stone);
		world.setBlock(i + 6, j + 7, k + 36, Blocks.stone);
		world.setBlock(i + 6, j + 7, k + 37, Blocks.stone);
		world.setBlock(i + 6, j + 7, k + 38, Blocks.stone);
		world.setBlock(i + 6, j + 7, k + 39, Blocks.stone);
		world.setBlock(i + 6, j + 7, k + 40, Blocks.stone);
		world.setBlock(i + 6, j + 7, k + 41, Blocks.stone);
		world.setBlock(i + 6, j + 7, k + 42, Blocks.stone);
		world.setBlock(i + 6, j + 7, k + 43, Blocks.stone);
		world.setBlock(i + 6, j + 7, k + 44, Blocks.stone);
		world.setBlock(i + 6, j + 7, k + 45, Blocks.stone);
		world.setBlock(i + 6, j + 7, k + 46, Blocks.stone);
		world.setBlock(i + 6, j + 7, k + 47, Blocks.stone);
		world.setBlock(i + 6, j + 7, k + 48, Blocks.stone);
		world.setBlock(i + 6, j + 7, k + 49, Blocks.stone);
		world.setBlock(i + 6, j + 7, k + 50, Blocks.stone);
		world.setBlock(i + 6, j + 7, k + 51, Blocks.stone);
		world.setBlock(i + 6, j + 7, k + 52, Blocks.stone);
		world.setBlock(i + 6, j + 7, k + 53, Blocks.stone);
		world.setBlock(i + 6, j + 7, k + 54, Blocks.stone);
		world.setBlock(i + 6, j + 7, k + 55, Blocks.stone);
		world.setBlock(i + 6, j + 7, k + 56, Blocks.stone);
		world.setBlock(i + 6, j + 8, k + 31, Wildycraft.denseStone);
		world.setBlock(i + 6, j + 8, k + 32, Wildycraft.denseStone);
		world.setBlock(i + 6, j + 8, k + 33, Wildycraft.denseStone);
		world.setBlock(i + 6, j + 8, k + 34, Wildycraft.denseStone);
		world.setBlock(i + 6, j + 8, k + 35, Wildycraft.denseStone);
		world.setBlock(i + 6, j + 8, k + 36, Wildycraft.denseStone);
		world.setBlock(i + 6, j + 8, k + 37, Wildycraft.denseStone);
		world.setBlock(i + 6, j + 8, k + 38, Wildycraft.denseStone);
		world.setBlock(i + 6, j + 8, k + 39, Wildycraft.denseStone);
		world.setBlock(i + 6, j + 8, k + 40, Wildycraft.denseStone);
		world.setBlock(i + 6, j + 8, k + 41, Wildycraft.denseStone);
		world.setBlock(i + 6, j + 8, k + 42, Wildycraft.denseStone);
		world.setBlock(i + 6, j + 8, k + 43, Wildycraft.denseStone);
		world.setBlock(i + 6, j + 8, k + 44, Wildycraft.denseStone);
		world.setBlock(i + 6, j + 8, k + 45, Wildycraft.denseStone);
		world.setBlock(i + 6, j + 8, k + 46, Wildycraft.denseStone);
		world.setBlock(i + 6, j + 8, k + 47, Wildycraft.denseStone);
		world.setBlock(i + 6, j + 8, k + 48, Wildycraft.denseStone);
		world.setBlock(i + 6, j + 8, k + 49, Wildycraft.denseStone);
		world.setBlock(i + 6, j + 8, k + 50, Wildycraft.denseStone);
		world.setBlock(i + 6, j + 8, k + 51, Wildycraft.denseStone);
		world.setBlock(i + 6, j + 8, k + 52, Wildycraft.denseStone);
		world.setBlock(i + 6, j + 8, k + 53, Wildycraft.denseStone);
		world.setBlock(i + 6, j + 8, k + 54, Wildycraft.denseStone);
		world.setBlock(i + 6, j + 8, k + 55, Wildycraft.denseStone);
		world.setBlock(i + 6, j + 8, k + 56, Wildycraft.denseStone);
		world.setBlock(i + 6, j + 8, k + 57, Wildycraft.denseStone);
		world.setBlock(i + 6, j + 8, k + 58, Wildycraft.denseStone);
		world.setBlock(i + 6, j + 8, k + 59, Wildycraft.denseStone);
		world.setBlock(i + 6, j + 8, k + 60, Wildycraft.denseStone);
		world.setBlock(i + 6, j + 8, k + 61, Wildycraft.denseStone);
		world.setBlock(i + 6, j + 8, k + 62, Wildycraft.denseStone);
		world.setBlock(i + 6, j + 8, k + 63, Wildycraft.denseStone);
		world.setBlock(i + 6, j + 8, k + 64, Wildycraft.denseStone);
		world.setBlock(i + 6, j + 9, k + 23, Wildycraft.denseStone);
		world.setBlock(i + 6, j + 9, k + 24, Wildycraft.denseStone);
		world.setBlock(i + 6, j + 9, k + 25, Wildycraft.denseStone);
		world.setBlock(i + 6, j + 9, k + 26, Wildycraft.denseStone);
		world.setBlock(i + 6, j + 9, k + 27, Wildycraft.denseStone);
		world.setBlock(i + 6, j + 9, k + 28, Wildycraft.denseStone);
		world.setBlock(i + 6, j + 9, k + 29, Wildycraft.denseStone);
		world.setBlock(i + 6, j + 9, k + 30, Wildycraft.denseStone);
		world.setBlock(i + 6, j + 9, k + 31, Wildycraft.denseStone);
		world.setBlock(i + 6, j + 9, k + 32, Wildycraft.denseStone);
		world.setBlock(i + 6, j + 9, k + 33, Wildycraft.denseStone);
		world.setBlock(i + 6, j + 9, k + 34, Wildycraft.denseStone);
		world.setBlock(i + 6, j + 9, k + 35, Wildycraft.denseStone);
		world.setBlock(i + 6, j + 9, k + 36, Wildycraft.denseStone);
		world.setBlock(i + 6, j + 9, k + 37, Wildycraft.denseStone);
		world.setBlock(i + 6, j + 9, k + 38, Wildycraft.denseStone);
		world.setBlock(i + 6, j + 9, k + 39, Wildycraft.denseStone);
		world.setBlock(i + 6, j + 9, k + 40, Wildycraft.denseStone);
		world.setBlock(i + 6, j + 9, k + 41, Wildycraft.denseStone);
		world.setBlock(i + 6, j + 9, k + 42, Wildycraft.denseStone);
		world.setBlock(i + 6, j + 9, k + 43, Wildycraft.denseStone);
		world.setBlock(i + 6, j + 9, k + 44, Wildycraft.denseStone);
		world.setBlock(i + 6, j + 9, k + 45, Wildycraft.denseStone);
		world.setBlock(i + 6, j + 9, k + 46, Wildycraft.denseStone);
		world.setBlock(i + 6, j + 9, k + 47, Wildycraft.denseStone);
		world.setBlock(i + 6, j + 9, k + 48, Wildycraft.denseStone);
		world.setBlock(i + 6, j + 9, k + 49, Wildycraft.denseStone);
		world.setBlock(i + 6, j + 9, k + 50, Wildycraft.denseStone);
		world.setBlock(i + 6, j + 9, k + 51, Wildycraft.denseStone);
		world.setBlock(i + 6, j + 9, k + 52, Wildycraft.denseStone);
		world.setBlock(i + 6, j + 9, k + 53, Wildycraft.denseStone);
		world.setBlock(i + 6, j + 9, k + 54, Wildycraft.denseStone);
		world.setBlock(i + 6, j + 9, k + 55, Wildycraft.denseStone);
		world.setBlock(i + 6, j + 9, k + 56, Wildycraft.denseStone);
		world.setBlock(i + 6, j + 9, k + 57, Wildycraft.denseStone);
		world.setBlock(i + 6, j + 9, k + 58, Wildycraft.denseStone);
		world.setBlock(i + 6, j + 9, k + 59, Wildycraft.denseStone);
		world.setBlock(i + 6, j + 9, k + 60, Wildycraft.denseStone);
		world.setBlock(i + 6, j + 9, k + 61, Wildycraft.denseStone);
		world.setBlock(i + 6, j + 9, k + 62, Wildycraft.denseStone);
		world.setBlock(i + 6, j + 9, k + 63, Wildycraft.denseStone);
		world.setBlock(i + 6, j + 9, k + 64, Wildycraft.denseStone);
		world.setBlock(i + 6, j + 9, k + 65, Wildycraft.denseStone);
		world.setBlock(i + 6, j + 10, k + 22, Wildycraft.denseStone);
		world.setBlock(i + 6, j + 10, k + 23, Wildycraft.denseStone);
		world.setBlock(i + 6, j + 10, k + 24, Wildycraft.denseStone);
		world.setBlock(i + 6, j + 10, k + 25, Wildycraft.denseStone);
		world.setBlock(i + 6, j + 10, k + 26, Wildycraft.denseStone);
		world.setBlock(i + 6, j + 10, k + 27, Wildycraft.denseStone);
		world.setBlock(i + 6, j + 10, k + 28, Wildycraft.denseStone);
		world.setBlock(i + 6, j + 10, k + 29, Wildycraft.denseStone);
		world.setBlock(i + 6, j + 10, k + 30, Wildycraft.denseStone);
		world.setBlock(i + 6, j + 10, k + 31, Wildycraft.denseStone);
		world.setBlock(i + 6, j + 10, k + 32, Wildycraft.denseStone);
		world.setBlock(i + 6, j + 10, k + 33, Wildycraft.denseStone);
		world.setBlock(i + 6, j + 10, k + 34, Wildycraft.denseStone);
		world.setBlock(i + 6, j + 10, k + 35, Wildycraft.denseStone);
		world.setBlock(i + 6, j + 10, k + 36, Wildycraft.denseStone);
		world.setBlock(i + 6, j + 10, k + 37, Wildycraft.denseStone);
		world.setBlock(i + 6, j + 10, k + 38, Wildycraft.denseStone);
		world.setBlock(i + 6, j + 10, k + 39, Wildycraft.denseStone);
		world.setBlock(i + 6, j + 10, k + 40, Wildycraft.denseStone);
		world.setBlock(i + 6, j + 10, k + 41, Wildycraft.denseStone);
		world.setBlock(i + 6, j + 10, k + 42, Wildycraft.denseStone);
		world.setBlock(i + 6, j + 10, k + 43, Wildycraft.denseStone);
		world.setBlock(i + 6, j + 10, k + 44, Wildycraft.denseStone);
		world.setBlock(i + 6, j + 10, k + 45, Wildycraft.denseStone);
		world.setBlock(i + 6, j + 10, k + 46, Wildycraft.denseStone);
		world.setBlock(i + 6, j + 10, k + 47, Wildycraft.denseStone);
		world.setBlock(i + 6, j + 10, k + 48, Wildycraft.denseStone);
		world.setBlock(i + 6, j + 10, k + 49, Wildycraft.denseStone);
		world.setBlock(i + 6, j + 10, k + 50, Wildycraft.denseStone);
		world.setBlock(i + 6, j + 10, k + 51, Wildycraft.denseStone);
		world.setBlock(i + 6, j + 10, k + 52, Wildycraft.denseStone);
		world.setBlock(i + 6, j + 10, k + 53, Wildycraft.denseStone);
		world.setBlock(i + 6, j + 10, k + 54, Wildycraft.denseStone);
		world.setBlock(i + 6, j + 10, k + 55, Wildycraft.denseStone);
		world.setBlock(i + 6, j + 10, k + 56, Wildycraft.denseStone);
		world.setBlock(i + 6, j + 10, k + 57, Wildycraft.denseStone);
		world.setBlock(i + 6, j + 10, k + 58, Wildycraft.denseStone);
		world.setBlock(i + 6, j + 10, k + 59, Wildycraft.denseStone);
		world.setBlock(i + 6, j + 10, k + 60, Wildycraft.denseStone);
		world.setBlock(i + 6, j + 10, k + 61, Wildycraft.denseStone);
		world.setBlock(i + 6, j + 10, k + 62, Wildycraft.denseStone);
		world.setBlock(i + 6, j + 10, k + 63, Wildycraft.denseStone);
		world.setBlock(i + 6, j + 10, k + 64, Wildycraft.denseStone);
		world.setBlock(i + 6, j + 10, k + 65, Wildycraft.denseStone);
		world.setBlock(i + 6, j + 10, k + 66, Wildycraft.denseStone);
		world.setBlock(i + 6, j + 10, k + 67, Wildycraft.denseStone);
		world.setBlock(i + 6, j + 10, k + 68, Wildycraft.denseStone);
		world.setBlock(i + 6, j + 10, k + 69, Wildycraft.denseStone);
		world.setBlock(i + 6, j + 10, k + 70, Wildycraft.denseStone);
		world.setBlock(i + 6, j + 10, k + 71, Wildycraft.denseStone);
		world.setBlock(i + 6, j + 11, k + 20, Blocks.dirt);
		world.setBlock(i + 6, j + 11, k + 21, Blocks.dirt);
		world.setBlock(i + 6, j + 11, k + 22, Blocks.dirt);
		world.setBlock(i + 6, j + 11, k + 23, Blocks.dirt);
		world.setBlock(i + 6, j + 11, k + 24, Blocks.dirt);
		world.setBlock(i + 6, j + 11, k + 25, Blocks.dirt);
		world.setBlock(i + 6, j + 11, k + 26, Blocks.dirt);
		world.setBlock(i + 6, j + 11, k + 27, Blocks.dirt);
		world.setBlock(i + 6, j + 11, k + 28, Blocks.dirt);
		world.setBlock(i + 6, j + 11, k + 29, Blocks.dirt);
		world.setBlock(i + 6, j + 11, k + 30, Blocks.dirt);
		world.setBlock(i + 6, j + 11, k + 31, Blocks.dirt);
		world.setBlock(i + 6, j + 11, k + 32, Blocks.dirt);
		world.setBlock(i + 6, j + 11, k + 33, Blocks.dirt);
		world.setBlock(i + 6, j + 11, k + 34, Blocks.dirt);
		world.setBlock(i + 6, j + 11, k + 35, Blocks.dirt);
		world.setBlock(i + 6, j + 11, k + 36, Blocks.dirt);
		world.setBlock(i + 6, j + 11, k + 37, Blocks.dirt);
		world.setBlock(i + 6, j + 11, k + 38, Blocks.dirt);
		world.setBlock(i + 6, j + 11, k + 39, Blocks.dirt);
		world.setBlock(i + 6, j + 11, k + 40, Blocks.dirt);
		world.setBlock(i + 6, j + 11, k + 41, Blocks.dirt);
		world.setBlock(i + 6, j + 11, k + 42, Blocks.dirt);
		world.setBlock(i + 6, j + 11, k + 43, Blocks.dirt);
		world.setBlock(i + 6, j + 11, k + 44, Blocks.dirt);
		world.setBlock(i + 6, j + 11, k + 45, Blocks.dirt);
		world.setBlock(i + 6, j + 11, k + 46, Blocks.dirt);
		world.setBlock(i + 6, j + 11, k + 47, Blocks.dirt);
		world.setBlock(i + 6, j + 11, k + 48, Blocks.dirt);
		world.setBlock(i + 6, j + 11, k + 49, Blocks.dirt);
		world.setBlock(i + 6, j + 11, k + 50, Blocks.dirt);
		world.setBlock(i + 6, j + 11, k + 51, Blocks.dirt);
		world.setBlock(i + 6, j + 11, k + 52, Blocks.dirt);
		world.setBlock(i + 6, j + 11, k + 53, Blocks.dirt);
		world.setBlock(i + 6, j + 11, k + 54, Blocks.dirt);
		world.setBlock(i + 6, j + 11, k + 55, Blocks.dirt);
		world.setBlock(i + 6, j + 11, k + 56, Blocks.dirt);
		world.setBlock(i + 6, j + 11, k + 57, Blocks.dirt);
		world.setBlock(i + 6, j + 11, k + 58, Blocks.dirt);
		world.setBlock(i + 6, j + 11, k + 59, Blocks.dirt);
		world.setBlock(i + 6, j + 11, k + 60, Blocks.dirt);
		world.setBlock(i + 6, j + 11, k + 61, Blocks.dirt);
		world.setBlock(i + 6, j + 11, k + 62, Blocks.dirt);
		world.setBlock(i + 6, j + 11, k + 63, Blocks.dirt);
		world.setBlock(i + 6, j + 11, k + 64, Blocks.dirt);
		world.setBlock(i + 6, j + 11, k + 65, Blocks.dirt);
		world.setBlock(i + 6, j + 11, k + 66, Blocks.dirt);
		world.setBlock(i + 6, j + 11, k + 67, Blocks.dirt);
		world.setBlock(i + 6, j + 11, k + 68, Blocks.dirt);
		world.setBlock(i + 6, j + 11, k + 69, Blocks.dirt);
		world.setBlock(i + 6, j + 11, k + 70, Blocks.dirt);
		world.setBlock(i + 6, j + 11, k + 71, Blocks.dirt);
		world.setBlock(i + 6, j + 11, k + 72, Blocks.dirt);
		world.setBlock(i + 6, j + 11, k + 73, Blocks.dirt);
		world.setBlock(i + 6, j + 11, k + 74, Blocks.dirt);
		world.setBlock(i + 6, j + 12, k + 20, Blocks.grass);
		world.setBlock(i + 6, j + 12, k + 21, Blocks.grass);
		world.setBlock(i + 6, j + 12, k + 22, Blocks.grass);
		world.setBlock(i + 6, j + 12, k + 23, Blocks.grass);
		world.setBlock(i + 6, j + 12, k + 24, Blocks.grass);
		world.setBlock(i + 6, j + 12, k + 25, Blocks.grass);
		world.setBlock(i + 6, j + 12, k + 26, Blocks.grass);
		world.setBlock(i + 6, j + 12, k + 27, Blocks.grass);
		world.setBlock(i + 6, j + 12, k + 28, Blocks.grass);
		world.setBlock(i + 6, j + 12, k + 29, Blocks.grass);
		world.setBlock(i + 6, j + 12, k + 30, Blocks.grass);
		world.setBlock(i + 6, j + 12, k + 31, Blocks.grass);
		world.setBlock(i + 6, j + 12, k + 32, Blocks.grass);
		world.setBlock(i + 6, j + 12, k + 33, Blocks.grass);
		world.setBlock(i + 6, j + 12, k + 34, Blocks.grass);
		world.setBlock(i + 6, j + 12, k + 35, Blocks.grass);
		world.setBlock(i + 6, j + 12, k + 36, Blocks.grass);
		world.setBlock(i + 6, j + 12, k + 37, Blocks.grass);
		world.setBlock(i + 6, j + 12, k + 38, Blocks.grass);
		world.setBlock(i + 6, j + 12, k + 39, Blocks.grass);
		world.setBlock(i + 6, j + 12, k + 40, Blocks.grass);
		world.setBlock(i + 6, j + 12, k + 41, Blocks.grass);
		world.setBlock(i + 6, j + 12, k + 42, Blocks.grass);
		world.setBlock(i + 6, j + 12, k + 43, Blocks.grass);
		world.setBlock(i + 6, j + 12, k + 44, Blocks.grass);
		world.setBlock(i + 6, j + 12, k + 45, Blocks.grass);
		world.setBlock(i + 6, j + 12, k + 46, Blocks.grass);
		world.setBlock(i + 6, j + 12, k + 47, Blocks.grass);
		world.setBlock(i + 6, j + 12, k + 48, Blocks.grass);
		world.setBlock(i + 6, j + 12, k + 49, Blocks.grass);
		world.setBlock(i + 6, j + 12, k + 50, Blocks.grass);
		world.setBlock(i + 6, j + 12, k + 51, Blocks.grass);
		world.setBlock(i + 6, j + 12, k + 52, Blocks.grass);
		world.setBlock(i + 6, j + 12, k + 53, Blocks.grass);
		world.setBlock(i + 6, j + 12, k + 54, Blocks.grass);
		world.setBlock(i + 6, j + 12, k + 55, Blocks.grass);
		world.setBlock(i + 6, j + 12, k + 56, Blocks.grass);
		world.setBlock(i + 6, j + 12, k + 57, Blocks.grass);
		world.setBlock(i + 6, j + 12, k + 58, Blocks.grass);
		world.setBlock(i + 6, j + 12, k + 59, Blocks.grass);
		world.setBlock(i + 6, j + 12, k + 60, Blocks.grass);
		world.setBlock(i + 6, j + 12, k + 61, Blocks.grass);
		world.setBlock(i + 6, j + 12, k + 62, Blocks.grass);
		world.setBlock(i + 6, j + 12, k + 63, Blocks.grass);
		world.setBlock(i + 6, j + 12, k + 64, Blocks.grass);
		world.setBlock(i + 6, j + 12, k + 65, Blocks.grass);
		world.setBlock(i + 6, j + 12, k + 66, Blocks.grass);
		world.setBlock(i + 6, j + 12, k + 67, Blocks.grass);
		world.setBlock(i + 6, j + 12, k + 68, Blocks.grass);
		world.setBlock(i + 6, j + 12, k + 69, Blocks.grass);
		world.setBlock(i + 6, j + 12, k + 70, Blocks.grass);
		world.setBlock(i + 6, j + 12, k + 71, Blocks.grass);
		world.setBlock(i + 6, j + 12, k + 72, Blocks.grass);
		world.setBlock(i + 6, j + 12, k + 73, Blocks.grass);
		world.setBlock(i + 6, j + 12, k + 74, Blocks.grass);
		world.setBlock(i + 6, j + 21, k + 27, Blocks.wooden_slab, 9, 4);
		world.setBlock(i + 6, j + 22, k + 26, Blocks.spruce_stairs, 6, 4);
		world.setBlock(i + 6, j + 22, k + 27, Blocks.planks, 1, 4);
		world.setBlock(i + 6, j + 22, k + 28, Blocks.spruce_stairs, 7, 4);
		world.setBlock(i + 6, j + 23, k + 25, Blocks.planks, 1, 4);
		world.setBlock(i + 6, j + 23, k + 26, Blocks.planks, 1, 4);
		world.setBlock(i + 6, j + 23, k + 27, Blocks.crafting_table);
		world.setBlock(i + 6, j + 23, k + 28, Blocks.planks, 1, 4);
		world.setBlock(i + 6, j + 23, k + 29, Blocks.spruce_stairs, 5, 4);
		world.setBlock(i + 6, j + 23, k + 31, Blocks.spruce_stairs, 2, 4);
		world.setBlock(i + 6, j + 23, k + 32, Blocks.planks, 1, 4);
		world.setBlock(i + 6, j + 23, k + 33, Blocks.spruce_stairs, 3, 4);
		world.setBlock(i + 6, j + 24, k + 25, Blocks.planks, 1, 4);
		world.setBlock(i + 6, j + 24, k + 26, Blocks.wooden_slab, 1, 4);
		world.setBlock(i + 6, j + 24, k + 28, Blocks.wooden_slab, 1, 4);
		world.setBlock(i + 6, j + 24, k + 29, Blocks.planks, 1, 4);
		world.setBlock(i + 6, j + 25, k + 25, Blocks.wooden_slab, 1, 4);
		world.setBlock(i + 6, j + 25, k + 29, Blocks.wooden_slab, 1, 4);
		world.setBlock(i + 6, j + 30, k + 26, Blocks.wool);
		world.setBlock(i + 6, j + 30, k + 27, Blocks.wool);
		world.setBlock(i + 6, j + 30, k + 28, Blocks.wool);
		world.setBlock(i + 6, j + 31, k + 25, Blocks.wool);
		world.setBlock(i + 6, j + 31, k + 26, Blocks.wool);
		world.setBlock(i + 6, j + 31, k + 27, Blocks.wool);
		world.setBlock(i + 6, j + 31, k + 28, Blocks.wool);
		world.setBlock(i + 6, j + 31, k + 29, Blocks.wool);
		world.setBlock(i + 6, j + 32, k + 25, Blocks.wool);
		world.setBlock(i + 6, j + 32, k + 26, Blocks.wool);
		world.setBlock(i + 6, j + 32, k + 27, Blocks.wool);
		world.setBlock(i + 6, j + 32, k + 28, Blocks.wool);
		world.setBlock(i + 6, j + 32, k + 29, Blocks.wool);
		world.setBlock(i + 6, j + 33, k + 25, Blocks.wool);
		world.setBlock(i + 6, j + 33, k + 26, Blocks.wool);
		world.setBlock(i + 6, j + 33, k + 27, Blocks.wool);
		world.setBlock(i + 6, j + 33, k + 28, Blocks.wool);
		world.setBlock(i + 6, j + 33, k + 29, Blocks.wool);
		world.setBlock(i + 6, j + 34, k + 26, Blocks.wool);
		world.setBlock(i + 6, j + 34, k + 27, Blocks.wool);
		world.setBlock(i + 6, j + 34, k + 28, Blocks.wool);
		world.setBlock(i + 7, j + 6, k + 36, Blocks.stone);
		world.setBlock(i + 7, j + 6, k + 37, Blocks.stone);
		world.setBlock(i + 7, j + 6, k + 38, Blocks.stone);
		world.setBlock(i + 7, j + 6, k + 39, Blocks.stone);
		world.setBlock(i + 7, j + 6, k + 40, Blocks.stone);
		world.setBlock(i + 7, j + 6, k + 41, Blocks.stone);
		world.setBlock(i + 7, j + 6, k + 42, Blocks.stone);
		world.setBlock(i + 7, j + 6, k + 43, Blocks.stone);
		world.setBlock(i + 7, j + 6, k + 44, Blocks.stone);
		world.setBlock(i + 7, j + 6, k + 45, Blocks.stone);
		world.setBlock(i + 7, j + 6, k + 46, Blocks.stone);
		world.setBlock(i + 7, j + 6, k + 47, Blocks.stone);
		world.setBlock(i + 7, j + 6, k + 48, Blocks.stone);
		world.setBlock(i + 7, j + 6, k + 49, Blocks.stone);
		world.setBlock(i + 7, j + 6, k + 50, Blocks.stone);
		world.setBlock(i + 7, j + 6, k + 51, Blocks.stone);
		world.setBlock(i + 7, j + 6, k + 52, Blocks.stone);
		world.setBlock(i + 7, j + 6, k + 53, Blocks.stone);
		world.setBlock(i + 7, j + 6, k + 54, Blocks.stone);
		world.setBlock(i + 7, j + 6, k + 55, Blocks.stone);
		world.setBlock(i + 7, j + 6, k + 56, Blocks.stone);
		world.setBlock(i + 7, j + 7, k + 29, Blocks.stone);
		world.setBlock(i + 7, j + 7, k + 30, Blocks.stone);
		world.setBlock(i + 7, j + 7, k + 31, Blocks.stone);
		world.setBlock(i + 7, j + 7, k + 32, Blocks.stone);
		world.setBlock(i + 7, j + 7, k + 33, Blocks.stone);
		world.setBlock(i + 7, j + 7, k + 34, Blocks.stone);
		world.setBlock(i + 7, j + 7, k + 35, Blocks.stone);
		world.setBlock(i + 7, j + 7, k + 36, Blocks.stone);
		world.setBlock(i + 7, j + 7, k + 37, Blocks.stone);
		world.setBlock(i + 7, j + 7, k + 38, Blocks.stone);
		world.setBlock(i + 7, j + 7, k + 39, Blocks.stone);
		world.setBlock(i + 7, j + 7, k + 40, Blocks.stone);
		world.setBlock(i + 7, j + 7, k + 41, Blocks.stone);
		world.setBlock(i + 7, j + 7, k + 42, Blocks.stone);
		world.setBlock(i + 7, j + 7, k + 43, Blocks.stone);
		world.setBlock(i + 7, j + 7, k + 44, Blocks.stone);
		world.setBlock(i + 7, j + 7, k + 45, Blocks.stone);
		world.setBlock(i + 7, j + 7, k + 46, Blocks.stone);
		world.setBlock(i + 7, j + 7, k + 47, Blocks.stone);
		world.setBlock(i + 7, j + 7, k + 48, Blocks.stone);
		world.setBlock(i + 7, j + 7, k + 49, Blocks.stone);
		world.setBlock(i + 7, j + 7, k + 50, Blocks.stone);
		world.setBlock(i + 7, j + 7, k + 51, Blocks.stone);
		world.setBlock(i + 7, j + 7, k + 52, Blocks.stone);
		world.setBlock(i + 7, j + 7, k + 53, Blocks.stone);
		world.setBlock(i + 7, j + 7, k + 54, Blocks.stone);
		world.setBlock(i + 7, j + 7, k + 55, Blocks.stone);
		world.setBlock(i + 7, j + 7, k + 56, Blocks.stone);
		world.setBlock(i + 7, j + 7, k + 57, Blocks.stone);
		world.setBlock(i + 7, j + 7, k + 58, Blocks.stone);
		world.setBlock(i + 7, j + 7, k + 59, Blocks.stone);
		world.setBlock(i + 7, j + 7, k + 60, Blocks.stone);
		world.setBlock(i + 7, j + 7, k + 61, Blocks.stone);
		world.setBlock(i + 7, j + 7, k + 62, Blocks.stone);
		world.setBlock(i + 7, j + 7, k + 63, Blocks.stone);
		world.setBlock(i + 7, j + 8, k + 24, Wildycraft.denseStone);
		world.setBlock(i + 7, j + 8, k + 25, Wildycraft.denseStone);
		world.setBlock(i + 7, j + 8, k + 26, Wildycraft.denseStone);
		world.setBlock(i + 7, j + 8, k + 27, Wildycraft.denseStone);
		world.setBlock(i + 7, j + 8, k + 28, Wildycraft.denseStone);
		world.setBlock(i + 7, j + 8, k + 29, Wildycraft.denseStone);
		world.setBlock(i + 7, j + 8, k + 30, Wildycraft.denseStone);
		world.setBlock(i + 7, j + 8, k + 31, Wildycraft.denseStone);
		world.setBlock(i + 7, j + 8, k + 32, Wildycraft.denseStone);
		world.setBlock(i + 7, j + 8, k + 33, Wildycraft.denseStone);
		world.setBlock(i + 7, j + 8, k + 34, Wildycraft.denseStone);
		world.setBlock(i + 7, j + 8, k + 35, Wildycraft.denseStone);
		world.setBlock(i + 7, j + 8, k + 36, Wildycraft.denseStone);
		world.setBlock(i + 7, j + 8, k + 37, Wildycraft.denseStone);
		world.setBlock(i + 7, j + 8, k + 38, Wildycraft.denseStone);
		world.setBlock(i + 7, j + 8, k + 39, Wildycraft.denseStone);
		world.setBlock(i + 7, j + 8, k + 40, Wildycraft.denseStone);
		world.setBlock(i + 7, j + 8, k + 41, Wildycraft.denseStone);
		world.setBlock(i + 7, j + 8, k + 42, Wildycraft.denseStone);
		world.setBlock(i + 7, j + 8, k + 43, Wildycraft.denseStone);
		world.setBlock(i + 7, j + 8, k + 44, Wildycraft.denseStone);
		world.setBlock(i + 7, j + 8, k + 45, Wildycraft.denseStone);
		world.setBlock(i + 7, j + 8, k + 46, Wildycraft.denseStone);
		world.setBlock(i + 7, j + 8, k + 47, Wildycraft.denseStone);
		world.setBlock(i + 7, j + 8, k + 48, Wildycraft.denseStone);
		world.setBlock(i + 7, j + 8, k + 49, Wildycraft.denseStone);
		world.setBlock(i + 7, j + 8, k + 50, Wildycraft.denseStone);
		world.setBlock(i + 7, j + 8, k + 51, Wildycraft.denseStone);
		world.setBlock(i + 7, j + 8, k + 52, Wildycraft.denseStone);
		world.setBlock(i + 7, j + 8, k + 53, Wildycraft.denseStone);
		world.setBlock(i + 7, j + 8, k + 54, Wildycraft.denseStone);
		world.setBlock(i + 7, j + 8, k + 55, Wildycraft.denseStone);
		world.setBlock(i + 7, j + 8, k + 56, Wildycraft.denseStone);
		world.setBlock(i + 7, j + 8, k + 57, Wildycraft.denseStone);
		world.setBlock(i + 7, j + 8, k + 58, Wildycraft.denseStone);
		world.setBlock(i + 7, j + 8, k + 59, Wildycraft.denseStone);
		world.setBlock(i + 7, j + 8, k + 60, Wildycraft.denseStone);
		world.setBlock(i + 7, j + 8, k + 61, Wildycraft.denseStone);
		world.setBlock(i + 7, j + 8, k + 62, Wildycraft.denseStone);
		world.setBlock(i + 7, j + 8, k + 63, Wildycraft.denseStone);
		world.setBlock(i + 7, j + 8, k + 64, Wildycraft.denseStone);
		world.setBlock(i + 7, j + 8, k + 65, Wildycraft.denseStone);
		world.setBlock(i + 7, j + 8, k + 66, Wildycraft.denseStone);
		world.setBlock(i + 7, j + 9, k + 22, Wildycraft.denseStone);
		world.setBlock(i + 7, j + 9, k + 23, Wildycraft.denseStone);
		world.setBlock(i + 7, j + 9, k + 24, Wildycraft.denseStone);
		world.setBlock(i + 7, j + 9, k + 25, Wildycraft.denseStone);
		world.setBlock(i + 7, j + 9, k + 26, Wildycraft.denseStone);
		world.setBlock(i + 7, j + 9, k + 27, Wildycraft.denseStone);
		world.setBlock(i + 7, j + 9, k + 28, Wildycraft.denseStone);
		world.setBlock(i + 7, j + 9, k + 29, Wildycraft.denseStone);
		world.setBlock(i + 7, j + 9, k + 30, Wildycraft.denseStone);
		world.setBlock(i + 7, j + 9, k + 31, Wildycraft.denseStone);
		world.setBlock(i + 7, j + 9, k + 32, Wildycraft.denseStone);
		world.setBlock(i + 7, j + 9, k + 33, Wildycraft.denseStone);
		world.setBlock(i + 7, j + 9, k + 34, Wildycraft.denseStone);
		world.setBlock(i + 7, j + 9, k + 35, Wildycraft.denseStone);
		world.setBlock(i + 7, j + 9, k + 36, Wildycraft.denseStone);
		world.setBlock(i + 7, j + 9, k + 37, Wildycraft.denseStone);
		world.setBlock(i + 7, j + 9, k + 38, Wildycraft.denseStone);
		world.setBlock(i + 7, j + 9, k + 39, Wildycraft.denseStone);
		world.setBlock(i + 7, j + 9, k + 40, Wildycraft.denseStone);
		world.setBlock(i + 7, j + 9, k + 41, Wildycraft.denseStone);
		world.setBlock(i + 7, j + 9, k + 42, Wildycraft.denseStone);
		world.setBlock(i + 7, j + 9, k + 43, Wildycraft.denseStone);
		world.setBlock(i + 7, j + 9, k + 44, Wildycraft.denseStone);
		world.setBlock(i + 7, j + 9, k + 45, Wildycraft.denseStone);
		world.setBlock(i + 7, j + 9, k + 46, Wildycraft.denseStone);
		world.setBlock(i + 7, j + 9, k + 47, Wildycraft.denseStone);
		world.setBlock(i + 7, j + 9, k + 48, Wildycraft.denseStone);
		world.setBlock(i + 7, j + 9, k + 49, Wildycraft.denseStone);
		world.setBlock(i + 7, j + 9, k + 50, Wildycraft.denseStone);
		world.setBlock(i + 7, j + 9, k + 51, Wildycraft.denseStone);
		world.setBlock(i + 7, j + 9, k + 52, Wildycraft.denseStone);
		world.setBlock(i + 7, j + 9, k + 53, Wildycraft.denseStone);
		world.setBlock(i + 7, j + 9, k + 54, Wildycraft.denseStone);
		world.setBlock(i + 7, j + 9, k + 55, Wildycraft.denseStone);
		world.setBlock(i + 7, j + 9, k + 56, Wildycraft.denseStone);
		world.setBlock(i + 7, j + 9, k + 57, Wildycraft.denseStone);
		world.setBlock(i + 7, j + 9, k + 58, Wildycraft.denseStone);
		world.setBlock(i + 7, j + 9, k + 59, Wildycraft.denseStone);
		world.setBlock(i + 7, j + 9, k + 60, Wildycraft.denseStone);
		world.setBlock(i + 7, j + 9, k + 61, Wildycraft.denseStone);
		world.setBlock(i + 7, j + 9, k + 62, Wildycraft.denseStone);
		world.setBlock(i + 7, j + 9, k + 63, Wildycraft.denseStone);
		world.setBlock(i + 7, j + 9, k + 64, Wildycraft.denseStone);
		world.setBlock(i + 7, j + 9, k + 65, Wildycraft.denseStone);
		world.setBlock(i + 7, j + 9, k + 66, Wildycraft.denseStone);
		world.setBlock(i + 7, j + 9, k + 67, Wildycraft.denseStone);
		world.setBlock(i + 7, j + 9, k + 68, Wildycraft.denseStone);
		world.setBlock(i + 7, j + 9, k + 69, Wildycraft.denseStone);
		world.setBlock(i + 7, j + 10, k + 20, Wildycraft.denseStone);
		world.setBlock(i + 7, j + 10, k + 21, Wildycraft.denseStone);
		world.setBlock(i + 7, j + 10, k + 22, Wildycraft.denseStone);
		world.setBlock(i + 7, j + 10, k + 23, Wildycraft.denseStone);
		world.setBlock(i + 7, j + 10, k + 24, Wildycraft.denseStone);
		world.setBlock(i + 7, j + 10, k + 25, Wildycraft.denseStone);
		world.setBlock(i + 7, j + 10, k + 26, Wildycraft.denseStone);
		world.setBlock(i + 7, j + 10, k + 27, Wildycraft.denseStone);
		world.setBlock(i + 7, j + 10, k + 28, Wildycraft.denseStone);
		world.setBlock(i + 7, j + 10, k + 29, Wildycraft.denseStone);
		world.setBlock(i + 7, j + 10, k + 30, Wildycraft.denseStone);
		world.setBlock(i + 7, j + 10, k + 31, Wildycraft.denseStone);
		world.setBlock(i + 7, j + 10, k + 32, Wildycraft.denseStone);
		world.setBlock(i + 7, j + 10, k + 33, Wildycraft.denseStone);
		world.setBlock(i + 7, j + 10, k + 34, Wildycraft.denseStone);
		world.setBlock(i + 7, j + 10, k + 35, Wildycraft.denseStone);
		world.setBlock(i + 7, j + 10, k + 36, Wildycraft.denseStone);
		world.setBlock(i + 7, j + 10, k + 37, Wildycraft.denseStone);
		world.setBlock(i + 7, j + 10, k + 38, Wildycraft.denseStone);
		world.setBlock(i + 7, j + 10, k + 39, Wildycraft.denseStone);
		world.setBlock(i + 7, j + 10, k + 40, Wildycraft.denseStone);
		world.setBlock(i + 7, j + 10, k + 41, Wildycraft.denseStone);
		world.setBlock(i + 7, j + 10, k + 42, Wildycraft.denseStone);
		world.setBlock(i + 7, j + 10, k + 43, Wildycraft.denseStone);
		world.setBlock(i + 7, j + 10, k + 44, Wildycraft.denseStone);
		world.setBlock(i + 7, j + 10, k + 45, Wildycraft.denseStone);
		world.setBlock(i + 7, j + 10, k + 46, Wildycraft.denseStone);
		world.setBlock(i + 7, j + 10, k + 47, Wildycraft.denseStone);
		world.setBlock(i + 7, j + 10, k + 48, Wildycraft.denseStone);
		world.setBlock(i + 7, j + 10, k + 49, Wildycraft.denseStone);
		world.setBlock(i + 7, j + 10, k + 50, Wildycraft.denseStone);
		world.setBlock(i + 7, j + 10, k + 51, Wildycraft.denseStone);
		world.setBlock(i + 7, j + 10, k + 52, Wildycraft.denseStone);
		world.setBlock(i + 7, j + 10, k + 53, Wildycraft.denseStone);
		world.setBlock(i + 7, j + 10, k + 54, Wildycraft.denseStone);
		world.setBlock(i + 7, j + 10, k + 55, Wildycraft.denseStone);
		world.setBlock(i + 7, j + 10, k + 56, Wildycraft.denseStone);
		world.setBlock(i + 7, j + 10, k + 57, Wildycraft.denseStone);
		world.setBlock(i + 7, j + 10, k + 58, Wildycraft.denseStone);
		world.setBlock(i + 7, j + 10, k + 59, Wildycraft.denseStone);
		world.setBlock(i + 7, j + 10, k + 60, Wildycraft.denseStone);
		world.setBlock(i + 7, j + 10, k + 61, Wildycraft.denseStone);
		world.setBlock(i + 7, j + 10, k + 62, Wildycraft.denseStone);
		world.setBlock(i + 7, j + 10, k + 63, Wildycraft.denseStone);
		world.setBlock(i + 7, j + 10, k + 64, Wildycraft.denseStone);
		world.setBlock(i + 7, j + 10, k + 65, Wildycraft.denseStone);
		world.setBlock(i + 7, j + 10, k + 66, Wildycraft.denseStone);
		world.setBlock(i + 7, j + 10, k + 67, Wildycraft.denseStone);
		world.setBlock(i + 7, j + 10, k + 68, Wildycraft.denseStone);
		world.setBlock(i + 7, j + 10, k + 69, Wildycraft.denseStone);
		world.setBlock(i + 7, j + 10, k + 70, Wildycraft.denseStone);
		world.setBlock(i + 7, j + 10, k + 71, Wildycraft.denseStone);
		world.setBlock(i + 7, j + 10, k + 72, Wildycraft.denseStone);
		world.setBlock(i + 7, j + 10, k + 73, Wildycraft.denseStone);
		world.setBlock(i + 7, j + 10, k + 74, Wildycraft.denseStone);
		world.setBlock(i + 7, j + 11, k + 18, Blocks.dirt);
		world.setBlock(i + 7, j + 11, k + 19, Blocks.dirt);
		world.setBlock(i + 7, j + 11, k + 20, Blocks.dirt);
		world.setBlock(i + 7, j + 11, k + 21, Blocks.dirt);
		world.setBlock(i + 7, j + 11, k + 22, Blocks.dirt);
		world.setBlock(i + 7, j + 11, k + 23, Blocks.dirt);
		world.setBlock(i + 7, j + 11, k + 24, Blocks.dirt);
		world.setBlock(i + 7, j + 11, k + 25, Blocks.dirt);
		world.setBlock(i + 7, j + 11, k + 26, Blocks.dirt);
		world.setBlock(i + 7, j + 11, k + 27, Blocks.dirt);
		world.setBlock(i + 7, j + 11, k + 28, Blocks.dirt);
		world.setBlock(i + 7, j + 11, k + 29, Blocks.dirt);
		world.setBlock(i + 7, j + 11, k + 30, Blocks.dirt);
		world.setBlock(i + 7, j + 11, k + 31, Blocks.dirt);
		world.setBlock(i + 7, j + 11, k + 32, Blocks.dirt);
		world.setBlock(i + 7, j + 11, k + 33, Blocks.dirt);
		world.setBlock(i + 7, j + 11, k + 34, Blocks.dirt);
		world.setBlock(i + 7, j + 11, k + 35, Blocks.dirt);
		world.setBlock(i + 7, j + 11, k + 36, Blocks.dirt);
		world.setBlock(i + 7, j + 11, k + 37, Blocks.dirt);
		world.setBlock(i + 7, j + 11, k + 38, Blocks.dirt);
		world.setBlock(i + 7, j + 11, k + 39, Blocks.dirt);
		world.setBlock(i + 7, j + 11, k + 40, Blocks.dirt);
		world.setBlock(i + 7, j + 11, k + 41, Blocks.dirt);
		world.setBlock(i + 7, j + 11, k + 42, Blocks.dirt);
		world.setBlock(i + 7, j + 11, k + 43, Blocks.dirt);
		world.setBlock(i + 7, j + 11, k + 44, Blocks.dirt);
		world.setBlock(i + 7, j + 11, k + 45, Blocks.dirt);
		world.setBlock(i + 7, j + 11, k + 46, Blocks.dirt);
		world.setBlock(i + 7, j + 11, k + 47, Blocks.dirt);
		world.setBlock(i + 7, j + 11, k + 48, Blocks.dirt);
		world.setBlock(i + 7, j + 11, k + 49, Blocks.dirt);
		world.setBlock(i + 7, j + 11, k + 50, Blocks.dirt);
		world.setBlock(i + 7, j + 11, k + 51, Blocks.dirt);
		world.setBlock(i + 7, j + 11, k + 52, Blocks.dirt);
		world.setBlock(i + 7, j + 11, k + 53, Blocks.dirt);
		world.setBlock(i + 7, j + 11, k + 54, Blocks.dirt);
		world.setBlock(i + 7, j + 11, k + 55, Blocks.dirt);
		world.setBlock(i + 7, j + 11, k + 56, Blocks.dirt);
		world.setBlock(i + 7, j + 11, k + 57, Blocks.dirt);
		world.setBlock(i + 7, j + 11, k + 58, Blocks.dirt);
		world.setBlock(i + 7, j + 11, k + 59, Blocks.dirt);
		world.setBlock(i + 7, j + 11, k + 60, Blocks.dirt);
		world.setBlock(i + 7, j + 11, k + 61, Blocks.dirt);
		world.setBlock(i + 7, j + 11, k + 62, Blocks.dirt);
		world.setBlock(i + 7, j + 11, k + 63, Blocks.dirt);
		world.setBlock(i + 7, j + 11, k + 64, Blocks.dirt);
		world.setBlock(i + 7, j + 11, k + 65, Blocks.dirt);
		world.setBlock(i + 7, j + 11, k + 66, Blocks.dirt);
		world.setBlock(i + 7, j + 11, k + 67, Blocks.dirt);
		world.setBlock(i + 7, j + 11, k + 68, Blocks.dirt);
		world.setBlock(i + 7, j + 11, k + 69, Blocks.dirt);
		world.setBlock(i + 7, j + 11, k + 70, Blocks.dirt);
		world.setBlock(i + 7, j + 11, k + 71, Blocks.dirt);
		world.setBlock(i + 7, j + 11, k + 72, Blocks.dirt);
		world.setBlock(i + 7, j + 11, k + 73, Blocks.dirt);
		world.setBlock(i + 7, j + 11, k + 74, Blocks.dirt);
		world.setBlock(i + 7, j + 11, k + 75, Blocks.dirt);
		world.setBlock(i + 7, j + 11, k + 76, Blocks.dirt);
		world.setBlock(i + 7, j + 12, k + 18, Blocks.grass);
		world.setBlock(i + 7, j + 12, k + 19, Blocks.grass);
		world.setBlock(i + 7, j + 12, k + 20, Blocks.grass);
		world.setBlock(i + 7, j + 12, k + 21, Blocks.grass);
		world.setBlock(i + 7, j + 12, k + 22, Blocks.grass);
		world.setBlock(i + 7, j + 12, k + 23, Blocks.grass);
		world.setBlock(i + 7, j + 12, k + 24, Blocks.grass);
		world.setBlock(i + 7, j + 12, k + 25, Blocks.grass);
		world.setBlock(i + 7, j + 12, k + 26, Blocks.grass);
		world.setBlock(i + 7, j + 12, k + 27, Blocks.grass);
		world.setBlock(i + 7, j + 12, k + 28, Blocks.grass);
		world.setBlock(i + 7, j + 12, k + 29, Blocks.grass);
		world.setBlock(i + 7, j + 12, k + 30, Blocks.grass);
		world.setBlock(i + 7, j + 12, k + 31, Blocks.grass);
		world.setBlock(i + 7, j + 12, k + 32, Blocks.grass);
		world.setBlock(i + 7, j + 12, k + 33, Blocks.grass);
		world.setBlock(i + 7, j + 12, k + 34, Blocks.grass);
		world.setBlock(i + 7, j + 12, k + 35, Blocks.grass);
		world.setBlock(i + 7, j + 12, k + 36, Blocks.grass);
		world.setBlock(i + 7, j + 12, k + 37, Blocks.grass);
		world.setBlock(i + 7, j + 12, k + 38, Blocks.grass);
		world.setBlock(i + 7, j + 12, k + 39, Blocks.grass);
		world.setBlock(i + 7, j + 12, k + 40, Blocks.grass);
		world.setBlock(i + 7, j + 12, k + 41, Blocks.grass);
		world.setBlock(i + 7, j + 12, k + 42, Blocks.grass);
		world.setBlock(i + 7, j + 12, k + 43, Blocks.grass);
		world.setBlock(i + 7, j + 12, k + 44, Blocks.grass);
		world.setBlock(i + 7, j + 12, k + 45, Blocks.grass);
		world.setBlock(i + 7, j + 12, k + 46, Blocks.grass);
		world.setBlock(i + 7, j + 12, k + 47, Blocks.grass);
		world.setBlock(i + 7, j + 12, k + 48, Blocks.grass);
		world.setBlock(i + 7, j + 12, k + 49, Blocks.dirt);
		world.setBlock(i + 7, j + 12, k + 50, Blocks.dirt);
		world.setBlock(i + 7, j + 12, k + 51, Blocks.dirt);
		world.setBlock(i + 7, j + 12, k + 52, Blocks.grass);
		world.setBlock(i + 7, j + 12, k + 53, Blocks.dirt);
		world.setBlock(i + 7, j + 12, k + 54, Blocks.grass);
		world.setBlock(i + 7, j + 12, k + 55, Blocks.grass);
		world.setBlock(i + 7, j + 12, k + 56, Blocks.dirt);
		world.setBlock(i + 7, j + 12, k + 57, Blocks.grass);
		world.setBlock(i + 7, j + 12, k + 58, Blocks.grass);
		world.setBlock(i + 7, j + 12, k + 59, Blocks.grass);
		world.setBlock(i + 7, j + 12, k + 60, Blocks.grass);
		world.setBlock(i + 7, j + 12, k + 61, Blocks.grass);
		world.setBlock(i + 7, j + 12, k + 62, Blocks.grass);
		world.setBlock(i + 7, j + 12, k + 63, Blocks.grass);
		world.setBlock(i + 7, j + 12, k + 64, Blocks.grass);
		world.setBlock(i + 7, j + 12, k + 65, Blocks.grass);
		world.setBlock(i + 7, j + 12, k + 66, Blocks.grass);
		world.setBlock(i + 7, j + 12, k + 67, Blocks.grass);
		world.setBlock(i + 7, j + 12, k + 68, Blocks.grass);
		world.setBlock(i + 7, j + 12, k + 69, Blocks.grass);
		world.setBlock(i + 7, j + 12, k + 70, Blocks.grass);
		world.setBlock(i + 7, j + 12, k + 71, Blocks.grass);
		world.setBlock(i + 7, j + 12, k + 72, Blocks.grass);
		world.setBlock(i + 7, j + 12, k + 73, Blocks.grass);
		world.setBlock(i + 7, j + 12, k + 74, Blocks.grass);
		world.setBlock(i + 7, j + 12, k + 75, Blocks.grass);
		world.setBlock(i + 7, j + 12, k + 76, Blocks.grass);
		world.setBlock(i + 7, j + 13, k + 49, Blocks.grass);
		world.setBlock(i + 7, j + 13, k + 50, Blocks.grass);
		world.setBlock(i + 7, j + 13, k + 51, Blocks.grass);
		world.setBlock(i + 7, j + 13, k + 53, Blocks.grass);
		world.setBlock(i + 7, j + 13, k + 56, Blocks.grass);
		world.setBlock(i + 7, j + 21, k + 27, Blocks.wooden_slab, 9, 4);
		world.setBlock(i + 7, j + 22, k + 26, Blocks.spruce_stairs, 5, 4);
		world.setBlock(i + 7, j + 22, k + 27, Blocks.planks, 1, 4);
		world.setBlock(i + 7, j + 22, k + 28, Blocks.spruce_stairs, 5, 4);
		world.setBlock(i + 7, j + 23, k + 25, Blocks.spruce_stairs, 5, 4);
		world.setBlock(i + 7, j + 23, k + 26, Blocks.planks, 1, 4);
		world.setBlock(i + 7, j + 23, k + 27, Blocks.chest, 4, 4);
		world.setBlock(i + 7, j + 23, k + 28, Blocks.planks, 1, 4);
		world.setBlock(i + 7, j + 23, k + 31, Blocks.spruce_stairs, 2, 4);
		world.setBlock(i + 7, j + 23, k + 32, Blocks.planks, 1, 4);
		world.setBlock(i + 7, j + 23, k + 33, Blocks.spruce_stairs, 3, 4);
		world.setBlock(i + 7, j + 24, k + 25, Blocks.planks, 1, 4);
		world.setBlock(i + 7, j + 24, k + 26, Blocks.spruce_stairs);
		world.setBlock(i + 7, j + 24, k + 28, Blocks.spruce_stairs);
		world.setBlock(i + 7, j + 24, k + 29, Blocks.planks, 1, 4);
		world.setBlock(i + 7, j + 25, k + 25, Blocks.wooden_slab, 1, 4);
		world.setBlock(i + 7, j + 25, k + 29, Blocks.wooden_slab, 1, 4);
		world.setBlock(i + 7, j + 30, k + 26, Blocks.wool);
		world.setBlock(i + 7, j + 30, k + 27, Blocks.wool);
		world.setBlock(i + 7, j + 30, k + 28, Blocks.wool);
		world.setBlock(i + 7, j + 31, k + 25, Blocks.wool);
		world.setBlock(i + 7, j + 31, k + 26, Blocks.wool);
		world.setBlock(i + 7, j + 31, k + 27, Blocks.wool);
		world.setBlock(i + 7, j + 31, k + 28, Blocks.wool);
		world.setBlock(i + 7, j + 31, k + 29, Blocks.wool);
		world.setBlock(i + 7, j + 32, k + 25, Blocks.wool);
		world.setBlock(i + 7, j + 32, k + 26, Blocks.wool);
		world.setBlock(i + 7, j + 32, k + 27, Blocks.wool);
		world.setBlock(i + 7, j + 32, k + 28, Blocks.wool);
		world.setBlock(i + 7, j + 32, k + 29, Blocks.wool);
		world.setBlock(i + 7, j + 33, k + 25, Blocks.wool);
		world.setBlock(i + 7, j + 33, k + 26, Blocks.wool);
		world.setBlock(i + 7, j + 33, k + 27, Blocks.wool);
		world.setBlock(i + 7, j + 33, k + 28, Blocks.wool);
		world.setBlock(i + 7, j + 33, k + 29, Blocks.wool);
		world.setBlock(i + 7, j + 34, k + 26, Blocks.wool);
		world.setBlock(i + 7, j + 34, k + 27, Blocks.wool);
		world.setBlock(i + 7, j + 34, k + 28, Blocks.wool);
		world.setBlock(i + 8, j + 5, k + 37, Blocks.stone);
		world.setBlock(i + 8, j + 5, k + 38, Blocks.stone);
		world.setBlock(i + 8, j + 5, k + 39, Blocks.stone);
		world.setBlock(i + 8, j + 5, k + 40, Blocks.stone);
		world.setBlock(i + 8, j + 5, k + 41, Blocks.stone);
		world.setBlock(i + 8, j + 5, k + 42, Blocks.stone);
		world.setBlock(i + 8, j + 5, k + 43, Blocks.stone);
		world.setBlock(i + 8, j + 5, k + 44, Blocks.stone);
		world.setBlock(i + 8, j + 5, k + 45, Blocks.stone);
		world.setBlock(i + 8, j + 5, k + 46, Blocks.stone);
		world.setBlock(i + 8, j + 5, k + 47, Blocks.stone);
		world.setBlock(i + 8, j + 5, k + 48, Blocks.stone);
		world.setBlock(i + 8, j + 5, k + 49, Blocks.stone);
		world.setBlock(i + 8, j + 5, k + 50, Blocks.stone);
		world.setBlock(i + 8, j + 5, k + 51, Blocks.stone);
		world.setBlock(i + 8, j + 5, k + 52, Blocks.stone);
		world.setBlock(i + 8, j + 5, k + 53, Blocks.stone);
		world.setBlock(i + 8, j + 5, k + 54, Blocks.stone);
		world.setBlock(i + 8, j + 5, k + 55, Blocks.stone);
		world.setBlock(i + 8, j + 6, k + 29, Blocks.stone);
		world.setBlock(i + 8, j + 6, k + 30, Blocks.stone);
		world.setBlock(i + 8, j + 6, k + 31, Blocks.stone);
		world.setBlock(i + 8, j + 6, k + 32, Blocks.stone);
		world.setBlock(i + 8, j + 6, k + 33, Blocks.stone);
		world.setBlock(i + 8, j + 6, k + 34, Blocks.stone);
		world.setBlock(i + 8, j + 6, k + 35, Blocks.stone);
		world.setBlock(i + 8, j + 6, k + 36, Blocks.stone);
		world.setBlock(i + 8, j + 6, k + 37, Blocks.stone);
		world.setBlock(i + 8, j + 6, k + 38, Blocks.stone);
		world.setBlock(i + 8, j + 6, k + 39, Blocks.stone);
		world.setBlock(i + 8, j + 6, k + 40, Blocks.stone);
		world.setBlock(i + 8, j + 6, k + 41, Blocks.stone);
		world.setBlock(i + 8, j + 6, k + 42, Blocks.stone);
		world.setBlock(i + 8, j + 6, k + 43, Blocks.stone);
		world.setBlock(i + 8, j + 6, k + 44, Blocks.stone);
		world.setBlock(i + 8, j + 6, k + 45, Blocks.stone);
		world.setBlock(i + 8, j + 6, k + 46, Blocks.stone);
		world.setBlock(i + 8, j + 6, k + 47, Blocks.stone);
		world.setBlock(i + 8, j + 6, k + 48, Blocks.stone);
		world.setBlock(i + 8, j + 6, k + 49, Blocks.stone);
		world.setBlock(i + 8, j + 6, k + 50, Blocks.stone);
		world.setBlock(i + 8, j + 6, k + 51, Blocks.stone);
		world.setBlock(i + 8, j + 6, k + 52, Blocks.stone);
		world.setBlock(i + 8, j + 6, k + 53, Blocks.stone);
		world.setBlock(i + 8, j + 6, k + 54, Blocks.stone);
		world.setBlock(i + 8, j + 6, k + 55, Blocks.stone);
		world.setBlock(i + 8, j + 6, k + 56, Blocks.stone);
		world.setBlock(i + 8, j + 6, k + 57, Blocks.stone);
		world.setBlock(i + 8, j + 6, k + 58, Blocks.stone);
		world.setBlock(i + 8, j + 6, k + 59, Blocks.stone);
		world.setBlock(i + 8, j + 6, k + 60, Blocks.stone);
		world.setBlock(i + 8, j + 6, k + 61, Blocks.stone);
		world.setBlock(i + 8, j + 6, k + 62, Blocks.stone);
		world.setBlock(i + 8, j + 7, k + 24, Blocks.stone);
		world.setBlock(i + 8, j + 7, k + 25, Blocks.stone);
		world.setBlock(i + 8, j + 7, k + 26, Blocks.stone);
		world.setBlock(i + 8, j + 7, k + 27, Blocks.stone);
		world.setBlock(i + 8, j + 7, k + 28, Blocks.stone);
		world.setBlock(i + 8, j + 7, k + 29, Blocks.stone);
		world.setBlock(i + 8, j + 7, k + 30, Blocks.stone);
		world.setBlock(i + 8, j + 7, k + 31, Blocks.stone);
		world.setBlock(i + 8, j + 7, k + 32, Blocks.stone);
		world.setBlock(i + 8, j + 7, k + 33, Blocks.stone);

		generate2(world, rand, i, j, k);
		return true;
	}

	public boolean generate2(World world, Random rand, int i, int j, int k) {
		world.setBlock(i + 8, j + 7, k + 34, Blocks.stone);
		world.setBlock(i + 8, j + 7, k + 35, Blocks.stone);
		world.setBlock(i + 8, j + 7, k + 36, Blocks.stone);
		world.setBlock(i + 8, j + 7, k + 37, Blocks.stone);
		world.setBlock(i + 8, j + 7, k + 38, Blocks.stone);
		world.setBlock(i + 8, j + 7, k + 39, Blocks.stone);
		world.setBlock(i + 8, j + 7, k + 40, Blocks.stone);
		world.setBlock(i + 8, j + 7, k + 41, Blocks.stone);
		world.setBlock(i + 8, j + 7, k + 42, Blocks.stone);
		world.setBlock(i + 8, j + 7, k + 43, Blocks.stone);
		world.setBlock(i + 8, j + 7, k + 44, Blocks.stone);
		world.setBlock(i + 8, j + 7, k + 45, Blocks.stone);
		world.setBlock(i + 8, j + 7, k + 46, Blocks.stone);
		world.setBlock(i + 8, j + 7, k + 47, Blocks.stone);
		world.setBlock(i + 8, j + 7, k + 48, Blocks.stone);
		world.setBlock(i + 8, j + 7, k + 49, Blocks.stone);
		world.setBlock(i + 8, j + 7, k + 50, Blocks.stone);
		world.setBlock(i + 8, j + 7, k + 51, Blocks.stone);
		world.setBlock(i + 8, j + 7, k + 52, Blocks.stone);
		world.setBlock(i + 8, j + 7, k + 53, Blocks.stone);
		world.setBlock(i + 8, j + 7, k + 54, Blocks.stone);
		world.setBlock(i + 8, j + 7, k + 55, Blocks.stone);
		world.setBlock(i + 8, j + 7, k + 56, Blocks.stone);
		world.setBlock(i + 8, j + 7, k + 57, Blocks.stone);
		world.setBlock(i + 8, j + 7, k + 58, Blocks.stone);
		world.setBlock(i + 8, j + 7, k + 59, Blocks.stone);
		world.setBlock(i + 8, j + 7, k + 60, Blocks.stone);
		world.setBlock(i + 8, j + 7, k + 61, Blocks.stone);
		world.setBlock(i + 8, j + 7, k + 62, Blocks.stone);
		world.setBlock(i + 8, j + 7, k + 63, Blocks.stone);
		world.setBlock(i + 8, j + 7, k + 64, Blocks.stone);
		world.setBlock(i + 8, j + 7, k + 65, Blocks.stone);
		world.setBlock(i + 8, j + 8, k + 22, Wildycraft.denseStone);
		world.setBlock(i + 8, j + 8, k + 23, Wildycraft.denseStone);
		world.setBlock(i + 8, j + 8, k + 24, Wildycraft.denseStone);
		world.setBlock(i + 8, j + 8, k + 25, Wildycraft.denseStone);
		world.setBlock(i + 8, j + 8, k + 26, Wildycraft.denseStone);
		world.setBlock(i + 8, j + 8, k + 27, Wildycraft.denseStone);
		world.setBlock(i + 8, j + 8, k + 28, Wildycraft.denseStone);
		world.setBlock(i + 8, j + 8, k + 29, Wildycraft.denseStone);
		world.setBlock(i + 8, j + 8, k + 30, Wildycraft.denseStone);
		world.setBlock(i + 8, j + 8, k + 31, Wildycraft.denseStone);
		world.setBlock(i + 8, j + 8, k + 32, Wildycraft.denseStone);
		world.setBlock(i + 8, j + 8, k + 33, Wildycraft.denseStone);
		world.setBlock(i + 8, j + 8, k + 34, Wildycraft.denseStone);
		world.setBlock(i + 8, j + 8, k + 35, Wildycraft.denseStone);
		world.setBlock(i + 8, j + 8, k + 36, Wildycraft.denseStone);
		world.setBlock(i + 8, j + 8, k + 37, Wildycraft.denseStone);
		world.setBlock(i + 8, j + 8, k + 38, Wildycraft.denseStone);
		world.setBlock(i + 8, j + 8, k + 39, Wildycraft.denseStone);
		world.setBlock(i + 8, j + 8, k + 40, Wildycraft.denseStone);
		world.setBlock(i + 8, j + 8, k + 41, Wildycraft.denseStone);
		world.setBlock(i + 8, j + 8, k + 42, Wildycraft.denseStone);
		world.setBlock(i + 8, j + 8, k + 43, Wildycraft.denseStone);
		world.setBlock(i + 8, j + 8, k + 44, Wildycraft.denseStone);
		world.setBlock(i + 8, j + 8, k + 45, Wildycraft.denseStone);
		world.setBlock(i + 8, j + 8, k + 46, Wildycraft.denseStone);
		world.setBlock(i + 8, j + 8, k + 47, Wildycraft.denseStone);
		world.setBlock(i + 8, j + 8, k + 48, Wildycraft.denseStone);
		world.setBlock(i + 8, j + 8, k + 49, Wildycraft.denseStone);
		world.setBlock(i + 8, j + 8, k + 50, Wildycraft.denseStone);
		world.setBlock(i + 8, j + 8, k + 51, Wildycraft.denseStone);
		world.setBlock(i + 8, j + 8, k + 52, Wildycraft.denseStone);
		world.setBlock(i + 8, j + 8, k + 53, Wildycraft.denseStone);
		world.setBlock(i + 8, j + 8, k + 54, Wildycraft.denseStone);
		world.setBlock(i + 8, j + 8, k + 55, Wildycraft.denseStone);
		world.setBlock(i + 8, j + 8, k + 56, Wildycraft.denseStone);
		world.setBlock(i + 8, j + 8, k + 57, Wildycraft.denseStone);
		world.setBlock(i + 8, j + 8, k + 58, Wildycraft.denseStone);
		world.setBlock(i + 8, j + 8, k + 59, Wildycraft.denseStone);
		world.setBlock(i + 8, j + 8, k + 60, Wildycraft.denseStone);
		world.setBlock(i + 8, j + 8, k + 61, Wildycraft.denseStone);
		world.setBlock(i + 8, j + 8, k + 62, Wildycraft.denseStone);
		world.setBlock(i + 8, j + 8, k + 63, Wildycraft.denseStone);
		world.setBlock(i + 8, j + 8, k + 64, Wildycraft.denseStone);
		world.setBlock(i + 8, j + 8, k + 65, Wildycraft.denseStone);
		world.setBlock(i + 8, j + 8, k + 66, Wildycraft.denseStone);
		world.setBlock(i + 8, j + 8, k + 67, Wildycraft.denseStone);
		world.setBlock(i + 8, j + 8, k + 68, Wildycraft.denseStone);
		world.setBlock(i + 8, j + 8, k + 69, Wildycraft.denseStone);
		world.setBlock(i + 8, j + 8, k + 70, Wildycraft.denseStone);
		world.setBlock(i + 8, j + 9, k + 21, Wildycraft.denseStone);
		world.setBlock(i + 8, j + 9, k + 22, Wildycraft.denseStone);
		world.setBlock(i + 8, j + 9, k + 23, Wildycraft.denseStone);
		world.setBlock(i + 8, j + 9, k + 24, Wildycraft.denseStone);
		world.setBlock(i + 8, j + 9, k + 25, Wildycraft.denseStone);
		world.setBlock(i + 8, j + 9, k + 26, Wildycraft.denseStone);
		world.setBlock(i + 8, j + 9, k + 27, Wildycraft.denseStone);
		world.setBlock(i + 8, j + 9, k + 28, Wildycraft.denseStone);
		world.setBlock(i + 8, j + 9, k + 29, Wildycraft.denseStone);
		world.setBlock(i + 8, j + 9, k + 30, Wildycraft.denseStone);
		world.setBlock(i + 8, j + 9, k + 31, Wildycraft.denseStone);
		world.setBlock(i + 8, j + 9, k + 32, Wildycraft.denseStone);
		world.setBlock(i + 8, j + 9, k + 33, Wildycraft.denseStone);
		world.setBlock(i + 8, j + 9, k + 34, Wildycraft.denseStone);
		world.setBlock(i + 8, j + 9, k + 35, Wildycraft.denseStone);
		world.setBlock(i + 8, j + 9, k + 36, Wildycraft.denseStone);
		world.setBlock(i + 8, j + 9, k + 37, Wildycraft.denseStone);
		world.setBlock(i + 8, j + 9, k + 38, Wildycraft.denseStone);
		world.setBlock(i + 8, j + 9, k + 39, Wildycraft.denseStone);
		world.setBlock(i + 8, j + 9, k + 40, Wildycraft.denseStone);
		world.setBlock(i + 8, j + 9, k + 41, Wildycraft.denseStone);
		world.setBlock(i + 8, j + 9, k + 42, Wildycraft.denseStone);
		world.setBlock(i + 8, j + 9, k + 43, Wildycraft.denseStone);
		world.setBlock(i + 8, j + 9, k + 44, Wildycraft.denseStone);
		world.setBlock(i + 8, j + 9, k + 45, Wildycraft.denseStone);
		world.setBlock(i + 8, j + 9, k + 46, Wildycraft.denseStone);
		world.setBlock(i + 8, j + 9, k + 47, Wildycraft.denseStone);
		world.setBlock(i + 8, j + 9, k + 48, Wildycraft.denseStone);
		world.setBlock(i + 8, j + 9, k + 49, Wildycraft.denseStone);
		world.setBlock(i + 8, j + 9, k + 50, Wildycraft.denseStone);
		world.setBlock(i + 8, j + 9, k + 51, Wildycraft.denseStone);
		world.setBlock(i + 8, j + 9, k + 52, Wildycraft.denseStone);
		world.setBlock(i + 8, j + 9, k + 53, Wildycraft.denseStone);
		world.setBlock(i + 8, j + 9, k + 54, Wildycraft.denseStone);
		world.setBlock(i + 8, j + 9, k + 55, Wildycraft.denseStone);
		world.setBlock(i + 8, j + 9, k + 56, Wildycraft.denseStone);
		world.setBlock(i + 8, j + 9, k + 57, Wildycraft.denseStone);
		world.setBlock(i + 8, j + 9, k + 58, Wildycraft.denseStone);
		world.setBlock(i + 8, j + 9, k + 59, Wildycraft.denseStone);
		world.setBlock(i + 8, j + 9, k + 60, Wildycraft.denseStone);
		world.setBlock(i + 8, j + 9, k + 61, Wildycraft.denseStone);
		world.setBlock(i + 8, j + 9, k + 62, Wildycraft.denseStone);
		world.setBlock(i + 8, j + 9, k + 63, Wildycraft.denseStone);
		world.setBlock(i + 8, j + 9, k + 64, Wildycraft.denseStone);
		world.setBlock(i + 8, j + 9, k + 65, Wildycraft.denseStone);
		world.setBlock(i + 8, j + 9, k + 66, Wildycraft.denseStone);
		world.setBlock(i + 8, j + 9, k + 67, Wildycraft.denseStone);
		world.setBlock(i + 8, j + 9, k + 68, Wildycraft.denseStone);
		world.setBlock(i + 8, j + 9, k + 69, Wildycraft.denseStone);
		world.setBlock(i + 8, j + 9, k + 70, Wildycraft.denseStone);
		world.setBlock(i + 8, j + 9, k + 71, Wildycraft.denseStone);
		world.setBlock(i + 8, j + 10, k + 18, Wildycraft.denseStone);
		world.setBlock(i + 8, j + 10, k + 19, Wildycraft.denseStone);
		world.setBlock(i + 8, j + 10, k + 20, Wildycraft.denseStone);
		world.setBlock(i + 8, j + 10, k + 21, Wildycraft.denseStone);
		world.setBlock(i + 8, j + 10, k + 22, Wildycraft.denseStone);
		world.setBlock(i + 8, j + 10, k + 23, Wildycraft.denseStone);
		world.setBlock(i + 8, j + 10, k + 24, Wildycraft.denseStone);
		world.setBlock(i + 8, j + 10, k + 25, Wildycraft.denseStone);
		world.setBlock(i + 8, j + 10, k + 26, Wildycraft.denseStone);
		world.setBlock(i + 8, j + 10, k + 27, Wildycraft.denseStone);
		world.setBlock(i + 8, j + 10, k + 28, Wildycraft.denseStone);
		world.setBlock(i + 8, j + 10, k + 29, Wildycraft.denseStone);
		world.setBlock(i + 8, j + 10, k + 30, Wildycraft.denseStone);
		world.setBlock(i + 8, j + 10, k + 31, Wildycraft.denseStone);
		world.setBlock(i + 8, j + 10, k + 32, Wildycraft.denseStone);
		world.setBlock(i + 8, j + 10, k + 33, Wildycraft.denseStone);
		world.setBlock(i + 8, j + 10, k + 34, Wildycraft.denseStone);
		world.setBlock(i + 8, j + 10, k + 35, Wildycraft.denseStone);
		world.setBlock(i + 8, j + 10, k + 36, Wildycraft.denseStone);
		world.setBlock(i + 8, j + 10, k + 37, Wildycraft.denseStone);
		world.setBlock(i + 8, j + 10, k + 38, Wildycraft.denseStone);
		world.setBlock(i + 8, j + 10, k + 39, Wildycraft.denseStone);
		world.setBlock(i + 8, j + 10, k + 40, Wildycraft.denseStone);
		world.setBlock(i + 8, j + 10, k + 41, Wildycraft.denseStone);
		world.setBlock(i + 8, j + 10, k + 42, Wildycraft.denseStone);
		world.setBlock(i + 8, j + 10, k + 43, Wildycraft.denseStone);
		world.setBlock(i + 8, j + 10, k + 44, Wildycraft.denseStone);
		world.setBlock(i + 8, j + 10, k + 45, Wildycraft.denseStone);
		world.setBlock(i + 8, j + 10, k + 46, Wildycraft.denseStone);
		world.setBlock(i + 8, j + 10, k + 47, Wildycraft.denseStone);
		world.setBlock(i + 8, j + 10, k + 48, Wildycraft.denseStone);
		world.setBlock(i + 8, j + 10, k + 49, Wildycraft.denseStone);
		world.setBlock(i + 8, j + 10, k + 50, Wildycraft.denseStone);
		world.setBlock(i + 8, j + 10, k + 51, Wildycraft.denseStone);
		world.setBlock(i + 8, j + 10, k + 52, Wildycraft.denseStone);
		world.setBlock(i + 8, j + 10, k + 53, Wildycraft.denseStone);
		world.setBlock(i + 8, j + 10, k + 54, Wildycraft.denseStone);
		world.setBlock(i + 8, j + 10, k + 55, Wildycraft.denseStone);
		world.setBlock(i + 8, j + 10, k + 56, Wildycraft.denseStone);
		world.setBlock(i + 8, j + 10, k + 57, Wildycraft.denseStone);
		world.setBlock(i + 8, j + 10, k + 58, Wildycraft.denseStone);
		world.setBlock(i + 8, j + 10, k + 59, Wildycraft.denseStone);
		world.setBlock(i + 8, j + 10, k + 60, Wildycraft.denseStone);
		world.setBlock(i + 8, j + 10, k + 61, Wildycraft.denseStone);
		world.setBlock(i + 8, j + 10, k + 62, Wildycraft.denseStone);
		world.setBlock(i + 8, j + 10, k + 63, Wildycraft.denseStone);
		world.setBlock(i + 8, j + 10, k + 64, Wildycraft.denseStone);
		world.setBlock(i + 8, j + 10, k + 65, Wildycraft.denseStone);
		world.setBlock(i + 8, j + 10, k + 66, Wildycraft.denseStone);
		world.setBlock(i + 8, j + 10, k + 67, Wildycraft.denseStone);
		world.setBlock(i + 8, j + 10, k + 68, Wildycraft.denseStone);
		world.setBlock(i + 8, j + 10, k + 69, Wildycraft.denseStone);
		world.setBlock(i + 8, j + 10, k + 70, Wildycraft.denseStone);
		world.setBlock(i + 8, j + 10, k + 71, Wildycraft.denseStone);
		world.setBlock(i + 8, j + 10, k + 72, Wildycraft.denseStone);
		world.setBlock(i + 8, j + 10, k + 73, Wildycraft.denseStone);
		world.setBlock(i + 8, j + 10, k + 74, Wildycraft.denseStone);
		world.setBlock(i + 8, j + 10, k + 75, Wildycraft.denseStone);
		world.setBlock(i + 8, j + 10, k + 76, Wildycraft.denseStone);
		world.setBlock(i + 8, j + 11, k + 16, Blocks.dirt);
		world.setBlock(i + 8, j + 11, k + 17, Blocks.dirt);
		world.setBlock(i + 8, j + 11, k + 18, Blocks.dirt);
		world.setBlock(i + 8, j + 11, k + 19, Blocks.dirt);
		world.setBlock(i + 8, j + 11, k + 20, Blocks.dirt);
		world.setBlock(i + 8, j + 11, k + 21, Blocks.dirt);
		world.setBlock(i + 8, j + 11, k + 22, Blocks.dirt);
		world.setBlock(i + 8, j + 11, k + 23, Blocks.dirt);
		world.setBlock(i + 8, j + 11, k + 24, Blocks.dirt);
