/*
*** MADE BY MITHION'S .SCHEMATIC TO JAVA CONVERTING TOOL v1.6 ***
*/

package wildycraft.structures;
import java.util.Random;

import wildycraft.Wildycraft;

import net.minecraft.init.Blocks;
import net.minecraft.init.Items;
import net.minecraft.item.ItemStack;
import net.minecraft.nbt.NBTTagCompound;
import net.minecraft.tileentity.TileEntityChest;
import net.minecraft.tileentity.TileEntityMobSpawner;
import net.minecraft.util.WeightedRandomChestContent;
import net.minecraft.world.World;
import net.minecraft.world.gen.feature.WorldGenerator;
import net.minecraftforge.common.ChestGenHooks;

public class Pyramid extends WorldGenerator
{
	
	public boolean generate(World world, Random rand, int i, int j, int k) {
		world.setBlock(i + 0, j + 0, k + 0, Wildycraft.rsSand);
		world.setBlock(i + 0, j + 0, k + 1, Wildycraft.rsSand);
		world.setBlock(i + 0, j + 0, k + 2, Wildycraft.rsSand);
		world.setBlock(i + 0, j + 0, k + 3, Wildycraft.rsSand);
		world.setBlock(i + 0, j + 0, k + 4, Wildycraft.rsSand);
		world.setBlock(i + 0, j + 0, k + 5, Wildycraft.rsSand);
		world.setBlock(i + 0, j + 0, k + 6, Wildycraft.rsSand);
		world.setBlock(i + 0, j + 0, k + 7, Wildycraft.rsSand);
		world.setBlock(i + 0, j + 0, k + 8, Wildycraft.rsSand);
		world.setBlock(i + 0, j + 0, k + 9, Wildycraft.rsSand);
		world.setBlock(i + 0, j + 0, k + 10, Wildycraft.rsSand);
		world.setBlock(i + 0, j + 0, k + 11, Wildycraft.rsSand);
		world.setBlock(i + 0, j + 0, k + 12, Wildycraft.rsSand);
		world.setBlock(i + 0, j + 0, k + 13, Wildycraft.rsSand);
		world.setBlock(i + 0, j + 0, k + 14, Wildycraft.rsSand);
		world.setBlock(i + 0, j + 0, k + 15, Wildycraft.rsSand);
		world.setBlock(i + 0, j + 0, k + 16, Wildycraft.rsSand);
		world.setBlock(i + 0, j + 0, k + 17, Wildycraft.rsSand);
		world.setBlock(i + 0, j + 0, k + 18, Wildycraft.rsSand);
		world.setBlock(i + 0, j + 0, k + 19, Wildycraft.rsSand);
		world.setBlock(i + 0, j + 0, k + 20, Wildycraft.rsSand);
		world.setBlock(i + 0, j + 0, k + 21, Wildycraft.rsSand);
		world.setBlock(i + 0, j + 0, k + 22, Wildycraft.rsSand);
		world.setBlock(i + 0, j + 0, k + 23, Wildycraft.rsSand);
		world.setBlock(i + 0, j + 0, k + 24, Wildycraft.rsSand);
		world.setBlock(i + 0, j + 0, k + 25, Wildycraft.rsSand);
		world.setBlock(i + 0, j + 0, k + 26, Wildycraft.rsSand);
		world.setBlock(i + 0, j + 0, k + 27, Wildycraft.rsSand);
		world.setBlock(i + 0, j + 0, k + 28, Wildycraft.rsSand);
		world.setBlock(i + 0, j + 0, k + 29, Wildycraft.rsSand);
		world.setBlock(i + 0, j + 0, k + 30, Wildycraft.rsSand);
		world.setBlock(i + 0, j + 0, k + 31, Wildycraft.rsSand);
		world.setBlock(i + 0, j + 0, k + 32, Wildycraft.rsSand);
		world.setBlock(i + 0, j + 0, k + 33, Wildycraft.rsSand);
		world.setBlock(i + 0, j + 0, k + 34, Wildycraft.rsSand);
		world.setBlock(i + 0, j + 0, k + 35, Wildycraft.rsSand);
		world.setBlock(i + 0, j + 0, k + 36, Wildycraft.rsSand);
		world.setBlock(i + 0, j + 0, k + 37, Wildycraft.rsSand);
		world.setBlock(i + 0, j + 0, k + 38, Wildycraft.rsSand);
		world.setBlock(i + 0, j + 0, k + 39, Wildycraft.rsSand);
		world.setBlock(i + 0, j + 0, k + 40, Wildycraft.rsSand);
		world.setBlock(i + 0, j + 0, k + 41, Wildycraft.rsSand);
		world.setBlock(i + 0, j + 0, k + 42, Wildycraft.rsSand);
		world.setBlock(i + 0, j + 0, k + 43, Wildycraft.rsSand);
		world.setBlock(i + 0, j + 0, k + 44, Wildycraft.rsSand);
		world.setBlock(i + 0, j + 0, k + 45, Wildycraft.rsSand);
		world.setBlock(i + 0, j + 0, k + 46, Wildycraft.rsSand);
		world.setBlock(i + 0, j + 0, k + 47, Wildycraft.rsSand);
		world.setBlock(i + 0, j + 0, k + 48, Wildycraft.rsSand);
		world.setBlock(i + 0, j + 0, k + 49, Wildycraft.rsSand);
		world.setBlock(i + 0, j + 0, k + 50, Wildycraft.rsSand);
		world.setBlock(i + 0, j + 0, k + 51, Wildycraft.rsSand);
		world.setBlock(i + 0, j + 0, k + 52, Wildycraft.rsSand);
		world.setBlock(i + 0, j + 0, k + 53, Wildycraft.rsSand);
		world.setBlock(i + 0, j + 0, k + 54, Wildycraft.rsSand);
		world.setBlock(i + 0, j + 0, k + 55, Wildycraft.rsSand);
		world.setBlock(i + 0, j + 0, k + 56, Wildycraft.rsSand);
		world.setBlock(i + 0, j + 0, k + 57, Wildycraft.rsSand);
		world.setBlock(i + 0, j + 0, k + 58, Wildycraft.rsSand);
		world.setBlock(i + 0, j + 0, k + 59, Wildycraft.rsSand);
		world.setBlock(i + 0, j + 1, k + 0, Blocks.sandstone_stairs, 2, 4);
		world.setBlock(i + 0, j + 1, k + 1, Blocks.sandstone_stairs);
		world.setBlock(i + 0, j + 1, k + 2, Blocks.sandstone_stairs);
		world.setBlock(i + 0, j + 1, k + 3, Blocks.sandstone_stairs);
		world.setBlock(i + 0, j + 1, k + 4, Blocks.sandstone, 2, 4);
		world.setBlock(i + 0, j + 1, k + 5, Blocks.sandstone, 2, 4);
		world.setBlock(i + 0, j + 1, k + 6, Blocks.sandstone, 2, 4);
		world.setBlock(i + 0, j + 1, k + 53, Blocks.sandstone, 2, 4);
		world.setBlock(i + 0, j + 1, k + 54, Blocks.sandstone, 2, 4);
		world.setBlock(i + 0, j + 1, k + 55, Blocks.sandstone, 2, 4);
		world.setBlock(i + 0, j + 1, k + 56, Blocks.sandstone_stairs);
		world.setBlock(i + 0, j + 1, k + 57, Blocks.sandstone_stairs);
		world.setBlock(i + 0, j + 1, k + 58, Blocks.sandstone_stairs);
		world.setBlock(i + 0, j + 1, k + 59, Blocks.sandstone_stairs, 3, 4);
		world.setBlock(i + 1, j + 0, k + 0, Wildycraft.rsSand);
		world.setBlock(i + 1, j + 0, k + 1, Wildycraft.rsSand);
		world.setBlock(i + 1, j + 0, k + 2, Wildycraft.rsSand);
		world.setBlock(i + 1, j + 0, k + 3, Wildycraft.rsSand);
		world.setBlock(i + 1, j + 0, k + 4, Wildycraft.rsSand);
		world.setBlock(i + 1, j + 0, k + 5, Wildycraft.rsSand);
		world.setBlock(i + 1, j + 0, k + 6, Wildycraft.rsSand);
		world.setBlock(i + 1, j + 0, k + 7, Wildycraft.rsSand);
		world.setBlock(i + 1, j + 0, k + 8, Wildycraft.rsSand);
		world.setBlock(i + 1, j + 0, k + 9, Wildycraft.rsSand);
		world.setBlock(i + 1, j + 0, k + 10, Wildycraft.rsSand);
		world.setBlock(i + 1, j + 0, k + 11, Wildycraft.rsSand);
		world.setBlock(i + 1, j + 0, k + 12, Wildycraft.rsSand);
		world.setBlock(i + 1, j + 0, k + 13, Wildycraft.rsSand);
		world.setBlock(i + 1, j + 0, k + 14, Wildycraft.rsSand);
		world.setBlock(i + 1, j + 0, k + 15, Wildycraft.rsSand);
		world.setBlock(i + 1, j + 0, k + 16, Wildycraft.rsSand);
		world.setBlock(i + 1, j + 0, k + 17, Wildycraft.rsSand);
		world.setBlock(i + 1, j + 0, k + 18, Wildycraft.rsSand);
		world.setBlock(i + 1, j + 0, k + 19, Wildycraft.rsSand);
		world.setBlock(i + 1, j + 0, k + 20, Wildycraft.rsSand);
		world.setBlock(i + 1, j + 0, k + 21, Wildycraft.rsSand);
		world.setBlock(i + 1, j + 0, k + 22, Wildycraft.rsSand);
		world.setBlock(i + 1, j + 0, k + 23, Wildycraft.rsSand);
		world.setBlock(i + 1, j + 0, k + 24, Wildycraft.rsSand);
		world.setBlock(i + 1, j + 0, k + 25, Wildycraft.rsSand);
		world.setBlock(i + 1, j + 0, k + 26, Wildycraft.rsSand);
		world.setBlock(i + 1, j + 0, k + 27, Wildycraft.rsSand);
		world.setBlock(i + 1, j + 0, k + 28, Wildycraft.rsSand);
		world.setBlock(i + 1, j + 0, k + 29, Wildycraft.rsSand);
		world.setBlock(i + 1, j + 0, k + 30, Wildycraft.rsSand);
		world.setBlock(i + 1, j + 0, k + 31, Wildycraft.rsSand);
		world.setBlock(i + 1, j + 0, k + 32, Wildycraft.rsSand);
		world.setBlock(i + 1, j + 0, k + 33, Wildycraft.rsSand);
		world.setBlock(i + 1, j + 0, k + 34, Wildycraft.rsSand);
		world.setBlock(i + 1, j + 0, k + 35, Wildycraft.rsSand);
		world.setBlock(i + 1, j + 0, k + 36, Wildycraft.rsSand);
		world.setBlock(i + 1, j + 0, k + 37, Wildycraft.rsSand);
		world.setBlock(i + 1, j + 0, k + 38, Wildycraft.rsSand);
		world.setBlock(i + 1, j + 0, k + 39, Wildycraft.rsSand);
		world.setBlock(i + 1, j + 0, k + 40, Wildycraft.rsSand);
		world.setBlock(i + 1, j + 0, k + 41, Wildycraft.rsSand);
		world.setBlock(i + 1, j + 0, k + 42, Wildycraft.rsSand);
		world.setBlock(i + 1, j + 0, k + 43, Wildycraft.rsSand);
		world.setBlock(i + 1, j + 0, k + 44, Wildycraft.rsSand);
		world.setBlock(i + 1, j + 0, k + 45, Wildycraft.rsSand);
		world.setBlock(i + 1, j + 0, k + 46, Wildycraft.rsSand);
		world.setBlock(i + 1, j + 0, k + 47, Wildycraft.rsSand);
		world.setBlock(i + 1, j + 0, k + 48, Wildycraft.rsSand);
		world.setBlock(i + 1, j + 0, k + 49, Wildycraft.rsSand);
		world.setBlock(i + 1, j + 0, k + 50, Wildycraft.rsSand);
		world.setBlock(i + 1, j + 0, k + 51, Wildycraft.rsSand);
		world.setBlock(i + 1, j + 0, k + 52, Wildycraft.rsSand);
		world.setBlock(i + 1, j + 0, k + 53, Wildycraft.rsSand);
		world.setBlock(i + 1, j + 0, k + 54, Wildycraft.rsSand);
		world.setBlock(i + 1, j + 0, k + 55, Wildycraft.rsSand);
		world.setBlock(i + 1, j + 0, k + 56, Wildycraft.rsSand);
		world.setBlock(i + 1, j + 0, k + 57, Wildycraft.rsSand);
		world.setBlock(i + 1, j + 0, k + 58, Wildycraft.rsSand);
		world.setBlock(i + 1, j + 0, k + 59, Wildycraft.rsSand);
		world.setBlock(i + 1, j + 1, k + 0, Blocks.sandstone_stairs, 2, 4);
		world.setBlock(i + 1, j + 1, k + 1, Blocks.sandstone, 2, 4);
		world.setBlock(i + 1, j + 1, k + 2, Blocks.sandstone, 2, 4);
		world.setBlock(i + 1, j + 1, k + 3, Blocks.sandstone, 2, 4);
		world.setBlock(i + 1, j + 1, k + 4, Blocks.sandstone, 2, 4);
		world.setBlock(i + 1, j + 1, k + 5, Blocks.sandstone, 2, 4);
		world.setBlock(i + 1, j + 1, k + 6, Blocks.sandstone, 2, 4);
		world.setBlock(i + 1, j + 1, k + 29, Blocks.sandstone_stairs);
		world.setBlock(i + 1, j + 1, k + 30, Blocks.sandstone_stairs);
		world.setBlock(i + 1, j + 1, k + 53, Blocks.sandstone, 2, 4);
		world.setBlock(i + 1, j + 1, k + 54, Blocks.sandstone, 2, 4);
		world.setBlock(i + 1, j + 1, k + 55, Blocks.sandstone, 2, 4);
		world.setBlock(i + 1, j + 1, k + 56, Blocks.sandstone, 2, 4);
		world.setBlock(i + 1, j + 1, k + 57, Blocks.sandstone, 2, 4);
		world.setBlock(i + 1, j + 1, k + 58, Blocks.sandstone, 2, 4);
		world.setBlock(i + 1, j + 1, k + 59, Blocks.sandstone_stairs, 3, 4);
		world.setBlock(i + 2, j + 0, k + 0, Wildycraft.rsSand);
		world.setBlock(i + 2, j + 0, k + 1, Wildycraft.rsSand);
		world.setBlock(i + 2, j + 0, k + 2, Wildycraft.rsSand);
		world.setBlock(i + 2, j + 0, k + 3, Wildycraft.rsSand);
		world.setBlock(i + 2, j + 0, k + 4, Wildycraft.rsSand);
		world.setBlock(i + 2, j + 0, k + 5, Wildycraft.rsSand);
		world.setBlock(i + 2, j + 0, k + 6, Wildycraft.rsSand);
		world.setBlock(i + 2, j + 0, k + 7, Wildycraft.rsSand);
		world.setBlock(i + 2, j + 0, k + 8, Wildycraft.rsSand);
		world.setBlock(i + 2, j + 0, k + 9, Wildycraft.rsSand);
		world.setBlock(i + 2, j + 0, k + 10, Wildycraft.rsSand);
		world.setBlock(i + 2, j + 0, k + 11, Wildycraft.rsSand);
		world.setBlock(i + 2, j + 0, k + 12, Wildycraft.rsSand);
		world.setBlock(i + 2, j + 0, k + 13, Wildycraft.rsSand);
		world.setBlock(i + 2, j + 0, k + 14, Wildycraft.rsSand);
		world.setBlock(i + 2, j + 0, k + 15, Wildycraft.rsSand);
		world.setBlock(i + 2, j + 0, k + 16, Wildycraft.rsSand);
		world.setBlock(i + 2, j + 0, k + 17, Wildycraft.rsSand);
		world.setBlock(i + 2, j + 0, k + 18, Wildycraft.rsSand);
		world.setBlock(i + 2, j + 0, k + 19, Wildycraft.rsSand);
		world.setBlock(i + 2, j + 0, k + 20, Wildycraft.rsSand);
		world.setBlock(i + 2, j + 0, k + 21, Wildycraft.rsSand);
		world.setBlock(i + 2, j + 0, k + 22, Wildycraft.rsSand);
		world.setBlock(i + 2, j + 0, k + 23, Wildycraft.rsSand);
		world.setBlock(i + 2, j + 0, k + 24, Wildycraft.rsSand);
		world.setBlock(i + 2, j + 0, k + 25, Wildycraft.rsSand);
		world.setBlock(i + 2, j + 0, k + 26, Wildycraft.rsSand);
		world.setBlock(i + 2, j + 0, k + 27, Wildycraft.rsSand);
		world.setBlock(i + 2, j + 0, k + 28, Wildycraft.rsSand);
		world.setBlock(i + 2, j + 0, k + 29, Wildycraft.rsSand);
		world.setBlock(i + 2, j + 0, k + 30, Wildycraft.rsSand);
		world.setBlock(i + 2, j + 0, k + 31, Wildycraft.rsSand);
		world.setBlock(i + 2, j + 0, k + 32, Wildycraft.rsSand);
		world.setBlock(i + 2, j + 0, k + 33, Wildycraft.rsSand);
		world.setBlock(i + 2, j + 0, k + 34, Wildycraft.rsSand);
		world.setBlock(i + 2, j + 0, k + 35, Wildycraft.rsSand);
		world.setBlock(i + 2, j + 0, k + 36, Wildycraft.rsSand);
		world.setBlock(i + 2, j + 0, k + 37, Wildycraft.rsSand);
		world.setBlock(i + 2, j + 0, k + 38, Wildycraft.rsSand);
		world.setBlock(i + 2, j + 0, k + 39, Wildycraft.rsSand);
		world.setBlock(i + 2, j + 0, k + 40, Wildycraft.rsSand);
		world.setBlock(i + 2, j + 0, k + 41, Wildycraft.rsSand);
		world.setBlock(i + 2, j + 0, k + 42, Wildycraft.rsSand);
		world.setBlock(i + 2, j + 0, k + 43, Wildycraft.rsSand);
		world.setBlock(i + 2, j + 0, k + 44, Wildycraft.rsSand);
		world.setBlock(i + 2, j + 0, k + 45, Wildycraft.rsSand);
		world.setBlock(i + 2, j + 0, k + 46, Wildycraft.rsSand);
		world.setBlock(i + 2, j + 0, k + 47, Wildycraft.rsSand);
		world.setBlock(i + 2, j + 0, k + 48, Wildycraft.rsSand);
		world.setBlock(i + 2, j + 0, k + 49, Wildycraft.rsSand);
		world.setBlock(i + 2, j + 0, k + 50, Wildycraft.rsSand);
		world.setBlock(i + 2, j + 0, k + 51, Wildycraft.rsSand);
		world.setBlock(i + 2, j + 0, k + 52, Wildycraft.rsSand);
		world.setBlock(i + 2, j + 0, k + 53, Wildycraft.rsSand);
		world.setBlock(i + 2, j + 0, k + 54, Wildycraft.rsSand);
		world.setBlock(i + 2, j + 0, k + 55, Wildycraft.rsSand);
		world.setBlock(i + 2, j + 0, k + 56, Wildycraft.rsSand);
		world.setBlock(i + 2, j + 0, k + 57, Wildycraft.rsSand);
		world.setBlock(i + 2, j + 0, k + 58, Wildycraft.rsSand);
		world.setBlock(i + 2, j + 0, k + 59, Wildycraft.rsSand);
		world.setBlock(i + 2, j + 1, k + 0, Blocks.sandstone_stairs, 2, 4);
		world.setBlock(i + 2, j + 1, k + 1, Blocks.sandstone, 2, 4);
		world.setBlock(i + 2, j + 1, k + 2, Blocks.sandstone, 2, 4);
		world.setBlock(i + 2, j + 1, k + 3, Blocks.sandstone, 2, 4);
		world.setBlock(i + 2, j + 1, k + 4, Blocks.sandstone, 2, 4);
		world.setBlock(i + 2, j + 1, k + 5, Blocks.sandstone, 2, 4);
		world.setBlock(i + 2, j + 1, k + 6, Blocks.sandstone, 2, 4);
		world.setBlock(i + 2, j + 1, k + 28, Blocks.sandstone, 2, 4);
		world.setBlock(i + 2, j + 1, k + 29, Blocks.sandstone);
		world.setBlock(i + 2, j + 1, k + 30, Blocks.sandstone);
		world.setBlock(i + 2, j + 1, k + 31, Blocks.sandstone, 2, 4);
		world.setBlock(i + 2, j + 1, k + 53, Blocks.sandstone, 2, 4);
		world.setBlock(i + 2, j + 1, k + 54, Blocks.sandstone, 2, 4);
		world.setBlock(i + 2, j + 1, k + 55, Blocks.sandstone, 2, 4);
		world.setBlock(i + 2, j + 1, k + 56, Blocks.sandstone, 2, 4);
		world.setBlock(i + 2, j + 1, k + 57, Blocks.sandstone, 2, 4);
		world.setBlock(i + 2, j + 1, k + 58, Blocks.sandstone, 2, 4);
		world.setBlock(i + 2, j + 1, k + 59, Blocks.sandstone_stairs, 3, 4);
		world.setBlock(i + 2, j + 2, k + 2, Blocks.sandstone, 2, 4);
		world.setBlock(i + 2, j + 2, k + 3, Blocks.sandstone, 2, 4);
		world.setBlock(i + 2, j + 2, k + 4, Blocks.sandstone, 2, 4);
		world.setBlock(i + 2, j + 2, k + 29, Blocks.sandstone_stairs);
		world.setBlock(i + 2, j + 2, k + 30, Blocks.sandstone_stairs);
		world.setBlock(i + 2, j + 2, k + 55, Blocks.sandstone, 2, 4);
		world.setBlock(i + 2, j + 2, k + 56, Blocks.sandstone, 2, 4);
		world.setBlock(i + 2, j + 2, k + 57, Blocks.sandstone, 2, 4);
		world.setBlock(i + 2, j + 3, k + 2, Blocks.sandstone, 2, 4);
		world.setBlock(i + 2, j + 3, k + 3, Blocks.sandstone, 2, 4);
		world.setBlock(i + 2, j + 3, k + 4, Blocks.sandstone, 2, 4);
		world.setBlock(i + 2, j + 3, k + 55, Blocks.sandstone, 2, 4);
		world.setBlock(i + 2, j + 3, k + 56, Blocks.sandstone, 2, 4);
		world.setBlock(i + 2, j + 3, k + 57, Blocks.sandstone, 2, 4);
		world.setBlock(i + 2, j + 4, k + 2, Blocks.sandstone, 2, 4);
		world.setBlock(i + 2, j + 4, k + 3, Blocks.stained_glass);
		world.setBlock(i + 2, j + 4, k + 4, Blocks.sandstone, 2, 4);
		world.setBlock(i + 2, j + 4, k + 55, Blocks.sandstone, 2, 4);
		world.setBlock(i + 2, j + 4, k + 56, Blocks.stained_glass, 14, 4);
		world.setBlock(i + 2, j + 4, k + 57, Blocks.sandstone, 2, 4);
		world.setBlock(i + 2, j + 5, k + 2, Blocks.sandstone, 2, 4);
		world.setBlock(i + 2, j + 5, k + 3, Blocks.sandstone, 2, 4);
		world.setBlock(i + 2, j + 5, k + 4, Blocks.sandstone, 2, 4);
		world.setBlock(i + 2, j + 5, k + 55, Blocks.sandstone, 2, 4);
		world.setBlock(i + 2, j + 5, k + 56, Blocks.sandstone, 2, 4);
		world.setBlock(i + 2, j + 5, k + 57, Blocks.sandstone, 2, 4);
		world.setBlock(i + 2, j + 6, k + 2, Blocks.sandstone, 2, 4);
		world.setBlock(i + 2, j + 6, k + 3, Blocks.sandstone, 2, 4);
		world.setBlock(i + 2, j + 6, k + 4, Blocks.sandstone, 2, 4);
		world.setBlock(i + 2, j + 6, k + 55, Blocks.sandstone, 2, 4);
		world.setBlock(i + 2, j + 6, k + 56, Blocks.sandstone, 2, 4);
		world.setBlock(i + 2, j + 6, k + 57, Blocks.sandstone, 2, 4);
		world.setBlock(i + 2, j + 7, k + 2, Blocks.sandstone, 2, 4);
		world.setBlock(i + 2, j + 7, k + 3, Blocks.sandstone, 2, 4);
		world.setBlock(i + 2, j + 7, k + 4, Blocks.sandstone, 2, 4);
		world.setBlock(i + 2, j + 7, k + 55, Blocks.sandstone, 2, 4);
		world.setBlock(i + 2, j + 7, k + 56, Blocks.sandstone, 2, 4);
		world.setBlock(i + 2, j + 7, k + 57, Blocks.sandstone, 2, 4);
		world.setBlock(i + 2, j + 8, k + 3, Blocks.sandstone_stairs);
		world.setBlock(i + 2, j + 8, k + 56, Blocks.sandstone_stairs);
		world.setBlock(i + 3, j + 0, k + 0, Wildycraft.rsSand);
		world.setBlock(i + 3, j + 0, k + 1, Wildycraft.rsSand);
		world.setBlock(i + 3, j + 0, k + 2, Wildycraft.rsSand);
		world.setBlock(i + 3, j + 0, k + 3, Wildycraft.rsSand);
		world.setBlock(i + 3, j + 0, k + 4, Wildycraft.rsSand);
		world.setBlock(i + 3, j + 0, k + 5, Wildycraft.rsSand);
		world.setBlock(i + 3, j + 0, k + 6, Wildycraft.rsSand);
		world.setBlock(i + 3, j + 0, k + 7, Wildycraft.rsSand);
		world.setBlock(i + 3, j + 0, k + 8, Wildycraft.rsSand);
		world.setBlock(i + 3, j + 0, k + 9, Wildycraft.rsSand);
		world.setBlock(i + 3, j + 0, k + 10, Wildycraft.rsSand);
		world.setBlock(i + 3, j + 0, k + 11, Wildycraft.rsSand);
		world.setBlock(i + 3, j + 0, k + 12, Wildycraft.rsSand);
		world.setBlock(i + 3, j + 0, k + 13, Wildycraft.rsSand);
		world.setBlock(i + 3, j + 0, k + 14, Wildycraft.rsSand);
		world.setBlock(i + 3, j + 0, k + 15, Wildycraft.rsSand);
		world.setBlock(i + 3, j + 0, k + 16, Wildycraft.rsSand);
		world.setBlock(i + 3, j + 0, k + 17, Wildycraft.rsSand);
		world.setBlock(i + 3, j + 0, k + 18, Wildycraft.rsSand);
		world.setBlock(i + 3, j + 0, k + 19, Wildycraft.rsSand);
		world.setBlock(i + 3, j + 0, k + 20, Wildycraft.rsSand);
		world.setBlock(i + 3, j + 0, k + 21, Wildycraft.rsSand);
		world.setBlock(i + 3, j + 0, k + 22, Wildycraft.rsSand);
		world.setBlock(i + 3, j + 0, k + 23, Wildycraft.rsSand);
		world.setBlock(i + 3, j + 0, k + 24, Wildycraft.rsSand);
		world.setBlock(i + 3, j + 0, k + 25, Wildycraft.rsSand);
		world.setBlock(i + 3, j + 0, k + 26, Wildycraft.rsSand);
		world.setBlock(i + 3, j + 0, k + 27, Wildycraft.rsSand);
		world.setBlock(i + 3, j + 0, k + 28, Blocks.netherrack);
		world.setBlock(i + 3, j + 0, k + 29, Wildycraft.rsSand);
		world.setBlock(i + 3, j + 0, k + 30, Wildycraft.rsSand);
		world.setBlock(i + 3, j + 0, k + 31, Blocks.netherrack);
		world.setBlock(i + 3, j + 0, k + 32, Wildycraft.rsSand);
		world.setBlock(i + 3, j + 0, k + 33, Wildycraft.rsSand);
		world.setBlock(i + 3, j + 0, k + 34, Wildycraft.rsSand);
		world.setBlock(i + 3, j + 0, k + 35, Wildycraft.rsSand);
		world.setBlock(i + 3, j + 0, k + 36, Wildycraft.rsSand);
		world.setBlock(i + 3, j + 0, k + 37, Wildycraft.rsSand);
		world.setBlock(i + 3, j + 0, k + 38, Wildycraft.rsSand);
		world.setBlock(i + 3, j + 0, k + 39, Wildycraft.rsSand);
		world.setBlock(i + 3, j + 0, k + 40, Wildycraft.rsSand);
		world.setBlock(i + 3, j + 0, k + 41, Wildycraft.rsSand);
		world.setBlock(i + 3, j + 0, k + 42, Wildycraft.rsSand);
		world.setBlock(i + 3, j + 0, k + 43, Wildycraft.rsSand);
		world.setBlock(i + 3, j + 0, k + 44, Wildycraft.rsSand);
		world.setBlock(i + 3, j + 0, k + 45, Wildycraft.rsSand);
		world.setBlock(i + 3, j + 0, k + 46, Wildycraft.rsSand);
		world.setBlock(i + 3, j + 0, k + 47, Wildycraft.rsSand);
		world.setBlock(i + 3, j + 0, k + 48, Wildycraft.rsSand);
		world.setBlock(i + 3, j + 0, k + 49, Wildycraft.rsSand);
		world.setBlock(i + 3, j + 0, k + 50, Wildycraft.rsSand);
		world.setBlock(i + 3, j + 0, k + 51, Wildycraft.rsSand);
		world.setBlock(i + 3, j + 0, k + 52, Wildycraft.rsSand);
		world.setBlock(i + 3, j + 0, k + 53, Wildycraft.rsSand);
		world.setBlock(i + 3, j + 0, k + 54, Wildycraft.rsSand);
		world.setBlock(i + 3, j + 0, k + 55, Wildycraft.rsSand);
		world.setBlock(i + 3, j + 0, k + 56, Wildycraft.rsSand);
		world.setBlock(i + 3, j + 0, k + 57, Wildycraft.rsSand);
		world.setBlock(i + 3, j + 0, k + 58, Wildycraft.rsSand);
		world.setBlock(i + 3, j + 0, k + 59, Wildycraft.rsSand);
		world.setBlock(i + 3, j + 1, k + 0, Blocks.sandstone_stairs, 2, 4);
		world.setBlock(i + 3, j + 1, k + 1, Blocks.sandstone, 2, 4);
		world.setBlock(i + 3, j + 1, k + 2, Blocks.sandstone, 2, 4);
		world.setBlock(i + 3, j + 1, k + 3, Blocks.sandstone, 2, 4);
		world.setBlock(i + 3, j + 1, k + 4, Blocks.sandstone, 2, 4);
		world.setBlock(i + 3, j + 1, k + 5, Blocks.sandstone, 2, 4);
		world.setBlock(i + 3, j + 1, k + 6, Blocks.sandstone, 2, 4);
		world.setBlock(i + 3, j + 1, k + 27, Blocks.sandstone);
		world.setBlock(i + 3, j + 1, k + 28, Blocks.fire, 15, 4);
		world.setBlock(i + 3, j + 1, k + 29, Blocks.sandstone);
		world.setBlock(i + 3, j + 1, k + 30, Blocks.sandstone);
		world.setBlock(i + 3, j + 1, k + 31, Blocks.fire, 15, 4);
		world.setBlock(i + 3, j + 1, k + 32, Blocks.sandstone);
		world.setBlock(i + 3, j + 1, k + 53, Blocks.sandstone, 2, 4);
		world.setBlock(i + 3, j + 1, k + 54, Blocks.sandstone, 2, 4);
		world.setBlock(i + 3, j + 1, k + 55, Blocks.sandstone, 2, 4);
		world.setBlock(i + 3, j + 1, k + 56, Blocks.sandstone, 2, 4);
		world.setBlock(i + 3, j + 1, k + 57, Blocks.sandstone, 2, 4);
		world.setBlock(i + 3, j + 1, k + 58, Blocks.sandstone, 2, 4);
		world.setBlock(i + 3, j + 1, k + 59, Blocks.sandstone_stairs, 3, 4);
		world.setBlock(i + 3, j + 2, k + 2, Blocks.sandstone, 2, 4);
		world.setBlock(i + 3, j + 2, k + 3, Blocks.sandstone, 2, 4);
		world.setBlock(i + 3, j + 2, k + 4, Blocks.sandstone, 2, 4);
		world.setBlock(i + 3, j + 2, k + 27, Blocks.sandstone_stairs, 2, 4);
		world.setBlock(i + 3, j + 2, k + 28, Blocks.stained_glass, 1, 4);
		world.setBlock(i + 3, j + 2, k + 29, Blocks.sandstone);
		world.setBlock(i + 3, j + 2, k + 30, Blocks.sandstone);
		world.setBlock(i + 3, j + 2, k + 31, Blocks.stained_glass, 1, 4);
		world.setBlock(i + 3, j + 2, k + 32, Blocks.sandstone_stairs, 3, 4);
		world.setBlock(i + 3, j + 2, k + 55, Blocks.sandstone, 2, 4);
		world.setBlock(i + 3, j + 2, k + 56, Blocks.sandstone, 2, 4);
		world.setBlock(i + 3, j + 2, k + 57, Blocks.sandstone, 2, 4);
		world.setBlock(i + 3, j + 3, k + 2, Blocks.sandstone, 2, 4);
		world.setBlock(i + 3, j + 3, k + 3, Blocks.netherrack);
		world.setBlock(i + 3, j + 3, k + 4, Blocks.sandstone, 2, 4);
		world.setBlock(i + 3, j + 3, k + 28, Blocks.sandstone, 1, 4);
		world.setBlock(i + 3, j + 3, k + 31, Blocks.sandstone, 1, 4);
		world.setBlock(i + 3, j + 3, k + 55, Blocks.sandstone, 2, 4);
		world.setBlock(i + 3, j + 3, k + 56, Blocks.netherrack);
		world.setBlock(i + 3, j + 3, k + 57, Blocks.sandstone, 2, 4);
		world.setBlock(i + 3, j + 4, k + 2, Blocks.stained_glass);
		world.setBlock(i + 3, j + 4, k + 3, Blocks.fire, 15, 4);
		world.setBlock(i + 3, j + 4, k + 4, Blocks.stained_glass);
		world.setBlock(i + 3, j + 4, k + 55, Blocks.stained_glass, 14, 4);
		world.setBlock(i + 3, j + 4, k + 56, Blocks.fire, 15, 4);
		world.setBlock(i + 3, j + 4, k + 57, Blocks.stained_glass, 14, 4);
		world.setBlock(i + 3, j + 5, k + 2, Blocks.sandstone, 2, 4);
		world.setBlock(i + 3, j + 5, k + 3, Blocks.sandstone, 2, 4);
		world.setBlock(i + 3, j + 5, k + 4, Blocks.sandstone, 2, 4);
		world.setBlock(i + 3, j + 5, k + 55, Blocks.sandstone, 2, 4);
		world.setBlock(i + 3, j + 5, k + 56, Blocks.sandstone, 2, 4);
		world.setBlock(i + 3, j + 5, k + 57, Blocks.sandstone, 2, 4);
		world.setBlock(i + 3, j + 6, k + 2, Blocks.sandstone, 2, 4);
		world.setBlock(i + 3, j + 6, k + 3, Blocks.sandstone, 2, 4);
		world.setBlock(i + 3, j + 6, k + 4, Blocks.sandstone, 2, 4);
		world.setBlock(i + 3, j + 6, k + 55, Blocks.sandstone, 2, 4);
		world.setBlock(i + 3, j + 6, k + 56, Blocks.sandstone, 2, 4);
		world.setBlock(i + 3, j + 6, k + 57, Blocks.sandstone, 2, 4);
		world.setBlock(i + 3, j + 7, k + 2, Blocks.sandstone, 2, 4);
		world.setBlock(i + 3, j + 7, k + 3, Blocks.sandstone, 2, 4);
		world.setBlock(i + 3, j + 7, k + 4, Blocks.sandstone, 2, 4);
		world.setBlock(i + 3, j + 7, k + 55, Blocks.sandstone, 2, 4);
		world.setBlock(i + 3, j + 7, k + 56, Blocks.sandstone, 2, 4);
		world.setBlock(i + 3, j + 7, k + 57, Blocks.sandstone, 2, 4);
		world.setBlock(i + 3, j + 8, k + 2, Blocks.sandstone_stairs, 2, 4);
		world.setBlock(i + 3, j + 8, k + 3, Blocks.sandstone, 1, 4);
		world.setBlock(i + 3, j + 8, k + 4, Blocks.sandstone_stairs, 3, 4);
		world.setBlock(i + 3, j + 8, k + 55, Blocks.sandstone_stairs, 2, 4);
		world.setBlock(i + 3, j + 8, k + 56, Blocks.sandstone, 1, 4);
		world.setBlock(i + 3, j + 8, k + 57, Blocks.sandstone_stairs, 3, 4);
		world.setBlock(i + 3, j + 9, k + 3, Blocks.sandstone, 1, 4);
		world.setBlock(i + 3, j + 9, k + 56, Blocks.sandstone, 1, 4);
		world.setBlock(i + 3, j + 10, k + 3, Blocks.sandstone, 1, 4);
		world.setBlock(i + 3, j + 10, k + 56, Blocks.sandstone, 1, 4);
		world.setBlock(i + 3, j + 11, k + 3, Blocks.sandstone, 1, 4);
		world.setBlock(i + 3, j + 11, k + 56, Blocks.stained_glass, 14, 4);
		world.setBlock(i + 3, j + 12, k + 3, Blocks.stained_glass);
		world.setBlock(i + 4, j + 0, k + 0, Wildycraft.rsSand);
		world.setBlock(i + 4, j + 0, k + 1, Wildycraft.rsSand);
		world.setBlock(i + 4, j + 0, k + 2, Wildycraft.rsSand);
		world.setBlock(i + 4, j + 0, k + 3, Wildycraft.rsSand);
		world.setBlock(i + 4, j + 0, k + 4, Wildycraft.rsSand);
		world.setBlock(i + 4, j + 0, k + 5, Wildycraft.rsSand);
		world.setBlock(i + 4, j + 0, k + 6, Wildycraft.rsSand);
		world.setBlock(i + 4, j + 0, k + 7, Wildycraft.rsSand);
		world.setBlock(i + 4, j + 0, k + 8, Wildycraft.rsSand);
		world.setBlock(i + 4, j + 0, k + 9, Wildycraft.rsSand);
		world.setBlock(i + 4, j + 0, k + 10, Wildycraft.rsSand);
		world.setBlock(i + 4, j + 0, k + 11, Wildycraft.rsSand);
		world.setBlock(i + 4, j + 0, k + 12, Wildycraft.rsSand);
		world.setBlock(i + 4, j + 0, k + 13, Wildycraft.rsSand);
		world.setBlock(i + 4, j + 0, k + 14, Wildycraft.rsSand);
		world.setBlock(i + 4, j + 0, k + 15, Wildycraft.rsSand);
		world.setBlock(i + 4, j + 0, k + 16, Wildycraft.rsSand);
		world.setBlock(i + 4, j + 0, k + 17, Wildycraft.rsSand);
		world.setBlock(i + 4, j + 0, k + 18, Wildycraft.rsSand);
		world.setBlock(i + 4, j + 0, k + 19, Wildycraft.rsSand);
		world.setBlock(i + 4, j + 0, k + 20, Wildycraft.rsSand);
		world.setBlock(i + 4, j + 0, k + 21, Wildycraft.rsSand);
		world.setBlock(i + 4, j + 0, k + 22, Wildycraft.rsSand);
		world.setBlock(i + 4, j + 0, k + 23, Wildycraft.rsSand);
		world.setBlock(i + 4, j + 0, k + 24, Wildycraft.rsSand);
		world.setBlock(i + 4, j + 0, k + 25, Wildycraft.rsSand);
		world.setBlock(i + 4, j + 0, k + 26, Wildycraft.rsSand);
		world.setBlock(i + 4, j + 0, k + 27, Wildycraft.rsSand);
		world.setBlock(i + 4, j + 0, k + 28, Wildycraft.rsSand);
		world.setBlock(i + 4, j + 0, k + 29, Wildycraft.rsSand);
		world.setBlock(i + 4, j + 0, k + 30, Wildycraft.rsSand);
		world.setBlock(i + 4, j + 0, k + 31, Wildycraft.rsSand);
		world.setBlock(i + 4, j + 0, k + 32, Wildycraft.rsSand);
		world.setBlock(i + 4, j + 0, k + 33, Wildycraft.rsSand);
		world.setBlock(i + 4, j + 0, k + 34, Wildycraft.rsSand);
		world.setBlock(i + 4, j + 0, k + 35, Wildycraft.rsSand);
		world.setBlock(i + 4, j + 0, k + 36, Wildycraft.rsSand);
		world.setBlock(i + 4, j + 0, k + 37, Wildycraft.rsSand);
		world.setBlock(i + 4, j + 0, k + 38, Wildycraft.rsSand);
		world.setBlock(i + 4, j + 0, k + 39, Wildycraft.rsSand);
		world.setBlock(i + 4, j + 0, k + 40, Wildycraft.rsSand);
		world.setBlock(i + 4, j + 0, k + 41, Wildycraft.rsSand);
		world.setBlock(i + 4, j + 0, k + 42, Wildycraft.rsSand);
		world.setBlock(i + 4, j + 0, k + 43, Wildycraft.rsSand);
		world.setBlock(i + 4, j + 0, k + 44, Wildycraft.rsSand);
		world.setBlock(i + 4, j + 0, k + 45, Wildycraft.rsSand);
		world.setBlock(i + 4, j + 0, k + 46, Wildycraft.rsSand);
		world.setBlock(i + 4, j + 0, k + 47, Wildycraft.rsSand);
		world.setBlock(i + 4, j + 0, k + 48, Wildycraft.rsSand);
		world.setBlock(i + 4, j + 0, k + 49, Wildycraft.rsSand);
		world.setBlock(i + 4, j + 0, k + 50, Wildycraft.rsSand);
		world.setBlock(i + 4, j + 0, k + 51, Wildycraft.rsSand);
		world.setBlock(i + 4, j + 0, k + 52, Wildycraft.rsSand);
		world.setBlock(i + 4, j + 0, k + 53, Wildycraft.rsSand);
		world.setBlock(i + 4, j + 0, k + 54, Wildycraft.rsSand);
		world.setBlock(i + 4, j + 0, k + 55, Wildycraft.rsSand);
		world.setBlock(i + 4, j + 0, k + 56, Wildycraft.rsSand);
		world.setBlock(i + 4, j + 0, k + 57, Wildycraft.rsSand);
		world.setBlock(i + 4, j + 0, k + 58, Wildycraft.rsSand);
		world.setBlock(i + 4, j + 0, k + 59, Wildycraft.rsSand);
		world.setBlock(i + 4, j + 1, k + 0, Blocks.sandstone, 2, 4);
		world.setBlock(i + 4, j + 1, k + 1, Blocks.sandstone, 2, 4);
		world.setBlock(i + 4, j + 1, k + 2, Blocks.sandstone, 2, 4);
		world.setBlock(i + 4, j + 1, k + 3, Blocks.sandstone, 2, 4);
		world.setBlock(i + 4, j + 1, k + 4, Blocks.sandstone, 2, 4);
		world.setBlock(i + 4, j + 1, k + 5, Blocks.sandstone, 2, 4);
		world.setBlock(i + 4, j + 1, k + 6, Blocks.sandstone, 2, 4);
		world.setBlock(i + 4, j + 1, k + 27, Blocks.sandstone);
		world.setBlock(i + 4, j + 1, k + 28, Blocks.sandstone);
		world.setBlock(i + 4, j + 1, k + 29, Blocks.sandstone);
		world.setBlock(i + 4, j + 1, k + 30, Blocks.sandstone);
		world.setBlock(i + 4, j + 1, k + 31, Blocks.sandstone);
		world.setBlock(i + 4, j + 1, k + 32, Blocks.sandstone);
		world.setBlock(i + 4, j + 1, k + 53, Blocks.sandstone, 2, 4);
		world.setBlock(i + 4, j + 1, k + 54, Blocks.sandstone, 2, 4);
		world.setBlock(i + 4, j + 1, k + 55, Blocks.sandstone, 2, 4);
		world.setBlock(i + 4, j + 1, k + 56, Blocks.sandstone, 2, 4);
		world.setBlock(i + 4, j + 1, k + 57, Blocks.sandstone, 2, 4);
		world.setBlock(i + 4, j + 1, k + 58, Blocks.sandstone, 2, 4);
		world.setBlock(i + 4, j + 1, k + 59, Blocks.sandstone, 2, 4);
		world.setBlock(i + 4, j + 2, k + 2, Blocks.sandstone, 2, 4);
		world.setBlock(i + 4, j + 2, k + 3, Blocks.sandstone, 2, 4);
		world.setBlock(i + 4, j + 2, k + 4, Blocks.sandstone, 2, 4);
		world.setBlock(i + 4, j + 2, k + 27, Blocks.sandstone_stairs, 2, 4);
		world.setBlock(i + 4, j + 2, k + 28, Blocks.sandstone);
		world.setBlock(i + 4, j + 2, k + 29, Blocks.sandstone);
		world.setBlock(i + 4, j + 2, k + 30, Blocks.sandstone);
		world.setBlock(i + 4, j + 2, k + 31, Blocks.sandstone, 2, 4);
		world.setBlock(i + 4, j + 2, k + 32, Blocks.sandstone_stairs, 3, 4);
		world.setBlock(i + 4, j + 2, k + 55, Blocks.sandstone, 2, 4);
		world.setBlock(i + 4, j + 2, k + 56, Blocks.sandstone, 2, 4);
		world.setBlock(i + 4, j + 2, k + 57, Blocks.sandstone, 2, 4);
		world.setBlock(i + 4, j + 3, k + 2, Blocks.sandstone, 2, 4);
		world.setBlock(i + 4, j + 3, k + 3, Blocks.sandstone, 2, 4);
		world.setBlock(i + 4, j + 3, k + 4, Blocks.sandstone, 2, 4);
		world.setBlock(i + 4, j + 3, k + 28, Blocks.sandstone, 2, 4);
		world.setBlock(i + 4, j + 3, k + 31, Blocks.sandstone, 2, 4);
		world.setBlock(i + 4, j + 3, k + 55, Blocks.sandstone, 2, 4);
		world.setBlock(i + 4, j + 3, k + 56, Blocks.sandstone, 2, 4);
		world.setBlock(i + 4, j + 3, k + 57, Blocks.sandstone, 2, 4);
		world.setBlock(i + 4, j + 4, k + 2, Blocks.sandstone, 2, 4);
		world.setBlock(i + 4, j + 4, k + 3, Blocks.stained_glass);
		world.setBlock(i + 4, j + 4, k + 4, Blocks.sandstone, 2, 4);
		world.setBlock(i + 4, j + 4, k + 55, Blocks.sandstone, 2, 4);
		world.setBlock(i + 4, j + 4, k + 56, Blocks.stained_glass, 14, 4);
		world.setBlock(i + 4, j + 4, k + 57, Blocks.sandstone, 2, 4);
		world.setBlock(i + 4, j + 5, k + 2, Blocks.sandstone, 2, 4);
		world.setBlock(i + 4, j + 5, k + 3, Blocks.sandstone, 2, 4);
		world.setBlock(i + 4, j + 5, k + 4, Blocks.sandstone, 2, 4);
		world.setBlock(i + 4, j + 5, k + 55, Blocks.sandstone, 2, 4);
		world.setBlock(i + 4, j + 5, k + 56, Blocks.sandstone, 2, 4);
		world.setBlock(i + 4, j + 5, k + 57, Blocks.sandstone, 2, 4);
		world.setBlock(i + 4, j + 6, k + 2, Blocks.sandstone, 2, 4);
		world.setBlock(i + 4, j + 6, k + 3, Blocks.sandstone, 2, 4);
		world.setBlock(i + 4, j + 6, k + 4, Blocks.sandstone, 2, 4);
		world.setBlock(i + 4, j + 6, k + 55, Blocks.sandstone, 2, 4);
		world.setBlock(i + 4, j + 6, k + 56, Blocks.sandstone, 2, 4);
		world.setBlock(i + 4, j + 6, k + 57, Blocks.sandstone, 2, 4);
		world.setBlock(i + 4, j + 7, k + 2, Blocks.sandstone, 2, 4);
		world.setBlock(i + 4, j + 7, k + 3, Blocks.sandstone, 2, 4);
		world.setBlock(i + 4, j + 7, k + 4, Blocks.sandstone, 2, 4);
		world.setBlock(i + 4, j + 7, k + 55, Blocks.sandstone, 2, 4);
		world.setBlock(i + 4, j + 7, k + 56, Blocks.sandstone, 2, 4);
		world.setBlock(i + 4, j + 7, k + 57, Blocks.sandstone, 2, 4);
		world.setBlock(i + 4, j + 8, k + 3, Blocks.sandstone_stairs, 1, 4);
		world.setBlock(i + 4, j + 8, k + 56, Blocks.sandstone_stairs, 1, 4);
		world.setBlock(i + 5, j + 0, k + 0, Wildycraft.rsSand);
		world.setBlock(i + 5, j + 0, k + 1, Wildycraft.rsSand);
		world.setBlock(i + 5, j + 0, k + 2, Wildycraft.rsSand);
		world.setBlock(i + 5, j + 0, k + 3, Wildycraft.rsSand);
		world.setBlock(i + 5, j + 0, k + 4, Wildycraft.rsSand);
		world.setBlock(i + 5, j + 0, k + 5, Wildycraft.rsSand);
		world.setBlock(i + 5, j + 0, k + 6, Wildycraft.rsSand);
		world.setBlock(i + 5, j + 0, k + 7, Wildycraft.rsSand);
		world.setBlock(i + 5, j + 0, k + 8, Wildycraft.rsSand);
		world.setBlock(i + 5, j + 0, k + 9, Wildycraft.rsSand);
		world.setBlock(i + 5, j + 0, k + 10, Wildycraft.rsSand);
		world.setBlock(i + 5, j + 0, k + 11, Wildycraft.rsSand);
		world.setBlock(i + 5, j + 0, k + 12, Wildycraft.rsSand);
		world.setBlock(i + 5, j + 0, k + 13, Wildycraft.rsSand);
		world.setBlock(i + 5, j + 0, k + 14, Wildycraft.rsSand);
		world.setBlock(i + 5, j + 0, k + 15, Wildycraft.rsSand);
		world.setBlock(i + 5, j + 0, k + 16, Wildycraft.rsSand);
		world.setBlock(i + 5, j + 0, k + 17, Wildycraft.rsSand);
		world.setBlock(i + 5, j + 0, k + 18, Wildycraft.rsSand);
		world.setBlock(i + 5, j + 0, k + 19, Wildycraft.rsSand);
		world.setBlock(i + 5, j + 0, k + 20, Wildycraft.rsSand);
		world.setBlock(i + 5, j + 0, k + 21, Wildycraft.rsSand);
		world.setBlock(i + 5, j + 0, k + 22, Wildycraft.rsSand);
		world.setBlock(i + 5, j + 0, k + 23, Wildycraft.rsSand);
		world.setBlock(i + 5, j + 0, k + 24, Wildycraft.rsSand);
		world.setBlock(i + 5, j + 0, k + 25, Wildycraft.rsSand);
		world.setBlock(i + 5, j + 0, k + 26, Wildycraft.rsSand);
		world.setBlock(i + 5, j + 0, k + 27, Wildycraft.rsSand);
		world.setBlock(i + 5, j + 0, k + 28, Wildycraft.rsSand);
		world.setBlock(i + 5, j + 0, k + 29, Wildycraft.rsSand);
		world.setBlock(i + 5, j + 0, k + 30, Wildycraft.rsSand);
		world.setBlock(i + 5, j + 0, k + 31, Wildycraft.rsSand);
		world.setBlock(i + 5, j + 0, k + 32, Wildycraft.rsSand);
		world.setBlock(i + 5, j + 0, k + 33, Wildycraft.rsSand);
		world.setBlock(i + 5, j + 0, k + 34, Wildycraft.rsSand);
		world.setBlock(i + 5, j + 0, k + 35, Wildycraft.rsSand);
		world.setBlock(i + 5, j + 0, k + 36, Wildycraft.rsSand);
		world.setBlock(i + 5, j + 0, k + 37, Wildycraft.rsSand);
		world.setBlock(i + 5, j + 0, k + 38, Wildycraft.rsSand);
		world.setBlock(i + 5, j + 0, k + 39, Wildycraft.rsSand);
		world.setBlock(i + 5, j + 0, k + 40, Wildycraft.rsSand);
		world.setBlock(i + 5, j + 0, k + 41, Wildycraft.rsSand);
		world.setBlock(i + 5, j + 0, k + 42, Wildycraft.rsSand);
		world.setBlock(i + 5, j + 0, k + 43, Wildycraft.rsSand);
		world.setBlock(i + 5, j + 0, k + 44, Wildycraft.rsSand);
		world.setBlock(i + 5, j + 0, k + 45, Wildycraft.rsSand);
		world.setBlock(i + 5, j + 0, k + 46, Wildycraft.rsSand);
		world.setBlock(i + 5, j + 0, k + 47, Wildycraft.rsSand);
		world.setBlock(i + 5, j + 0, k + 48, Wildycraft.rsSand);
		world.setBlock(i + 5, j + 0, k + 49, Wildycraft.rsSand);
		world.setBlock(i + 5, j + 0, k + 50, Wildycraft.rsSand);
		world.setBlock(i + 5, j + 0, k + 51, Wildycraft.rsSand);
		world.setBlock(i + 5, j + 0, k + 52, Wildycraft.rsSand);
		world.setBlock(i + 5, j + 0, k + 53, Wildycraft.rsSand);
		world.setBlock(i + 5, j + 0, k + 54, Wildycraft.rsSand);
		world.setBlock(i + 5, j + 0, k + 55, Wildycraft.rsSand);
		world.setBlock(i + 5, j + 0, k + 56, Wildycraft.rsSand);
		world.setBlock(i + 5, j + 0, k + 57, Wildycraft.rsSand);
		world.setBlock(i + 5, j + 0, k + 58, Wildycraft.rsSand);
		world.setBlock(i + 5, j + 0, k + 59, Wildycraft.rsSand);
		world.setBlock(i + 5, j + 1, k + 0, Blocks.sandstone, 2, 4);
		world.setBlock(i + 5, j + 1, k + 1, Blocks.sandstone, 2, 4);
		world.setBlock(i + 5, j + 1, k + 2, Blocks.sandstone, 2, 4);
		world.setBlock(i + 5, j + 1, k + 3, Blocks.sandstone, 2, 4);
		world.setBlock(i + 5, j + 1, k + 4, Blocks.sandstone, 2, 4);
		world.setBlock(i + 5, j + 1, k + 5, Blocks.sandstone, 2, 4);
		world.setBlock(i + 5, j + 1, k + 6, Blocks.sandstone, 2, 4);
		world.setBlock(i + 5, j + 1, k + 27, Blocks.sandstone);
		world.setBlock(i + 5, j + 1, k + 28, Blocks.sandstone);
		world.setBlock(i + 5, j + 1, k + 29, Blocks.sandstone);
		world.setBlock(i + 5, j + 1, k + 30, Blocks.sandstone);
		world.setBlock(i + 5, j + 1, k + 31, Blocks.sandstone);
		world.setBlock(i + 5, j + 1, k + 32, Blocks.sandstone);
		world.setBlock(i + 5, j + 1, k + 53, Blocks.sandstone, 2, 4);
		world.setBlock(i + 5, j + 1, k + 54, Blocks.sandstone, 2, 4);
		world.setBlock(i + 5, j + 1, k + 55, Blocks.sandstone, 2, 4);
		world.setBlock(i + 5, j + 1, k + 56, Blocks.sandstone, 2, 4);
		world.setBlock(i + 5, j + 1, k + 57, Blocks.sandstone, 2, 4);
		world.setBlock(i + 5, j + 1, k + 58, Blocks.sandstone, 2, 4);
		world.setBlock(i + 5, j + 1, k + 59, Blocks.sandstone, 2, 4);
		world.setBlock(i + 5, j + 2, k + 27, Blocks.sandstone_stairs, 2, 4);
		world.setBlock(i + 5, j + 2, k + 28, Blocks.sandstone);
		world.setBlock(i + 5, j + 2, k + 29, Blocks.sandstone);
		world.setBlock(i + 5, j + 2, k + 30, Blocks.sandstone);
		world.setBlock(i + 5, j + 2, k + 31, Blocks.sandstone);
		world.setBlock(i + 5, j + 2, k + 32, Blocks.sandstone_stairs, 3, 4);
		world.setBlock(i + 5, j + 3, k + 28, Blocks.sandstone, 2, 4);
		world.setBlock(i + 5, j + 3, k + 31, Blocks.sandstone, 2, 4);
		world.setBlock(i + 6, j + 0, k + 0, Wildycraft.rsSand);
		world.setBlock(i + 6, j + 0, k + 1, Wildycraft.rsSand);
		world.setBlock(i + 6, j + 0, k + 2, Wildycraft.rsSand);
		world.setBlock(i + 6, j + 0, k + 3, Wildycraft.rsSand);
		world.setBlock(i + 6, j + 0, k + 4, Wildycraft.rsSand);
		world.setBlock(i + 6, j + 0, k + 5, Wildycraft.rsSand);
		world.setBlock(i + 6, j + 0, k + 6, Wildycraft.rsSand);
		world.setBlock(i + 6, j + 0, k + 7, Wildycraft.rsSand);
		world.setBlock(i + 6, j + 0, k + 8, Wildycraft.rsSand);
		world.setBlock(i + 6, j + 0, k + 9, Wildycraft.rsSand);
		world.setBlock(i + 6, j + 0, k + 10, Wildycraft.rsSand);
		world.setBlock(i + 6, j + 0, k + 11, Wildycraft.rsSand);
		world.setBlock(i + 6, j + 0, k + 12, Wildycraft.rsSand);
		world.setBlock(i + 6, j + 0, k + 13, Wildycraft.rsSand);
		world.setBlock(i + 6, j + 0, k + 14, Wildycraft.rsSand);
		world.setBlock(i + 6, j + 0, k + 15, Wildycraft.rsSand);
		world.setBlock(i + 6, j + 0, k + 16, Wildycraft.rsSand);
		world.setBlock(i + 6, j + 0, k + 17, Wildycraft.rsSand);
		world.setBlock(i + 6, j + 0, k + 18, Wildycraft.rsSand);
		world.setBlock(i + 6, j + 0, k + 19, Wildycraft.rsSand);
		world.setBlock(i + 6, j + 0, k + 20, Wildycraft.rsSand);
		world.setBlock(i + 6, j + 0, k + 21, Wildycraft.rsSand);
		world.setBlock(i + 6, j + 0, k + 22, Wildycraft.rsSand);
		world.setBlock(i + 6, j + 0, k + 23, Wildycraft.rsSand);
		world.setBlock(i + 6, j + 0, k + 24, Wildycraft.rsSand);
		world.setBlock(i + 6, j + 0, k + 25, Wildycraft.rsSand);
		world.setBlock(i + 6, j + 0, k + 26, Wildycraft.rsSand);
		world.setBlock(i + 6, j + 0, k + 27, Wildycraft.rsSand);
		world.setBlock(i + 6, j + 0, k + 28, Wildycraft.rsSand);
		world.setBlock(i + 6, j + 0, k + 29, Wildycraft.rsSand);
		world.setBlock(i + 6, j + 0, k + 30, Wildycraft.rsSand);
		world.setBlock(i + 6, j + 0, k + 31, Wildycraft.rsSand);
		world.setBlock(i + 6, j + 0, k + 32, Wildycraft.rsSand);
		world.setBlock(i + 6, j + 0, k + 33, Wildycraft.rsSand);
		world.setBlock(i + 6, j + 0, k + 34, Wildycraft.rsSand);
		world.setBlock(i + 6, j + 0, k + 35, Wildycraft.rsSand);
		world.setBlock(i + 6, j + 0, k + 36, Wildycraft.rsSand);
		world.setBlock(i + 6, j + 0, k + 37, Wildycraft.rsSand);
		world.setBlock(i + 6, j + 0, k + 38, Wildycraft.rsSand);
		world.setBlock(i + 6, j + 0, k + 39, Wildycraft.rsSand);
		world.setBlock(i + 6, j + 0, k + 40, Wildycraft.rsSand);
		world.setBlock(i + 6, j + 0, k + 41, Wildycraft.rsSand);
		world.setBlock(i + 6, j + 0, k + 42, Wildycraft.rsSand);
		world.setBlock(i + 6, j + 0, k + 43, Wildycraft.rsSand);
		world.setBlock(i + 6, j + 0, k + 44, Wildycraft.rsSand);
		world.setBlock(i + 6, j + 0, k + 45, Wildycraft.rsSand);
		world.setBlock(i + 6, j + 0, k + 46, Wildycraft.rsSand);
		world.setBlock(i + 6, j + 0, k + 47, Wildycraft.rsSand);
		world.setBlock(i + 6, j + 0, k + 48, Wildycraft.rsSand);
		world.setBlock(i + 6, j + 0, k + 49, Wildycraft.rsSand);
		world.setBlock(i + 6, j + 0, k + 50, Wildycraft.rsSand);
		world.setBlock(i + 6, j + 0, k + 51, Wildycraft.rsSand);
		world.setBlock(i + 6, j + 0, k + 52, Wildycraft.rsSand);
		world.setBlock(i + 6, j + 0, k + 53, Wildycraft.rsSand);
		world.setBlock(i + 6, j + 0, k + 54, Wildycraft.rsSand);
		world.setBlock(i + 6, j + 0, k + 55, Wildycraft.rsSand);
		world.setBlock(i + 6, j + 0, k + 56, Wildycraft.rsSand);
		world.setBlock(i + 6, j + 0, k + 57, Wildycraft.rsSand);
		world.setBlock(i + 6, j + 0, k + 58, Wildycraft.rsSand);
		world.setBlock(i + 6, j + 0, k + 59, Wildycraft.rsSand);
		world.setBlock(i + 6, j + 1, k + 0, Blocks.sandstone, 2, 4);
		world.setBlock(i + 6, j + 1, k + 1, Blocks.sandstone, 2, 4);
		world.setBlock(i + 6, j + 1, k + 2, Blocks.sandstone, 2, 4);
		world.setBlock(i + 6, j + 1, k + 3, Blocks.sandstone, 2, 4);
		world.setBlock(i + 6, j + 1, k + 4, Blocks.sandstone, 2, 4);
		world.setBlock(i + 6, j + 1, k + 5, Blocks.sandstone, 2, 4);
		world.setBlock(i + 6, j + 1, k + 6, Blocks.sandstone, 2, 4);
		world.setBlock(i + 6, j + 1, k + 7, Blocks.sandstone_stairs);
		world.setBlock(i + 6, j + 1, k + 8, Blocks.sandstone_stairs);
		world.setBlock(i + 6, j + 1, k + 9, Blocks.sandstone_stairs);
		world.setBlock(i + 6, j + 1, k + 10, Blocks.sandstone_stairs);
		world.setBlock(i + 6, j + 1, k + 11, Blocks.sandstone_stairs);
		world.setBlock(i + 6, j + 1, k + 12, Blocks.sandstone_stairs);
		world.setBlock(i + 6, j + 1, k + 13, Blocks.sandstone_stairs);
		world.setBlock(i + 6, j + 1, k + 14, Blocks.sandstone_stairs);
		world.setBlock(i + 6, j + 1, k + 15, Blocks.sandstone_stairs);
		world.setBlock(i + 6, j + 1, k + 16, Blocks.sandstone_stairs);
		world.setBlock(i + 6, j + 1, k + 17, Blocks.sandstone_stairs);
		world.setBlock(i + 6, j + 1, k + 18, Blocks.sandstone_stairs);
		world.setBlock(i + 6, j + 1, k + 19, Blocks.sandstone_stairs);
		world.setBlock(i + 6, j + 1, k + 20, Blocks.sandstone_stairs);
		world.setBlock(i + 6, j + 1, k + 21, Blocks.sandstone_stairs);
		world.setBlock(i + 6, j + 1, k + 22, Blocks.sandstone_stairs);
		world.setBlock(i + 6, j + 1, k + 23, Blocks.sandstone_stairs);
		world.setBlock(i + 6, j + 1, k + 24, Blocks.sandstone_stairs);
		world.setBlock(i + 6, j + 1, k + 25, Blocks.sandstone_stairs);
		world.setBlock(i + 6, j + 1, k + 26, Blocks.sandstone_stairs);
		world.setBlock(i + 6, j + 1, k + 27, Blocks.sandstone_stairs);
		world.setBlock(i + 6, j + 1, k + 28, Blocks.sandstone_stairs);
		world.setBlock(i + 6, j + 1, k + 29, Blocks.sandstone);
		world.setBlock(i + 6, j + 1, k + 30, Blocks.sandstone);
		world.setBlock(i + 6, j + 1, k + 31, Blocks.sandstone_stairs);
		world.setBlock(i + 6, j + 1, k + 32, Blocks.sandstone_stairs);
		world.setBlock(i + 6, j + 1, k + 33, Blocks.sandstone_stairs);
		world.setBlock(i + 6, j + 1, k + 34, Blocks.sandstone_stairs);
		world.setBlock(i + 6, j + 1, k + 35, Blocks.sandstone_stairs);
		world.setBlock(i + 6, j + 1, k + 36, Blocks.sandstone_stairs);
		world.setBlock(i + 6, j + 1, k + 37, Blocks.sandstone_stairs);
		world.setBlock(i + 6, j + 1, k + 38, Blocks.sandstone_stairs);
		world.setBlock(i + 6, j + 1, k + 39, Blocks.sandstone_stairs);
		world.setBlock(i + 6, j + 1, k + 40, Blocks.sandstone_stairs);
		world.setBlock(i + 6, j + 1, k + 41, Blocks.sandstone_stairs);
		world.setBlock(i + 6, j + 1, k + 42, Blocks.sandstone_stairs);
		world.setBlock(i + 6, j + 1, k + 43, Blocks.sandstone_stairs);
		world.setBlock(i + 6, j + 1, k + 44, Blocks.sandstone_stairs);
		world.setBlock(i + 6, j + 1, k + 45, Blocks.sandstone_stairs);
		world.setBlock(i + 6, j + 1, k + 46, Blocks.sandstone_stairs);
		world.setBlock(i + 6, j + 1, k + 47, Blocks.sandstone_stairs);
		world.setBlock(i + 6, j + 1, k + 48, Blocks.sandstone_stairs);
		world.setBlock(i + 6, j + 1, k + 49, Blocks.sandstone_stairs);
		world.setBlock(i + 6, j + 1, k + 50, Blocks.sandstone_stairs);
		world.setBlock(i + 6, j + 1, k + 51, Blocks.sandstone_stairs);
		world.setBlock(i + 6, j + 1, k + 52, Blocks.sandstone_stairs);
		world.setBlock(i + 6, j + 1, k + 53, Blocks.sandstone, 2, 4);
		world.setBlock(i + 6, j + 1, k + 54, Blocks.sandstone, 2, 4);
		world.setBlock(i + 6, j + 1, k + 55, Blocks.sandstone, 2, 4);
		world.setBlock(i + 6, j + 1, k + 56, Blocks.sandstone, 2, 4);
		world.setBlock(i + 6, j + 1, k + 57, Blocks.sandstone, 2, 4);
		world.setBlock(i + 6, j + 1, k + 58, Blocks.sandstone, 2, 4);
		world.setBlock(i + 6, j + 1, k + 59, Blocks.sandstone, 2, 4);
		world.setBlock(i + 6, j + 2, k + 29, Blocks.sandstone);
		world.setBlock(i + 6, j + 2, k + 30, Blocks.sandstone);
		world.setBlock(i + 6, j + 3, k + 29, Blocks.sandstone_stairs);
		world.setBlock(i + 6, j + 3, k + 30, Blocks.sandstone_stairs);
		world.setBlock(i + 7, j + 0, k + 0, Wildycraft.rsSand);
		world.setBlock(i + 7, j + 0, k + 1, Wildycraft.rsSand);
		world.setBlock(i + 7, j + 0, k + 2, Wildycraft.rsSand);
		world.setBlock(i + 7, j + 0, k + 3, Wildycraft.rsSand);
		world.setBlock(i + 7, j + 0, k + 4, Wildycraft.rsSand);
		world.setBlock(i + 7, j + 0, k + 5, Wildycraft.rsSand);
		world.setBlock(i + 7, j + 0, k + 6, Wildycraft.rsSand);
		world.setBlock(i + 7, j + 0, k + 7, Wildycraft.rsSand);
		world.setBlock(i + 7, j + 0, k + 8, Wildycraft.rsSand);
		world.setBlock(i + 7, j + 0, k + 9, Wildycraft.rsSand);
		world.setBlock(i + 7, j + 0, k + 10, Wildycraft.rsSand);
		world.setBlock(i + 7, j + 0, k + 11, Wildycraft.rsSand);
		world.setBlock(i + 7, j + 0, k + 12, Wildycraft.rsSand);
		world.setBlock(i + 7, j + 0, k + 13, Wildycraft.rsSand);
		world.setBlock(i + 7, j + 0, k + 14, Wildycraft.rsSand);
		world.setBlock(i + 7, j + 0, k + 15, Wildycraft.rsSand);
		world.setBlock(i + 7, j + 0, k + 16, Wildycraft.rsSand);
		world.setBlock(i + 7, j + 0, k + 17, Wildycraft.rsSand);
		world.setBlock(i + 7, j + 0, k + 18, Wildycraft.rsSand);
		world.setBlock(i + 7, j + 0, k + 19, Wildycraft.rsSand);
		world.setBlock(i + 7, j + 0, k + 20, Wildycraft.rsSand);
		world.setBlock(i + 7, j + 0, k + 21, Wildycraft.rsSand);
		world.setBlock(i + 7, j + 0, k + 22, Wildycraft.rsSand);
		world.setBlock(i + 7, j + 0, k + 23, Wildycraft.rsSand);
		world.setBlock(i + 7, j + 0, k + 24, Wildycraft.rsSand);
		world.setBlock(i + 7, j + 0, k + 25, Wildycraft.rsSand);
		world.setBlock(i + 7, j + 0, k + 26, Wildycraft.rsSand);
		world.setBlock(i + 7, j + 0, k + 27, Wildycraft.rsSand);
		world.setBlock(i + 7, j + 0, k + 28, Wildycraft.rsSand);
		world.setBlock(i + 7, j + 0, k + 29, Wildycraft.rsSand);
		world.setBlock(i + 7, j + 0, k + 30, Wildycraft.rsSand);
		world.setBlock(i + 7, j + 0, k + 31, Wildycraft.rsSand);
		world.setBlock(i + 7, j + 0, k + 32, Wildycraft.rsSand);
		world.setBlock(i + 7, j + 0, k + 33, Wildycraft.rsSand);
		world.setBlock(i + 7, j + 0, k + 34, Wildycraft.rsSand);
		world.setBlock(i + 7, j + 0, k + 35, Wildycraft.rsSand);
		world.setBlock(i + 7, j + 0, k + 36, Wildycraft.rsSand);
		world.setBlock(i + 7, j + 0, k + 37, Wildycraft.rsSand);
		world.setBlock(i + 7, j + 0, k + 38, Wildycraft.rsSand);
		world.setBlock(i + 7, j + 0, k + 39, Wildycraft.rsSand);
		world.setBlock(i + 7, j + 0, k + 40, Wildycraft.rsSand);
		world.setBlock(i + 7, j + 0, k + 41, Wildycraft.rsSand);
		world.setBlock(i + 7, j + 0, k + 42, Wildycraft.rsSand);
		world.setBlock(i + 7, j + 0, k + 43, Wildycraft.rsSand);
		world.setBlock(i + 7, j + 0, k + 44, Wildycraft.rsSand);
		world.setBlock(i + 7, j + 0, k + 45, Wildycraft.rsSand);
		world.setBlock(i + 7, j + 0, k + 46, Wildycraft.rsSand);
		world.setBlock(i + 7, j + 0, k + 47, Wildycraft.rsSand);
		world.setBlock(i + 7, j + 0, k + 48, Wildycraft.rsSand);
		world.setBlock(i + 7, j + 0, k + 49, Wildycraft.rsSand);
		world.setBlock(i + 7, j + 0, k + 50, Wildycraft.rsSand);
		world.setBlock(i + 7, j + 0, k + 51, Wildycraft.rsSand);
		world.setBlock(i + 7, j + 0, k + 52, Wildycraft.rsSand);
		world.setBlock(i + 7, j + 0, k + 53, Wildycraft.rsSand);
		world.setBlock(i + 7, j + 0, k + 54, Wildycraft.rsSand);
		world.setBlock(i + 7, j + 0, k + 55, Wildycraft.rsSand);
		world.setBlock(i + 7, j + 0, k + 56, Wildycraft.rsSand);
		world.setBlock(i + 7, j + 0, k + 57, Wildycraft.rsSand);
		world.setBlock(i + 7, j + 0, k + 58, Wildycraft.rsSand);
		world.setBlock(i + 7, j + 0, k + 59, Wildycraft.rsSand);
		world.setBlock(i + 7, j + 1, k + 6, Blocks.sandstone_stairs, 2, 4);
		world.setBlock(i + 7, j + 1, k + 7, Blocks.sandstone);
		world.setBlock(i + 7, j + 1, k + 8, Blocks.sandstone);
		world.setBlock(i + 7, j + 1, k + 9, Blocks.sandstone);
		world.setBlock(i + 7, j + 1, k + 10, Blocks.sandstone);
		world.setBlock(i + 7, j + 1, k + 11, Blocks.sandstone);
		world.setBlock(i + 7, j + 1, k + 12, Blocks.sandstone);
		world.setBlock(i + 7, j + 1, k + 13, Blocks.sandstone);
		world.setBlock(i + 7, j + 1, k + 14, Blocks.sandstone);
		world.setBlock(i + 7, j + 1, k + 15, Blocks.sandstone);
		world.setBlock(i + 7, j + 1, k + 16, Blocks.sandstone);
		world.setBlock(i + 7, j + 1, k + 17, Blocks.sandstone);
		world.setBlock(i + 7, j + 1, k + 18, Blocks.sandstone);
		world.setBlock(i + 7, j + 1, k + 19, Blocks.sandstone);
		world.setBlock(i + 7, j + 1, k + 20, Blocks.sandstone);
		world.setBlock(i + 7, j + 1, k + 21, Blocks.sandstone);
		world.setBlock(i + 7, j + 1, k + 22, Blocks.sandstone);
		world.setBlock(i + 7, j + 1, k + 23, Blocks.sandstone);
		world.setBlock(i + 7, j + 1, k + 24, Blocks.sandstone);
		world.setBlock(i + 7, j + 1, k + 25, Blocks.sandstone);
		world.setBlock(i + 7, j + 1, k + 26, Blocks.sandstone);
		world.setBlock(i + 7, j + 1, k + 27, Blocks.sandstone);
		world.setBlock(i + 7, j + 1, k + 28, Blocks.sandstone);
		world.setBlock(i + 7, j + 1, k + 29, Blocks.sandstone);
		world.setBlock(i + 7, j + 1, k + 30, Blocks.sandstone);
		world.setBlock(i + 7, j + 1, k + 31, Blocks.sandstone);
		world.setBlock(i + 7, j + 1, k + 32, Blocks.sandstone);
		world.setBlock(i + 7, j + 1, k + 33, Blocks.sandstone);
		world.setBlock(i + 7, j + 1, k + 34, Blocks.sandstone);
		world.setBlock(i + 7, j + 1, k + 35, Blocks.sandstone);
		world.setBlock(i + 7, j + 1, k + 36, Blocks.sandstone);
		world.setBlock(i + 7, j + 1, k + 37, Blocks.sandstone);
		world.setBlock(i + 7, j + 1, k + 38, Blocks.sandstone);
		world.setBlock(i + 7, j + 1, k + 39, Blocks.sandstone);
		world.setBlock(i + 7, j + 1, k + 40, Blocks.sandstone);
		world.setBlock(i + 7, j + 1, k + 41, Blocks.sandstone);
		world.setBlock(i + 7, j + 1, k + 42, Blocks.sandstone);
		world.setBlock(i + 7, j + 1, k + 43, Blocks.sandstone);
		world.setBlock(i + 7, j + 1, k + 44, Blocks.sandstone);
		world.setBlock(i + 7, j + 1, k + 45, Blocks.sandstone);
		world.setBlock(i + 7, j + 1, k + 46, Blocks.sandstone);
		world.setBlock(i + 7, j + 1, k + 47, Blocks.sandstone);
		world.setBlock(i + 7, j + 1, k + 48, Blocks.sandstone);
		world.setBlock(i + 7, j + 1, k + 49, Blocks.sandstone);
		world.setBlock(i + 7, j + 1, k + 50, Blocks.sandstone);
		world.setBlock(i + 7, j + 1, k + 51, Blocks.sandstone);
		world.setBlock(i + 7, j + 1, k + 52, Blocks.sandstone);
		world.setBlock(i + 7, j + 1, k + 53, Blocks.sandstone_stairs, 3, 4);
		world.setBlock(i + 7, j + 2, k + 7, Blocks.sandstone_stairs);
		world.setBlock(i + 7, j + 2, k + 8, Blocks.sandstone_stairs);
		world.setBlock(i + 7, j + 2, k + 9, Blocks.sandstone_stairs);
		world.setBlock(i + 7, j + 2, k + 10, Blocks.sandstone_stairs);
		world.setBlock(i + 7, j + 2, k + 11, Blocks.sandstone_stairs);
		world.setBlock(i + 7, j + 2, k + 12, Blocks.sandstone_stairs);
		world.setBlock(i + 7, j + 2, k + 13, Blocks.sandstone_stairs);
		world.setBlock(i + 7, j + 2, k + 14, Blocks.sandstone_stairs);
		world.setBlock(i + 7, j + 2, k + 15, Blocks.sandstone_stairs);
		world.setBlock(i + 7, j + 2, k + 16, Blocks.sandstone_stairs);
		world.setBlock(i + 7, j + 2, k + 17, Blocks.sandstone_stairs);
		world.setBlock(i + 7, j + 2, k + 18, Blocks.sandstone_stairs);
		world.setBlock(i + 7, j + 2, k + 19, Blocks.sandstone_stairs);
		world.setBlock(i + 7, j + 2, k + 20, Blocks.sandstone_stairs);
		world.setBlock(i + 7, j + 2, k + 21, Blocks.sandstone_stairs);
		world.setBlock(i + 7, j + 2, k + 22, Blocks.sandstone_stairs);
		world.setBlock(i + 7, j + 2, k + 23, Blocks.sandstone_stairs);
		world.setBlock(i + 7, j + 2, k + 24, Blocks.sandstone_stairs);
		world.setBlock(i + 7, j + 2, k + 25, Blocks.sandstone_stairs);
		world.setBlock(i + 7, j + 2, k + 26, Blocks.sandstone_stairs);
		world.setBlock(i + 7, j + 2, k + 27, Blocks.sandstone_stairs);
		world.setBlock(i + 7, j + 2, k + 28, Blocks.sandstone_stairs);
		world.setBlock(i + 7, j + 2, k + 29, Blocks.sandstone);
		world.setBlock(i + 7, j + 2, k + 30, Blocks.sandstone);
		world.setBlock(i + 7, j + 2, k + 31, Blocks.sandstone_stairs);
		world.setBlock(i + 7, j + 2, k + 32, Blocks.sandstone_stairs);
		world.setBlock(i + 7, j + 2, k + 33, Blocks.sandstone_stairs);
		world.setBlock(i + 7, j + 2, k + 34, Blocks.sandstone_stairs);
		world.setBlock(i + 7, j + 2, k + 35, Blocks.sandstone_stairs);
		world.setBlock(i + 7, j + 2, k + 36, Blocks.sandstone_stairs);
		world.setBlock(i + 7, j + 2, k + 37, Blocks.sandstone_stairs);
		world.setBlock(i + 7, j + 2, k + 38, Blocks.sandstone_stairs);
		world.setBlock(i + 7, j + 2, k + 39, Blocks.sandstone_stairs);
		world.setBlock(i + 7, j + 2, k + 40, Blocks.sandstone_stairs);
		world.setBlock(i + 7, j + 2, k + 41, Blocks.sandstone_stairs);
		world.setBlock(i + 7, j + 2, k + 42, Blocks.sandstone_stairs);
		world.setBlock(i + 7, j + 2, k + 43, Blocks.sandstone_stairs);
		world.setBlock(i + 7, j + 2, k + 44, Blocks.sandstone_stairs);
		world.setBlock(i + 7, j + 2, k + 45, Blocks.sandstone_stairs);
		world.setBlock(i + 7, j + 2, k + 46, Blocks.sandstone_stairs);
		world.setBlock(i + 7, j + 2, k + 47, Blocks.sandstone_stairs);
		world.setBlock(i + 7, j + 2, k + 48, Blocks.sandstone_stairs);
		world.setBlock(i + 7, j + 2, k + 49, Blocks.sandstone_stairs);
		world.setBlock(i + 7, j + 2, k + 50, Blocks.sandstone_stairs);
		world.setBlock(i + 7, j + 2, k + 51, Blocks.sandstone_stairs);
		world.setBlock(i + 7, j + 2, k + 52, Blocks.sandstone_stairs, 3, 4);
		world.setBlock(i + 7, j + 3, k + 29, Blocks.sandstone);
		world.setBlock(i + 7, j + 3, k + 30, Blocks.sandstone);
		world.setBlock(i + 7, j + 4, k + 29, Blocks.sandstone_stairs);
		world.setBlock(i + 7, j + 4, k + 30, Blocks.sandstone_stairs);
		world.setBlock(i + 8, j + 0, k + 0, Wildycraft.rsSand);
		world.setBlock(i + 8, j + 0, k + 1, Wildycraft.rsSand);
		world.setBlock(i + 8, j + 0, k + 2, Wildycraft.rsSand);
		world.setBlock(i + 8, j + 0, k + 3, Wildycraft.rsSand);
		world.setBlock(i + 8, j + 0, k + 4, Wildycraft.rsSand);
		world.setBlock(i + 8, j + 0, k + 5, Wildycraft.rsSand);
		world.setBlock(i + 8, j + 0, k + 6, Wildycraft.rsSand);
		world.setBlock(i + 8, j + 0, k + 7, Wildycraft.rsSand);
		world.setBlock(i + 8, j + 0, k + 8, Wildycraft.rsSand);
		world.setBlock(i + 8, j + 0, k + 9, Wildycraft.rsSand);
		world.setBlock(i + 8, j + 0, k + 10, Wildycraft.rsSand);
		world.setBlock(i + 8, j + 0, k + 11, Wildycraft.rsSand);
		world.setBlock(i + 8, j + 0, k + 12, Wildycraft.rsSand);
		world.setBlock(i + 8, j + 0, k + 13, Wildycraft.rsSand);
		world.setBlock(i + 8, j + 0, k + 14, Wildycraft.rsSand);
		world.setBlock(i + 8, j + 0, k + 15, Wildycraft.rsSand);
		world.setBlock(i + 8, j + 0, k + 16, Wildycraft.rsSand);
		world.setBlock(i + 8, j + 0, k + 17, Wildycraft.rsSand);
		world.setBlock(i + 8, j + 0, k + 18, Wildycraft.rsSand);
		world.setBlock(i + 8, j + 0, k + 19, Wildycraft.rsSand);
		world.setBlock(i + 8, j + 0, k + 20, Wildycraft.rsSand);
		world.setBlock(i + 8, j + 0, k + 21, Wildycraft.rsSand);
		world.setBlock(i + 8, j + 0, k + 22, Wildycraft.rsSand);
		world.setBlock(i + 8, j + 0, k + 23, Wildycraft.rsSand);
		world.setBlock(i + 8, j + 0, k + 24, Wildycraft.rsSand);
		world.setBlock(i + 8, j + 0, k + 25, Wildycraft.rsSand);
		world.setBlock(i + 8, j + 0, k + 26, Wildycraft.rsSand);
		world.setBlock(i + 8, j + 0, k + 27, Wildycraft.rsSand);
		world.setBlock(i + 8, j + 0, k + 28, Wildycraft.rsSand);
		world.setBlock(i + 8, j + 0, k + 29, Wildycraft.rsSand);
		world.setBlock(i + 8, j + 0, k + 30, Wildycraft.rsSand);
		world.setBlock(i + 8, j + 0, k + 31, Wildycraft.rsSand);
		world.setBlock(i + 8, j + 0, k + 32, Wildycraft.rsSand);
		world.setBlock(i + 8, j + 0, k + 33, Wildycraft.rsSand);
		world.setBlock(i + 8, j + 0, k + 34, Wildycraft.rsSand);
		world.setBlock(i + 8, j + 0, k + 35, Wildycraft.rsSand);
		world.setBlock(i + 8, j + 0, k + 36, Wildycraft.rsSand);
		world.setBlock(i + 8, j + 0, k + 37, Wildycraft.rsSand);
		world.setBlock(i + 8, j + 0, k + 38, Wildycraft.rsSand);
		world.setBlock(i + 8, j + 0, k + 39, Wildycraft.rsSand);
		world.setBlock(i + 8, j + 0, k + 40, Wildycraft.rsSand);
		world.setBlock(i + 8, j + 0, k + 41, Wildycraft.rsSand);
		world.setBlock(i + 8, j + 0, k + 42, Wildycraft.rsSand);
		world.setBlock(i + 8, j + 0, k + 43, Wildycraft.rsSand);
		world.setBlock(i + 8, j + 0, k + 44, Wildycraft.rsSand);
		world.setBlock(i + 8, j + 0, k + 45, Wildycraft.rsSand);
		world.setBlock(i + 8, j + 0, k + 46, Wildycraft.rsSand);
		world.setBlock(i + 8, j + 0, k + 47, Wildycraft.rsSand);
		world.setBlock(i + 8, j + 0, k + 48, Wildycraft.rsSand);
		world.setBlock(i + 8, j + 0, k + 49, Wildycraft.rsSand);
		world.setBlock(i + 8, j + 0, k + 50, Wildycraft.rsSand);
		world.setBlock(i + 8, j + 0, k + 51, Wildycraft.rsSand);
		world.setBlock(i + 8, j + 0, k + 52, Wildycraft.rsSand);
		world.setBlock(i + 8, j + 0, k + 53, Wildycraft.rsSand);
		world.setBlock(i + 8, j + 0, k + 54, Wildycraft.rsSand);
		world.setBlock(i + 8, j + 0, k + 55, Wildycraft.rsSand);
		world.setBlock(i + 8, j + 0, k + 56, Wildycraft.rsSand);
		world.setBlock(i + 8, j + 0, k + 57, Wildycraft.rsSand);
		world.setBlock(i + 8, j + 0, k + 58, Wildycraft.rsSand);
		world.setBlock(i + 8, j + 0, k + 59, Wildycraft.rsSand);
		world.setBlock(i + 8, j + 1, k + 6, Blocks.sandstone_stairs, 2, 4);
		world.setBlock(i + 8, j + 1, k + 7, Blocks.sandstone);
		world.setBlock(i + 8, j + 1, k + 8, Blocks.sandstone);
		world.setBlock(i + 8, j + 1, k + 9, Blocks.sandstone);
		world.setBlock(i + 8, j + 1, k + 10, Blocks.sandstone);
		world.setBlock(i + 8, j + 1, k + 11, Blocks.sandstone);
		world.setBlock(i + 8, j + 1, k + 12, Blocks.sandstone);
		world.setBlock(i + 8, j + 1, k + 13, Blocks.sandstone);
		world.setBlock(i + 8, j + 1, k + 14, Blocks.sandstone);
		world.setBlock(i + 8, j + 1, k + 15, Blocks.sandstone);
		world.setBlock(i + 8, j + 1, k + 16, Blocks.sandstone);
		world.setBlock(i + 8, j + 1, k + 17, Blocks.sandstone);
		world.setBlock(i + 8, j + 1, k + 18, Blocks.sandstone);
		world.setBlock(i + 8, j + 1, k + 19, Blocks.sandstone);
		world.setBlock(i + 8, j + 1, k + 20, Blocks.sandstone);
		world.setBlock(i + 8, j + 1, k + 21, Blocks.sandstone);
		world.setBlock(i + 8, j + 1, k + 22, Blocks.sandstone);
		world.setBlock(i + 8, j + 1, k + 23, Blocks.sandstone);
		world.setBlock(i + 8, j + 1, k + 24, Blocks.sandstone);
		world.setBlock(i + 8, j + 1, k + 25, Blocks.sandstone);
		world.setBlock(i + 8, j + 1, k + 26, Blocks.sandstone);
		world.setBlock(i + 8, j + 1, k + 27, Blocks.sandstone);
		world.setBlock(i + 8, j + 1, k + 28, Blocks.sandstone);
		world.setBlock(i + 8, j + 1, k + 29, Blocks.sandstone);
		world.setBlock(i + 8, j + 1, k + 30, Blocks.sandstone);
		world.setBlock(i + 8, j + 1, k + 31, Blocks.sandstone);
		world.setBlock(i + 8, j + 1, k + 32, Blocks.sandstone);
		world.setBlock(i + 8, j + 1, k + 33, Blocks.sandstone);
		world.setBlock(i + 8, j + 1, k + 34, Blocks.sandstone);
		world.setBlock(i + 8, j + 1, k + 35, Blocks.sandstone);
		world.setBlock(i + 8, j + 1, k + 36, Blocks.sandstone);
		world.setBlock(i + 8, j + 1, k + 37, Blocks.sandstone);
		world.setBlock(i + 8, j + 1, k + 38, Blocks.sandstone);
		world.setBlock(i + 8, j + 1, k + 39, Blocks.sandstone);
		world.setBlock(i + 8, j + 1, k + 40, Blocks.sandstone);
		world.setBlock(i + 8, j + 1, k + 41, Blocks.sandstone);
		world.setBlock(i + 8, j + 1, k + 42, Blocks.sandstone);
		world.setBlock(i + 8, j + 1, k + 43, Blocks.sandstone);
		world.setBlock(i + 8, j + 1, k + 44, Blocks.sandstone);
		world.setBlock(i + 8, j + 1, k + 45, Blocks.sandstone);
		world.setBlock(i + 8, j + 1, k + 46, Blocks.sandstone);
		world.setBlock(i + 8, j + 1, k + 47, Blocks.sandstone);
		world.setBlock(i + 8, j + 1, k + 48, Blocks.sandstone);
		world.setBlock(i + 8, j + 1, k + 49, Blocks.sandstone);
		world.setBlock(i + 8, j + 1, k + 50, Blocks.sandstone);
		world.setBlock(i + 8, j + 1, k + 51, Blocks.sandstone);
		world.setBlock(i + 8, j + 1, k + 52, Blocks.sandstone);
		world.setBlock(i + 8, j + 1, k + 53, Blocks.sandstone_stairs, 3, 4);
		world.setBlock(i + 8, j + 2, k + 7, Blocks.sandstone_stairs, 2, 4);
		world.setBlock(i + 8, j + 2, k + 8, Blocks.sandstone);
		world.setBlock(i + 8, j + 2, k + 9, Blocks.sandstone);
		world.setBlock(i + 8, j + 2, k + 10, Blocks.sandstone);
		world.setBlock(i + 8, j + 2, k + 11, Blocks.sandstone);
		world.setBlock(i + 8, j + 2, k + 12, Blocks.sandstone);
		world.setBlock(i + 8, j + 2, k + 13, Blocks.sandstone);
		world.setBlock(i + 8, j + 2, k + 14, Blocks.sandstone);
		world.setBlock(i + 8, j + 2, k + 15, Blocks.sandstone);
		world.setBlock(i + 8, j + 2, k + 16, Blocks.sandstone);
		world.setBlock(i + 8, j + 2, k + 17, Blocks.sandstone);
		world.setBlock(i + 8, j + 2, k + 18, Blocks.sandstone);
		world.setBlock(i + 8, j + 2, k + 19, Blocks.sandstone);
		world.setBlock(i + 8, j + 2, k + 20, Blocks.sandstone);
		world.setBlock(i + 8, j + 2, k + 21, Blocks.sandstone);
		world.setBlock(i + 8, j + 2, k + 22, Blocks.sandstone);
		world.setBlock(i + 8, j + 2, k + 23, Blocks.sandstone);
		world.setBlock(i + 8, j + 2, k + 24, Blocks.sandstone);
		world.setBlock(i + 8, j + 2, k + 25, Blocks.sandstone);
		world.setBlock(i + 8, j + 2, k + 26, Blocks.sandstone);
		world.setBlock(i + 8, j + 2, k + 27, Blocks.sandstone);
		world.setBlock(i + 8, j + 2, k + 28, Blocks.sandstone);
		world.setBlock(i + 8, j + 2, k + 29, Blocks.sandstone);
		world.setBlock(i + 8, j + 2, k + 30, Blocks.sandstone);
		world.setBlock(i + 8, j + 2, k + 31, Blocks.sandstone);
		world.setBlock(i + 8, j + 2, k + 32, Blocks.sandstone);
		world.setBlock(i + 8, j + 2, k + 33, Blocks.sandstone);
		world.setBlock(i + 8, j + 2, k + 34, Blocks.sandstone);
		world.setBlock(i + 8, j + 2, k + 35, Blocks.sandstone);
		world.setBlock(i + 8, j + 2, k + 36, Blocks.sandstone);
		world.setBlock(i + 8, j + 2, k + 37, Blocks.sandstone);
		world.setBlock(i + 8, j + 2, k + 38, Blocks.sandstone);
		world.setBlock(i + 8, j + 2, k + 39, Blocks.sandstone);
		world.setBlock(i + 8, j + 2, k + 40, Blocks.sandstone);
		world.setBlock(i + 8, j + 2, k + 41, Blocks.sandstone);
		world.setBlock(i + 8, j + 2, k + 42, Blocks.sandstone);
		world.setBlock(i + 8, j + 2, k + 43, Blocks.sandstone);
		world.setBlock(i + 8, j + 2, k + 44, Blocks.sandstone);
		world.setBlock(i + 8, j + 2, k + 45, Blocks.sandstone);
		world.setBlock(i + 8, j + 2, k + 46, Blocks.sandstone);
		world.setBlock(i + 8, j + 2, k + 47, Blocks.sandstone);
		world.setBlock(i + 8, j + 2, k + 48, Blocks.sandstone);
		world.setBlock(i + 8, j + 2, k + 49, Blocks.sandstone);
		world.setBlock(i + 8, j + 2, k + 50, Blocks.sandstone);
		world.setBlock(i + 8, j + 2, k + 51, Blocks.sandstone);
		world.setBlock(i + 8, j + 2, k + 52, Blocks.sandstone_stairs, 3, 4);
		world.setBlock(i + 8, j + 3, k + 8, Blocks.sandstone_stairs);
		world.setBlock(i + 8, j + 3, k + 9, Blocks.sandstone_stairs);
		world.setBlock(i + 8, j + 3, k + 10, Blocks.sandstone_stairs);
		world.setBlock(i + 8, j + 3, k + 11, Blocks.sandstone_stairs);
		world.setBlock(i + 8, j + 3, k + 12, Blocks.sandstone_stairs);
		world.setBlock(i + 8, j + 3, k + 13, Blocks.sandstone_stairs);
		world.setBlock(i + 8, j + 3, k + 14, Blocks.sandstone_stairs);
		world.setBlock(i + 8, j + 3, k + 15, Blocks.sandstone_stairs);
		world.setBlock(i + 8, j + 3, k + 16, Blocks.sandstone_stairs);
		world.setBlock(i + 8, j + 3, k + 17, Blocks.sandstone_stairs);
		world.setBlock(i + 8, j + 3, k + 18, Blocks.sandstone_stairs);
		world.setBlock(i + 8, j + 3, k + 19, Blocks.sandstone_stairs);
		world.setBlock(i + 8, j + 3, k + 20, Blocks.sandstone_stairs);
		world.setBlock(i + 8, j + 3, k + 21, Blocks.sandstone_stairs);
		world.setBlock(i + 8, j + 3, k + 22, Blocks.sandstone_stairs);
		world.setBlock(i + 8, j + 3, k + 23, Blocks.sandstone_stairs);
		world.setBlock(i + 8, j + 3, k + 24, Blocks.sandstone_stairs);
		world.setBlock(i + 8, j + 3, k + 25, Blocks.sandstone_stairs);
		world.setBlock(i + 8, j + 3, k + 26, Blocks.sandstone_stairs);
		world.setBlock(i + 8, j + 3, k + 27, Blocks.sandstone_stairs);
		world.setBlock(i + 8, j + 3, k + 28, Blocks.sandstone_stairs);
		world.setBlock(i + 8, j + 3, k + 29, Blocks.sandstone);
		world.setBlock(i + 8, j + 3, k + 30, Blocks.sandstone);
		world.setBlock(i + 8, j + 3, k + 31, Blocks.sandstone_stairs);
		world.setBlock(i + 8, j + 3, k + 32, Blocks.sandstone_stairs);
		world.setBlock(i + 8, j + 3, k + 33, Blocks.sandstone_stairs);
		world.setBlock(i + 8, j + 3, k + 34, Blocks.sandstone_stairs);
		world.setBlock(i + 8, j + 3, k + 35, Blocks.sandstone_stairs);
		world.setBlock(i + 8, j + 3, k + 36, Blocks.sandstone_stairs);
		world.setBlock(i + 8, j + 3, k + 37, Blocks.sandstone_stairs);
		world.setBlock(i + 8, j + 3, k + 38, Blocks.sandstone_stairs);
		world.setBlock(i + 8, j + 3, k + 39, Blocks.sandstone_stairs);
		world.setBlock(i + 8, j + 3, k + 40, Blocks.sandstone_stairs);
		world.setBlock(i + 8, j + 3, k + 41, Blocks.sandstone_stairs);
		world.setBlock(i + 8, j + 3, k + 42, Blocks.sandstone_stairs);
		world.setBlock(i + 8, j + 3, k + 43, Blocks.sandstone_stairs);
		world.setBlock(i + 8, j + 3, k + 44, Blocks.sandstone_stairs);
		world.setBlock(i + 8, j + 3, k + 45, Blocks.sandstone_stairs);
		world.setBlock(i + 8, j + 3, k + 46, Blocks.sandstone_stairs);
		world.setBlock(i + 8, j + 3, k + 47, Blocks.sandstone_stairs);
		world.setBlock(i + 8, j + 3, k + 48, Blocks.sandstone_stairs);
		world.setBlock(i + 8, j + 3, k + 49, Blocks.sandstone_stairs);
		world.setBlock(i + 8, j + 3, k + 50, Blocks.sandstone_stairs);
		world.setBlock(i + 8, j + 3, k + 51, Blocks.sandstone_stairs, 3, 4);
		world.setBlock(i + 8, j + 4, k + 29, Blocks.sandstone);
		world.setBlock(i + 8, j + 4, k + 30, Blocks.sandstone);
		world.setBlock(i + 8, j + 5, k + 29, Blocks.sandstone_stairs);
		world.setBlock(i + 8, j + 5, k + 30, Blocks.sandstone_stairs);
		world.setBlock(i + 9, j + 0, k + 0, Wildycraft.rsSand);
		world.setBlock(i + 9, j + 0, k + 1, Wildycraft.rsSand);
		world.setBlock(i + 9, j + 0, k + 2, Wildycraft.rsSand);
		world.setBlock(i + 9, j + 0, k + 3, Wildycraft.rsSand);
		world.setBlock(i + 9, j + 0, k + 4, Wildycraft.rsSand);
		world.setBlock(i + 9, j + 0, k + 5, Wildycraft.rsSand);
		world.setBlock(i + 9, j + 0, k + 6, Wildycraft.rsSand);
		world.setBlock(i + 9, j + 0, k + 7, Wildycraft.rsSand);
		world.setBlock(i + 9, j + 0, k + 8, Wildycraft.rsSand);
		world.setBlock(i + 9, j + 0, k + 9, Wildycraft.rsSand);
		world.setBlock(i + 9, j + 0, k + 10, Wildycraft.rsSand);
		world.setBlock(i + 9, j + 0, k + 11, Wildycraft.rsSand);
		world.setBlock(i + 9, j + 0, k + 12, Wildycraft.rsSand);
		world.setBlock(i + 9, j + 0, k + 13, Wildycraft.rsSand);
		world.setBlock(i + 9, j + 0, k + 14, Wildycraft.rsSand);
		world.setBlock(i + 9, j + 0, k + 15, Wildycraft.rsSand);
		world.setBlock(i + 9, j + 0, k + 16, Wildycraft.rsSand);
		world.setBlock(i + 9, j + 0, k + 17, Wildycraft.rsSand);
		world.setBlock(i + 9, j + 0, k + 18, Wildycraft.rsSand);
		world.setBlock(i + 9, j + 0, k + 19, Wildycraft.rsSand);
		world.setBlock(i + 9, j + 0, k + 20, Wildycraft.rsSand);
		world.setBlock(i + 9, j + 0, k + 21, Wildycraft.rsSand);
		world.setBlock(i + 9, j + 0, k + 22, Wildycraft.rsSand);
		world.setBlock(i + 9, j + 0, k + 23, Wildycraft.rsSand);
		world.setBlock(i + 9, j + 0, k + 24, Wildycraft.rsSand);
		world.setBlock(i + 9, j + 0, k + 25, Wildycraft.rsSand);
		world.setBlock(i + 9, j + 0, k + 26, Wildycraft.rsSand);
		world.setBlock(i + 9, j + 0, k + 27, Wildycraft.rsSand);
		world.setBlock(i + 9, j + 0, k + 28, Wildycraft.rsSand);
		world.setBlock(i + 9, j + 0, k + 29, Wildycraft.rsSand);
		world.setBlock(i + 9, j + 0, k + 30, Wildycraft.rsSand);
		world.setBlock(i + 9, j + 0, k + 31, Wildycraft.rsSand);
		world.setBlock(i + 9, j + 0, k + 32, Wildycraft.rsSand);
		world.setBlock(i + 9, j + 0, k + 33, Wildycraft.rsSand);
		world.setBlock(i + 9, j + 0, k + 34, Wildycraft.rsSand);
		world.setBlock(i + 9, j + 0, k + 35, Wildycraft.rsSand);
		world.setBlock(i + 9, j + 0, k + 36, Wildycraft.rsSand);
		world.setBlock(i + 9, j + 0, k + 37, Wildycraft.rsSand);
		world.setBlock(i + 9, j + 0, k + 38, Wildycraft.rsSand);
		world.setBlock(i + 9, j + 0, k + 39, Wildycraft.rsSand);
		world.setBlock(i + 9, j + 0, k + 40, Wildycraft.rsSand);
		world.setBlock(i + 9, j + 0, k + 41, Wildycraft.rsSand);
		world.setBlock(i + 9, j + 0, k + 42, Wildycraft.rsSand);
		world.setBlock(i + 9, j + 0, k + 43, Wildycraft.rsSand);
		world.setBlock(i + 9, j + 0, k + 44, Wildycraft.rsSand);
		world.setBlock(i + 9, j + 0, k + 45, Wildycraft.rsSand);
		world.setBlock(i + 9, j + 0, k + 46, Wildycraft.rsSand);
		world.setBlock(i + 9, j + 0, k + 47, Wildycraft.rsSand);
		world.setBlock(i + 9, j + 0, k + 48, Wildycraft.rsSand);
		world.setBlock(i + 9, j + 0, k + 49, Wildycraft.rsSand);
		world.setBlock(i + 9, j + 0, k + 50, Wildycraft.rsSand);
		world.setBlock(i + 9, j + 0, k + 51, Wildycraft.rsSand);
		world.setBlock(i + 9, j + 0, k + 52, Wildycraft.rsSand);
		world.setBlock(i + 9, j + 0, k + 53, Wildycraft.rsSand);
		world.setBlock(i + 9, j + 0, k + 54, Wildycraft.rsSand);
		world.setBlock(i + 9, j + 0, k + 55, Wildycraft.rsSand);
		world.setBlock(i + 9, j + 0, k + 56, Wildycraft.rsSand);
		world.setBlock(i + 9, j + 0, k + 57, Wildycraft.rsSand);
		world.setBlock(i + 9, j + 0, k + 58, Wildycraft.rsSand);
		world.setBlock(i + 9, j + 0, k + 59, Wildycraft.rsSand);
		world.setBlock(i + 9, j + 1, k + 6, Blocks.sandstone_stairs, 2, 4);
		world.setBlock(i + 9, j + 1, k + 7, Blocks.sandstone);
		world.setBlock(i + 9, j + 1, k + 8, Blocks.sandstone);
		world.setBlock(i + 9, j + 1, k + 9, Blocks.sandstone);
		world.setBlock(i + 9, j + 1, k + 10, Blocks.sandstone);
		world.setBlock(i + 9, j + 1, k + 11, Blocks.sandstone);
		world.setBlock(i + 9, j + 1, k + 12, Blocks.sandstone);
		world.setBlock(i + 9, j + 1, k + 13, Blocks.sandstone);
		world.setBlock(i + 9, j + 1, k + 14, Blocks.sandstone);
		world.setBlock(i + 9, j + 1, k + 15, Blocks.sandstone);
		world.setBlock(i + 9, j + 1, k + 16, Blocks.sandstone);
		world.setBlock(i + 9, j + 1, k + 17, Blocks.sandstone);
		world.setBlock(i + 9, j + 1, k + 18, Blocks.sandstone);
		world.setBlock(i + 9, j + 1, k + 19, Blocks.sandstone);
		world.setBlock(i + 9, j + 1, k + 20, Blocks.sandstone);
		world.setBlock(i + 9, j + 1, k + 21, Blocks.sandstone);
		world.setBlock(i + 9, j + 1, k + 22, Blocks.sandstone);
		world.setBlock(i + 9, j + 1, k + 23, Blocks.sandstone);
		world.setBlock(i + 9, j + 1, k + 24, Blocks.sandstone);
		world.setBlock(i + 9, j + 1, k + 25, Blocks.sandstone);
		world.setBlock(i + 9, j + 1, k + 26, Blocks.sandstone);
		world.setBlock(i + 9, j + 1, k + 27, Blocks.sandstone);
		world.setBlock(i + 9, j + 1, k + 28, Blocks.sandstone);
		world.setBlock(i + 9, j + 1, k + 29, Blocks.sandstone);
		world.setBlock(i + 9, j + 1, k + 30, Blocks.sandstone);
		world.setBlock(i + 9, j + 1, k + 31, Blocks.sandstone);
		world.setBlock(i + 9, j + 1, k + 32, Blocks.sandstone);
		world.setBlock(i + 9, j + 1, k + 33, Blocks.sandstone);
		world.setBlock(i + 9, j + 1, k + 34, Blocks.sandstone);
		world.setBlock(i + 9, j + 1, k + 35, Blocks.sandstone);
		world.setBlock(i + 9, j + 1, k + 36, Blocks.sandstone);
		world.setBlock(i + 9, j + 1, k + 37, Blocks.sandstone);
		world.setBlock(i + 9, j + 1, k + 38, Blocks.sandstone);
		world.setBlock(i + 9, j + 1, k + 39, Blocks.sandstone);
		world.setBlock(i + 9, j + 1, k + 40, Blocks.sandstone);
		world.setBlock(i + 9, j + 1, k + 41, Blocks.sandstone);
		world.setBlock(i + 9, j + 1, k + 42, Blocks.sandstone);
		world.setBlock(i + 9, j + 1, k + 43, Blocks.sandstone);
		world.setBlock(i + 9, j + 1, k + 44, Blocks.sandstone);
		world.setBlock(i + 9, j + 1, k + 45, Blocks.sandstone);
		world.setBlock(i + 9, j + 1, k + 46, Blocks.sandstone);
		world.setBlock(i + 9, j + 1, k + 47, Blocks.sandstone);
		world.setBlock(i + 9, j + 1, k + 48, Blocks.sandstone);
		world.setBlock(i + 9, j + 1, k + 49, Blocks.sandstone);
		world.setBlock(i + 9, j + 1, k + 50, Blocks.sandstone);
		world.setBlock(i + 9, j + 1, k + 51, Blocks.sandstone);
		world.setBlock(i + 9, j + 1, k + 52, Blocks.sandstone);
		world.setBlock(i + 9, j + 1, k + 53, Blocks.sandstone_stairs, 3, 4);
		world.setBlock(i + 9, j + 2, k + 7, Blocks.sandstone_stairs, 2, 4);
		world.setBlock(i + 9, j + 2, k + 8, Blocks.sandstone);
		world.setBlock(i + 9, j + 2, k + 9, Blocks.sandstone);
		world.setBlock(i + 9, j + 2, k + 10, Blocks.sandstone);
		world.setBlock(i + 9, j + 2, k + 11, Blocks.sandstone);
		world.setBlock(i + 9, j + 2, k + 12, Blocks.sandstone);
		world.setBlock(i + 9, j + 2, k + 13, Blocks.sandstone);
		world.setBlock(i + 9, j + 2, k + 14, Blocks.sandstone);
		world.setBlock(i + 9, j + 2, k + 15, Blocks.sandstone);
		world.setBlock(i + 9, j + 2, k + 16, Blocks.sandstone);
		world.setBlock(i + 9, j + 2, k + 17, Blocks.sandstone);
		world.setBlock(i + 9, j + 2, k + 18, Blocks.sandstone);
		world.setBlock(i + 9, j + 2, k + 19, Blocks.sandstone);
		world.setBlock(i + 9, j + 2, k + 20, Blocks.sandstone);
		world.setBlock(i + 9, j + 2, k + 21, Blocks.sandstone);
		world.setBlock(i + 9, j + 2, k + 22, Blocks.sandstone);
		world.setBlock(i + 9, j + 2, k + 23, Blocks.sandstone);
		world.setBlock(i + 9, j + 2, k + 24, Blocks.sandstone);
		world.setBlock(i + 9, j + 2, k + 25, Blocks.sandstone);
		world.setBlock(i + 9, j + 2, k + 26, Blocks.sandstone);
		world.setBlock(i + 9, j + 2, k + 27, Blocks.sandstone);
		world.setBlock(i + 9, j + 2, k + 28, Blocks.sandstone);
		world.setBlock(i + 9, j + 2, k + 29, Blocks.sandstone);
		world.setBlock(i + 9, j + 2, k + 30, Blocks.sandstone);
		world.setBlock(i + 9, j + 2, k + 31, Blocks.sandstone);
		world.setBlock(i + 9, j + 2, k + 32, Blocks.sandstone);
		world.setBlock(i + 9, j + 2, k + 33, Blocks.sandstone);
		world.setBlock(i + 9, j + 2, k + 34, Blocks.sandstone);
		world.setBlock(i + 9, j + 2, k + 35, Blocks.sandstone);
		world.setBlock(i + 9, j + 2, k + 36, Blocks.sandstone);
		world.setBlock(i + 9, j + 2, k + 37, Blocks.sandstone);
		world.setBlock(i + 9, j + 2, k + 38, Blocks.sandstone);
		world.setBlock(i + 9, j + 2, k + 39, Blocks.sandstone);
		world.setBlock(i + 9, j + 2, k + 40, Blocks.sandstone);
		world.setBlock(i + 9, j + 2, k + 41, Blocks.sandstone);
		world.setBlock(i + 9, j + 2, k + 42, Blocks.sandstone);
		world.setBlock(i + 9, j + 2, k + 43, Blocks.sandstone);
		world.setBlock(i + 9, j + 2, k + 44, Blocks.sandstone);
		world.setBlock(i + 9, j + 2, k + 45, Blocks.sandstone);
		world.setBlock(i + 9, j + 2, k + 46, Blocks.sandstone);
		world.setBlock(i + 9, j + 2, k + 47, Blocks.sandstone);
		world.setBlock(i + 9, j + 2, k + 48, Blocks.sandstone);
		world.setBlock(i + 9, j + 2, k + 49, Blocks.sandstone);
		world.setBlock(i + 9, j + 2, k + 50, Blocks.sandstone);
		world.setBlock(i + 9, j + 2, k + 51, Blocks.sandstone);
		world.setBlock(i + 9, j + 2, k + 52, Blocks.sandstone_stairs, 3, 4);
		world.setBlock(i + 9, j + 3, k + 8, Blocks.sandstone_stairs, 2, 4);
		world.setBlock(i + 9, j + 3, k + 9, Blocks.sandstone);
		world.setBlock(i + 9, j + 3, k + 10, Blocks.sandstone);
		world.setBlock(i + 9, j + 3, k + 11, Blocks.sandstone);
		world.setBlock(i + 9, j + 3, k + 12, Blocks.sandstone);
		world.setBlock(i + 9, j + 3, k + 13, Blocks.sandstone);
		world.setBlock(i + 9, j + 3, k + 14, Blocks.sandstone);
		world.setBlock(i + 9, j + 3, k + 15, Blocks.sandstone);
		world.setBlock(i + 9, j + 3, k + 16, Blocks.sandstone);
		world.setBlock(i + 9, j + 3, k + 17, Blocks.sandstone);
		world.setBlock(i + 9, j + 3, k + 18, Blocks.sandstone);
		world.setBlock(i + 9, j + 3, k + 19, Blocks.sandstone);
		world.setBlock(i + 9, j + 3, k + 20, Blocks.sandstone);
		world.setBlock(i + 9, j + 3, k + 21, Blocks.sandstone);
		world.setBlock(i + 9, j + 3, k + 22, Blocks.sandstone);
		world.setBlock(i + 9, j + 3, k + 23, Blocks.sandstone);
		world.setBlock(i + 9, j + 3, k + 24, Blocks.sandstone);
		world.setBlock(i + 9, j + 3, k + 25, Blocks.sandstone);
		world.setBlock(i + 9, j + 3, k + 26, Blocks.sandstone);
		world.setBlock(i + 9, j + 3, k + 27, Blocks.sandstone);
		world.setBlock(i + 9, j + 3, k + 28, Blocks.sandstone);
		world.setBlock(i + 9, j + 3, k + 29, Blocks.sandstone);
		world.setBlock(i + 9, j + 3, k + 30, Blocks.sandstone);
		world.setBlock(i + 9, j + 3, k + 31, Blocks.sandstone);
		world.setBlock(i + 9, j + 3, k + 32, Blocks.sandstone);
		world.setBlock(i + 9, j + 3, k + 33, Blocks.sandstone);
		world.setBlock(i + 9, j + 3, k + 34, Blocks.sandstone);
		world.setBlock(i + 9, j + 3, k + 35, Blocks.sandstone);
		world.setBlock(i + 9, j + 3, k + 36, Blocks.sandstone);
		world.setBlock(i + 9, j + 3, k + 37, Blocks.sandstone);
		world.setBlock(i + 9, j + 3, k + 38, Blocks.sandstone);
		world.setBlock(i + 9, j + 3, k + 39, Blocks.sandstone);
		world.setBlock(i + 9, j + 3, k + 40, Blocks.sandstone);
		world.setBlock(i + 9, j + 3, k + 41, Blocks.sandstone);
		world.setBlock(i + 9, j + 3, k + 42, Blocks.sandstone);
		world.setBlock(i + 9, j + 3, k + 43, Blocks.sandstone);
		world.setBlock(i + 9, j + 3, k + 44, Blocks.sandstone);
		world.setBlock(i + 9, j + 3, k + 45, Blocks.sandstone);
		world.setBlock(i + 9, j + 3, k + 46, Blocks.sandstone);
		world.setBlock(i + 9, j + 3, k + 47, Blocks.sandstone);
		world.setBlock(i + 9, j + 3, k + 48, Blocks.sandstone);
		world.setBlock(i + 9, j + 3, k + 49, Blocks.sandstone);
		world.setBlock(i + 9, j + 3, k + 50, Blocks.sandstone);
		world.setBlock(i + 9, j + 3, k + 51, Blocks.sandstone_stairs, 3, 4);
		world.setBlock(i + 9, j + 4, k + 9, Blocks.sandstone_stairs);
		world.setBlock(i + 9, j + 4, k + 10, Blocks.sandstone_stairs);
		world.setBlock(i + 9, j + 4, k + 11, Blocks.sandstone_stairs);
		world.setBlock(i + 9, j + 4, k + 12, Blocks.sandstone_stairs);
		world.setBlock(i + 9, j + 4, k + 13, Blocks.sandstone_stairs);
		world.setBlock(i + 9, j + 4, k + 14, Blocks.sandstone_stairs);
		world.setBlock(i + 9, j + 4, k + 15, Blocks.sandstone_stairs);
		world.setBlock(i + 9, j + 4, k + 16, Blocks.sandstone_stairs);
		world.setBlock(i + 9, j + 4, k + 17, Blocks.sandstone_stairs);
		world.setBlock(i + 9, j + 4, k + 18, Blocks.sandstone_stairs);
		world.setBlock(i + 9, j + 4, k + 19, Blocks.sandstone_stairs);
		world.setBlock(i + 9, j + 4, k + 20, Blocks.sandstone_stairs);
		world.setBlock(i + 9, j + 4, k + 21, Blocks.sandstone_stairs);
		world.setBlock(i + 9, j + 4, k + 22, Blocks.sandstone_stairs);
		world.setBlock(i + 9, j + 4, k + 23, Blocks.sandstone_stairs);
		world.setBlock(i + 9, j + 4, k + 24, Blocks.sandstone_stairs);
		world.setBlock(i + 9, j + 4, k + 25, Blocks.sandstone_stairs);
		world.setBlock(i + 9, j + 4, k + 26, Blocks.sandstone_stairs);
		world.setBlock(i + 9, j + 4, k + 27, Blocks.sandstone_stairs);
		world.setBlock(i + 9, j + 4, k + 28, Blocks.sandstone_stairs);
		world.setBlock(i + 9, j + 4, k + 29, Blocks.sandstone);
		world.setBlock(i + 9, j + 4, k + 30, Blocks.sandstone);
		world.setBlock(i + 9, j + 4, k + 31, Blocks.sandstone_stairs);
		world.setBlock(i + 9, j + 4, k + 32, Blocks.sandstone_stairs);
		world.setBlock(i + 9, j + 4, k + 33, Blocks.sandstone_stairs);
		world.setBlock(i + 9, j + 4, k + 34, Blocks.sandstone_stairs);
		world.setBlock(i + 9, j + 4, k + 35, Blocks.sandstone_stairs);
		world.setBlock(i + 9, j + 4, k + 36, Blocks.sandstone_stairs);
		world.setBlock(i + 9, j + 4, k + 37, Blocks.sandstone_stairs);
		world.setBlock(i + 9, j + 4, k + 38, Blocks.sandstone_stairs);
		world.setBlock(i + 9, j + 4, k + 39, Blocks.sandstone_stairs);
		world.setBlock(i + 9, j + 4, k + 40, Blocks.sandstone_stairs);
		world.setBlock(i + 9, j + 4, k + 41, Blocks.sandstone_stairs);
		world.setBlock(i + 9, j + 4, k + 42, Blocks.sandstone_stairs);
		world.setBlock(i + 9, j + 4, k + 43, Blocks.sandstone_stairs);
		world.setBlock(i + 9, j + 4, k + 44, Blocks.sandstone_stairs);
		world.setBlock(i + 9, j + 4, k + 45, Blocks.sandstone_stairs);
		world.setBlock(i + 9, j + 4, k + 46, Blocks.sandstone_stairs);
		world.setBlock(i + 9, j + 4, k + 47, Blocks.sandstone_stairs);
		world.setBlock(i + 9, j + 4, k + 48, Blocks.sandstone_stairs);
		world.setBlock(i + 9, j + 4, k + 49, Blocks.sandstone_stairs);
		world.setBlock(i + 9, j + 4, k + 50, Blocks.sandstone_stairs);
		world.setBlock(i + 9, j + 5, k + 29, Blocks.sandstone);
		world.setBlock(i + 9, j + 5, k + 30, Blocks.sandstone);
		world.setBlock(i + 9, j + 6, k + 29, Blocks.sandstone_stairs);
		world.setBlock(i + 9, j + 6, k + 30, Blocks.sandstone_stairs);
		world.setBlock(i + 10, j + 0, k + 0, Wildycraft.rsSand);
		world.setBlock(i + 10, j + 0, k + 1, Wildycraft.rsSand);
		world.setBlock(i + 10, j + 0, k + 2, Wildycraft.rsSand);
		world.setBlock(i + 10, j + 0, k + 3, Wildycraft.rsSand);
		world.setBlock(i + 10, j + 0, k + 4, Wildycraft.rsSand);
		world.setBlock(i + 10, j + 0, k + 5, Wildycraft.rsSand);
		world.setBlock(i + 10, j + 0, k + 6, Wildycraft.rsSand);
		world.setBlock(i + 10, j + 0, k + 7, Wildycraft.rsSand);
		world.setBlock(i + 10, j + 0, k + 8, Wildycraft.rsSand);
		world.setBlock(i + 10, j + 0, k + 9, Wildycraft.rsSand);
		world.setBlock(i + 10, j + 0, k + 10, Wildycraft.rsSand);
		world.setBlock(i + 10, j + 0, k + 11, Wildycraft.rsSand);
		world.setBlock(i + 10, j + 0, k + 12, Wildycraft.rsSand);
		world.setBlock(i + 10, j + 0, k + 13, Wildycraft.rsSand);
		world.setBlock(i + 10, j + 0, k + 14, Wildycraft.rsSand);
		world.setBlock(i + 10, j + 0, k + 15, Wildycraft.rsSand);
		world.setBlock(i + 10, j + 0, k + 16, Wildycraft.rsSand);
		world.setBlock(i + 10, j + 0, k + 17, Wildycraft.rsSand);
		world.setBlock(i + 10, j + 0, k + 18, Wildycraft.rsSand);
		world.setBlock(i + 10, j + 0, k + 19, Wildycraft.rsSand);
		world.setBlock(i + 10, j + 0, k + 20, Wildycraft.rsSand);
		world.setBlock(i + 10, j + 0, k + 21, Wildycraft.rsSand);
		world.setBlock(i + 10, j + 0, k + 22, Wildycraft.rsSand);
		world.setBlock(i + 10, j + 0, k + 23, Wildycraft.rsSand);
		world.setBlock(i + 10, j + 0, k + 24, Wildycraft.rsSand);
		world.setBlock(i + 10, j + 0, k + 25, Wildycraft.rsSand);
		world.setBlock(i + 10, j + 0, k + 26, Wildycraft.rsSand);
		world.setBlock(i + 10, j + 0, k + 27, Wildycraft.rsSand);
		world.setBlock(i + 10, j + 0, k + 28, Wildycraft.rsSand);
		world.setBlock(i + 10, j + 0, k + 29, Wildycraft.rsSand);
		world.setBlock(i + 10, j + 0, k + 30, Wildycraft.rsSand);
		world.setBlock(i + 10, j + 0, k + 31, Wildycraft.rsSand);
		world.setBlock(i + 10, j + 0, k + 32, Wildycraft.rsSand);
		world.setBlock(i + 10, j + 0, k + 33, Wildycraft.rsSand);
		world.setBlock(i + 10, j + 0, k + 34, Wildycraft.rsSand);
		world.setBlock(i + 10, j + 0, k + 35, Wildycraft.rsSand);
		world.setBlock(i + 10, j + 0, k + 36, Wildycraft.rsSand);
		world.setBlock(i + 10, j + 0, k + 37, Wildycraft.rsSand);
		world.setBlock(i + 10, j + 0, k + 38, Wildycraft.rsSand);
		world.setBlock(i + 10, j + 0, k + 39, Wildycraft.rsSand);
		world.setBlock(i + 10, j + 0, k + 40, Wildycraft.rsSand);
		world.setBlock(i + 10, j + 0, k + 41, Wildycraft.rsSand);
		world.setBlock(i + 10, j + 0, k + 42, Wildycraft.rsSand);
		world.setBlock(i + 10, j + 0, k + 43, Wildycraft.rsSand);
		world.setBlock(i + 10, j + 0, k + 44, Wildycraft.rsSand);
		world.setBlock(i + 10, j + 0, k + 45, Wildycraft.rsSand);
		world.setBlock(i + 10, j + 0, k + 46, Wildycraft.rsSand);
		world.setBlock(i + 10, j + 0, k + 47, Wildycraft.rsSand);
		world.setBlock(i + 10, j + 0, k + 48, Wildycraft.rsSand);
		world.setBlock(i + 10, j + 0, k + 49, Wildycraft.rsSand);
		world.setBlock(i + 10, j + 0, k + 50, Wildycraft.rsSand);
		world.setBlock(i + 10, j + 0, k + 51, Wildycraft.rsSand);
		world.setBlock(i + 10, j + 0, k + 52, Wildycraft.rsSand);
		world.setBlock(i + 10, j + 0, k + 53, Wildycraft.rsSand);
		world.setBlock(i + 10, j + 0, k + 54, Wildycraft.rsSand);
		world.setBlock(i + 10, j + 0, k + 55, Wildycraft.rsSand);
		world.setBlock(i + 10, j + 0, k + 56, Wildycraft.rsSand);
		world.setBlock(i + 10, j + 0, k + 57, Wildycraft.rsSand);
		world.setBlock(i + 10, j + 0, k + 58, Wildycraft.rsSand);
		world.setBlock(i + 10, j + 0, k + 59, Wildycraft.rsSand);
		world.setBlock(i + 10, j + 1, k + 6, Blocks.sandstone_stairs, 2, 4);
		world.setBlock(i + 10, j + 1, k + 7, Blocks.sandstone);
		world.setBlock(i + 10, j + 1, k + 8, Blocks.sandstone);
		world.setBlock(i + 10, j + 1, k + 9, Blocks.sandstone);
		world.setBlock(i + 10, j + 1, k + 10, Blocks.sandstone, 1, 4);
		world.setBlock(i + 10, j + 1, k + 11, Blocks.sandstone, 1, 4);
		world.setBlock(i + 10, j + 1, k + 12, Blocks.sandstone, 1, 4);
		world.setBlock(i + 10, j + 1, k + 13, Blocks.sandstone, 1, 4);
		world.setBlock(i + 10, j + 1, k + 14, Blocks.sandstone, 1, 4);
		world.setBlock(i + 10, j + 1, k + 15, Blocks.sandstone, 1, 4);
		world.setBlock(i + 10, j + 1, k + 16, Blocks.sandstone, 1, 4);
		world.setBlock(i + 10, j + 1, k + 17, Blocks.sandstone, 1, 4);
		world.setBlock(i + 10, j + 1, k + 18, Blocks.sandstone, 1, 4);
		world.setBlock(i + 10, j + 1, k + 19, Blocks.sandstone, 1, 4);
		world.setBlock(i + 10, j + 1, k + 20, Blocks.sandstone, 1, 4);
		world.setBlock(i + 10, j + 1, k + 21, Blocks.sandstone, 1, 4);
		world.setBlock(i + 10, j + 1, k + 22, Blocks.sandstone, 1, 4);
		world.setBlock(i + 10, j + 1, k + 23, Blocks.sandstone, 1, 4);
		world.setBlock(i + 10, j + 1, k + 24, Blocks.sandstone, 1, 4);
		world.setBlock(i + 10, j + 1, k + 25, Blocks.sandstone, 1, 4);
		world.setBlock(i + 10, j + 1, k + 26, Blocks.sandstone, 1, 4);
		world.setBlock(i + 10, j + 1, k + 27, Blocks.sandstone, 1, 4);
		world.setBlock(i + 10, j + 1, k + 28, Blocks.sandstone, 1, 4);
		world.setBlock(i + 10, j + 1, k + 29, Blocks.sandstone, 1, 4);
		world.setBlock(i + 10, j + 1, k + 30, Blocks.sandstone, 1, 4);
		world.setBlock(i + 10, j + 1, k + 31, Blocks.sandstone, 1, 4);
		world.setBlock(i + 10, j + 1, k + 32, Blocks.sandstone, 1, 4);
		world.setBlock(i + 10, j + 1, k + 33, Blocks.sandstone, 1, 4);
		world.setBlock(i + 10, j + 1, k + 34, Blocks.sandstone, 1, 4);
		world.setBlock(i + 10, j + 1, k + 35, Blocks.sandstone, 1, 4);
		world.setBlock(i + 10, j + 1, k + 36, Blocks.sandstone, 1, 4);
		world.setBlock(i + 10, j + 1, k + 37, Blocks.sandstone, 1, 4);
		world.setBlock(i + 10, j + 1, k + 38, Blocks.sandstone, 1, 4);
		world.setBlock(i + 10, j + 1, k + 39, Blocks.sandstone, 1, 4);
		world.setBlock(i + 10, j + 1, k + 40, Blocks.sandstone, 1, 4);
		world.setBlock(i + 10, j + 1, k + 41, Blocks.sandstone, 1, 4);
		world.setBlock(i + 10, j + 1, k + 42, Blocks.sandstone, 1, 4);
		world.setBlock(i + 10, j + 1, k + 43, Blocks.sandstone, 1, 4);
		world.setBlock(i + 10, j + 1, k + 44, Blocks.sandstone, 1, 4);
		world.setBlock(i + 10, j + 1, k + 45, Blocks.sandstone, 1, 4);
		world.setBlock(i + 10, j + 1, k + 46, Blocks.sandstone, 1, 4);
		world.setBlock(i + 10, j + 1, k + 47, Blocks.sandstone, 1, 4);
		world.setBlock(i + 10, j + 1, k + 48, Blocks.sandstone, 1, 4);
		world.setBlock(i + 10, j + 1, k + 49, Blocks.sandstone);
		world.setBlock(i + 10, j + 1, k + 50, Blocks.sandstone);
		world.setBlock(i + 10, j + 1, k + 51, Blocks.sandstone);
		world.setBlock(i + 10, j + 1, k + 52, Blocks.sandstone);
		world.setBlock(i + 10, j + 1, k + 53, Blocks.sandstone_stairs, 3, 4);
		world.setBlock(i + 10, j + 2, k + 7, Blocks.sandstone_stairs, 2, 4);
		world.setBlock(i + 10, j + 2, k + 8, Blocks.sandstone);
		world.setBlock(i + 10, j + 2, k + 9, Blocks.sandstone);
		world.setBlock(i + 10, j + 2, k + 10, Blocks.sandstone);
		world.setBlock(i + 10, j + 2, k + 11, Blocks.sandstone);
		world.setBlock(i + 10, j + 2, k + 12, Blocks.sandstone);
		world.setBlock(i + 10, j + 2, k + 13, Blocks.sandstone);
		world.setBlock(i + 10, j + 2, k + 14, Blocks.sandstone);
		world.setBlock(i + 10, j + 2, k + 15, Blocks.sandstone);
		world.setBlock(i + 10, j + 2, k + 16, Blocks.sandstone);
		world.setBlock(i + 10, j + 2, k + 17, Blocks.sandstone);
		world.setBlock(i + 10, j + 2, k + 18, Blocks.sandstone);
		world.setBlock(i + 10, j + 2, k + 19, Blocks.sandstone);
		world.setBlock(i + 10, j + 2, k + 20, Blocks.sandstone);
		world.setBlock(i + 10, j + 2, k + 21, Blocks.sandstone);
		world.setBlock(i + 10, j + 2, k + 22, Blocks.sandstone);
		world.setBlock(i + 10, j + 2, k + 23, Blocks.sandstone);
		world.setBlock(i + 10, j + 2, k + 24, Blocks.sandstone);
		world.setBlock(i + 10, j + 2, k + 25, Blocks.sandstone);
		world.setBlock(i + 10, j + 2, k + 26, Blocks.sandstone);
		world.setBlock(i + 10, j + 2, k + 27, Blocks.sandstone);
		world.setBlock(i + 10, j + 2, k + 28, Blocks.sandstone);
		world.setBlock(i + 10, j + 2, k + 29, Blocks.sandstone);
		world.setBlock(i + 10, j + 2, k + 30, Blocks.sandstone);
		world.setBlock(i + 10, j + 2, k + 31, Blocks.sandstone);
		world.setBlock(i + 10, j + 2, k + 32, Blocks.sandstone);
		world.setBlock(i + 10, j + 2, k + 33, Blocks.sandstone);
		world.setBlock(i + 10, j + 2, k + 34, Blocks.sandstone);
		world.setBlock(i + 10, j + 2, k + 35, Blocks.sandstone);
		world.setBlock(i + 10, j + 2, k + 36, Blocks.sandstone);
		world.setBlock(i + 10, j + 2, k + 37, Blocks.sandstone);
		world.setBlock(i + 10, j + 2, k + 38, Blocks.sandstone);
		world.setBlock(i + 10, j + 2, k + 39, Blocks.sandstone);
		world.setBlock(i + 10, j + 2, k + 40, Blocks.sandstone);
		world.setBlock(i + 10, j + 2, k + 41, Blocks.sandstone);
		world.setBlock(i + 10, j + 2, k + 42, Blocks.sandstone);
		world.setBlock(i + 10, j + 2, k + 43, Blocks.sandstone);
		world.setBlock(i + 10, j + 2, k + 44, Blocks.sandstone);
		world.setBlock(i + 10, j + 2, k + 45, Blocks.sandstone);
		world.setBlock(i + 10, j + 2, k + 46, Blocks.sandstone);
		world.setBlock(i + 10, j + 2, k + 47, Blocks.sandstone);
		world.setBlock(i + 10, j + 2, k + 48, Blocks.sandstone);
		world.setBlock(i + 10, j + 2, k + 49, Blocks.sandstone);
		world.setBlock(i + 10, j + 2, k + 50, Blocks.sandstone);
		world.setBlock(i + 10, j + 2, k + 51, Blocks.sandstone);

		generate2(world, rand, i, j, k);
		return true;
	}

	public boolean generate2(World world, Random rand, int i, int j, int k) {
		world.setBlock(i + 10, j + 2, k + 52, Blocks.sandstone_stairs, 3, 4);
		world.setBlock(i + 10, j + 3, k + 8, Blocks.sandstone_stairs, 2, 4);
		world.setBlock(i + 10, j + 3, k + 9, Blocks.sandstone);
		world.setBlock(i + 10, j + 3, k + 10, Blocks.sandstone);
		world.setBlock(i + 10, j + 3, k + 11, Blocks.sandstone);
		world.setBlock(i + 10, j + 3, k + 12, Blocks.sandstone);
		world.setBlock(i + 10, j + 3, k + 13, Blocks.sandstone);
		world.setBlock(i + 10, j + 3, k + 14, Blocks.sandstone);
		world.setBlock(i + 10, j + 3, k + 15, Blocks.sandstone);
		world.setBlock(i + 10, j + 3, k + 16, Blocks.sandstone);
		world.setBlock(i + 10, j + 3, k + 17, Blocks.sandstone);
		world.setBlock(i + 10, j + 3, k + 18, Blocks.sandstone);
		world.setBlock(i + 10, j + 3, k + 19, Blocks.sandstone);
		world.setBlock(i + 10, j + 3, k + 20, Blocks.sandstone);
		world.setBlock(i + 10, j + 3, k + 21, Blocks.sandstone);
		world.setBlock(i + 10, j + 3, k + 22, Blocks.sandstone);
		world.setBlock(i + 10, j + 3, k + 23, Blocks.sandstone);
		world.setBlock(i + 10, j + 3, k + 24, Blocks.sandstone);
		world.setBlock(i + 10, j + 3, k + 25, Blocks.sandstone);
		world.setBlock(i + 10, j + 3, k + 26, Blocks.sandstone);
		world.setBlock(i + 10, j + 3, k + 27, Blocks.sandstone);
		world.setBlock(i + 10, j + 3, k + 28, Blocks.sandstone);
		world.setBlock(i + 10, j + 3, k + 29, Blocks.sandstone);
		world.setBlock(i + 10, j + 3, k + 30, Blocks.sandstone);
		world.setBlock(i + 10, j + 3, k + 31, Blocks.sandstone);
		world.setBlock(i + 10, j + 3, k + 32, Blocks.sandstone);
		world.setBlock(i + 10, j + 3, k + 33, Blocks.sandstone);
		world.setBlock(i + 10, j + 3, k + 34, Blocks.sandstone);
		world.setBlock(i + 10, j + 3, k + 35, Blocks.sandstone);
		world.setBlock(i + 10, j + 3, k + 36, Blocks.sandstone);
		world.setBlock(i + 10, j + 3, k + 37, Blocks.sandstone);
		world.setBlock(i + 10, j + 3, k + 38, Blocks.sandstone);
		world.setBlock(i + 10, j + 3, k + 39, Blocks.sandstone);
		world.setBlock(i + 10, j + 3, k + 40, Blocks.sandstone);
		world.setBlock(i + 10, j + 3, k + 41, Blocks.sandstone);
		world.setBlock(i + 10, j + 3, k + 42, Blocks.sandstone);
		world.setBlock(i + 10, j + 3, k + 43, Blocks.sandstone);
		world.setBlock(i + 10, j + 3, k + 44, Blocks.sandstone);
		world.setBlock(i + 10, j + 3, k + 45, Blocks.sandstone);
		world.setBlock(i + 10, j + 3, k + 46, Blocks.sandstone);
		world.setBlock(i + 10, j + 3, k + 47, Blocks.sandstone);
		world.setBlock(i + 10, j + 3, k + 48, Blocks.sandstone);
		world.setBlock(i + 10, j + 3, k + 49, Blocks.sandstone);
		world.setBlock(i + 10, j + 3, k + 50, Blocks.sandstone);
		world.setBlock(i + 10, j + 3, k + 51, Blocks.sandstone_stairs, 3, 4);
		world.setBlock(i + 10, j + 4, k + 9, Blocks.sandstone_stairs, 2, 4);
		world.setBlock(i + 10, j + 4, k + 10, Blocks.sandstone);
		world.setBlock(i + 10, j + 4, k + 11, Blocks.sandstone);
		world.setBlock(i + 10, j + 4, k + 12, Blocks.sandstone);
		world.setBlock(i + 10, j + 4, k + 13, Blocks.sandstone);
		world.setBlock(i + 10, j + 4, k + 14, Blocks.sandstone);
		world.setBlock(i + 10, j + 4, k + 15, Blocks.sandstone);
		world.setBlock(i + 10, j + 4, k + 16, Blocks.sandstone);
		world.setBlock(i + 10, j + 4, k + 17, Blocks.sandstone);
		world.setBlock(i + 10, j + 4, k + 18, Blocks.sandstone);
		world.setBlock(i + 10, j + 4, k + 19, Blocks.sandstone);
		world.setBlock(i + 10, j + 4, k + 20, Blocks.sandstone);
		world.setBlock(i + 10, j + 4, k + 21, Blocks.sandstone);
		world.setBlock(i + 10, j + 4, k + 22, Blocks.sandstone);
		world.setBlock(i + 10, j + 4, k + 23, Blocks.sandstone);
		world.setBlock(i + 10, j + 4, k + 24, Blocks.sandstone);
		world.setBlock(i + 10, j + 4, k + 25, Blocks.sandstone);
		world.setBlock(i + 10, j + 4, k + 26, Blocks.sandstone);
		world.setBlock(i + 10, j + 4, k + 27, Blocks.sandstone);
		world.setBlock(i + 10, j + 4, k + 28, Blocks.sandstone);
		world.setBlock(i + 10, j + 4, k + 29, Blocks.sandstone);
		world.setBlock(i + 10, j + 4, k + 30, Blocks.sandstone);
		world.setBlock(i + 10, j + 4, k + 31, Blocks.sandstone);
		world.setBlock(i + 10, j + 4, k + 32, Blocks.sandstone);
		world.setBlock(i + 10, j + 4, k + 33, Blocks.sandstone);
		world.setBlock(i + 10, j + 4, k + 34, Blocks.sandstone);
		world.setBlock(i + 10, j + 4, k + 35, Blocks.sandstone);
		world.setBlock(i + 10, j + 4, k + 36, Blocks.sandstone);
		world.setBlock(i + 10, j + 4, k + 37, Blocks.sandstone);
		world.setBlock(i + 10, j + 4, k + 38, Blocks.sandstone);
		world.setBlock(i + 10, j + 4, k + 39, Blocks.sandstone);
		world.setBlock(i + 10, j + 4, k + 40, Blocks.sandstone);
		world.setBlock(i + 10, j + 4, k + 41, Blocks.sandstone);
		world.setBlock(i + 10, j + 4, k + 42, Blocks.sandstone);
		world.setBlock(i + 10, j + 4, k + 43, Blocks.sandstone);
		world.setBlock(i + 10, j + 4, k + 44, Blocks.sandstone);
		world.setBlock(i + 10, j + 4, k + 45, Blocks.sandstone);
		world.setBlock(i + 10, j + 4, k + 46, Blocks.sandstone);
		world.setBlock(i + 10, j + 4, k + 47, Blocks.sandstone);
		world.setBlock(i + 10, j + 4, k + 48, Blocks.sandstone);
		world.setBlock(i + 10, j + 4, k + 49, Blocks.sandstone);
		world.setBlock(i + 10, j + 4, k + 50, Blocks.sandstone_stairs, 3, 4);
		world.setBlock(i + 10, j + 5, k + 10, Blocks.sandstone_stairs);
		world.setBlock(i + 10, j + 5, k + 11, Blocks.sandstone_stairs);
		world.setBlock(i + 10, j + 5, k + 12, Blocks.sandstone_stairs);
		world.setBlock(i + 10, j + 5, k + 13, Blocks.sandstone_stairs);
		world.setBlock(i + 10, j + 5, k + 14, Blocks.sandstone_stairs);
		world.setBlock(i + 10, j + 5, k + 15, Blocks.sandstone_stairs);
		world.setBlock(i + 10, j + 5, k + 16, Blocks.sandstone_stairs);
		world.setBlock(i + 10, j + 5, k + 17, Blocks.sandstone_stairs);
		world.setBlock(i + 10, j + 5, k + 18, Blocks.sandstone_stairs);
		world.setBlock(i + 10, j + 5, k + 19, Blocks.sandstone_stairs);
		world.setBlock(i + 10, j + 5, k + 20, Blocks.sandstone_stairs);
		world.setBlock(i + 10, j + 5, k + 21, Blocks.sandstone_stairs);
		world.setBlock(i + 10, j + 5, k + 22, Blocks.sandstone_stairs);
		world.setBlock(i + 10, j + 5, k + 23, Blocks.sandstone_stairs);
		world.setBlock(i + 10, j + 5, k + 24, Blocks.sandstone_stairs);
		world.setBlock(i + 10, j + 5, k + 25, Blocks.sandstone_stairs);
		world.setBlock(i + 10, j + 5, k + 26, Blocks.sandstone_stairs);
		world.setBlock(i + 10, j + 5, k + 27, Blocks.sandstone_stairs);
		world.setBlock(i + 10, j + 5, k + 28, Blocks.sandstone_stairs);
		world.setBlock(i + 10, j + 5, k + 29, Blocks.sandstone);
		world.setBlock(i + 10, j + 5, k + 30, Blocks.sandstone);
		world.setBlock(i + 10, j + 5, k + 31, Blocks.sandstone_stairs);
		world.setBlock(i + 10, j + 5, k + 32, Blocks.sandstone_stairs);
		world.setBlock(i + 10, j + 5, k + 33, Blocks.sandstone_stairs);
		world.setBlock(i + 10, j + 5, k + 34, Blocks.sandstone_stairs);
		world.setBlock(i + 10, j + 5, k + 35, Blocks.sandstone_stairs);
		world.setBlock(i + 10, j + 5, k + 36, Blocks.sandstone_stairs);
		world.setBlock(i + 10, j + 5, k + 37, Blocks.sandstone_stairs);
		world.setBlock(i + 10, j + 5, k + 38, Blocks.sandstone_stairs);
		world.setBlock(i + 10, j + 5, k + 39, Blocks.sandstone_stairs);
		world.setBlock(i + 10, j + 5, k + 40, Blocks.sandstone_stairs);
		world.setBlock(i + 10, j + 5, k + 41, Blocks.sandstone_stairs);
		world.setBlock(i + 10, j + 5, k + 42, Blocks.sandstone_stairs);
		world.setBlock(i + 10, j + 5, k + 43, Blocks.sandstone_stairs);
		world.setBlock(i + 10, j + 5, k + 44, Blocks.sandstone_stairs);
		world.setBlock(i + 10, j + 5, k + 45, Blocks.sandstone_stairs);
		world.setBlock(i + 10, j + 5, k + 46, Blocks.sandstone_stairs);
		world.setBlock(i + 10, j + 5, k + 47, Blocks.sandstone_stairs);
		world.setBlock(i + 10, j + 5, k + 48, Blocks.sandstone_stairs);
		world.setBlock(i + 10, j + 5, k + 49, Blocks.sandstone_stairs);
		world.setBlock(i + 10, j + 6, k + 29, Blocks.sandstone);
		world.setBlock(i + 10, j + 6, k + 30, Blocks.sandstone);
		world.setBlock(i + 10, j + 7, k + 29, Blocks.sandstone_stairs);
		world.setBlock(i + 10, j + 7, k + 30, Blocks.sandstone_stairs);
		world.setBlock(i + 11, j + 0, k + 0, Wildycraft.rsSand);
		world.setBlock(i + 11, j + 0, k + 1, Wildycraft.rsSand);
		world.setBlock(i + 11, j + 0, k + 2, Wildycraft.rsSand);
