package wildycraft.structures;
import java.util.Random;

import net.minecraft.init.Blocks;
import net.minecraft.nbt.NBTTagCompound;
import net.minecraft.tileentity.TileEntityMobSpawner;
import net.minecraft.world.World;
import net.minecraft.world.gen.feature.WorldGenerator;

public class SlayerTower extends WorldGenerator
{
	public SlayerTower() { }

	public boolean generate(World world, Random rand, int i, int j, int k) {

		world.setBlock(i + 0, j + 0, k + 5, Blocks.stonebrick);
		world.setBlock(i + 0, j + 0, k + 6, Blocks.stonebrick);
		world.setBlock(i + 0, j + 0, k + 7, Blocks.stonebrick);
		world.setBlock(i + 0, j + 0, k + 8, Blocks.stonebrick);
		world.setBlock(i + 0, j + 0, k + 37, Blocks.stonebrick);
		world.setBlock(i + 0, j + 0, k + 38, Blocks.stonebrick);
		world.setBlock(i + 0, j + 0, k + 39, Blocks.stonebrick);
		world.setBlock(i + 0, j + 0, k + 40, Blocks.stonebrick);
		world.setBlock(i + 0, j + 1, k + 5, Blocks.stonebrick);
		world.setBlock(i + 0, j + 1, k + 6, Blocks.stonebrick);
		world.setBlock(i + 0, j + 1, k + 7, Blocks.stonebrick);
		world.setBlock(i + 0, j + 1, k + 8, Blocks.stonebrick);
		world.setBlock(i + 0, j + 1, k + 37, Blocks.stonebrick);
		world.setBlock(i + 0, j + 1, k + 38, Blocks.stonebrick);
		world.setBlock(i + 0, j + 1, k + 39, Blocks.stonebrick);
		world.setBlock(i + 0, j + 1, k + 40, Blocks.stonebrick);
		world.setBlock(i + 0, j + 2, k + 5, Blocks.stonebrick);
		world.setBlock(i + 0, j + 2, k + 6, Blocks.glass_pane);
		world.setBlock(i + 0, j + 2, k + 7, Blocks.stonebrick);
		world.setBlock(i + 0, j + 2, k + 8, Blocks.stonebrick);
		world.setBlock(i + 0, j + 2, k + 37, Blocks.stonebrick);
		world.setBlock(i + 0, j + 2, k + 38, Blocks.stonebrick);
		world.setBlock(i + 0, j + 2, k + 39, Blocks.glass_pane);
		world.setBlock(i + 0, j + 2, k + 40, Blocks.stonebrick);
		world.setBlock(i + 0, j + 3, k + 5, Blocks.stonebrick);
		world.setBlock(i + 0, j + 3, k + 6, Blocks.glass_pane);
		world.setBlock(i + 0, j + 3, k + 7, Blocks.stonebrick);
		world.setBlock(i + 0, j + 3, k + 8, Blocks.stonebrick);
		world.setBlock(i + 0, j + 3, k + 37, Blocks.stonebrick);
		world.setBlock(i + 0, j + 3, k + 38, Blocks.stonebrick);
		world.setBlock(i + 0, j + 3, k + 39, Blocks.glass_pane);
		world.setBlock(i + 0, j + 3, k + 40, Blocks.stonebrick);
		world.setBlock(i + 0, j + 4, k + 5, Blocks.stonebrick);
		world.setBlock(i + 0, j + 4, k + 6, Blocks.stonebrick);
		world.setBlock(i + 0, j + 4, k + 7, Blocks.stonebrick);
		world.setBlock(i + 0, j + 4, k + 8, Blocks.stonebrick);
		world.setBlock(i + 0, j + 4, k + 37, Blocks.stonebrick);
		world.setBlock(i + 0, j + 4, k + 38, Blocks.stonebrick);
		world.setBlock(i + 0, j + 4, k + 39, Blocks.stonebrick);
		world.setBlock(i + 0, j + 4, k + 40, Blocks.stonebrick);
		world.setBlock(i + 0, j + 5, k + 5, Blocks.stonebrick);
		world.setBlock(i + 0, j + 5, k + 6, Blocks.stonebrick);
		world.setBlock(i + 0, j + 5, k + 7, Blocks.stonebrick);
		world.setBlock(i + 0, j + 5, k + 8, Blocks.stonebrick);
		world.setBlock(i + 0, j + 5, k + 37, Blocks.stonebrick);
		world.setBlock(i + 0, j + 5, k + 38, Blocks.stonebrick);
		world.setBlock(i + 0, j + 5, k + 39, Blocks.stonebrick);
		world.setBlock(i + 0, j + 5, k + 40, Blocks.stonebrick);
		world.setBlock(i + 0, j + 6, k + 5, Blocks.stonebrick);
		world.setBlock(i + 0, j + 6, k + 6, Blocks.stonebrick);
		world.setBlock(i + 0, j + 6, k + 7, Blocks.stonebrick);
		world.setBlock(i + 0, j + 6, k + 8, Blocks.stonebrick);
		world.setBlock(i + 0, j + 6, k + 37, Blocks.stonebrick);
		world.setBlock(i + 0, j + 6, k + 38, Blocks.stonebrick);
		world.setBlock(i + 0, j + 6, k + 39, Blocks.stonebrick);
		world.setBlock(i + 0, j + 6, k + 40, Blocks.stonebrick);
		world.setBlock(i + 0, j + 7, k + 5, Blocks.stonebrick);
		world.setBlock(i + 0, j + 7, k + 6, Blocks.glass_pane);
		world.setBlock(i + 0, j + 7, k + 7, Blocks.stonebrick);
		world.setBlock(i + 0, j + 7, k + 8, Blocks.stonebrick);
		world.setBlock(i + 0, j + 7, k + 37, Blocks.stonebrick);
		world.setBlock(i + 0, j + 7, k + 38, Blocks.stonebrick);
		world.setBlock(i + 0, j + 7, k + 39, Blocks.glass_pane);
		world.setBlock(i + 0, j + 7, k + 40, Blocks.stonebrick);
		world.setBlock(i + 0, j + 8, k + 5, Blocks.stonebrick);
		world.setBlock(i + 0, j + 8, k + 6, Blocks.glass_pane);
		world.setBlock(i + 0, j + 8, k + 7, Blocks.stonebrick);
		world.setBlock(i + 0, j + 8, k + 8, Blocks.stonebrick);
		world.setBlock(i + 0, j + 8, k + 37, Blocks.stonebrick);
		world.setBlock(i + 0, j + 8, k + 38, Blocks.stonebrick);
		world.setBlock(i + 0, j + 8, k + 39, Blocks.glass_pane);
		world.setBlock(i + 0, j + 8, k + 40, Blocks.stonebrick);
		world.setBlock(i + 0, j + 9, k + 5, Blocks.stonebrick);
		world.setBlock(i + 0, j + 9, k + 6, Blocks.stonebrick);
		world.setBlock(i + 0, j + 9, k + 7, Blocks.stonebrick);
		world.setBlock(i + 0, j + 9, k + 8, Blocks.stonebrick);
		world.setBlock(i + 0, j + 9, k + 37, Blocks.stonebrick);
		world.setBlock(i + 0, j + 9, k + 38, Blocks.stonebrick);
		world.setBlock(i + 0, j + 9, k + 39, Blocks.stonebrick);
		world.setBlock(i + 0, j + 9, k + 40, Blocks.stonebrick);
		world.setBlock(i + 0, j + 10, k + 5, Blocks.stonebrick);
		world.setBlock(i + 0, j + 10, k + 6, Blocks.stonebrick);
		world.setBlock(i + 0, j + 10, k + 7, Blocks.stonebrick);
		world.setBlock(i + 0, j + 10, k + 8, Blocks.stonebrick);
		world.setBlock(i + 0, j + 10, k + 37, Blocks.stonebrick);
		world.setBlock(i + 0, j + 10, k + 38, Blocks.stonebrick);
		world.setBlock(i + 0, j + 10, k + 39, Blocks.stonebrick);
		world.setBlock(i + 0, j + 10, k + 40, Blocks.stonebrick);
		world.setBlock(i + 0, j + 11, k + 5, Blocks.stonebrick);
		world.setBlock(i + 0, j + 11, k + 6, Blocks.stonebrick);
		world.setBlock(i + 0, j + 11, k + 7, Blocks.stonebrick);
		world.setBlock(i + 0, j + 11, k + 8, Blocks.stonebrick);
		world.setBlock(i + 0, j + 11, k + 37, Blocks.stonebrick);
		world.setBlock(i + 0, j + 11, k + 38, Blocks.stonebrick);
		world.setBlock(i + 0, j + 11, k + 39, Blocks.stonebrick);
		world.setBlock(i + 0, j + 11, k + 40, Blocks.stonebrick);
		world.setBlock(i + 0, j + 12, k + 5, Blocks.stonebrick);
		world.setBlock(i + 0, j + 12, k + 6, Blocks.glass_pane);
		world.setBlock(i + 0, j + 12, k + 7, Blocks.stonebrick);
		world.setBlock(i + 0, j + 12, k + 8, Blocks.stonebrick);
		world.setBlock(i + 0, j + 12, k + 37, Blocks.stonebrick);
		world.setBlock(i + 0, j + 12, k + 38, Blocks.stonebrick);
		world.setBlock(i + 0, j + 12, k + 39, Blocks.glass_pane);
		world.setBlock(i + 0, j + 12, k + 40, Blocks.stonebrick);
		world.setBlock(i + 0, j + 13, k + 5, Blocks.stonebrick);
		world.setBlock(i + 0, j + 13, k + 6, Blocks.glass_pane);
		world.setBlock(i + 0, j + 13, k + 7, Blocks.stonebrick);
		world.setBlock(i + 0, j + 13, k + 8, Blocks.stonebrick);
		world.setBlock(i + 0, j + 13, k + 37, Blocks.stonebrick);
		world.setBlock(i + 0, j + 13, k + 38, Blocks.stonebrick);
		world.setBlock(i + 0, j + 13, k + 39, Blocks.glass_pane);
		world.setBlock(i + 0, j + 13, k + 40, Blocks.stonebrick);
		world.setBlock(i + 0, j + 14, k + 5, Blocks.stonebrick);
		world.setBlock(i + 0, j + 14, k + 6, Blocks.stonebrick);
		world.setBlock(i + 0, j + 14, k + 7, Blocks.stonebrick);
		world.setBlock(i + 0, j + 14, k + 8, Blocks.stonebrick);
		world.setBlock(i + 0, j + 14, k + 37, Blocks.stonebrick);
		world.setBlock(i + 0, j + 14, k + 38, Blocks.stonebrick);
		world.setBlock(i + 0, j + 14, k + 39, Blocks.stonebrick);
		world.setBlock(i + 0, j + 14, k + 40, Blocks.stonebrick);
		world.setBlock(i + 0, j + 15, k + 5, Blocks.stonebrick);
		world.setBlock(i + 0, j + 15, k + 6, Blocks.stonebrick);
		world.setBlock(i + 0, j + 15, k + 7, Blocks.stonebrick);
		world.setBlock(i + 0, j + 15, k + 8, Blocks.stonebrick);
		world.setBlock(i + 0, j + 15, k + 37, Blocks.stonebrick);
		world.setBlock(i + 0, j + 15, k + 38, Blocks.stonebrick);
		world.setBlock(i + 0, j + 15, k + 39, Blocks.stonebrick);
		world.setBlock(i + 0, j + 15, k + 40, Blocks.stonebrick);
		world.setBlock(i + 0, j + 16, k + 5, Blocks.stonebrick);
		world.setBlock(i + 0, j + 16, k + 6, Blocks.stonebrick);
		world.setBlock(i + 0, j + 16, k + 7, Blocks.stonebrick);
		world.setBlock(i + 0, j + 16, k + 8, Blocks.stonebrick);
		world.setBlock(i + 0, j + 16, k + 37, Blocks.stonebrick);
		world.setBlock(i + 0, j + 16, k + 38, Blocks.stonebrick);
		world.setBlock(i + 0, j + 16, k + 39, Blocks.stonebrick);
		world.setBlock(i + 0, j + 16, k + 40, Blocks.stonebrick);
		world.setBlock(i + 1, j + 0, k + 4, Blocks.stonebrick);
		world.setBlock(i + 1, j + 0, k + 5, Blocks.stonebrick);
		world.setBlock(i + 1, j + 0, k + 6, Blocks.stonebrick);
		world.setBlock(i + 1, j + 0, k + 7, Blocks.stonebrick);
		world.setBlock(i + 1, j + 0, k + 8, Blocks.stonebrick);
		world.setBlock(i + 1, j + 0, k + 9, Blocks.stonebrick);
		world.setBlock(i + 1, j + 0, k + 36, Blocks.stonebrick);
		world.setBlock(i + 1, j + 0, k + 37, Blocks.stonebrick);
		world.setBlock(i + 1, j + 0, k + 38, Blocks.stonebrick);
		world.setBlock(i + 1, j + 0, k + 39, Blocks.stonebrick);
		world.setBlock(i + 1, j + 0, k + 40, Blocks.stonebrick);
		world.setBlock(i + 1, j + 0, k + 41, Blocks.stonebrick);
		world.setBlock(i + 1, j + 1, k + 4, Blocks.stonebrick);
		world.setBlock(i + 1, j + 1, k + 7, Blocks.crafting_table);
		world.setBlock(i + 1, j + 1, k + 9, Blocks.stonebrick);
		world.setBlock(i + 1, j + 1, k + 36, Blocks.stonebrick);
		world.setBlock(i + 1, j + 1, k + 41, Blocks.stonebrick);
		world.setBlock(i + 1, j + 2, k + 4, Blocks.stonebrick);
		world.setBlock(i + 1, j + 2, k + 9, Blocks.stonebrick);
		world.setBlock(i + 1, j + 2, k + 36, Blocks.stonebrick);
		world.setBlock(i + 1, j + 2, k + 41, Blocks.stonebrick);
		world.setBlock(i + 1, j + 3, k + 4, Blocks.stonebrick);
		world.setBlock(i + 1, j + 3, k + 9, Blocks.stonebrick);
		world.setBlock(i + 1, j + 3, k + 36, Blocks.stonebrick);
		world.setBlock(i + 1, j + 3, k + 41, Blocks.stonebrick);
		world.setBlock(i + 1, j + 4, k + 4, Blocks.stonebrick);
		world.setBlock(i + 1, j + 4, k + 9, Blocks.stonebrick);
		world.setBlock(i + 1, j + 4, k + 36, Blocks.stonebrick);
		world.setBlock(i + 1, j + 4, k + 41, Blocks.stonebrick);
		world.setBlock(i + 1, j + 5, k + 4, Blocks.stonebrick);
		world.setBlock(i + 1, j + 5, k + 5, Blocks.stonebrick);
		world.setBlock(i + 1, j + 5, k + 6, Blocks.stonebrick);
		world.setBlock(i + 1, j + 5, k + 7, Blocks.stonebrick);
		world.setBlock(i + 1, j + 5, k + 8, Blocks.stonebrick);
		world.setBlock(i + 1, j + 5, k + 9, Blocks.stonebrick);
		world.setBlock(i + 1, j + 5, k + 36, Blocks.stonebrick);
		world.setBlock(i + 1, j + 5, k + 37, Blocks.stonebrick);
		world.setBlock(i + 1, j + 5, k + 38, Blocks.stonebrick);
		world.setBlock(i + 1, j + 5, k + 39, Blocks.stonebrick);
		world.setBlock(i + 1, j + 5, k + 40, Blocks.stonebrick);
		world.setBlock(i + 1, j + 5, k + 41, Blocks.stonebrick);
		world.setBlock(i + 1, j + 6, k + 4, Blocks.stonebrick);
		world.setBlock(i + 1, j + 6, k + 9, Blocks.stonebrick);
		world.setBlock(i + 1, j + 6, k + 36, Blocks.stonebrick);
		world.setBlock(i + 1, j + 6, k + 41, Blocks.stonebrick);
		world.setBlock(i + 1, j + 7, k + 4, Blocks.stonebrick);
		world.setBlock(i + 1, j + 7, k + 9, Blocks.stonebrick);
		world.setBlock(i + 1, j + 7, k + 36, Blocks.stonebrick);
		world.setBlock(i + 1, j + 7, k + 41, Blocks.stonebrick);
		world.setBlock(i + 1, j + 8, k + 4, Blocks.stonebrick);
		world.setBlock(i + 1, j + 8, k + 9, Blocks.stonebrick);
		world.setBlock(i + 1, j + 8, k + 36, Blocks.stonebrick);
		world.setBlock(i + 1, j + 8, k + 41, Blocks.stonebrick);
		world.setBlock(i + 1, j + 9, k + 4, Blocks.stonebrick);
		world.setBlock(i + 1, j + 9, k + 9, Blocks.stonebrick);
		world.setBlock(i + 1, j + 9, k + 36, Blocks.stonebrick);
		world.setBlock(i + 1, j + 9, k + 41, Blocks.stonebrick);
		world.setBlock(i + 1, j + 10, k + 4, Blocks.stonebrick);
		world.setBlock(i + 1, j + 10, k + 5, Blocks.stonebrick);
		world.setBlock(i + 1, j + 10, k + 6, Blocks.stonebrick);
		world.setBlock(i + 1, j + 10, k + 7, Blocks.stonebrick);
		world.setBlock(i + 1, j + 10, k + 8, Blocks.stonebrick);
		world.setBlock(i + 1, j + 10, k + 9, Blocks.stonebrick);
		world.setBlock(i + 1, j + 10, k + 36, Blocks.stonebrick);
		world.setBlock(i + 1, j + 10, k + 37, Blocks.stonebrick);
		world.setBlock(i + 1, j + 10, k + 38, Blocks.stonebrick);
		world.setBlock(i + 1, j + 10, k + 39, Blocks.stonebrick);
		world.setBlock(i + 1, j + 10, k + 40, Blocks.stonebrick);
		world.setBlock(i + 1, j + 10, k + 41, Blocks.stonebrick);
		world.setBlock(i + 1, j + 11, k + 4, Blocks.stonebrick);
		world.setBlock(i + 1, j + 11, k + 9, Blocks.stonebrick);
		world.setBlock(i + 1, j + 11, k + 36, Blocks.stonebrick);
		world.setBlock(i + 1, j + 11, k + 37, Blocks.stonebrick);
		world.setBlock(i + 1, j + 11, k + 41, Blocks.stonebrick);
		world.setBlock(i + 1, j + 12, k + 4, Blocks.stonebrick);
		world.setBlock(i + 1, j + 12, k + 9, Blocks.stonebrick);
		world.setBlock(i + 1, j + 12, k + 36, Blocks.stonebrick);
		world.setBlock(i + 1, j + 12, k + 41, Blocks.stonebrick);
		world.setBlock(i + 1, j + 13, k + 4, Blocks.stonebrick);
		world.setBlock(i + 1, j + 13, k + 9, Blocks.stonebrick);
		world.setBlock(i + 1, j + 13, k + 36, Blocks.stonebrick);
		world.setBlock(i + 1, j + 13, k + 41, Blocks.stonebrick);
		world.setBlock(i + 1, j + 14, k + 4, Blocks.stonebrick);
		world.setBlock(i + 1, j + 14, k + 9, Blocks.stonebrick);
		world.setBlock(i + 1, j + 14, k + 36, Blocks.stonebrick);
		world.setBlock(i + 1, j + 14, k + 41, Blocks.stonebrick);
		world.setBlock(i + 1, j + 15, k + 4, Blocks.stonebrick);
		world.setBlock(i + 1, j + 15, k + 5, Blocks.stonebrick);
		world.setBlock(i + 1, j + 15, k + 6, Blocks.stonebrick);
		world.setBlock(i + 1, j + 15, k + 7, Blocks.stonebrick);
		world.setBlock(i + 1, j + 15, k + 8, Blocks.stonebrick);
		world.setBlock(i + 1, j + 15, k + 9, Blocks.stonebrick);
		world.setBlock(i + 1, j + 15, k + 36, Blocks.stonebrick);
		world.setBlock(i + 1, j + 15, k + 37, Blocks.stonebrick);
		world.setBlock(i + 1, j + 15, k + 38, Blocks.stonebrick);
		world.setBlock(i + 1, j + 15, k + 39, Blocks.stonebrick);
		world.setBlock(i + 1, j + 15, k + 40, Blocks.stonebrick);
		world.setBlock(i + 1, j + 15, k + 41, Blocks.stonebrick);
		world.setBlock(i + 1, j + 16, k + 4, Blocks.stonebrick);
		world.setBlock(i + 1, j + 16, k + 9, Blocks.stonebrick);
		world.setBlock(i + 1, j + 16, k + 36, Blocks.stonebrick);
		world.setBlock(i + 1, j + 16, k + 41, Blocks.stonebrick);
		world.setBlock(i + 2, j + 0, k + 3, Blocks.stonebrick);
		world.setBlock(i + 2, j + 0, k + 4, Blocks.stonebrick);
		world.setBlock(i + 2, j + 0, k + 5, Blocks.stonebrick);
		world.setBlock(i + 2, j + 0, k + 6, Blocks.stonebrick);
		world.setBlock(i + 2, j + 0, k + 7, Blocks.stonebrick);
		world.setBlock(i + 2, j + 0, k + 8, Blocks.stonebrick);
		world.setBlock(i + 2, j + 0, k + 9, Blocks.stonebrick);
		world.setBlock(i + 2, j + 0, k + 10, Blocks.stonebrick);
		world.setBlock(i + 2, j + 0, k + 15, Blocks.stonebrick);
		world.setBlock(i + 2, j + 0, k + 16, Blocks.stonebrick);
		world.setBlock(i + 2, j + 0, k + 17, Blocks.stonebrick);
		world.setBlock(i + 2, j + 0, k + 18, Blocks.stonebrick);
		world.setBlock(i + 2, j + 0, k + 22, Blocks.stonebrick);
		world.setBlock(i + 2, j + 0, k + 23, Blocks.stonebrick);
		world.setBlock(i + 2, j + 0, k + 27, Blocks.stonebrick);
		world.setBlock(i + 2, j + 0, k + 28, Blocks.stonebrick);
		world.setBlock(i + 2, j + 0, k + 29, Blocks.stonebrick);
		world.setBlock(i + 2, j + 0, k + 30, Blocks.stonebrick);
		world.setBlock(i + 2, j + 0, k + 35, Blocks.stonebrick);
		world.setBlock(i + 2, j + 0, k + 36, Blocks.stonebrick);
		world.setBlock(i + 2, j + 0, k + 37, Blocks.stonebrick);
		world.setBlock(i + 2, j + 0, k + 38, Blocks.stonebrick);
		world.setBlock(i + 2, j + 0, k + 39, Blocks.stonebrick);
		world.setBlock(i + 2, j + 0, k + 40, Blocks.stonebrick);
		world.setBlock(i + 2, j + 0, k + 41, Blocks.stonebrick);
		world.setBlock(i + 2, j + 0, k + 42, Blocks.stonebrick);
		world.setBlock(i + 2, j + 1, k + 3, Blocks.stonebrick);
		world.setBlock(i + 2, j + 1, k + 10, Blocks.stonebrick);
		world.setBlock(i + 2, j + 1, k + 15, Blocks.stonebrick);
		world.setBlock(i + 2, j + 1, k + 16, Blocks.stonebrick);
		world.setBlock(i + 2, j + 1, k + 17, Blocks.stonebrick);
		world.setBlock(i + 2, j + 1, k + 18, Blocks.stonebrick);
		world.setBlock(i + 2, j + 1, k + 27, Blocks.stonebrick);
		world.setBlock(i + 2, j + 1, k + 28, Blocks.stonebrick);
		world.setBlock(i + 2, j + 1, k + 29, Blocks.stonebrick);
		world.setBlock(i + 2, j + 1, k + 30, Blocks.stonebrick);
		world.setBlock(i + 2, j + 1, k + 35, Blocks.stonebrick);
		world.setBlock(i + 2, j + 1, k + 42, Blocks.stonebrick);
		world.setBlock(i + 2, j + 2, k + 3, Blocks.stonebrick);
		world.setBlock(i + 2, j + 2, k + 10, Blocks.stonebrick);
		world.setBlock(i + 2, j + 2, k + 15, Blocks.stonebrick);
		world.setBlock(i + 2, j + 2, k + 16, Blocks.glass_pane);
		world.setBlock(i + 2, j + 2, k + 17, Blocks.stonebrick);
		world.setBlock(i + 2, j + 2, k + 18, Blocks.stonebrick);
		world.setBlock(i + 2, j + 2, k + 27, Blocks.stonebrick);
		world.setBlock(i + 2, j + 2, k + 28, Blocks.stonebrick);
		world.setBlock(i + 2, j + 2, k + 29, Blocks.glass_pane);
		world.setBlock(i + 2, j + 2, k + 30, Blocks.stonebrick);
		world.setBlock(i + 2, j + 2, k + 35, Blocks.stonebrick);
		world.setBlock(i + 2, j + 2, k + 42, Blocks.stonebrick);
		world.setBlock(i + 2, j + 3, k + 3, Blocks.stonebrick);
		world.setBlock(i + 2, j + 3, k + 10, Blocks.stonebrick);
		world.setBlock(i + 2, j + 3, k + 15, Blocks.stonebrick);
		world.setBlock(i + 2, j + 3, k + 16, Blocks.glass_pane);
		world.setBlock(i + 2, j + 3, k + 17, Blocks.stonebrick);
		world.setBlock(i + 2, j + 3, k + 18, Blocks.stonebrick);
		world.setBlock(i + 2, j + 3, k + 27, Blocks.stonebrick);
		world.setBlock(i + 2, j + 3, k + 28, Blocks.stonebrick);
		world.setBlock(i + 2, j + 3, k + 29, Blocks.glass_pane);
		world.setBlock(i + 2, j + 3, k + 30, Blocks.stonebrick);
		world.setBlock(i + 2, j + 3, k + 35, Blocks.stonebrick);
		world.setBlock(i + 2, j + 3, k + 42, Blocks.stonebrick);
		world.setBlock(i + 2, j + 4, k + 3, Blocks.stonebrick);
		world.setBlock(i + 2, j + 4, k + 10, Blocks.stonebrick);
		world.setBlock(i + 2, j + 4, k + 15, Blocks.stonebrick);
		world.setBlock(i + 2, j + 4, k + 16, Blocks.stonebrick);
		world.setBlock(i + 2, j + 4, k + 17, Blocks.stonebrick);
		world.setBlock(i + 2, j + 4, k + 18, Blocks.stonebrick);
		world.setBlock(i + 2, j + 4, k + 27, Blocks.stonebrick);
		world.setBlock(i + 2, j + 4, k + 28, Blocks.stonebrick);
		world.setBlock(i + 2, j + 4, k + 29, Blocks.stonebrick);
		world.setBlock(i + 2, j + 4, k + 30, Blocks.stonebrick);
		world.setBlock(i + 2, j + 4, k + 35, Blocks.stonebrick);
		world.setBlock(i + 2, j + 4, k + 42, Blocks.stonebrick);
		world.setBlock(i + 2, j + 5, k + 3, Blocks.stonebrick);
		world.setBlock(i + 2, j + 5, k + 4, Blocks.stonebrick);
		world.setBlock(i + 2, j + 5, k + 5, Blocks.stonebrick);
		world.setBlock(i + 2, j + 5, k + 6, Blocks.stonebrick);
		world.setBlock(i + 2, j + 5, k + 7, Blocks.stonebrick);
		world.setBlock(i + 2, j + 5, k + 8, Blocks.stonebrick);
		world.setBlock(i + 2, j + 5, k + 9, Blocks.stonebrick);
		world.setBlock(i + 2, j + 5, k + 10, Blocks.stonebrick);
		world.setBlock(i + 2, j + 5, k + 15, Blocks.stonebrick);
		world.setBlock(i + 2, j + 5, k + 16, Blocks.stonebrick);
		world.setBlock(i + 2, j + 5, k + 17, Blocks.stonebrick);
		world.setBlock(i + 2, j + 5, k + 18, Blocks.stonebrick);
		world.setBlock(i + 2, j + 5, k + 27, Blocks.stonebrick);
		world.setBlock(i + 2, j + 5, k + 28, Blocks.stonebrick);
		world.setBlock(i + 2, j + 5, k + 29, Blocks.stonebrick);
		world.setBlock(i + 2, j + 5, k + 30, Blocks.stonebrick);
		world.setBlock(i + 2, j + 5, k + 35, Blocks.stonebrick);
		world.setBlock(i + 2, j + 5, k + 36, Blocks.stonebrick);
		world.setBlock(i + 2, j + 5, k + 37, Blocks.stonebrick);
		world.setBlock(i + 2, j + 5, k + 38, Blocks.stonebrick);
		world.setBlock(i + 2, j + 5, k + 39, Blocks.stonebrick);
		world.setBlock(i + 2, j + 5, k + 40, Blocks.stonebrick);
		world.setBlock(i + 2, j + 5, k + 41, Blocks.stonebrick);
		world.setBlock(i + 2, j + 5, k + 42, Blocks.stonebrick);
		world.setBlock(i + 2, j + 6, k + 3, Blocks.stonebrick);
		world.setBlock(i + 2, j + 6, k + 10, Blocks.stonebrick);
		world.setBlock(i + 2, j + 6, k + 15, Blocks.stonebrick);
		world.setBlock(i + 2, j + 6, k + 16, Blocks.stonebrick);
		world.setBlock(i + 2, j + 6, k + 17, Blocks.stonebrick);
		world.setBlock(i + 2, j + 6, k + 18, Blocks.stonebrick);
		world.setBlock(i + 2, j + 6, k + 27, Blocks.stonebrick);
		world.setBlock(i + 2, j + 6, k + 28, Blocks.stonebrick);
		world.setBlock(i + 2, j + 6, k + 29, Blocks.stonebrick);
		world.setBlock(i + 2, j + 6, k + 30, Blocks.stonebrick);
		world.setBlock(i + 2, j + 6, k + 35, Blocks.stonebrick);
		world.setBlock(i + 2, j + 6, k + 36, Blocks.stonebrick);
		world.setBlock(i + 2, j + 6, k + 42, Blocks.stonebrick);
		world.setBlock(i + 2, j + 7, k + 3, Blocks.stonebrick);
		world.setBlock(i + 2, j + 7, k + 10, Blocks.stonebrick);
		world.setBlock(i + 2, j + 7, k + 15, Blocks.stonebrick);
		world.setBlock(i + 2, j + 7, k + 16, Blocks.glass_pane);
		world.setBlock(i + 2, j + 7, k + 17, Blocks.stonebrick);
		world.setBlock(i + 2, j + 7, k + 18, Blocks.stonebrick);
		world.setBlock(i + 2, j + 7, k + 27, Blocks.stonebrick);
		world.setBlock(i + 2, j + 7, k + 28, Blocks.stonebrick);
		world.setBlock(i + 2, j + 7, k + 29, Blocks.glass_pane);
		world.setBlock(i + 2, j + 7, k + 30, Blocks.stonebrick);
		world.setBlock(i + 2, j + 7, k + 35, Blocks.stonebrick);
		world.setBlock(i + 2, j + 7, k + 36, Blocks.stonebrick);
		world.setBlock(i + 2, j + 7, k + 42, Blocks.stonebrick);
		world.setBlock(i + 2, j + 8, k + 3, Blocks.stonebrick);
		world.setBlock(i + 2, j + 8, k + 10, Blocks.stonebrick);
		world.setBlock(i + 2, j + 8, k + 15, Blocks.stonebrick);
		world.setBlock(i + 2, j + 8, k + 16, Blocks.glass_pane);
		world.setBlock(i + 2, j + 8, k + 17, Blocks.stonebrick);
		world.setBlock(i + 2, j + 8, k + 18, Blocks.stonebrick);
		world.setBlock(i + 2, j + 8, k + 27, Blocks.stonebrick);
		world.setBlock(i + 2, j + 8, k + 28, Blocks.stonebrick);
		world.setBlock(i + 2, j + 8, k + 29, Blocks.glass_pane);
		world.setBlock(i + 2, j + 8, k + 30, Blocks.stonebrick);
		world.setBlock(i + 2, j + 8, k + 35, Blocks.stonebrick);
		world.setBlock(i + 2, j + 8, k + 36, Blocks.stonebrick);
		world.setBlock(i + 2, j + 8, k + 42, Blocks.stonebrick);
		world.setBlock(i + 2, j + 9, k + 3, Blocks.stonebrick);
		world.setBlock(i + 2, j + 9, k + 10, Blocks.stonebrick);
		world.setBlock(i + 2, j + 9, k + 15, Blocks.stonebrick);
		world.setBlock(i + 2, j + 9, k + 16, Blocks.stonebrick);
		world.setBlock(i + 2, j + 9, k + 17, Blocks.stonebrick);
		world.setBlock(i + 2, j + 9, k + 18, Blocks.stonebrick);
		world.setBlock(i + 2, j + 9, k + 27, Blocks.stonebrick);
		world.setBlock(i + 2, j + 9, k + 28, Blocks.stonebrick);
		world.setBlock(i + 2, j + 9, k + 29, Blocks.stonebrick);
		world.setBlock(i + 2, j + 9, k + 30, Blocks.stonebrick);
		world.setBlock(i + 2, j + 9, k + 35, Blocks.stonebrick);
		world.setBlock(i + 2, j + 9, k + 36, Blocks.stonebrick);
		world.setBlock(i + 2, j + 9, k + 42, Blocks.stonebrick);
		world.setBlock(i + 2, j + 10, k + 3, Blocks.stonebrick);
		world.setBlock(i + 2, j + 10, k + 4, Blocks.stonebrick);
		world.setBlock(i + 2, j + 10, k + 5, Blocks.stonebrick);
		world.setBlock(i + 2, j + 10, k + 6, Blocks.stonebrick);
		world.setBlock(i + 2, j + 10, k + 7, Blocks.stonebrick);
		world.setBlock(i + 2, j + 10, k + 8, Blocks.stonebrick);
		world.setBlock(i + 2, j + 10, k + 9, Blocks.stonebrick);
		world.setBlock(i + 2, j + 10, k + 10, Blocks.stonebrick);
		world.setBlock(i + 2, j + 10, k + 15, Blocks.stonebrick);
		world.setBlock(i + 2, j + 10, k + 16, Blocks.stonebrick);
		world.setBlock(i + 2, j + 10, k + 17, Blocks.stonebrick);
		world.setBlock(i + 2, j + 10, k + 18, Blocks.stonebrick);
		world.setBlock(i + 2, j + 10, k + 27, Blocks.stonebrick);
		world.setBlock(i + 2, j + 10, k + 28, Blocks.stonebrick);
		world.setBlock(i + 2, j + 10, k + 29, Blocks.stonebrick);
		world.setBlock(i + 2, j + 10, k + 30, Blocks.stonebrick);
		world.setBlock(i + 2, j + 10, k + 35, Blocks.stonebrick);
		world.setBlock(i + 2, j + 10, k + 36, Blocks.stonebrick);
		world.setBlock(i + 2, j + 10, k + 37, Blocks.stonebrick);
		world.setBlock(i + 2, j + 10, k + 38, Blocks.stonebrick);
		world.setBlock(i + 2, j + 10, k + 39, Blocks.stonebrick);
		world.setBlock(i + 2, j + 10, k + 40, Blocks.stonebrick);
		world.setBlock(i + 2, j + 10, k + 41, Blocks.stonebrick);
		world.setBlock(i + 2, j + 10, k + 42, Blocks.stonebrick);
		world.setBlock(i + 2, j + 11, k + 3, Blocks.stonebrick);
		world.setBlock(i + 2, j + 11, k + 10, Blocks.stonebrick);
		world.setBlock(i + 2, j + 11, k + 15, Blocks.stonebrick);
		world.setBlock(i + 2, j + 11, k + 16, Blocks.stonebrick);
		world.setBlock(i + 2, j + 11, k + 17, Blocks.stonebrick);
		world.setBlock(i + 2, j + 11, k + 18, Blocks.stonebrick);
		world.setBlock(i + 2, j + 11, k + 27, Blocks.stonebrick);
		world.setBlock(i + 2, j + 11, k + 28, Blocks.stonebrick);
		world.setBlock(i + 2, j + 11, k + 29, Blocks.stonebrick);
		world.setBlock(i + 2, j + 11, k + 30, Blocks.stonebrick);
		world.setBlock(i + 2, j + 11, k + 35, Blocks.stonebrick);
		world.setBlock(i + 2, j + 11, k + 37, Blocks.stonebrick);
		world.setBlock(i + 2, j + 11, k + 42, Blocks.stonebrick);
		world.setBlock(i + 2, j + 12, k + 3, Blocks.stonebrick);
		world.setBlock(i + 2, j + 12, k + 10, Blocks.stonebrick);
		world.setBlock(i + 2, j + 12, k + 15, Blocks.stonebrick);
		world.setBlock(i + 2, j + 12, k + 16, Blocks.glass_pane);
		world.setBlock(i + 2, j + 12, k + 17, Blocks.stonebrick);
		world.setBlock(i + 2, j + 12, k + 18, Blocks.stonebrick);
		world.setBlock(i + 2, j + 12, k + 27, Blocks.stonebrick);
		world.setBlock(i + 2, j + 12, k + 28, Blocks.stonebrick);
		world.setBlock(i + 2, j + 12, k + 29, Blocks.glass_pane);
		world.setBlock(i + 2, j + 12, k + 30, Blocks.stonebrick);
		world.setBlock(i + 2, j + 12, k + 35, Blocks.stonebrick);
		world.setBlock(i + 2, j + 12, k + 42, Blocks.stonebrick);
		world.setBlock(i + 2, j + 13, k + 3, Blocks.stonebrick);
		world.setBlock(i + 2, j + 13, k + 10, Blocks.stonebrick);
		world.setBlock(i + 2, j + 13, k + 15, Blocks.stonebrick);
		world.setBlock(i + 2, j + 13, k + 16, Blocks.glass_pane);
		world.setBlock(i + 2, j + 13, k + 17, Blocks.stonebrick);
		world.setBlock(i + 2, j + 13, k + 18, Blocks.stonebrick);
		world.setBlock(i + 2, j + 13, k + 27, Blocks.stonebrick);
		world.setBlock(i + 2, j + 13, k + 28, Blocks.stonebrick);
		world.setBlock(i + 2, j + 13, k + 29, Blocks.glass_pane);
		world.setBlock(i + 2, j + 13, k + 30, Blocks.stonebrick);
		world.setBlock(i + 2, j + 13, k + 35, Blocks.stonebrick);
		world.setBlock(i + 2, j + 13, k + 42, Blocks.stonebrick);
		world.setBlock(i + 2, j + 14, k + 3, Blocks.stonebrick);
		world.setBlock(i + 2, j + 14, k + 10, Blocks.stonebrick);
		world.setBlock(i + 2, j + 14, k + 15, Blocks.stonebrick);
		world.setBlock(i + 2, j + 14, k + 16, Blocks.stonebrick);
		world.setBlock(i + 2, j + 14, k + 17, Blocks.stonebrick);
		world.setBlock(i + 2, j + 14, k + 18, Blocks.stonebrick);
		world.setBlock(i + 2, j + 14, k + 27, Blocks.stonebrick);
		world.setBlock(i + 2, j + 14, k + 28, Blocks.stonebrick);
		world.setBlock(i + 2, j + 14, k + 29, Blocks.stonebrick);
		world.setBlock(i + 2, j + 14, k + 30, Blocks.stonebrick);
		world.setBlock(i + 2, j + 14, k + 35, Blocks.stonebrick);
		world.setBlock(i + 2, j + 14, k + 42, Blocks.stonebrick);
		world.setBlock(i + 2, j + 15, k + 3, Blocks.stonebrick);
		world.setBlock(i + 2, j + 15, k + 4, Blocks.stonebrick);
		world.setBlock(i + 2, j + 15, k + 5, Blocks.stonebrick);
		world.setBlock(i + 2, j + 15, k + 6, Blocks.stonebrick);
		world.setBlock(i + 2, j + 15, k + 7, Blocks.stonebrick);
		world.setBlock(i + 2, j + 15, k + 8, Blocks.stonebrick);
		world.setBlock(i + 2, j + 15, k + 9, Blocks.stonebrick);
		world.setBlock(i + 2, j + 15, k + 10, Blocks.stonebrick);
		world.setBlock(i + 2, j + 15, k + 15, Blocks.stonebrick);
		world.setBlock(i + 2, j + 15, k + 16, Blocks.stonebrick);
		world.setBlock(i + 2, j + 15, k + 17, Blocks.stonebrick);
		world.setBlock(i + 2, j + 15, k + 18, Blocks.stonebrick);
		world.setBlock(i + 2, j + 15, k + 27, Blocks.stonebrick);
		world.setBlock(i + 2, j + 15, k + 28, Blocks.stonebrick);
		world.setBlock(i + 2, j + 15, k + 29, Blocks.stonebrick);
		world.setBlock(i + 2, j + 15, k + 30, Blocks.stonebrick);
		world.setBlock(i + 2, j + 15, k + 35, Blocks.stonebrick);
		world.setBlock(i + 2, j + 15, k + 36, Blocks.stonebrick);
		world.setBlock(i + 2, j + 15, k + 37, Blocks.stonebrick);
		world.setBlock(i + 2, j + 15, k + 38, Blocks.stonebrick);
		world.setBlock(i + 2, j + 15, k + 39, Blocks.stonebrick);
		world.setBlock(i + 2, j + 15, k + 40, Blocks.stonebrick);
		world.setBlock(i + 2, j + 15, k + 41, Blocks.stonebrick);
		world.setBlock(i + 2, j + 15, k + 42, Blocks.stonebrick);
		world.setBlock(i + 2, j + 16, k + 3, Blocks.stonebrick);
		world.setBlock(i + 2, j + 16, k + 10, Blocks.stonebrick);
		world.setBlock(i + 2, j + 16, k + 15, Blocks.stonebrick);
		world.setBlock(i + 2, j + 16, k + 16, Blocks.stonebrick);
		world.setBlock(i + 2, j + 16, k + 17, Blocks.stonebrick);
		world.setBlock(i + 2, j + 16, k + 18, Blocks.stonebrick);
		world.setBlock(i + 2, j + 16, k + 27, Blocks.stonebrick);
		world.setBlock(i + 2, j + 16, k + 28, Blocks.stonebrick);
		world.setBlock(i + 2, j + 16, k + 29, Blocks.stonebrick);
		world.setBlock(i + 2, j + 16, k + 30, Blocks.stonebrick);
		world.setBlock(i + 2, j + 16, k + 35, Blocks.stonebrick);
		world.setBlock(i + 2, j + 16, k + 42, Blocks.stonebrick);
		world.setBlock(i + 3, j + 0, k + 2, Blocks.stonebrick);
		world.setBlock(i + 3, j + 0, k + 3, Blocks.stonebrick);
		world.setBlock(i + 3, j + 0, k + 4, Blocks.stonebrick);
		world.setBlock(i + 3, j + 0, k + 5, Blocks.stonebrick);
		world.setBlock(i + 3, j + 0, k + 6, Blocks.stonebrick);
		world.setBlock(i + 3, j + 0, k + 7, Blocks.stonebrick);
		world.setBlock(i + 3, j + 0, k + 8, Blocks.stonebrick);
		world.setBlock(i + 3, j + 0, k + 9, Blocks.stonebrick);
		world.setBlock(i + 3, j + 0, k + 10, Blocks.stonebrick);
		world.setBlock(i + 3, j + 0, k + 11, Blocks.stonebrick);
		world.setBlock(i + 3, j + 0, k + 12, Blocks.stonebrick);
		world.setBlock(i + 3, j + 0, k + 13, Blocks.stonebrick);
		world.setBlock(i + 3, j + 0, k + 14, Blocks.stonebrick);
		world.setBlock(i + 3, j + 0, k + 15, Blocks.stonebrick);
		world.setBlock(i + 3, j + 0, k + 16, Blocks.stonebrick);
		world.setBlock(i + 3, j + 0, k + 17, Blocks.stonebrick);
		world.setBlock(i + 3, j + 0, k + 18, Blocks.stonebrick);
		world.setBlock(i + 3, j + 0, k + 19, Blocks.stonebrick);
		world.setBlock(i + 3, j + 0, k + 21, Blocks.stonebrick);
		world.setBlock(i + 3, j + 0, k + 22, Blocks.stonebrick);
		world.setBlock(i + 3, j + 0, k + 23, Blocks.stonebrick);
		world.setBlock(i + 3, j + 0, k + 24, Blocks.stonebrick);
		world.setBlock(i + 3, j + 0, k + 26, Blocks.stonebrick);
		world.setBlock(i + 3, j + 0, k + 27, Blocks.stonebrick);
		world.setBlock(i + 3, j + 0, k + 28, Blocks.stonebrick);
		world.setBlock(i + 3, j + 0, k + 29, Blocks.stonebrick);
		world.setBlock(i + 3, j + 0, k + 30, Blocks.stonebrick);
		world.setBlock(i + 3, j + 0, k + 31, Blocks.stonebrick);
		world.setBlock(i + 3, j + 0, k + 32, Blocks.stonebrick);
		world.setBlock(i + 3, j + 0, k + 33, Blocks.stonebrick);
		world.setBlock(i + 3, j + 0, k + 34, Blocks.stonebrick);
		world.setBlock(i + 3, j + 0, k + 35, Blocks.stonebrick);
		world.setBlock(i + 3, j + 0, k + 36, Blocks.stonebrick);
		world.setBlock(i + 3, j + 0, k + 37, Blocks.stonebrick);
		world.setBlock(i + 3, j + 0, k + 38, Blocks.stonebrick);
		world.setBlock(i + 3, j + 0, k + 39, Blocks.stonebrick);
		world.setBlock(i + 3, j + 0, k + 40, Blocks.stonebrick);
		world.setBlock(i + 3, j + 0, k + 41, Blocks.stonebrick);
		world.setBlock(i + 3, j + 0, k + 42, Blocks.stonebrick);
		world.setBlock(i + 3, j + 0, k + 43, Blocks.stonebrick);
		world.setBlock(i + 3, j + 1, k + 2, Blocks.stonebrick);
		world.setBlock(i + 3, j + 1, k + 11, Blocks.stonebrick);
		world.setBlock(i + 3, j + 1, k + 12, Blocks.stonebrick);
		world.setBlock(i + 3, j + 1, k + 13, Blocks.stonebrick);
		world.setBlock(i + 3, j + 1, k + 14, Blocks.stonebrick);
		world.setBlock(i + 3, j + 1, k + 19, Blocks.stonebrick);
		world.setBlock(i + 3, j + 1, k + 26, Blocks.stonebrick);
		world.setBlock(i + 3, j + 1, k + 31, Blocks.stonebrick);
		world.setBlock(i + 3, j + 1, k + 32, Blocks.stonebrick);
		world.setBlock(i + 3, j + 1, k + 33, Blocks.stonebrick);
		world.setBlock(i + 3, j + 1, k + 34, Blocks.stonebrick);
		world.setBlock(i + 3, j + 1, k + 43, Blocks.stonebrick);
		world.setBlock(i + 3, j + 2, k + 2, Blocks.stonebrick);
		world.setBlock(i + 3, j + 2, k + 11, Blocks.stonebrick);
		world.setBlock(i + 3, j + 2, k + 12, Blocks.stonebrick);
		world.setBlock(i + 3, j + 2, k + 13, Blocks.stonebrick);
		world.setBlock(i + 3, j + 2, k + 14, Blocks.stonebrick);
		world.setBlock(i + 3, j + 2, k + 19, Blocks.stonebrick);
		world.setBlock(i + 3, j + 2, k + 26, Blocks.stonebrick);
		world.setBlock(i + 3, j + 2, k + 31, Blocks.stonebrick);
		world.setBlock(i + 3, j + 2, k + 32, Blocks.stonebrick);
		world.setBlock(i + 3, j + 2, k + 33, Blocks.stonebrick);
		world.setBlock(i + 3, j + 2, k + 34, Blocks.stonebrick);
		world.setBlock(i + 3, j + 2, k + 43, Blocks.stonebrick);
		world.setBlock(i + 3, j + 3, k + 2, Blocks.stonebrick);
		world.setBlock(i + 3, j + 3, k + 11, Blocks.stonebrick);
		world.setBlock(i + 3, j + 3, k + 12, Blocks.stonebrick);
		world.setBlock(i + 3, j + 3, k + 13, Blocks.stonebrick);
		world.setBlock(i + 3, j + 3, k + 14, Blocks.stonebrick);
		world.setBlock(i + 3, j + 3, k + 19, Blocks.stonebrick);
		world.setBlock(i + 3, j + 3, k + 26, Blocks.stonebrick);
		world.setBlock(i + 3, j + 3, k + 31, Blocks.stonebrick);
		world.setBlock(i + 3, j + 3, k + 32, Blocks.stonebrick);
		world.setBlock(i + 3, j + 3, k + 33, Blocks.stonebrick);
		world.setBlock(i + 3, j + 3, k + 34, Blocks.stonebrick);
		world.setBlock(i + 3, j + 3, k + 43, Blocks.stonebrick);
		world.setBlock(i + 3, j + 4, k + 2, Blocks.stonebrick);
		world.setBlock(i + 3, j + 4, k + 11, Blocks.stonebrick);
		world.setBlock(i + 3, j + 4, k + 12, Blocks.stonebrick);
		world.setBlock(i + 3, j + 4, k + 13, Blocks.stonebrick);
		world.setBlock(i + 3, j + 4, k + 14, Blocks.stonebrick);
		world.setBlock(i + 3, j + 4, k + 19, Blocks.stonebrick);
		world.setBlock(i + 3, j + 4, k + 26, Blocks.stonebrick);
		world.setBlock(i + 3, j + 4, k + 31, Blocks.stonebrick);
		world.setBlock(i + 3, j + 4, k + 32, Blocks.stonebrick);
		world.setBlock(i + 3, j + 4, k + 33, Blocks.stonebrick);
		world.setBlock(i + 3, j + 4, k + 34, Blocks.stonebrick);
		world.setBlock(i + 3, j + 4, k + 43, Blocks.stonebrick);
		world.setBlock(i + 3, j + 5, k + 2, Blocks.stonebrick);
		world.setBlock(i + 3, j + 5, k + 3, Blocks.stonebrick);
		world.setBlock(i + 3, j + 5, k + 4, Blocks.stonebrick);
		world.setBlock(i + 3, j + 5, k + 5, Blocks.stonebrick);
		world.setBlock(i + 3, j + 5, k + 6, Blocks.stonebrick);
		world.setBlock(i + 3, j + 5, k + 7, Blocks.stonebrick);
		world.setBlock(i + 3, j + 5, k + 8, Blocks.stonebrick);
		world.setBlock(i + 3, j + 5, k + 9, Blocks.stonebrick);
		world.setBlock(i + 3, j + 5, k + 10, Blocks.stonebrick);
		world.setBlock(i + 3, j + 5, k + 11, Blocks.stonebrick);
		world.setBlock(i + 3, j + 5, k + 12, Blocks.stonebrick);
		world.setBlock(i + 3, j + 5, k + 13, Blocks.stonebrick);
		world.setBlock(i + 3, j + 5, k + 14, Blocks.stonebrick);
		world.setBlock(i + 3, j + 5, k + 15, Blocks.stonebrick);
		world.setBlock(i + 3, j + 5, k + 16, Blocks.stonebrick);
		world.setBlock(i + 3, j + 5, k + 17, Blocks.stonebrick);
		world.setBlock(i + 3, j + 5, k + 18, Blocks.stonebrick);
		world.setBlock(i + 3, j + 5, k + 19, Blocks.stonebrick);
		world.setBlock(i + 3, j + 5, k + 26, Blocks.stonebrick);
		world.setBlock(i + 3, j + 5, k + 27, Blocks.stonebrick);
		world.setBlock(i + 3, j + 5, k + 28, Blocks.stonebrick);
		world.setBlock(i + 3, j + 5, k + 29, Blocks.stonebrick);
		world.setBlock(i + 3, j + 5, k + 30, Blocks.stonebrick);
		world.setBlock(i + 3, j + 5, k + 31, Blocks.stonebrick);
		world.setBlock(i + 3, j + 5, k + 32, Blocks.stonebrick);
		world.setBlock(i + 3, j + 5, k + 33, Blocks.stonebrick);
		world.setBlock(i + 3, j + 5, k + 34, Blocks.stonebrick);
		world.setBlock(i + 3, j + 5, k + 35, Blocks.stonebrick);
		world.setBlock(i + 3, j + 5, k + 36, Blocks.stonebrick);
		world.setBlock(i + 3, j + 5, k + 37, Blocks.stonebrick);
		world.setBlock(i + 3, j + 5, k + 38, Blocks.stonebrick);
		world.setBlock(i + 3, j + 5, k + 39, Blocks.stonebrick);
		world.setBlock(i + 3, j + 5, k + 40, Blocks.stonebrick);
		world.setBlock(i + 3, j + 5, k + 41, Blocks.stonebrick);
		world.setBlock(i + 3, j + 5, k + 42, Blocks.stonebrick);
		world.setBlock(i + 3, j + 5, k + 43, Blocks.stonebrick);
		world.setBlock(i + 3, j + 6, k + 2, Blocks.stonebrick);
		world.setBlock(i + 3, j + 6, k + 11, Blocks.stonebrick);
		world.setBlock(i + 3, j + 6, k + 12, Blocks.stonebrick);
		world.setBlock(i + 3, j + 6, k + 13, Blocks.stonebrick);
		world.setBlock(i + 3, j + 6, k + 14, Blocks.stonebrick);
		world.setBlock(i + 3, j + 6, k + 15, Blocks.chest, 5, 4);
		world.setBlock(i + 3, j + 6, k + 19, Blocks.stonebrick);
		world.setBlock(i + 3, j + 6, k + 26, Blocks.stonebrick);
		world.setBlock(i + 3, j + 6, k + 31, Blocks.stonebrick);
		world.setBlock(i + 3, j + 6, k + 32, Blocks.stonebrick);
		world.setBlock(i + 3, j + 6, k + 33, Blocks.stonebrick);
		world.setBlock(i + 3, j + 6, k + 34, Blocks.stonebrick);
		world.setBlock(i + 3, j + 6, k + 36, Blocks.stonebrick);
		world.setBlock(i + 3, j + 6, k + 43, Blocks.stonebrick);
		world.setBlock(i + 3, j + 7, k + 2, Blocks.stonebrick);
		world.setBlock(i + 3, j + 7, k + 11, Blocks.stonebrick);
		world.setBlock(i + 3, j + 7, k + 12, Blocks.stonebrick);
		world.setBlock(i + 3, j + 7, k + 13, Blocks.stonebrick);
		world.setBlock(i + 3, j + 7, k + 14, Blocks.stonebrick);
		world.setBlock(i + 3, j + 7, k + 19, Blocks.stonebrick);
		world.setBlock(i + 3, j + 7, k + 26, Blocks.stonebrick);
		world.setBlock(i + 3, j + 7, k + 31, Blocks.stonebrick);
		world.setBlock(i + 3, j + 7, k + 32, Blocks.stonebrick);
		world.setBlock(i + 3, j + 7, k + 33, Blocks.stonebrick);
		world.setBlock(i + 3, j + 7, k + 34, Blocks.stonebrick);
		world.setBlock(i + 3, j + 7, k + 36, Blocks.stonebrick);
		world.setBlock(i + 3, j + 7, k + 43, Blocks.stonebrick);
		world.setBlock(i + 3, j + 8, k + 2, Blocks.stonebrick);
		world.setBlock(i + 3, j + 8, k + 11, Blocks.stonebrick);
		world.setBlock(i + 3, j + 8, k + 12, Blocks.stonebrick);
		world.setBlock(i + 3, j + 8, k + 13, Blocks.stonebrick);
		world.setBlock(i + 3, j + 8, k + 14, Blocks.stonebrick);
		world.setBlock(i + 3, j + 8, k + 19, Blocks.stonebrick);
		world.setBlock(i + 3, j + 8, k + 26, Blocks.stonebrick);
		world.setBlock(i + 3, j + 8, k + 31, Blocks.stonebrick);
		world.setBlock(i + 3, j + 8, k + 32, Blocks.stonebrick);
		world.setBlock(i + 3, j + 8, k + 33, Blocks.stonebrick);
		world.setBlock(i + 3, j + 8, k + 34, Blocks.stonebrick);
		world.setBlock(i + 3, j + 8, k + 36, Blocks.stonebrick);
		world.setBlock(i + 3, j + 8, k + 43, Blocks.stonebrick);
		world.setBlock(i + 3, j + 9, k + 2, Blocks.stonebrick);
		world.setBlock(i + 3, j + 9, k + 11, Blocks.stonebrick);
		world.setBlock(i + 3, j + 9, k + 12, Blocks.stonebrick);
		world.setBlock(i + 3, j + 9, k + 13, Blocks.stonebrick);
		world.setBlock(i + 3, j + 9, k + 14, Blocks.stonebrick);
		world.setBlock(i + 3, j + 9, k + 19, Blocks.stonebrick);
		world.setBlock(i + 3, j + 9, k + 26, Blocks.stonebrick);
		world.setBlock(i + 3, j + 9, k + 31, Blocks.stonebrick);
		world.setBlock(i + 3, j + 9, k + 32, Blocks.stonebrick);
		world.setBlock(i + 3, j + 9, k + 33, Blocks.stonebrick);
		world.setBlock(i + 3, j + 9, k + 34, Blocks.stonebrick);
		world.setBlock(i + 3, j + 9, k + 36, Blocks.stonebrick);
		world.setBlock(i + 3, j + 9, k + 43, Blocks.stonebrick);
		world.setBlock(i + 3, j + 10, k + 2, Blocks.stonebrick);
		world.setBlock(i + 3, j + 10, k + 3, Blocks.stonebrick);
		world.setBlock(i + 3, j + 10, k + 4, Blocks.stonebrick);
		world.setBlock(i + 3, j + 10, k + 5, Blocks.stonebrick);
		world.setBlock(i + 3, j + 10, k + 6, Blocks.stonebrick);
		world.setBlock(i + 3, j + 10, k + 7, Blocks.stonebrick);
		world.setBlock(i + 3, j + 10, k + 8, Blocks.stonebrick);
		world.setBlock(i + 3, j + 10, k + 9, Blocks.stonebrick);
		world.setBlock(i + 3, j + 10, k + 10, Blocks.stonebrick);
		world.setBlock(i + 3, j + 10, k + 11, Blocks.stonebrick);
		world.setBlock(i + 3, j + 10, k + 12, Blocks.stonebrick);
		world.setBlock(i + 3, j + 10, k + 13, Blocks.stonebrick);
		world.setBlock(i + 3, j + 10, k + 14, Blocks.stonebrick);
		world.setBlock(i + 3, j + 10, k + 15, Blocks.stonebrick);
		world.setBlock(i + 3, j + 10, k + 16, Blocks.stonebrick);
		world.setBlock(i + 3, j + 10, k + 17, Blocks.stonebrick);
		world.setBlock(i + 3, j + 10, k + 18, Blocks.stonebrick);
		world.setBlock(i + 3, j + 10, k + 19, Blocks.stonebrick);
		world.setBlock(i + 3, j + 10, k + 26, Blocks.stonebrick);
		world.setBlock(i + 3, j + 10, k + 27, Blocks.stonebrick);
		world.setBlock(i + 3, j + 10, k + 28, Blocks.stonebrick);
		world.setBlock(i + 3, j + 10, k + 29, Blocks.stonebrick);
		world.setBlock(i + 3, j + 10, k + 30, Blocks.stonebrick);
		world.setBlock(i + 3, j + 10, k + 31, Blocks.stonebrick);
		world.setBlock(i + 3, j + 10, k + 32, Blocks.stonebrick);
		world.setBlock(i + 3, j + 10, k + 33, Blocks.stonebrick);
		world.setBlock(i + 3, j + 10, k + 34, Blocks.stonebrick);
		world.setBlock(i + 3, j + 10, k + 35, Blocks.stonebrick);
		world.setBlock(i + 3, j + 10, k + 36, Blocks.stonebrick);
		world.setBlock(i + 3, j + 10, k + 37, Blocks.stonebrick);
		world.setBlock(i + 3, j + 10, k + 38, Blocks.stonebrick);
		world.setBlock(i + 3, j + 10, k + 39, Blocks.stonebrick);
		world.setBlock(i + 3, j + 10, k + 40, Blocks.stonebrick);
		world.setBlock(i + 3, j + 10, k + 41, Blocks.stonebrick);
		world.setBlock(i + 3, j + 10, k + 42, Blocks.stonebrick);
		world.setBlock(i + 3, j + 10, k + 43, Blocks.stonebrick);
		world.setBlock(i + 3, j + 11, k + 2, Blocks.stonebrick);
		world.setBlock(i + 3, j + 11, k + 11, Blocks.stonebrick);
		world.setBlock(i + 3, j + 11, k + 12, Blocks.stonebrick);
		world.setBlock(i + 3, j + 11, k + 13, Blocks.stonebrick);
		world.setBlock(i + 3, j + 11, k + 14, Blocks.stonebrick);
		world.setBlock(i + 3, j + 11, k + 19, Blocks.stonebrick);
		world.setBlock(i + 3, j + 11, k + 26, Blocks.stonebrick);
		world.setBlock(i + 3, j + 11, k + 31, Blocks.stonebrick);
		world.setBlock(i + 3, j + 11, k + 32, Blocks.stonebrick);
		world.setBlock(i + 3, j + 11, k + 33, Blocks.stonebrick);
		world.setBlock(i + 3, j + 11, k + 34, Blocks.stonebrick);
		world.setBlock(i + 3, j + 11, k + 43, Blocks.stonebrick);
		world.setBlock(i + 3, j + 12, k + 2, Blocks.stonebrick);
		world.setBlock(i + 3, j + 12, k + 11, Blocks.stonebrick);
		world.setBlock(i + 3, j + 12, k + 12, Blocks.stonebrick);
		world.setBlock(i + 3, j + 12, k + 13, Blocks.stonebrick);
		world.setBlock(i + 3, j + 12, k + 14, Blocks.stonebrick);
		world.setBlock(i + 3, j + 12, k + 19, Blocks.stonebrick);
		world.setBlock(i + 3, j + 12, k + 26, Blocks.stonebrick);
		world.setBlock(i + 3, j + 12, k + 31, Blocks.stonebrick);
		world.setBlock(i + 3, j + 12, k + 32, Blocks.stonebrick);
		world.setBlock(i + 3, j + 12, k + 33, Blocks.stonebrick);
		world.setBlock(i + 3, j + 12, k + 34, Blocks.stonebrick);
		world.setBlock(i + 3, j + 12, k + 43, Blocks.stonebrick);
		world.setBlock(i + 3, j + 13, k + 2, Blocks.stonebrick);
		world.setBlock(i + 3, j + 13, k + 11, Blocks.stonebrick);
		world.setBlock(i + 3, j + 13, k + 12, Blocks.stonebrick);
		world.setBlock(i + 3, j + 13, k + 13, Blocks.stonebrick);
		world.setBlock(i + 3, j + 13, k + 14, Blocks.stonebrick);
		world.setBlock(i + 3, j + 13, k + 19, Blocks.stonebrick);
		world.setBlock(i + 3, j + 13, k + 26, Blocks.stonebrick);
		world.setBlock(i + 3, j + 13, k + 31, Blocks.stonebrick);
		world.setBlock(i + 3, j + 13, k + 32, Blocks.stonebrick);
		world.setBlock(i + 3, j + 13, k + 33, Blocks.stonebrick);
		world.setBlock(i + 3, j + 13, k + 34, Blocks.stonebrick);
		world.setBlock(i + 3, j + 13, k + 43, Blocks.stonebrick);
		world.setBlock(i + 3, j + 14, k + 2, Blocks.stonebrick);
		world.setBlock(i + 3, j + 14, k + 11, Blocks.stonebrick);
		world.setBlock(i + 3, j + 14, k + 12, Blocks.stonebrick);
		world.setBlock(i + 3, j + 14, k + 13, Blocks.stonebrick);
		world.setBlock(i + 3, j + 14, k + 14, Blocks.stonebrick);
		world.setBlock(i + 3, j + 14, k + 19, Blocks.stonebrick);
		world.setBlock(i + 3, j + 14, k + 26, Blocks.stonebrick);
		world.setBlock(i + 3, j + 14, k + 31, Blocks.stonebrick);
		world.setBlock(i + 3, j + 14, k + 32, Blocks.stonebrick);
		world.setBlock(i + 3, j + 14, k + 33, Blocks.stonebrick);
		world.setBlock(i + 3, j + 14, k + 34, Blocks.stonebrick);
		world.setBlock(i + 3, j + 14, k + 43, Blocks.stonebrick);
		world.setBlock(i + 3, j + 15, k + 2, Blocks.stonebrick);
		world.setBlock(i + 3, j + 15, k + 3, Blocks.stonebrick);
		world.setBlock(i + 3, j + 15, k + 4, Blocks.stonebrick);
		world.setBlock(i + 3, j + 15, k + 5, Blocks.stonebrick);
		world.setBlock(i + 3, j + 15, k + 6, Blocks.stonebrick);
		world.setBlock(i + 3, j + 15, k + 7, Blocks.stonebrick);
		world.setBlock(i + 3, j + 15, k + 8, Blocks.stonebrick);
		world.setBlock(i + 3, j + 15, k + 9, Blocks.stonebrick);
		world.setBlock(i + 3, j + 15, k + 10, Blocks.stonebrick);
		world.setBlock(i + 3, j + 15, k + 11, Blocks.stonebrick);
		world.setBlock(i + 3, j + 15, k + 12, Blocks.stonebrick);
		world.setBlock(i + 3, j + 15, k + 13, Blocks.stonebrick);
		world.setBlock(i + 3, j + 15, k + 14, Blocks.stonebrick);
		world.setBlock(i + 3, j + 15, k + 15, Blocks.stonebrick);
		world.setBlock(i + 3, j + 15, k + 16, Blocks.stonebrick);
		world.setBlock(i + 3, j + 15, k + 17, Blocks.stonebrick);
		world.setBlock(i + 3, j + 15, k + 18, Blocks.stonebrick);
		world.setBlock(i + 3, j + 15, k + 19, Blocks.stonebrick);
		world.setBlock(i + 3, j + 15, k + 26, Blocks.stonebrick);
		world.setBlock(i + 3, j + 15, k + 27, Blocks.stonebrick);
		world.setBlock(i + 3, j + 15, k + 28, Blocks.stonebrick);
		world.setBlock(i + 3, j + 15, k + 29, Blocks.stonebrick);
		world.setBlock(i + 3, j + 15, k + 30, Blocks.stonebrick);
		world.setBlock(i + 3, j + 15, k + 31, Blocks.stonebrick);
		world.setBlock(i + 3, j + 15, k + 32, Blocks.stonebrick);
		world.setBlock(i + 3, j + 15, k + 33, Blocks.stonebrick);
		world.setBlock(i + 3, j + 15, k + 34, Blocks.stonebrick);
		world.setBlock(i + 3, j + 15, k + 35, Blocks.stonebrick);
		world.setBlock(i + 3, j + 15, k + 36, Blocks.stonebrick);
		world.setBlock(i + 3, j + 15, k + 37, Blocks.stonebrick);
		world.setBlock(i + 3, j + 15, k + 38, Blocks.stonebrick);
		world.setBlock(i + 3, j + 15, k + 39, Blocks.stonebrick);
		world.setBlock(i + 3, j + 15, k + 40, Blocks.stonebrick);
		world.setBlock(i + 3, j + 15, k + 41, Blocks.stonebrick);
		world.setBlock(i + 3, j + 15, k + 42, Blocks.stonebrick);
		world.setBlock(i + 3, j + 15, k + 43, Blocks.stonebrick);
		world.setBlock(i + 3, j + 16, k + 2, Blocks.stonebrick);
		world.setBlock(i + 3, j + 16, k + 11, Blocks.stonebrick);
		world.setBlock(i + 3, j + 16, k + 12, Blocks.stonebrick);
		world.setBlock(i + 3, j + 16, k + 13, Blocks.stonebrick);
		world.setBlock(i + 3, j + 16, k + 14, Blocks.stonebrick);
		world.setBlock(i + 3, j + 16, k + 19, Blocks.stonebrick);
		world.setBlock(i + 3, j + 16, k + 26, Blocks.stonebrick);
		world.setBlock(i + 3, j + 16, k + 31, Blocks.stonebrick);
		world.setBlock(i + 3, j + 16, k + 32, Blocks.stonebrick);
		world.setBlock(i + 3, j + 16, k + 33, Blocks.stonebrick);
		world.setBlock(i + 3, j + 16, k + 34, Blocks.stonebrick);
		world.setBlock(i + 3, j + 16, k + 43, Blocks.stonebrick);
		world.setBlock(i + 4, j + 0, k + 1, Blocks.stonebrick);
		world.setBlock(i + 4, j + 0, k + 2, Blocks.stonebrick);
		world.setBlock(i + 4, j + 0, k + 3, Blocks.stonebrick);
		world.setBlock(i + 4, j + 0, k + 4, Blocks.stonebrick);
		world.setBlock(i + 4, j + 0, k + 5, Blocks.stonebrick);
		world.setBlock(i + 4, j + 0, k + 6, Blocks.stonebrick);
		world.setBlock(i + 4, j + 0, k + 7, Blocks.stonebrick);
		world.setBlock(i + 4, j + 0, k + 8, Blocks.stonebrick);
		world.setBlock(i + 4, j + 0, k + 9, Blocks.stonebrick);
		world.setBlock(i + 4, j + 0, k + 10, Blocks.stonebrick);
		world.setBlock(i + 4, j + 0, k + 11, Blocks.stonebrick);
		world.setBlock(i + 4, j + 0, k + 12, Blocks.stonebrick);
		world.setBlock(i + 4, j + 0, k + 13, Blocks.stonebrick);
		world.setBlock(i + 4, j + 0, k + 14, Blocks.stonebrick);
		world.setBlock(i + 4, j + 0, k + 15, Blocks.stonebrick);
		world.setBlock(i + 4, j + 0, k + 16, Blocks.stonebrick);
		world.setBlock(i + 4, j + 0, k + 17, Blocks.stonebrick);
		world.setBlock(i + 4, j + 0, k + 18, Blocks.stonebrick);
		world.setBlock(i + 4, j + 0, k + 19, Blocks.stonebrick);
		world.setBlock(i + 4, j + 0, k + 20, Blocks.stonebrick);
		world.setBlock(i + 4, j + 0, k + 21, Blocks.stonebrick);
		world.setBlock(i + 4, j + 0, k + 22, Blocks.stonebrick);
		world.setBlock(i + 4, j + 0, k + 23, Blocks.stonebrick);
		world.setBlock(i + 4, j + 0, k + 24, Blocks.stonebrick);
		world.setBlock(i + 4, j + 0, k + 25, Blocks.stonebrick);
		world.setBlock(i + 4, j + 0, k + 26, Blocks.stonebrick);
		world.setBlock(i + 4, j + 0, k + 27, Blocks.stonebrick);
		world.setBlock(i + 4, j + 0, k + 28, Blocks.stonebrick);
		world.setBlock(i + 4, j + 0, k + 29, Blocks.stonebrick);
		world.setBlock(i + 4, j + 0, k + 30, Blocks.stonebrick);
		world.setBlock(i + 4, j + 0, k + 31, Blocks.stonebrick);
		world.setBlock(i + 4, j + 0, k + 32, Blocks.stonebrick);
		world.setBlock(i + 4, j + 0, k + 33, Blocks.stonebrick);
		world.setBlock(i + 4, j + 0, k + 34, Blocks.stonebrick);
		world.setBlock(i + 4, j + 0, k + 35, Blocks.stonebrick);
		world.setBlock(i + 4, j + 0, k + 36, Blocks.stonebrick);
		world.setBlock(i + 4, j + 0, k + 37, Blocks.stonebrick);
		world.setBlock(i + 4, j + 0, k + 38, Blocks.stonebrick);
		world.setBlock(i + 4, j + 0, k + 39, Blocks.stonebrick);
		world.setBlock(i + 4, j + 0, k + 40, Blocks.stonebrick);
		world.setBlock(i + 4, j + 0, k + 41, Blocks.stonebrick);
		world.setBlock(i + 4, j + 0, k + 42, Blocks.stonebrick);
		world.setBlock(i + 4, j + 0, k + 43, Blocks.stonebrick);
		world.setBlock(i + 4, j + 0, k + 44, Blocks.stonebrick);
		world.setBlock(i + 4, j + 1, k + 1, Blocks.stonebrick);
		world.setBlock(i + 4, j + 1, k + 11, Blocks.stonebrick);
		world.setBlock(i + 4, j + 1, k + 20, Blocks.stonebrick);
		world.setBlock(i + 4, j + 1, k + 25, Blocks.stonebrick);
		world.setBlock(i + 4, j + 1, k + 34, Blocks.stonebrick);
		world.setBlock(i + 4, j + 1, k + 44, Blocks.stonebrick);
		world.setBlock(i + 4, j + 2, k + 1, Blocks.stonebrick);
		world.setBlock(i + 4, j + 2, k + 11, Blocks.cobblestone_wall);
		world.setBlock(i + 4, j + 2, k + 20, Blocks.stonebrick);
		world.setBlock(i + 4, j + 2, k + 25, Blocks.stonebrick);
		world.setBlock(i + 4, j + 2, k + 44, Blocks.stonebrick);
		world.setBlock(i + 4, j + 3, k + 1, Blocks.stonebrick);
		world.setBlock(i + 4, j + 3, k + 20, Blocks.stonebrick);
		world.setBlock(i + 4, j + 3, k + 25, Blocks.stonebrick);
		world.setBlock(i + 4, j + 3, k + 44, Blocks.stonebrick);
		world.setBlock(i + 4, j + 4, k + 1, Blocks.stonebrick);
		world.setBlock(i + 4, j + 4, k + 20, Blocks.stonebrick);
		world.setBlock(i + 4, j + 4, k + 25, Blocks.stonebrick);
		world.setBlock(i + 4, j + 4, k + 44, Blocks.stonebrick);
		world.setBlock(i + 4, j + 5, k + 1, Blocks.stonebrick);
		world.setBlock(i + 4, j + 5, k + 2, Blocks.stonebrick);
		world.setBlock(i + 4, j + 5, k + 3, Blocks.stonebrick);
		world.setBlock(i + 4, j + 5, k + 4, Blocks.stonebrick);
		world.setBlock(i + 4, j + 5, k + 5, Blocks.stonebrick);
		world.setBlock(i + 4, j + 5, k + 6, Blocks.stonebrick);
		world.setBlock(i + 4, j + 5, k + 7, Blocks.stonebrick);
		world.setBlock(i + 4, j + 5, k + 8, Blocks.stonebrick);
		world.setBlock(i + 4, j + 5, k + 9, Blocks.stonebrick);
		world.setBlock(i + 4, j + 5, k + 10, Blocks.stonebrick);
		world.setBlock(i + 4, j + 5, k + 11, Blocks.stonebrick);
		world.setBlock(i + 4, j + 5, k + 12, Blocks.stonebrick);
		world.setBlock(i + 4, j + 5, k + 13, Blocks.stonebrick);
		world.setBlock(i + 4, j + 5, k + 14, Blocks.stonebrick);
		world.setBlock(i + 4, j + 5, k + 15, Blocks.stonebrick);
		world.setBlock(i + 4, j + 5, k + 16, Blocks.stonebrick);
		world.setBlock(i + 4, j + 5, k + 17, Blocks.stonebrick);
		world.setBlock(i + 4, j + 5, k + 18, Blocks.stonebrick);
		world.setBlock(i + 4, j + 5, k + 19, Blocks.stonebrick);
		world.setBlock(i + 4, j + 5, k + 20, Blocks.stonebrick);
		world.setBlock(i + 4, j + 5, k + 25, Blocks.stonebrick);
		world.setBlock(i + 4, j + 5, k + 26, Blocks.stonebrick);
		world.setBlock(i + 4, j + 5, k + 27, Blocks.stonebrick);
		world.setBlock(i + 4, j + 5, k + 28, Blocks.stonebrick);
		world.setBlock(i + 4, j + 5, k + 29, Blocks.stonebrick);
		world.setBlock(i + 4, j + 5, k + 30, Blocks.stonebrick);
		world.setBlock(i + 4, j + 5, k + 31, Blocks.stonebrick);
		world.setBlock(i + 4, j + 5, k + 32, Blocks.stonebrick);
		world.setBlock(i + 4, j + 5, k + 33, Blocks.stonebrick);
		world.setBlock(i + 4, j + 5, k + 34, Blocks.stonebrick);
		world.setBlock(i + 4, j + 5, k + 35, Blocks.stonebrick);
		world.setBlock(i + 4, j + 5, k + 36, Blocks.stonebrick);
		world.setBlock(i + 4, j + 5, k + 37, Blocks.stonebrick);
		world.setBlock(i + 4, j + 5, k + 38, Blocks.stonebrick);
		world.setBlock(i + 4, j + 5, k + 39, Blocks.stonebrick);
		world.setBlock(i + 4, j + 5, k + 40, Blocks.stonebrick);
		world.setBlock(i + 4, j + 5, k + 41, Blocks.stonebrick);
		world.setBlock(i + 4, j + 5, k + 42, Blocks.stonebrick);
		world.setBlock(i + 4, j + 5, k + 43, Blocks.stonebrick);
		world.setBlock(i + 4, j + 5, k + 44, Blocks.stonebrick);
		world.setBlock(i + 4, j + 6, k + 1, Blocks.stonebrick);
		world.setBlock(i + 4, j + 6, k + 20, Blocks.stonebrick);
		world.setBlock(i + 4, j + 6, k + 25, Blocks.stonebrick);
		world.setBlock(i + 4, j + 6, k + 36, Blocks.stonebrick);
		world.setBlock(i + 4, j + 6, k + 44, Blocks.stonebrick);
		world.setBlock(i + 4, j + 7, k + 1, Blocks.stonebrick);
		world.setBlock(i + 4, j + 7, k + 20, Blocks.stonebrick);
		world.setBlock(i + 4, j + 7, k + 25, Blocks.stonebrick);
		world.setBlock(i + 4, j + 7, k + 36, Blocks.stonebrick);
		world.setBlock(i + 4, j + 7, k + 44, Blocks.stonebrick);
		world.setBlock(i + 4, j + 8, k + 1, Blocks.stonebrick);
		world.setBlock(i + 4, j + 8, k + 20, Blocks.stonebrick);
		world.setBlock(i + 4, j + 8, k + 25, Blocks.stonebrick);
		world.setBlock(i + 4, j + 8, k + 36, Blocks.stonebrick);
		world.setBlock(i + 4, j + 8, k + 44, Blocks.stonebrick);
		world.setBlock(i + 4, j + 9, k + 1, Blocks.stonebrick);
		world.setBlock(i + 4, j + 9, k + 20, Blocks.stonebrick);
		world.setBlock(i + 4, j + 9, k + 25, Blocks.stonebrick);
		world.setBlock(i + 4, j + 9, k + 36, Blocks.stonebrick);
		world.setBlock(i + 4, j + 9, k + 44, Blocks.stonebrick);
		world.setBlock(i + 4, j + 10, k + 1, Blocks.stonebrick);
		world.setBlock(i + 4, j + 10, k + 2, Blocks.stonebrick);
		world.setBlock(i + 4, j + 10, k + 3, Blocks.stonebrick);
		world.setBlock(i + 4, j + 10, k + 4, Blocks.stonebrick);
		world.setBlock(i + 4, j + 10, k + 5, Blocks.stonebrick);
		world.setBlock(i + 4, j + 10, k + 6, Blocks.stonebrick);
		world.setBlock(i + 4, j + 10, k + 7, Blocks.stonebrick);
		world.setBlock(i + 4, j + 10, k + 8, Blocks.stonebrick);
		world.setBlock(i + 4, j + 10, k + 9, Blocks.stonebrick);
		world.setBlock(i + 4, j + 10, k + 10, Blocks.stonebrick);
		world.setBlock(i + 4, j + 10, k + 11, Blocks.stonebrick);
		world.setBlock(i + 4, j + 10, k + 12, Blocks.stonebrick);
		world.setBlock(i + 4, j + 10, k + 13, Blocks.stonebrick);
		world.setBlock(i + 4, j + 10, k + 14, Blocks.stonebrick);
		world.setBlock(i + 4, j + 10, k + 15, Blocks.stonebrick);
		world.setBlock(i + 4, j + 10, k + 16, Blocks.stonebrick);
		world.setBlock(i + 4, j + 10, k + 17, Blocks.stonebrick);
		world.setBlock(i + 4, j + 10, k + 18, Blocks.stonebrick);
		world.setBlock(i + 4, j + 10, k + 19, Blocks.stonebrick);
		world.setBlock(i + 4, j + 10, k + 20, Blocks.stonebrick);
		world.setBlock(i + 4, j + 10, k + 25, Blocks.stonebrick);
		world.setBlock(i + 4, j + 10, k + 26, Blocks.stonebrick);
		world.setBlock(i + 4, j + 10, k + 27, Blocks.stonebrick);
		world.setBlock(i + 4, j + 10, k + 28, Blocks.stonebrick);
		world.setBlock(i + 4, j + 10, k + 29, Blocks.stonebrick);
		world.setBlock(i + 4, j + 10, k + 30, Blocks.stonebrick);
		world.setBlock(i + 4, j + 10, k + 31, Blocks.stonebrick);
		world.setBlock(i + 4, j + 10, k + 32, Blocks.stonebrick);
		world.setBlock(i + 4, j + 10, k + 33, Blocks.stonebrick);
		world.setBlock(i + 4, j + 10, k + 34, Blocks.stonebrick);
		world.setBlock(i + 4, j + 10, k + 35, Blocks.stonebrick);
		world.setBlock(i + 4, j + 10, k + 36, Blocks.stonebrick);
		world.setBlock(i + 4, j + 10, k + 37, Blocks.stonebrick);
		world.setBlock(i + 4, j + 10, k + 38, Blocks.stonebrick);
		world.setBlock(i + 4, j + 10, k + 39, Blocks.stonebrick);
		world.setBlock(i + 4, j + 10, k + 40, Blocks.stonebrick);
		world.setBlock(i + 4, j + 10, k + 41, Blocks.stonebrick);
		world.setBlock(i + 4, j + 10, k + 42, Blocks.stonebrick);
		world.setBlock(i + 4, j + 10, k + 43, Blocks.stonebrick);
		world.setBlock(i + 4, j + 10, k + 44, Blocks.stonebrick);
		world.setBlock(i + 4, j + 11, k + 1, Blocks.stonebrick);
		world.setBlock(i + 4, j + 11, k + 11, Blocks.stonebrick);
		world.setBlock(i + 4, j + 11, k + 20, Blocks.stonebrick);
		world.setBlock(i + 4, j + 11, k + 25, Blocks.stonebrick);
		world.setBlock(i + 4, j + 11, k + 31, Blocks.stonebrick);
		world.setBlock(i + 4, j + 11, k + 42, Blocks.stonebrick);
		world.setBlock(i + 4, j + 11, k + 43, Blocks.stonebrick);
		world.setBlock(i + 4, j + 11, k + 44, Blocks.stonebrick);
		world.setBlock(i + 4, j + 12, k + 1, Blocks.stonebrick);
		world.setBlock(i + 4, j + 12, k + 11, Blocks.stonebrick);
		world.setBlock(i + 4, j + 12, k + 20, Blocks.stonebrick);
		world.setBlock(i + 4, j + 12, k + 25, Blocks.stonebrick);
		world.setBlock(i + 4, j + 12, k + 44, Blocks.stonebrick);
		world.setBlock(i + 4, j + 13, k + 1, Blocks.stonebrick);
		world.setBlock(i + 4, j + 13, k + 11, Blocks.stonebrick);
		world.setBlock(i + 4, j + 13, k + 20, Blocks.stonebrick);
		world.setBlock(i + 4, j + 13, k + 25, Blocks.stonebrick);
		world.setBlock(i + 4, j + 13, k + 44, Blocks.stonebrick);
		world.setBlock(i + 4, j + 14, k + 1, Blocks.stonebrick);
		world.setBlock(i + 4, j + 14, k + 20, Blocks.stonebrick);
		world.setBlock(i + 4, j + 14, k + 25, Blocks.stonebrick);
		world.setBlock(i + 4, j + 14, k + 44, Blocks.stonebrick);
		world.setBlock(i + 4, j + 15, k + 1, Blocks.stonebrick);
		world.setBlock(i + 4, j + 15, k + 2, Blocks.stonebrick);
		world.setBlock(i + 4, j + 15, k + 3, Blocks.stonebrick);
		world.setBlock(i + 4, j + 15, k + 4, Blocks.stonebrick);
		world.setBlock(i + 4, j + 15, k + 5, Blocks.stonebrick);
		world.setBlock(i + 4, j + 15, k + 6, Blocks.stonebrick);
		world.setBlock(i + 4, j + 15, k + 7, Blocks.stonebrick);
		world.setBlock(i + 4, j + 15, k + 8, Blocks.stonebrick);
		world.setBlock(i + 4, j + 15, k + 9, Blocks.stonebrick);
		world.setBlock(i + 4, j + 15, k + 10, Blocks.stonebrick);
		world.setBlock(i + 4, j + 15, k + 11, Blocks.stonebrick);
		world.setBlock(i + 4, j + 15, k + 12, Blocks.stonebrick);
		world.setBlock(i + 4, j + 15, k + 13, Blocks.stonebrick);
		world.setBlock(i + 4, j + 15, k + 14, Blocks.stonebrick);
		world.setBlock(i + 4, j + 15, k + 15, Blocks.stonebrick);
		world.setBlock(i + 4, j + 15, k + 16, Blocks.stonebrick);
		world.setBlock(i + 4, j + 15, k + 17, Blocks.stonebrick);
		world.setBlock(i + 4, j + 15, k + 18, Blocks.stonebrick);
		world.setBlock(i + 4, j + 15, k + 19, Blocks.stonebrick);
		world.setBlock(i + 4, j + 15, k + 20, Blocks.stonebrick);
		world.setBlock(i + 4, j + 15, k + 25, Blocks.stonebrick);
		world.setBlock(i + 4, j + 15, k + 26, Blocks.stonebrick);
		world.setBlock(i + 4, j + 15, k + 27, Blocks.stonebrick);
		world.setBlock(i + 4, j + 15, k + 28, Blocks.stonebrick);
		world.setBlock(i + 4, j + 15, k + 29, Blocks.stonebrick);
		world.setBlock(i + 4, j + 15, k + 30, Blocks.stonebrick);
		world.setBlock(i + 4, j + 15, k + 31, Blocks.stonebrick);
		world.setBlock(i + 4, j + 15, k + 32, Blocks.stonebrick);
		world.setBlock(i + 4, j + 15, k + 33, Blocks.stonebrick);
		world.setBlock(i + 4, j + 15, k + 34, Blocks.stonebrick);
		world.setBlock(i + 4, j + 15, k + 35, Blocks.stonebrick);
		world.setBlock(i + 4, j + 15, k + 36, Blocks.stonebrick);
		world.setBlock(i + 4, j + 15, k + 37, Blocks.stonebrick);
		world.setBlock(i + 4, j + 15, k + 38, Blocks.stonebrick);
		world.setBlock(i + 4, j + 15, k + 39, Blocks.stonebrick);
		world.setBlock(i + 4, j + 15, k + 40, Blocks.stonebrick);
		world.setBlock(i + 4, j + 15, k + 41, Blocks.stonebrick);
		world.setBlock(i + 4, j + 15, k + 42, Blocks.stonebrick);
		world.setBlock(i + 4, j + 15, k + 43, Blocks.stonebrick);
		world.setBlock(i + 4, j + 15, k + 44, Blocks.stonebrick);
		world.setBlock(i + 4, j + 16, k + 1, Blocks.stonebrick);
		world.setBlock(i + 4, j + 16, k + 20, Blocks.stonebrick);
		world.setBlock(i + 4, j + 16, k + 25, Blocks.stonebrick);
		world.setBlock(i + 4, j + 16, k + 44, Blocks.stonebrick);
		world.setBlock(i + 5, j + 0, k + 0, Blocks.stonebrick);
		world.setBlock(i + 5, j + 0, k + 1, Blocks.stonebrick);
		world.setBlock(i + 5, j + 0, k + 2, Blocks.stonebrick);
		world.setBlock(i + 5, j + 0, k + 3, Blocks.stonebrick);
		world.setBlock(i + 5, j + 0, k + 4, Blocks.stonebrick);
		world.setBlock(i + 5, j + 0, k + 5, Blocks.stonebrick);
		world.setBlock(i + 5, j + 0, k + 6, Blocks.stonebrick);
		world.setBlock(i + 5, j + 0, k + 7, Blocks.stonebrick);
		world.setBlock(i + 5, j + 0, k + 8, Blocks.stonebrick);
		world.setBlock(i + 5, j + 0, k + 9, Blocks.stonebrick);
		world.setBlock(i + 5, j + 0, k + 10, Blocks.stonebrick);
		world.setBlock(i + 5, j + 0, k + 11, Blocks.stonebrick);
		world.setBlock(i + 5, j + 0, k + 12, Blocks.stonebrick);
		world.setBlock(i + 5, j + 0, k + 13, Blocks.stonebrick);
		world.setBlock(i + 5, j + 0, k + 14, Blocks.stonebrick);
		world.setBlock(i + 5, j + 0, k + 15, Blocks.stonebrick);
		world.setBlock(i + 5, j + 0, k + 16, Blocks.stonebrick);
		world.setBlock(i + 5, j + 0, k + 17, Blocks.stonebrick);
		world.setBlock(i + 5, j + 0, k + 18, Blocks.stonebrick);
		world.setBlock(i + 5, j + 0, k + 19, Blocks.stonebrick);
		world.setBlock(i + 5, j + 0, k + 20, Blocks.stonebrick);
		world.setBlock(i + 5, j + 0, k + 21, Blocks.stonebrick);
		world.setBlock(i + 5, j + 0, k + 22, Blocks.stonebrick);
		world.setBlock(i + 5, j + 0, k + 23, Blocks.stonebrick);
		world.setBlock(i + 5, j + 0, k + 24, Blocks.stonebrick);
		world.setBlock(i + 5, j + 0, k + 25, Blocks.stonebrick);
		world.setBlock(i + 5, j + 0, k + 26, Blocks.stonebrick);
		world.setBlock(i + 5, j + 0, k + 27, Blocks.stonebrick);
		world.setBlock(i + 5, j + 0, k + 28, Blocks.stonebrick);
		world.setBlock(i + 5, j + 0, k + 29, Blocks.stonebrick);
		world.setBlock(i + 5, j + 0, k + 30, Blocks.stonebrick);
		world.setBlock(i + 5, j + 0, k + 31, Blocks.stonebrick);
		world.setBlock(i + 5, j + 0, k + 32, Blocks.stonebrick);
		world.setBlock(i + 5, j + 0, k + 33, Blocks.stonebrick);
		world.setBlock(i + 5, j + 0, k + 34, Blocks.stonebrick);
		world.setBlock(i + 5, j + 0, k + 35, Blocks.stonebrick);
		world.setBlock(i + 5, j + 0, k + 36, Blocks.stonebrick);
		world.setBlock(i + 5, j + 0, k + 37, Blocks.stonebrick);
		world.setBlock(i + 5, j + 0, k + 38, Blocks.stonebrick);
		world.setBlock(i + 5, j + 0, k + 39, Blocks.stonebrick);
		world.setBlock(i + 5, j + 0, k + 40, Blocks.stonebrick);
		world.setBlock(i + 5, j + 0, k + 41, Blocks.stonebrick);
		world.setBlock(i + 5, j + 0, k + 42, Blocks.stonebrick);
		world.setBlock(i + 5, j + 0, k + 43, Blocks.stonebrick);
		world.setBlock(i + 5, j + 0, k + 44, Blocks.stonebrick);
		world.setBlock(i + 5, j + 0, k + 45, Blocks.stonebrick);
		world.setBlock(i + 5, j + 1, k + 0, Blocks.stonebrick);
		world.setBlock(i + 5, j + 1, k + 20, Blocks.stonebrick);
		world.setBlock(i + 5, j + 1, k + 21, Blocks.stonebrick);
		world.setBlock(i + 5, j + 1, k + 24, Blocks.stonebrick);
		world.setBlock(i + 5, j + 1, k + 25, Blocks.stonebrick);
		world.setBlock(i + 5, j + 1, k + 31, Blocks.fence);
		world.setBlock(i + 5, j + 1, k + 45, Blocks.stonebrick);
		world.setBlock(i + 5, j + 2, k + 0, Blocks.stonebrick);
		world.setBlock(i + 5, j + 2, k + 20, Blocks.stonebrick);
		world.setBlock(i + 5, j + 2, k + 21, Blocks.stonebrick);
		world.setBlock(i + 5, j + 2, k + 24, Blocks.stonebrick);
		world.setBlock(i + 5, j + 2, k + 25, Blocks.stonebrick);
		world.setBlock(i + 5, j + 2, k + 45, Blocks.stonebrick);
		world.setBlock(i + 5, j + 3, k + 0, Blocks.stonebrick);
		world.setBlock(i + 5, j + 3, k + 20, Blocks.stonebrick);
		world.setBlock(i + 5, j + 3, k + 21, Blocks.stonebrick);
		world.setBlock(i + 5, j + 3, k + 22, Blocks.stonebrick);
		world.setBlock(i + 5, j + 3, k + 23, Blocks.stonebrick);
		world.setBlock(i + 5, j + 3, k + 24, Blocks.stonebrick);
		world.setBlock(i + 5, j + 3, k + 25, Blocks.stonebrick);
		world.setBlock(i + 5, j + 3, k + 45, Blocks.stonebrick);
		world.setBlock(i + 5, j + 4, k + 0, Blocks.stonebrick);
		world.setBlock(i + 5, j + 4, k + 20, Blocks.stonebrick);
		world.setBlock(i + 5, j + 4, k + 21, Blocks.stonebrick);
		world.setBlock(i + 5, j + 4, k + 22, Blocks.stonebrick);
		world.setBlock(i + 5, j + 4, k + 23, Blocks.stonebrick);
		world.setBlock(i + 5, j + 4, k + 24, Blocks.stonebrick);
		world.setBlock(i + 5, j + 4, k + 25, Blocks.stonebrick);
		world.setBlock(i + 5, j + 4, k + 45, Blocks.stonebrick);
		world.setBlock(i + 5, j + 5, k + 0, Blocks.stonebrick);
		world.setBlock(i + 5, j + 5, k + 1, Blocks.stonebrick);
		world.setBlock(i + 5, j + 5, k + 2, Blocks.stonebrick);
		world.setBlock(i + 5, j + 5, k + 3, Blocks.stonebrick);
		world.setBlock(i + 5, j + 5, k + 4, Blocks.stonebrick);
		world.setBlock(i + 5, j + 5, k + 5, Blocks.stonebrick);
		world.setBlock(i + 5, j + 5, k + 6, Blocks.stonebrick);
		world.setBlock(i + 5, j + 5, k + 7, Blocks.stonebrick);
		world.setBlock(i + 5, j + 5, k + 8, Blocks.stonebrick);
		world.setBlock(i + 5, j + 5, k + 9, Blocks.stonebrick);
		world.setBlock(i + 5, j + 5, k + 10, Blocks.stonebrick);
		world.setBlock(i + 5, j + 5, k + 11, Blocks.stonebrick);
		world.setBlock(i + 5, j + 5, k + 12, Blocks.stonebrick);
		world.setBlock(i + 5, j + 5, k + 13, Blocks.stonebrick);
		world.setBlock(i + 5, j + 5, k + 14, Blocks.stonebrick);
		world.setBlock(i + 5, j + 5, k + 15, Blocks.stonebrick);
		world.setBlock(i + 5, j + 5, k + 16, Blocks.stonebrick);
		world.setBlock(i + 5, j + 5, k + 17, Blocks.stonebrick);
		world.setBlock(i + 5, j + 5, k + 18, Blocks.stonebrick);
		world.setBlock(i + 5, j + 5, k + 19, Blocks.stonebrick);
		world.setBlock(i + 5, j + 5, k + 20, Blocks.stonebrick);
		world.setBlock(i + 5, j + 5, k + 21, Blocks.stonebrick);
		world.setBlock(i + 5, j + 5, k + 22, Blocks.stonebrick);
		world.setBlock(i + 5, j + 5, k + 23, Blocks.stonebrick);
		world.setBlock(i + 5, j + 5, k + 24, Blocks.stonebrick);
		world.setBlock(i + 5, j + 5, k + 25, Blocks.stonebrick);
		world.setBlock(i + 5, j + 5, k + 26, Blocks.stonebrick);
		world.setBlock(i + 5, j + 5, k + 27, Blocks.stonebrick);
		world.setBlock(i + 5, j + 5, k + 28, Blocks.stonebrick);
		world.setBlock(i + 5, j + 5, k + 29, Blocks.stonebrick);
		world.setBlock(i + 5, j + 5, k + 30, Blocks.stonebrick);
		world.setBlock(i + 5, j + 5, k + 31, Blocks.stonebrick);
		world.setBlock(i + 5, j + 5, k + 32, Blocks.stonebrick);
		world.setBlock(i + 5, j + 5, k + 33, Blocks.stonebrick);
		world.setBlock(i + 5, j + 5, k + 34, Blocks.stonebrick);
		world.setBlock(i + 5, j + 5, k + 35, Blocks.stonebrick);
		world.setBlock(i + 5, j + 5, k + 36, Blocks.stonebrick);
		world.setBlock(i + 5, j + 5, k + 37, Blocks.stonebrick);
		world.setBlock(i + 5, j + 5, k + 38, Blocks.stonebrick);
		world.setBlock(i + 5, j + 5, k + 39, Blocks.stonebrick);
		world.setBlock(i + 5, j + 5, k + 40, Blocks.stonebrick);
		world.setBlock(i + 5, j + 5, k + 41, Blocks.stonebrick);
		world.setBlock(i + 5, j + 5, k + 42, Blocks.stonebrick);
		world.setBlock(i + 5, j + 5, k + 43, Blocks.stonebrick);
		world.setBlock(i + 5, j + 5, k + 44, Blocks.stonebrick);
		world.setBlock(i + 5, j + 5, k + 45, Blocks.stonebrick);
		world.setBlock(i + 5, j + 6, k + 0, Blocks.stonebrick);
		world.setBlock(i + 5, j + 6, k + 21, Blocks.stonebrick);
		world.setBlock(i + 5, j + 6, k + 22, Blocks.stonebrick);
		world.setBlock(i + 5, j + 6, k + 23, Blocks.stonebrick);
		world.setBlock(i + 5, j + 6, k + 24, Blocks.stonebrick);
		world.setBlock(i + 5, j + 6, k + 25, Blocks.stonebrick);
		world.setBlock(i + 5, j + 6, k + 36, Blocks.stonebrick);
		world.setBlock(i + 5, j + 6, k + 45, Blocks.stonebrick);
		world.setBlock(i + 5, j + 7, k + 0, Blocks.stonebrick);
		world.setBlock(i + 5, j + 7, k + 21, Blocks.stonebrick);
		world.setBlock(i + 5, j + 7, k + 22, Blocks.stonebrick);
		world.setBlock(i + 5, j + 7, k + 23, Blocks.stonebrick);
		world.setBlock(i + 5, j + 7, k + 24, Blocks.stonebrick);
		world.setBlock(i + 5, j + 7, k + 25, Blocks.stonebrick);
		world.setBlock(i + 5, j + 7, k + 36, Blocks.stonebrick);
		world.setBlock(i + 5, j + 7, k + 45, Blocks.stonebrick);
		world.setBlock(i + 5, j + 8, k + 0, Blocks.stonebrick);
		world.setBlock(i + 5, j + 8, k + 21, Blocks.stonebrick);
		world.setBlock(i + 5, j + 8, k + 22, Blocks.stonebrick);
		world.setBlock(i + 5, j + 8, k + 23, Blocks.stonebrick);
		world.setBlock(i + 5, j + 8, k + 24, Blocks.stonebrick);
		world.setBlock(i + 5, j + 8, k + 25, Blocks.stonebrick);
		world.setBlock(i + 5, j + 8, k + 36, Blocks.stonebrick);
		world.setBlock(i + 5, j + 8, k + 45, Blocks.stonebrick);
		world.setBlock(i + 5, j + 9, k + 0, Blocks.stonebrick);
		world.setBlock(i + 5, j + 9, k + 21, Blocks.stonebrick);
		world.setBlock(i + 5, j + 9, k + 22, Blocks.stonebrick);
		world.setBlock(i + 5, j + 9, k + 23, Blocks.stonebrick);
		world.setBlock(i + 5, j + 9, k + 24, Blocks.stonebrick);
		world.setBlock(i + 5, j + 9, k + 25, Blocks.stonebrick);
		world.setBlock(i + 5, j + 9, k + 36, Blocks.stonebrick);
		world.setBlock(i + 5, j + 9, k + 45, Blocks.stonebrick);
		world.setBlock(i + 5, j + 10, k + 0, Blocks.stonebrick);
		world.setBlock(i + 5, j + 10, k + 1, Blocks.stonebrick);
		world.setBlock(i + 5, j + 10, k + 2, Blocks.stonebrick);
		world.setBlock(i + 5, j + 10, k + 3, Blocks.stonebrick);
		world.setBlock(i + 5, j + 10, k + 4, Blocks.stonebrick);
		world.setBlock(i + 5, j + 10, k + 5, Blocks.stonebrick);
		world.setBlock(i + 5, j + 10, k + 6, Blocks.stonebrick);
		world.setBlock(i + 5, j + 10, k + 7, Blocks.stonebrick);
		world.setBlock(i + 5, j + 10, k + 8, Blocks.stonebrick);
		world.setBlock(i + 5, j + 10, k + 9, Blocks.stonebrick);
		world.setBlock(i + 5, j + 10, k + 10, Blocks.stonebrick);
		world.setBlock(i + 5, j + 10, k + 11, Blocks.stonebrick);
		world.setBlock(i + 5, j + 10, k + 12, Blocks.stonebrick);
		world.setBlock(i + 5, j + 10, k + 13, Blocks.stonebrick);
		world.setBlock(i + 5, j + 10, k + 14, Blocks.stonebrick);
		world.setBlock(i + 5, j + 10, k + 15, Blocks.stonebrick);
		world.setBlock(i + 5, j + 10, k + 16, Blocks.stonebrick);
		world.setBlock(i + 5, j + 10, k + 17, Blocks.stonebrick);
		world.setBlock(i + 5, j + 10, k + 18, Blocks.stonebrick);
		world.setBlock(i + 5, j + 10, k + 19, Blocks.stonebrick);
		world.setBlock(i + 5, j + 10, k + 20, Blocks.stonebrick);
		world.setBlock(i + 5, j + 10, k + 21, Blocks.stonebrick);
		world.setBlock(i + 5, j + 10, k + 22, Blocks.stonebrick);
		world.setBlock(i + 5, j + 10, k + 23, Blocks.stonebrick);
		world.setBlock(i + 5, j + 10, k + 24, Blocks.stonebrick);
		world.setBlock(i + 5, j + 10, k + 25, Blocks.stonebrick);
		world.setBlock(i + 5, j + 10, k + 26, Blocks.stonebrick);
		world.setBlock(i + 5, j + 10, k + 27, Blocks.stonebrick);
		world.setBlock(i + 5, j + 10, k + 28, Blocks.stonebrick);
		world.setBlock(i + 5, j + 10, k + 29, Blocks.stonebrick);
		world.setBlock(i + 5, j + 10, k + 30, Blocks.stonebrick);
		world.setBlock(i + 5, j + 10, k + 31, Blocks.stonebrick);
		world.setBlock(i + 5, j + 10, k + 32, Blocks.stonebrick);
		world.setBlock(i + 5, j + 10, k + 33, Blocks.stonebrick);
		world.setBlock(i + 5, j + 10, k + 34, Blocks.stonebrick);
		world.setBlock(i + 5, j + 10, k + 35, Blocks.stonebrick);
		world.setBlock(i + 5, j + 10, k + 36, Blocks.stonebrick);
		world.setBlock(i + 5, j + 10, k + 37, Blocks.stonebrick);
		world.setBlock(i + 5, j + 10, k + 38, Blocks.stonebrick);
		world.setBlock(i + 5, j + 10, k + 39, Blocks.stonebrick);
		world.setBlock(i + 5, j + 10, k + 40, Blocks.stonebrick);
		world.setBlock(i + 5, j + 10, k + 41, Blocks.stonebrick);
		world.setBlock(i + 5, j + 10, k + 42, Blocks.stonebrick);
		world.setBlock(i + 5, j + 10, k + 43, Blocks.stonebrick);
		world.setBlock(i + 5, j + 10, k + 44, Blocks.stonebrick);
		world.setBlock(i + 5, j + 10, k + 45, Blocks.stonebrick);
		world.setBlock(i + 5, j + 11, k + 0, Blocks.stonebrick);
		world.setBlock(i + 5, j + 11, k + 11, Blocks.stonebrick);
		world.setBlock(i + 5, j + 11, k + 21, Blocks.stonebrick);
		world.setBlock(i + 5, j + 11, k + 22, Blocks.stonebrick);
		world.setBlock(i + 5, j + 11, k + 23, Blocks.stonebrick);
		world.setBlock(i + 5, j + 11, k + 24, Blocks.stonebrick);
		world.setBlock(i + 5, j + 11, k + 31, Blocks.stonebrick);
		world.setBlock(i + 5, j + 11, k + 45, Blocks.stonebrick);
		world.setBlock(i + 5, j + 12, k + 0, Blocks.stonebrick);
		world.setBlock(i + 5, j + 12, k + 21, Blocks.stonebrick);
		world.setBlock(i + 5, j + 12, k + 22, Blocks.stonebrick);
		world.setBlock(i + 5, j + 12, k + 23, Blocks.stonebrick);
		world.setBlock(i + 5, j + 12, k + 24, Blocks.stonebrick);
		world.setBlock(i + 5, j + 12, k + 45, Blocks.stonebrick);
		world.setBlock(i + 5, j + 13, k + 0, Blocks.stonebrick);
		world.setBlock(i + 5, j + 13, k + 21, Blocks.stonebrick);
		world.setBlock(i + 5, j + 13, k + 22, Blocks.stonebrick);
		world.setBlock(i + 5, j + 13, k + 23, Blocks.stonebrick);
		world.setBlock(i + 5, j + 13, k + 24, Blocks.stonebrick);
		world.setBlock(i + 5, j + 13, k + 45, Blocks.stonebrick);
		world.setBlock(i + 5, j + 14, k + 0, Blocks.stonebrick);
		world.setBlock(i + 5, j + 14, k + 21, Blocks.stonebrick);
		world.setBlock(i + 5, j + 14, k + 22, Blocks.stonebrick);
		world.setBlock(i + 5, j + 14, k + 23, Blocks.stonebrick);
		world.setBlock(i + 5, j + 14, k + 24, Blocks.stonebrick);
		world.setBlock(i + 5, j + 14, k + 45, Blocks.stonebrick);
		world.setBlock(i + 5, j + 15, k + 0, Blocks.stonebrick);
		world.setBlock(i + 5, j + 15, k + 1, Blocks.stonebrick);
		world.setBlock(i + 5, j + 15, k + 2, Blocks.stonebrick);
		world.setBlock(i + 5, j + 15, k + 3, Blocks.stonebrick);
		world.setBlock(i + 5, j + 15, k + 4, Blocks.stonebrick);
		world.setBlock(i + 5, j + 15, k + 5, Blocks.stonebrick);
		world.setBlock(i + 5, j + 15, k + 6, Blocks.stonebrick);
		world.setBlock(i + 5, j + 15, k + 7, Blocks.stonebrick);
		world.setBlock(i + 5, j + 15, k + 8, Blocks.stonebrick);
		world.setBlock(i + 5, j + 15, k + 9, Blocks.stonebrick);
		world.setBlock(i + 5, j + 15, k + 10, Blocks.stonebrick);
		world.setBlock(i + 5, j + 15, k + 11, Blocks.stonebrick);
		world.setBlock(i + 5, j + 15, k + 12, Blocks.stonebrick);
		world.setBlock(i + 5, j + 15, k + 13, Blocks.stonebrick);
		world.setBlock(i + 5, j + 15, k + 14, Blocks.stonebrick);
		world.setBlock(i + 5, j + 15, k + 15, Blocks.stonebrick);
		world.setBlock(i + 5, j + 15, k + 16, Blocks.stonebrick);
		world.setBlock(i + 5, j + 15, k + 17, Blocks.stonebrick);
		world.setBlock(i + 5, j + 15, k + 18, Blocks.stonebrick);
		world.setBlock(i + 5, j + 15, k + 19, Blocks.stonebrick);
		world.setBlock(i + 5, j + 15, k + 20, Blocks.stonebrick);
		world.setBlock(i + 5, j + 15, k + 21, Blocks.stonebrick);
		world.setBlock(i + 5, j + 15, k + 22, Blocks.stonebrick);
		world.setBlock(i + 5, j + 15, k + 23, Blocks.stonebrick);
		world.setBlock(i + 5, j + 15, k + 24, Blocks.stonebrick);
		world.setBlock(i + 5, j + 15, k + 25, Blocks.stonebrick);
		world.setBlock(i + 5, j + 15, k + 26, Blocks.stonebrick);
		world.setBlock(i + 5, j + 15, k + 27, Blocks.stonebrick);
		world.setBlock(i + 5, j + 15, k + 28, Blocks.stonebrick);
		world.setBlock(i + 5, j + 15, k + 29, Blocks.stonebrick);
		world.setBlock(i + 5, j + 15, k + 30, Blocks.stonebrick);
		world.setBlock(i + 5, j + 15, k + 31, Blocks.stonebrick);
		world.setBlock(i + 5, j + 15, k + 32, Blocks.stonebrick);
		world.setBlock(i + 5, j + 15, k + 33, Blocks.stonebrick);
		world.setBlock(i + 5, j + 15, k + 34, Blocks.stonebrick);
		world.setBlock(i + 5, j + 15, k + 35, Blocks.stonebrick);
		world.setBlock(i + 5, j + 15, k + 36, Blocks.stonebrick);
		world.setBlock(i + 5, j + 15, k + 37, Blocks.stonebrick);
		world.setBlock(i + 5, j + 15, k + 38, Blocks.stonebrick);
		world.setBlock(i + 5, j + 15, k + 39, Blocks.stonebrick);
		world.setBlock(i + 5, j + 15, k + 40, Blocks.stonebrick);
		world.setBlock(i + 5, j + 15, k + 41, Blocks.stonebrick);
		world.setBlock(i + 5, j + 15, k + 42, Blocks.stonebrick);
		world.setBlock(i + 5, j + 15, k + 43, Blocks.stonebrick);
		world.setBlock(i + 5, j + 15, k + 44, Blocks.stonebrick);
		world.setBlock(i + 5, j + 15, k + 45, Blocks.stonebrick);
		world.setBlock(i + 5, j + 16, k + 0, Blocks.stonebrick);
		world.setBlock(i + 5, j + 16, k + 21, Blocks.stonebrick);
		world.setBlock(i + 5, j + 16, k + 22, Blocks.stonebrick);
		world.setBlock(i + 5, j + 16, k + 23, Blocks.stonebrick);
		world.setBlock(i + 5, j + 16, k + 24, Blocks.stonebrick);
		world.setBlock(i + 5, j + 16, k + 45, Blocks.stonebrick);
		world.setBlock(i + 6, j + 0, k + 0, Blocks.stonebrick);
		world.setBlock(i + 6, j + 0, k + 1, Blocks.stonebrick);
		world.setBlock(i + 6, j + 0, k + 2, Blocks.stonebrick);
		world.setBlock(i + 6, j + 0, k + 3, Blocks.stonebrick);
		world.setBlock(i + 6, j + 0, k + 4, Blocks.stonebrick);
		world.setBlock(i + 6, j + 0, k + 5, Blocks.stonebrick);
		world.setBlock(i + 6, j + 0, k + 6, Blocks.stonebrick);
		world.setBlock(i + 6, j + 0, k + 7, Blocks.stonebrick);
		world.setBlock(i + 6, j + 0, k + 8, Blocks.stonebrick);
		world.setBlock(i + 6, j + 0, k + 9, Blocks.stonebrick);
		world.setBlock(i + 6, j + 0, k + 10, Blocks.stonebrick);
		world.setBlock(i + 6, j + 0, k + 11, Blocks.stonebrick);
		world.setBlock(i + 6, j + 0, k + 12, Blocks.stonebrick);
		world.setBlock(i + 6, j + 0, k + 13, Blocks.stonebrick);
		world.setBlock(i + 6, j + 0, k + 14, Blocks.stonebrick);
		world.setBlock(i + 6, j + 0, k + 15, Blocks.stonebrick);
		world.setBlock(i + 6, j + 0, k + 16, Blocks.stonebrick);
		world.setBlock(i + 6, j + 0, k + 17, Blocks.stonebrick);
		world.setBlock(i + 6, j + 0, k + 18, Blocks.stonebrick);
		world.setBlock(i + 6, j + 0, k + 19, Blocks.stonebrick);
		world.setBlock(i + 6, j + 0, k + 20, Blocks.stonebrick);
		world.setBlock(i + 6, j + 0, k + 21, Blocks.stonebrick);
		world.setBlock(i + 6, j + 0, k + 22, Blocks.stonebrick);
		world.setBlock(i + 6, j + 0, k + 23, Blocks.stonebrick);
		world.setBlock(i + 6, j + 0, k + 24, Blocks.stonebrick);
		world.setBlock(i + 6, j + 0, k + 25, Blocks.stonebrick);
		world.setBlock(i + 6, j + 0, k + 26, Blocks.stonebrick);
		world.setBlock(i + 6, j + 0, k + 27, Blocks.stonebrick);
		world.setBlock(i + 6, j + 0, k + 28, Blocks.stonebrick);
		world.setBlock(i + 6, j + 0, k + 29, Blocks.stonebrick);
		world.setBlock(i + 6, j + 0, k + 30, Blocks.stonebrick);
		world.setBlock(i + 6, j + 0, k + 31, Blocks.stonebrick);
		world.setBlock(i + 6, j + 0, k + 32, Blocks.stonebrick);
		world.setBlock(i + 6, j + 0, k + 33, Blocks.stonebrick);
		world.setBlock(i + 6, j + 0, k + 34, Blocks.stonebrick);
		world.setBlock(i + 6, j + 0, k + 35, Blocks.stonebrick);
		world.setBlock(i + 6, j + 0, k + 36, Blocks.stonebrick);
		world.setBlock(i + 6, j + 0, k + 37, Blocks.stonebrick);
		world.setBlock(i + 6, j + 0, k + 38, Blocks.stonebrick);
		world.setBlock(i + 6, j + 0, k + 39, Blocks.stonebrick);
		world.setBlock(i + 6, j + 0, k + 40, Blocks.stonebrick);
		world.setBlock(i + 6, j + 0, k + 41, Blocks.stonebrick);
		world.setBlock(i + 6, j + 0, k + 42, Blocks.stonebrick);
		world.setBlock(i + 6, j + 0, k + 43, Blocks.stonebrick);
		world.setBlock(i + 6, j + 0, k + 44, Blocks.stonebrick);
		world.setBlock(i + 6, j + 0, k + 45, Blocks.stonebrick);
		world.setBlock(i + 6, j + 1, k + 0, Blocks.stonebrick);
		world.setBlock(i + 6, j + 1, k + 1, Blocks.crafting_table);
		world.setBlock(i + 6, j + 1, k + 6, Blocks.mob_spawner);
		TileEntityMobSpawner var19 = (TileEntityMobSpawner)world.getTileEntity(i + 6, j + 1, k + 6);

        if (var19 != null)
        {
            NBTTagCompound n = new NBTTagCompound();
            n.setString("EntityId", "CrawlingHand");
            n.setShort("Delay", (short) 0);
            n.setShort("MinSpawnDelay", (short)300);
            n.setShort("MaxSpawnDelay", (short)600);
            n.setShort("SpawnCount", (short)1);
            n.setShort("MaxNearbyEntities", (short)3);
            n.setShort("RequiredPlayerRange", (short)16);
            var19.func_145881_a().readFromNBT(n);
        }
		world.setBlock(i + 6, j + 1, k + 25, Blocks.stonebrick);
		world.setBlock(i + 6, j + 1, k + 27, Blocks.stonebrick);
		world.setBlock(i + 6, j + 1, k + 28, Blocks.stonebrick);
		world.setBlock(i + 6, j + 1, k + 29, Blocks.stonebrick);
		world.setBlock(i + 6, j + 1, k + 30, Blocks.stonebrick);
		world.setBlock(i + 6, j + 1, k + 31, Blocks.stone_brick_stairs, 3, 4);
		world.setBlock(i + 6, j + 1, k + 34, Blocks.stonebrick);
		world.setBlock(i + 6, j + 1, k + 45, Blocks.stonebrick);
		world.setBlock(i + 6, j + 2, k + 0, Blocks.glass_pane);
		world.setBlock(i + 6, j + 2, k + 25, Blocks.stonebrick);
		world.setBlock(i + 6, j + 2, k + 27, Blocks.stonebrick);
		world.setBlock(i + 6, j + 2, k + 28, Blocks.stonebrick);
		world.setBlock(i + 6, j + 2, k + 29, Blocks.stonebrick);
		world.setBlock(i + 6, j + 2, k + 30, Blocks.stone_brick_stairs, 3, 4);
		world.setBlock(i + 6, j + 2, k + 45, Blocks.glass_pane);
		world.setBlock(i + 6, j + 3, k + 0, Blocks.glass_pane);
		world.setBlock(i + 6, j + 3, k + 25, Blocks.stonebrick);
		world.setBlock(i + 6, j + 3, k + 27, Blocks.stonebrick);
		world.setBlock(i + 6, j + 3, k + 28, Blocks.stonebrick);
		world.setBlock(i + 6, j + 3, k + 29, Blocks.stone_brick_stairs, 3, 4);
		world.setBlock(i + 6, j + 3, k + 45, Blocks.glass_pane);
		world.setBlock(i + 6, j + 4, k + 0, Blocks.stonebrick);
		world.setBlock(i + 6, j + 4, k + 25, Blocks.stonebrick);
		world.setBlock(i + 6, j + 4, k + 27, Blocks.stonebrick);
		world.setBlock(i + 6, j + 4, k + 28, Blocks.stone_brick_stairs, 3, 4);
		world.setBlock(i + 6, j + 4, k + 45, Blocks.stonebrick);
		world.setBlock(i + 6, j + 5, k + 0, Blocks.stonebrick);
		world.setBlock(i + 6, j + 5, k + 1, Blocks.stonebrick);
		world.setBlock(i + 6, j + 5, k + 2, Blocks.stonebrick);
		world.setBlock(i + 6, j + 5, k + 3, Blocks.stonebrick);
		world.setBlock(i + 6, j + 5, k + 4, Blocks.stonebrick);
		world.setBlock(i + 6, j + 5, k + 5, Blocks.stonebrick);
		world.setBlock(i + 6, j + 5, k + 6, Blocks.stonebrick);
		world.setBlock(i + 6, j + 5, k + 7, Blocks.stonebrick);
		world.setBlock(i + 6, j + 5, k + 8, Blocks.stonebrick);
		world.setBlock(i + 6, j + 5, k + 9, Blocks.stonebrick);
		world.setBlock(i + 6, j + 5, k + 10, Blocks.stonebrick);
		world.setBlock(i + 6, j + 5, k + 11, Blocks.stonebrick);
		world.setBlock(i + 6, j + 5, k + 12, Blocks.stonebrick);
		world.setBlock(i + 6, j + 5, k + 13, Blocks.stonebrick);
		world.setBlock(i + 6, j + 5, k + 14, Blocks.stonebrick);
		world.setBlock(i + 6, j + 5, k + 15, Blocks.stonebrick);
		world.setBlock(i + 6, j + 5, k + 16, Blocks.stonebrick);
		world.setBlock(i + 6, j + 5, k + 17, Blocks.stonebrick);
		world.setBlock(i + 6, j + 5, k + 18, Blocks.stonebrick);
		world.setBlock(i + 6, j + 5, k + 19, Blocks.stonebrick);
		world.setBlock(i + 6, j + 5, k + 20, Blocks.stonebrick);
		world.setBlock(i + 6, j + 5, k + 21, Blocks.stonebrick);
		world.setBlock(i + 6, j + 5, k + 22, Blocks.stonebrick);
		world.setBlock(i + 6, j + 5, k + 23, Blocks.stonebrick);
		world.setBlock(i + 6, j + 5, k + 24, Blocks.stonebrick);
		world.setBlock(i + 6, j + 5, k + 25, Blocks.stonebrick);
		world.setBlock(i + 6, j + 5, k + 26, Blocks.stonebrick);
		world.setBlock(i + 6, j + 5, k + 27, Blocks.stone_brick_stairs, 3, 4);
		world.setBlock(i + 6, j + 5, k + 32, Blocks.stonebrick);
		world.setBlock(i + 6, j + 5, k + 33, Blocks.stonebrick);
		world.setBlock(i + 6, j + 5, k + 34, Blocks.stonebrick);
		world.setBlock(i + 6, j + 5, k + 35, Blocks.stonebrick);
		world.setBlock(i + 6, j + 5, k + 36, Blocks.stonebrick);
		world.setBlock(i + 6, j + 5, k + 37, Blocks.stonebrick);
		world.setBlock(i + 6, j + 5, k + 38, Blocks.stonebrick);
		world.setBlock(i + 6, j + 5, k + 39, Blocks.stonebrick);
		world.setBlock(i + 6, j + 5, k + 40, Blocks.stonebrick);
		world.setBlock(i + 6, j + 5, k + 41, Blocks.stonebrick);
		world.setBlock(i + 6, j + 5, k + 42, Blocks.stonebrick);
		world.setBlock(i + 6, j + 5, k + 43, Blocks.stonebrick);
		world.setBlock(i + 6, j + 5, k + 44, Blocks.stonebrick);
		world.setBlock(i + 6, j + 5, k + 45, Blocks.stonebrick);
		world.setBlock(i + 6, j + 6, k + 0, Blocks.stonebrick);
		world.setBlock(i + 6, j + 6, k + 22, Blocks.fence);
		world.setBlock(i + 6, j + 6, k + 23, Blocks.spruce_stairs, 2, 4);
		world.setBlock(i + 6, j + 6, k + 25, Blocks.stonebrick);
		world.setBlock(i + 6, j + 6, k + 45, Blocks.stonebrick);
		world.setBlock(i + 6, j + 7, k + 0, Blocks.stonebrick);
		world.setBlock(i + 6, j + 7, k + 22, Blocks.carpet, 12,4);
		world.setBlock(i + 6, j + 7, k + 25, Blocks.stonebrick);
		world.setBlock(i + 6, j + 7, k + 45, Blocks.glass_pane);
		world.setBlock(i + 6, j + 8, k + 0, Blocks.glass_pane);
		world.setBlock(i + 6, j + 8, k + 25, Blocks.stonebrick);
		world.setBlock(i + 6, j + 8, k + 45, Blocks.glass_pane);
		world.setBlock(i + 6, j + 9, k + 0, Blocks.glass_pane);
		world.setBlock(i + 6, j + 9, k + 25, Blocks.stonebrick);
		world.setBlock(i + 6, j + 9, k + 45, Blocks.stonebrick);
		world.setBlock(i + 6, j + 10, k + 0, Blocks.stonebrick);
		world.setBlock(i + 6, j + 10, k + 1, Blocks.stonebrick);
		world.setBlock(i + 6, j + 10, k + 2, Blocks.stonebrick);
		world.setBlock(i + 6, j + 10, k + 3, Blocks.stonebrick);
		world.setBlock(i + 6, j + 10, k + 4, Blocks.stonebrick);
		world.setBlock(i + 6, j + 10, k + 5, Blocks.stonebrick);
		world.setBlock(i + 6, j + 10, k + 6, Blocks.stonebrick);
		world.setBlock(i + 6, j + 10, k + 7, Blocks.stonebrick);
		world.setBlock(i + 6, j + 10, k + 8, Blocks.stonebrick);
		world.setBlock(i + 6, j + 10, k + 9, Blocks.stonebrick);
		world.setBlock(i + 6, j + 10, k + 10, Blocks.stonebrick);
		world.setBlock(i + 6, j + 10, k + 11, Blocks.stonebrick);
		world.setBlock(i + 6, j + 10, k + 12, Blocks.stonebrick);
		world.setBlock(i + 6, j + 10, k + 13, Blocks.stonebrick);
		world.setBlock(i + 6, j + 10, k + 14, Blocks.stonebrick);
		world.setBlock(i + 6, j + 10, k + 15, Blocks.stonebrick);
		world.setBlock(i + 6, j + 10, k + 16, Blocks.stonebrick);
		world.setBlock(i + 6, j + 10, k + 17, Blocks.stonebrick);
		world.setBlock(i + 6, j + 10, k + 18, Blocks.stonebrick);
		world.setBlock(i + 6, j + 10, k + 19, Blocks.stonebrick);
		world.setBlock(i + 6, j + 10, k + 20, Blocks.stonebrick);
		world.setBlock(i + 6, j + 10, k + 21, Blocks.stonebrick);
		world.setBlock(i + 6, j + 10, k + 22, Blocks.stonebrick);
		world.setBlock(i + 6, j + 10, k + 23, Blocks.stonebrick);
		world.setBlock(i + 6, j + 10, k + 24, Blocks.stonebrick);
		world.setBlock(i + 6, j + 10, k + 25, Blocks.stonebrick);
		world.setBlock(i + 6, j + 10, k + 26, Blocks.stonebrick);
		world.setBlock(i + 6, j + 10, k + 27, Blocks.stonebrick);
		world.setBlock(i + 6, j + 10, k + 28, Blocks.stonebrick);
		world.setBlock(i + 6, j + 10, k + 29, Blocks.stonebrick);
		world.setBlock(i + 6, j + 10, k + 30, Blocks.stonebrick);
		world.setBlock(i + 6, j + 10, k + 31, Blocks.stonebrick);
		world.setBlock(i + 6, j + 10, k + 32, Blocks.stonebrick);
		world.setBlock(i + 6, j + 10, k + 33, Blocks.stonebrick);
		world.setBlock(i + 6, j + 10, k + 34, Blocks.stonebrick);
		world.setBlock(i + 6, j + 10, k + 35, Blocks.stonebrick);
		world.setBlock(i + 6, j + 10, k + 36, Blocks.stonebrick);
		world.setBlock(i + 6, j + 10, k + 37, Blocks.stonebrick);
		world.setBlock(i + 6, j + 10, k + 38, Blocks.stonebrick);
		world.setBlock(i + 6, j + 10, k + 39, Blocks.stonebrick);
		world.setBlock(i + 6, j + 10, k + 40, Blocks.stonebrick);
		world.setBlock(i + 6, j + 10, k + 41, Blocks.stonebrick);
		world.setBlock(i + 6, j + 10, k + 42, Blocks.stonebrick);
		world.setBlock(i + 6, j + 10, k + 43, Blocks.stonebrick);
		world.setBlock(i + 6, j + 10, k + 44, Blocks.stonebrick);
		world.setBlock(i + 6, j + 10, k + 45, Blocks.stonebrick);
		world.setBlock(i + 6, j + 11, k + 0, Blocks.stonebrick);
		world.setBlock(i + 6, j + 11, k + 21, Blocks.stonebrick);
		world.setBlock(i + 6, j + 11, k + 24, Blocks.stonebrick);
		world.setBlock(i + 6, j + 11, k + 45, Blocks.stonebrick);
		world.setBlock(i + 6, j + 12, k + 0, Blocks.glass_pane);
		world.setBlock(i + 6, j + 12, k + 21, Blocks.stonebrick);
		world.setBlock(i + 6, j + 12, k + 24, Blocks.stonebrick);
		world.setBlock(i + 6, j + 12, k + 45, Blocks.glass_pane);
		world.setBlock(i + 6, j + 13, k + 0, Blocks.glass_pane);
		world.setBlock(i + 6, j + 13, k + 24, Blocks.stonebrick);

		generate2(world, rand, i, j, k);
		return true;
	}

	public boolean generate2(World world, Random rand, int i, int j, int k) {
		world.setBlock(i + 6, j + 13, k + 45, Blocks.glass_pane);
		world.setBlock(i + 6, j + 14, k + 0, Blocks.stonebrick);
		world.setBlock(i + 6, j + 14, k + 24, Blocks.stonebrick);
		world.setBlock(i + 6, j + 14, k + 45, Blocks.stonebrick);
		world.setBlock(i + 6, j + 15, k + 0, Blocks.stonebrick);
		world.setBlock(i + 6, j + 15, k + 1, Blocks.stonebrick);
		world.setBlock(i + 6, j + 15, k + 2, Blocks.stonebrick);
		world.setBlock(i + 6, j + 15, k + 3, Blocks.stonebrick);
		world.setBlock(i + 6, j + 15, k + 4, Blocks.stonebrick);
		world.setBlock(i + 6, j + 15, k + 5, Blocks.stonebrick);
		world.setBlock(i + 6, j + 15, k + 6, Blocks.stonebrick);
		world.setBlock(i + 6, j + 15, k + 7, Blocks.stonebrick);
		world.setBlock(i + 6, j + 15, k + 8, Blocks.stonebrick);
		world.setBlock(i + 6, j + 15, k + 9, Blocks.stonebrick);
		world.setBlock(i + 6, j + 15, k + 10, Blocks.stonebrick);
		world.setBlock(i + 6, j + 15, k + 11, Blocks.stonebrick);
		world.setBlock(i + 6, j + 15, k + 12, Blocks.stonebrick);
		world.setBlock(i + 6, j + 15, k + 13, Blocks.stonebrick);
		world.setBlock(i + 6, j + 15, k + 14, Blocks.stonebrick);
		world.setBlock(i + 6, j + 15, k + 15, Blocks.stonebrick);
		world.setBlock(i + 6, j + 15, k + 16, Blocks.stonebrick);
		world.setBlock(i + 6, j + 15, k + 17, Blocks.stonebrick);
		world.setBlock(i + 6, j + 15, k + 18, Blocks.stonebrick);
		world.setBlock(i + 6, j + 15, k + 19, Blocks.stonebrick);
		world.setBlock(i + 6, j + 15, k + 20, Blocks.stonebrick);
		world.setBlock(i + 6, j + 15, k + 21, Blocks.stonebrick);
		world.setBlock(i + 6, j + 15, k + 22, Blocks.stonebrick);
		world.setBlock(i + 6, j + 15, k + 23, Blocks.stonebrick);
		world.setBlock(i + 6, j + 15, k + 24, Blocks.stonebrick);
		world.setBlock(i + 6, j + 15, k + 25, Blocks.stonebrick);
		world.setBlock(i + 6, j + 15, k + 26, Blocks.stonebrick);
		world.setBlock(i + 6, j + 15, k + 27, Blocks.stonebrick);
		world.setBlock(i + 6, j + 15, k + 28, Blocks.stonebrick);
		world.setBlock(i + 6, j + 15, k + 29, Blocks.stonebrick);
		world.setBlock(i + 6, j + 15, k + 30, Blocks.stonebrick);
		world.setBlock(i + 6, j + 15, k + 31, Blocks.stonebrick);
		world.setBlock(i + 6, j + 15, k + 32, Blocks.stonebrick);
		world.setBlock(i + 6, j + 15, k + 33, Blocks.stonebrick);
		world.setBlock(i + 6, j + 15, k + 34, Blocks.stonebrick);
		world.setBlock(i + 6, j + 15, k + 35, Blocks.stonebrick);
		world.setBlock(i + 6, j + 15, k + 36, Blocks.stonebrick);
		world.setBlock(i + 6, j + 15, k + 37, Blocks.stonebrick);
		world.setBlock(i + 6, j + 15, k + 38, Blocks.stonebrick);
		world.setBlock(i + 6, j + 15, k + 39, Blocks.stonebrick);
		world.setBlock(i + 6, j + 15, k + 40, Blocks.stonebrick);
		world.setBlock(i + 6, j + 15, k + 41, Blocks.stonebrick);
		world.setBlock(i + 6, j + 15, k + 42, Blocks.stonebrick);
		world.setBlock(i + 6, j + 15, k + 43, Blocks.stonebrick);
		world.setBlock(i + 6, j + 15, k + 44, Blocks.stonebrick);
		world.setBlock(i + 6, j + 15, k + 45, Blocks.stonebrick);
		world.setBlock(i + 6, j + 16, k + 0, Blocks.stonebrick);
		world.setBlock(i + 6, j + 16, k + 45, Blocks.stonebrick);
		world.setBlock(i + 7, j + 0, k + 0, Blocks.stonebrick);
		world.setBlock(i + 7, j + 0, k + 1, Blocks.stonebrick);
		world.setBlock(i + 7, j + 0, k + 2, Blocks.stonebrick);
		world.setBlock(i + 7, j + 0, k + 3, Blocks.stonebrick);
		world.setBlock(i + 7, j + 0, k + 4, Blocks.stonebrick);
		world.setBlock(i + 7, j + 0, k + 5, Blocks.stonebrick);
		world.setBlock(i + 7, j + 0, k + 6, Blocks.stonebrick);
		world.setBlock(i + 7, j + 0, k + 7, Blocks.stonebrick);
		world.setBlock(i + 7, j + 0, k + 8, Blocks.stonebrick);
		world.setBlock(i + 7, j + 0, k + 9, Blocks.stonebrick);
		world.setBlock(i + 7, j + 0, k + 10, Blocks.stonebrick);
		world.setBlock(i + 7, j + 0, k + 11, Blocks.stonebrick);
		world.setBlock(i + 7, j + 0, k + 12, Blocks.stonebrick);
		world.setBlock(i + 7, j + 0, k + 13, Blocks.stonebrick);
		world.setBlock(i + 7, j + 0, k + 14, Blocks.stonebrick);
		world.setBlock(i + 7, j + 0, k + 15, Blocks.stonebrick);
		world.setBlock(i + 7, j + 0, k + 16, Blocks.stonebrick);
		world.setBlock(i + 7, j + 0, k + 17, Blocks.stonebrick);
		world.setBlock(i + 7, j + 0, k + 18, Blocks.stonebrick);
		world.setBlock(i + 7, j + 0, k + 19, Blocks.stonebrick);
		world.setBlock(i + 7, j + 0, k + 20, Blocks.stonebrick);
		world.setBlock(i + 7, j + 0, k + 21, Blocks.stonebrick);
		world.setBlock(i + 7, j + 0, k + 22, Blocks.stonebrick);
		world.setBlock(i + 7, j + 0, k + 23, Blocks.stonebrick);
		world.setBlock(i + 7, j + 0, k + 24, Blocks.stonebrick);
		world.setBlock(i + 7, j + 0, k + 25, Blocks.stonebrick);
		world.setBlock(i + 7, j + 0, k + 26, Blocks.stonebrick);
		world.setBlock(i + 7, j + 0, k + 27, Blocks.stonebrick);
		world.setBlock(i + 7, j + 0, k + 28, Blocks.stonebrick);
		world.setBlock(i + 7, j + 0, k + 29, Blocks.stonebrick);
		world.setBlock(i + 7, j + 0, k + 30, Blocks.stonebrick);
		world.setBlock(i + 7, j + 0, k + 31, Blocks.stonebrick);
		world.setBlock(i + 7, j + 0, k + 32, Blocks.stonebrick);
		world.setBlock(i + 7, j + 0, k + 33, Blocks.stonebrick);
		world.setBlock(i + 7, j + 0, k + 34, Blocks.stonebrick);
		world.setBlock(i + 7, j + 0, k + 35, Blocks.stonebrick);
		world.setBlock(i + 7, j + 0, k + 36, Blocks.stonebrick);
		world.setBlock(i + 7, j + 0, k + 37, Blocks.stonebrick);
		world.setBlock(i + 7, j + 0, k + 38, Blocks.stonebrick);
		world.setBlock(i + 7, j + 0, k + 39, Blocks.stonebrick);
		world.setBlock(i + 7, j + 0, k + 40, Blocks.stonebrick);
		world.setBlock(i + 7, j + 0, k + 41, Blocks.stonebrick);
		world.setBlock(i + 7, j + 0, k + 42, Blocks.stonebrick);
		world.setBlock(i + 7, j + 0, k + 43, Blocks.stonebrick);
		world.setBlock(i + 7, j + 0, k + 44, Blocks.stonebrick);
		world.setBlock(i + 7, j + 0, k + 45, Blocks.stonebrick);
		world.setBlock(i + 7, j + 1, k + 0, Blocks.stonebrick);
		world.setBlock(i + 7, j + 1, k + 25, Blocks.stonebrick);
		world.setBlock(i + 7, j + 1, k + 27, Blocks.stonebrick);
		world.setBlock(i + 7, j + 1, k + 28, Blocks.stonebrick);
		world.setBlock(i + 7, j + 1, k + 29, Blocks.stonebrick);
		world.setBlock(i + 7, j + 1, k + 30, Blocks.stonebrick);
		world.setBlock(i + 7, j + 1, k + 31, Blocks.stone_brick_stairs, 3, 4);
		world.setBlock(i + 7, j + 1, k + 45, Blocks.stonebrick);
		world.setBlock(i + 7, j + 2, k + 0, Blocks.stonebrick);
		world.setBlock(i + 7, j + 2, k + 25, Blocks.stonebrick);
		world.setBlock(i + 7, j + 2, k + 27, Blocks.stonebrick);
		world.setBlock(i + 7, j + 2, k + 28, Blocks.stonebrick);
		world.setBlock(i + 7, j + 2, k + 29, Blocks.stonebrick);
		world.setBlock(i + 7, j + 2, k + 30, Blocks.stone_brick_stairs, 3, 4);
		world.setBlock(i + 7, j + 2, k + 45, Blocks.stonebrick);
		world.setBlock(i + 7, j + 3, k + 0, Blocks.stonebrick);
		world.setBlock(i + 7, j + 3, k + 25, Blocks.stonebrick);
		world.setBlock(i + 7, j + 3, k + 27, Blocks.stonebrick);
		world.setBlock(i + 7, j + 3, k + 28, Blocks.stonebrick);
		world.setBlock(i + 7, j + 3, k + 29, Blocks.stone_brick_stairs, 3, 4);
		world.setBlock(i + 7, j + 3, k + 45, Blocks.stonebrick);
		world.setBlock(i + 7, j + 4, k + 0, Blocks.stonebrick);
		world.setBlock(i + 7, j + 4, k + 25, Blocks.stonebrick);
		world.setBlock(i + 7, j + 4, k + 27, Blocks.stonebrick);
		world.setBlock(i + 7, j + 4, k + 28, Blocks.stone_brick_stairs, 3, 4);
		world.setBlock(i + 7, j + 4, k + 45, Blocks.stonebrick);
		world.setBlock(i + 7, j + 5, k + 0, Blocks.stonebrick);
		world.setBlock(i + 7, j + 5, k + 1, Blocks.stonebrick);
		world.setBlock(i + 7, j + 5, k + 2, Blocks.stonebrick);
		world.setBlock(i + 7, j + 5, k + 3, Blocks.stonebrick);
		world.setBlock(i + 7, j + 5, k + 4, Blocks.stonebrick);
		world.setBlock(i + 7, j + 5, k + 5, Blocks.stonebrick);
		world.setBlock(i + 7, j + 5, k + 6, Blocks.stonebrick);
		world.setBlock(i + 7, j + 5, k + 7, Blocks.stonebrick);
		world.setBlock(i + 7, j + 5, k + 8, Blocks.stonebrick);
		world.setBlock(i + 7, j + 5, k + 9, Blocks.stonebrick);
		world.setBlock(i + 7, j + 5, k + 10, Blocks.stonebrick);
		world.setBlock(i + 7, j + 5, k + 11, Blocks.stonebrick);
		world.setBlock(i + 7, j + 5, k + 12, Blocks.stonebrick);
		world.setBlock(i + 7, j + 5, k + 13, Blocks.stonebrick);
		world.setBlock(i + 7, j + 5, k + 14, Blocks.stonebrick);
		world.setBlock(i + 7, j + 5, k + 15, Blocks.stonebrick);
		world.setBlock(i + 7, j + 5, k + 16, Blocks.stonebrick);
		world.setBlock(i + 7, j + 5, k + 17, Blocks.stonebrick);
		world.setBlock(i + 7, j + 5, k + 18, Blocks.stonebrick);
		world.setBlock(i + 7, j + 5, k + 19, Blocks.stonebrick);
		world.setBlock(i + 7, j + 5, k + 20, Blocks.stonebrick);
		world.setBlock(i + 7, j + 5, k + 21, Blocks.stonebrick);
		world.setBlock(i + 7, j + 5, k + 22, Blocks.stonebrick);
		world.setBlock(i + 7, j + 5, k + 23, Blocks.stonebrick);
		world.setBlock(i + 7, j + 5, k + 24, Blocks.stonebrick);
		world.setBlock(i + 7, j + 5, k + 25, Blocks.stonebrick);
		world.setBlock(i + 7, j + 5, k + 26, Blocks.stonebrick);
		world.setBlock(i + 7, j + 5, k + 27, Blocks.stone_brick_stairs, 3, 4);
		world.setBlock(i + 7, j + 5, k + 32, Blocks.stonebrick);
		world.setBlock(i + 7, j + 5, k + 33, Blocks.stonebrick);
		world.setBlock(i + 7, j + 5, k + 34, Blocks.stonebrick);
		world.setBlock(i + 7, j + 5, k + 35, Blocks.stonebrick);
		world.setBlock(i + 7, j + 5, k + 36, Blocks.stonebrick);
		world.setBlock(i + 7, j + 5, k + 37, Blocks.stonebrick);
		world.setBlock(i + 7, j + 5, k + 38, Blocks.stonebrick);
		world.setBlock(i + 7, j + 5, k + 39, Blocks.stonebrick);
		world.setBlock(i + 7, j + 5, k + 40, Blocks.stonebrick);
		world.setBlock(i + 7, j + 5, k + 41, Blocks.stonebrick);
		world.setBlock(i + 7, j + 5, k + 42, Blocks.stonebrick);
		world.setBlock(i + 7, j + 5, k + 43, Blocks.stonebrick);
		world.setBlock(i + 7, j + 5, k + 44, Blocks.stonebrick);
		world.setBlock(i + 7, j + 5, k + 45, Blocks.stonebrick);
		world.setBlock(i + 7, j + 6, k + 0, Blocks.stonebrick);
